Workbook

Sheet Cover
A1: Argan, Inc. (AGX)
A2: DCF valuation — exit-multiple terminal · defaults anchored to consensus
A4: Last updated | B4: 2026-07-06
A5: Data pulled (FMP) | B5: Q4 2026
A6: Assumptions by | B6: Opus 4.8 — values as of 2026-07-04 (provenance seeded)
A8: VALUATION SUMMARY
A10: Fair value / share | B10: =Valuation!B36
A11: Current price | B11: =Valuation!$B$2
A12: Upside / (downside) | B12: =Valuation!B42
A13: Verdict | B13: =IF(Valuation!B36>Valuation!$B$2,"Undervalued","Overvalued")
A14: Monte Carlo P(undervalued) | B14: ='Monte Carlo'!B20
A15: KEY ASSUMPTIONS
A17: WACC (from WACC tab) | B17: =WACC!B15
A18: Terminal method | B18: =Valuation!$B$6
A19: Exit basis / multiple | B19: =Valuation!$B$7
A20: Exit multiple | B20: =Valuation!$B$8
A21: Terminal growth (g) | B21: =Valuation!$B$4
A22: Terminal weight | B22: =Valuation!B39
A23: Forecast horizon | B23: 10 years
A25: THE STORY (Opus)
A27: (Opus narrative)

Sheet Dashboard
A1: Argan, Inc. (AGX) — Control Dashboard
A2: Edit the yellow cells; everything recomputes. Orange = a driver you've moved off consensus.
A4: VERDICT
A5: Fair value / share | B5: =Valuation!B36
A6: Current price | B6: =Dashboard!$B$48
A7: Upside / (downside) | B7: =Valuation!B42
A8: Verdict | B8: =IF(Valuation!B36>Dashboard!$B$48,"Undervalued","Overvalued")
A9: Monte Carlo P(undervalued) | B9: ='Monte Carlo'!B20
A11: GUARDRAIL SIGNALS (are my assumptions sane?)
A12: Signal | B12: Value | C12: Flag | D12: Healthy
A13: Terminal weight (% of EV) | B13: =Valuation!B39 | C13: =IF(Valuation!B39>0.9,"! high","ok") | D13: < 90%
A14: Implied g vs exit multiple | B14: =Valuation!B40 | C14: =IF(Valuation!B40>Dashboard!$B$46+0.02,"! rich","ok") | D14: near term g
A15: ROIC - WACC (2026) | B15: =IF(Model!F36<=0,"n/a (neg. capital)",Model!G38-WACC!B15) | C15: =IF(Model!F36<=0,"n/a",IF(Model!G38-WACC!B15<0,"! destroys","creates")) | D15: > 0
A16: Revenue vs consensus (2026) | B16: =Consensus!B6 | C16: =IF(ABS(Consensus!B6)>0.05,"! off-Street","on") | D16: +/- 5%
A17: MC P(undervalued) | B17: ='Monte Carlo'!B20 | C17: =IF('Monte Carlo'!B20<0.5,"! coin-flip","ok") | D17: context
A18: REVENUE DRIVERS — near-term & terminal growth per segment
A19: Segment | B19: Near-term | C19: Terminal | D19: Consensus | E19: Thesis claim
A20: Power Industry Services | B20: 0.16985097 | C20: 0.05 | D20: 0.16985097
A21: Industrial Fabrication And Field Services | B21: 0.098298517 | C21: 0.05 | D21: 0.098298517
A28: PROFITABILITY & TAX
A29: Near-term operating margin | B29: 0.15679525 | D29: 0.15679525 | E29: consensus-implied; ramps to terminal
A30: Terminal operating margin | B30: 0.14119337 | E30: AI/ads mix + operating leverage
A31: Tax rate | B31: 0.24
A33: CAPITAL INTENSITY
A34: 2026 capex ($M) | B34: 4.2647 | D34: 4.2647 | E34: ~last-year capex +10%; set to guidance
A35: Terminal capex / D&A | B35: 1.05 | E35: converges to ~1.0x as build-out matures
A37: DISCOUNT RATE & TERMINAL
A38: Risk-free rate (10Y) | B38: 0.043
A39: Equity risk premium | B39: 0.045
A40: Beta (levered) | B40: 0.564 | E40: FMP raw beta; Damodaran bottom-up ~1.2
A41: Pre-tax cost of debt | B41: 0.045
A42: WACC (computed) | B42: =WACC!B15
A43: Terminal method | B43: Exit multiple
A44: Exit basis | B44: EV/EBITDA
A45: Exit multiple | B45: 12
A46: Terminal growth (g) | B46: 0.045
A47: Country risk premium | B47: 0 | E47: Damodaran country premiums, revenue-weighted (2026-01); 0 for US/mature
A48: Current price | B48: 706.15002
A49: Growth fade curvature | B49: 1 | E49: convexity of the near->terminal growth fade, fit to consensus (1.0=linear); higher = faster early deceleration
A50: SCENARIOS — Bull / Bear offsets vs Base (edit the yellow Δs)
...

Sheet Assumptions
A1: AGX — Assumptions & Reasoning
A2: Provenance of every Dashboard input. Read-only — regenerated by each build/refresh. Current is a live link to the Dashboard; Source / Opus value / Note are as of the last refresh_dcf run.
A4: Assumptions baseline | B4: seeded 2026-07-04 from the synced assumptions block (pass predates provenance tracking — may already include your edits)
A6: DASHBOARD INPUTS — value · source · reasoning
A7: Input | B7: Cell | C7: Current | D7: Source | E7: Opus value | F7: Note
A8: Power Industry Services — near-term growth | B8: B20 | C8: =Dashboard!B20 | D8: Opus | E8: 17.0%
A9: Power Industry Services — terminal growth | B9: C20 | C9: =Dashboard!C20 | D9: Opus | E9: 5.0%
A10: Industrial Fabrication And Field Services — near-term growth | B10: B21 | C10: =Dashboard!B21 | D10: Opus | E10: 9.8%
A11: Industrial Fabrication And Field Services — terminal growth | B11: C21 | C11: =Dashboard!C21 | D11: Opus | E11: 5.0%
A12: Near-term operating margin | B12: B29 | C12: =Dashboard!B29 | D12: Opus | E12: 15.7%
A13: Terminal operating margin | B13: B30 | C13: =Dashboard!B30 | D13: Opus | E13: 14.1%
A14: Tax rate | B14: B31 | C14: =Dashboard!B31 | D14: Opus | E14: 24.0%
A15: Terminal capex / D&A | B15: B35 | C15: =Dashboard!B35 | D15: Opus | E15: 1.1x
A16: Risk-free rate (10Y) | B16: B38 | C16: =Dashboard!B38 | D16: workbook (synced) | E16: — | F16: no Opus pass — value synced from this workbook
A17: Equity risk premium | B17: B39 | C17: =Dashboard!B39 | D17: workbook (synced) | E17: — | F17: no Opus pass — value synced from this workbook
A18: Beta (levered) | B18: B40 | C18: =Dashboard!B40 | D18: Opus | E18: 0.564
A19: Pre-tax cost of debt | B19: B41 | C19: =Dashboard!B41 | D19: Opus | E19: 4.5%
A20: Terminal method | B20: B43 | C20: =Dashboard!B43 | D20: Opus | E20: Exit multiple
A21: Exit basis | B21: B44 | C21: =Dashboard!B44 | D21: Opus | E21: EV/EBITDA
A22: Exit multiple | B22: B45 | C22: =Dashboard!B45 | D22: Opus | E22: 12.0x
A23: Terminal growth (g) | B23: B46 | C23: =Dashboard!B46 | D23: Opus | E23: 4.5%
A24: 2026 capex ($M) | B24: B34 | C24: =Dashboard!B34 | D24: workbook (synced) | E24: — | F24: last-year capex +10% unless set to guidance; edits not tracked
A25: Bull Δ — segment growth, near-term | B25: C52 | C25: =Dashboard!C52 | D25: seed default | E25: 3.0%
A26: Bear Δ — segment growth, near-term | B26: D52 | C26: =Dashboard!D52 | D26: seed default | E26: -3.0%
A27: Bull Δ — segment growth, terminal | B27: C53 | C27: =Dashboard!C53 | D27: seed default | E27: 1.0%
A28: Bear Δ — segment growth, terminal | B28: D53 | C28: =Dashboard!D53 | D28: seed default | E28: -1.0%
A29: Bull Δ — operating margin, near-term | B29: C54 | C29: =Dashboard!C54 | D29: seed default | E29: 1.0%
A30: Bear Δ — operating margin, near-term | B30: D54 | C30: =Dashboard!D54 | D30: seed default | E30: -1.0%
A31: Bull Δ — operating margin, terminal | B31: C55 | C31: =Dashboard!C55 | D31: seed default | E31: 2.0%
A32: Bear Δ — operating margin, terminal | B32: D55 | C32: =Dashboard!D55 | D32: seed default | E32: -2.0%
A33: Bull Δ — exit multiple | B33: C56 | C33: =Dashboard!C56 | D33: seed default | E33: 2.0x
A34: Bear Δ — exit multiple | B34: D56 | C34: =Dashboard!D56 | D34: seed default | E34: -2.0x
A35: Bull Δ — terminal growth (g) | B35: C57 | C35: =Dashboard!C57 | D35: seed default | E35: 0.5%
A36: Bear Δ — terminal growth (g) | B36: D57 | C36: =Dashboard!D57 | D36: seed default | E36: -0.5%

Sheet Color Code
A1: Color | B1: Meaning
A2: Black | B2: Formula-driven (same-sheet)
A3: Blue | B3: Hard-coded actuals (from FMP filings)
A4: Yellow | B4: An assumption you can change — edit these to drive the model
A5: Green | B5: A formula that links to another sheet
A6: Orange | B6: (Dashboard) an assumption you've moved off consensus — your active bet
A7: How to use | B7: Edit yellow cells (Model assumptions, WACC drivers, Valuation toggles). Everything else recomputes.

Sheet WACC
A1: WACC Calculator
A2: Risk-free rate (10Y) | B2: =Dashboard!$B$38
A3: Equity risk premium | B3: =Dashboard!$B$39
A4: Beta (levered) | B4: =Dashboard!$B$40
A5: Country risk premium | B5: =Dashboard!$B$47
A6: Cost of equity (CAPM) | B6: =B2+B4*B3+B5
A7: Pre-tax cost of debt | B7: =Dashboard!$B$41
A8: Tax rate | B8: =Dashboard!$B$31
A9: After-tax cost of debt | B9: =B7*(1-B8)
A10: Market cap (E) | B10: =Dashboard!$B$48*Financials!AC17
A11: Total debt (D) | B11: =Financials!AC41
A12: Equity weight | B12: =B10/(B10+B11)
A13: Debt weight | B13: =B11/(B10+B11)
A15: WACC | B15: =B12*B6+B13*B9
A17: Yellow = edit. CAPM cost of equity (incl. country risk premium); market-value weights. Feeds Valuation!WACC.

Sheet Model
A1: $M unless noted | B1: FY2022A | C1: FY2023A | D1: FY2024A | E1: FY2025A | F1: FY2026A | G1: FY2027E | H1: FY2028E | I1: FY2029E | J1: FY2030E | K1: FY2031E | L1: FY2032E | M1: FY2033E | N1: FY2034E | O1: FY2035E | P1: FY2036E
A3: REVENUE BY SEGMENT (yellow = growth assumption; actuals link to Financials)
A4: Power Industry Services | B4: =SUM(Financials!J19:M19) | C4: =SUM(Financials!N19:Q19) | D4: =SUM(Financials!R19:U19) | E4: =SUM(Financials!V19:Y19) | F4: =SUM(Financials!Z19:AC19) | G4: =F4*(1+G5) | H4: =G4*(1+H5) | I4: =H4*(1+I5) | J4: =I4*(1+J5) | K4: =J4*(1+K5) | L4: =K4*(1+L5) | M4: =L4*(1+M5) | N4: =M4*(1+N5) | ... P4: =O4*(1+P5)
A5: growth % (convex fade; curvature from Dashboard) | C5: =IFERROR(C4/B4-1,"") | D5: =IFERROR(D4/C4-1,"") | E5: =IFERROR(E4/D4-1,"") | F5: =IFERROR(F4/E4-1,"") | G5: =Dashboard!$C$20+(Dashboard!$B$20-Dashboard!$C$20)*((9-0)/9)^Dashboard!$B$49 | H5: =Dashboard!$C$20+(Dashboard!$B$20-Dashboard!$C$20)*((9-1)/9)^Dashboard!$B$49 | I5: =Dashboard!$C$20+(Dashboard!$B$20-Dashboard!$C$20)*((9-2)/9)^Dashboard!$B$49 | J5: =Dashboard!$C$20+(Dashboard!$B$20-Dashboard!$C$20)*((9-3)/9)^Dashboard!$B$49 | K5: =Dashboard!$C$20+(Dashboard!$B$20-Dashboard!$C$20)*((9-4)/9)^Dashboard!$B$49 | L5: =Dashboard!$C$20+(Dashboard!$B$20-Dashboard!$C$20)*((9-5)/9)^Dashboard!$B$49 | M5: =Dashboard!$C$20+(Dashboard!$B$20-Dashboard!$C$20)*((9-6)/9)^Dashboard!$B$49 | N5: =Dashboard!$C$20+(Dashboard!$B$20-Dashboard!$C$20)*((9-7)/9)^Dashboard!$B$49 | O5: =Dashboard!$C$20+(Dashboard!$B$20-Dashboard!$C$20)*((9-8)/9)^Dashboard!$B$49 | P5: =Dashboard!$C$20+(Dashboard!$B$20-Dashboard!$C$20)*((9-9)/9)^Dashboard!$B$49
A6: Industrial Fabrication And Field Services | B6: =SUM(Financials!J22:M22) | C6: =SUM(Financials!N22:Q22) | D6: =SUM(Financials!R22:U22) | E6: =SUM(Financials!V22:Y22) | F6: =SUM(Financials!Z22:AC22) | G6: =F6*(1+G7) | H6: =G6*(1+H7) | I6: =H6*(1+I7) | J6: =I6*(1+J7) | K6: =J6*(1+K7) | L6: =K6*(1+L7) | M6: =L6*(1+M7) | N6: =M6*(1+N7) | ... P6: =O6*(1+P7)
A7: growth % (convex fade; curvature from Dashboard) | C7: =IFERROR(C6/B6-1,"") | D7: =IFERROR(D6/C6-1,"") | E7: =IFERROR(E6/D6-1,"") | F7: =IFERROR(F6/E6-1,"") | G7: =Dashboard!$C$21+(Dashboard!$B$21-Dashboard!$C$21)*((9-0)/9)^Dashboard!$B$49 | H7: =Dashboard!$C$21+(Dashboard!$B$21-Dashboard!$C$21)*((9-1)/9)^Dashboard!$B$49 | I7: =Dashboard!$C$21+(Dashboard!$B$21-Dashboard!$C$21)*((9-2)/9)^Dashboard!$B$49 | J7: =Dashboard!$C$21+(Dashboard!$B$21-Dashboard!$C$21)*((9-3)/9)^Dashboard!$B$49 | K7: =Dashboard!$C$21+(Dashboard!$B$21-Dashboard!$C$21)*((9-4)/9)^Dashboard!$B$49 | L7: =Dashboard!$C$21+(Dashboard!$B$21-Dashboard!$C$21)*((9-5)/9)^Dashboard!$B$49 | M7: =Dashboard!$C$21+(Dashboard!$B$21-Dashboard!$C$21)*((9-6)/9)^Dashboard!$B$49 | N7: =Dashboard!$C$21+(Dashboard!$B$21-Dashboard!$C$21)*((9-7)/9)^Dashboard!$B$49 | O7: =Dashboard!$C$21+(Dashboard!$B$21-Dashboard!$C$21)*((9-8)/9)^Dashboard!$B$49 | P7: =Dashboard!$C$21+(Dashboard!$B$21-Dashboard!$C$21)*((9-9)/9)^Dashboard!$B$49
A8: Total revenue | B8: =B4+B6 | C8: =C4+C6 | D8: =D4+D6 | E8: =E4+E6 | F8: =F4+F6 | G8: =G4+G6 | H8: =H4+H6 | I8: =I4+I6 | ... P8: =P4+P6
A9: growth % | C9: =IFERROR(C8/B8-1,"") | D9: =IFERROR(D8/C8-1,"") | E9: =IFERROR(E8/D8-1,"") | F9: =IFERROR(F8/E8-1,"") | G9: =IFERROR(G8/F8-1,"") | H9: =IFERROR(H8/G8-1,"") | I9: =IFERROR(I8/H8-1,"") | J9: =IFERROR(J8/I8-1,"") | ... P9: =IFERROR(P8/O8-1,"")
A11: COST STRUCTURE (yellow = % of revenue)
A12: Cost of revenue | B12: =SUM(Financials!J5:M5) | C12: =SUM(Financials!N5:Q5) | D12: =SUM(Financials!R5:U5) | E12: =SUM(Financials!V5:Y5) | F12: =SUM(Financials!Z5:AC5) | G12: =G8*G13 | H12: =H8*H13 | I12: =I8*I13 | J12: =J8*J13 | K12: =K8*K13 | L12: =L8*L13 | M12: =M8*M13 | N12: =N8*N13 | ... P12: =P8*P13
A13: % of revenue | B13: =IFERROR(B12/B8,"") | C13: =IFERROR(C12/C8,"") | D13: =IFERROR(D12/D8,"") | E13: =IFERROR(E12/E8,"") | F13: =IFERROR(F12/F8,"") | G13: 0.79496425 | H13: 0.79496425 | I13: 0.79496425 | J13: 0.79496425 | K13: 0.79496425 | L13: 0.79496425 | M13: 0.79496425 | N13: 0.79496425 | O13: 0.79496425 | P13: 0.79496425
A14: R&D / Technology | B14: =SUM(Financials!J7:M7) | C14: =SUM(Financials!N7:Q7) | D14: =SUM(Financials!R7:U7) | E14: =SUM(Financials!V7:Y7) | F14: =SUM(Financials!Z7:AC7) | G14: =G8*G15 | H14: =H8*H15 | I14: =I8*I15 | J14: =J8*J15 | K14: =K8*K15 | L14: =L8*L15 | M14: =M8*M15 | N14: =N8*N15 | ... P14: =P8*P15
A15: % of revenue | B15: =IFERROR(B14/B8,"") | C15: =IFERROR(C14/C8,"") | D15: =IFERROR(D14/D8,"") | E15: =IFERROR(E14/E8,"") | F15: =IFERROR(F14/F8,"") | G15: 0 | H15: 0 | I15: 0 | J15: 0 | K15: 0 | L15: 0 | M15: 0 | N15: 0 | O15: 0 | P15: 0
A16: SG&A | B16: =SUM(Financials!J9:M9) | C16: =SUM(Financials!N9:Q9) | D16: =SUM(Financials!R9:U9) | E16: =SUM(Financials!V9:Y9) | F16: =SUM(Financials!Z9:AC9) | G16: =G8*G17 | H16: =H8*H17 | I16: =I8*I17 | J16: =J8*J17 | K16: =K8*K17 | L16: =L8*L17 | M16: =M8*M17 | N16: =N8*N17 | ... P16: =P8*P17
A17: % of revenue | B17: =IFERROR(B16/B8,"") | C17: =IFERROR(C16/C8,"") | D17: =IFERROR(D16/D8,"") | E17: =IFERROR(E16/E8,"") | F17: =IFERROR(F16/F8,"") | G17: 0.062435555 | H17: 0.062435555 | I17: 0.062435555 | J17: 0.062435555 | K17: 0.062435555 | L17: 0.062435555 | M17: 0.062435555 | N17: 0.062435555 | O17: 0.062435555 | P17: 0.062435555
A18: Other opex (fulfilment, etc.) | B18: =B8-(B12+B14+B16)-SUM(Financials!J13:M13) | C18: =C8-(C12+C14+C16)-SUM(Financials!N13:Q13) | D18: =D8-(D12+D14+D16)-SUM(Financials!R13:U13) | E18: =E8-(E12+E14+E16)-SUM(Financials!V13:Y13) | F18: =F8-(F12+F14+F16)-SUM(Financials!Z13:AC13) | G18: =G8*(1-(Dashboard!$B$29+(Dashboard!$B$30-Dashboard!$B$29)*MIN(1,0/4)))-(G12+G14+G16) | H18: =H8*(1-(Dashboard!$B$29+(Dashboard!$B$30-Dashboard!$B$29)*MIN(1,1/4)))-(H12+H14+H16) | I18: =I8*(1-(Dashboard!$B$29+(Dashboard!$B$30-Dashboard!$B$29)*MIN(1,2/4)))-(I12+I14+I16) | J18: =J8*(1-(Dashboard!$B$29+(Dashboard!$B$30-Dashboard!$B$29)*MIN(1,3/4)))-(J12+J14+J16) | K18: =K8*(1-(Dashboard!$B$29+(Dashboard!$B$30-Dashboard!$B$29)*MIN(1,4/4)))-(K12+K14+K16) | L18: =L8*(1-(Dashboard!$B$29+(Dashboard!$B$30-Dashboard!$B$29)*MIN(1,5/4)))-(L12+L14+L16) | M18: =M8*(1-(Dashboard!$B$29+(Dashboard!$B$30-Dashboard!$B$29)*MIN(1,6/4)))-(M12+M14+M16) | N18: =N8*(1-(Dashboard!$B$29+(Dashboard!$B$30-Dashboard!$B$29)*MIN(1,7/4)))-(N12+N14+N16) | O18: =O8*(1-(Dashboard!$B$29+(Dashboard!$B$30-Dashboard!$B$29)*MIN(1,8/4)))-(O12+O14+O16) | P18: =P8*(1-(Dashboard!$B$29+(Dashboard!$B$30-Dashboard!$B$29)*MIN(1,9/4)))-(P12+P14+P16)
A19: % of revenue | B19: =IFERROR(B18/B8,"") | C19: =IFERROR(C18/C8,"") | D19: =IFERROR(D18/D8,"") | E19: =IFERROR(E18/E8,"") | F19: =IFERROR(F18/F8,"") | G19: =IFERROR(G18/G8,"") | H19: =IFERROR(H18/H8,"") | I19: =IFERROR(I18/I8,"") | ... P19: =IFERROR(P18/P8,"")
A21: Operating income (EBIT) | B21: =B8-(B12+B14+B16)-B18 | C21: =C8-(C12+C14+C16)-C18 | D21: =D8-(D12+D14+D16)-D18 | E21: =E8-(E12+E14+E16)-E18 | F21: =F8-(F12+F14+F16)-F18 | G21: =G8-(G12+G14+G16)-G18 | H21: =H8-(H12+H14+H16)-H18 | I21: =I8-(I12+I14+I16)-I18 | ... P21: =P8-(P12+P14+P16)-P18
A22: operating margin | B22: =IFERROR(B21/B8,"") | C22: =IFERROR(C21/C8,"") | D22: =IFERROR(D21/D8,"") | E22: =IFERROR(E21/E8,"") | F22: =IFERROR(F21/F8,"") | G22: =IFERROR(G21/G8,"") | H22: =IFERROR(H21/H8,"") | I22: =IFERROR(I21/I8,"") | ... P22: =IFERROR(P21/P8,"")
A24: FCF BRIDGE (NOPAT + D&A + SBC - dNWC - Capex)
A25: NOPAT = EBIT x (1 - tax) | B25: =B21*(1-Valuation!$B$5) | C25: =C21*(1-Valuation!$B$5) | D25: =D21*(1-Valuation!$B$5) | E25: =E21*(1-Valuation!$B$5) | F25: =F21*(1-Valuation!$B$5) | G25: =G21*(1-Valuation!$B$5) | H25: =H21*(1-Valuation!$B$5) | I25: =I21*(1-Valuation!$B$5) | ... P25: =P21*(1-Valuation!$B$5)
A26: + D&A | B26: =SUM(Financials!J44:M44) | C26: =SUM(Financials!N44:Q44) | D26: =SUM(Financials!R44:U44) | E26: =SUM(Financials!V44:Y44) | F26: =SUM(Financials!Z44:AC44) | G26: =G8*0.0020 | H26: =H8*0.0020 | I26: =I8*0.0020 | J26: =J8*0.0020 | K26: =K8*0.0020 | L26: =L8*0.0020 | M26: =M8*0.0020 | N26: =N8*0.0020 | ... P26: =P8*0.0020
A27: + SBC (non-cash) | B27: =SUM(Financials!J45:M45) | C27: =SUM(Financials!N45:Q45) | D27: =SUM(Financials!R45:U45) | E27: =SUM(Financials!V45:Y45) | F27: =SUM(Financials!Z45:AC45) | G27: =G8*(Dashboard!$B$65+(Dashboard!$B$66-Dashboard!$B$65)*0/9) | H27: =H8*(Dashboard!$B$65+(Dashboard!$B$66-Dashboard!$B$65)*1/9) | I27: =I8*(Dashboard!$B$65+(Dashboard!$B$66-Dashboard!$B$65)*2/9) | J27: =J8*(Dashboard!$B$65+(Dashboard!$B$66-Dashboard!$B$65)*3/9) | K27: =K8*(Dashboard!$B$65+(Dashboard!$B$66-Dashboard!$B$65)*4/9) | L27: =L8*(Dashboard!$B$65+(Dashboard!$B$66-Dashboard!$B$65)*5/9) | M27: =M8*(Dashboard!$B$65+(Dashboard!$B$66-Dashboard!$B$65)*6/9) | N27: =N8*(Dashboard!$B$65+(Dashboard!$B$66-Dashboard!$B$65)*7/9) | O27: =O8*(Dashboard!$B$65+(Dashboard!$B$66-Dashboard!$B$65)*8/9) | P27: =P8*(Dashboard!$B$65+(Dashboard!$B$66-Dashboard!$B$65)*9/9)
A28: - dNWC | G28: =(G8-F8)*0.0050 | H28: =(H8-G8)*0.0050 | I28: =(I8-H8)*0.0050 | J28: =(J8-I8)*0.0050 | K28: =(K8-J8)*0.0050 | L28: =(L8-K8)*0.0050 | M28: =(M8-L8)*0.0050 | N28: =(N8-M8)*0.0050 | ... P28: =(P8-O8)*0.0050
A29: - Capex | B29: =-SUM(Financials!J48:M48) | C29: =-SUM(Financials!N48:Q48) | D29: =-SUM(Financials!R48:U48) | E29: =-SUM(Financials!V48:Y48) | F29: =-SUM(Financials!Z48:AC48) | G29: =G26*G30 | H29: =H26*H30 | I29: =I26*I30 | J29: =J26*J30 | K29: =K26*K30 | L29: =L26*L30 | M29: =M26*M30 | N29: =N26*N30 | ... P29: =P26*P30
A30: Capex / D&A (from Dashboard: $cap'26 -> terminal) | B30: =IFERROR(B29/B26,"") | C30: =IFERROR(C29/C26,"") | D30: =IFERROR(D29/D26,"") | E30: =IFERROR(E29/E26,"") | F30: =IFERROR(F29/F26,"") | G30: =(Dashboard!$B$34/G26)+(Dashboard!$B$35-(Dashboard!$B$34/G26))*0/9 | H30: =(Dashboard!$B$34/G26)+(Dashboard!$B$35-(Dashboard!$B$34/G26))*1/9 | I30: =(Dashboard!$B$34/G26)+(Dashboard!$B$35-(Dashboard!$B$34/G26))*2/9 | J30: =(Dashboard!$B$34/G26)+(Dashboard!$B$35-(Dashboard!$B$34/G26))*3/9 | K30: =(Dashboard!$B$34/G26)+(Dashboard!$B$35-(Dashboard!$B$34/G26))*4/9 | L30: =(Dashboard!$B$34/G26)+(Dashboard!$B$35-(Dashboard!$B$34/G26))*5/9 | M30: =(Dashboard!$B$34/G26)+(Dashboard!$B$35-(Dashboard!$B$34/G26))*6/9 | N30: =(Dashboard!$B$34/G26)+(Dashboard!$B$35-(Dashboard!$B$34/G26))*7/9 | O30: =(Dashboard!$B$34/G26)+(Dashboard!$B$35-(Dashboard!$B$34/G26))*8/9 | P30: =(Dashboard!$B$34/G26)+(Dashboard!$B$35-(Dashboard!$B$34/G26))*9/9
A32: FCFF (firm) | B32: =B25+B26+B27-B28-B29 | C32: =C25+C26+C27-C28-C29 | D32: =D25+D26+D27-D28-D29 | E32: =E25+E26+E27-E28-E29 | F32: =F25+F26+F27-F28-F29 | G32: =G25+G26+G27-G28-G29 | H32: =H25+H26+H27-H28-H29 | I32: =I25+I26+I27-I28-I29 | ... P32: =P25+P26+P27-P28-P29
A33: Valuation FCF (NOPAT + D&A - dNWC - Capex - after-tax SBC) | B33: =B32-B27-B27*(1-Valuation!$B$5) | C33: =C32-C27-C27*(1-Valuation!$B$5) | D33: =D32-D27-D27*(1-Valuation!$B$5) | E33: =E32-E27-E27*(1-Valuation!$B$5) | F33: =F32-F27-F27*(1-Valuation!$B$5) | G33: =G32-G27-G27*(1-Valuation!$B$5) | H33: =H32-H27-H27*(1-Valuation!$B$5) | I33: =I32-I27-I27*(1-Valuation!$B$5) | ... P33: =P32-P27-P27*(1-Valuation!$B$5)
A35: RETURNS ON CAPITAL & EFFICIENCY (is new revenue/capital earning its keep?)
A36: Invested capital (debt + equity - cash) | B36: =Financials!M42+Financials!M41-Financials!M36 | C36: =Financials!Q42+Financials!Q41-Financials!Q36 | D36: =Financials!U42+Financials!U41-Financials!U36 | E36: =Financials!Y42+Financials!Y41-Financials!Y36 | F36: =Financials!AC42+Financials!AC41-Financials!AC36 | G36: =F36+G29-G26+G28 | H36: =G36+H29-H26+H28 | I36: =H36+I29-I26+I28 | J36: =I36+J29-J26+J28 | K36: =J36+K29-K26+K28 | L36: =K36+L29-L26+L28 | M36: =L36+M29-M26+M28 | N36: =M36+N29-N26+N28 | ... P36: =O36+P29-P26+P28
A37: Book equity (year-end) | B37: =Financials!M42 | C37: =Financials!Q42 | D37: =Financials!U42 | E37: =Financials!Y42 | F37: =Financials!AC42 | G37: =F37+G25 | H37: =G37+H25 | I37: =H37+I25 | J37: =I37+J25 | K37: =J37+K25 | L37: =K37+L25 | M37: =L37+M25 | N37: =M37+N25 | ... P37: =O37+P25
A38: ROIC (NOPAT / beg. invested capital) | C38: =IFERROR(C25/B36,"") | D38: =IFERROR(D25/C36,"") | E38: =IFERROR(E25/D36,"") | F38: =IFERROR(F25/E36,"") | G38: =IFERROR(G25/F36,"") | H38: =IFERROR(H25/G36,"") | I38: =IFERROR(I25/H36,"") | J38: =IFERROR(J25/I36,"") | ... P38: =IFERROR(P25/O36,"")
A39: ROE (earnings / beg. equity) | C39: =IFERROR(SUM(Financials!N15:Q15)/B37,"") | D39: =IFERROR(SUM(Financials!R15:U15)/C37,"") | E39: =IFERROR(SUM(Financials!V15:Y15)/D37,"") | F39: =IFERROR(SUM(Financials!Z15:AC15)/E37,"") | G39: =IFERROR(G25/F37,"") | H39: =IFERROR(H25/G37,"") | I39: =IFERROR(I25/H37,"") | J39: =IFERROR(J25/I37,"") | K39: =IFERROR(K25/J37,"") | L39: =IFERROR(L25/K37,"") | M39: =IFERROR(M25/L37,"") | N39: =IFERROR(N25/M37,"") | ... P39: =IFERROR(P25/O37,"")
A40: ROIC - WACC spread (value created) | C40: =IFERROR(C38-WACC!$B$15,"") | D40: =IFERROR(D38-WACC!$B$15,"") | E40: =IFERROR(E38-WACC!$B$15,"") | F40: =IFERROR(F38-WACC!$B$15,"") | G40: =IFERROR(G38-WACC!$B$15,"") | H40: =IFERROR(H38-WACC!$B$15,"") | I40: =IFERROR(I38-WACC!$B$15,"") | J40: =IFERROR(J38-WACC!$B$15,"") | ... P40: =IFERROR(P38-WACC!$B$15,"")
A41: Incremental op margin (ΔEBIT / ΔRev) | C41: =IFERROR((C21-B21)/(C8-B8),"") | D41: =IFERROR((D21-C21)/(D8-C8),"") | E41: =IFERROR((E21-D21)/(E8-D8),"") | F41: =IFERROR((F21-E21)/(F8-E8),"") | G41: =IFERROR((G21-F21)/(G8-F8),"") | H41: =IFERROR((H21-G21)/(H8-G8),"") | I41: =IFERROR((I21-H21)/(I8-H8),"") | J41: =IFERROR((J21-I21)/(J8-I8),"") | ... P41: =IFERROR((P21-O21)/(P8-O8),"")
A42: ROIIC (ΔNOPAT / ΔInvested capital) | C42: =IFERROR((C25-B25)/(C36-B36),"") | D42: =IFERROR((D25-C25)/(D36-C36),"") | E42: =IFERROR((E25-D25)/(E36-D36),"") | F42: =IFERROR((F25-E25)/(F36-E36),"") | G42: =IFERROR((G25-F25)/(G36-F36),"") | H42: =IFERROR((H25-G25)/(H36-G36),"") | I42: =IFERROR((I25-H25)/(I36-H36),"") | J42: =IFERROR((J25-I25)/(J36-I36),"") | ... P42: =IFERROR((P25-O25)/(P36-O36),"")
A43: Sales-to-capital (ΔRev / ΔInvested capital) | C43: =IFERROR((C8-B8)/(C36-B36),"") | D43: =IFERROR((D8-C8)/(D36-C36),"") | E43: =IFERROR((E8-D8)/(E36-D36),"") | F43: =IFERROR((F8-E8)/(F36-E36),"") | G43: =IFERROR((G8-F8)/(G36-F36),"") | H43: =IFERROR((H8-G8)/(H36-G36),"") | I43: =IFERROR((I8-H8)/(I36-H36),"") | J43: =IFERROR((J8-I8)/(J36-I36),"") | ... P43: =IFERROR((P8-O8)/(P36-O36),"")
A44: Reinvestment rate (ΔInvested capital / NOPAT) | C44: =IFERROR((C36-B36)/C25,"") | D44: =IFERROR((D36-C36)/D25,"") | E44: =IFERROR((E36-D36)/E25,"") | F44: =IFERROR((F36-E36)/F25,"") | G44: =IFERROR((G36-F36)/G25,"") | H44: =IFERROR((H36-G36)/H25,"") | I44: =IFERROR((I36-H36)/I25,"") | J44: =IFERROR((J36-I36)/J25,"") | ... P44: =IFERROR((P36-O36)/P25,"")
A46: Blue/green = actual · Yellow = assumption · Black = formula

Sheet Financials
A1: Line Item ($M) | B1: Q1 2020 | C1: Q2 2020 | D1: Q3 2020 | E1: Q4 2020 | F1: Q1 2021 | G1: Q2 2021 | H1: Q3 2021 | I1: Q4 2021 | J1: Q1 2022 | K1: Q2 2022 | L1: Q3 2022 | M1: Q4 2022 | N1: Q1 2023 | O1: Q2 2023 | P1: Q3 2023 | Q1: Q4 2023 | R1: Q1 2024 | S1: Q2 2024 | T1: Q3 2024 | U1: Q4 2024 | V1: Q1 2025 | W1: Q2 2025 | X1: Q3 2025 | Y1: Q4 2025 | Z1: Q1 2026 | AA1: Q2 2026 | AB1: Q3 2026 | AC1: Q4 2026
A2: INCOME STATEMENT
A3: Revenue | B3: 49.544 | C3: 63.059 | D3: 58.406 | E3: 67.988 | F3: 60.148 | G3: 87.492 | H3: 127.331 | I3: 117.235 | J3: 126.341 | K3: 133.008 | L3: 124.451 | M3: 125.57 | N3: 100.277 | O3: 118.11 | P3: 117.875 | Q3: 118.778 | R3: 103.675 | S3: 141.349 | T3: 163.755 | U3: 164.554 | V3: 157.682 | W3: 227.015 | X3: 257.008 | Y3: 232.474 | Z3: 193.66 | AA3: 237.743 | AB3: 251.153 | AC3: 262.05
A4: % YoY | F4: =IFERROR(F3/B3-1,"") | G4: =IFERROR(G3/C3-1,"") | H4: =IFERROR(H3/D3-1,"") | I4: =IFERROR(I3/E3-1,"") | J4: =IFERROR(J3/F3-1,"") | K4: =IFERROR(K3/G3-1,"") | L4: =IFERROR(L3/H3-1,"") | M4: =IFERROR(M3/I3-1,"") | ... AC4: =IFERROR(AC3/Y3-1,"")
A5: Cost of Revenue | B5: 70.57 | C5: 60.094 | D5: 52.414 | E5: 62.739 | F5: 56.139 | G5: 71.862 | H5: 106.988 | I5: 95.15 | J5: 102.627 | K5: 105.356 | L5: 98.316 | M5: 103.339 | N5: 80.539 | O5: 93.723 | P5: 95.667 | Q5: 98.75 | R5: 89.451 | S5: 117.607 | T5: 144.52 | U5: 141.41 | V5: 140.218 | W5: 195.91 | X5: 212.681 | Y5: 184.861 | Z5: 156.797 | AA5: 193.476 | AB5: 204.204 | AC5: 196.451
A6: % of revenue | B6: =IFERROR(B5/B3,"") | C6: =IFERROR(C5/C3,"") | D6: =IFERROR(D5/D3,"") | E6: =IFERROR(E5/E3,"") | F6: =IFERROR(F5/F3,"") | G6: =IFERROR(G5/G3,"") | H6: =IFERROR(H5/H3,"") | I6: =IFERROR(I5/I3,"") | ... AC6: =IFERROR(AC5/AC3,"")
A7: R&D Expense | B7: 0 | C7: 0 | D7: 0 | E7: 0 | F7: 0 | G7: 0 | H7: 0 | I7: 0 | J7: 0 | K7: 0 | L7: 0 | M7: 0 | N7: 0 | O7: 0 | P7: 0 | Q7: 0 | R7: 0 | S7: 0 | T7: 0 | U7: 0 | V7: 0 | W7: 0 | X7: 0 | Y7: 0 | Z7: 0 | AA7: 0 | AB7: 0 | AC7: 0
A8: % of revenue | B8: =IFERROR(B7/B3,"") | C8: =IFERROR(C7/C3,"") | D8: =IFERROR(D7/D3,"") | E8: =IFERROR(E7/E3,"") | F8: =IFERROR(F7/F3,"") | G8: =IFERROR(G7/G3,"") | H8: =IFERROR(H7/H3,"") | I8: =IFERROR(I7/I3,"") | ... AC8: =IFERROR(AC7/AC3,"")
A9: SG&A Expense | B9: 9.588 | C9: 10.038 | D9: 12.135 | E9: 12.364 | F9: 10.344 | G9: 9.085 | H9: 9.398 | I9: 10.214 | J9: 9.892 | K9: 10.331 | L9: 11.59 | M9: 15.508 | N9: 10.575 | O9: 10.984 | P9: 12.667 | Q9: 10.466 | R9: 10.591 | S9: 10.501 | T9: 11.375 | U9: 11.42 | V9: 10.945 | W9: 12.428 | X9: 13.995 | Y9: 14.946 | Z9: 12.521 | AA9: 14.212 | AB9: 14.316 | AC9: 17.928
A10: % of revenue | B10: =IFERROR(B9/B3,"") | C10: =IFERROR(C9/C3,"") | D10: =IFERROR(D9/D3,"") | E10: =IFERROR(E9/E3,"") | F10: =IFERROR(F9/F3,"") | G10: =IFERROR(G9/G3,"") | H10: =IFERROR(H9/H3,"") | I10: =IFERROR(I9/I3,"") | ... AC10: =IFERROR(AC9/AC3,"")
A11: Gross Profit | B11: -21.026 | C11: 2.965 | D11: 5.992 | E11: 5.249 | F11: 4.009 | G11: 15.63 | H11: 20.343 | I11: 22.085 | J11: 23.714 | K11: 27.652 | L11: 26.135 | M11: 22.231 | N11: 19.738 | O11: 24.387 | P11: 22.208 | Q11: 20.028 | R11: 14.224 | S11: 23.742 | T11: 19.235 | U11: 23.144 | V11: 17.464 | W11: 31.105 | X11: 44.327 | Y11: 47.613 | Z11: 36.863 | AA11: 44.267 | AB11: 46.949 | AC11: 65.599
A12: gross margin | B12: =IFERROR(B11/B3,"") | C12: =IFERROR(C11/C3,"") | D12: =IFERROR(D11/D3,"") | E12: =IFERROR(E11/E3,"") | F12: =IFERROR(F11/F3,"") | G12: =IFERROR(G11/G3,"") | H12: =IFERROR(H11/H3,"") | I12: =IFERROR(I11/I3,"") | ... AC12: =IFERROR(AC11/AC3,"")
A13: Operating Income | B13: -32.686 | C13: -7.073 | D13: -6.143 | E13: -9.938 | F13: -6.335 | G13: 6.545 | H13: 10.945 | I13: 11.871 | J13: 13.822 | K13: 17.321 | L13: 14.545 | M13: -1.178 | N13: 9.163 | O13: 13.403 | P13: 9.541 | Q13: 9.562 | R13: 3.633 | S13: 13.241 | T13: 7.86 | U13: 11.724 | V13: 6.519 | W13: 18.677 | X13: 30.332 | Y13: 32.667 | Z13: 24.342 | AA13: 30.055 | AB13: 32.633 | AC13: 47.671
A14: operating margin | B14: =IFERROR(B13/B3,"") | C14: =IFERROR(C13/C3,"") | D14: =IFERROR(D13/D3,"") | E14: =IFERROR(E13/E3,"") | F14: =IFERROR(F13/F3,"") | G14: =IFERROR(G13/G3,"") | H14: =IFERROR(H13/H3,"") | I14: =IFERROR(I13/I3,"") | ... AC14: =IFERROR(AC13/AC3,"")
A15: Net Income | B15: -29.8 | C15: 1.154 | D15: -6.855 | E15: -7.188 | F15: -0.763 | G15: 5.609 | H15: 9.454 | I15: 9.551 | J15: 10.766 | K15: 12.87 | L15: 12.393 | M15: 2.215 | N15: 7.485 | O15: 4.222 | P15: 7.758 | Q15: 13.633 | R15: 2.109 | S15: 12.767 | T15: 5.464 | U15: 12.018 | V15: 7.882 | W15: 18.198 | X15: 28.01 | Y15: 31.369 | Z15: 22.55 | AA15: 35.275 | AB15: 30.737 | AC15: 49.212
A16: net margin | B16: =IFERROR(B15/B3,"") | C16: =IFERROR(C15/C3,"") | D16: =IFERROR(D15/D3,"") | E16: =IFERROR(E15/E3,"") | F16: =IFERROR(F15/F3,"") | G16: =IFERROR(G15/G3,"") | H16: =IFERROR(H15/H3,"") | I16: =IFERROR(I15/I3,"") | ... AC16: =IFERROR(AC15/AC3,"")
A17: Diluted Shares (M) | B17: 15.583 | C17: 15.757 | D17: 15.633 | E17: 15.634 | F17: 15.643 | G17: 15.788 | H17: 15.833 | I17: 15.88 | J17: 15.961 | K17: 15.982 | L17: 15.963 | M17: 15.713 | N17: 14.992 | O17: 14.247 | P17: 13.812 | Q17: 13.625 | R17: 13.546 | S17: 13.542 | T17: 13.559 | U17: 13.548 | V17: 13.572 | W17: 13.88 | X17: 14.034 | Y17: 14.135 | Z17: 14.112 | AA17: 14.131 | AB17: 14.157 | AC17: 14.182
A18: REVENUE BY SEGMENT — PRODUCT (% YoY, % of revenue)
A19: Power Industry Services | B19: 20.203 | C19: 27.89 | D19: 35.848 | E19: 51.788 | F19: 48.612 | G19: 69.039 | H19: 109.712 | I19: 91.99 | J19: 97.172 | K19: 99.004 | L19: 99.56 | M19: 102.353 | N19: 73.949 | O19: 91.327 | P19: 90.682 | Q19: 90.075 | R19: 70.176 | S19: 105.345 | T19: 121.3 | U19: 119.46 | V19: 110.266 | W19: 173.76 | X19: 212.096 | Y19: 196.914 | Z19: 160.356 | AA19: 196.948 | AB19: 195.507 | AC19: 203.688
A20: % YoY | F20: =IFERROR(F19/B19-1,"") | G20: =IFERROR(G19/C19-1,"") | H20: =IFERROR(H19/D19-1,"") | I20: =IFERROR(I19/E19-1,"") | J20: =IFERROR(J19/F19-1,"") | K20: =IFERROR(K19/G19-1,"") | L20: =IFERROR(L19/H19-1,"") | M20: =IFERROR(M19/I19-1,"") | ... AC20: =IFERROR(AC19/Y19-1,"")
A21: % of revenue | B21: =IFERROR(B19/B3,"") | C21: =IFERROR(C19/C3,"") | D21: =IFERROR(D19/D3,"") | E21: =IFERROR(E19/E3,"") | F21: =IFERROR(F19/F3,"") | G21: =IFERROR(G19/G3,"") | H21: =IFERROR(H19/H3,"") | I21: =IFERROR(I19/I3,"") | ... AC21: =IFERROR(AC19/AC3,"")
A22: Industrial Fabrication And Field Services | B22: 27.069 | C22: 33.23 | D22: 20.143 | E22: 14.24 | F22: 9.744 | G22: 16.689 | H22: 15.73 | I22: 23.1 | J22: 26.658 | K22: 30.153 | L22: 21.402 | M22: 19.677 | N22: 22.501 | O22: 23.022 | P22: 22.137 | Q22: 25.114 | R22: 30.307 | S22: 32.756 | T22: 38.434 | U22: 41.304 | V22: 43.699 | W22: 49.642 | X22: 41.337 | Y22: 32.946 | Z22: 29.184 | AA22: 36.065 | AB22: 49.361 | AC22: 52.943
A23: % YoY | F23: =IFERROR(F22/B22-1,"") | G23: =IFERROR(G22/C22-1,"") | H23: =IFERROR(H22/D22-1,"") | I23: =IFERROR(I22/E22-1,"") | J23: =IFERROR(J22/F22-1,"") | K23: =IFERROR(K22/G22-1,"") | L23: =IFERROR(L22/H22-1,"") | M23: =IFERROR(M22/I22-1,"") | ... AC23: =IFERROR(AC22/Y22-1,"")
A24: % of revenue | B24: =IFERROR(B22/B3,"") | C24: =IFERROR(C22/C3,"") | D24: =IFERROR(D22/D3,"") | E24: =IFERROR(E22/E3,"") | F24: =IFERROR(F22/F3,"") | G24: =IFERROR(G22/G3,"") | H24: =IFERROR(H22/H3,"") | I24: =IFERROR(I22/I3,"") | ... AC24: =IFERROR(AC22/AC3,"")
A25: REVENUE BY SEGMENT — GEOGRAPHY (% YoY, % of revenue)
A26: U [S] | L26: 110.196 | M26: 300.392 | N26: 80.273 | O26: 93.949 | P26: 81.81 | Q26: 72.818 | R26: 65.244 | S26: 80.281 | T26: 92.066 | U26: 96.653 | V26: 124.331 | W26: 195.249 | X26: 239.489 | Y26: 224.038 | Z26: 181.106 | AA26: 214.195 | AB26: 222.637 | AC26: 234.274
A27: % YoY | F27: =IFERROR(F26/B26-1,"") | G27: =IFERROR(G26/C26-1,"") | H27: =IFERROR(H26/D26-1,"") | I27: =IFERROR(I26/E26-1,"") | J27: =IFERROR(J26/F26-1,"") | K27: =IFERROR(K26/G26-1,"") | L27: =IFERROR(L26/H26-1,"") | M27: =IFERROR(M26/I26-1,"") | ... AC27: =IFERROR(AC26/Y26-1,"")
A28: % of revenue | B28: =IFERROR(B26/B3,"") | C28: =IFERROR(C26/C3,"") | D28: =IFERROR(D26/D3,"") | E28: =IFERROR(E26/E3,"") | F28: =IFERROR(F26/F3,"") | G28: =IFERROR(G26/G3,"") | H28: =IFERROR(H26/H3,"") | I28: =IFERROR(I26/I3,"") | ... AC28: =IFERROR(AC26/AC3,"")
A29: I [E] | L29: 9.698 | M29: 12.655 | N29: 9.653 | O29: 15.532 | P29: 21.833 | Q29: 21.224 | R29: 24.856 | S29: 48.075 | T29: 68.359 | U29: 57.411 | V29: 28.891 | W29: 28.167 | X29: 16.981 | Y29: 7.317 | Z29: 9.888 | AA29: 17.244 | AB29: 19.303 | AC29: 18.574
A30: % YoY | F30: =IFERROR(F29/B29-1,"") | G30: =IFERROR(G29/C29-1,"") | H30: =IFERROR(H29/D29-1,"") | I30: =IFERROR(I29/E29-1,"") | J30: =IFERROR(J29/F29-1,"") | K30: =IFERROR(K29/G29-1,"") | L30: =IFERROR(L29/H29-1,"") | M30: =IFERROR(M29/I29-1,"") | ... AC30: =IFERROR(AC29/Y29-1,"")
A31: % of revenue | B31: =IFERROR(B29/B3,"") | C31: =IFERROR(C29/C3,"") | D31: =IFERROR(D29/D3,"") | E31: =IFERROR(E29/E3,"") | F31: =IFERROR(F29/F3,"") | G31: =IFERROR(G29/G3,"") | H31: =IFERROR(H29/H3,"") | I31: =IFERROR(I29/I3,"") | ... AC31: =IFERROR(AC29/AC3,"")
A32: G [B] | L32: 4.496 | N32: 10.351 | O32: 8.629 | P32: 14.232 | Q32: 24.736 | R32: 13.575 | S32: 12.993 | T32: 3.33 | U32: 10.49 | V32: 4.46 | W32: 3.599 | X32: 0.538 | Y32: 1.119 | Z32: 2.666 | AA32: 6.304 | AB32: 9.213 | AC32: 9.202
A33: % YoY | F33: =IFERROR(F32/B32-1,"") | G33: =IFERROR(G32/C32-1,"") | H33: =IFERROR(H32/D32-1,"") | I33: =IFERROR(I32/E32-1,"") | J33: =IFERROR(J32/F32-1,"") | K33: =IFERROR(K32/G32-1,"") | L33: =IFERROR(L32/H32-1,"") | M33: =IFERROR(M32/I32-1,"") | ... AC33: =IFERROR(AC32/Y32-1,"")
A34: % of revenue | B34: =IFERROR(B32/B3,"") | C34: =IFERROR(C32/C3,"") | D34: =IFERROR(D32/D3,"") | E34: =IFERROR(E32/E3,"") | F34: =IFERROR(F32/F3,"") | G34: =IFERROR(G32/G3,"") | H34: =IFERROR(H32/H3,"") | I34: =IFERROR(I32/I3,"") | ... AC34: =IFERROR(AC32/AC3,"")
A35: BALANCE SHEET
A36: Cash & ST Investments | B36: 255.764 | C36: 233.624 | D36: 294.589 | E36: 327.862 | F36: 363.544 | G36: 407.628 | H36: 443.23 | I36: 456.726 | J36: 466.75 | K36: 491.48 | L36: 481.564 | M36: 440.498 | N36: 367.484 | O36: 318.987 | P36: 286.631 | Q36: 325.458 | R36: 316.937 | S36: 346.415 | T36: 397.515 | U36: 412.405 | V36: 416.356 | W36: 484.682 | X36: 506.282 | Y36: 525.137 | Z36: 546.457 | AA36: 572.19 | AB36: 726.821 | AC36: 894.981
A37: Total Current Assets | B37: 373.161 | C37: 353.137 | D37: 405.9 | E37: 421.755 | F37: 455.736 | G37: 503.456 | H37: 538.82 | I37: 546.22 | J37: 559.031 | K37: 597.656 | L37: 559.719 | M37: 507.284 | N37: 447.591 | O37: 378.193 | P37: 364.965 | Q37: 438.702 | R37: 425.001 | S37: 455.132 | T37: 514.071 | U37: 547.179 | V37: 574.326 | W37: 674.954 | X37: 717.141 | Y37: 781.3 | Z37: 738.077 | AA37: 828.784 | AB37: 997.171 | AC37: 1132.257
A38: PP&E (net) | B38: 22.036 | C38: 21.946 | D38: 24.549 | E38: 24.947 | F38: 24.509 | G38: 25.158 | H38: 24.413 | I38: 24.121 | J38: 27.129 | K38: 22.746 | L38: 22.074 | M38: 14.489 | N38: 14.011 | O38: 13.903 | P38: 15.175 | Q38: 16.454 | R38: 16.543 | S38: 16.22 | T38: 16.101 | U38: 18.541 | V38: 17.624 | W38: 19.928 | X38: 20.512 | Y38: 24.516 | Z38: 24.317 | AA38: 24.257 | AB38: 21.633 | AC38: 24.614
A39: Total Assets | B39: 433.161 | C39: 419.724 | D39: 472.717 | E39: 487.54 | F39: 512.964 | G39: 561.107 | H39: 595.5 | I39: 602.63 | J39: 617.972 | K39: 651.989 | L39: 613.153 | M39: 553.585 | N39: 492.81 | O39: 423.07 | P39: 410.903 | Q39: 489.487 | R39: 475.694 | S39: 505.708 | T39: 563.652 | U39: 598.229 | V39: 624.408 | W39: 726.574 | X39: 768.864 | Y39: 836.227 | Z39: 792.155 | AA39: 882.704 | AB39: 1050.869 | AC39: 1186.354
A40: Total Current Liabilities | B40: 71.026 | C40: 58.714 | D40: 118.957 | E40: 144.034 | F40: 173.106 | G40: 233.435 | H40: 261.03 | I40: 276.087 | J40: 283.065 | K40: 307.347 | L40: 259.045 | M40: 223.027 | N40: 186.274 | O40: 142.012 | P40: 134.542 | Q40: 202.503 | R40: 192.397 | S40: 215.606 | T40: 273.894 | U40: 302.26 | V40: 327.598 | W40: 415.127 | X40: 436.164 | Y40: 479.857 | Z40: 422.95 | AA40: 484.322 | AB40: 619.86 | AC40: 706.495
...

Sheet Consensus
A1: Full consensus check — model vs Street (FMP estimates, $M)
A2: Fiscal year | B2: 2027 | C2: 2028 | D2: 2029 | E2: 2030 | F2: 2031
A3: EVERY AVAILABLE FMP CONSENSUS FIELD (consensus / model / % diff)
A4: Revenue — consensus | B4: 1251.8062 | C4: 1513.3922 | D4: 1653.0348 | E4: 1791 | F4: 1882
A5: model | B5: =Model!G8 | C5: =Model!H8 | D5: =Model!I8 | E5: =Model!J8 | F5: =Model!K8
A6: vs consensus | B6: =IFERROR(B5/B4-1,"") | C6: =IFERROR(C5/C4-1,"") | D6: =IFERROR(D5/D4-1,"") | E6: =IFERROR(E5/E4-1,"") | F6: =IFERROR(F5/F4-1,"")
A8: EBITDA* — consensus | B8: 132.97148 | C8: 160.75811 | D8: 175.59146 | E8: 190.24664 | F8: 199.913
A9: model | B9: =Model!G21+Model!G26 | C9: =Model!H21+Model!H26 | D9: =Model!I21+Model!I26 | E9: =Model!J21+Model!J26 | F9: =Model!K21+Model!K26
A10: vs consensus | B10: =IFERROR(B9/B8-1,"") | C10: =IFERROR(C9/C8-1,"") | D10: =IFERROR(D9/D8-1,"") | E10: =IFERROR(E9/E8-1,"") | F10: =IFERROR(F9/F8-1,"")
A12: EBIT* — consensus | B12: 125.56734 | C12: 151.80675 | D12: 165.81415 | E12: 179.6533 | F12: 188.78141
A13: model | B13: =Model!G21 | C13: =Model!H21 | D13: =Model!I21 | E13: =Model!J21 | F13: =Model!K21
A14: vs consensus | B14: =IFERROR(B13/B12-1,"") | C14: =IFERROR(C13/C12-1,"") | D14: =IFERROR(D13/D12-1,"") | E14: =IFERROR(E13/E12-1,"") | F14: =IFERROR(F13/F12-1,"")
A16: SG&A — consensus | B16: 97.977579 | C16: 118.45165 | D16: 129.38132 | E16: 140.17972 | F16: 147.3022
A17: model | B17: =Model!G16 | C17: =Model!H16 | D17: =Model!I16 | E17: =Model!J16 | F17: =Model!K16
A18: vs consensus | B18: =IFERROR(B17/B16-1,"") | C18: =IFERROR(C17/C16-1,"") | D18: =IFERROR(D17/D16-1,"") | E18: =IFERROR(E17/E16-1,"") | F18: =IFERROR(F17/F16-1,"")
A20: Net income (NOPAT) — consensus | B20: 149.17072 | C20: 195.7693 | D20: 224.50275 | E20: 192.73339 | F20: 201.95169
A21: model | B21: =Model!G25 | C21: =Model!H25 | D21: =Model!I25 | E21: =Model!J25 | F21: =Model!K25
A22: vs consensus | B22: =IFERROR(B21/B20-1,"") | C22: =IFERROR(C21/C20-1,"") | D22: =IFERROR(D21/D20-1,"") | E22: =IFERROR(E21/E20-1,"") | F22: =IFERROR(F21/F20-1,"")
A24: EPS — consensus | B24: 11.036 | C24: 14.376 | D24: 16.6375 | E24: 13.59 | F24: 14.24
A25: model | B25: =Model!G25/Financials!AC17 | C25: =Model!H25/Financials!AC17 | D25: =Model!I25/Financials!AC17 | E25: =Model!J25/Financials!AC17 | F25: =Model!K25/Financials!AC17
A26: vs consensus | B26: =IFERROR(B25/B24-1,"") | C26: =IFERROR(C25/C24-1,"") | D26: =IFERROR(D25/D24-1,"") | E26: =IFERROR(E25/E24-1,"") | F26: =IFERROR(F25/F24-1,"")
A28: Defaults anchored to consensus revenue + net income (≈0% diff). Other rows show where the model sits vs Street.
A29: *FMP's EBITDA/EBIT estimates look unreliable for AMZN (it reports NI > EBIT) — don't over-read those two.

Sheet Valuation
A1: Argan, Inc. — DCF Valuation
A2: Current price | B2: =Dashboard!$B$48
A3: WACC | B3: =WACC!B15
A4: Terminal growth (g) | B4: =Dashboard!$B$46
A5: Tax rate | B5: =Dashboard!$B$31
A6: Terminal method | B6: =Dashboard!$B$43
A7: Exit basis | B7: =Dashboard!$B$44
A8: Exit multiple | B8: =Dashboard!$B$45
A11: Forecast year | C11: 2027 | D11: 2028 | E11: 2029 | F11: 2030 | G11: 2031 | H11: 2032 | I11: 2033 | J11: 2034 | K11: 2035 | L11: 2036
A12: FCFF ($M) | C12: =Model!G33 | D12: =Model!H33 | E12: =Model!I33 | F12: =Model!J33 | G12: =Model!K33 | H12: =Model!L33 | I12: =Model!M33 | J12: =Model!N33 | ... L12: =Model!P33
A13: PV factor | C13: =1/(1+$B$3)^1 | D13: =1/(1+$B$3)^2 | E13: =1/(1+$B$3)^3 | F13: =1/(1+$B$3)^4 | G13: =1/(1+$B$3)^5 | H13: =1/(1+$B$3)^6 | I13: =1/(1+$B$3)^7 | J13: =1/(1+$B$3)^8 | K13: =1/(1+$B$3)^9 | L13: =1/(1+$B$3)^10
A14: PV of FCFF ($M) | C14: =C12*C13 | D14: =D12*D13 | E14: =E12*E13 | F14: =F12*F13 | G14: =G12*G13 | H14: =H12*H13 | I14: =I12*I13 | J14: =J12*J13 | ... L14: =L12*L13
A16: Sum PV of FCFF | B16: =SUM(C14:L14)
A18: TERMINAL VALUE (exit multiple = default; perpetuity = cross-check)
A19: Terminal-year FCFF | B19: =L12
A20: Terminal revenue | B20: =Model!P8
A21: Terminal EBIT | B21: =Model!P21
A22: Terminal EBITDA (SBC-burdened) | B22: =Model!P21+Model!P26-Model!P27
A23: Terminal metric (per exit basis) | B23: =IF($B$7="EV/EBITDA",B22,IF($B$7="EV/Sales",B20,IF($B$7="EV/EBIT",B21,B19)))
A24: TV (exit) = metric x multiple | B24: =B23*$B$8
A25: PV of TV — exit multiple | B25: =B24/(1+$B$3)^10
A26: TV (perpetuity) = FCFF(1+g)/(WACC-g) | B26: =B19*(1+$B$4)/($B$3-$B$4)
A27: PV of TV — perpetuity | B27: =B26/(1+$B$3)^10
A28: PV of TV — SELECTED | B28: =IF($B$6="Perpetuity",B27,B25)
A30: EQUITY BRIDGE -> VALUE / SHARE
A31: Operating value (enterprise value) | B31: =B16+B28
A32: + Cash & ST investments | B32: =Financials!AC36
A33: - Long-term debt | B33: =-Financials!AC41
A34: Equity value | B34: =B31+B32+B33
A35: Diluted shares (M) | B35: =Financials!AC17
A36: VALUE / SHARE | B36: =B34/B35*1.0
A38: CROSS-CHECKS & RETURN
A39: Terminal weight (% of EV) | B39: =B28/B31
A40: Implied perpetuity g (from exit multiple) | B40: =(B24*$B$3-B19)/(B24+B19)
A41: Implied exit EV/EBITDA (from perpetuity) | B41: =B26/B22
A42: Upside / (downside) to fair value | B42: =B36/$B$2-1
A44: Owner cashflow / share | B44: =-$B$2 | C44: =C12/B35 | D44: =D12/B35 | E44: =E12/B35 | F44: =F12/B35 | G44: =G12/B35 | H44: =H12/B35 | I44: =I12/B35 | J44: =J12/B35 | K44: =K12/B35 | L44: =L12/B35+B36
A45: IRR (buy at price, hold 10y) | B45: =IRR(B44:L44)

Sheet Sensitivity
A1: Sensitivity — fair value / share (USD)
A2: WACC x exit multiple (EV/EBITDA). Static grid recomputed by every rebuild/refresh — edit the Dashboard, re-run refresh_dcf to update. Shaded = base case; green = above current price.
A4: EV/EBITDA x \ WACC | B4: 0.05338 | C4: 0.05838 | D4: 0.06338 | E4: 0.06838 | F4: 0.07338 | G4: 0.07838 | H4: 0.08338
A5: 9 | B5: 288.09765 | C5: 279.54541 | D5: 271.39302 | E5: 263.61945 | F5: 256.20485 | G5: 249.13054 | H5: 242.37889
A6: 10 | B6: 302.44444 | C6: 293.22865 | D6: 284.44632 | E6: 276.07456 | F6: 268.09179 | G6: 260.47769 | H6: 253.2131
A7: 11 | B7: 316.79122 | C7: 306.91189 | D7: 297.49962 | E7: 288.52967 | F7: 279.97874 | G7: 271.82485 | H7: 264.0473
A8: 12 | B8: 331.138 | C8: 320.59513 | D8: 310.55292 | E8: 300.98479 | F8: 291.86568 | G8: 283.172 | H8: 274.88151
A9: 13 | B9: 345.48478 | C9: 334.27837 | D9: 323.60622 | E9: 313.4399 | F9: 303.75262 | G9: 294.51916 | H9: 285.71572
A10: 14 | B10: 359.83157 | C10: 347.96161 | D10: 336.65953 | E10: 325.89502 | F10: 315.63957 | G10: 305.86631 | H10: 296.54992
A11: 15 | B11: 374.17835 | C11: 361.64486 | D11: 349.71283 | E11: 338.35013 | F11: 327.52651 | G11: 317.21346 | H11: 307.38413
A13: Current price | B13: 706.15002
A14: Base WACC / multiple | B14: 0.06838 | C14: 12

Sheet Monte Carlo
A1: Monte Carlo simulation (live) | H1: SIMULATION ENGINE — leave as-is | K1: cagr | L1: term margin | M1: wacc | N1: exit | O1: value/share
A2: 1,000 trials, recomputed in-sheet on every edit. Edit the yellow driver distributions to re-roll. Engine grid is to the right (cols H+). | H2: R0 (base revenue) | I2: =Model!F8 | K2: =MAX(-0.05,NORMINV(RAND(),$C$6,$D$6)) | L2: =MAX(0.02,NORMINV(RAND(),$C$7,$D$7)) | M2: =MIN(0.16,MAX(0.05,NORMINV(RAND(),$C$8,$D$8))) | N2: =MIN(24,MAX(5,NORMINV(RAND(),$C$9,$D$9))) | O2: =$I$8*(SUMPRODUCT(($I$2*(1+K2)^{1;2;3;4;5;6;7;8;9;10})*(($I$3+(L2-$I$3)*{1;2;3;4;5;6;7;8;9;10}/10)*(1-$I$7)+$I$4-$I$4*($I$5+(1.05-$I$5)*{1;2;3;4;5;6;7;8;9;10}/10)-(K2/(1+K2))*$I$6)/(1+M2)^{1;2;3;4;5;6;7;8;9;10})+$I$2*(1+K2)^10*(L2+$I$4)*N2/(1+M2)^10+$I$9-$I$10)/$I$11
H3: m0 (base op margin) | I3: =Model!F22 | K3: =MAX(-0.05,NORMINV(RAND(),$C$6,$D$6)) | L3: =MAX(0.02,NORMINV(RAND(),$C$7,$D$7)) | M3: =MIN(0.16,MAX(0.05,NORMINV(RAND(),$C$8,$D$8))) | N3: =MIN(24,MAX(5,NORMINV(RAND(),$C$9,$D$9))) | O3: =$I$8*(SUMPRODUCT(($I$2*(1+K3)^{1;2;3;4;5;6;7;8;9;10})*(($I$3+(L3-$I$3)*{1;2;3;4;5;6;7;8;9;10}/10)*(1-$I$7)+$I$4-$I$4*($I$5+(1.05-$I$5)*{1;2;3;4;5;6;7;8;9;10}/10)-(K3/(1+K3))*$I$6)/(1+M3)^{1;2;3;4;5;6;7;8;9;10})+$I$2*(1+K3)^10*(L3+$I$4)*N3/(1+M3)^10+$I$9-$I$10)/$I$11
A4: DRIVER DISTRIBUTIONS (yellow = edit; Opus-set defaults) | H4: da (D&A / revenue) | I4: 0.0020241243 | K4: =MAX(-0.05,NORMINV(RAND(),$C$6,$D$6)) | L4: =MAX(0.02,NORMINV(RAND(),$C$7,$D$7)) | M4: =MIN(0.16,MAX(0.05,NORMINV(RAND(),$C$8,$D$8))) | N4: =MIN(24,MAX(5,NORMINV(RAND(),$C$9,$D$9))) | O4: =$I$8*(SUMPRODUCT(($I$2*(1+K4)^{1;2;3;4;5;6;7;8;9;10})*(($I$3+(L4-$I$3)*{1;2;3;4;5;6;7;8;9;10}/10)*(1-$I$7)+$I$4-$I$4*($I$5+(1.05-$I$5)*{1;2;3;4;5;6;7;8;9;10}/10)-(K4/(1+K4))*$I$6)/(1+M4)^{1;2;3;4;5;6;7;8;9;10})+$I$2*(1+K4)^10*(L4+$I$4)*N4/(1+M4)^10+$I$9-$I$10)/$I$11
A5: Driver | B5: Dist | C5: Mean | D5: Std dev | H5: cda0 (2026 capex/D&A) | I5: 1.6831166 | K5: =MAX(-0.05,NORMINV(RAND(),$C$6,$D$6)) | L5: =MAX(0.02,NORMINV(RAND(),$C$7,$D$7)) | M5: =MIN(0.16,MAX(0.05,NORMINV(RAND(),$C$8,$D$8))) | N5: =MIN(24,MAX(5,NORMINV(RAND(),$C$9,$D$9))) | O5: =$I$8*(SUMPRODUCT(($I$2*(1+K5)^{1;2;3;4;5;6;7;8;9;10})*(($I$3+(L5-$I$3)*{1;2;3;4;5;6;7;8;9;10}/10)*(1-$I$7)+$I$4-$I$4*($I$5+(1.05-$I$5)*{1;2;3;4;5;6;7;8;9;10}/10)-(K5/(1+K5))*$I$6)/(1+M5)^{1;2;3;4;5;6;7;8;9;10})+$I$2*(1+K5)^10*(L5+$I$4)*N5/(1+M5)^10+$I$9-$I$10)/$I$11
A6: Revenue 10y CAGR | B6: Normal | C6: =(Model!P8/Model!F8)^(1/10)-1 | D6: 0.03 | H6: nwc (% incr revenue) | I6: 0.005 | K6: =MAX(-0.05,NORMINV(RAND(),$C$6,$D$6)) | L6: =MAX(0.02,NORMINV(RAND(),$C$7,$D$7)) | M6: =MIN(0.16,MAX(0.05,NORMINV(RAND(),$C$8,$D$8))) | N6: =MIN(24,MAX(5,NORMINV(RAND(),$C$9,$D$9))) | O6: =$I$8*(SUMPRODUCT(($I$2*(1+K6)^{1;2;3;4;5;6;7;8;9;10})*(($I$3+(L6-$I$3)*{1;2;3;4;5;6;7;8;9;10}/10)*(1-$I$7)+$I$4-$I$4*($I$5+(1.05-$I$5)*{1;2;3;4;5;6;7;8;9;10}/10)-(K6/(1+K6))*$I$6)/(1+M6)^{1;2;3;4;5;6;7;8;9;10})+$I$2*(1+K6)^10*(L6+$I$4)*N6/(1+M6)^10+$I$9-$I$10)/$I$11
A7: Terminal operating margin | B7: Normal | C7: =Dashboard!$B$30 | D7: 0.025816675 | H7: tax | I7: =Valuation!$B$5 | K7: =MAX(-0.05,NORMINV(RAND(),$C$6,$D$6)) | L7: =MAX(0.02,NORMINV(RAND(),$C$7,$D$7)) | M7: =MIN(0.16,MAX(0.05,NORMINV(RAND(),$C$8,$D$8))) | N7: =MIN(24,MAX(5,NORMINV(RAND(),$C$9,$D$9))) | O7: =$I$8*(SUMPRODUCT(($I$2*(1+K7)^{1;2;3;4;5;6;7;8;9;10})*(($I$3+(L7-$I$3)*{1;2;3;4;5;6;7;8;9;10}/10)*(1-$I$7)+$I$4-$I$4*($I$5+(1.05-$I$5)*{1;2;3;4;5;6;7;8;9;10}/10)-(K7/(1+K7))*$I$6)/(1+M7)^{1;2;3;4;5;6;7;8;9;10})+$I$2*(1+K7)^10*(L7+$I$4)*N7/(1+M7)^10+$I$9-$I$10)/$I$11
A8: WACC | B8: Normal | C8: =WACC!B15 | D8: 0.005 | H8: k (calibration) | I8: 0.9968457 | K8: =MAX(-0.05,NORMINV(RAND(),$C$6,$D$6)) | L8: =MAX(0.02,NORMINV(RAND(),$C$7,$D$7)) | M8: =MIN(0.16,MAX(0.05,NORMINV(RAND(),$C$8,$D$8))) | N8: =MIN(24,MAX(5,NORMINV(RAND(),$C$9,$D$9))) | O8: =$I$8*(SUMPRODUCT(($I$2*(1+K8)^{1;2;3;4;5;6;7;8;9;10})*(($I$3+(L8-$I$3)*{1;2;3;4;5;6;7;8;9;10}/10)*(1-$I$7)+$I$4-$I$4*($I$5+(1.05-$I$5)*{1;2;3;4;5;6;7;8;9;10}/10)-(K8/(1+K8))*$I$6)/(1+M8)^{1;2;3;4;5;6;7;8;9;10})+$I$2*(1+K8)^10*(L8+$I$4)*N8/(1+M8)^10+$I$9-$I$10)/$I$11
A9: Exit EV/EBITDA multiple | B9: Normal | C9: =Dashboard!$B$45 | D9: 1.5 | H9: cash | I9: =Financials!AC36 | K9: =MAX(-0.05,NORMINV(RAND(),$C$6,$D$6)) | L9: =MAX(0.02,NORMINV(RAND(),$C$7,$D$7)) | M9: =MIN(0.16,MAX(0.05,NORMINV(RAND(),$C$8,$D$8))) | N9: =MIN(24,MAX(5,NORMINV(RAND(),$C$9,$D$9))) | O9: =$I$8*(SUMPRODUCT(($I$2*(1+K9)^{1;2;3;4;5;6;7;8;9;10})*(($I$3+(L9-$I$3)*{1;2;3;4;5;6;7;8;9;10}/10)*(1-$I$7)+$I$4-$I$4*($I$5+(1.05-$I$5)*{1;2;3;4;5;6;7;8;9;10}/10)-(K9/(1+K9))*$I$6)/(1+M9)^{1;2;3;4;5;6;7;8;9;10})+$I$2*(1+K9)^10*(L9+$I$4)*N9/(1+M9)^10+$I$9-$I$10)/$I$11
H10: debt | I10: =Financials!AC41 | K10: =MAX(-0.05,NORMINV(RAND(),$C$6,$D$6)) | L10: =MAX(0.02,NORMINV(RAND(),$C$7,$D$7)) | M10: =MIN(0.16,MAX(0.05,NORMINV(RAND(),$C$8,$D$8))) | N10: =MIN(24,MAX(5,NORMINV(RAND(),$C$9,$D$9))) | O10: =$I$8*(SUMPRODUCT(($I$2*(1+K10)^{1;2;3;4;5;6;7;8;9;10})*(($I$3+(L10-$I$3)*{1;2;3;4;5;6;7;8;9;10}/10)*(1-$I$7)+$I$4-$I$4*($I$5+(1.05-$I$5)*{1;2;3;4;5;6;7;8;9;10}/10)-(K10/(1+K10))*$I$6)/(1+M10)^{1;2;3;4;5;6;7;8;9;10})+$I$2*(1+K10)^10*(L10+$I$4)*N10/(1+M10)^10+$I$9-$I$10)/$I$11
A11: SIMULATION OUTPUT — value / share (live) | H11: shares | I11: =Financials!AC17 | K11: =MAX(-0.05,NORMINV(RAND(),$C$6,$D$6)) | L11: =MAX(0.02,NORMINV(RAND(),$C$7,$D$7)) | M11: =MIN(0.16,MAX(0.05,NORMINV(RAND(),$C$8,$D$8))) | N11: =MIN(24,MAX(5,NORMINV(RAND(),$C$9,$D$9))) | O11: =$I$8*(SUMPRODUCT(($I$2*(1+K11)^{1;2;3;4;5;6;7;8;9;10})*(($I$3+(L11-$I$3)*{1;2;3;4;5;6;7;8;9;10}/10)*(1-$I$7)+$I$4-$I$4*($I$5+(1.05-$I$5)*{1;2;3;4;5;6;7;8;9;10}/10)-(K11/(1+K11))*$I$6)/(1+M11)^{1;2;3;4;5;6;7;8;9;10})+$I$2*(1+K11)^10*(L11+$I$4)*N11/(1+M11)^10+$I$9-$I$10)/$I$11
A12: Mean | B12: =AVERAGE($O$2:$O$1001) | K12: =MAX(-0.05,NORMINV(RAND(),$C$6,$D$6)) | L12: =MAX(0.02,NORMINV(RAND(),$C$7,$D$7)) | M12: =MIN(0.16,MAX(0.05,NORMINV(RAND(),$C$8,$D$8))) | N12: =MIN(24,MAX(5,NORMINV(RAND(),$C$9,$D$9))) | O12: =$I$8*(SUMPRODUCT(($I$2*(1+K12)^{1;2;3;4;5;6;7;8;9;10})*(($I$3+(L12-$I$3)*{1;2;3;4;5;6;7;8;9;10}/10)*(1-$I$7)+$I$4-$I$4*($I$5+(1.05-$I$5)*{1;2;3;4;5;6;7;8;9;10}/10)-(K12/(1+K12))*$I$6)/(1+M12)^{1;2;3;4;5;6;7;8;9;10})+$I$2*(1+K12)^10*(L12+$I$4)*N12/(1+M12)^10+$I$9-$I$10)/$I$11
A13: Median (P50) | B13: =MEDIAN($O$2:$O$1001) | K13: =MAX(-0.05,NORMINV(RAND(),$C$6,$D$6)) | L13: =MAX(0.02,NORMINV(RAND(),$C$7,$D$7)) | M13: =MIN(0.16,MAX(0.05,NORMINV(RAND(),$C$8,$D$8))) | N13: =MIN(24,MAX(5,NORMINV(RAND(),$C$9,$D$9))) | O13: =$I$8*(SUMPRODUCT(($I$2*(1+K13)^{1;2;3;4;5;6;7;8;9;10})*(($I$3+(L13-$I$3)*{1;2;3;4;5;6;7;8;9;10}/10)*(1-$I$7)+$I$4-$I$4*($I$5+(1.05-$I$5)*{1;2;3;4;5;6;7;8;9;10}/10)-(K13/(1+K13))*$I$6)/(1+M13)^{1;2;3;4;5;6;7;8;9;10})+$I$2*(1+K13)^10*(L13+$I$4)*N13/(1+M13)^10+$I$9-$I$10)/$I$11
A14: Std dev | B14: =STDEV($O$2:$O$1001) | K14: =MAX(-0.05,NORMINV(RAND(),$C$6,$D$6)) | L14: =MAX(0.02,NORMINV(RAND(),$C$7,$D$7)) | M14: =MIN(0.16,MAX(0.05,NORMINV(RAND(),$C$8,$D$8))) | N14: =MIN(24,MAX(5,NORMINV(RAND(),$C$9,$D$9))) | O14: =$I$8*(SUMPRODUCT(($I$2*(1+K14)^{1;2;3;4;5;6;7;8;9;10})*(($I$3+(L14-$I$3)*{1;2;3;4;5;6;7;8;9;10}/10)*(1-$I$7)+$I$4-$I$4*($I$5+(1.05-$I$5)*{1;2;3;4;5;6;7;8;9;10}/10)-(K14/(1+K14))*$I$6)/(1+M14)^{1;2;3;4;5;6;7;8;9;10})+$I$2*(1+K14)^10*(L14+$I$4)*N14/(1+M14)^10+$I$9-$I$10)/$I$11
A15: Min | B15: =MIN($O$2:$O$1001) | K15: =MAX(-0.05,NORMINV(RAND(),$C$6,$D$6)) | L15: =MAX(0.02,NORMINV(RAND(),$C$7,$D$7)) | M15: =MIN(0.16,MAX(0.05,NORMINV(RAND(),$C$8,$D$8))) | N15: =MIN(24,MAX(5,NORMINV(RAND(),$C$9,$D$9))) | O15: =$I$8*(SUMPRODUCT(($I$2*(1+K15)^{1;2;3;4;5;6;7;8;9;10})*(($I$3+(L15-$I$3)*{1;2;3;4;5;6;7;8;9;10}/10)*(1-$I$7)+$I$4-$I$4*($I$5+(1.05-$I$5)*{1;2;3;4;5;6;7;8;9;10}/10)-(K15/(1+K15))*$I$6)/(1+M15)^{1;2;3;4;5;6;7;8;9;10})+$I$2*(1+K15)^10*(L15+$I$4)*N15/(1+M15)^10+$I$9-$I$10)/$I$11
A16: Max | B16: =MAX($O$2:$O$1001) | K16: =MAX(-0.05,NORMINV(RAND(),$C$6,$D$6)) | L16: =MAX(0.02,NORMINV(RAND(),$C$7,$D$7)) | M16: =MIN(0.16,MAX(0.05,NORMINV(RAND(),$C$8,$D$8))) | N16: =MIN(24,MAX(5,NORMINV(RAND(),$C$9,$D$9))) | O16: =$I$8*(SUMPRODUCT(($I$2*(1+K16)^{1;2;3;4;5;6;7;8;9;10})*(($I$3+(L16-$I$3)*{1;2;3;4;5;6;7;8;9;10}/10)*(1-$I$7)+$I$4-$I$4*($I$5+(1.05-$I$5)*{1;2;3;4;5;6;7;8;9;10}/10)-(K16/(1+K16))*$I$6)/(1+M16)^{1;2;3;4;5;6;7;8;9;10})+$I$2*(1+K16)^10*(L16+$I$4)*N16/(1+M16)^10+$I$9-$I$10)/$I$11
A17: Current price | B17: =Valuation!$B$2 | K17: =MAX(-0.05,NORMINV(RAND(),$C$6,$D$6)) | L17: =MAX(0.02,NORMINV(RAND(),$C$7,$D$7)) | M17: =MIN(0.16,MAX(0.05,NORMINV(RAND(),$C$8,$D$8))) | N17: =MIN(24,MAX(5,NORMINV(RAND(),$C$9,$D$9))) | O17: =$I$8*(SUMPRODUCT(($I$2*(1+K17)^{1;2;3;4;5;6;7;8;9;10})*(($I$3+(L17-$I$3)*{1;2;3;4;5;6;7;8;9;10}/10)*(1-$I$7)+$I$4-$I$4*($I$5+(1.05-$I$5)*{1;2;3;4;5;6;7;8;9;10}/10)-(K17/(1+K17))*$I$6)/(1+M17)^{1;2;3;4;5;6;7;8;9;10})+$I$2*(1+K17)^10*(L17+$I$4)*N17/(1+M17)^10+$I$9-$I$10)/$I$11
A18: Base case (full model) | B18: =Valuation!B36 | K18: =MAX(-0.05,NORMINV(RAND(),$C$6,$D$6)) | L18: =MAX(0.02,NORMINV(RAND(),$C$7,$D$7)) | M18: =MIN(0.16,MAX(0.05,NORMINV(RAND(),$C$8,$D$8))) | N18: =MIN(24,MAX(5,NORMINV(RAND(),$C$9,$D$9))) | O18: =$I$8*(SUMPRODUCT(($I$2*(1+K18)^{1;2;3;4;5;6;7;8;9;10})*(($I$3+(L18-$I$3)*{1;2;3;4;5;6;7;8;9;10}/10)*(1-$I$7)+$I$4-$I$4*($I$5+(1.05-$I$5)*{1;2;3;4;5;6;7;8;9;10}/10)-(K18/(1+K18))*$I$6)/(1+M18)^{1;2;3;4;5;6;7;8;9;10})+$I$2*(1+K18)^10*(L18+$I$4)*N18/(1+M18)^10+$I$9-$I$10)/$I$11
K19: =MAX(-0.05,NORMINV(RAND(),$C$6,$D$6)) | L19: =MAX(0.02,NORMINV(RAND(),$C$7,$D$7)) | M19: =MIN(0.16,MAX(0.05,NORMINV(RAND(),$C$8,$D$8))) | N19: =MIN(24,MAX(5,NORMINV(RAND(),$C$9,$D$9))) | O19: =$I$8*(SUMPRODUCT(($I$2*(1+K19)^{1;2;3;4;5;6;7;8;9;10})*(($I$3+(L19-$I$3)*{1;2;3;4;5;6;7;8;9;10}/10)*(1-$I$7)+$I$4-$I$4*($I$5+(1.05-$I$5)*{1;2;3;4;5;6;7;8;9;10}/10)-(K19/(1+K19))*$I$6)/(1+M19)^{1;2;3;4;5;6;7;8;9;10})+$I$2*(1+K19)^10*(L19+$I$4)*N19/(1+M19)^10+$I$9-$I$10)/$I$11
A20: P(undervalued at current price) | B20: =COUNTIF($O$2:$O$1001,">"&Valuation!$B$2)/1000 | K20: =MAX(-0.05,NORMINV(RAND(),$C$6,$D$6)) | L20: =MAX(0.02,NORMINV(RAND(),$C$7,$D$7)) | M20: =MIN(0.16,MAX(0.05,NORMINV(RAND(),$C$8,$D$8))) | N20: =MIN(24,MAX(5,NORMINV(RAND(),$C$9,$D$9))) | O20: =$I$8*(SUMPRODUCT(($I$2*(1+K20)^{1;2;3;4;5;6;7;8;9;10})*(($I$3+(L20-$I$3)*{1;2;3;4;5;6;7;8;9;10}/10)*(1-$I$7)+$I$4-$I$4*($I$5+(1.05-$I$5)*{1;2;3;4;5;6;7;8;9;10}/10)-(K20/(1+K20))*$I$6)/(1+M20)^{1;2;3;4;5;6;7;8;9;10})+$I$2*(1+K20)^10*(L20+$I$4)*N20/(1+M20)^10+$I$9-$I$10)/$I$11
A21: P(>20% upside) | B21: =COUNTIF($O$2:$O$1001,">"&Valuation!$B$2*1.2)/1000 | K21: =MAX(-0.05,NORMINV(RAND(),$C$6,$D$6)) | L21: =MAX(0.02,NORMINV(RAND(),$C$7,$D$7)) | M21: =MIN(0.16,MAX(0.05,NORMINV(RAND(),$C$8,$D$8))) | N21: =MIN(24,MAX(5,NORMINV(RAND(),$C$9,$D$9))) | O21: =$I$8*(SUMPRODUCT(($I$2*(1+K21)^{1;2;3;4;5;6;7;8;9;10})*(($I$3+(L21-$I$3)*{1;2;3;4;5;6;7;8;9;10}/10)*(1-$I$7)+$I$4-$I$4*($I$5+(1.05-$I$5)*{1;2;3;4;5;6;7;8;9;10}/10)-(K21/(1+K21))*$I$6)/(1+M21)^{1;2;3;4;5;6;7;8;9;10})+$I$2*(1+K21)^10*(L21+$I$4)*N21/(1+M21)^10+$I$9-$I$10)/$I$11
K22: =MAX(-0.05,NORMINV(RAND(),$C$6,$D$6)) | L22: =MAX(0.02,NORMINV(RAND(),$C$7,$D$7)) | M22: =MIN(0.16,MAX(0.05,NORMINV(RAND(),$C$8,$D$8))) | N22: =MIN(24,MAX(5,NORMINV(RAND(),$C$9,$D$9))) | O22: =$I$8*(SUMPRODUCT(($I$2*(1+K22)^{1;2;3;4;5;6;7;8;9;10})*(($I$3+(L22-$I$3)*{1;2;3;4;5;6;7;8;9;10}/10)*(1-$I$7)+$I$4-$I$4*($I$5+(1.05-$I$5)*{1;2;3;4;5;6;7;8;9;10}/10)-(K22/(1+K22))*$I$6)/(1+M22)^{1;2;3;4;5;6;7;8;9;10})+$I$2*(1+K22)^10*(L22+$I$4)*N22/(1+M22)^10+$I$9-$I$10)/$I$11
A23: PERCENTILES (live) | K23: =MAX(-0.05,NORMINV(RAND(),$C$6,$D$6)) | L23: =MAX(0.02,NORMINV(RAND(),$C$7,$D$7)) | M23: =MIN(0.16,MAX(0.05,NORMINV(RAND(),$C$8,$D$8))) | N23: =MIN(24,MAX(5,NORMINV(RAND(),$C$9,$D$9))) | O23: =$I$8*(SUMPRODUCT(($I$2*(1+K23)^{1;2;3;4;5;6;7;8;9;10})*(($I$3+(L23-$I$3)*{1;2;3;4;5;6;7;8;9;10}/10)*(1-$I$7)+$I$4-$I$4*($I$5+(1.05-$I$5)*{1;2;3;4;5;6;7;8;9;10}/10)-(K23/(1+K23))*$I$6)/(1+M23)^{1;2;3;4;5;6;7;8;9;10})+$I$2*(1+K23)^10*(L23+$I$4)*N23/(1+M23)^10+$I$9-$I$10)/$I$11
A24: P5 | B24: =PERCENTILE($O$2:$O$1001,0.05) | K24: =MAX(-0.05,NORMINV(RAND(),$C$6,$D$6)) | L24: =MAX(0.02,NORMINV(RAND(),$C$7,$D$7)) | M24: =MIN(0.16,MAX(0.05,NORMINV(RAND(),$C$8,$D$8))) | N24: =MIN(24,MAX(5,NORMINV(RAND(),$C$9,$D$9))) | O24: =$I$8*(SUMPRODUCT(($I$2*(1+K24)^{1;2;3;4;5;6;7;8;9;10})*(($I$3+(L24-$I$3)*{1;2;3;4;5;6;7;8;9;10}/10)*(1-$I$7)+$I$4-$I$4*($I$5+(1.05-$I$5)*{1;2;3;4;5;6;7;8;9;10}/10)-(K24/(1+K24))*$I$6)/(1+M24)^{1;2;3;4;5;6;7;8;9;10})+$I$2*(1+K24)^10*(L24+$I$4)*N24/(1+M24)^10+$I$9-$I$10)/$I$11
A25: P10 | B25: =PERCENTILE($O$2:$O$1001,0.1) | K25: =MAX(-0.05,NORMINV(RAND(),$C$6,$D$6)) | L25: =MAX(0.02,NORMINV(RAND(),$C$7,$D$7)) | M25: =MIN(0.16,MAX(0.05,NORMINV(RAND(),$C$8,$D$8))) | N25: =MIN(24,MAX(5,NORMINV(RAND(),$C$9,$D$9))) | O25: =$I$8*(SUMPRODUCT(($I$2*(1+K25)^{1;2;3;4;5;6;7;8;9;10})*(($I$3+(L25-$I$3)*{1;2;3;4;5;6;7;8;9;10}/10)*(1-$I$7)+$I$4-$I$4*($I$5+(1.05-$I$5)*{1;2;3;4;5;6;7;8;9;10}/10)-(K25/(1+K25))*$I$6)/(1+M25)^{1;2;3;4;5;6;7;8;9;10})+$I$2*(1+K25)^10*(L25+$I$4)*N25/(1+M25)^10+$I$9-$I$10)/$I$11
A26: P25 | B26: =PERCENTILE($O$2:$O$1001,0.25) | K26: =MAX(-0.05,NORMINV(RAND(),$C$6,$D$6)) | L26: =MAX(0.02,NORMINV(RAND(),$C$7,$D$7)) | M26: =MIN(0.16,MAX(0.05,NORMINV(RAND(),$C$8,$D$8))) | N26: =MIN(24,MAX(5,NORMINV(RAND(),$C$9,$D$9))) | O26: =$I$8*(SUMPRODUCT(($I$2*(1+K26)^{1;2;3;4;5;6;7;8;9;10})*(($I$3+(L26-$I$3)*{1;2;3;4;5;6;7;8;9;10}/10)*(1-$I$7)+$I$4-$I$4*($I$5+(1.05-$I$5)*{1;2;3;4;5;6;7;8;9;10}/10)-(K26/(1+K26))*$I$6)/(1+M26)^{1;2;3;4;5;6;7;8;9;10})+$I$2*(1+K26)^10*(L26+$I$4)*N26/(1+M26)^10+$I$9-$I$10)/$I$11
A27: P50 | B27: =PERCENTILE($O$2:$O$1001,0.5) | K27: =MAX(-0.05,NORMINV(RAND(),$C$6,$D$6)) | L27: =MAX(0.02,NORMINV(RAND(),$C$7,$D$7)) | M27: =MIN(0.16,MAX(0.05,NORMINV(RAND(),$C$8,$D$8))) | N27: =MIN(24,MAX(5,NORMINV(RAND(),$C$9,$D$9))) | O27: =$I$8*(SUMPRODUCT(($I$2*(1+K27)^{1;2;3;4;5;6;7;8;9;10})*(($I$3+(L27-$I$3)*{1;2;3;4;5;6;7;8;9;10}/10)*(1-$I$7)+$I$4-$I$4*($I$5+(1.05-$I$5)*{1;2;3;4;5;6;7;8;9;10}/10)-(K27/(1+K27))*$I$6)/(1+M27)^{1;2;3;4;5;6;7;8;9;10})+$I$2*(1+K27)^10*(L27+$I$4)*N27/(1+M27)^10+$I$9-$I$10)/$I$11
A28: P75 | B28: =PERCENTILE($O$2:$O$1001,0.75) | K28: =MAX(-0.05,NORMINV(RAND(),$C$6,$D$6)) | L28: =MAX(0.02,NORMINV(RAND(),$C$7,$D$7)) | M28: =MIN(0.16,MAX(0.05,NORMINV(RAND(),$C$8,$D$8))) | N28: =MIN(24,MAX(5,NORMINV(RAND(),$C$9,$D$9))) | O28: =$I$8*(SUMPRODUCT(($I$2*(1+K28)^{1;2;3;4;5;6;7;8;9;10})*(($I$3+(L28-$I$3)*{1;2;3;4;5;6;7;8;9;10}/10)*(1-$I$7)+$I$4-$I$4*($I$5+(1.05-$I$5)*{1;2;3;4;5;6;7;8;9;10}/10)-(K28/(1+K28))*$I$6)/(1+M28)^{1;2;3;4;5;6;7;8;9;10})+$I$2*(1+K28)^10*(L28+$I$4)*N28/(1+M28)^10+$I$9-$I$10)/$I$11
A29: P90 | B29: =PERCENTILE($O$2:$O$1001,0.9) | K29: =MAX(-0.05,NORMINV(RAND(),$C$6,$D$6)) | L29: =MAX(0.02,NORMINV(RAND(),$C$7,$D$7)) | M29: =MIN(0.16,MAX(0.05,NORMINV(RAND(),$C$8,$D$8))) | N29: =MIN(24,MAX(5,NORMINV(RAND(),$C$9,$D$9))) | O29: =$I$8*(SUMPRODUCT(($I$2*(1+K29)^{1;2;3;4;5;6;7;8;9;10})*(($I$3+(L29-$I$3)*{1;2;3;4;5;6;7;8;9;10}/10)*(1-$I$7)+$I$4-$I$4*($I$5+(1.05-$I$5)*{1;2;3;4;5;6;7;8;9;10}/10)-(K29/(1+K29))*$I$6)/(1+M29)^{1;2;3;4;5;6;7;8;9;10})+$I$2*(1+K29)^10*(L29+$I$4)*N29/(1+M29)^10+$I$9-$I$10)/$I$11
A30: P95 | B30: =PERCENTILE($O$2:$O$1001,0.95) | K30: =MAX(-0.05,NORMINV(RAND(),$C$6,$D$6)) | L30: =MAX(0.02,NORMINV(RAND(),$C$7,$D$7)) | M30: =MIN(0.16,MAX(0.05,NORMINV(RAND(),$C$8,$D$8))) | N30: =MIN(24,MAX(5,NORMINV(RAND(),$C$9,$D$9))) | O30: =$I$8*(SUMPRODUCT(($I$2*(1+K30)^{1;2;3;4;5;6;7;8;9;10})*(($I$3+(L30-$I$3)*{1;2;3;4;5;6;7;8;9;10}/10)*(1-$I$7)+$I$4-$I$4*($I$5+(1.05-$I$5)*{1;2;3;4;5;6;7;8;9;10}/10)-(K30/(1+K30))*$I$6)/(1+M30)^{1;2;3;4;5;6;7;8;9;10})+$I$2*(1+K30)^10*(L30+$I$4)*N30/(1+M30)^10+$I$9-$I$10)/$I$11
K31: =MAX(-0.05,NORMINV(RAND(),$C$6,$D$6)) | L31: =MAX(0.02,NORMINV(RAND(),$C$7,$D$7)) | M31: =MIN(0.16,MAX(0.05,NORMINV(RAND(),$C$8,$D$8))) | N31: =MIN(24,MAX(5,NORMINV(RAND(),$C$9,$D$9))) | O31: =$I$8*(SUMPRODUCT(($I$2*(1+K31)^{1;2;3;4;5;6;7;8;9;10})*(($I$3+(L31-$I$3)*{1;2;3;4;5;6;7;8;9;10}/10)*(1-$I$7)+$I$4-$I$4*($I$5+(1.05-$I$5)*{1;2;3;4;5;6;7;8;9;10}/10)-(K31/(1+K31))*$I$6)/(1+M31)^{1;2;3;4;5;6;7;8;9;10})+$I$2*(1+K31)^10*(L31+$I$4)*N31/(1+M31)^10+$I$9-$I$10)/$I$11
A32: VALUE DISTRIBUTION (live histogram) | K32: =MAX(-0.05,NORMINV(RAND(),$C$6,$D$6)) | L32: =MAX(0.02,NORMINV(RAND(),$C$7,$D$7)) | M32: =MIN(0.16,MAX(0.05,NORMINV(RAND(),$C$8,$D$8))) | N32: =MIN(24,MAX(5,NORMINV(RAND(),$C$9,$D$9))) | O32: =$I$8*(SUMPRODUCT(($I$2*(1+K32)^{1;2;3;4;5;6;7;8;9;10})*(($I$3+(L32-$I$3)*{1;2;3;4;5;6;7;8;9;10}/10)*(1-$I$7)+$I$4-$I$4*($I$5+(1.05-$I$5)*{1;2;3;4;5;6;7;8;9;10}/10)-(K32/(1+K32))*$I$6)/(1+M32)^{1;2;3;4;5;6;7;8;9;10})+$I$2*(1+K32)^10*(L32+$I$4)*N32/(1+M32)^10+$I$9-$I$10)/$I$11
A33: Bin midpoint ($/sh) | B33: Count | K33: =MAX(-0.05,NORMINV(RAND(),$C$6,$D$6)) | L33: =MAX(0.02,NORMINV(RAND(),$C$7,$D$7)) | M33: =MIN(0.16,MAX(0.05,NORMINV(RAND(),$C$8,$D$8))) | N33: =MIN(24,MAX(5,NORMINV(RAND(),$C$9,$D$9))) | O33: =$I$8*(SUMPRODUCT(($I$2*(1+K33)^{1;2;3;4;5;6;7;8;9;10})*(($I$3+(L33-$I$3)*{1;2;3;4;5;6;7;8;9;10}/10)*(1-$I$7)+$I$4-$I$4*($I$5+(1.05-$I$5)*{1;2;3;4;5;6;7;8;9;10}/10)-(K33/(1+K33))*$I$6)/(1+M33)^{1;2;3;4;5;6;7;8;9;10})+$I$2*(1+K33)^10*(L33+$I$4)*N33/(1+M33)^10+$I$9-$I$10)/$I$11
A34: =$B$15+0.5*($B$16-$B$15)/15 | B34: =COUNTIFS($O$2:$O$1001,">="&($B$15+0*($B$16-$B$15)/15),$O$2:$O$1001,"<"&($B$15+1*($B$16-$B$15)/15)) | K34: =MAX(-0.05,NORMINV(RAND(),$C$6,$D$6)) | L34: =MAX(0.02,NORMINV(RAND(),$C$7,$D$7)) | M34: =MIN(0.16,MAX(0.05,NORMINV(RAND(),$C$8,$D$8))) | N34: =MIN(24,MAX(5,NORMINV(RAND(),$C$9,$D$9))) | O34: =$I$8*(SUMPRODUCT(($I$2*(1+K34)^{1;2;3;4;5;6;7;8;9;10})*(($I$3+(L34-$I$3)*{1;2;3;4;5;6;7;8;9;10}/10)*(1-$I$7)+$I$4-$I$4*($I$5+(1.05-$I$5)*{1;2;3;4;5;6;7;8;9;10}/10)-(K34/(1+K34))*$I$6)/(1+M34)^{1;2;3;4;5;6;7;8;9;10})+$I$2*(1+K34)^10*(L34+$I$4)*N34/(1+M34)^10+$I$9-$I$10)/$I$11
