Workbook

Sheet Cover
A1: Coherent, Inc. (COHR)
A2: DCF valuation — exit-multiple terminal · defaults anchored to consensus
A4: Last updated | B4: 2026-07-08
A5: Data pulled (FMP) | B5: Q3 2026
A6: Assumptions by | B6: Opus 4.8 — values as of 2026-06-12 (provenance seeded)
A8: VALUATION SUMMARY
A10: Fair value / share | B10: =Valuation!B36
A11: Current price | B11: =Valuation!$B$2
A12: Upside / (downside) | B12: =Valuation!B42
A13: Verdict | B13: =IF(Valuation!B36>Valuation!$B$2,"Undervalued","Overvalued")
A14: Monte Carlo P(undervalued) | B14: ='Monte Carlo'!B20
A15: KEY ASSUMPTIONS
A17: WACC (from WACC tab) | B17: =WACC!B15
A18: Terminal method | B18: =Valuation!$B$6
A19: Exit basis / multiple | B19: =Valuation!$B$7
A20: Exit multiple | B20: =Valuation!$B$8
A21: Terminal growth (g) | B21: =Valuation!$B$4
A22: Terminal weight | B22: =Valuation!B39
A23: Forecast horizon | B23: 10 years
A25: THE STORY (Opus)
A27: Coherent is an optical/photonics and compound-semiconductor supplier whose near-term growth is dominated by AI datacenter transceiver demand, with legacy Lasers and Materials segments growing more modestly and cyclically. We anchor 2026-2028 to consensus that implies ~20-35% top-line growth, then fade toward a low-single-digit mature rate as datacenter buildout normalizes, while operating margins expand from 9.4% (FY25) toward ~18% via mix shift to high-value optics and operating leverage. We value the firm on a mature ~12x EV/EBITDA exit, reflecting a normalized hardware/photonics business rather than peak-cycle multiples.

Sheet Dashboard
A1: Coherent, Inc. (COHR) — Control Dashboard
A2: Edit the yellow cells; everything recomputes. Orange = a driver you've moved off consensus.
A4: VERDICT
A5: Fair value / share | B5: =Valuation!B36
A6: Current price | B6: =Dashboard!$B$48
A7: Upside / (downside) | B7: =Valuation!B42
A8: Verdict | B8: =IF(Valuation!B36>Dashboard!$B$48,"Undervalued","Overvalued")
A9: Monte Carlo P(undervalued) | B9: ='Monte Carlo'!B20
A11: GUARDRAIL SIGNALS (are my assumptions sane?)
A12: Signal | B12: Value | C12: Flag | D12: Healthy
A13: Terminal weight (% of EV) | B13: =Valuation!B39 | C13: =IF(Valuation!B39>0.9,"! high","ok") | D13: < 90%
A14: Implied g vs exit multiple | B14: =Valuation!B40 | C14: =IF(Valuation!B40>Dashboard!$B$46+0.02,"! rich","ok") | D14: near term g
A15: ROIC - WACC (2026) | B15: =IF(Model!F34<=0,"n/a (neg. capital)",Model!G36-WACC!B15) | C15: =IF(Model!F34<=0,"n/a",IF(Model!G36-WACC!B15<0,"! destroys","creates")) | D15: > 0
A16: Revenue vs consensus (2026) | B16: =Consensus!B6 | C16: =IF(ABS(Consensus!B6)>0.05,"! off-Street","on") | D16: +/- 5%
A17: MC P(undervalued) | B17: ='Monte Carlo'!B20 | C17: =IF('Monte Carlo'!B20<0.5,"! coin-flip","ok") | D17: context
A18: REVENUE DRIVERS — near-term & terminal growth per segment
A19: Segment | B19: Near-term | C19: Terminal | D19: Consensus | E19: Thesis claim
A20: Total company | B20: 0.37165192 | C20: 0.05 | D20: 0.37165192
A28: PROFITABILITY & TAX
A29: Near-term operating margin | B29: 0.13 | D29: 0.13 | E29: consensus-implied; ramps to terminal
A30: Terminal operating margin | B30: 0.18 | E30: AI/ads mix + operating leverage
A31: Tax rate | B31: 0.21
A33: CAPITAL INTENSITY
A34: 2026 capex ($M) | B34: 529.30504 | D34: 529.30504 | E34: ~last-year capex +10%; set to guidance
A35: Terminal capex / D&A | B35: 1.05 | E35: converges to ~1.0x as build-out matures
A37: DISCOUNT RATE & TERMINAL
A38: Risk-free rate (10Y) | B38: 0.043
A39: Equity risk premium | B39: 0.045
A40: Beta (levered) | B40: 2.053 | E40: FMP raw beta; Damodaran bottom-up ~1.2
A41: Pre-tax cost of debt | B41: 0.045
A42: WACC (computed) | B42: =WACC!B15
A43: Terminal method | B43: Exit multiple
A44: Exit basis | B44: EV/EBITDA
A45: Exit multiple | B45: 12
A46: Terminal growth (g) | B46: 0.04
A47: Country risk premium | B47: 0.0066351894 | E47: Damodaran country premiums, revenue-weighted (2026-01); 0 for US/mature
A48: Current price | B48: 314.98001
A49: Growth fade curvature | B49: 2 | E49: convexity of the near->terminal growth fade, fit to consensus (1.0=linear); higher = faster early deceleration
A50: SCENARIOS — Bull / Bear offsets vs Base (edit the yellow Δs)
A51: Scenario lever | B51: Base | C51: Bull Δ | D51: Bear Δ
...

Sheet Assumptions
A1: COHR — Assumptions & Reasoning
A2: Provenance of every Dashboard input. Read-only — regenerated by each build/refresh. Current is a live link to the Dashboard; Source / Opus value / Note are as of the last refresh_dcf run.
A4: Assumptions baseline | B4: seeded 2026-06-12 from the synced assumptions block (pass predates provenance tracking — may already include your edits)
A6: THE STORY (Opus narrative)
A7: Coherent is an optical/photonics and compound-semiconductor supplier whose near-term growth is dominated by AI datacenter transceiver demand, with legacy Lasers and Materials segments growing more modestly and cyclically. We anchor 2026-2028 to consensus that implies ~20-35% top-line growth, then fade toward a low-single-digit mature rate as datacenter buildout normalizes, while operating margins expand from 9.4% (FY25) toward ~18% via mix shift to high-value optics and operating leverage. We value the firm on a mature ~12x EV/EBITDA exit, reflecting a normalized hardware/photonics business rather than peak-cycle multiples.
A12: KEY JUDGMENTS (Opus reasoning)
A13: Key calls: the two listed segments (Lasers, Materials) are the slower-growth legacy pieces, so I set their growth well below the consensus-implied total-company trajectory that the AI/datacenter optics business drives. I kept terminal margins (18%) and the exit multiple (12x EV/EBITDA) conservative given high cyclicality and a 2.05 beta, and converged capex/D&A to ~1.1x to reflect a shift from expansion to maintenance capex at maturity.
A18: DASHBOARD INPUTS — value · source · reasoning
A19: Input | B19: Cell | C19: Current | D19: Source | E19: Opus value | F19: Note
A20: Total company — near-term growth | B20: B20 | C20: =Dashboard!B20 | D20: builder default | E20: —
A21: Total company — terminal growth | B21: C20 | C21: =Dashboard!C20 | D21: builder default | E21: —
A22: Near-term operating margin | B22: B29 | C22: =Dashboard!B29 | D22: Opus | E22: 13.0%
A23: Terminal operating margin | B23: B30 | C23: =Dashboard!B30 | D23: Opus | E23: 18.0%
A24: Tax rate | B24: B31 | C24: =Dashboard!B31 | D24: Opus | E24: 21.0%
A25: Terminal capex / D&A | B25: B35 | C25: =Dashboard!B35 | D25: user-edited | E25: 1.1x | F25: overridden from Opus 1.1x on 2026-06-12
A26: Risk-free rate (10Y) | B26: B38 | C26: =Dashboard!B38 | D26: builder default | E26: —
A27: Equity risk premium | B27: B39 | C27: =Dashboard!B39 | D27: builder default | E27: —
A28: Beta (levered) | B28: B40 | C28: =Dashboard!B40 | D28: builder default | E28: —
A29: Pre-tax cost of debt | B29: B41 | C29: =Dashboard!B41 | D29: builder default | E29: —
A30: Terminal method | B30: B43 | C30: =Dashboard!B43 | D30: Opus | E30: Exit multiple
A31: Exit basis | B31: B44 | C31: =Dashboard!B44 | D31: Opus | E31: EV/EBITDA
A32: Exit multiple | B32: B45 | C32: =Dashboard!B45 | D32: Opus | E32: 12.0x
A33: Terminal growth (g) | B33: B46 | C33: =Dashboard!B46 | D33: Opus | E33: 4.0%
A34: 2026 capex ($M) | B34: B34 | C34: =Dashboard!B34 | D34: Opus | E34: — | F34: set from Opus 8% of FY1E revenue; edits not tracked (unit differs from the JSON)
A35: Bull Δ — segment growth, near-term | B35: C52 | C35: =Dashboard!C52 | D35: seed default | E35: 3.0%
A36: Bear Δ — segment growth, near-term | B36: D52 | C36: =Dashboard!D52 | D36: seed default | E36: -3.0%
A37: Bull Δ — segment growth, terminal | B37: C53 | C37: =Dashboard!C53 | D37: seed default | E37: 1.0%
A38: Bear Δ — segment growth, terminal | B38: D53 | C38: =Dashboard!D53 | D38: seed default | E38: -1.0%
A39: Bull Δ — operating margin, near-term | B39: C54 | C39: =Dashboard!C54 | D39: seed default | E39: 1.0%
A40: Bear Δ — operating margin, near-term | B40: D54 | C40: =Dashboard!D54 | D40: seed default | E40: -1.0%
A41: Bull Δ — operating margin, terminal | B41: C55 | C41: =Dashboard!C55 | D41: seed default | E41: 2.0%
A42: Bear Δ — operating margin, terminal | B42: D55 | C42: =Dashboard!D55 | D42: seed default | E42: -2.0%
A43: Bull Δ — exit multiple | B43: C56 | C43: =Dashboard!C56 | D43: seed default | E43: 2.0x
A44: Bear Δ — exit multiple | B44: D56 | C44: =Dashboard!D56 | D44: seed default | E44: -2.0x
A45: Bull Δ — terminal growth (g) | B45: C57 | C45: =Dashboard!C57 | D45: seed default | E45: 0.5%
A46: Bear Δ — terminal growth (g) | B46: D57 | C46: =Dashboard!D57 | D46: seed default | E46: -0.5%

Sheet Color Code
A1: Color | B1: Meaning
A2: Black | B2: Formula-driven (same-sheet)
A3: Blue | B3: Hard-coded actuals (from FMP filings)
A4: Yellow | B4: An assumption you can change — edit these to drive the model
A5: Green | B5: A formula that links to another sheet
A6: Orange | B6: (Dashboard) an assumption you've moved off consensus — your active bet
A7: How to use | B7: Edit yellow cells (Model assumptions, WACC drivers, Valuation toggles). Everything else recomputes.

Sheet WACC
A1: WACC Calculator
A2: Risk-free rate (10Y) | B2: =Dashboard!$B$38
A3: Equity risk premium | B3: =Dashboard!$B$39
A4: Beta (levered) | B4: =Dashboard!$B$40
A5: Country risk premium | B5: =Dashboard!$B$47
A6: Cost of equity (CAPM) | B6: =B2+B4*B3+B5
A7: Pre-tax cost of debt | B7: =Dashboard!$B$41
A8: Tax rate | B8: =Dashboard!$B$31
A9: After-tax cost of debt | B9: =B7*(1-B8)
A10: Market cap (E) | B10: =Dashboard!$B$48*Financials!AC17
A11: Total debt (D) | B11: =Financials!AC40
A12: Equity weight | B12: =B10/(B10+B11)
A13: Debt weight | B13: =B11/(B10+B11)
A15: WACC | B15: =B12*B6+B13*B9
A17: Yellow = edit. CAPM cost of equity (incl. country risk premium); market-value weights. Feeds Valuation!WACC.

Sheet Model
A1: $M unless noted | B1: FY2021A | C1: FY2022A | D1: FY2023A | E1: FY2024A | F1: FY2025A | G1: FY2026E | H1: FY2027E | I1: FY2028E | J1: FY2029E | K1: FY2030E | L1: FY2031E | M1: FY2032E | N1: FY2033E | O1: FY2034E | P1: FY2035E
A3: REVENUE BY SEGMENT (yellow = growth assumption; actuals link to Financials)
A4: Total company | B4: =SUM(Financials!G3:J3) | C4: =SUM(Financials!K3:N3) | D4: =SUM(Financials!O3:R3) | E4: =SUM(Financials!S3:V3) | F4: =SUM(Financials!W3:Z3) | G4: =F4*(1+G5) | H4: =G4*(1+H5) | I4: =H4*(1+I5) | J4: =I4*(1+J5) | K4: =J4*(1+K5) | L4: =K4*(1+L5) | M4: =L4*(1+M5) | N4: =M4*(1+N5) | ... P4: =O4*(1+P5)
A5: growth % (convex fade; curvature from Dashboard) | C5: =IFERROR(C4/B4-1,"") | D5: =IFERROR(D4/C4-1,"") | E5: =IFERROR(E4/D4-1,"") | F5: =IFERROR(F4/E4-1,"") | G5: =Dashboard!$C$20+(Dashboard!$B$20-Dashboard!$C$20)*((9-0)/9)^Dashboard!$B$49 | H5: =Dashboard!$C$20+(Dashboard!$B$20-Dashboard!$C$20)*((9-1)/9)^Dashboard!$B$49 | I5: =Dashboard!$C$20+(Dashboard!$B$20-Dashboard!$C$20)*((9-2)/9)^Dashboard!$B$49 | J5: =Dashboard!$C$20+(Dashboard!$B$20-Dashboard!$C$20)*((9-3)/9)^Dashboard!$B$49 | K5: =Dashboard!$C$20+(Dashboard!$B$20-Dashboard!$C$20)*((9-4)/9)^Dashboard!$B$49 | L5: =Dashboard!$C$20+(Dashboard!$B$20-Dashboard!$C$20)*((9-5)/9)^Dashboard!$B$49 | M5: =Dashboard!$C$20+(Dashboard!$B$20-Dashboard!$C$20)*((9-6)/9)^Dashboard!$B$49 | N5: =Dashboard!$C$20+(Dashboard!$B$20-Dashboard!$C$20)*((9-7)/9)^Dashboard!$B$49 | O5: =Dashboard!$C$20+(Dashboard!$B$20-Dashboard!$C$20)*((9-8)/9)^Dashboard!$B$49 | P5: =Dashboard!$C$20+(Dashboard!$B$20-Dashboard!$C$20)*((9-9)/9)^Dashboard!$B$49
A6: Total revenue | B6: =B4 | C6: =C4 | D6: =D4 | E6: =E4 | F6: =F4 | G6: =G4 | H6: =H4 | I6: =I4 | ... P6: =P4
A7: growth % | C7: =IFERROR(C6/B6-1,"") | D7: =IFERROR(D6/C6-1,"") | E7: =IFERROR(E6/D6-1,"") | F7: =IFERROR(F6/E6-1,"") | G7: =IFERROR(G6/F6-1,"") | H7: =IFERROR(H6/G6-1,"") | I7: =IFERROR(I6/H6-1,"") | J7: =IFERROR(J6/I6-1,"") | ... P7: =IFERROR(P6/O6-1,"")
A9: COST STRUCTURE (yellow = % of revenue)
A10: Cost of revenue | B10: =SUM(Financials!G5:J5) | C10: =SUM(Financials!K5:N5) | D10: =SUM(Financials!O5:R5) | E10: =SUM(Financials!S5:V5) | F10: =SUM(Financials!W5:Z5) | G10: =G6*G11 | H10: =H6*H11 | I10: =I6*I11 | J10: =J6*J11 | K10: =K6*K11 | L10: =L6*L11 | M10: =M6*M11 | N10: =N6*N11 | ... P10: =P6*P11
A11: % of revenue | B11: =IFERROR(B10/B6,"") | C11: =IFERROR(C10/C6,"") | D11: =IFERROR(D10/D6,"") | E11: =IFERROR(E10/E6,"") | F11: =IFERROR(F10/F6,"") | G11: 0.64590684 | H11: 0.64590684 | I11: 0.64590684 | J11: 0.64590684 | K11: 0.64590684 | L11: 0.64590684 | M11: 0.64590684 | N11: 0.64590684 | O11: 0.64590684 | P11: 0.64590684
A12: R&D / Technology | B12: =SUM(Financials!G7:J7) | C12: =SUM(Financials!K7:N7) | D12: =SUM(Financials!O7:R7) | E12: =SUM(Financials!S7:V7) | F12: =SUM(Financials!W7:Z7) | G12: =G6*G13 | H12: =H6*H13 | I12: =I6*I13 | J12: =J6*J13 | K12: =K6*K13 | L12: =L6*L13 | M12: =M6*M13 | N12: =N6*N13 | ... P12: =P6*P13
A13: % of revenue | B13: =IFERROR(B12/B6,"") | C13: =IFERROR(C12/C6,"") | D13: =IFERROR(D12/D6,"") | E13: =IFERROR(E12/E6,"") | F13: =IFERROR(F12/F6,"") | G13: 0.10015705 | H13: 0.10015705 | I13: 0.10015705 | J13: 0.10015705 | K13: 0.10015705 | L13: 0.10015705 | M13: 0.10015705 | N13: 0.10015705 | O13: 0.10015705 | P13: 0.10015705
A14: SG&A | B14: =SUM(Financials!G9:J9) | C14: =SUM(Financials!K9:N9) | D14: =SUM(Financials!O9:R9) | E14: =SUM(Financials!S9:V9) | F14: =SUM(Financials!W9:Z9) | G14: =G6*G15 | H14: =H6*H15 | I14: =I6*I15 | J14: =J6*J15 | K14: =K6*K15 | L14: =L6*L15 | M14: =M6*M15 | N14: =N6*N15 | ... P14: =P6*P15
A15: % of revenue | B15: =IFERROR(B14/B6,"") | C15: =IFERROR(C14/C6,"") | D15: =IFERROR(D14/D6,"") | E15: =IFERROR(E14/E6,"") | F15: =IFERROR(F14/F6,"") | G15: 0 | H15: 0 | I15: 0 | J15: 0 | K15: 0 | L15: 0 | M15: 0 | N15: 0 | O15: 0 | P15: 0
A16: Other opex (fulfilment, etc.) | B16: =B6-(B10+B12+B14)-SUM(Financials!G13:J13) | C16: =C6-(C10+C12+C14)-SUM(Financials!K13:N13) | D16: =D6-(D10+D12+D14)-SUM(Financials!O13:R13) | E16: =E6-(E10+E12+E14)-SUM(Financials!S13:V13) | F16: =F6-(F10+F12+F14)-SUM(Financials!W13:Z13) | G16: =G6*(1-(Dashboard!$B$29+(Dashboard!$B$30-Dashboard!$B$29)*MIN(1,0/3)))-(G10+G12+G14) | H16: =H6*(1-(Dashboard!$B$29+(Dashboard!$B$30-Dashboard!$B$29)*MIN(1,1/3)))-(H10+H12+H14) | I16: =I6*(1-(Dashboard!$B$29+(Dashboard!$B$30-Dashboard!$B$29)*MIN(1,2/3)))-(I10+I12+I14) | J16: =J6*(1-(Dashboard!$B$29+(Dashboard!$B$30-Dashboard!$B$29)*MIN(1,3/3)))-(J10+J12+J14) | K16: =K6*(1-(Dashboard!$B$29+(Dashboard!$B$30-Dashboard!$B$29)*MIN(1,4/3)))-(K10+K12+K14) | L16: =L6*(1-(Dashboard!$B$29+(Dashboard!$B$30-Dashboard!$B$29)*MIN(1,5/3)))-(L10+L12+L14) | M16: =M6*(1-(Dashboard!$B$29+(Dashboard!$B$30-Dashboard!$B$29)*MIN(1,6/3)))-(M10+M12+M14) | N16: =N6*(1-(Dashboard!$B$29+(Dashboard!$B$30-Dashboard!$B$29)*MIN(1,7/3)))-(N10+N12+N14) | O16: =O6*(1-(Dashboard!$B$29+(Dashboard!$B$30-Dashboard!$B$29)*MIN(1,8/3)))-(O10+O12+O14) | P16: =P6*(1-(Dashboard!$B$29+(Dashboard!$B$30-Dashboard!$B$29)*MIN(1,9/3)))-(P10+P12+P14)
A17: % of revenue | B17: =IFERROR(B16/B6,"") | C17: =IFERROR(C16/C6,"") | D17: =IFERROR(D16/D6,"") | E17: =IFERROR(E16/E6,"") | F17: =IFERROR(F16/F6,"") | G17: =IFERROR(G16/G6,"") | H17: =IFERROR(H16/H6,"") | I17: =IFERROR(I16/I6,"") | ... P17: =IFERROR(P16/P6,"")
A19: Operating income (EBIT) | B19: =B6-(B10+B12+B14)-B16 | C19: =C6-(C10+C12+C14)-C16 | D19: =D6-(D10+D12+D14)-D16 | E19: =E6-(E10+E12+E14)-E16 | F19: =F6-(F10+F12+F14)-F16 | G19: =G6-(G10+G12+G14)-G16 | H19: =H6-(H10+H12+H14)-H16 | I19: =I6-(I10+I12+I14)-I16 | ... P19: =P6-(P10+P12+P14)-P16
A20: operating margin | B20: =IFERROR(B19/B6,"") | C20: =IFERROR(C19/C6,"") | D20: =IFERROR(D19/D6,"") | E20: =IFERROR(E19/E6,"") | F20: =IFERROR(F19/F6,"") | G20: =IFERROR(G19/G6,"") | H20: =IFERROR(H19/H6,"") | I20: =IFERROR(I19/I6,"") | ... P20: =IFERROR(P19/P6,"")
A22: FCF BRIDGE (NOPAT + D&A + SBC - dNWC - Capex)
A23: NOPAT = EBIT x (1 - tax) | B23: =B19*(1-Valuation!$B$5) | C23: =C19*(1-Valuation!$B$5) | D23: =D19*(1-Valuation!$B$5) | E23: =E19*(1-Valuation!$B$5) | F23: =F19*(1-Valuation!$B$5) | G23: =G19*(1-Valuation!$B$5) | H23: =H19*(1-Valuation!$B$5) | I23: =I19*(1-Valuation!$B$5) | ... P23: =P19*(1-Valuation!$B$5)
A24: + D&A | B24: =SUM(Financials!G43:J43) | C24: =SUM(Financials!K43:N43) | D24: =SUM(Financials!O43:R43) | E24: =SUM(Financials!S43:V43) | F24: =SUM(Financials!W43:Z43) | G24: =G6*0.1152 | H24: =H6*0.1152 | I24: =I6*0.1152 | J24: =J6*0.1152 | K24: =K6*0.1152 | L24: =L6*0.1152 | M24: =M6*0.1152 | N24: =N6*0.1152 | ... P24: =P6*0.1152
A25: + SBC (non-cash) | B25: =SUM(Financials!G44:J44) | C25: =SUM(Financials!K44:N44) | D25: =SUM(Financials!O44:R44) | E25: =SUM(Financials!S44:V44) | F25: =SUM(Financials!W44:Z44) | G25: =G6*(Dashboard!$B$65+(Dashboard!$B$66-Dashboard!$B$65)*0/9) | H25: =H6*(Dashboard!$B$65+(Dashboard!$B$66-Dashboard!$B$65)*1/9) | I25: =I6*(Dashboard!$B$65+(Dashboard!$B$66-Dashboard!$B$65)*2/9) | J25: =J6*(Dashboard!$B$65+(Dashboard!$B$66-Dashboard!$B$65)*3/9) | K25: =K6*(Dashboard!$B$65+(Dashboard!$B$66-Dashboard!$B$65)*4/9) | L25: =L6*(Dashboard!$B$65+(Dashboard!$B$66-Dashboard!$B$65)*5/9) | M25: =M6*(Dashboard!$B$65+(Dashboard!$B$66-Dashboard!$B$65)*6/9) | N25: =N6*(Dashboard!$B$65+(Dashboard!$B$66-Dashboard!$B$65)*7/9) | O25: =O6*(Dashboard!$B$65+(Dashboard!$B$66-Dashboard!$B$65)*8/9) | P25: =P6*(Dashboard!$B$65+(Dashboard!$B$66-Dashboard!$B$65)*9/9)
A26: - dNWC | G26: =(G6-F6)*0.0050 | H26: =(H6-G6)*0.0050 | I26: =(I6-H6)*0.0050 | J26: =(J6-I6)*0.0050 | K26: =(K6-J6)*0.0050 | L26: =(L6-K6)*0.0050 | M26: =(M6-L6)*0.0050 | N26: =(N6-M6)*0.0050 | ... P26: =(P6-O6)*0.0050
A27: - Capex | B27: =-SUM(Financials!G47:J47) | C27: =-SUM(Financials!K47:N47) | D27: =-SUM(Financials!O47:R47) | E27: =-SUM(Financials!S47:V47) | F27: =-SUM(Financials!W47:Z47) | G27: =G24*G28 | H27: =H24*H28 | I27: =I24*I28 | J27: =J24*J28 | K27: =K24*K28 | L27: =L24*L28 | M27: =M24*M28 | N27: =N24*N28 | ... P27: =P24*P28
A28: Capex / D&A (from Dashboard: $cap'26 -> terminal) | B28: =IFERROR(B27/B24,"") | C28: =IFERROR(C27/C24,"") | D28: =IFERROR(D27/D24,"") | E28: =IFERROR(E27/E24,"") | F28: =IFERROR(F27/F24,"") | G28: =(Dashboard!$B$34/G24)+(Dashboard!$B$35-(Dashboard!$B$34/G24))*0/9 | H28: =(Dashboard!$B$34/G24)+(Dashboard!$B$35-(Dashboard!$B$34/G24))*1/9 | I28: =(Dashboard!$B$34/G24)+(Dashboard!$B$35-(Dashboard!$B$34/G24))*2/9 | J28: =(Dashboard!$B$34/G24)+(Dashboard!$B$35-(Dashboard!$B$34/G24))*3/9 | K28: =(Dashboard!$B$34/G24)+(Dashboard!$B$35-(Dashboard!$B$34/G24))*4/9 | L28: =(Dashboard!$B$34/G24)+(Dashboard!$B$35-(Dashboard!$B$34/G24))*5/9 | M28: =(Dashboard!$B$34/G24)+(Dashboard!$B$35-(Dashboard!$B$34/G24))*6/9 | N28: =(Dashboard!$B$34/G24)+(Dashboard!$B$35-(Dashboard!$B$34/G24))*7/9 | O28: =(Dashboard!$B$34/G24)+(Dashboard!$B$35-(Dashboard!$B$34/G24))*8/9 | P28: =(Dashboard!$B$34/G24)+(Dashboard!$B$35-(Dashboard!$B$34/G24))*9/9
A30: FCFF (firm) | B30: =B23+B24+B25-B26-B27 | C30: =C23+C24+C25-C26-C27 | D30: =D23+D24+D25-D26-D27 | E30: =E23+E24+E25-E26-E27 | F30: =F23+F24+F25-F26-F27 | G30: =G23+G24+G25-G26-G27 | H30: =H23+H24+H25-H26-H27 | I30: =I23+I24+I25-I26-I27 | ... P30: =P23+P24+P25-P26-P27
A31: Valuation FCF (NOPAT + D&A - dNWC - Capex - after-tax SBC) | B31: =B30-B25-B25*(1-Valuation!$B$5) | C31: =C30-C25-C25*(1-Valuation!$B$5) | D31: =D30-D25-D25*(1-Valuation!$B$5) | E31: =E30-E25-E25*(1-Valuation!$B$5) | F31: =F30-F25-F25*(1-Valuation!$B$5) | G31: =G30-G25-G25*(1-Valuation!$B$5) | H31: =H30-H25-H25*(1-Valuation!$B$5) | I31: =I30-I25-I25*(1-Valuation!$B$5) | ... P31: =P30-P25-P25*(1-Valuation!$B$5)
A33: RETURNS ON CAPITAL & EFFICIENCY (is new revenue/capital earning its keep?)
A34: Invested capital (debt + equity - cash) | B34: =Financials!J41+Financials!J40-Financials!J35 | C34: =Financials!N41+Financials!N40-Financials!N35 | D34: =Financials!R41+Financials!R40-Financials!R35 | E34: =Financials!V41+Financials!V40-Financials!V35 | F34: =Financials!Z41+Financials!Z40-Financials!Z35 | G34: =F34+G27-G24+G26 | H34: =G34+H27-H24+H26 | I34: =H34+I27-I24+I26 | J34: =I34+J27-J24+J26 | K34: =J34+K27-K24+K26 | L34: =K34+L27-L24+L26 | M34: =L34+M27-M24+M26 | N34: =M34+N27-N24+N26 | ... P34: =O34+P27-P24+P26
A35: Book equity (year-end) | B35: =Financials!J41 | C35: =Financials!N41 | D35: =Financials!R41 | E35: =Financials!V41 | F35: =Financials!Z41 | G35: =F35+G23 | H35: =G35+H23 | I35: =H35+I23 | J35: =I35+J23 | K35: =J35+K23 | L35: =K35+L23 | M35: =L35+M23 | N35: =M35+N23 | ... P35: =O35+P23
A36: ROIC (NOPAT / beg. invested capital) | C36: =IFERROR(C23/B34,"") | D36: =IFERROR(D23/C34,"") | E36: =IFERROR(E23/D34,"") | F36: =IFERROR(F23/E34,"") | G36: =IFERROR(G23/F34,"") | H36: =IFERROR(H23/G34,"") | I36: =IFERROR(I23/H34,"") | J36: =IFERROR(J23/I34,"") | ... P36: =IFERROR(P23/O34,"")
A37: ROE (earnings / beg. equity) | C37: =IFERROR(SUM(Financials!K15:N15)/B35,"") | D37: =IFERROR(SUM(Financials!O15:R15)/C35,"") | E37: =IFERROR(SUM(Financials!S15:V15)/D35,"") | F37: =IFERROR(SUM(Financials!W15:Z15)/E35,"") | G37: =IFERROR(G23/F35,"") | H37: =IFERROR(H23/G35,"") | I37: =IFERROR(I23/H35,"") | J37: =IFERROR(J23/I35,"") | K37: =IFERROR(K23/J35,"") | L37: =IFERROR(L23/K35,"") | M37: =IFERROR(M23/L35,"") | N37: =IFERROR(N23/M35,"") | ... P37: =IFERROR(P23/O35,"")
A38: ROIC - WACC spread (value created) | C38: =IFERROR(C36-WACC!$B$15,"") | D38: =IFERROR(D36-WACC!$B$15,"") | E38: =IFERROR(E36-WACC!$B$15,"") | F38: =IFERROR(F36-WACC!$B$15,"") | G38: =IFERROR(G36-WACC!$B$15,"") | H38: =IFERROR(H36-WACC!$B$15,"") | I38: =IFERROR(I36-WACC!$B$15,"") | J38: =IFERROR(J36-WACC!$B$15,"") | ... P38: =IFERROR(P36-WACC!$B$15,"")
A39: Incremental op margin (ΔEBIT / ΔRev) | C39: =IFERROR((C19-B19)/(C6-B6),"") | D39: =IFERROR((D19-C19)/(D6-C6),"") | E39: =IFERROR((E19-D19)/(E6-D6),"") | F39: =IFERROR((F19-E19)/(F6-E6),"") | G39: =IFERROR((G19-F19)/(G6-F6),"") | H39: =IFERROR((H19-G19)/(H6-G6),"") | I39: =IFERROR((I19-H19)/(I6-H6),"") | J39: =IFERROR((J19-I19)/(J6-I6),"") | ... P39: =IFERROR((P19-O19)/(P6-O6),"")
A40: ROIIC (ΔNOPAT / ΔInvested capital) | C40: =IFERROR((C23-B23)/(C34-B34),"") | D40: =IFERROR((D23-C23)/(D34-C34),"") | E40: =IFERROR((E23-D23)/(E34-D34),"") | F40: =IFERROR((F23-E23)/(F34-E34),"") | G40: =IFERROR((G23-F23)/(G34-F34),"") | H40: =IFERROR((H23-G23)/(H34-G34),"") | I40: =IFERROR((I23-H23)/(I34-H34),"") | J40: =IFERROR((J23-I23)/(J34-I34),"") | ... P40: =IFERROR((P23-O23)/(P34-O34),"")
A41: Sales-to-capital (ΔRev / ΔInvested capital) | C41: =IFERROR((C6-B6)/(C34-B34),"") | D41: =IFERROR((D6-C6)/(D34-C34),"") | E41: =IFERROR((E6-D6)/(E34-D34),"") | F41: =IFERROR((F6-E6)/(F34-E34),"") | G41: =IFERROR((G6-F6)/(G34-F34),"") | H41: =IFERROR((H6-G6)/(H34-G34),"") | I41: =IFERROR((I6-H6)/(I34-H34),"") | J41: =IFERROR((J6-I6)/(J34-I34),"") | ... P41: =IFERROR((P6-O6)/(P34-O34),"")
A42: Reinvestment rate (ΔInvested capital / NOPAT) | C42: =IFERROR((C34-B34)/C23,"") | D42: =IFERROR((D34-C34)/D23,"") | E42: =IFERROR((E34-D34)/E23,"") | F42: =IFERROR((F34-E34)/F23,"") | G42: =IFERROR((G34-F34)/G23,"") | H42: =IFERROR((H34-G34)/H23,"") | I42: =IFERROR((I34-H34)/I23,"") | J42: =IFERROR((J34-I34)/J23,"") | ... P42: =IFERROR((P34-O34)/P23,"")
A44: Blue/green = actual · Yellow = assumption · Black = formula

Sheet Financials
A1: Line Item ($M) | B1: Q4 2019 | C1: Q1 2020 | D1: Q2 2020 | E1: Q3 2020 | F1: Q4 2020 | G1: Q1 2021 | H1: Q2 2021 | I1: Q3 2021 | J1: Q4 2021 | K1: Q1 2022 | L1: Q2 2022 | M1: Q3 2022 | N1: Q4 2022 | O1: Q1 2023 | P1: Q2 2023 | Q1: Q3 2023 | R1: Q4 2023 | S1: Q1 2024 | T1: Q2 2024 | U1: Q3 2024 | V1: Q4 2024 | W1: Q1 2025 | X1: Q2 2025 | Y1: Q3 2025 | Z1: Q4 2025 | AA1: Q1 2026 | AB1: Q2 2026 | AC1: Q3 2026
A2: INCOME STATEMENT
A3: Revenue | B3: 362.728 | C3: 340.409 | D3: 666.331 | E3: 627.041 | F3: 746.29 | G3: 728.084 | H3: 786.569 | I3: 783.232 | J3: 808.006 | K3: 795.111 | L3: 806.819 | M3: 827.724 | N3: 886.962 | O3: 1344.57 | P3: 1370.285 | Q3: 1240.194 | R3: 1205.051 | S3: 1053.083 | T3: 1131.434 | U3: 1208.809 | V3: 1314.362 | W3: 1348.135 | X3: 1434.665 | Y3: 1497.879 | Z3: 1529.436 | AA3: 1581.378 | AB3: 1686 | AC3: 1805.6
A4: % YoY | F4: =IFERROR(F3/B3-1,"") | G4: =IFERROR(G3/C3-1,"") | H4: =IFERROR(H3/D3-1,"") | I4: =IFERROR(I3/E3-1,"") | J4: =IFERROR(J3/F3-1,"") | K4: =IFERROR(K3/G3-1,"") | L4: =IFERROR(L3/H3-1,"") | M4: =IFERROR(M3/I3-1,"") | ... AC4: =IFERROR(AC3/Y3-1,"")
A5: Cost of Revenue | B5: 224.076 | C5: 210.169 | D5: 437.391 | E5: 381.108 | F5: 444.153 | G5: 441.52 | H5: 473.863 | I5: 493.242 | J5: 510.213 | K5: 488.487 | L5: 495.652 | M5: 506.051 | N5: 560.93 | O5: 900.996 | P5: 959.097 | Q5: 820.038 | R5: 853.686 | S5: 746.188 | T5: 780.793 | U5: 842.322 | V5: 882.421 | W5: 888.003 | X5: 925.314 | Y5: 970.189 | Z5: 969.287 | AA5: 1002.178 | AB5: 1063 | AC5: 1125.7
A6: % of revenue | B6: =IFERROR(B5/B3,"") | C6: =IFERROR(C5/C3,"") | D6: =IFERROR(D5/D3,"") | E6: =IFERROR(E5/E3,"") | F6: =IFERROR(F5/F3,"") | G6: =IFERROR(G5/G3,"") | H6: =IFERROR(H5/H3,"") | I6: =IFERROR(I5/I3,"") | ... AC6: =IFERROR(AC5/AC3,"")
A7: R&D Expense | B7: 36.202 | C7: 36.12 | D7: 107.7 | E7: 94.764 | F7: 100.489 | G7: 78.248 | H7: 84.858 | I7: 83.231 | J7: 83.768 | K7: 88.966 | L7: 95.328 | M7: 96.895 | N7: 95.917 | O7: 121.084 | P7: 128.791 | Q7: 126.382 | R7: 123.346 | S7: 113.488 | T7: 111.163 | U7: 127.485 | V7: 126.652 | W7: 131.602 | X7: 143.852 | Y7: 150.731 | Z7: 155.739 | AA7: 154.877 | AB7: 166 | AC7: 186
A8: % of revenue | B8: =IFERROR(B7/B3,"") | C8: =IFERROR(C7/C3,"") | D8: =IFERROR(D7/D3,"") | E8: =IFERROR(E7/E3,"") | F8: =IFERROR(F7/F3,"") | G8: =IFERROR(G7/G3,"") | H8: =IFERROR(H7/H3,"") | I8: =IFERROR(I7/I3,"") | ... AC8: =IFERROR(AC7/AC3,"")
A9: SG&A Expense | B9: 61.731 | C9: 65.295 | D9: 0 | E9: 0 | F9: 0 | G9: 0 | H9: 0 | I9: 0 | J9: 0 | K9: 0 | L9: 0 | M9: 0 | N9: 0 | O9: 0 | P9: 0 | Q9: 0 | R9: 0 | S9: 0 | T9: 0 | U9: 0 | V9: 0 | W9: 0 | X9: 0 | Y9: 0 | Z9: 0 | AA9: 0 | AB9: 258 | AC9: 267.6
A10: % of revenue | B10: =IFERROR(B9/B3,"") | C10: =IFERROR(C9/C3,"") | D10: =IFERROR(D9/D3,"") | E10: =IFERROR(E9/E3,"") | F10: =IFERROR(F9/F3,"") | G10: =IFERROR(G9/G3,"") | H10: =IFERROR(H9/H3,"") | I10: =IFERROR(I9/I3,"") | ... AC10: =IFERROR(AC9/AC3,"")
A11: Gross Profit | B11: 138.652 | C11: 130.24 | D11: 228.94 | E11: 245.933 | F11: 302.137 | G11: 286.564 | H11: 312.706 | I11: 289.99 | J11: 297.793 | K11: 306.624 | L11: 311.167 | M11: 321.673 | N11: 326.032 | O11: 443.574 | P11: 411.188 | Q11: 420.156 | R11: 351.365 | S11: 306.895 | T11: 350.641 | U11: 366.487 | V11: 431.941 | W11: 460.132 | X11: 509.351 | Y11: 527.69 | Z11: 560.149 | AA11: 579.2 | AB11: 623 | AC11: 679.9
A12: gross margin | B12: =IFERROR(B11/B3,"") | C12: =IFERROR(C11/C3,"") | D12: =IFERROR(D11/D3,"") | E12: =IFERROR(E11/E3,"") | F12: =IFERROR(F11/F3,"") | G12: =IFERROR(G11/G3,"") | H12: =IFERROR(H11/H3,"") | I12: =IFERROR(I11/I3,"") | ... AC12: =IFERROR(AC11/AC3,"")
A13: Operating Income | B13: 40.719 | C13: 28.825 | D13: 2.022 | E13: 74.936 | F13: 0.796 | G13: 103.13 | H13: 118.715 | I13: 85.081 | J13: 97.193 | K13: 95.05 | L13: 98.222 | M13: 106.769 | N13: 114.253 | O13: 42.476 | P13: 8.246 | Q13: 67.388 | R13: 40.871 | S13: -18.29 | T13: 30.315 | U13: 33.835 | V13: 77.315 | W13: 99.562 | X13: 144.887 | Y13: 145.52 | Z13: 158.978 | AA13: 172.239 | AB13: 199 | AC13: 148.6
A14: operating margin | B14: =IFERROR(B13/B3,"") | C14: =IFERROR(C13/C3,"") | D14: =IFERROR(D13/D3,"") | E14: =IFERROR(E13/E3,"") | F14: =IFERROR(F13/F3,"") | G14: =IFERROR(G13/G3,"") | H14: =IFERROR(H13/H3,"") | I14: =IFERROR(I13/I3,"") | ... AC14: =IFERROR(AC13/AC3,"")
A15: Net Income | B15: 28.028 | C15: -25.998 | D15: -98.213 | E15: 5.921 | F15: 51.261 | G15: 46.266 | H15: 87.9 | I15: 81.092 | J15: 82.294 | K15: 74.464 | L15: 67.657 | M15: 49.002 | N15: 43.636 | O15: -38.698 | P15: -45.072 | Q15: 2.546 | R15: -178.234 | S15: -67.534 | T15: -26.991 | U15: -13.187 | V15: -48.442 | W15: 25.887 | X15: 103.385 | Y15: 15.711 | Z15: -95.619 | AA15: 226.349 | AB15: 147 | AC15: 191.3
A16: net margin | B16: =IFERROR(B15/B3,"") | C16: =IFERROR(C15/C3,"") | D16: =IFERROR(D15/D3,"") | E16: =IFERROR(E15/E3,"") | F16: =IFERROR(F15/F3,"") | G16: =IFERROR(G15/G3,"") | H16: =IFERROR(H15/H3,"") | I16: =IFERROR(I15/I3,"") | ... AC16: =IFERROR(AC15/AC3,"")
A17: Diluted Shares (M) | B17: 65.686 | C17: 65.97 | D17: 90.886 | E17: 93.435 | F17: 102.142 | G17: 105.247 | H17: 115.053 | I17: 116.302 | J17: 116.225 | K17: 115.849 | L17: 116.44 | M17: 116.949 | N17: 116.949 | O17: 133.28 | P17: 138.623 | Q17: 139.113 | R17: 139.342 | S17: 150.328 | T17: 151.564 | U17: 152.138 | V17: 152.6 | W17: 153.626 | X17: 159.989 | Y17: 155.2 | Z17: 155.5 | AA17: 155.5 | AB17: 155.5 | AC17: 155.5
A18: REVENUE BY SEGMENT — GEOGRAPHY (% YoY, % of revenue)
A19: North America | AC19: 1163.467
A20: % YoY | F20: =IFERROR(F19/B19-1,"") | G20: =IFERROR(G19/C19-1,"") | H20: =IFERROR(H19/D19-1,"") | I20: =IFERROR(I19/E19-1,"") | J20: =IFERROR(J19/F19-1,"") | K20: =IFERROR(K19/G19-1,"") | L20: =IFERROR(L19/H19-1,"") | M20: =IFERROR(M19/I19-1,"") | ... AC20: =IFERROR(AC19/Y19-1,"")
A21: % of revenue | B21: =IFERROR(B19/B3,"") | C21: =IFERROR(C19/C3,"") | D21: =IFERROR(D19/D3,"") | E21: =IFERROR(E19/E3,"") | F21: =IFERROR(F19/F3,"") | G21: =IFERROR(G19/G3,"") | H21: =IFERROR(H19/H3,"") | I21: =IFERROR(I19/I3,"") | ... AC21: =IFERROR(AC19/AC3,"")
A22: Europe | AC22: 214.873
A23: % YoY | F23: =IFERROR(F22/B22-1,"") | G23: =IFERROR(G22/C22-1,"") | H23: =IFERROR(H22/D22-1,"") | I23: =IFERROR(I22/E22-1,"") | J23: =IFERROR(J22/F22-1,"") | K23: =IFERROR(K22/G22-1,"") | L23: =IFERROR(L22/H22-1,"") | M23: =IFERROR(M22/I22-1,"") | ... AC23: =IFERROR(AC22/Y22-1,"")
A24: % of revenue | B24: =IFERROR(B22/B3,"") | C24: =IFERROR(C22/C3,"") | D24: =IFERROR(D22/D3,"") | E24: =IFERROR(E22/E3,"") | F24: =IFERROR(F22/F3,"") | G24: =IFERROR(G22/G3,"") | H24: =IFERROR(H22/H3,"") | I24: =IFERROR(I22/I3,"") | ... AC24: =IFERROR(AC22/AC3,"")
A25: CHINA | AC25: 206.011
A26: % YoY | F26: =IFERROR(F25/B25-1,"") | G26: =IFERROR(G25/C25-1,"") | H26: =IFERROR(H25/D25-1,"") | I26: =IFERROR(I25/E25-1,"") | J26: =IFERROR(J25/F25-1,"") | K26: =IFERROR(K25/G25-1,"") | L26: =IFERROR(L25/H25-1,"") | M26: =IFERROR(M25/I25-1,"") | ... AC26: =IFERROR(AC25/Y25-1,"")
A27: % of revenue | B27: =IFERROR(B25/B3,"") | C27: =IFERROR(C25/C3,"") | D27: =IFERROR(D25/D3,"") | E27: =IFERROR(E25/E3,"") | F27: =IFERROR(F25/F3,"") | G27: =IFERROR(G25/G3,"") | H27: =IFERROR(H25/H3,"") | I27: =IFERROR(I25/I3,"") | ... AC27: =IFERROR(AC25/AC3,"")
A28: Other Countries | AC28: 136.872
A29: % YoY | F29: =IFERROR(F28/B28-1,"") | G29: =IFERROR(G28/C28-1,"") | H29: =IFERROR(H28/D28-1,"") | I29: =IFERROR(I28/E28-1,"") | J29: =IFERROR(J28/F28-1,"") | K29: =IFERROR(K28/G28-1,"") | L29: =IFERROR(L28/H28-1,"") | M29: =IFERROR(M28/I28-1,"") | ... AC29: =IFERROR(AC28/Y28-1,"")
A30: % of revenue | B30: =IFERROR(B28/B3,"") | C30: =IFERROR(C28/C3,"") | D30: =IFERROR(D28/D3,"") | E30: =IFERROR(E28/E3,"") | F30: =IFERROR(F28/F3,"") | G30: =IFERROR(G28/G3,"") | H30: =IFERROR(H28/H3,"") | I30: =IFERROR(I28/I3,"") | ... AC30: =IFERROR(AC28/AC3,"")
A31: JAPAN | AC31: 84.418
A32: % YoY | F32: =IFERROR(F31/B31-1,"") | G32: =IFERROR(G31/C31-1,"") | H32: =IFERROR(H31/D31-1,"") | I32: =IFERROR(I31/E31-1,"") | J32: =IFERROR(J31/F31-1,"") | K32: =IFERROR(K31/G31-1,"") | L32: =IFERROR(L31/H31-1,"") | M32: =IFERROR(M31/I31-1,"") | ... AC32: =IFERROR(AC31/Y31-1,"")
A33: % of revenue | B33: =IFERROR(B31/B3,"") | C33: =IFERROR(C31/C3,"") | D33: =IFERROR(D31/D3,"") | E33: =IFERROR(E31/E3,"") | F33: =IFERROR(F31/F3,"") | G33: =IFERROR(G31/G3,"") | H33: =IFERROR(H31/H3,"") | I33: =IFERROR(I31/I3,"") | ... AC33: =IFERROR(AC31/AC3,"")
A34: BALANCE SHEET
A35: Cash & ST Investments | B35: 204.872 | C35: 439.551 | D35: 376.84 | E35: 388.107 | F35: 493.046 | G35: 683.985 | H35: 834.54 | I35: 1535.31 | J35: 1591.892 | K35: 1560.175 | L35: 2649.716 | M35: 2600.315 | N35: 2582.371 | O35: 898.501 | P35: 913.286 | Q35: 901.028 | R35: 821.31 | S35: 941.081 | T35: 856.255 | U35: 898.578 | V35: 926.033 | W35: 1019.648 | X35: 917.815 | Y35: 890.258 | Z35: 909.2 | AA35: 852.778 | AB35: 863.739 | AC35: 2417.7
A36: Total Current Assets | B36: 812.911 | C36: 1756.199 | D36: 1589.189 | E36: 1591.088 | F36: 1788.969 | G36: 1991.742 | H36: 2137.723 | I36: 2888.766 | J36: 3027.394 | K36: 3050.951 | L36: 4165.795 | M36: 4233.799 | N36: 4305.192 | O36: 3394.63 | P36: 3416.4 | Q36: 3406.644 | R36: 3251.998 | S36: 3243.731 | T36: 3421.603 | U36: 3550.234 | V36: 3660.099 | W36: 3630.287 | X36: 3497.442 | Y36: 3699.857 | Z36: 3927.154 | AA36: 4041.955 | AB36: 4393.387 | AC36: 6445.2
A37: PP&E (net) | B37: 582.79 | C37: 1335.622 | D37: 1347.147 | E37: 1247.167 | F37: 1214.772 | G37: 1218.575 | H37: 1250.48 | I37: 1232.146 | J37: 1242.906 | K37: 1242.093 | L37: 1272.377 | M37: 1320.191 | N37: 1363.195 | O37: 1803.646 | P37: 1875.558 | Q37: 1910.561 | R37: 1782.035 | S37: 1775.384 | T37: 1849.119 | U37: 1851.383 | V37: 1817.259 | W37: 1875.314 | X37: 1889.578 | Y37: 1936.436 | Z37: 1877.507 | AA37: 1944.353 | AB37: 2116.957 | AC37: 2420.1
A38: Total Assets | B38: 1953.773 | C38: 5370.686 | D38: 5208.209 | E38: 5106.823 | F38: 5234.714 | G38: 5470.619 | H38: 5646.563 | I38: 6361.72 | J38: 6512.65 | K38: 6515.862 | L38: 7649.283 | M38: 7767.196 | N38: 7844.846 | O38: 13830.559 | P38: 14108.894 | Q38: 14117.632 | R38: 13711.133 | S38: 13521.298 | T38: 14662.88 | U38: 14520.412 | V38: 14488.634 | W38: 14699.3 | X38: 14197.334 | Y38: 14444.825 | Z38: 14910.936 | AA38: 14698.845 | AB38: 15087.717 | AC38: 17286.7
A39: Total Current Liabilities | B39: 270.563 | C39: 545.777 | D39: 571.599 | E39: 569.171 | F39: 672.893 | G39: 644.893 | H39: 664.474 | I39: 678.837 | J39: 729.589 | K39: 1028.657 | L39: 2083.24 | M39: 2123.881 | N39: 1266.959 | O39: 1183.084 | P39: 1132.916 | Q39: 1107.456 | R39: 1078.748 | S39: 1083.136 | T39: 1187.773 | U39: 1310.628 | V39: 1343.767 | W39: 1357.99 | X39: 1309.288 | Y39: 1497.004 | Z39: 1794.841 | AA39: 1735.975 | AB39: 1951.088 | AC39: 2113.4
A40: Long-term Debt | B40: 443.163 | C40: 2332.612 | D40: 2228.207 | E40: 2213.175 | F40: 2186.092 | G40: 1468.096 | H40: 1408.79 | I40: 1323.402 | J40: 1313.091 | K40: 956.377 | L40: 942.579 | M40: 928.745 | N40: 1897.214 | O40: 4494.282 | P40: 4422.817 | Q40: 4349.923 | R40: 4234.962 | S40: 4219.366 | T40: 4137.009 | U40: 4082.656 | V40: 4026.448 | W40: 3918.841 | X40: 3832.694 | Y40: 3727.13 | Z40: 3498.615 | AA40: 3259.406 | AB40: 3245.403 | AC40: 3184.8
...

Sheet Consensus
A1: Full consensus check — model vs Street (FMP estimates, $M)
A2: Fiscal year | B2: 2026 | C2: 2027 | D2: 2028 | E2: 2029
A3: EVERY AVAILABLE FMP CONSENSUS FIELD (consensus / model / % diff)
A4: Revenue — consensus | B4: 7057.4005 | C4: 9615.7187 | D4: 12751.607 | E4: 20189.75
A5: model | B5: =Model!G6 | C5: =Model!H6 | D5: =Model!I6 | E5: =Model!J6
A6: vs consensus | B6: =IFERROR(B5/B4-1,"") | C6: =IFERROR(C5/C4-1,"") | D6: =IFERROR(D5/D4-1,"") | E6: =IFERROR(E5/E4-1,"")
A8: EBITDA* — consensus | B8: 1335.4471 | C8: 1819.5487 | D8: 2412.9418 | E8: 3820.4357
A9: model | B9: =Model!G19+Model!G24 | C9: =Model!H19+Model!H24 | D9: =Model!I19+Model!I24 | E9: =Model!J19+Model!J24
A10: vs consensus | B10: =IFERROR(B9/B8-1,"") | C10: =IFERROR(C9/C8-1,"") | D10: =IFERROR(D9/D8-1,"") | E10: =IFERROR(E9/E8-1,"")
A12: EBIT* — consensus | B12: 601.88143 | C12: 820.06434 | D12: 1087.5045 | E12: 1721.8572
A13: model | B13: =Model!G19 | C13: =Model!H19 | D13: =Model!I19 | E13: =Model!J19
A14: vs consensus | B14: =IFERROR(B13/B12-1,"") | C14: =IFERROR(C13/C12-1,"") | D14: =IFERROR(D13/D12-1,"") | E14: =IFERROR(E13/E12-1,"")
A16: SG&A — consensus | B16: 201.76501 | C16: 274.90513 | D16: 364.55747 | E16: 577.20761
A17: model | B17: =Model!G14 | C17: =Model!H14 | D17: =Model!I14 | E17: =Model!J14
A18: vs consensus | B18: =IFERROR(B17/B16-1,"") | C18: =IFERROR(C17/C16-1,"") | D18: =IFERROR(D17/D16-1,"") | E18: =IFERROR(E17/E16-1,"")
A20: Net income (NOPAT) — consensus | B20: 847.66004 | C20: 1184.2 | D20: 1787.1667 | E20: 0
A21: model | B21: =Model!G23 | C21: =Model!H23 | D21: =Model!I23 | E21: =Model!J23
A22: vs consensus | B22: =IFERROR(B21/B20-1,"") | C22: =IFERROR(C21/C20-1,"") | D22: =IFERROR(D21/D20-1,"") | E22: =IFERROR(E21/E20-1,"")
A24: EPS — consensus | B24: 5.45593 | C24: 8.21542 | D24: 12.07792 | E24: 0
A25: model | B25: =Model!G23/Financials!AC17 | C25: =Model!H23/Financials!AC17 | D25: =Model!I23/Financials!AC17 | E25: =Model!J23/Financials!AC17
A26: vs consensus | B26: =IFERROR(B25/B24-1,"") | C26: =IFERROR(C25/C24-1,"") | D26: =IFERROR(D25/D24-1,"") | E26: =IFERROR(E25/E24-1,"")
A28: Defaults anchored to consensus revenue + net income (≈0% diff). Other rows show where the model sits vs Street.
A29: *FMP's EBITDA/EBIT estimates look unreliable for AMZN (it reports NI > EBIT) — don't over-read those two.

Sheet Valuation
A1: Coherent, Inc. — DCF Valuation
A2: Current price | B2: =Dashboard!$B$48
A3: WACC | B3: =WACC!B15
A4: Terminal growth (g) | B4: =Dashboard!$B$46
A5: Tax rate | B5: =Dashboard!$B$31
A6: Terminal method | B6: =Dashboard!$B$43
A7: Exit basis | B7: =Dashboard!$B$44
A8: Exit multiple | B8: =Dashboard!$B$45
A11: Forecast year | C11: 2026 | D11: 2027 | E11: 2028 | F11: 2029 | G11: 2030 | H11: 2031 | I11: 2032 | J11: 2033 | K11: 2034 | L11: 2035
A12: FCFF ($M) | C12: =Model!G31 | D12: =Model!H31 | E12: =Model!I31 | F12: =Model!J31 | G12: =Model!K31 | H12: =Model!L31 | I12: =Model!M31 | J12: =Model!N31 | ... L12: =Model!P31
A13: PV factor | C13: =1/(1+$B$3)^1 | D13: =1/(1+$B$3)^2 | E13: =1/(1+$B$3)^3 | F13: =1/(1+$B$3)^4 | G13: =1/(1+$B$3)^5 | H13: =1/(1+$B$3)^6 | I13: =1/(1+$B$3)^7 | J13: =1/(1+$B$3)^8 | K13: =1/(1+$B$3)^9 | L13: =1/(1+$B$3)^10
A14: PV of FCFF ($M) | C14: =C12*C13 | D14: =D12*D13 | E14: =E12*E13 | F14: =F12*F13 | G14: =G12*G13 | H14: =H12*H13 | I14: =I12*I13 | J14: =J12*J13 | ... L14: =L12*L13
A16: Sum PV of FCFF | B16: =SUM(C14:L14)
A18: TERMINAL VALUE (exit multiple = default; perpetuity = cross-check)
A19: Terminal-year FCFF | B19: =L12
A20: Terminal revenue | B20: =Model!P6
A21: Terminal EBIT | B21: =Model!P19
A22: Terminal EBITDA (SBC-burdened) | B22: =Model!P19+Model!P24-Model!P25
A23: Terminal metric (per exit basis) | B23: =IF($B$7="EV/EBITDA",B22,IF($B$7="EV/Sales",B20,IF($B$7="EV/EBIT",B21,B19)))
A24: TV (exit) = metric x multiple | B24: =B23*$B$8
A25: PV of TV — exit multiple | B25: =B24/(1+$B$3)^10
A26: TV (perpetuity) = FCFF(1+g)/(WACC-g) | B26: =B19*(1+$B$4)/($B$3-$B$4)
A27: PV of TV — perpetuity | B27: =B26/(1+$B$3)^10
A28: PV of TV — SELECTED | B28: =IF($B$6="Perpetuity",B27,B25)
A30: EQUITY BRIDGE -> VALUE / SHARE
A31: Operating value (enterprise value) | B31: =B16+B28
A32: + Cash & ST investments | B32: =Financials!AC35
A33: - Long-term debt | B33: =-Financials!AC40
A34: Equity value | B34: =B31+B32+B33
A35: Diluted shares (M) | B35: =Financials!AC17
A36: VALUE / SHARE | B36: =B34/B35*1.0
A38: CROSS-CHECKS & RETURN
A39: Terminal weight (% of EV) | B39: =B28/B31
A40: Implied perpetuity g (from exit multiple) | B40: =(B24*$B$3-B19)/(B24+B19)
A41: Implied exit EV/EBITDA (from perpetuity) | B41: =B26/B22
A42: Upside / (downside) to fair value | B42: =B36/$B$2-1
A44: Owner cashflow / share | B44: =-$B$2 | C44: =C12/B35 | D44: =D12/B35 | E44: =E12/B35 | F44: =F12/B35 | G44: =G12/B35 | H44: =H12/B35 | I44: =I12/B35 | J44: =J12/B35 | K44: =K12/B35 | L44: =L12/B35+B36
A45: IRR (buy at price, hold 10y) | B45: =IRR(B44:L44)

Sheet Sensitivity
A1: Sensitivity — fair value / share (USD)
A2: WACC x exit multiple (EV/EBITDA). Static grid recomputed by every rebuild/refresh — edit the Dashboard, re-run refresh_dcf to update. Shaded = base case; green = above current price.
A4: EV/EBITDA x \ WACC | B4: 0.12051982 | C4: 0.12551982 | D4: 0.13051982 | E4: 0.13551982 | F4: 0.14051982 | G4: 0.14551982 | H4: 0.15051982
A5: 9 | B5: 192.94248 | C5: 185.73505 | D5: 178.84721 | E5: 172.26306 | F5: 165.96753 | G5: 159.94639 | H5: 154.18617
A6: 10 | B6: 206.8389 | C6: 199.02633 | D6: 191.56222 | E6: 184.42916 | F6: 177.61067 | G6: 171.09119 | H6: 164.85599
A7: 11 | B7: 220.73532 | C7: 212.31762 | D7: 204.27723 | E7: 196.59525 | F7: 189.25381 | G7: 182.23599 | H7: 175.52582
A8: 12 | B8: 234.63175 | C8: 225.6089 | D8: 216.99224 | E8: 208.76135 | F8: 200.89695 | G8: 193.3808 | H8: 186.19565
A9: 13 | B9: 248.52817 | C9: 238.90019 | D9: 229.70725 | E9: 220.92745 | F9: 212.54009 | G9: 204.5256 | H9: 196.86548
A10: 14 | B10: 262.42459 | C10: 252.19148 | D10: 242.42226 | E10: 233.09355 | F10: 224.18323 | G10: 215.6704 | H10: 207.53531
A11: 15 | B11: 276.32102 | C11: 265.48276 | D11: 255.13727 | E11: 245.25964 | F11: 235.82637 | G11: 226.8152 | H11: 218.20514
A13: Current price | B13: 314.98001
A14: Base WACC / multiple | B14: 0.13551982 | C14: 12

Sheet Monte Carlo
A1: Monte Carlo simulation (live) | H1: SIMULATION ENGINE — leave as-is | K1: cagr | L1: term margin | M1: wacc | N1: exit | O1: value/share
A2: 1,000 trials, recomputed in-sheet on every edit. Edit the yellow driver distributions to re-roll. Engine grid is to the right (cols H+). | H2: R0 (base revenue) | I2: =Model!F6 | K2: =MAX(-0.05,NORMINV(RAND(),$C$6,$D$6)) | L2: =MAX(0.02,NORMINV(RAND(),$C$7,$D$7)) | M2: =MIN(0.16,MAX(0.05,NORMINV(RAND(),$C$8,$D$8))) | N2: =MIN(24,MAX(5,NORMINV(RAND(),$C$9,$D$9))) | O2: =$I$8*(SUMPRODUCT(($I$2*(1+K2)^{1;2;3;4;5;6;7;8;9;10})*(($I$3+(L2-$I$3)*{1;2;3;4;5;6;7;8;9;10}/10)*(1-$I$7)+$I$4-$I$4*($I$5+(1.05-$I$5)*{1;2;3;4;5;6;7;8;9;10}/10)-(K2/(1+K2))*$I$6)/(1+M2)^{1;2;3;4;5;6;7;8;9;10})+$I$2*(1+K2)^10*(L2+$I$4)*N2/(1+M2)^10+$I$9-$I$10)/$I$11
H3: m0 (base op margin) | I3: =Model!F20 | K3: =MAX(-0.05,NORMINV(RAND(),$C$6,$D$6)) | L3: =MAX(0.02,NORMINV(RAND(),$C$7,$D$7)) | M3: =MIN(0.16,MAX(0.05,NORMINV(RAND(),$C$8,$D$8))) | N3: =MIN(24,MAX(5,NORMINV(RAND(),$C$9,$D$9))) | O3: =$I$8*(SUMPRODUCT(($I$2*(1+K3)^{1;2;3;4;5;6;7;8;9;10})*(($I$3+(L3-$I$3)*{1;2;3;4;5;6;7;8;9;10}/10)*(1-$I$7)+$I$4-$I$4*($I$5+(1.05-$I$5)*{1;2;3;4;5;6;7;8;9;10}/10)-(K3/(1+K3))*$I$6)/(1+M3)^{1;2;3;4;5;6;7;8;9;10})+$I$2*(1+K3)^10*(L3+$I$4)*N3/(1+M3)^10+$I$9-$I$10)/$I$11
A4: DRIVER DISTRIBUTIONS (yellow = edit; Opus-set defaults) | H4: da (D&A / revenue) | I4: 0.11517263 | K4: =MAX(-0.05,NORMINV(RAND(),$C$6,$D$6)) | L4: =MAX(0.02,NORMINV(RAND(),$C$7,$D$7)) | M4: =MIN(0.16,MAX(0.05,NORMINV(RAND(),$C$8,$D$8))) | N4: =MIN(24,MAX(5,NORMINV(RAND(),$C$9,$D$9))) | O4: =$I$8*(SUMPRODUCT(($I$2*(1+K4)^{1;2;3;4;5;6;7;8;9;10})*(($I$3+(L4-$I$3)*{1;2;3;4;5;6;7;8;9;10}/10)*(1-$I$7)+$I$4-$I$4*($I$5+(1.05-$I$5)*{1;2;3;4;5;6;7;8;9;10}/10)-(K4/(1+K4))*$I$6)/(1+M4)^{1;2;3;4;5;6;7;8;9;10})+$I$2*(1+K4)^10*(L4+$I$4)*N4/(1+M4)^10+$I$9-$I$10)/$I$11
A5: Driver | B5: Dist | C5: Mean | D5: Std dev | H5: cda0 (2026 capex/D&A) | I5: 0.65119638 | K5: =MAX(-0.05,NORMINV(RAND(),$C$6,$D$6)) | L5: =MAX(0.02,NORMINV(RAND(),$C$7,$D$7)) | M5: =MIN(0.16,MAX(0.05,NORMINV(RAND(),$C$8,$D$8))) | N5: =MIN(24,MAX(5,NORMINV(RAND(),$C$9,$D$9))) | O5: =$I$8*(SUMPRODUCT(($I$2*(1+K5)^{1;2;3;4;5;6;7;8;9;10})*(($I$3+(L5-$I$3)*{1;2;3;4;5;6;7;8;9;10}/10)*(1-$I$7)+$I$4-$I$4*($I$5+(1.05-$I$5)*{1;2;3;4;5;6;7;8;9;10}/10)-(K5/(1+K5))*$I$6)/(1+M5)^{1;2;3;4;5;6;7;8;9;10})+$I$2*(1+K5)^10*(L5+$I$4)*N5/(1+M5)^10+$I$9-$I$10)/$I$11
A6: Revenue 10y CAGR | B6: Normal | C6: =(Model!P6/Model!F6)^(1/10)-1 | D6: 0.03 | H6: nwc (% incr revenue) | I6: 0.005 | K6: =MAX(-0.05,NORMINV(RAND(),$C$6,$D$6)) | L6: =MAX(0.02,NORMINV(RAND(),$C$7,$D$7)) | M6: =MIN(0.16,MAX(0.05,NORMINV(RAND(),$C$8,$D$8))) | N6: =MIN(24,MAX(5,NORMINV(RAND(),$C$9,$D$9))) | O6: =$I$8*(SUMPRODUCT(($I$2*(1+K6)^{1;2;3;4;5;6;7;8;9;10})*(($I$3+(L6-$I$3)*{1;2;3;4;5;6;7;8;9;10}/10)*(1-$I$7)+$I$4-$I$4*($I$5+(1.05-$I$5)*{1;2;3;4;5;6;7;8;9;10}/10)-(K6/(1+K6))*$I$6)/(1+M6)^{1;2;3;4;5;6;7;8;9;10})+$I$2*(1+K6)^10*(L6+$I$4)*N6/(1+M6)^10+$I$9-$I$10)/$I$11
A7: Terminal operating margin | B7: Normal | C7: =Dashboard!$B$30 | D7: 0.03 | H7: tax | I7: =Valuation!$B$5 | K7: =MAX(-0.05,NORMINV(RAND(),$C$6,$D$6)) | L7: =MAX(0.02,NORMINV(RAND(),$C$7,$D$7)) | M7: =MIN(0.16,MAX(0.05,NORMINV(RAND(),$C$8,$D$8))) | N7: =MIN(24,MAX(5,NORMINV(RAND(),$C$9,$D$9))) | O7: =$I$8*(SUMPRODUCT(($I$2*(1+K7)^{1;2;3;4;5;6;7;8;9;10})*(($I$3+(L7-$I$3)*{1;2;3;4;5;6;7;8;9;10}/10)*(1-$I$7)+$I$4-$I$4*($I$5+(1.05-$I$5)*{1;2;3;4;5;6;7;8;9;10}/10)-(K7/(1+K7))*$I$6)/(1+M7)^{1;2;3;4;5;6;7;8;9;10})+$I$2*(1+K7)^10*(L7+$I$4)*N7/(1+M7)^10+$I$9-$I$10)/$I$11
A8: WACC | B8: Normal | C8: =WACC!B15 | D8: 0.005 | H8: k (calibration) | I8: 0.98528347 | K8: =MAX(-0.05,NORMINV(RAND(),$C$6,$D$6)) | L8: =MAX(0.02,NORMINV(RAND(),$C$7,$D$7)) | M8: =MIN(0.16,MAX(0.05,NORMINV(RAND(),$C$8,$D$8))) | N8: =MIN(24,MAX(5,NORMINV(RAND(),$C$9,$D$9))) | O8: =$I$8*(SUMPRODUCT(($I$2*(1+K8)^{1;2;3;4;5;6;7;8;9;10})*(($I$3+(L8-$I$3)*{1;2;3;4;5;6;7;8;9;10}/10)*(1-$I$7)+$I$4-$I$4*($I$5+(1.05-$I$5)*{1;2;3;4;5;6;7;8;9;10}/10)-(K8/(1+K8))*$I$6)/(1+M8)^{1;2;3;4;5;6;7;8;9;10})+$I$2*(1+K8)^10*(L8+$I$4)*N8/(1+M8)^10+$I$9-$I$10)/$I$11
A9: Exit EV/EBITDA multiple | B9: Normal | C9: =Dashboard!$B$45 | D9: 1.5 | H9: cash | I9: =Financials!AC35 | K9: =MAX(-0.05,NORMINV(RAND(),$C$6,$D$6)) | L9: =MAX(0.02,NORMINV(RAND(),$C$7,$D$7)) | M9: =MIN(0.16,MAX(0.05,NORMINV(RAND(),$C$8,$D$8))) | N9: =MIN(24,MAX(5,NORMINV(RAND(),$C$9,$D$9))) | O9: =$I$8*(SUMPRODUCT(($I$2*(1+K9)^{1;2;3;4;5;6;7;8;9;10})*(($I$3+(L9-$I$3)*{1;2;3;4;5;6;7;8;9;10}/10)*(1-$I$7)+$I$4-$I$4*($I$5+(1.05-$I$5)*{1;2;3;4;5;6;7;8;9;10}/10)-(K9/(1+K9))*$I$6)/(1+M9)^{1;2;3;4;5;6;7;8;9;10})+$I$2*(1+K9)^10*(L9+$I$4)*N9/(1+M9)^10+$I$9-$I$10)/$I$11
H10: debt | I10: =Financials!AC40 | K10: =MAX(-0.05,NORMINV(RAND(),$C$6,$D$6)) | L10: =MAX(0.02,NORMINV(RAND(),$C$7,$D$7)) | M10: =MIN(0.16,MAX(0.05,NORMINV(RAND(),$C$8,$D$8))) | N10: =MIN(24,MAX(5,NORMINV(RAND(),$C$9,$D$9))) | O10: =$I$8*(SUMPRODUCT(($I$2*(1+K10)^{1;2;3;4;5;6;7;8;9;10})*(($I$3+(L10-$I$3)*{1;2;3;4;5;6;7;8;9;10}/10)*(1-$I$7)+$I$4-$I$4*($I$5+(1.05-$I$5)*{1;2;3;4;5;6;7;8;9;10}/10)-(K10/(1+K10))*$I$6)/(1+M10)^{1;2;3;4;5;6;7;8;9;10})+$I$2*(1+K10)^10*(L10+$I$4)*N10/(1+M10)^10+$I$9-$I$10)/$I$11
A11: SIMULATION OUTPUT — value / share (live) | H11: shares | I11: =Financials!AC17 | K11: =MAX(-0.05,NORMINV(RAND(),$C$6,$D$6)) | L11: =MAX(0.02,NORMINV(RAND(),$C$7,$D$7)) | M11: =MIN(0.16,MAX(0.05,NORMINV(RAND(),$C$8,$D$8))) | N11: =MIN(24,MAX(5,NORMINV(RAND(),$C$9,$D$9))) | O11: =$I$8*(SUMPRODUCT(($I$2*(1+K11)^{1;2;3;4;5;6;7;8;9;10})*(($I$3+(L11-$I$3)*{1;2;3;4;5;6;7;8;9;10}/10)*(1-$I$7)+$I$4-$I$4*($I$5+(1.05-$I$5)*{1;2;3;4;5;6;7;8;9;10}/10)-(K11/(1+K11))*$I$6)/(1+M11)^{1;2;3;4;5;6;7;8;9;10})+$I$2*(1+K11)^10*(L11+$I$4)*N11/(1+M11)^10+$I$9-$I$10)/$I$11
A12: Mean | B12: =AVERAGE($O$2:$O$1001) | K12: =MAX(-0.05,NORMINV(RAND(),$C$6,$D$6)) | L12: =MAX(0.02,NORMINV(RAND(),$C$7,$D$7)) | M12: =MIN(0.16,MAX(0.05,NORMINV(RAND(),$C$8,$D$8))) | N12: =MIN(24,MAX(5,NORMINV(RAND(),$C$9,$D$9))) | O12: =$I$8*(SUMPRODUCT(($I$2*(1+K12)^{1;2;3;4;5;6;7;8;9;10})*(($I$3+(L12-$I$3)*{1;2;3;4;5;6;7;8;9;10}/10)*(1-$I$7)+$I$4-$I$4*($I$5+(1.05-$I$5)*{1;2;3;4;5;6;7;8;9;10}/10)-(K12/(1+K12))*$I$6)/(1+M12)^{1;2;3;4;5;6;7;8;9;10})+$I$2*(1+K12)^10*(L12+$I$4)*N12/(1+M12)^10+$I$9-$I$10)/$I$11
A13: Median (P50) | B13: =MEDIAN($O$2:$O$1001) | K13: =MAX(-0.05,NORMINV(RAND(),$C$6,$D$6)) | L13: =MAX(0.02,NORMINV(RAND(),$C$7,$D$7)) | M13: =MIN(0.16,MAX(0.05,NORMINV(RAND(),$C$8,$D$8))) | N13: =MIN(24,MAX(5,NORMINV(RAND(),$C$9,$D$9))) | O13: =$I$8*(SUMPRODUCT(($I$2*(1+K13)^{1;2;3;4;5;6;7;8;9;10})*(($I$3+(L13-$I$3)*{1;2;3;4;5;6;7;8;9;10}/10)*(1-$I$7)+$I$4-$I$4*($I$5+(1.05-$I$5)*{1;2;3;4;5;6;7;8;9;10}/10)-(K13/(1+K13))*$I$6)/(1+M13)^{1;2;3;4;5;6;7;8;9;10})+$I$2*(1+K13)^10*(L13+$I$4)*N13/(1+M13)^10+$I$9-$I$10)/$I$11
A14: Std dev | B14: =STDEV($O$2:$O$1001) | K14: =MAX(-0.05,NORMINV(RAND(),$C$6,$D$6)) | L14: =MAX(0.02,NORMINV(RAND(),$C$7,$D$7)) | M14: =MIN(0.16,MAX(0.05,NORMINV(RAND(),$C$8,$D$8))) | N14: =MIN(24,MAX(5,NORMINV(RAND(),$C$9,$D$9))) | O14: =$I$8*(SUMPRODUCT(($I$2*(1+K14)^{1;2;3;4;5;6;7;8;9;10})*(($I$3+(L14-$I$3)*{1;2;3;4;5;6;7;8;9;10}/10)*(1-$I$7)+$I$4-$I$4*($I$5+(1.05-$I$5)*{1;2;3;4;5;6;7;8;9;10}/10)-(K14/(1+K14))*$I$6)/(1+M14)^{1;2;3;4;5;6;7;8;9;10})+$I$2*(1+K14)^10*(L14+$I$4)*N14/(1+M14)^10+$I$9-$I$10)/$I$11
A15: Min | B15: =MIN($O$2:$O$1001) | K15: =MAX(-0.05,NORMINV(RAND(),$C$6,$D$6)) | L15: =MAX(0.02,NORMINV(RAND(),$C$7,$D$7)) | M15: =MIN(0.16,MAX(0.05,NORMINV(RAND(),$C$8,$D$8))) | N15: =MIN(24,MAX(5,NORMINV(RAND(),$C$9,$D$9))) | O15: =$I$8*(SUMPRODUCT(($I$2*(1+K15)^{1;2;3;4;5;6;7;8;9;10})*(($I$3+(L15-$I$3)*{1;2;3;4;5;6;7;8;9;10}/10)*(1-$I$7)+$I$4-$I$4*($I$5+(1.05-$I$5)*{1;2;3;4;5;6;7;8;9;10}/10)-(K15/(1+K15))*$I$6)/(1+M15)^{1;2;3;4;5;6;7;8;9;10})+$I$2*(1+K15)^10*(L15+$I$4)*N15/(1+M15)^10+$I$9-$I$10)/$I$11
A16: Max | B16: =MAX($O$2:$O$1001) | K16: =MAX(-0.05,NORMINV(RAND(),$C$6,$D$6)) | L16: =MAX(0.02,NORMINV(RAND(),$C$7,$D$7)) | M16: =MIN(0.16,MAX(0.05,NORMINV(RAND(),$C$8,$D$8))) | N16: =MIN(24,MAX(5,NORMINV(RAND(),$C$9,$D$9))) | O16: =$I$8*(SUMPRODUCT(($I$2*(1+K16)^{1;2;3;4;5;6;7;8;9;10})*(($I$3+(L16-$I$3)*{1;2;3;4;5;6;7;8;9;10}/10)*(1-$I$7)+$I$4-$I$4*($I$5+(1.05-$I$5)*{1;2;3;4;5;6;7;8;9;10}/10)-(K16/(1+K16))*$I$6)/(1+M16)^{1;2;3;4;5;6;7;8;9;10})+$I$2*(1+K16)^10*(L16+$I$4)*N16/(1+M16)^10+$I$9-$I$10)/$I$11
A17: Current price | B17: =Valuation!$B$2 | K17: =MAX(-0.05,NORMINV(RAND(),$C$6,$D$6)) | L17: =MAX(0.02,NORMINV(RAND(),$C$7,$D$7)) | M17: =MIN(0.16,MAX(0.05,NORMINV(RAND(),$C$8,$D$8))) | N17: =MIN(24,MAX(5,NORMINV(RAND(),$C$9,$D$9))) | O17: =$I$8*(SUMPRODUCT(($I$2*(1+K17)^{1;2;3;4;5;6;7;8;9;10})*(($I$3+(L17-$I$3)*{1;2;3;4;5;6;7;8;9;10}/10)*(1-$I$7)+$I$4-$I$4*($I$5+(1.05-$I$5)*{1;2;3;4;5;6;7;8;9;10}/10)-(K17/(1+K17))*$I$6)/(1+M17)^{1;2;3;4;5;6;7;8;9;10})+$I$2*(1+K17)^10*(L17+$I$4)*N17/(1+M17)^10+$I$9-$I$10)/$I$11
A18: Base case (full model) | B18: =Valuation!B36 | K18: =MAX(-0.05,NORMINV(RAND(),$C$6,$D$6)) | L18: =MAX(0.02,NORMINV(RAND(),$C$7,$D$7)) | M18: =MIN(0.16,MAX(0.05,NORMINV(RAND(),$C$8,$D$8))) | N18: =MIN(24,MAX(5,NORMINV(RAND(),$C$9,$D$9))) | O18: =$I$8*(SUMPRODUCT(($I$2*(1+K18)^{1;2;3;4;5;6;7;8;9;10})*(($I$3+(L18-$I$3)*{1;2;3;4;5;6;7;8;9;10}/10)*(1-$I$7)+$I$4-$I$4*($I$5+(1.05-$I$5)*{1;2;3;4;5;6;7;8;9;10}/10)-(K18/(1+K18))*$I$6)/(1+M18)^{1;2;3;4;5;6;7;8;9;10})+$I$2*(1+K18)^10*(L18+$I$4)*N18/(1+M18)^10+$I$9-$I$10)/$I$11
K19: =MAX(-0.05,NORMINV(RAND(),$C$6,$D$6)) | L19: =MAX(0.02,NORMINV(RAND(),$C$7,$D$7)) | M19: =MIN(0.16,MAX(0.05,NORMINV(RAND(),$C$8,$D$8))) | N19: =MIN(24,MAX(5,NORMINV(RAND(),$C$9,$D$9))) | O19: =$I$8*(SUMPRODUCT(($I$2*(1+K19)^{1;2;3;4;5;6;7;8;9;10})*(($I$3+(L19-$I$3)*{1;2;3;4;5;6;7;8;9;10}/10)*(1-$I$7)+$I$4-$I$4*($I$5+(1.05-$I$5)*{1;2;3;4;5;6;7;8;9;10}/10)-(K19/(1+K19))*$I$6)/(1+M19)^{1;2;3;4;5;6;7;8;9;10})+$I$2*(1+K19)^10*(L19+$I$4)*N19/(1+M19)^10+$I$9-$I$10)/$I$11
A20: P(undervalued at current price) | B20: =COUNTIF($O$2:$O$1001,">"&Valuation!$B$2)/1000 | K20: =MAX(-0.05,NORMINV(RAND(),$C$6,$D$6)) | L20: =MAX(0.02,NORMINV(RAND(),$C$7,$D$7)) | M20: =MIN(0.16,MAX(0.05,NORMINV(RAND(),$C$8,$D$8))) | N20: =MIN(24,MAX(5,NORMINV(RAND(),$C$9,$D$9))) | O20: =$I$8*(SUMPRODUCT(($I$2*(1+K20)^{1;2;3;4;5;6;7;8;9;10})*(($I$3+(L20-$I$3)*{1;2;3;4;5;6;7;8;9;10}/10)*(1-$I$7)+$I$4-$I$4*($I$5+(1.05-$I$5)*{1;2;3;4;5;6;7;8;9;10}/10)-(K20/(1+K20))*$I$6)/(1+M20)^{1;2;3;4;5;6;7;8;9;10})+$I$2*(1+K20)^10*(L20+$I$4)*N20/(1+M20)^10+$I$9-$I$10)/$I$11
A21: P(>20% upside) | B21: =COUNTIF($O$2:$O$1001,">"&Valuation!$B$2*1.2)/1000 | K21: =MAX(-0.05,NORMINV(RAND(),$C$6,$D$6)) | L21: =MAX(0.02,NORMINV(RAND(),$C$7,$D$7)) | M21: =MIN(0.16,MAX(0.05,NORMINV(RAND(),$C$8,$D$8))) | N21: =MIN(24,MAX(5,NORMINV(RAND(),$C$9,$D$9))) | O21: =$I$8*(SUMPRODUCT(($I$2*(1+K21)^{1;2;3;4;5;6;7;8;9;10})*(($I$3+(L21-$I$3)*{1;2;3;4;5;6;7;8;9;10}/10)*(1-$I$7)+$I$4-$I$4*($I$5+(1.05-$I$5)*{1;2;3;4;5;6;7;8;9;10}/10)-(K21/(1+K21))*$I$6)/(1+M21)^{1;2;3;4;5;6;7;8;9;10})+$I$2*(1+K21)^10*(L21+$I$4)*N21/(1+M21)^10+$I$9-$I$10)/$I$11
K22: =MAX(-0.05,NORMINV(RAND(),$C$6,$D$6)) | L22: =MAX(0.02,NORMINV(RAND(),$C$7,$D$7)) | M22: =MIN(0.16,MAX(0.05,NORMINV(RAND(),$C$8,$D$8))) | N22: =MIN(24,MAX(5,NORMINV(RAND(),$C$9,$D$9))) | O22: =$I$8*(SUMPRODUCT(($I$2*(1+K22)^{1;2;3;4;5;6;7;8;9;10})*(($I$3+(L22-$I$3)*{1;2;3;4;5;6;7;8;9;10}/10)*(1-$I$7)+$I$4-$I$4*($I$5+(1.05-$I$5)*{1;2;3;4;5;6;7;8;9;10}/10)-(K22/(1+K22))*$I$6)/(1+M22)^{1;2;3;4;5;6;7;8;9;10})+$I$2*(1+K22)^10*(L22+$I$4)*N22/(1+M22)^10+$I$9-$I$10)/$I$11
A23: PERCENTILES (live) | K23: =MAX(-0.05,NORMINV(RAND(),$C$6,$D$6)) | L23: =MAX(0.02,NORMINV(RAND(),$C$7,$D$7)) | M23: =MIN(0.16,MAX(0.05,NORMINV(RAND(),$C$8,$D$8))) | N23: =MIN(24,MAX(5,NORMINV(RAND(),$C$9,$D$9))) | O23: =$I$8*(SUMPRODUCT(($I$2*(1+K23)^{1;2;3;4;5;6;7;8;9;10})*(($I$3+(L23-$I$3)*{1;2;3;4;5;6;7;8;9;10}/10)*(1-$I$7)+$I$4-$I$4*($I$5+(1.05-$I$5)*{1;2;3;4;5;6;7;8;9;10}/10)-(K23/(1+K23))*$I$6)/(1+M23)^{1;2;3;4;5;6;7;8;9;10})+$I$2*(1+K23)^10*(L23+$I$4)*N23/(1+M23)^10+$I$9-$I$10)/$I$11
A24: P5 | B24: =PERCENTILE($O$2:$O$1001,0.05) | K24: =MAX(-0.05,NORMINV(RAND(),$C$6,$D$6)) | L24: =MAX(0.02,NORMINV(RAND(),$C$7,$D$7)) | M24: =MIN(0.16,MAX(0.05,NORMINV(RAND(),$C$8,$D$8))) | N24: =MIN(24,MAX(5,NORMINV(RAND(),$C$9,$D$9))) | O24: =$I$8*(SUMPRODUCT(($I$2*(1+K24)^{1;2;3;4;5;6;7;8;9;10})*(($I$3+(L24-$I$3)*{1;2;3;4;5;6;7;8;9;10}/10)*(1-$I$7)+$I$4-$I$4*($I$5+(1.05-$I$5)*{1;2;3;4;5;6;7;8;9;10}/10)-(K24/(1+K24))*$I$6)/(1+M24)^{1;2;3;4;5;6;7;8;9;10})+$I$2*(1+K24)^10*(L24+$I$4)*N24/(1+M24)^10+$I$9-$I$10)/$I$11
A25: P10 | B25: =PERCENTILE($O$2:$O$1001,0.1) | K25: =MAX(-0.05,NORMINV(RAND(),$C$6,$D$6)) | L25: =MAX(0.02,NORMINV(RAND(),$C$7,$D$7)) | M25: =MIN(0.16,MAX(0.05,NORMINV(RAND(),$C$8,$D$8))) | N25: =MIN(24,MAX(5,NORMINV(RAND(),$C$9,$D$9))) | O25: =$I$8*(SUMPRODUCT(($I$2*(1+K25)^{1;2;3;4;5;6;7;8;9;10})*(($I$3+(L25-$I$3)*{1;2;3;4;5;6;7;8;9;10}/10)*(1-$I$7)+$I$4-$I$4*($I$5+(1.05-$I$5)*{1;2;3;4;5;6;7;8;9;10}/10)-(K25/(1+K25))*$I$6)/(1+M25)^{1;2;3;4;5;6;7;8;9;10})+$I$2*(1+K25)^10*(L25+$I$4)*N25/(1+M25)^10+$I$9-$I$10)/$I$11
A26: P25 | B26: =PERCENTILE($O$2:$O$1001,0.25) | K26: =MAX(-0.05,NORMINV(RAND(),$C$6,$D$6)) | L26: =MAX(0.02,NORMINV(RAND(),$C$7,$D$7)) | M26: =MIN(0.16,MAX(0.05,NORMINV(RAND(),$C$8,$D$8))) | N26: =MIN(24,MAX(5,NORMINV(RAND(),$C$9,$D$9))) | O26: =$I$8*(SUMPRODUCT(($I$2*(1+K26)^{1;2;3;4;5;6;7;8;9;10})*(($I$3+(L26-$I$3)*{1;2;3;4;5;6;7;8;9;10}/10)*(1-$I$7)+$I$4-$I$4*($I$5+(1.05-$I$5)*{1;2;3;4;5;6;7;8;9;10}/10)-(K26/(1+K26))*$I$6)/(1+M26)^{1;2;3;4;5;6;7;8;9;10})+$I$2*(1+K26)^10*(L26+$I$4)*N26/(1+M26)^10+$I$9-$I$10)/$I$11
A27: P50 | B27: =PERCENTILE($O$2:$O$1001,0.5) | K27: =MAX(-0.05,NORMINV(RAND(),$C$6,$D$6)) | L27: =MAX(0.02,NORMINV(RAND(),$C$7,$D$7)) | M27: =MIN(0.16,MAX(0.05,NORMINV(RAND(),$C$8,$D$8))) | N27: =MIN(24,MAX(5,NORMINV(RAND(),$C$9,$D$9))) | O27: =$I$8*(SUMPRODUCT(($I$2*(1+K27)^{1;2;3;4;5;6;7;8;9;10})*(($I$3+(L27-$I$3)*{1;2;3;4;5;6;7;8;9;10}/10)*(1-$I$7)+$I$4-$I$4*($I$5+(1.05-$I$5)*{1;2;3;4;5;6;7;8;9;10}/10)-(K27/(1+K27))*$I$6)/(1+M27)^{1;2;3;4;5;6;7;8;9;10})+$I$2*(1+K27)^10*(L27+$I$4)*N27/(1+M27)^10+$I$9-$I$10)/$I$11
A28: P75 | B28: =PERCENTILE($O$2:$O$1001,0.75) | K28: =MAX(-0.05,NORMINV(RAND(),$C$6,$D$6)) | L28: =MAX(0.02,NORMINV(RAND(),$C$7,$D$7)) | M28: =MIN(0.16,MAX(0.05,NORMINV(RAND(),$C$8,$D$8))) | N28: =MIN(24,MAX(5,NORMINV(RAND(),$C$9,$D$9))) | O28: =$I$8*(SUMPRODUCT(($I$2*(1+K28)^{1;2;3;4;5;6;7;8;9;10})*(($I$3+(L28-$I$3)*{1;2;3;4;5;6;7;8;9;10}/10)*(1-$I$7)+$I$4-$I$4*($I$5+(1.05-$I$5)*{1;2;3;4;5;6;7;8;9;10}/10)-(K28/(1+K28))*$I$6)/(1+M28)^{1;2;3;4;5;6;7;8;9;10})+$I$2*(1+K28)^10*(L28+$I$4)*N28/(1+M28)^10+$I$9-$I$10)/$I$11
A29: P90 | B29: =PERCENTILE($O$2:$O$1001,0.9) | K29: =MAX(-0.05,NORMINV(RAND(),$C$6,$D$6)) | L29: =MAX(0.02,NORMINV(RAND(),$C$7,$D$7)) | M29: =MIN(0.16,MAX(0.05,NORMINV(RAND(),$C$8,$D$8))) | N29: =MIN(24,MAX(5,NORMINV(RAND(),$C$9,$D$9))) | O29: =$I$8*(SUMPRODUCT(($I$2*(1+K29)^{1;2;3;4;5;6;7;8;9;10})*(($I$3+(L29-$I$3)*{1;2;3;4;5;6;7;8;9;10}/10)*(1-$I$7)+$I$4-$I$4*($I$5+(1.05-$I$5)*{1;2;3;4;5;6;7;8;9;10}/10)-(K29/(1+K29))*$I$6)/(1+M29)^{1;2;3;4;5;6;7;8;9;10})+$I$2*(1+K29)^10*(L29+$I$4)*N29/(1+M29)^10+$I$9-$I$10)/$I$11
A30: P95 | B30: =PERCENTILE($O$2:$O$1001,0.95) | K30: =MAX(-0.05,NORMINV(RAND(),$C$6,$D$6)) | L30: =MAX(0.02,NORMINV(RAND(),$C$7,$D$7)) | M30: =MIN(0.16,MAX(0.05,NORMINV(RAND(),$C$8,$D$8))) | N30: =MIN(24,MAX(5,NORMINV(RAND(),$C$9,$D$9))) | O30: =$I$8*(SUMPRODUCT(($I$2*(1+K30)^{1;2;3;4;5;6;7;8;9;10})*(($I$3+(L30-$I$3)*{1;2;3;4;5;6;7;8;9;10}/10)*(1-$I$7)+$I$4-$I$4*($I$5+(1.05-$I$5)*{1;2;3;4;5;6;7;8;9;10}/10)-(K30/(1+K30))*$I$6)/(1+M30)^{1;2;3;4;5;6;7;8;9;10})+$I$2*(1+K30)^10*(L30+$I$4)*N30/(1+M30)^10+$I$9-$I$10)/$I$11
K31: =MAX(-0.05,NORMINV(RAND(),$C$6,$D$6)) | L31: =MAX(0.02,NORMINV(RAND(),$C$7,$D$7)) | M31: =MIN(0.16,MAX(0.05,NORMINV(RAND(),$C$8,$D$8))) | N31: =MIN(24,MAX(5,NORMINV(RAND(),$C$9,$D$9))) | O31: =$I$8*(SUMPRODUCT(($I$2*(1+K31)^{1;2;3;4;5;6;7;8;9;10})*(($I$3+(L31-$I$3)*{1;2;3;4;5;6;7;8;9;10}/10)*(1-$I$7)+$I$4-$I$4*($I$5+(1.05-$I$5)*{1;2;3;4;5;6;7;8;9;10}/10)-(K31/(1+K31))*$I$6)/(1+M31)^{1;2;3;4;5;6;7;8;9;10})+$I$2*(1+K31)^10*(L31+$I$4)*N31/(1+M31)^10+$I$9-$I$10)/$I$11
A32: VALUE DISTRIBUTION (live histogram) | K32: =MAX(-0.05,NORMINV(RAND(),$C$6,$D$6)) | L32: =MAX(0.02,NORMINV(RAND(),$C$7,$D$7)) | M32: =MIN(0.16,MAX(0.05,NORMINV(RAND(),$C$8,$D$8))) | N32: =MIN(24,MAX(5,NORMINV(RAND(),$C$9,$D$9))) | O32: =$I$8*(SUMPRODUCT(($I$2*(1+K32)^{1;2;3;4;5;6;7;8;9;10})*(($I$3+(L32-$I$3)*{1;2;3;4;5;6;7;8;9;10}/10)*(1-$I$7)+$I$4-$I$4*($I$5+(1.05-$I$5)*{1;2;3;4;5;6;7;8;9;10}/10)-(K32/(1+K32))*$I$6)/(1+M32)^{1;2;3;4;5;6;7;8;9;10})+$I$2*(1+K32)^10*(L32+$I$4)*N32/(1+M32)^10+$I$9-$I$10)/$I$11
A33: Bin midpoint ($/sh) | B33: Count | K33: =MAX(-0.05,NORMINV(RAND(),$C$6,$D$6)) | L33: =MAX(0.02,NORMINV(RAND(),$C$7,$D$7)) | M33: =MIN(0.16,MAX(0.05,NORMINV(RAND(),$C$8,$D$8))) | N33: =MIN(24,MAX(5,NORMINV(RAND(),$C$9,$D$9))) | O33: =$I$8*(SUMPRODUCT(($I$2*(1+K33)^{1;2;3;4;5;6;7;8;9;10})*(($I$3+(L33-$I$3)*{1;2;3;4;5;6;7;8;9;10}/10)*(1-$I$7)+$I$4-$I$4*($I$5+(1.05-$I$5)*{1;2;3;4;5;6;7;8;9;10}/10)-(K33/(1+K33))*$I$6)/(1+M33)^{1;2;3;4;5;6;7;8;9;10})+$I$2*(1+K33)^10*(L33+$I$4)*N33/(1+M33)^10+$I$9-$I$10)/$I$11
A34: =$B$15+0.5*($B$16-$B$15)/15 | B34: =COUNTIFS($O$2:$O$1001,">="&($B$15+0*($B$16-$B$15)/15),$O$2:$O$1001,"<"&($B$15+1*($B$16-$B$15)/15)) | K34: =MAX(-0.05,NORMINV(RAND(),$C$6,$D$6)) | L34: =MAX(0.02,NORMINV(RAND(),$C$7,$D$7)) | M34: =MIN(0.16,MAX(0.05,NORMINV(RAND(),$C$8,$D$8))) | N34: =MIN(24,MAX(5,NORMINV(RAND(),$C$9,$D$9))) | O34: =$I$8*(SUMPRODUCT(($I$2*(1+K34)^{1;2;3;4;5;6;7;8;9;10})*(($I$3+(L34-$I$3)*{1;2;3;4;5;6;7;8;9;10}/10)*(1-$I$7)+$I$4-$I$4*($I$5+(1.05-$I$5)*{1;2;3;4;5;6;7;8;9;10}/10)-(K34/(1+K34))*$I$6)/(1+M34)^{1;2;3;4;5;6;7;8;9;10})+$I$2*(1+K34)^10*(L34+$I$4)*N34/(1+M34)^10+$I$9-$I$10)/$I$11
A35: =$B$15+1.5*($B$16-$B$15)/15 | B35: =COUNTIFS($O$2:$O$1001,">="&($B$15+1*($B$16-$B$15)/15),$O$2:$O$1001,"<"&($B$15+2*($B$16-$B$15)/15)) | K35: =MAX(-0.05,NORMINV(RAND(),$C$6,$D$6)) | L35: =MAX(0.02,NORMINV(RAND(),$C$7,$D$7)) | M35: =MIN(0.16,MAX(0.05,NORMINV(RAND(),$C$8,$D$8))) | N35: =MIN(24,MAX(5,NORMINV(RAND(),$C$9,$D$9))) | O35: =$I$8*(SUMPRODUCT(($I$2*(1+K35)^{1;2;3;4;5;6;7;8;9;10})*(($I$3+(L35-$I$3)*{1;2;3;4;5;6;7;8;9;10}/10)*(1-$I$7)+$I$4-$I$4*($I$5+(1.05-$I$5)*{1;2;3;4;5;6;7;8;9;10}/10)-(K35/(1+K35))*$I$6)/(1+M35)^{1;2;3;4;5;6;7;8;9;10})+$I$2*(1+K35)^10*(L35+$I$4)*N35/(1+M35)^10+$I$9-$I$10)/$I$11
A36: =$B$15+2.5*($B$16-$B$15)/15 | B36: =COUNTIFS($O$2:$O$1001,">="&($B$15+2*($B$16-$B$15)/15),$O$2:$O$1001,"<"&($B$15+3*($B$16-$B$15)/15)) | K36: =MAX(-0.05,NORMINV(RAND(),$C$6,$D$6)) | L36: =MAX(0.02,NORMINV(RAND(),$C$7,$D$7)) | M36: =MIN(0.16,MAX(0.05,NORMINV(RAND(),$C$8,$D$8))) | N36: =MIN(24,MAX(5,NORMINV(RAND(),$C$9,$D$9))) | O36: =$I$8*(SUMPRODUCT(($I$2*(1+K36)^{1;2;3;4;5;6;7;8;9;10})*(($I$3+(L36-$I$3)*{1;2;3;4;5;6;7;8;9;10}/10)*(1-$I$7)+$I$4-$I$4*($I$5+(1.05-$I$5)*{1;2;3;4;5;6;7;8;9;10}/10)-(K36/(1+K36))*$I$6)/(1+M36)^{1;2;3;4;5;6;7;8;9;10})+$I$2*(1+K36)^10*(L36+$I$4)*N36/(1+M36)^10+$I$9-$I$10)/$I$11
