Workbook

Sheet Cover
A1: Salesforce, Inc. (CRM)
A2: DCF valuation — exit-multiple terminal · defaults anchored to consensus
A4: Last updated | B4: 2026-07-06
A5: Data pulled (FMP) | B5: Q4 2026
A6: Assumptions by | B6: Opus 4.8 — values as of 2026-06-12 (provenance seeded)
A8: VALUATION SUMMARY
A10: Fair value / share | B10: =Valuation!B36
A11: Current price | B11: =Valuation!$B$2
A12: Upside / (downside) | B12: =Valuation!B42
A13: Verdict | B13: =IF(Valuation!B36>Valuation!$B$2,"Undervalued","Overvalued")
A14: Monte Carlo P(undervalued) | B14: ='Monte Carlo'!B20
A15: KEY ASSUMPTIONS
A17: WACC (from WACC tab) | B17: =WACC!B15
A18: Terminal method | B18: =Valuation!$B$6
A19: Exit basis / multiple | B19: =Valuation!$B$7
A20: Exit multiple | B20: =Valuation!$B$8
A21: Terminal growth (g) | B21: =Valuation!$B$4
A22: Terminal weight | B22: =Valuation!B39
A23: Forecast horizon | B23: 10 years
A25: THE STORY (Opus)
A27: Salesforce is a mature enterprise SaaS leader whose growth is decelerating into the high-single/low-double digits as its core Sales and Service clouds saturate, offset by faster Platform/Data Cloud and AI (Agentforce) adoption. The investment case rests on durable mid-single-digit terminal growth plus continued operating-margin expansion from ~22% today toward ~30% as the company exercises pricing power and prior reorg discipline. Free cash flow remains the standout: low capex intensity (~1.4% of revenue) and a software model convert margin gains efficiently into FCFF.

Sheet Dashboard
A1: Salesforce, Inc. (CRM) — Control Dashboard
A2: Edit the yellow cells; everything recomputes. Orange = a driver you've moved off consensus.
A4: VERDICT
A5: Fair value / share | B5: =Valuation!B36
A6: Current price | B6: =Dashboard!$B$48
A7: Upside / (downside) | B7: =Valuation!B42
A8: Verdict | B8: =IF(Valuation!B36>Dashboard!$B$48,"Undervalued","Overvalued")
A9: Monte Carlo P(undervalued) | B9: ='Monte Carlo'!B20
A11: GUARDRAIL SIGNALS (are my assumptions sane?)
A12: Signal | B12: Value | C12: Flag | D12: Healthy
A13: Terminal weight (% of EV) | B13: =Valuation!B39 | C13: =IF(Valuation!B39>0.9,"! high","ok") | D13: < 90%
A14: Implied g vs exit multiple | B14: =Valuation!B40 | C14: =IF(Valuation!B40>Dashboard!$B$46+0.02,"! rich","ok") | D14: near term g
A15: ROIC - WACC (2026) | B15: =IF(Model!F44<=0,"n/a (neg. capital)",Model!G46-WACC!B15) | C15: =IF(Model!F44<=0,"n/a",IF(Model!G46-WACC!B15<0,"! destroys","creates")) | D15: > 0
A16: Revenue vs consensus (2026) | B16: =Consensus!B6 | C16: =IF(ABS(Consensus!B6)>0.05,"! off-Street","on") | D16: +/- 5%
A17: MC P(undervalued) | B17: ='Monte Carlo'!B20 | C17: =IF('Monte Carlo'!B20<0.5,"! coin-flip","ok") | D17: context
A18: REVENUE DRIVERS — near-term & terminal growth per segment
A19: Segment | B19: Near-term | C19: Terminal | D19: Consensus | E19: Thesis claim
A20: Salesforce Platform and Other | B20: 0.16 | C20: 0.04 | D20: 0.16
A21: Service Cloud | B21: 0.08 | C21: 0.03 | D21: 0.08
A22: Sales Cloud | B22: 0.08 | C22: 0.03 | D22: 0.08
A23: Integration And Analytics | B23: 0.09 | C23: 0.03 | D23: 0.09
A24: Marketing and Commerce Cloud | B24: 0.04 | C24: 0.025 | D24: 0.04
A25: Professional Services and Other | B25: 0 | C25: 0.02 | D25: 0
A28: PROFITABILITY & TAX
A29: Near-term operating margin | B29: 0.22 | D29: 0.22 | E29: consensus-implied; ramps to terminal
A30: Terminal operating margin | B30: 0.3 | E30: AI/ads mix + operating leverage
A31: Tax rate | B31: 0.23
A33: CAPITAL INTENSITY
A34: 2026 capex ($M) | B34: 645.69906 | D34: 645.69906 | E34: ~last-year capex +10%; set to guidance
A35: Terminal capex / D&A | B35: 1.05 | E35: converges to ~1.0x as build-out matures
A37: DISCOUNT RATE & TERMINAL
A38: Risk-free rate (10Y) | B38: 0.043
A39: Equity risk premium | B39: 0.045
A40: Beta (levered) | B40: 1.139 | E40: FMP raw beta; Damodaran bottom-up ~1.2
A41: Pre-tax cost of debt | B41: 0.045
A42: WACC (computed) | B42: =WACC!B15
A43: Terminal method | B43: Exit multiple
A44: Exit basis | B44: EV/EBITDA
A45: Exit multiple | B45: 15
A46: Terminal growth (g) | B46: 0.04
...

Sheet Assumptions
A1: CRM — Assumptions & Reasoning
A2: Provenance of every Dashboard input. Read-only — regenerated by each build/refresh. Current is a live link to the Dashboard; Source / Opus value / Note are as of the last refresh_dcf run.
A4: Assumptions baseline | B4: seeded 2026-06-12 from the synced assumptions block (pass predates provenance tracking — may already include your edits)
A6: THE STORY (Opus narrative)
A7: Salesforce is a mature enterprise SaaS leader whose growth is decelerating into the high-single/low-double digits as its core Sales and Service clouds saturate, offset by faster Platform/Data Cloud and AI (Agentforce) adoption. The investment case rests on durable mid-single-digit terminal growth plus continued operating-margin expansion from ~22% today toward ~30% as the company exercises pricing power and prior reorg discipline. Free cash flow remains the standout: low capex intensity (~1.4% of revenue) and a software model convert margin gains efficiently into FCFF.
A12: KEY JUDGMENTS (Opus reasoning)
A13: Near-term segment growth and ~22% op-margin are anchored to FMP consensus (revenue fading from ~11% to ~10% and net margin near 18-21%), then faded toward a 4% terminal tied to the risk-free rate. Terminal op-margin of 30% reflects best-in-class mature software profitability via operating leverage, and capex is converged toward maintenance (capex/D&A ~1.1x); EV/EBITDA at 15x is the basis the market actually applies to large-cap profitable software and is conservative versus current trading.
A18: DASHBOARD INPUTS — value · source · reasoning
A19: Input | B19: Cell | C19: Current | D19: Source | E19: Opus value | F19: Note
A20: Salesforce Platform and Other — near-term growth | B20: B20 | C20: =Dashboard!B20 | D20: Opus | E20: 16.0%
A21: Salesforce Platform and Other — terminal growth | B21: C20 | C21: =Dashboard!C20 | D21: Opus | E21: 4.0%
A22: Service Cloud — near-term growth | B22: B21 | C22: =Dashboard!B21 | D22: Opus | E22: 8.0%
A23: Service Cloud — terminal growth | B23: C21 | C23: =Dashboard!C21 | D23: Opus | E23: 3.0%
A24: Sales Cloud — near-term growth | B24: B22 | C24: =Dashboard!B22 | D24: Opus | E24: 8.0%
A25: Sales Cloud — terminal growth | B25: C22 | C25: =Dashboard!C22 | D25: Opus | E25: 3.0%
A26: Integration And Analytics — near-term growth | B26: B23 | C26: =Dashboard!B23 | D26: Opus | E26: 9.0%
A27: Integration And Analytics — terminal growth | B27: C23 | C27: =Dashboard!C23 | D27: Opus | E27: 3.0%
A28: Marketing and Commerce Cloud — near-term growth | B28: B24 | C28: =Dashboard!B24 | D28: Opus | E28: 4.0%
A29: Marketing and Commerce Cloud — terminal growth | B29: C24 | C29: =Dashboard!C24 | D29: Opus | E29: 2.5%
A30: Professional Services and Other — near-term growth | B30: B25 | C30: =Dashboard!B25 | D30: Opus | E30: 0.0%
A31: Professional Services and Other — terminal growth | B31: C25 | C31: =Dashboard!C25 | D31: Opus | E31: 2.0%
A32: Near-term operating margin | B32: B29 | C32: =Dashboard!B29 | D32: Opus | E32: 22.0%
A33: Terminal operating margin | B33: B30 | C33: =Dashboard!B30 | D33: Opus | E33: 30.0%
A34: Tax rate | B34: B31 | C34: =Dashboard!B31 | D34: Opus | E34: 23.0%
A35: Terminal capex / D&A | B35: B35 | C35: =Dashboard!B35 | D35: user-edited | E35: 1.1x | F35: overridden from Opus 1.1x on 2026-06-12
A36: Risk-free rate (10Y) | B36: B38 | C36: =Dashboard!B38 | D36: builder default | E36: —
A37: Equity risk premium | B37: B39 | C37: =Dashboard!B39 | D37: builder default | E37: —
A38: Beta (levered) | B38: B40 | C38: =Dashboard!B40 | D38: builder default | E38: —
A39: Pre-tax cost of debt | B39: B41 | C39: =Dashboard!B41 | D39: builder default | E39: —
A40: Terminal method | B40: B43 | C40: =Dashboard!B43 | D40: Opus | E40: Exit multiple
A41: Exit basis | B41: B44 | C41: =Dashboard!B44 | D41: Opus | E41: EV/EBITDA
A42: Exit multiple | B42: B45 | C42: =Dashboard!B45 | D42: Opus | E42: 15.0x
A43: Terminal growth (g) | B43: B46 | C43: =Dashboard!B46 | D43: Opus | E43: 4.0%
A44: 2026 capex ($M) | B44: B34 | C44: =Dashboard!B34 | D44: Opus | E44: — | F44: set from Opus 1% of FY1E revenue; edits not tracked (unit differs from the JSON)
A45: Bull Δ — segment growth, near-term | B45: C52 | C45: =Dashboard!C52 | D45: seed default | E45: 3.0%
A46: Bear Δ — segment growth, near-term | B46: D52 | C46: =Dashboard!D52 | D46: seed default | E46: -3.0%
A47: Bull Δ — segment growth, terminal | B47: C53 | C47: =Dashboard!C53 | D47: seed default | E47: 1.0%
A48: Bear Δ — segment growth, terminal | B48: D53 | C48: =Dashboard!D53 | D48: seed default | E48: -1.0%
A49: Bull Δ — operating margin, near-term | B49: C54 | C49: =Dashboard!C54 | D49: seed default | E49: 1.0%
A50: Bear Δ — operating margin, near-term | B50: D54 | C50: =Dashboard!D54 | D50: seed default | E50: -1.0%
...

Sheet Color Code
A1: Color | B1: Meaning
A2: Black | B2: Formula-driven (same-sheet)
A3: Blue | B3: Hard-coded actuals (from FMP filings)
A4: Yellow | B4: An assumption you can change — edit these to drive the model
A5: Green | B5: A formula that links to another sheet
A6: Orange | B6: (Dashboard) an assumption you've moved off consensus — your active bet
A7: How to use | B7: Edit yellow cells (Model assumptions, WACC drivers, Valuation toggles). Everything else recomputes.

Sheet WACC
A1: WACC Calculator
A2: Risk-free rate (10Y) | B2: =Dashboard!$B$38
A3: Equity risk premium | B3: =Dashboard!$B$39
A4: Beta (levered) | B4: =Dashboard!$B$40
A5: Country risk premium | B5: =Dashboard!$B$47
A6: Cost of equity (CAPM) | B6: =B2+B4*B3+B5
A7: Pre-tax cost of debt | B7: =Dashboard!$B$41
A8: Tax rate | B8: =Dashboard!$B$31
A9: After-tax cost of debt | B9: =B7*(1-B8)
A10: Market cap (E) | B10: =Dashboard!$B$48*Financials!AC17
A11: Total debt (D) | B11: =Financials!AC53
A12: Equity weight | B12: =B10/(B10+B11)
A13: Debt weight | B13: =B11/(B10+B11)
A15: WACC | B15: =B12*B6+B13*B9
A17: Yellow = edit. CAPM cost of equity (incl. country risk premium); market-value weights. Feeds Valuation!WACC.

Sheet Model
A1: $M unless noted | B1: FY2022A | C1: FY2023A | D1: FY2024A | E1: FY2025A | F1: FY2026A | G1: FY2027E | H1: FY2028E | I1: FY2029E | J1: FY2030E | K1: FY2031E | L1: FY2032E | M1: FY2033E | N1: FY2034E | O1: FY2035E | P1: FY2036E
A3: REVENUE BY SEGMENT (yellow = growth assumption; actuals link to Financials)
A4: Salesforce Platform and Other | B4: =SUM(Financials!J19:M19) | C4: =SUM(Financials!N19:Q19) | D4: =SUM(Financials!R19:U19) | E4: =SUM(Financials!V19:Y19) | F4: =SUM(Financials!Z19:AC19) | G4: =F4*(1+G5) | H4: =G4*(1+H5) | I4: =H4*(1+I5) | J4: =I4*(1+J5) | K4: =J4*(1+K5) | L4: =K4*(1+L5) | M4: =L4*(1+M5) | N4: =M4*(1+N5) | ... P4: =O4*(1+P5)
A5: growth % (convex fade; curvature from Dashboard) | C5: =IFERROR(C4/B4-1,"") | D5: =IFERROR(D4/C4-1,"") | E5: =IFERROR(E4/D4-1,"") | F5: =IFERROR(F4/E4-1,"") | G5: =Dashboard!$C$20+(Dashboard!$B$20-Dashboard!$C$20)*((9-0)/9)^Dashboard!$B$49 | H5: =Dashboard!$C$20+(Dashboard!$B$20-Dashboard!$C$20)*((9-1)/9)^Dashboard!$B$49 | I5: =Dashboard!$C$20+(Dashboard!$B$20-Dashboard!$C$20)*((9-2)/9)^Dashboard!$B$49 | J5: =Dashboard!$C$20+(Dashboard!$B$20-Dashboard!$C$20)*((9-3)/9)^Dashboard!$B$49 | K5: =Dashboard!$C$20+(Dashboard!$B$20-Dashboard!$C$20)*((9-4)/9)^Dashboard!$B$49 | L5: =Dashboard!$C$20+(Dashboard!$B$20-Dashboard!$C$20)*((9-5)/9)^Dashboard!$B$49 | M5: =Dashboard!$C$20+(Dashboard!$B$20-Dashboard!$C$20)*((9-6)/9)^Dashboard!$B$49 | N5: =Dashboard!$C$20+(Dashboard!$B$20-Dashboard!$C$20)*((9-7)/9)^Dashboard!$B$49 | O5: =Dashboard!$C$20+(Dashboard!$B$20-Dashboard!$C$20)*((9-8)/9)^Dashboard!$B$49 | P5: =Dashboard!$C$20+(Dashboard!$B$20-Dashboard!$C$20)*((9-9)/9)^Dashboard!$B$49
A6: Service Cloud | B6: =SUM(Financials!J22:M22) | C6: =SUM(Financials!N22:Q22) | D6: =SUM(Financials!R22:U22) | E6: =SUM(Financials!V22:Y22) | F6: =SUM(Financials!Z22:AC22) | G6: =F6*(1+G7) | H6: =G6*(1+H7) | I6: =H6*(1+I7) | J6: =I6*(1+J7) | K6: =J6*(1+K7) | L6: =K6*(1+L7) | M6: =L6*(1+M7) | N6: =M6*(1+N7) | ... P6: =O6*(1+P7)
A7: growth % (convex fade; curvature from Dashboard) | C7: =IFERROR(C6/B6-1,"") | D7: =IFERROR(D6/C6-1,"") | E7: =IFERROR(E6/D6-1,"") | F7: =IFERROR(F6/E6-1,"") | G7: =Dashboard!$C$21+(Dashboard!$B$21-Dashboard!$C$21)*((9-0)/9)^Dashboard!$B$49 | H7: =Dashboard!$C$21+(Dashboard!$B$21-Dashboard!$C$21)*((9-1)/9)^Dashboard!$B$49 | I7: =Dashboard!$C$21+(Dashboard!$B$21-Dashboard!$C$21)*((9-2)/9)^Dashboard!$B$49 | J7: =Dashboard!$C$21+(Dashboard!$B$21-Dashboard!$C$21)*((9-3)/9)^Dashboard!$B$49 | K7: =Dashboard!$C$21+(Dashboard!$B$21-Dashboard!$C$21)*((9-4)/9)^Dashboard!$B$49 | L7: =Dashboard!$C$21+(Dashboard!$B$21-Dashboard!$C$21)*((9-5)/9)^Dashboard!$B$49 | M7: =Dashboard!$C$21+(Dashboard!$B$21-Dashboard!$C$21)*((9-6)/9)^Dashboard!$B$49 | N7: =Dashboard!$C$21+(Dashboard!$B$21-Dashboard!$C$21)*((9-7)/9)^Dashboard!$B$49 | O7: =Dashboard!$C$21+(Dashboard!$B$21-Dashboard!$C$21)*((9-8)/9)^Dashboard!$B$49 | P7: =Dashboard!$C$21+(Dashboard!$B$21-Dashboard!$C$21)*((9-9)/9)^Dashboard!$B$49
A8: Sales Cloud | B8: =SUM(Financials!J25:M25) | C8: =SUM(Financials!N25:Q25) | D8: =SUM(Financials!R25:U25) | E8: =SUM(Financials!V25:Y25) | F8: =SUM(Financials!Z25:AC25) | G8: =F8*(1+G9) | H8: =G8*(1+H9) | I8: =H8*(1+I9) | J8: =I8*(1+J9) | K8: =J8*(1+K9) | L8: =K8*(1+L9) | M8: =L8*(1+M9) | N8: =M8*(1+N9) | ... P8: =O8*(1+P9)
A9: growth % (convex fade; curvature from Dashboard) | C9: =IFERROR(C8/B8-1,"") | D9: =IFERROR(D8/C8-1,"") | E9: =IFERROR(E8/D8-1,"") | F9: =IFERROR(F8/E8-1,"") | G9: =Dashboard!$C$22+(Dashboard!$B$22-Dashboard!$C$22)*((9-0)/9)^Dashboard!$B$49 | H9: =Dashboard!$C$22+(Dashboard!$B$22-Dashboard!$C$22)*((9-1)/9)^Dashboard!$B$49 | I9: =Dashboard!$C$22+(Dashboard!$B$22-Dashboard!$C$22)*((9-2)/9)^Dashboard!$B$49 | J9: =Dashboard!$C$22+(Dashboard!$B$22-Dashboard!$C$22)*((9-3)/9)^Dashboard!$B$49 | K9: =Dashboard!$C$22+(Dashboard!$B$22-Dashboard!$C$22)*((9-4)/9)^Dashboard!$B$49 | L9: =Dashboard!$C$22+(Dashboard!$B$22-Dashboard!$C$22)*((9-5)/9)^Dashboard!$B$49 | M9: =Dashboard!$C$22+(Dashboard!$B$22-Dashboard!$C$22)*((9-6)/9)^Dashboard!$B$49 | N9: =Dashboard!$C$22+(Dashboard!$B$22-Dashboard!$C$22)*((9-7)/9)^Dashboard!$B$49 | O9: =Dashboard!$C$22+(Dashboard!$B$22-Dashboard!$C$22)*((9-8)/9)^Dashboard!$B$49 | P9: =Dashboard!$C$22+(Dashboard!$B$22-Dashboard!$C$22)*((9-9)/9)^Dashboard!$B$49
A10: Integration And Analytics | B10: =SUM(Financials!J28:M28) | C10: =SUM(Financials!N28:Q28) | D10: =SUM(Financials!R28:U28) | E10: =SUM(Financials!V28:Y28) | F10: =SUM(Financials!Z28:AC28) | G10: =F10*(1+G11) | H10: =G10*(1+H11) | I10: =H10*(1+I11) | J10: =I10*(1+J11) | K10: =J10*(1+K11) | L10: =K10*(1+L11) | M10: =L10*(1+M11) | N10: =M10*(1+N11) | ... P10: =O10*(1+P11)
A11: growth % (convex fade; curvature from Dashboard) | C11: =IFERROR(C10/B10-1,"") | D11: =IFERROR(D10/C10-1,"") | E11: =IFERROR(E10/D10-1,"") | F11: =IFERROR(F10/E10-1,"") | G11: =Dashboard!$C$23+(Dashboard!$B$23-Dashboard!$C$23)*((9-0)/9)^Dashboard!$B$49 | H11: =Dashboard!$C$23+(Dashboard!$B$23-Dashboard!$C$23)*((9-1)/9)^Dashboard!$B$49 | I11: =Dashboard!$C$23+(Dashboard!$B$23-Dashboard!$C$23)*((9-2)/9)^Dashboard!$B$49 | J11: =Dashboard!$C$23+(Dashboard!$B$23-Dashboard!$C$23)*((9-3)/9)^Dashboard!$B$49 | K11: =Dashboard!$C$23+(Dashboard!$B$23-Dashboard!$C$23)*((9-4)/9)^Dashboard!$B$49 | L11: =Dashboard!$C$23+(Dashboard!$B$23-Dashboard!$C$23)*((9-5)/9)^Dashboard!$B$49 | M11: =Dashboard!$C$23+(Dashboard!$B$23-Dashboard!$C$23)*((9-6)/9)^Dashboard!$B$49 | N11: =Dashboard!$C$23+(Dashboard!$B$23-Dashboard!$C$23)*((9-7)/9)^Dashboard!$B$49 | O11: =Dashboard!$C$23+(Dashboard!$B$23-Dashboard!$C$23)*((9-8)/9)^Dashboard!$B$49 | P11: =Dashboard!$C$23+(Dashboard!$B$23-Dashboard!$C$23)*((9-9)/9)^Dashboard!$B$49
A12: Marketing and Commerce Cloud | B12: =SUM(Financials!J31:M31) | C12: =SUM(Financials!N31:Q31) | D12: =SUM(Financials!R31:U31) | E12: =SUM(Financials!V31:Y31) | F12: =SUM(Financials!Z31:AC31) | G12: =F12*(1+G13) | H12: =G12*(1+H13) | I12: =H12*(1+I13) | J12: =I12*(1+J13) | K12: =J12*(1+K13) | L12: =K12*(1+L13) | M12: =L12*(1+M13) | N12: =M12*(1+N13) | ... P12: =O12*(1+P13)
A13: growth % (convex fade; curvature from Dashboard) | C13: =IFERROR(C12/B12-1,"") | D13: =IFERROR(D12/C12-1,"") | E13: =IFERROR(E12/D12-1,"") | F13: =IFERROR(F12/E12-1,"") | G13: =Dashboard!$C$24+(Dashboard!$B$24-Dashboard!$C$24)*((9-0)/9)^Dashboard!$B$49 | H13: =Dashboard!$C$24+(Dashboard!$B$24-Dashboard!$C$24)*((9-1)/9)^Dashboard!$B$49 | I13: =Dashboard!$C$24+(Dashboard!$B$24-Dashboard!$C$24)*((9-2)/9)^Dashboard!$B$49 | J13: =Dashboard!$C$24+(Dashboard!$B$24-Dashboard!$C$24)*((9-3)/9)^Dashboard!$B$49 | K13: =Dashboard!$C$24+(Dashboard!$B$24-Dashboard!$C$24)*((9-4)/9)^Dashboard!$B$49 | L13: =Dashboard!$C$24+(Dashboard!$B$24-Dashboard!$C$24)*((9-5)/9)^Dashboard!$B$49 | M13: =Dashboard!$C$24+(Dashboard!$B$24-Dashboard!$C$24)*((9-6)/9)^Dashboard!$B$49 | N13: =Dashboard!$C$24+(Dashboard!$B$24-Dashboard!$C$24)*((9-7)/9)^Dashboard!$B$49 | O13: =Dashboard!$C$24+(Dashboard!$B$24-Dashboard!$C$24)*((9-8)/9)^Dashboard!$B$49 | P13: =Dashboard!$C$24+(Dashboard!$B$24-Dashboard!$C$24)*((9-9)/9)^Dashboard!$B$49
A14: Professional Services and Other | B14: =SUM(Financials!J34:M34) | C14: =SUM(Financials!N34:Q34) | D14: =SUM(Financials!R34:U34) | E14: =SUM(Financials!V34:Y34) | F14: =SUM(Financials!Z34:AC34) | G14: =F14*(1+G15) | H14: =G14*(1+H15) | I14: =H14*(1+I15) | J14: =I14*(1+J15) | K14: =J14*(1+K15) | L14: =K14*(1+L15) | M14: =L14*(1+M15) | N14: =M14*(1+N15) | ... P14: =O14*(1+P15)
A15: growth % (convex fade; curvature from Dashboard) | C15: =IFERROR(C14/B14-1,"") | D15: =IFERROR(D14/C14-1,"") | E15: =IFERROR(E14/D14-1,"") | F15: =IFERROR(F14/E14-1,"") | G15: =Dashboard!$C$25+(Dashboard!$B$25-Dashboard!$C$25)*((9-0)/9)^Dashboard!$B$49 | H15: =Dashboard!$C$25+(Dashboard!$B$25-Dashboard!$C$25)*((9-1)/9)^Dashboard!$B$49 | I15: =Dashboard!$C$25+(Dashboard!$B$25-Dashboard!$C$25)*((9-2)/9)^Dashboard!$B$49 | J15: =Dashboard!$C$25+(Dashboard!$B$25-Dashboard!$C$25)*((9-3)/9)^Dashboard!$B$49 | K15: =Dashboard!$C$25+(Dashboard!$B$25-Dashboard!$C$25)*((9-4)/9)^Dashboard!$B$49 | L15: =Dashboard!$C$25+(Dashboard!$B$25-Dashboard!$C$25)*((9-5)/9)^Dashboard!$B$49 | M15: =Dashboard!$C$25+(Dashboard!$B$25-Dashboard!$C$25)*((9-6)/9)^Dashboard!$B$49 | N15: =Dashboard!$C$25+(Dashboard!$B$25-Dashboard!$C$25)*((9-7)/9)^Dashboard!$B$49 | O15: =Dashboard!$C$25+(Dashboard!$B$25-Dashboard!$C$25)*((9-8)/9)^Dashboard!$B$49 | P15: =Dashboard!$C$25+(Dashboard!$B$25-Dashboard!$C$25)*((9-9)/9)^Dashboard!$B$49
A16: Total revenue | B16: =B4+B6+B8+B10+B12+B14 | C16: =C4+C6+C8+C10+C12+C14 | D16: =D4+D6+D8+D10+D12+D14 | E16: =E4+E6+E8+E10+E12+E14 | F16: =F4+F6+F8+F10+F12+F14 | G16: =G4+G6+G8+G10+G12+G14 | H16: =H4+H6+H8+H10+H12+H14 | I16: =I4+I6+I8+I10+I12+I14 | ... P16: =P4+P6+P8+P10+P12+P14
A17: growth % | C17: =IFERROR(C16/B16-1,"") | D17: =IFERROR(D16/C16-1,"") | E17: =IFERROR(E16/D16-1,"") | F17: =IFERROR(F16/E16-1,"") | G17: =IFERROR(G16/F16-1,"") | H17: =IFERROR(H16/G16-1,"") | I17: =IFERROR(I16/H16-1,"") | J17: =IFERROR(J16/I16-1,"") | ... P17: =IFERROR(P16/O16-1,"")
A19: COST STRUCTURE (yellow = % of revenue)
A20: Cost of revenue | B20: =SUM(Financials!J5:M5) | C20: =SUM(Financials!N5:Q5) | D20: =SUM(Financials!R5:U5) | E20: =SUM(Financials!V5:Y5) | F20: =SUM(Financials!Z5:AC5) | G20: =G16*G21 | H20: =H16*H21 | I20: =I16*I21 | J20: =J16*J21 | K20: =K16*K21 | L20: =L16*L21 | M20: =M16*M21 | N20: =N16*N21 | ... P20: =P16*P21
A21: % of revenue | B21: =IFERROR(B20/B16,"") | C21: =IFERROR(C20/C16,"") | D21: =IFERROR(D20/D16,"") | E21: =IFERROR(E20/E16,"") | F21: =IFERROR(F20/F16,"") | G21: 0.22323901 | H21: 0.22323901 | I21: 0.22323901 | J21: 0.22323901 | K21: 0.22323901 | L21: 0.22323901 | M21: 0.22323901 | N21: 0.22323901 | O21: 0.22323901 | P21: 0.22323901
A22: R&D / Technology | B22: =SUM(Financials!J7:M7) | C22: =SUM(Financials!N7:Q7) | D22: =SUM(Financials!R7:U7) | E22: =SUM(Financials!V7:Y7) | F22: =SUM(Financials!Z7:AC7) | G22: =G16*G23 | H22: =H16*H23 | I22: =I16*I23 | J22: =J16*J23 | K22: =K16*K23 | L22: =L16*L23 | M22: =M16*M23 | N22: =N16*N23 | ... P22: =P16*P23
A23: % of revenue | B23: =IFERROR(B22/B16,"") | C23: =IFERROR(C22/C16,"") | D23: =IFERROR(D22/D16,"") | E23: =IFERROR(E22/E16,"") | F23: =IFERROR(F22/F16,"") | G23: 0.1443227 | H23: 0.1443227 | I23: 0.1443227 | J23: 0.1443227 | K23: 0.1443227 | L23: 0.1443227 | M23: 0.1443227 | N23: 0.1443227 | O23: 0.1443227 | P23: 0.1443227
A24: SG&A | B24: =SUM(Financials!J9:M9) | C24: =SUM(Financials!N9:Q9) | D24: =SUM(Financials!R9:U9) | E24: =SUM(Financials!V9:Y9) | F24: =SUM(Financials!Z9:AC9) | G24: =G16*G25 | H24: =H16*H25 | I24: =I16*I25 | J24: =J16*J25 | K24: =K16*K25 | L24: =L16*L25 | M24: =M16*M25 | N24: =N16*N25 | ... P24: =P16*P25
A25: % of revenue | B25: =IFERROR(B24/B16,"") | C25: =IFERROR(C24/C16,"") | D25: =IFERROR(D24/D16,"") | E25: =IFERROR(E24/E16,"") | F25: =IFERROR(F24/F16,"") | G25: 0.41770018 | H25: 0.41770018 | I25: 0.41770018 | J25: 0.41770018 | K25: 0.41770018 | L25: 0.41770018 | M25: 0.41770018 | N25: 0.41770018 | O25: 0.41770018 | P25: 0.41770018
A26: Other opex (fulfilment, etc.) | B26: =B16-(B20+B22+B24)-SUM(Financials!J13:M13) | C26: =C16-(C20+C22+C24)-SUM(Financials!N13:Q13) | D26: =D16-(D20+D22+D24)-SUM(Financials!R13:U13) | E26: =E16-(E20+E22+E24)-SUM(Financials!V13:Y13) | F26: =F16-(F20+F22+F24)-SUM(Financials!Z13:AC13) | G26: =G16*(1-(Dashboard!$B$29+(Dashboard!$B$30-Dashboard!$B$29)*MIN(1,0/3)))-(G20+G22+G24) | H26: =H16*(1-(Dashboard!$B$29+(Dashboard!$B$30-Dashboard!$B$29)*MIN(1,1/3)))-(H20+H22+H24) | I26: =I16*(1-(Dashboard!$B$29+(Dashboard!$B$30-Dashboard!$B$29)*MIN(1,2/3)))-(I20+I22+I24) | J26: =J16*(1-(Dashboard!$B$29+(Dashboard!$B$30-Dashboard!$B$29)*MIN(1,3/3)))-(J20+J22+J24) | K26: =K16*(1-(Dashboard!$B$29+(Dashboard!$B$30-Dashboard!$B$29)*MIN(1,4/3)))-(K20+K22+K24) | L26: =L16*(1-(Dashboard!$B$29+(Dashboard!$B$30-Dashboard!$B$29)*MIN(1,5/3)))-(L20+L22+L24) | M26: =M16*(1-(Dashboard!$B$29+(Dashboard!$B$30-Dashboard!$B$29)*MIN(1,6/3)))-(M20+M22+M24) | N26: =N16*(1-(Dashboard!$B$29+(Dashboard!$B$30-Dashboard!$B$29)*MIN(1,7/3)))-(N20+N22+N24) | O26: =O16*(1-(Dashboard!$B$29+(Dashboard!$B$30-Dashboard!$B$29)*MIN(1,8/3)))-(O20+O22+O24) | P26: =P16*(1-(Dashboard!$B$29+(Dashboard!$B$30-Dashboard!$B$29)*MIN(1,9/3)))-(P20+P22+P24)
A27: % of revenue | B27: =IFERROR(B26/B16,"") | C27: =IFERROR(C26/C16,"") | D27: =IFERROR(D26/D16,"") | E27: =IFERROR(E26/E16,"") | F27: =IFERROR(F26/F16,"") | G27: =IFERROR(G26/G16,"") | H27: =IFERROR(H26/H16,"") | I27: =IFERROR(I26/I16,"") | ... P27: =IFERROR(P26/P16,"")
A29: Operating income (EBIT) | B29: =B16-(B20+B22+B24)-B26 | C29: =C16-(C20+C22+C24)-C26 | D29: =D16-(D20+D22+D24)-D26 | E29: =E16-(E20+E22+E24)-E26 | F29: =F16-(F20+F22+F24)-F26 | G29: =G16-(G20+G22+G24)-G26 | H29: =H16-(H20+H22+H24)-H26 | I29: =I16-(I20+I22+I24)-I26 | ... P29: =P16-(P20+P22+P24)-P26
A30: operating margin | B30: =IFERROR(B29/B16,"") | C30: =IFERROR(C29/C16,"") | D30: =IFERROR(D29/D16,"") | E30: =IFERROR(E29/E16,"") | F30: =IFERROR(F29/F16,"") | G30: =IFERROR(G29/G16,"") | H30: =IFERROR(H29/H16,"") | I30: =IFERROR(I29/I16,"") | ... P30: =IFERROR(P29/P16,"")
A32: FCF BRIDGE (NOPAT + D&A + SBC - dNWC - Capex)
A33: NOPAT = EBIT x (1 - tax) | B33: =B29*(1-Valuation!$B$5) | C33: =C29*(1-Valuation!$B$5) | D33: =D29*(1-Valuation!$B$5) | E33: =E29*(1-Valuation!$B$5) | F33: =F29*(1-Valuation!$B$5) | G33: =G29*(1-Valuation!$B$5) | H33: =H29*(1-Valuation!$B$5) | I33: =I29*(1-Valuation!$B$5) | ... P33: =P29*(1-Valuation!$B$5)
A34: + D&A | B34: =SUM(Financials!J56:M56) | C34: =SUM(Financials!N56:Q56) | D34: =SUM(Financials!R56:U56) | E34: =SUM(Financials!V56:Y56) | F34: =SUM(Financials!Z56:AC56) | G34: =G16*0.0874 | H34: =H16*0.0874 | I34: =I16*0.0874 | J34: =J16*0.0874 | K34: =K16*0.0874 | L34: =L16*0.0874 | M34: =M16*0.0874 | N34: =N16*0.0874 | ... P34: =P16*0.0874
A35: + SBC (non-cash) | B35: =SUM(Financials!J57:M57) | C35: =SUM(Financials!N57:Q57) | D35: =SUM(Financials!R57:U57) | E35: =SUM(Financials!V57:Y57) | F35: =SUM(Financials!Z57:AC57) | G35: =G16*(Dashboard!$B$65+(Dashboard!$B$66-Dashboard!$B$65)*0/9) | H35: =H16*(Dashboard!$B$65+(Dashboard!$B$66-Dashboard!$B$65)*1/9) | I35: =I16*(Dashboard!$B$65+(Dashboard!$B$66-Dashboard!$B$65)*2/9) | J35: =J16*(Dashboard!$B$65+(Dashboard!$B$66-Dashboard!$B$65)*3/9) | K35: =K16*(Dashboard!$B$65+(Dashboard!$B$66-Dashboard!$B$65)*4/9) | L35: =L16*(Dashboard!$B$65+(Dashboard!$B$66-Dashboard!$B$65)*5/9) | M35: =M16*(Dashboard!$B$65+(Dashboard!$B$66-Dashboard!$B$65)*6/9) | N35: =N16*(Dashboard!$B$65+(Dashboard!$B$66-Dashboard!$B$65)*7/9) | O35: =O16*(Dashboard!$B$65+(Dashboard!$B$66-Dashboard!$B$65)*8/9) | P35: =P16*(Dashboard!$B$65+(Dashboard!$B$66-Dashboard!$B$65)*9/9)
A36: - dNWC | G36: =(G16-F16)*0.0050 | H36: =(H16-G16)*0.0050 | I36: =(I16-H16)*0.0050 | J36: =(J16-I16)*0.0050 | K36: =(K16-J16)*0.0050 | L36: =(L16-K16)*0.0050 | M36: =(M16-L16)*0.0050 | N36: =(N16-M16)*0.0050 | ... P36: =(P16-O16)*0.0050
A37: - Capex | B37: =-SUM(Financials!J60:M60) | C37: =-SUM(Financials!N60:Q60) | D37: =-SUM(Financials!R60:U60) | E37: =-SUM(Financials!V60:Y60) | F37: =-SUM(Financials!Z60:AC60) | G37: =G34*G38 | H37: =H34*H38 | I37: =I34*I38 | J37: =J34*J38 | K37: =K34*K38 | L37: =L34*L38 | M37: =M34*M38 | N37: =N34*N38 | ... P37: =P34*P38
A38: Capex / D&A (from Dashboard: $cap'26 -> terminal) | B38: =IFERROR(B37/B34,"") | C38: =IFERROR(C37/C34,"") | D38: =IFERROR(D37/D34,"") | E38: =IFERROR(E37/E34,"") | F38: =IFERROR(F37/F34,"") | G38: =(Dashboard!$B$34/G34)+(Dashboard!$B$35-(Dashboard!$B$34/G34))*0/9 | H38: =(Dashboard!$B$34/G34)+(Dashboard!$B$35-(Dashboard!$B$34/G34))*1/9 | I38: =(Dashboard!$B$34/G34)+(Dashboard!$B$35-(Dashboard!$B$34/G34))*2/9 | J38: =(Dashboard!$B$34/G34)+(Dashboard!$B$35-(Dashboard!$B$34/G34))*3/9 | K38: =(Dashboard!$B$34/G34)+(Dashboard!$B$35-(Dashboard!$B$34/G34))*4/9 | L38: =(Dashboard!$B$34/G34)+(Dashboard!$B$35-(Dashboard!$B$34/G34))*5/9 | M38: =(Dashboard!$B$34/G34)+(Dashboard!$B$35-(Dashboard!$B$34/G34))*6/9 | N38: =(Dashboard!$B$34/G34)+(Dashboard!$B$35-(Dashboard!$B$34/G34))*7/9 | O38: =(Dashboard!$B$34/G34)+(Dashboard!$B$35-(Dashboard!$B$34/G34))*8/9 | P38: =(Dashboard!$B$34/G34)+(Dashboard!$B$35-(Dashboard!$B$34/G34))*9/9
A40: FCFF (firm) | B40: =B33+B34+B35-B36-B37 | C40: =C33+C34+C35-C36-C37 | D40: =D33+D34+D35-D36-D37 | E40: =E33+E34+E35-E36-E37 | F40: =F33+F34+F35-F36-F37 | G40: =G33+G34+G35-G36-G37 | H40: =H33+H34+H35-H36-H37 | I40: =I33+I34+I35-I36-I37 | ... P40: =P33+P34+P35-P36-P37
A41: Valuation FCF (NOPAT + D&A - dNWC - Capex - after-tax SBC) | B41: =B40-B35-B35*(1-Valuation!$B$5) | C41: =C40-C35-C35*(1-Valuation!$B$5) | D41: =D40-D35-D35*(1-Valuation!$B$5) | E41: =E40-E35-E35*(1-Valuation!$B$5) | F41: =F40-F35-F35*(1-Valuation!$B$5) | G41: =G40-G35-G35*(1-Valuation!$B$5) | H41: =H40-H35-H35*(1-Valuation!$B$5) | I41: =I40-I35-I35*(1-Valuation!$B$5) | ... P41: =P40-P35-P35*(1-Valuation!$B$5)
A43: RETURNS ON CAPITAL & EFFICIENCY (is new revenue/capital earning its keep?)
A44: Invested capital (debt + equity - cash) | B44: =Financials!M54+Financials!M53-Financials!M48 | C44: =Financials!Q54+Financials!Q53-Financials!Q48 | D44: =Financials!U54+Financials!U53-Financials!U48 | E44: =Financials!Y54+Financials!Y53-Financials!Y48 | F44: =Financials!AC54+Financials!AC53-Financials!AC48 | G44: =F44+G37-G34+G36 | H44: =G44+H37-H34+H36 | I44: =H44+I37-I34+I36 | J44: =I44+J37-J34+J36 | K44: =J44+K37-K34+K36 | L44: =K44+L37-L34+L36 | M44: =L44+M37-M34+M36 | N44: =M44+N37-N34+N36 | ... P44: =O44+P37-P34+P36
A45: Book equity (year-end) | B45: =Financials!M54 | C45: =Financials!Q54 | D45: =Financials!U54 | E45: =Financials!Y54 | F45: =Financials!AC54 | G45: =F45+G33 | H45: =G45+H33 | I45: =H45+I33 | J45: =I45+J33 | K45: =J45+K33 | L45: =K45+L33 | M45: =L45+M33 | N45: =M45+N33 | ... P45: =O45+P33
A46: ROIC (NOPAT / beg. invested capital) | C46: =IFERROR(C33/B44,"") | D46: =IFERROR(D33/C44,"") | E46: =IFERROR(E33/D44,"") | F46: =IFERROR(F33/E44,"") | G46: =IFERROR(G33/F44,"") | H46: =IFERROR(H33/G44,"") | I46: =IFERROR(I33/H44,"") | J46: =IFERROR(J33/I44,"") | ... P46: =IFERROR(P33/O44,"")
...

Sheet Financials
A1: Line Item ($M) | B1: Q1 2020 | C1: Q2 2020 | D1: Q3 2020 | E1: Q4 2020 | F1: Q1 2021 | G1: Q2 2021 | H1: Q3 2021 | I1: Q4 2021 | J1: Q1 2022 | K1: Q2 2022 | L1: Q3 2022 | M1: Q4 2022 | N1: Q1 2023 | O1: Q2 2023 | P1: Q3 2023 | Q1: Q4 2023 | R1: Q1 2024 | S1: Q2 2024 | T1: Q3 2024 | U1: Q4 2024 | V1: Q1 2025 | W1: Q2 2025 | X1: Q3 2025 | Y1: Q4 2025 | Z1: Q1 2026 | AA1: Q2 2026 | AB1: Q3 2026 | AC1: Q4 2026
A2: INCOME STATEMENT
A3: Revenue | B3: 3737 | C3: 3997 | D3: 4513 | E3: 4851 | F3: 4865 | G3: 5151 | H3: 5419 | I3: 5817 | J3: 5963 | K3: 6340 | L3: 6863 | M3: 7326 | N3: 7411 | O3: 7720 | P3: 7837 | Q3: 8384 | R3: 8247 | S3: 8603 | T3: 8720 | U3: 9287 | V3: 9133 | W3: 9325 | X3: 9444 | Y3: 9993 | Z3: 9829 | AA3: 10236 | AB3: 10259 | AC3: 11201
A4: % YoY | F4: =IFERROR(F3/B3-1,"") | G4: =IFERROR(G3/C3-1,"") | H4: =IFERROR(H3/D3-1,"") | I4: =IFERROR(I3/E3-1,"") | J4: =IFERROR(J3/F3-1,"") | K4: =IFERROR(K3/G3-1,"") | L4: =IFERROR(L3/H3-1,"") | M4: =IFERROR(M3/I3-1,"") | ... AC4: =IFERROR(AC3/Y3-1,"")
A5: Cost of Revenue | B5: 914 | C5: 967 | D5: 1134 | E5: 1220 | F5: 1254 | G5: 1311 | H5: 1394 | I5: 1479 | J5: 1555 | K5: 1613 | L5: 1844 | M5: 2014 | N5: 2045 | O5: 2127 | P5: 2088 | Q5: 2100 | R5: 2125 | S5: 2113 | T5: 2155 | U5: 2148 | V5: 2162 | W5: 2159 | X5: 2105 | Y5: 2217 | Z5: 2265 | AA5: 2242 | AB5: 2255 | AC5: 2508
A6: % of revenue | B6: =IFERROR(B5/B3,"") | C6: =IFERROR(C5/C3,"") | D6: =IFERROR(D5/D3,"") | E6: =IFERROR(E5/E3,"") | F6: =IFERROR(F5/F3,"") | G6: =IFERROR(G5/G3,"") | H6: =IFERROR(H5/H3,"") | I6: =IFERROR(I5/I3,"") | ... AC6: =IFERROR(AC5/AC3,"")
A7: R&D Expense | B7: 554 | C7: 607 | D7: 774 | E7: 831 | F7: 859 | G7: 898 | H7: 902 | I7: 939 | J7: 951 | K7: 1020 | L7: 1203 | M7: 1291 | N7: 1318 | O7: 1329 | P7: 1280 | Q7: 1128 | R7: 1207 | S7: 1220 | T7: 1204 | U7: 1275 | V7: 1368 | W7: 1349 | X7: 1356 | Y7: 1420 | Z7: 1460 | AA7: 1481 | AB7: 1433 | AC7: 1619
A8: % of revenue | B8: =IFERROR(B7/B3,"") | C8: =IFERROR(C7/C3,"") | D8: =IFERROR(D7/D3,"") | E8: =IFERROR(E7/E3,"") | F8: =IFERROR(F7/F3,"") | G8: =IFERROR(G7/G3,"") | H8: =IFERROR(H7/H3,"") | I8: =IFERROR(I7/I3,"") | ... AC8: =IFERROR(AC7/AC3,"")
A9: SG&A Expense | B9: 2059 | C9: 2199 | D9: 2540 | E9: 2836 | F9: 2892 | G9: 2764 | H9: 2899 | I9: 3206 | J9: 3103 | K9: 3375 | L9: 3778 | M9: 4197 | N9: 4028 | O9: 4071 | P9: 4009 | Q9: 3971 | R9: 3792 | S9: 3745 | T9: 3805 | U9: 4069 | V9: 3886 | W9: 3935 | X9: 4034 | Y9: 4238 | Z9: 4126 | AA9: 4177 | AB9: 4123 | AC9: 4919
A10: % of revenue | B10: =IFERROR(B9/B3,"") | C10: =IFERROR(C9/C3,"") | D10: =IFERROR(D9/D3,"") | E10: =IFERROR(E9/E3,"") | F10: =IFERROR(F9/F3,"") | G10: =IFERROR(G9/G3,"") | H10: =IFERROR(H9/H3,"") | I10: =IFERROR(I9/I3,"") | ... AC10: =IFERROR(AC9/AC3,"")
A11: Gross Profit | B11: 2823 | C11: 3030 | D11: 3379 | E11: 3631 | F11: 3611 | G11: 3840 | H11: 4025 | I11: 4338 | J11: 4408 | K11: 4727 | L11: 5019 | M11: 5312 | N11: 5366 | O11: 5593 | P11: 5749 | Q11: 6284 | R11: 6122 | S11: 6490 | T11: 6565 | U11: 7139 | V11: 6971 | W11: 7166 | X11: 7339 | Y11: 7776 | Z11: 7564 | AA11: 7994 | AB11: 8004 | AC11: 8693
A12: gross margin | B12: =IFERROR(B11/B3,"") | C12: =IFERROR(C11/C3,"") | D12: =IFERROR(D11/D3,"") | E12: =IFERROR(E11/E3,"") | F12: =IFERROR(F11/F3,"") | G12: =IFERROR(G11/G3,"") | H12: =IFERROR(H11/H3,"") | I12: =IFERROR(I11/I3,"") | ... AC12: =IFERROR(AC11/AC3,"")
A13: Operating Income | B13: 210 | C13: 58 | D13: 65 | E13: -36 | F13: -140 | G13: 178 | H13: 224 | I13: 193 | J13: 354 | K13: 332 | L13: 38 | M13: -176 | N13: 20 | O13: 193 | P13: 460 | Q13: 357 | R13: 412 | S13: 1476 | T13: 1501 | U13: 1622 | V13: 1709 | W13: 1783 | X13: 1893 | Y13: 1820 | Z13: 1942 | AA13: 2332 | AB13: 2188 | AC13: 2451
A14: operating margin | B14: =IFERROR(B13/B3,"") | C14: =IFERROR(C13/C3,"") | D14: =IFERROR(D13/D3,"") | E14: =IFERROR(E13/E3,"") | F14: =IFERROR(F13/F3,"") | G14: =IFERROR(G13/G3,"") | H14: =IFERROR(H13/H3,"") | I14: =IFERROR(I13/I3,"") | ... AC14: =IFERROR(AC13/AC3,"")
A15: Net Income | B15: 392 | C15: 91 | D15: -109 | E15: -248 | F15: 99 | G15: 2625 | H15: 1081 | I15: 267 | J15: 469 | K15: 535 | L15: 468 | M15: -28 | N15: 28 | O15: 68 | P15: 210 | Q15: -98 | R15: 199 | S15: 1267 | T15: 1224 | U15: 1446 | V15: 1533 | W15: 1429 | X15: 1527 | Y15: 1708 | Z15: 1541 | AA15: 1887 | AB15: 2086 | AC15: 1943
A16: net margin | B16: =IFERROR(B15/B3,"") | C16: =IFERROR(C15/C3,"") | D16: =IFERROR(D15/D3,"") | E16: =IFERROR(E15/E3,"") | F16: =IFERROR(F15/F3,"") | G16: =IFERROR(G15/G3,"") | H16: =IFERROR(H15/H3,"") | I16: =IFERROR(I15/I3,"") | ... AC16: =IFERROR(AC15/AC3,"")
A17: Diluted Shares (M) | B17: 793 | C17: 795 | D17: 879 | E17: 889 | F17: 913 | G17: 922 | H17: 939 | I17: 939 | J17: 940 | K17: 950 | L17: 1001 | M17: 986 | N17: 1001 | O17: 1001 | P17: 1000 | Q17: 984 | R17: 988 | S17: 986 | T17: 981 | U17: 983 | V17: 985 | W17: 973 | X17: 975 | Y17: 974 | Z17: 970 | AA17: 962 | AB17: 962 | AC17: 940
A18: REVENUE BY SEGMENT — PRODUCT (% YoY, % of revenue)
A19: Salesforce Platform and Other | B19: 842 | C19: 912 | D19: 1287 | E19: 1432 | F19: 1364 | G19: 1512 | H19: 1594 | I19: 1805 | J19: 1747 | K19: 1882 | L19: 1277 | M19: 0 | N19: 1419 | O19: 1478 | P19: 1513 | Q19: 1557 | R19: 1567 | S19: 1638 | T19: 1686 | U19: 1720 | V19: 1718 | W19: 1786 | X19: 1825 | Y19: 1918 | Z19: 1963 | AA19: 2084 | AB19: 2180 | AC19: 2655
A20: % YoY | F20: =IFERROR(F19/B19-1,"") | G20: =IFERROR(G19/C19-1,"") | H20: =IFERROR(H19/D19-1,"") | I20: =IFERROR(I19/E19-1,"") | J20: =IFERROR(J19/F19-1,"") | K20: =IFERROR(K19/G19-1,"") | L20: =IFERROR(L19/H19-1,"") | M20: =IFERROR(M19/I19-1,"") | ... AC20: =IFERROR(AC19/Y19-1,"")
A21: % of revenue | B21: =IFERROR(B19/B3,"") | C21: =IFERROR(C19/C3,"") | D21: =IFERROR(D19/D3,"") | E21: =IFERROR(E19/E3,"") | F21: =IFERROR(F19/F3,"") | G21: =IFERROR(G19/G3,"") | H21: =IFERROR(H19/H3,"") | I21: =IFERROR(I19/I3,"") | ... AC21: =IFERROR(AC19/AC3,"")
A22: Service Cloud | B22: 1020 | C22: 1087 | D22: 1140 | E22: 1219 | F22: 1252 | G22: 1303 | H22: 1376 | I22: 1446 | J22: 1506 | K22: 1600 | L22: 1658 | M22: 1710 | N22: 1761 | O22: 1828 | P22: 1856 | Q22: 1924 | R22: 1964 | S22: 2049 | T22: 2074 | U22: 2158 | V22: 2182 | W22: 2257 | X22: 2288 | Y22: 2327 | Z22: 2334 | AA22: 2458 | AB22: 2495 | AC22: 2531
A23: % YoY | F23: =IFERROR(F22/B22-1,"") | G23: =IFERROR(G22/C22-1,"") | H23: =IFERROR(H22/D22-1,"") | I23: =IFERROR(I22/E22-1,"") | J23: =IFERROR(J22/F22-1,"") | K23: =IFERROR(K22/G22-1,"") | L23: =IFERROR(L22/H22-1,"") | M23: =IFERROR(M22/I22-1,"") | ... AC23: =IFERROR(AC22/Y22-1,"")
A24: % of revenue | B24: =IFERROR(B22/B3,"") | C24: =IFERROR(C22/C3,"") | D24: =IFERROR(D22/D3,"") | E24: =IFERROR(E22/E3,"") | F24: =IFERROR(F22/F3,"") | G24: =IFERROR(G22/G3,"") | H24: =IFERROR(H22/H3,"") | I24: =IFERROR(I22/I3,"") | ... AC24: =IFERROR(AC22/AC3,"")
A25: Sales Cloud | B25: 1073 | C25: 1130 | D25: 1168 | E25: 1227 | F25: 1245 | G25: 1279 | H25: 1311 | I25: 1356 | J25: 1388 | K25: 1477 | L25: 1538 | M25: 1586 | N25: 1632 | O25: 1695 | P25: 1717 | Q25: 1787 | R25: 1810 | S25: 1895 | T25: 1906 | U25: 1969 | V25: 1998 | W25: 2071 | X25: 2119 | Y25: 2134 | Z25: 2131 | AA25: 2267 | AB25: 2297 | AC25: 2333
A26: % YoY | F26: =IFERROR(F25/B25-1,"") | G26: =IFERROR(G25/C25-1,"") | H26: =IFERROR(H25/D25-1,"") | I26: =IFERROR(I25/E25-1,"") | J26: =IFERROR(J25/F25-1,"") | K26: =IFERROR(K25/G25-1,"") | L26: =IFERROR(L25/H25-1,"") | M26: =IFERROR(M25/I25-1,"") | ... AC26: =IFERROR(AC25/Y25-1,"")
A27: % of revenue | B27: =IFERROR(B25/B3,"") | C27: =IFERROR(C25/C3,"") | D27: =IFERROR(D25/D3,"") | E27: =IFERROR(E25/E3,"") | F27: =IFERROR(F25/F3,"") | G27: =IFERROR(G25/G3,"") | H27: =IFERROR(H25/H3,"") | I27: =IFERROR(I25/I3,"") | ... AC27: =IFERROR(AC25/AC3,"")
A28: Integration And Analytics | L28: 900 | M28: 2883 | N28: 955 | O28: 1021 | P28: 1018 | Q28: 1344 | R28: 1131 | S28: 1186 | T28: 1245 | U28: 1627 | V28: 1405 | W28: 1342 | X28: 1313 | Y28: 1715 | Z28: 1544 | AA28: 1516 | AB28: 1393 | AC28: 1779
A29: % YoY | F29: =IFERROR(F28/B28-1,"") | G29: =IFERROR(G28/C28-1,"") | H29: =IFERROR(H28/D28-1,"") | I29: =IFERROR(I28/E28-1,"") | J29: =IFERROR(J28/F28-1,"") | K29: =IFERROR(K28/G28-1,"") | L29: =IFERROR(L28/H28-1,"") | M29: =IFERROR(M28/I28-1,"") | ... AC29: =IFERROR(AC28/Y28-1,"")
A30: % of revenue | B30: =IFERROR(B28/B3,"") | C30: =IFERROR(C28/C3,"") | D30: =IFERROR(D28/D3,"") | E30: =IFERROR(E28/E3,"") | F30: =IFERROR(F28/F3,"") | G30: =IFERROR(G28/G3,"") | H30: =IFERROR(H28/H3,"") | I30: =IFERROR(I28/I3,"") | ... AC30: =IFERROR(AC28/AC3,"")
A31: Marketing and Commerce Cloud | B31: 561 | C31: 616 | D31: 644 | E31: 685 | F31: 714 | G31: 746 | H31: 804 | I31: 869 | J31: 895 | K31: 955 | L31: 1006 | M31: 1046 | N31: 1089 | O31: 1121 | P31: 1129 | Q31: 1177 | R31: 1170 | S31: 1238 | T31: 1230 | U31: 1274 | V31: 1282 | W31: 1308 | X31: 1334 | Y31: 1357 | Z31: 1325 | AA31: 1365 | AB31: 1361 | AC31: 1377
A32: % YoY | F32: =IFERROR(F31/B31-1,"") | G32: =IFERROR(G31/C31-1,"") | H32: =IFERROR(H31/D31-1,"") | I32: =IFERROR(I31/E31-1,"") | J32: =IFERROR(J31/F31-1,"") | K32: =IFERROR(K31/G31-1,"") | L32: =IFERROR(L31/H31-1,"") | M32: =IFERROR(M31/I31-1,"") | ... AC32: =IFERROR(AC31/Y31-1,"")
A33: % of revenue | B33: =IFERROR(B31/B3,"") | C33: =IFERROR(C31/C3,"") | D33: =IFERROR(D31/D3,"") | E33: =IFERROR(E31/E3,"") | F33: =IFERROR(F31/F3,"") | G33: =IFERROR(G31/G3,"") | H33: =IFERROR(H31/H3,"") | I33: =IFERROR(I31/I3,"") | ... AC33: =IFERROR(AC31/AC3,"")
A34: Professional Services and Other | B34: 241 | C34: 252 | D34: 274 | E34: 288 | F34: 290 | G34: 311 | H34: 334 | I34: 341 | J34: 427 | K34: 426 | L34: 484 | M34: 498 | N34: 555 | O34: 577 | P34: 604 | Q34: 595 | R34: 605 | S34: 597 | T34: 579 | U34: 539 | V34: 548 | W34: 561 | X34: 565 | Y34: 542 | Z34: 532 | AA34: 546 | AB34: 533 | AC34: 526
A35: % YoY | F35: =IFERROR(F34/B34-1,"") | G35: =IFERROR(G34/C34-1,"") | H35: =IFERROR(H34/D34-1,"") | I35: =IFERROR(I34/E34-1,"") | J35: =IFERROR(J34/F34-1,"") | K35: =IFERROR(K34/G34-1,"") | L35: =IFERROR(L34/H34-1,"") | M35: =IFERROR(M34/I34-1,"") | ... AC35: =IFERROR(AC34/Y34-1,"")
A36: % of revenue | B36: =IFERROR(B34/B3,"") | C36: =IFERROR(C34/C3,"") | D36: =IFERROR(D34/D3,"") | E36: =IFERROR(E34/E3,"") | F36: =IFERROR(F34/F3,"") | G36: =IFERROR(G34/G3,"") | H36: =IFERROR(H34/H3,"") | I36: =IFERROR(I34/I3,"") | ... AC36: =IFERROR(AC34/AC3,"")
A37: REVENUE BY SEGMENT — GEOGRAPHY (% YoY, % of revenue)
A38: Americas | B38: 2617 | C38: 2816 | D38: 3216 | E38: 3402 | F38: 3370 | G38: 3596 | H38: 3758 | I38: 4012 | J38: 4094 | K38: 4312 | L38: 4638 | M38: 4939 | N38: 4971 | O38: 5261 | P38: 5361 | Q38: 5657 | R38: 5482 | S38: 5769 | T38: 5862 | U38: 6176 | V38: 6062 | W38: 6201 | X38: 6220 | Y38: 6660 | Z38: 6469 | AA38: 6736 | AB38: 6703 | AC38: 7285
A39: % YoY | F39: =IFERROR(F38/B38-1,"") | G39: =IFERROR(G38/C38-1,"") | H39: =IFERROR(H38/D38-1,"") | I39: =IFERROR(I38/E38-1,"") | J39: =IFERROR(J38/F38-1,"") | K39: =IFERROR(K38/G38-1,"") | L39: =IFERROR(L38/H38-1,"") | M39: =IFERROR(M38/I38-1,"") | ... AC39: =IFERROR(AC38/Y38-1,"")
A40: % of revenue | B40: =IFERROR(B38/B3,"") | C40: =IFERROR(C38/C3,"") | D40: =IFERROR(D38/D3,"") | E40: =IFERROR(E38/E3,"") | F40: =IFERROR(F38/F3,"") | G40: =IFERROR(G38/G3,"") | H40: =IFERROR(H38/H3,"") | I40: =IFERROR(I38/I3,"") | ... AC40: =IFERROR(AC38/AC3,"")
...

Sheet Consensus
A1: Full consensus check — model vs Street (FMP estimates, $M)
A2: Fiscal year | B2: 2027 | C2: 2028 | D2: 2029 | E2: 2030
A3: EVERY AVAILABLE FMP CONSENSUS FIELD (consensus / model / % diff)
A4: Revenue — consensus | B4: 46121.362 | C4: 50521.985 | D4: 55480.668 | E4: 60784.675
A5: model | B5: =Model!G16 | C5: =Model!H16 | D5: =Model!I16 | E5: =Model!J16
A6: vs consensus | B6: =IFERROR(B5/B4-1,"") | C6: =IFERROR(C5/C4-1,"") | D6: =IFERROR(D5/D4-1,"") | E6: =IFERROR(E5/E4-1,"")
A8: EBITDA* — consensus | B8: 22747.371 | C8: 24917.789 | D8: 27363.445 | E8: 29979.418
A9: model | B9: =Model!G29+Model!G34 | C9: =Model!H29+Model!H34 | D9: =Model!I29+Model!I34 | E9: =Model!J29+Model!J34
A10: vs consensus | B10: =IFERROR(B9/B8-1,"") | C10: =IFERROR(C9/C8-1,"") | D10: =IFERROR(D9/D8-1,"") | E10: =IFERROR(E9/E8-1,"")
A12: EBIT* — consensus | B12: 20359.157 | C12: 22301.705 | D12: 24490.595 | E12: 26831.921
A13: model | B13: =Model!G29 | C13: =Model!H29 | D13: =Model!I29 | E13: =Model!J29
A14: vs consensus | B14: =IFERROR(B13/B12-1,"") | C14: =IFERROR(C13/C12-1,"") | D14: =IFERROR(D13/D12-1,"") | E14: =IFERROR(E13/E12-1,"")
A16: SG&A — consensus | B16: 21611.633 | C16: 23673.685 | D16: 25997.234 | E16: 28482.596
A17: model | B17: =Model!G24 | C17: =Model!H24 | D17: =Model!I24 | E17: =Model!J24
A18: vs consensus | B18: =IFERROR(B17/B16-1,"") | C18: =IFERROR(C17/C16-1,"") | D18: =IFERROR(D17/D16-1,"") | E18: =IFERROR(E17/E16-1,"")
A20: Net income (NOPAT) — consensus | B20: 12572.007 | C20: 14215.318 | D20: 16485.627 | E20: 18756.72
A21: model | B21: =Model!G33 | C21: =Model!H33 | D21: =Model!I33 | E21: =Model!J33
A22: vs consensus | B22: =IFERROR(B21/B20-1,"") | C22: =IFERROR(C21/C20-1,"") | D22: =IFERROR(D21/D20-1,"") | E22: =IFERROR(E21/E20-1,"")
A24: EPS — consensus | B24: 13.20587 | C24: 14.86958 | D24: 17.58669 | E24: 19.62
A25: model | B25: =Model!G33/Financials!AC17 | C25: =Model!H33/Financials!AC17 | D25: =Model!I33/Financials!AC17 | E25: =Model!J33/Financials!AC17
A26: vs consensus | B26: =IFERROR(B25/B24-1,"") | C26: =IFERROR(C25/C24-1,"") | D26: =IFERROR(D25/D24-1,"") | E26: =IFERROR(E25/E24-1,"")
A28: Defaults anchored to consensus revenue + net income (≈0% diff). Other rows show where the model sits vs Street.
A29: *FMP's EBITDA/EBIT estimates look unreliable for AMZN (it reports NI > EBIT) — don't over-read those two.

Sheet Valuation
A1: Salesforce, Inc. — DCF Valuation
A2: Current price | B2: =Dashboard!$B$48
A3: WACC | B3: =WACC!B15
A4: Terminal growth (g) | B4: =Dashboard!$B$46
A5: Tax rate | B5: =Dashboard!$B$31
A6: Terminal method | B6: =Dashboard!$B$43
A7: Exit basis | B7: =Dashboard!$B$44
A8: Exit multiple | B8: =Dashboard!$B$45
A11: Forecast year | C11: 2027 | D11: 2028 | E11: 2029 | F11: 2030 | G11: 2031 | H11: 2032 | I11: 2033 | J11: 2034 | K11: 2035 | L11: 2036
A12: FCFF ($M) | C12: =Model!G41 | D12: =Model!H41 | E12: =Model!I41 | F12: =Model!J41 | G12: =Model!K41 | H12: =Model!L41 | I12: =Model!M41 | J12: =Model!N41 | ... L12: =Model!P41
A13: PV factor | C13: =1/(1+$B$3)^1 | D13: =1/(1+$B$3)^2 | E13: =1/(1+$B$3)^3 | F13: =1/(1+$B$3)^4 | G13: =1/(1+$B$3)^5 | H13: =1/(1+$B$3)^6 | I13: =1/(1+$B$3)^7 | J13: =1/(1+$B$3)^8 | K13: =1/(1+$B$3)^9 | L13: =1/(1+$B$3)^10
A14: PV of FCFF ($M) | C14: =C12*C13 | D14: =D12*D13 | E14: =E12*E13 | F14: =F12*F13 | G14: =G12*G13 | H14: =H12*H13 | I14: =I12*I13 | J14: =J12*J13 | ... L14: =L12*L13
A16: Sum PV of FCFF | B16: =SUM(C14:L14)
A18: TERMINAL VALUE (exit multiple = default; perpetuity = cross-check)
A19: Terminal-year FCFF | B19: =L12
A20: Terminal revenue | B20: =Model!P16
A21: Terminal EBIT | B21: =Model!P29
A22: Terminal EBITDA (SBC-burdened) | B22: =Model!P29+Model!P34-Model!P35
A23: Terminal metric (per exit basis) | B23: =IF($B$7="EV/EBITDA",B22,IF($B$7="EV/Sales",B20,IF($B$7="EV/EBIT",B21,B19)))
A24: TV (exit) = metric x multiple | B24: =B23*$B$8
A25: PV of TV — exit multiple | B25: =B24/(1+$B$3)^10
A26: TV (perpetuity) = FCFF(1+g)/(WACC-g) | B26: =B19*(1+$B$4)/($B$3-$B$4)
A27: PV of TV — perpetuity | B27: =B26/(1+$B$3)^10
A28: PV of TV — SELECTED | B28: =IF($B$6="Perpetuity",B27,B25)
A30: EQUITY BRIDGE -> VALUE / SHARE
A31: Operating value (enterprise value) | B31: =B16+B28
A32: + Cash & ST investments | B32: =Financials!AC48
A33: - Long-term debt | B33: =-Financials!AC53
A34: Equity value | B34: =B31+B32+B33
A35: Diluted shares (M) | B35: =Financials!AC17
A36: VALUE / SHARE | B36: =B34/B35*1.0
A38: CROSS-CHECKS & RETURN
A39: Terminal weight (% of EV) | B39: =B28/B31
A40: Implied perpetuity g (from exit multiple) | B40: =(B24*$B$3-B19)/(B24+B19)
A41: Implied exit EV/EBITDA (from perpetuity) | B41: =B26/B22
A42: Upside / (downside) to fair value | B42: =B36/$B$2-1
A44: Owner cashflow / share | B44: =-$B$2 | C44: =C12/B35 | D44: =D12/B35 | E44: =E12/B35 | F44: =F12/B35 | G44: =G12/B35 | H44: =H12/B35 | I44: =I12/B35 | J44: =J12/B35 | K44: =K12/B35 | L44: =L12/B35+B36
A45: IRR (buy at price, hold 10y) | B45: =IRR(B44:L44)

Sheet Sensitivity
A1: Sensitivity — fair value / share (USD)
A2: WACC x exit multiple (EV/EBITDA). Static grid recomputed by every rebuild/refresh — edit the Dashboard, re-run refresh_dcf to update. Shaded = base case; green = above current price.
A4: EV/EBITDA x \ WACC | B4: 0.075519812 | C4: 0.080519812 | D4: 0.085519812 | E4: 0.090519812 | F4: 0.095519812 | G4: 0.10051981 | H4: 0.10551981
A5: 12 | B5: 244.16944 | C5: 234.87028 | D5: 226.002 | E5: 217.5422 | F5: 209.46974 | G5: 201.76471 | H5: 194.40829
A6: 13 | B6: 257.32044 | C6: 247.42525 | D6: 237.99052 | E6: 228.99225 | F6: 220.40781 | G6: 212.21586 | H6: 204.39627
A7: 14 | B7: 270.47144 | C7: 259.98022 | D7: 249.97903 | E7: 240.4423 | F7: 231.34588 | G7: 222.66702 | H7: 214.38425
A8: 15 | B8: 283.62244 | C8: 272.53519 | D8: 261.96755 | E8: 251.89235 | F8: 242.28395 | G8: 233.11818 | H8: 224.37223
A9: 16 | B9: 296.77344 | C9: 285.09015 | D9: 273.95607 | E9: 263.3424 | F9: 253.22201 | G9: 243.56933 | H9: 234.36021
A10: 17 | B10: 309.92444 | C10: 297.64512 | D10: 285.94458 | E10: 274.79245 | F10: 264.16008 | G10: 254.02049 | H10: 244.34819
A11: 18 | B11: 323.07544 | C11: 310.20009 | D11: 297.9331 | E11: 286.24249 | F11: 275.09815 | G11: 264.47164 | H11: 254.33617
A13: Current price | B13: 166.11
A14: Base WACC / multiple | B14: 0.090519812 | C14: 15

Sheet Monte Carlo
A1: Monte Carlo simulation (live) | H1: SIMULATION ENGINE — leave as-is | K1: cagr | L1: term margin | M1: wacc | N1: exit | O1: value/share
A2: 1,000 trials, recomputed in-sheet on every edit. Edit the yellow driver distributions to re-roll. Engine grid is to the right (cols H+). | H2: R0 (base revenue) | I2: =Model!F16 | K2: =MAX(-0.05,NORMINV(RAND(),$C$6,$D$6)) | L2: =MAX(0.02,NORMINV(RAND(),$C$7,$D$7)) | M2: =MIN(0.16,MAX(0.05,NORMINV(RAND(),$C$8,$D$8))) | N2: =MIN(24,MAX(5,NORMINV(RAND(),$C$9,$D$9))) | O2: =$I$8*(SUMPRODUCT(($I$2*(1+K2)^{1;2;3;4;5;6;7;8;9;10})*(($I$3+(L2-$I$3)*{1;2;3;4;5;6;7;8;9;10}/10)*(1-$I$7)+$I$4-$I$4*($I$5+(1.05-$I$5)*{1;2;3;4;5;6;7;8;9;10}/10)-(K2/(1+K2))*$I$6)/(1+M2)^{1;2;3;4;5;6;7;8;9;10})+$I$2*(1+K2)^10*(L2+$I$4)*N2/(1+M2)^10+$I$9-$I$10)/$I$11
H3: m0 (base op margin) | I3: =Model!F30 | K3: =MAX(-0.05,NORMINV(RAND(),$C$6,$D$6)) | L3: =MAX(0.02,NORMINV(RAND(),$C$7,$D$7)) | M3: =MIN(0.16,MAX(0.05,NORMINV(RAND(),$C$8,$D$8))) | N3: =MIN(24,MAX(5,NORMINV(RAND(),$C$9,$D$9))) | O3: =$I$8*(SUMPRODUCT(($I$2*(1+K3)^{1;2;3;4;5;6;7;8;9;10})*(($I$3+(L3-$I$3)*{1;2;3;4;5;6;7;8;9;10}/10)*(1-$I$7)+$I$4-$I$4*($I$5+(1.05-$I$5)*{1;2;3;4;5;6;7;8;9;10}/10)-(K3/(1+K3))*$I$6)/(1+M3)^{1;2;3;4;5;6;7;8;9;10})+$I$2*(1+K3)^10*(L3+$I$4)*N3/(1+M3)^10+$I$9-$I$10)/$I$11
A4: DRIVER DISTRIBUTIONS (yellow = edit; Opus-set defaults) | H4: da (D&A / revenue) | I4: 0.0874413 | K4: =MAX(-0.05,NORMINV(RAND(),$C$6,$D$6)) | L4: =MAX(0.02,NORMINV(RAND(),$C$7,$D$7)) | M4: =MIN(0.16,MAX(0.05,NORMINV(RAND(),$C$8,$D$8))) | N4: =MIN(24,MAX(5,NORMINV(RAND(),$C$9,$D$9))) | O4: =$I$8*(SUMPRODUCT(($I$2*(1+K4)^{1;2;3;4;5;6;7;8;9;10})*(($I$3+(L4-$I$3)*{1;2;3;4;5;6;7;8;9;10}/10)*(1-$I$7)+$I$4-$I$4*($I$5+(1.05-$I$5)*{1;2;3;4;5;6;7;8;9;10}/10)-(K4/(1+K4))*$I$6)/(1+M4)^{1;2;3;4;5;6;7;8;9;10})+$I$2*(1+K4)^10*(L4+$I$4)*N4/(1+M4)^10+$I$9-$I$10)/$I$11
A5: Driver | B5: Dist | C5: Mean | D5: Std dev | H5: cda0 (2026 capex/D&A) | I5: 0.16010741 | K5: =MAX(-0.05,NORMINV(RAND(),$C$6,$D$6)) | L5: =MAX(0.02,NORMINV(RAND(),$C$7,$D$7)) | M5: =MIN(0.16,MAX(0.05,NORMINV(RAND(),$C$8,$D$8))) | N5: =MIN(24,MAX(5,NORMINV(RAND(),$C$9,$D$9))) | O5: =$I$8*(SUMPRODUCT(($I$2*(1+K5)^{1;2;3;4;5;6;7;8;9;10})*(($I$3+(L5-$I$3)*{1;2;3;4;5;6;7;8;9;10}/10)*(1-$I$7)+$I$4-$I$4*($I$5+(1.05-$I$5)*{1;2;3;4;5;6;7;8;9;10}/10)-(K5/(1+K5))*$I$6)/(1+M5)^{1;2;3;4;5;6;7;8;9;10})+$I$2*(1+K5)^10*(L5+$I$4)*N5/(1+M5)^10+$I$9-$I$10)/$I$11
A6: Revenue 10y CAGR | B6: Normal | C6: =(Model!P16/Model!F16)^(1/10)-1 | D6: 0.018969398 | H6: nwc (% incr revenue) | I6: 0.005 | K6: =MAX(-0.05,NORMINV(RAND(),$C$6,$D$6)) | L6: =MAX(0.02,NORMINV(RAND(),$C$7,$D$7)) | M6: =MIN(0.16,MAX(0.05,NORMINV(RAND(),$C$8,$D$8))) | N6: =MIN(24,MAX(5,NORMINV(RAND(),$C$9,$D$9))) | O6: =$I$8*(SUMPRODUCT(($I$2*(1+K6)^{1;2;3;4;5;6;7;8;9;10})*(($I$3+(L6-$I$3)*{1;2;3;4;5;6;7;8;9;10}/10)*(1-$I$7)+$I$4-$I$4*($I$5+(1.05-$I$5)*{1;2;3;4;5;6;7;8;9;10}/10)-(K6/(1+K6))*$I$6)/(1+M6)^{1;2;3;4;5;6;7;8;9;10})+$I$2*(1+K6)^10*(L6+$I$4)*N6/(1+M6)^10+$I$9-$I$10)/$I$11
A7: Terminal operating margin | B7: Normal | C7: =Dashboard!$B$30 | D7: 0.03 | H7: tax | I7: =Valuation!$B$5 | K7: =MAX(-0.05,NORMINV(RAND(),$C$6,$D$6)) | L7: =MAX(0.02,NORMINV(RAND(),$C$7,$D$7)) | M7: =MIN(0.16,MAX(0.05,NORMINV(RAND(),$C$8,$D$8))) | N7: =MIN(24,MAX(5,NORMINV(RAND(),$C$9,$D$9))) | O7: =$I$8*(SUMPRODUCT(($I$2*(1+K7)^{1;2;3;4;5;6;7;8;9;10})*(($I$3+(L7-$I$3)*{1;2;3;4;5;6;7;8;9;10}/10)*(1-$I$7)+$I$4-$I$4*($I$5+(1.05-$I$5)*{1;2;3;4;5;6;7;8;9;10}/10)-(K7/(1+K7))*$I$6)/(1+M7)^{1;2;3;4;5;6;7;8;9;10})+$I$2*(1+K7)^10*(L7+$I$4)*N7/(1+M7)^10+$I$9-$I$10)/$I$11
A8: WACC | B8: Normal | C8: =WACC!B15 | D8: 0.005 | H8: k (calibration) | I8: 0.88189568 | K8: =MAX(-0.05,NORMINV(RAND(),$C$6,$D$6)) | L8: =MAX(0.02,NORMINV(RAND(),$C$7,$D$7)) | M8: =MIN(0.16,MAX(0.05,NORMINV(RAND(),$C$8,$D$8))) | N8: =MIN(24,MAX(5,NORMINV(RAND(),$C$9,$D$9))) | O8: =$I$8*(SUMPRODUCT(($I$2*(1+K8)^{1;2;3;4;5;6;7;8;9;10})*(($I$3+(L8-$I$3)*{1;2;3;4;5;6;7;8;9;10}/10)*(1-$I$7)+$I$4-$I$4*($I$5+(1.05-$I$5)*{1;2;3;4;5;6;7;8;9;10}/10)-(K8/(1+K8))*$I$6)/(1+M8)^{1;2;3;4;5;6;7;8;9;10})+$I$2*(1+K8)^10*(L8+$I$4)*N8/(1+M8)^10+$I$9-$I$10)/$I$11
A9: Exit EV/EBITDA multiple | B9: Normal | C9: =Dashboard!$B$45 | D9: 1.5 | H9: cash | I9: =Financials!AC48 | K9: =MAX(-0.05,NORMINV(RAND(),$C$6,$D$6)) | L9: =MAX(0.02,NORMINV(RAND(),$C$7,$D$7)) | M9: =MIN(0.16,MAX(0.05,NORMINV(RAND(),$C$8,$D$8))) | N9: =MIN(24,MAX(5,NORMINV(RAND(),$C$9,$D$9))) | O9: =$I$8*(SUMPRODUCT(($I$2*(1+K9)^{1;2;3;4;5;6;7;8;9;10})*(($I$3+(L9-$I$3)*{1;2;3;4;5;6;7;8;9;10}/10)*(1-$I$7)+$I$4-$I$4*($I$5+(1.05-$I$5)*{1;2;3;4;5;6;7;8;9;10}/10)-(K9/(1+K9))*$I$6)/(1+M9)^{1;2;3;4;5;6;7;8;9;10})+$I$2*(1+K9)^10*(L9+$I$4)*N9/(1+M9)^10+$I$9-$I$10)/$I$11
H10: debt | I10: =Financials!AC53 | K10: =MAX(-0.05,NORMINV(RAND(),$C$6,$D$6)) | L10: =MAX(0.02,NORMINV(RAND(),$C$7,$D$7)) | M10: =MIN(0.16,MAX(0.05,NORMINV(RAND(),$C$8,$D$8))) | N10: =MIN(24,MAX(5,NORMINV(RAND(),$C$9,$D$9))) | O10: =$I$8*(SUMPRODUCT(($I$2*(1+K10)^{1;2;3;4;5;6;7;8;9;10})*(($I$3+(L10-$I$3)*{1;2;3;4;5;6;7;8;9;10}/10)*(1-$I$7)+$I$4-$I$4*($I$5+(1.05-$I$5)*{1;2;3;4;5;6;7;8;9;10}/10)-(K10/(1+K10))*$I$6)/(1+M10)^{1;2;3;4;5;6;7;8;9;10})+$I$2*(1+K10)^10*(L10+$I$4)*N10/(1+M10)^10+$I$9-$I$10)/$I$11
A11: SIMULATION OUTPUT — value / share (live) | H11: shares | I11: =Financials!AC17 | K11: =MAX(-0.05,NORMINV(RAND(),$C$6,$D$6)) | L11: =MAX(0.02,NORMINV(RAND(),$C$7,$D$7)) | M11: =MIN(0.16,MAX(0.05,NORMINV(RAND(),$C$8,$D$8))) | N11: =MIN(24,MAX(5,NORMINV(RAND(),$C$9,$D$9))) | O11: =$I$8*(SUMPRODUCT(($I$2*(1+K11)^{1;2;3;4;5;6;7;8;9;10})*(($I$3+(L11-$I$3)*{1;2;3;4;5;6;7;8;9;10}/10)*(1-$I$7)+$I$4-$I$4*($I$5+(1.05-$I$5)*{1;2;3;4;5;6;7;8;9;10}/10)-(K11/(1+K11))*$I$6)/(1+M11)^{1;2;3;4;5;6;7;8;9;10})+$I$2*(1+K11)^10*(L11+$I$4)*N11/(1+M11)^10+$I$9-$I$10)/$I$11
A12: Mean | B12: =AVERAGE($O$2:$O$1001) | K12: =MAX(-0.05,NORMINV(RAND(),$C$6,$D$6)) | L12: =MAX(0.02,NORMINV(RAND(),$C$7,$D$7)) | M12: =MIN(0.16,MAX(0.05,NORMINV(RAND(),$C$8,$D$8))) | N12: =MIN(24,MAX(5,NORMINV(RAND(),$C$9,$D$9))) | O12: =$I$8*(SUMPRODUCT(($I$2*(1+K12)^{1;2;3;4;5;6;7;8;9;10})*(($I$3+(L12-$I$3)*{1;2;3;4;5;6;7;8;9;10}/10)*(1-$I$7)+$I$4-$I$4*($I$5+(1.05-$I$5)*{1;2;3;4;5;6;7;8;9;10}/10)-(K12/(1+K12))*$I$6)/(1+M12)^{1;2;3;4;5;6;7;8;9;10})+$I$2*(1+K12)^10*(L12+$I$4)*N12/(1+M12)^10+$I$9-$I$10)/$I$11
A13: Median (P50) | B13: =MEDIAN($O$2:$O$1001) | K13: =MAX(-0.05,NORMINV(RAND(),$C$6,$D$6)) | L13: =MAX(0.02,NORMINV(RAND(),$C$7,$D$7)) | M13: =MIN(0.16,MAX(0.05,NORMINV(RAND(),$C$8,$D$8))) | N13: =MIN(24,MAX(5,NORMINV(RAND(),$C$9,$D$9))) | O13: =$I$8*(SUMPRODUCT(($I$2*(1+K13)^{1;2;3;4;5;6;7;8;9;10})*(($I$3+(L13-$I$3)*{1;2;3;4;5;6;7;8;9;10}/10)*(1-$I$7)+$I$4-$I$4*($I$5+(1.05-$I$5)*{1;2;3;4;5;6;7;8;9;10}/10)-(K13/(1+K13))*$I$6)/(1+M13)^{1;2;3;4;5;6;7;8;9;10})+$I$2*(1+K13)^10*(L13+$I$4)*N13/(1+M13)^10+$I$9-$I$10)/$I$11
A14: Std dev | B14: =STDEV($O$2:$O$1001) | K14: =MAX(-0.05,NORMINV(RAND(),$C$6,$D$6)) | L14: =MAX(0.02,NORMINV(RAND(),$C$7,$D$7)) | M14: =MIN(0.16,MAX(0.05,NORMINV(RAND(),$C$8,$D$8))) | N14: =MIN(24,MAX(5,NORMINV(RAND(),$C$9,$D$9))) | O14: =$I$8*(SUMPRODUCT(($I$2*(1+K14)^{1;2;3;4;5;6;7;8;9;10})*(($I$3+(L14-$I$3)*{1;2;3;4;5;6;7;8;9;10}/10)*(1-$I$7)+$I$4-$I$4*($I$5+(1.05-$I$5)*{1;2;3;4;5;6;7;8;9;10}/10)-(K14/(1+K14))*$I$6)/(1+M14)^{1;2;3;4;5;6;7;8;9;10})+$I$2*(1+K14)^10*(L14+$I$4)*N14/(1+M14)^10+$I$9-$I$10)/$I$11
A15: Min | B15: =MIN($O$2:$O$1001) | K15: =MAX(-0.05,NORMINV(RAND(),$C$6,$D$6)) | L15: =MAX(0.02,NORMINV(RAND(),$C$7,$D$7)) | M15: =MIN(0.16,MAX(0.05,NORMINV(RAND(),$C$8,$D$8))) | N15: =MIN(24,MAX(5,NORMINV(RAND(),$C$9,$D$9))) | O15: =$I$8*(SUMPRODUCT(($I$2*(1+K15)^{1;2;3;4;5;6;7;8;9;10})*(($I$3+(L15-$I$3)*{1;2;3;4;5;6;7;8;9;10}/10)*(1-$I$7)+$I$4-$I$4*($I$5+(1.05-$I$5)*{1;2;3;4;5;6;7;8;9;10}/10)-(K15/(1+K15))*$I$6)/(1+M15)^{1;2;3;4;5;6;7;8;9;10})+$I$2*(1+K15)^10*(L15+$I$4)*N15/(1+M15)^10+$I$9-$I$10)/$I$11
A16: Max | B16: =MAX($O$2:$O$1001) | K16: =MAX(-0.05,NORMINV(RAND(),$C$6,$D$6)) | L16: =MAX(0.02,NORMINV(RAND(),$C$7,$D$7)) | M16: =MIN(0.16,MAX(0.05,NORMINV(RAND(),$C$8,$D$8))) | N16: =MIN(24,MAX(5,NORMINV(RAND(),$C$9,$D$9))) | O16: =$I$8*(SUMPRODUCT(($I$2*(1+K16)^{1;2;3;4;5;6;7;8;9;10})*(($I$3+(L16-$I$3)*{1;2;3;4;5;6;7;8;9;10}/10)*(1-$I$7)+$I$4-$I$4*($I$5+(1.05-$I$5)*{1;2;3;4;5;6;7;8;9;10}/10)-(K16/(1+K16))*$I$6)/(1+M16)^{1;2;3;4;5;6;7;8;9;10})+$I$2*(1+K16)^10*(L16+$I$4)*N16/(1+M16)^10+$I$9-$I$10)/$I$11
A17: Current price | B17: =Valuation!$B$2 | K17: =MAX(-0.05,NORMINV(RAND(),$C$6,$D$6)) | L17: =MAX(0.02,NORMINV(RAND(),$C$7,$D$7)) | M17: =MIN(0.16,MAX(0.05,NORMINV(RAND(),$C$8,$D$8))) | N17: =MIN(24,MAX(5,NORMINV(RAND(),$C$9,$D$9))) | O17: =$I$8*(SUMPRODUCT(($I$2*(1+K17)^{1;2;3;4;5;6;7;8;9;10})*(($I$3+(L17-$I$3)*{1;2;3;4;5;6;7;8;9;10}/10)*(1-$I$7)+$I$4-$I$4*($I$5+(1.05-$I$5)*{1;2;3;4;5;6;7;8;9;10}/10)-(K17/(1+K17))*$I$6)/(1+M17)^{1;2;3;4;5;6;7;8;9;10})+$I$2*(1+K17)^10*(L17+$I$4)*N17/(1+M17)^10+$I$9-$I$10)/$I$11
A18: Base case (full model) | B18: =Valuation!B36 | K18: =MAX(-0.05,NORMINV(RAND(),$C$6,$D$6)) | L18: =MAX(0.02,NORMINV(RAND(),$C$7,$D$7)) | M18: =MIN(0.16,MAX(0.05,NORMINV(RAND(),$C$8,$D$8))) | N18: =MIN(24,MAX(5,NORMINV(RAND(),$C$9,$D$9))) | O18: =$I$8*(SUMPRODUCT(($I$2*(1+K18)^{1;2;3;4;5;6;7;8;9;10})*(($I$3+(L18-$I$3)*{1;2;3;4;5;6;7;8;9;10}/10)*(1-$I$7)+$I$4-$I$4*($I$5+(1.05-$I$5)*{1;2;3;4;5;6;7;8;9;10}/10)-(K18/(1+K18))*$I$6)/(1+M18)^{1;2;3;4;5;6;7;8;9;10})+$I$2*(1+K18)^10*(L18+$I$4)*N18/(1+M18)^10+$I$9-$I$10)/$I$11
K19: =MAX(-0.05,NORMINV(RAND(),$C$6,$D$6)) | L19: =MAX(0.02,NORMINV(RAND(),$C$7,$D$7)) | M19: =MIN(0.16,MAX(0.05,NORMINV(RAND(),$C$8,$D$8))) | N19: =MIN(24,MAX(5,NORMINV(RAND(),$C$9,$D$9))) | O19: =$I$8*(SUMPRODUCT(($I$2*(1+K19)^{1;2;3;4;5;6;7;8;9;10})*(($I$3+(L19-$I$3)*{1;2;3;4;5;6;7;8;9;10}/10)*(1-$I$7)+$I$4-$I$4*($I$5+(1.05-$I$5)*{1;2;3;4;5;6;7;8;9;10}/10)-(K19/(1+K19))*$I$6)/(1+M19)^{1;2;3;4;5;6;7;8;9;10})+$I$2*(1+K19)^10*(L19+$I$4)*N19/(1+M19)^10+$I$9-$I$10)/$I$11
A20: P(undervalued at current price) | B20: =COUNTIF($O$2:$O$1001,">"&Valuation!$B$2)/1000 | K20: =MAX(-0.05,NORMINV(RAND(),$C$6,$D$6)) | L20: =MAX(0.02,NORMINV(RAND(),$C$7,$D$7)) | M20: =MIN(0.16,MAX(0.05,NORMINV(RAND(),$C$8,$D$8))) | N20: =MIN(24,MAX(5,NORMINV(RAND(),$C$9,$D$9))) | O20: =$I$8*(SUMPRODUCT(($I$2*(1+K20)^{1;2;3;4;5;6;7;8;9;10})*(($I$3+(L20-$I$3)*{1;2;3;4;5;6;7;8;9;10}/10)*(1-$I$7)+$I$4-$I$4*($I$5+(1.05-$I$5)*{1;2;3;4;5;6;7;8;9;10}/10)-(K20/(1+K20))*$I$6)/(1+M20)^{1;2;3;4;5;6;7;8;9;10})+$I$2*(1+K20)^10*(L20+$I$4)*N20/(1+M20)^10+$I$9-$I$10)/$I$11
A21: P(>20% upside) | B21: =COUNTIF($O$2:$O$1001,">"&Valuation!$B$2*1.2)/1000 | K21: =MAX(-0.05,NORMINV(RAND(),$C$6,$D$6)) | L21: =MAX(0.02,NORMINV(RAND(),$C$7,$D$7)) | M21: =MIN(0.16,MAX(0.05,NORMINV(RAND(),$C$8,$D$8))) | N21: =MIN(24,MAX(5,NORMINV(RAND(),$C$9,$D$9))) | O21: =$I$8*(SUMPRODUCT(($I$2*(1+K21)^{1;2;3;4;5;6;7;8;9;10})*(($I$3+(L21-$I$3)*{1;2;3;4;5;6;7;8;9;10}/10)*(1-$I$7)+$I$4-$I$4*($I$5+(1.05-$I$5)*{1;2;3;4;5;6;7;8;9;10}/10)-(K21/(1+K21))*$I$6)/(1+M21)^{1;2;3;4;5;6;7;8;9;10})+$I$2*(1+K21)^10*(L21+$I$4)*N21/(1+M21)^10+$I$9-$I$10)/$I$11
K22: =MAX(-0.05,NORMINV(RAND(),$C$6,$D$6)) | L22: =MAX(0.02,NORMINV(RAND(),$C$7,$D$7)) | M22: =MIN(0.16,MAX(0.05,NORMINV(RAND(),$C$8,$D$8))) | N22: =MIN(24,MAX(5,NORMINV(RAND(),$C$9,$D$9))) | O22: =$I$8*(SUMPRODUCT(($I$2*(1+K22)^{1;2;3;4;5;6;7;8;9;10})*(($I$3+(L22-$I$3)*{1;2;3;4;5;6;7;8;9;10}/10)*(1-$I$7)+$I$4-$I$4*($I$5+(1.05-$I$5)*{1;2;3;4;5;6;7;8;9;10}/10)-(K22/(1+K22))*$I$6)/(1+M22)^{1;2;3;4;5;6;7;8;9;10})+$I$2*(1+K22)^10*(L22+$I$4)*N22/(1+M22)^10+$I$9-$I$10)/$I$11
A23: PERCENTILES (live) | K23: =MAX(-0.05,NORMINV(RAND(),$C$6,$D$6)) | L23: =MAX(0.02,NORMINV(RAND(),$C$7,$D$7)) | M23: =MIN(0.16,MAX(0.05,NORMINV(RAND(),$C$8,$D$8))) | N23: =MIN(24,MAX(5,NORMINV(RAND(),$C$9,$D$9))) | O23: =$I$8*(SUMPRODUCT(($I$2*(1+K23)^{1;2;3;4;5;6;7;8;9;10})*(($I$3+(L23-$I$3)*{1;2;3;4;5;6;7;8;9;10}/10)*(1-$I$7)+$I$4-$I$4*($I$5+(1.05-$I$5)*{1;2;3;4;5;6;7;8;9;10}/10)-(K23/(1+K23))*$I$6)/(1+M23)^{1;2;3;4;5;6;7;8;9;10})+$I$2*(1+K23)^10*(L23+$I$4)*N23/(1+M23)^10+$I$9-$I$10)/$I$11
A24: P5 | B24: =PERCENTILE($O$2:$O$1001,0.05) | K24: =MAX(-0.05,NORMINV(RAND(),$C$6,$D$6)) | L24: =MAX(0.02,NORMINV(RAND(),$C$7,$D$7)) | M24: =MIN(0.16,MAX(0.05,NORMINV(RAND(),$C$8,$D$8))) | N24: =MIN(24,MAX(5,NORMINV(RAND(),$C$9,$D$9))) | O24: =$I$8*(SUMPRODUCT(($I$2*(1+K24)^{1;2;3;4;5;6;7;8;9;10})*(($I$3+(L24-$I$3)*{1;2;3;4;5;6;7;8;9;10}/10)*(1-$I$7)+$I$4-$I$4*($I$5+(1.05-$I$5)*{1;2;3;4;5;6;7;8;9;10}/10)-(K24/(1+K24))*$I$6)/(1+M24)^{1;2;3;4;5;6;7;8;9;10})+$I$2*(1+K24)^10*(L24+$I$4)*N24/(1+M24)^10+$I$9-$I$10)/$I$11
A25: P10 | B25: =PERCENTILE($O$2:$O$1001,0.1) | K25: =MAX(-0.05,NORMINV(RAND(),$C$6,$D$6)) | L25: =MAX(0.02,NORMINV(RAND(),$C$7,$D$7)) | M25: =MIN(0.16,MAX(0.05,NORMINV(RAND(),$C$8,$D$8))) | N25: =MIN(24,MAX(5,NORMINV(RAND(),$C$9,$D$9))) | O25: =$I$8*(SUMPRODUCT(($I$2*(1+K25)^{1;2;3;4;5;6;7;8;9;10})*(($I$3+(L25-$I$3)*{1;2;3;4;5;6;7;8;9;10}/10)*(1-$I$7)+$I$4-$I$4*($I$5+(1.05-$I$5)*{1;2;3;4;5;6;7;8;9;10}/10)-(K25/(1+K25))*$I$6)/(1+M25)^{1;2;3;4;5;6;7;8;9;10})+$I$2*(1+K25)^10*(L25+$I$4)*N25/(1+M25)^10+$I$9-$I$10)/$I$11
A26: P25 | B26: =PERCENTILE($O$2:$O$1001,0.25) | K26: =MAX(-0.05,NORMINV(RAND(),$C$6,$D$6)) | L26: =MAX(0.02,NORMINV(RAND(),$C$7,$D$7)) | M26: =MIN(0.16,MAX(0.05,NORMINV(RAND(),$C$8,$D$8))) | N26: =MIN(24,MAX(5,NORMINV(RAND(),$C$9,$D$9))) | O26: =$I$8*(SUMPRODUCT(($I$2*(1+K26)^{1;2;3;4;5;6;7;8;9;10})*(($I$3+(L26-$I$3)*{1;2;3;4;5;6;7;8;9;10}/10)*(1-$I$7)+$I$4-$I$4*($I$5+(1.05-$I$5)*{1;2;3;4;5;6;7;8;9;10}/10)-(K26/(1+K26))*$I$6)/(1+M26)^{1;2;3;4;5;6;7;8;9;10})+$I$2*(1+K26)^10*(L26+$I$4)*N26/(1+M26)^10+$I$9-$I$10)/$I$11
A27: P50 | B27: =PERCENTILE($O$2:$O$1001,0.5) | K27: =MAX(-0.05,NORMINV(RAND(),$C$6,$D$6)) | L27: =MAX(0.02,NORMINV(RAND(),$C$7,$D$7)) | M27: =MIN(0.16,MAX(0.05,NORMINV(RAND(),$C$8,$D$8))) | N27: =MIN(24,MAX(5,NORMINV(RAND(),$C$9,$D$9))) | O27: =$I$8*(SUMPRODUCT(($I$2*(1+K27)^{1;2;3;4;5;6;7;8;9;10})*(($I$3+(L27-$I$3)*{1;2;3;4;5;6;7;8;9;10}/10)*(1-$I$7)+$I$4-$I$4*($I$5+(1.05-$I$5)*{1;2;3;4;5;6;7;8;9;10}/10)-(K27/(1+K27))*$I$6)/(1+M27)^{1;2;3;4;5;6;7;8;9;10})+$I$2*(1+K27)^10*(L27+$I$4)*N27/(1+M27)^10+$I$9-$I$10)/$I$11
