Workbook

Sheet Cover
A1: GitLab Inc. (GTLB)
A2: DCF valuation — exit-multiple terminal · defaults anchored to consensus
A4: Last updated | B4: 2026-06-05
A5: Data pulled (FMP) | B5: Q4 2026
A6: Assumptions by | B6: Opus 4.8 — 2026-06-05
A8: VALUATION SUMMARY
A10: Fair value / share | B10: =Valuation!B36
A11: Current price | B11: =Valuation!$B$2
A12: Upside / (downside) | B12: =Valuation!B42
A13: Verdict | B13: =IF(Valuation!B36>Valuation!$B$2,"Undervalued","Overvalued")
A14: Monte Carlo P(undervalued) | B14: ='Monte Carlo'!B20
A15: KEY ASSUMPTIONS
A17: WACC (from WACC tab) | B17: =WACC!B14
A18: Terminal method | B18: =Valuation!$B$6
A19: Exit basis / multiple | B19: =Valuation!$B$7
A20: Exit multiple | B20: =Valuation!$B$8
A21: Terminal growth (g) | B21: =Valuation!$B$4
A22: Terminal weight | B22: =Valuation!B39
A23: Forecast horizon | B23: 10 years
A25: THE STORY (Opus)
A27: (Opus narrative)

Sheet Dashboard
A1: GitLab Inc. (GTLB) — Control Dashboard
A2: Edit the yellow cells; everything recomputes. Orange = a driver you've moved off consensus.
A4: VERDICT
A5: Fair value / share | B5: =Valuation!B36
A6: Current price | B6: =Dashboard!$B$48
A7: Upside / (downside) | B7: =Valuation!B42
A8: Verdict | B8: =IF(Valuation!B36>Dashboard!$B$48,"Undervalued","Overvalued")
A9: Monte Carlo P(undervalued) | B9: ='Monte Carlo'!B20
A11: GUARDRAIL SIGNALS (are my assumptions sane?)
A12: Signal | B12: Value | C12: Flag | D12: Healthy
A13: Terminal weight (% of EV) | B13: =Valuation!B39 | C13: =IF(Valuation!B39>0.9,"! high","ok") | D13: < 90%
A14: Implied g vs exit multiple | B14: =Valuation!B40 | C14: =IF(Valuation!B40>Dashboard!$B$46+0.02,"! rich","ok") | D14: near term g
A15: ROIC - WACC (2026) | B15: =Model!G46-WACC!B14 | C15: =IF(Model!G46-WACC!B14<0,"! destroys","creates") | D15: > 0
A16: Revenue vs consensus (2026) | B16: =Consensus!B6 | C16: =IF(ABS(Consensus!B6)>0.05,"! off-Street","on") | D16: +/- 5%
A17: MC P(undervalued) | B17: ='Monte Carlo'!B20 | C17: =IF('Monte Carlo'!B20<0.5,"! coin-flip","ok") | D17: context
A18: REVENUE DRIVERS — near-term & terminal growth per segment
A19: Segment | B19: Near-term | C19: Terminal | D19: Consensus | E19: Thesis claim
A20: Subscription and Software | B20: -0.05612049 | C20: 0.05 | D20: -0.05612049
A21: Subscription and Circulation | B21: 0.082937261 | C21: 0.05 | D21: 0.082937261
A22: Subscription, Software As A Service | B22: 0.13054618 | C22: 0.05 | D22: 0.13054618
A23: License, Professional Services, and Other | B23: -0.05612049 | C23: 0.05 | D23: -0.05612049
A24: License | B24: -0.097053312 | C24: 0.05 | D24: -0.097053312
A25: Professional Services and Other | B25: 0.13054618 | C25: 0.05 | D25: 0.13054618
A28: PROFITABILITY & TAX
A29: Near-term operating margin | B29: 0.175542 | D29: 0.175542 | E29: consensus-implied; ramps to terminal
A30: Terminal operating margin | B30: 0.17203977 | E30: AI/ads mix + operating leverage
A31: Tax rate | B31: 0.24
A33: CAPITAL INTENSITY
A34: 2026 capex ($M) | B34: 11.9097 | D34: 11.9097 | E34: ~last-year capex +10%; set to guidance
A35: Terminal capex / D&A | B35: 1.05 | E35: converges to ~1.0x as build-out matures
A37: DISCOUNT RATE & TERMINAL
A38: Risk-free rate (10Y) | B38: 0.043
A39: Equity risk premium | B39: 0.045
A40: Beta (levered) | B40: 0.823 | E40: FMP raw beta; Damodaran bottom-up ~1.2
A41: Pre-tax cost of debt | B41: 0.045
A42: WACC (computed) | B42: =WACC!B14
A43: Terminal method | B43: Exit multiple
A44: Exit basis | B44: EV/EBITDA
A45: Exit multiple | B45: 12
A46: Terminal growth (g) | B46: 0.045
...

Sheet Color Code
A1: Color | B1: Meaning
A2: Black | B2: Formula-driven (same-sheet)
A3: Blue | B3: Hard-coded actuals (from FMP filings)
A4: Yellow | B4: An assumption you can change — edit these to drive the model
A5: Green | B5: A formula that links to another sheet
A6: Orange | B6: (Dashboard) an assumption you've moved off consensus — your active bet
A7: How to use | B7: Edit yellow cells (Model assumptions, WACC drivers, Valuation toggles). Everything else recomputes.

Sheet WACC
A1: WACC Calculator
A2: Risk-free rate (10Y) | B2: =Dashboard!$B$38
A3: Equity risk premium | B3: =Dashboard!$B$39
A4: Beta (levered) | B4: =Dashboard!$B$40
A5: Cost of equity (CAPM) | B5: =B2+B4*B3
A6: Pre-tax cost of debt | B6: =Dashboard!$B$41
A7: Tax rate | B7: =Dashboard!$B$31
A8: After-tax cost of debt | B8: =B6*(1-B7)
A9: Market cap (E) | B9: =Dashboard!$B$48*Financials!Y17
A10: Total debt (D) | B10: =Financials!Y53
A11: Equity weight | B11: =B9/(B9+B10)
A12: Debt weight | B12: =B10/(B9+B10)
A14: WACC | B14: =B11*B5+B12*B8
A16: Yellow = edit. CAPM cost of equity; market-value weights. Feeds Valuation!WACC.

Sheet Model
A1: $M unless noted | B1: FY2022A | C1: FY2023A | D1: FY2024A | E1: FY2025A | F1: FY2026A | G1: FY2027E | H1: FY2028E | I1: FY2029E | J1: FY2030E | K1: FY2031E | L1: FY2032E | M1: FY2033E | N1: FY2034E | O1: FY2035E | P1: FY2036E
A3: REVENUE BY SEGMENT (yellow = growth assumption; actuals link to Financials)
A4: Subscription and Software | B4: =SUM(Financials!F19:I19) | C4: =SUM(Financials!J19:M19) | D4: =SUM(Financials!N19:Q19) | E4: =SUM(Financials!R19:U19) | F4: =SUM(Financials!V19:Y19) | G4: =F4*(1+G5) | H4: =G4*(1+H5) | I4: =H4*(1+I5) | J4: =I4*(1+J5) | K4: =J4*(1+K5) | L4: =K4*(1+L5) | M4: =L4*(1+M5) | N4: =M4*(1+N5) | ... P4: =O4*(1+P5)
A5: growth % (interpolated from Dashboard) | C5: =IFERROR(C4/B4-1,"") | D5: =IFERROR(D4/C4-1,"") | E5: =IFERROR(E4/D4-1,"") | F5: =IFERROR(F4/E4-1,"") | G5: =Dashboard!$B$20+(Dashboard!$C$20-Dashboard!$B$20)*MAX(0,0-2)/7 | H5: =Dashboard!$B$20+(Dashboard!$C$20-Dashboard!$B$20)*MAX(0,1-2)/7 | I5: =Dashboard!$B$20+(Dashboard!$C$20-Dashboard!$B$20)*MAX(0,2-2)/7 | J5: =Dashboard!$B$20+(Dashboard!$C$20-Dashboard!$B$20)*MAX(0,3-2)/7 | K5: =Dashboard!$B$20+(Dashboard!$C$20-Dashboard!$B$20)*MAX(0,4-2)/7 | L5: =Dashboard!$B$20+(Dashboard!$C$20-Dashboard!$B$20)*MAX(0,5-2)/7 | M5: =Dashboard!$B$20+(Dashboard!$C$20-Dashboard!$B$20)*MAX(0,6-2)/7 | N5: =Dashboard!$B$20+(Dashboard!$C$20-Dashboard!$B$20)*MAX(0,7-2)/7 | O5: =Dashboard!$B$20+(Dashboard!$C$20-Dashboard!$B$20)*MAX(0,8-2)/7 | P5: =Dashboard!$B$20+(Dashboard!$C$20-Dashboard!$B$20)*MAX(0,9-2)/7
A6: Subscription and Circulation | B6: =SUM(Financials!F22:I22) | C6: =SUM(Financials!J22:M22) | D6: =SUM(Financials!N22:Q22) | E6: =SUM(Financials!R22:U22) | F6: =SUM(Financials!V22:Y22) | G6: =F6*(1+G7) | H6: =G6*(1+H7) | I6: =H6*(1+I7) | J6: =I6*(1+J7) | K6: =J6*(1+K7) | L6: =K6*(1+L7) | M6: =L6*(1+M7) | N6: =M6*(1+N7) | ... P6: =O6*(1+P7)
A7: growth % (interpolated from Dashboard) | C7: =IFERROR(C6/B6-1,"") | D7: =IFERROR(D6/C6-1,"") | E7: =IFERROR(E6/D6-1,"") | F7: =IFERROR(F6/E6-1,"") | G7: =Dashboard!$B$21+(Dashboard!$C$21-Dashboard!$B$21)*MAX(0,0-2)/7 | H7: =Dashboard!$B$21+(Dashboard!$C$21-Dashboard!$B$21)*MAX(0,1-2)/7 | I7: =Dashboard!$B$21+(Dashboard!$C$21-Dashboard!$B$21)*MAX(0,2-2)/7 | J7: =Dashboard!$B$21+(Dashboard!$C$21-Dashboard!$B$21)*MAX(0,3-2)/7 | K7: =Dashboard!$B$21+(Dashboard!$C$21-Dashboard!$B$21)*MAX(0,4-2)/7 | L7: =Dashboard!$B$21+(Dashboard!$C$21-Dashboard!$B$21)*MAX(0,5-2)/7 | M7: =Dashboard!$B$21+(Dashboard!$C$21-Dashboard!$B$21)*MAX(0,6-2)/7 | N7: =Dashboard!$B$21+(Dashboard!$C$21-Dashboard!$B$21)*MAX(0,7-2)/7 | O7: =Dashboard!$B$21+(Dashboard!$C$21-Dashboard!$B$21)*MAX(0,8-2)/7 | P7: =Dashboard!$B$21+(Dashboard!$C$21-Dashboard!$B$21)*MAX(0,9-2)/7
A8: Subscription, Software As A Service | B8: =SUM(Financials!F25:I25) | C8: =SUM(Financials!J25:M25) | D8: =SUM(Financials!N25:Q25) | E8: =SUM(Financials!R25:U25) | F8: =SUM(Financials!V25:Y25) | G8: =F8*(1+G9) | H8: =G8*(1+H9) | I8: =H8*(1+I9) | J8: =I8*(1+J9) | K8: =J8*(1+K9) | L8: =K8*(1+L9) | M8: =L8*(1+M9) | N8: =M8*(1+N9) | ... P8: =O8*(1+P9)
A9: growth % (interpolated from Dashboard) | C9: =IFERROR(C8/B8-1,"") | D9: =IFERROR(D8/C8-1,"") | E9: =IFERROR(E8/D8-1,"") | F9: =IFERROR(F8/E8-1,"") | G9: =Dashboard!$B$22+(Dashboard!$C$22-Dashboard!$B$22)*MAX(0,0-2)/7 | H9: =Dashboard!$B$22+(Dashboard!$C$22-Dashboard!$B$22)*MAX(0,1-2)/7 | I9: =Dashboard!$B$22+(Dashboard!$C$22-Dashboard!$B$22)*MAX(0,2-2)/7 | J9: =Dashboard!$B$22+(Dashboard!$C$22-Dashboard!$B$22)*MAX(0,3-2)/7 | K9: =Dashboard!$B$22+(Dashboard!$C$22-Dashboard!$B$22)*MAX(0,4-2)/7 | L9: =Dashboard!$B$22+(Dashboard!$C$22-Dashboard!$B$22)*MAX(0,5-2)/7 | M9: =Dashboard!$B$22+(Dashboard!$C$22-Dashboard!$B$22)*MAX(0,6-2)/7 | N9: =Dashboard!$B$22+(Dashboard!$C$22-Dashboard!$B$22)*MAX(0,7-2)/7 | O9: =Dashboard!$B$22+(Dashboard!$C$22-Dashboard!$B$22)*MAX(0,8-2)/7 | P9: =Dashboard!$B$22+(Dashboard!$C$22-Dashboard!$B$22)*MAX(0,9-2)/7
A10: License, Professional Services, and Other | B10: =SUM(Financials!F28:I28) | C10: =SUM(Financials!J28:M28) | D10: =SUM(Financials!N28:Q28) | E10: =SUM(Financials!R28:U28) | F10: =SUM(Financials!V28:Y28) | G10: =F10*(1+G11) | H10: =G10*(1+H11) | I10: =H10*(1+I11) | J10: =I10*(1+J11) | K10: =J10*(1+K11) | L10: =K10*(1+L11) | M10: =L10*(1+M11) | N10: =M10*(1+N11) | ... P10: =O10*(1+P11)
A11: growth % (interpolated from Dashboard) | C11: =IFERROR(C10/B10-1,"") | D11: =IFERROR(D10/C10-1,"") | E11: =IFERROR(E10/D10-1,"") | F11: =IFERROR(F10/E10-1,"") | G11: =Dashboard!$B$23+(Dashboard!$C$23-Dashboard!$B$23)*MAX(0,0-2)/7 | H11: =Dashboard!$B$23+(Dashboard!$C$23-Dashboard!$B$23)*MAX(0,1-2)/7 | I11: =Dashboard!$B$23+(Dashboard!$C$23-Dashboard!$B$23)*MAX(0,2-2)/7 | J11: =Dashboard!$B$23+(Dashboard!$C$23-Dashboard!$B$23)*MAX(0,3-2)/7 | K11: =Dashboard!$B$23+(Dashboard!$C$23-Dashboard!$B$23)*MAX(0,4-2)/7 | L11: =Dashboard!$B$23+(Dashboard!$C$23-Dashboard!$B$23)*MAX(0,5-2)/7 | M11: =Dashboard!$B$23+(Dashboard!$C$23-Dashboard!$B$23)*MAX(0,6-2)/7 | N11: =Dashboard!$B$23+(Dashboard!$C$23-Dashboard!$B$23)*MAX(0,7-2)/7 | O11: =Dashboard!$B$23+(Dashboard!$C$23-Dashboard!$B$23)*MAX(0,8-2)/7 | P11: =Dashboard!$B$23+(Dashboard!$C$23-Dashboard!$B$23)*MAX(0,9-2)/7
A12: License | B12: =SUM(Financials!F31:I31) | C12: =SUM(Financials!J31:M31) | D12: =SUM(Financials!N31:Q31) | E12: =SUM(Financials!R31:U31) | F12: =SUM(Financials!V31:Y31) | G12: =F12*(1+G13) | H12: =G12*(1+H13) | I12: =H12*(1+I13) | J12: =I12*(1+J13) | K12: =J12*(1+K13) | L12: =K12*(1+L13) | M12: =L12*(1+M13) | N12: =M12*(1+N13) | ... P12: =O12*(1+P13)
A13: growth % (interpolated from Dashboard) | C13: =IFERROR(C12/B12-1,"") | D13: =IFERROR(D12/C12-1,"") | E13: =IFERROR(E12/D12-1,"") | F13: =IFERROR(F12/E12-1,"") | G13: =Dashboard!$B$24+(Dashboard!$C$24-Dashboard!$B$24)*MAX(0,0-2)/7 | H13: =Dashboard!$B$24+(Dashboard!$C$24-Dashboard!$B$24)*MAX(0,1-2)/7 | I13: =Dashboard!$B$24+(Dashboard!$C$24-Dashboard!$B$24)*MAX(0,2-2)/7 | J13: =Dashboard!$B$24+(Dashboard!$C$24-Dashboard!$B$24)*MAX(0,3-2)/7 | K13: =Dashboard!$B$24+(Dashboard!$C$24-Dashboard!$B$24)*MAX(0,4-2)/7 | L13: =Dashboard!$B$24+(Dashboard!$C$24-Dashboard!$B$24)*MAX(0,5-2)/7 | M13: =Dashboard!$B$24+(Dashboard!$C$24-Dashboard!$B$24)*MAX(0,6-2)/7 | N13: =Dashboard!$B$24+(Dashboard!$C$24-Dashboard!$B$24)*MAX(0,7-2)/7 | O13: =Dashboard!$B$24+(Dashboard!$C$24-Dashboard!$B$24)*MAX(0,8-2)/7 | P13: =Dashboard!$B$24+(Dashboard!$C$24-Dashboard!$B$24)*MAX(0,9-2)/7
A14: Professional Services and Other | B14: =SUM(Financials!F34:I34) | C14: =SUM(Financials!J34:M34) | D14: =SUM(Financials!N34:Q34) | E14: =SUM(Financials!R34:U34) | F14: =SUM(Financials!V34:Y34) | G14: =F14*(1+G15) | H14: =G14*(1+H15) | I14: =H14*(1+I15) | J14: =I14*(1+J15) | K14: =J14*(1+K15) | L14: =K14*(1+L15) | M14: =L14*(1+M15) | N14: =M14*(1+N15) | ... P14: =O14*(1+P15)
A15: growth % (interpolated from Dashboard) | C15: =IFERROR(C14/B14-1,"") | D15: =IFERROR(D14/C14-1,"") | E15: =IFERROR(E14/D14-1,"") | F15: =IFERROR(F14/E14-1,"") | G15: =Dashboard!$B$25+(Dashboard!$C$25-Dashboard!$B$25)*MAX(0,0-2)/7 | H15: =Dashboard!$B$25+(Dashboard!$C$25-Dashboard!$B$25)*MAX(0,1-2)/7 | I15: =Dashboard!$B$25+(Dashboard!$C$25-Dashboard!$B$25)*MAX(0,2-2)/7 | J15: =Dashboard!$B$25+(Dashboard!$C$25-Dashboard!$B$25)*MAX(0,3-2)/7 | K15: =Dashboard!$B$25+(Dashboard!$C$25-Dashboard!$B$25)*MAX(0,4-2)/7 | L15: =Dashboard!$B$25+(Dashboard!$C$25-Dashboard!$B$25)*MAX(0,5-2)/7 | M15: =Dashboard!$B$25+(Dashboard!$C$25-Dashboard!$B$25)*MAX(0,6-2)/7 | N15: =Dashboard!$B$25+(Dashboard!$C$25-Dashboard!$B$25)*MAX(0,7-2)/7 | O15: =Dashboard!$B$25+(Dashboard!$C$25-Dashboard!$B$25)*MAX(0,8-2)/7 | P15: =Dashboard!$B$25+(Dashboard!$C$25-Dashboard!$B$25)*MAX(0,9-2)/7
A16: Total revenue | B16: =B4+B6+B8+B10+B12+B14 | C16: =C4+C6+C8+C10+C12+C14 | D16: =D4+D6+D8+D10+D12+D14 | E16: =E4+E6+E8+E10+E12+E14 | F16: =F4+F6+F8+F10+F12+F14 | G16: =G4+G6+G8+G10+G12+G14 | H16: =H4+H6+H8+H10+H12+H14 | I16: =I4+I6+I8+I10+I12+I14 | ... P16: =P4+P6+P8+P10+P12+P14
A17: growth % | C17: =IFERROR(C16/B16-1,"") | D17: =IFERROR(D16/C16-1,"") | E17: =IFERROR(E16/D16-1,"") | F17: =IFERROR(F16/E16-1,"") | G17: =IFERROR(G16/F16-1,"") | H17: =IFERROR(H16/G16-1,"") | I17: =IFERROR(I16/H16-1,"") | J17: =IFERROR(J16/I16-1,"") | ... P17: =IFERROR(P16/O16-1,"")
A19: COST STRUCTURE (yellow = % of revenue)
A20: Cost of revenue | B20: =SUM(Financials!F5:I5) | C20: =SUM(Financials!J5:M5) | D20: =SUM(Financials!N5:Q5) | E20: =SUM(Financials!R5:U5) | F20: =SUM(Financials!V5:Y5) | G20: =G16*G21 | H20: =H16*H21 | I20: =I16*I21 | J20: =J16*J21 | K20: =K16*K21 | L20: =L16*L21 | M20: =M16*M21 | N20: =N16*N21 | ... P20: =P16*P21
A21: % of revenue | B21: =IFERROR(B20/B16,"") | C21: =IFERROR(C20/C16,"") | D21: =IFERROR(D20/D16,"") | E21: =IFERROR(E20/E16,"") | F21: =IFERROR(F20/F16,"") | G21: 0.12624264 | H21: 0.12624264 | I21: 0.12624264 | J21: 0.12624264 | K21: 0.12624264 | L21: 0.12624264 | M21: 0.12624264 | N21: 0.12624264 | O21: 0.12624264 | P21: 0.12624264
A22: R&D / Technology | B22: =SUM(Financials!F7:I7) | C22: =SUM(Financials!J7:M7) | D22: =SUM(Financials!N7:Q7) | E22: =SUM(Financials!R7:U7) | F22: =SUM(Financials!V7:Y7) | G22: =G16*G23 | H22: =H16*H23 | I22: =I16*I23 | J22: =J16*J23 | K22: =K16*K23 | L22: =L16*L23 | M22: =M16*M23 | N22: =N16*N23 | ... P22: =P16*P23
A23: % of revenue | B23: =IFERROR(B22/B16,"") | C23: =IFERROR(C22/C16,"") | D23: =IFERROR(D22/D16,"") | E23: =IFERROR(E22/E16,"") | F23: =IFERROR(F22/F16,"") | G23: 0.28744462 | H23: 0.28744462 | I23: 0.28744462 | J23: 0.28744462 | K23: 0.28744462 | L23: 0.28744462 | M23: 0.28744462 | N23: 0.28744462 | O23: 0.28744462 | P23: 0.28744462
A24: SG&A | B24: =SUM(Financials!F9:I9) | C24: =SUM(Financials!J9:M9) | D24: =SUM(Financials!N9:Q9) | E24: =SUM(Financials!R9:U9) | F24: =SUM(Financials!V9:Y9) | G24: =G16*G25 | H24: =H16*H25 | I24: =I16*I25 | J24: =J16*J25 | K24: =K16*K25 | L24: =L16*L25 | M24: =M16*M25 | N24: =N16*N25 | ... P24: =P16*P25
A25: % of revenue | B25: =IFERROR(B24/B16,"") | C25: =IFERROR(C24/C16,"") | D25: =IFERROR(D24/D16,"") | E25: =IFERROR(E24/E16,"") | F25: =IFERROR(F24/F16,"") | G25: 0.65822886 | H25: 0.65822886 | I25: 0.65822886 | J25: 0.65822886 | K25: 0.65822886 | L25: 0.65822886 | M25: 0.65822886 | N25: 0.65822886 | O25: 0.65822886 | P25: 0.65822886
A26: Other opex (fulfilment, etc.) | B26: =B16-(B20+B22+B24)-SUM(Financials!F13:I13) | C26: =C16-(C20+C22+C24)-SUM(Financials!J13:M13) | D26: =D16-(D20+D22+D24)-SUM(Financials!N13:Q13) | E26: =E16-(E20+E22+E24)-SUM(Financials!R13:U13) | F26: =F16-(F20+F22+F24)-SUM(Financials!V13:Y13) | G26: =G16*(1-(Dashboard!$B$29+(Dashboard!$B$30-Dashboard!$B$29)*MIN(1,0/4)))-(G20+G22+G24) | H26: =H16*(1-(Dashboard!$B$29+(Dashboard!$B$30-Dashboard!$B$29)*MIN(1,1/4)))-(H20+H22+H24) | I26: =I16*(1-(Dashboard!$B$29+(Dashboard!$B$30-Dashboard!$B$29)*MIN(1,2/4)))-(I20+I22+I24) | J26: =J16*(1-(Dashboard!$B$29+(Dashboard!$B$30-Dashboard!$B$29)*MIN(1,3/4)))-(J20+J22+J24) | K26: =K16*(1-(Dashboard!$B$29+(Dashboard!$B$30-Dashboard!$B$29)*MIN(1,4/4)))-(K20+K22+K24) | L26: =L16*(1-(Dashboard!$B$29+(Dashboard!$B$30-Dashboard!$B$29)*MIN(1,5/4)))-(L20+L22+L24) | M26: =M16*(1-(Dashboard!$B$29+(Dashboard!$B$30-Dashboard!$B$29)*MIN(1,6/4)))-(M20+M22+M24) | N26: =N16*(1-(Dashboard!$B$29+(Dashboard!$B$30-Dashboard!$B$29)*MIN(1,7/4)))-(N20+N22+N24) | O26: =O16*(1-(Dashboard!$B$29+(Dashboard!$B$30-Dashboard!$B$29)*MIN(1,8/4)))-(O20+O22+O24) | P26: =P16*(1-(Dashboard!$B$29+(Dashboard!$B$30-Dashboard!$B$29)*MIN(1,9/4)))-(P20+P22+P24)
A27: % of revenue | B27: =IFERROR(B26/B16,"") | C27: =IFERROR(C26/C16,"") | D27: =IFERROR(D26/D16,"") | E27: =IFERROR(E26/E16,"") | F27: =IFERROR(F26/F16,"") | G27: =IFERROR(G26/G16,"") | H27: =IFERROR(H26/H16,"") | I27: =IFERROR(I26/I16,"") | ... P27: =IFERROR(P26/P16,"")
A29: Operating income (EBIT) | B29: =B16-(B20+B22+B24)-B26 | C29: =C16-(C20+C22+C24)-C26 | D29: =D16-(D20+D22+D24)-D26 | E29: =E16-(E20+E22+E24)-E26 | F29: =F16-(F20+F22+F24)-F26 | G29: =G16-(G20+G22+G24)-G26 | H29: =H16-(H20+H22+H24)-H26 | I29: =I16-(I20+I22+I24)-I26 | ... P29: =P16-(P20+P22+P24)-P26
A30: operating margin | B30: =IFERROR(B29/B16,"") | C30: =IFERROR(C29/C16,"") | D30: =IFERROR(D29/D16,"") | E30: =IFERROR(E29/E16,"") | F30: =IFERROR(F29/F16,"") | G30: =IFERROR(G29/G16,"") | H30: =IFERROR(H29/H16,"") | I30: =IFERROR(I29/I16,"") | ... P30: =IFERROR(P29/P16,"")
A32: FCF BRIDGE (NOPAT + D&A + SBC - dNWC - Capex)
A33: NOPAT = EBIT x (1 - tax) | B33: =B29*(1-Valuation!$B$5) | C33: =C29*(1-Valuation!$B$5) | D33: =D29*(1-Valuation!$B$5) | E33: =E29*(1-Valuation!$B$5) | F33: =F29*(1-Valuation!$B$5) | G33: =G29*(1-Valuation!$B$5) | H33: =H29*(1-Valuation!$B$5) | I33: =I29*(1-Valuation!$B$5) | ... P33: =P29*(1-Valuation!$B$5)
A34: + D&A | B34: =SUM(Financials!F56:I56) | C34: =SUM(Financials!J56:M56) | D34: =SUM(Financials!N56:Q56) | E34: =SUM(Financials!R56:U56) | F34: =SUM(Financials!V56:Y56) | G34: =G16*0.0098 | H34: =H16*0.0098 | I34: =I16*0.0098 | J34: =J16*0.0098 | K34: =K16*0.0098 | L34: =L16*0.0098 | M34: =M16*0.0098 | N34: =N16*0.0098 | ... P34: =P16*0.0098
A35: + SBC (non-cash) | B35: =SUM(Financials!F57:I57) | C35: =SUM(Financials!J57:M57) | D35: =SUM(Financials!N57:Q57) | E35: =SUM(Financials!R57:U57) | F35: =SUM(Financials!V57:Y57) | G35: =G16*0.2250 | H35: =H16*0.2150 | I35: =I16*0.2050 | J35: =J16*0.1950 | K35: =K16*0.1850 | L35: =L16*0.1750 | M35: =M16*0.1650 | N35: =N16*0.1550 | O35: =O16*0.1450 | P35: =P16*0.1350
A36: - dNWC | G36: =(G16-F16)*0.0050 | H36: =(H16-G16)*0.0050 | I36: =(I16-H16)*0.0050 | J36: =(J16-I16)*0.0050 | K36: =(K16-J16)*0.0050 | L36: =(L16-K16)*0.0050 | M36: =(M16-L16)*0.0050 | N36: =(N16-M16)*0.0050 | ... P36: =(P16-O16)*0.0050
A37: - Capex | B37: =-SUM(Financials!F60:I60) | C37: =-SUM(Financials!J60:M60) | D37: =-SUM(Financials!N60:Q60) | E37: =-SUM(Financials!R60:U60) | F37: =-SUM(Financials!V60:Y60) | G37: =G34*G38 | H37: =H34*H38 | I37: =I34*I38 | J37: =J34*J38 | K37: =K34*K38 | L37: =L34*L38 | M37: =M34*M38 | N37: =N34*N38 | ... P37: =P34*P38
A38: Capex / D&A (from Dashboard: $cap'26 -> terminal) | B38: =IFERROR(B37/B34,"") | C38: =IFERROR(C37/C34,"") | D38: =IFERROR(D37/D34,"") | E38: =IFERROR(E37/E34,"") | F38: =IFERROR(F37/F34,"") | G38: =(Dashboard!$B$34/G34)+(Dashboard!$B$35-(Dashboard!$B$34/G34))*0/9 | H38: =(Dashboard!$B$34/G34)+(Dashboard!$B$35-(Dashboard!$B$34/G34))*1/9 | I38: =(Dashboard!$B$34/G34)+(Dashboard!$B$35-(Dashboard!$B$34/G34))*2/9 | J38: =(Dashboard!$B$34/G34)+(Dashboard!$B$35-(Dashboard!$B$34/G34))*3/9 | K38: =(Dashboard!$B$34/G34)+(Dashboard!$B$35-(Dashboard!$B$34/G34))*4/9 | L38: =(Dashboard!$B$34/G34)+(Dashboard!$B$35-(Dashboard!$B$34/G34))*5/9 | M38: =(Dashboard!$B$34/G34)+(Dashboard!$B$35-(Dashboard!$B$34/G34))*6/9 | N38: =(Dashboard!$B$34/G34)+(Dashboard!$B$35-(Dashboard!$B$34/G34))*7/9 | O38: =(Dashboard!$B$34/G34)+(Dashboard!$B$35-(Dashboard!$B$34/G34))*8/9 | P38: =(Dashboard!$B$34/G34)+(Dashboard!$B$35-(Dashboard!$B$34/G34))*9/9
A40: FCFF (firm) | B40: =B33+B34+B35-B36-B37 | C40: =C33+C34+C35-C36-C37 | D40: =D33+D34+D35-D36-D37 | E40: =E33+E34+E35-E36-E37 | F40: =F33+F34+F35-F36-F37 | G40: =G33+G34+G35-G36-G37 | H40: =H33+H34+H35-H36-H37 | I40: =I33+I34+I35-I36-I37 | ... P40: =P33+P34+P35-P36-P37
A41: Valuation FCF (FCFF - SBC) | B41: =B40-B35 | C41: =C40-C35 | D41: =D40-D35 | E41: =E40-E35 | F41: =F40-F35 | G41: =G40-G35 | H41: =H40-H35 | I41: =I40-I35 | ... P41: =P40-P35
A43: RETURNS ON CAPITAL & EFFICIENCY (is new revenue/capital earning its keep?)
A44: Invested capital (debt + equity - cash) | B44: =Financials!I54+Financials!I53-Financials!I48 | C44: =Financials!M54+Financials!M53-Financials!M48 | D44: =Financials!Q54+Financials!Q53-Financials!Q48 | E44: =Financials!U54+Financials!U53-Financials!U48 | F44: =Financials!Y54+Financials!Y53-Financials!Y48 | G44: =F44+G37-G34+G36 | H44: =G44+H37-H34+H36 | I44: =H44+I37-I34+I36 | J44: =I44+J37-J34+J36 | K44: =J44+K37-K34+K36 | L44: =K44+L37-L34+L36 | M44: =L44+M37-M34+M36 | N44: =M44+N37-N34+N36 | ... P44: =O44+P37-P34+P36
A45: Book equity (year-end) | B45: =Financials!I54 | C45: =Financials!M54 | D45: =Financials!Q54 | E45: =Financials!U54 | F45: =Financials!Y54 | G45: =F45+G33 | H45: =G45+H33 | I45: =H45+I33 | J45: =I45+J33 | K45: =J45+K33 | L45: =K45+L33 | M45: =L45+M33 | N45: =M45+N33 | ... P45: =O45+P33
A46: ROIC (NOPAT / beg. invested capital) | C46: =IFERROR(C33/B44,"") | D46: =IFERROR(D33/C44,"") | E46: =IFERROR(E33/D44,"") | F46: =IFERROR(F33/E44,"") | G46: =IFERROR(G33/F44,"") | H46: =IFERROR(H33/G44,"") | I46: =IFERROR(I33/H44,"") | J46: =IFERROR(J33/I44,"") | ... P46: =IFERROR(P33/O44,"")
...

Sheet Financials
A1: Line Item ($M) | B1: Q1 2021 | C1: Q2 2021 | D1: Q3 2021 | E1: Q4 2021 | F1: Q1 2022 | G1: Q2 2022 | H1: Q3 2022 | I1: Q4 2022 | J1: Q1 2023 | K1: Q2 2023 | L1: Q3 2023 | M1: Q4 2023 | N1: Q1 2024 | O1: Q2 2024 | P1: Q3 2024 | Q1: Q4 2024 | R1: Q1 2025 | S1: Q2 2025 | T1: Q3 2025 | U1: Q4 2025 | V1: Q1 2026 | W1: Q2 2026 | X1: Q3 2026 | Y1: Q4 2026
A2: INCOME STATEMENT
A3: Revenue | B3: 29.515 | C3: 34.362 | D3: 42.152 | E3: 46.147 | F3: 49.93 | G3: 58.127 | H3: 66.8 | I3: 77.796 | J3: 87.407 | K3: 101.041 | L3: 112.981 | M3: 122.907 | N3: 126.878 | O3: 139.581 | P3: 149.668 | Q3: 163.779 | R3: 169.187 | S3: 182.584 | T3: 196.047 | U3: 211.431 | V3: 214.509 | W3: 235.96 | X3: 244.353 | Y3: 260.402
A4: % YoY | F4: =IFERROR(F3/B3-1,"") | G4: =IFERROR(G3/C3-1,"") | H4: =IFERROR(H3/D3-1,"") | I4: =IFERROR(I3/E3-1,"") | J4: =IFERROR(J3/F3-1,"") | K4: =IFERROR(K3/G3-1,"") | L4: =IFERROR(L3/H3-1,"") | M4: =IFERROR(M3/I3-1,"") | ... Y4: =IFERROR(Y3/U3-1,"")
A5: Cost of Revenue | B5: 3.789 | C5: 3.812 | D5: 4.637 | E5: 6.225 | F5: 6.425 | G5: 7.192 | H5: 7.195 | I5: 9.173 | J5: 9.848 | K5: 13.03 | L5: 14.564 | M5: 14.238 | N5: 13.939 | O5: 14.696 | P5: 15.084 | Q5: 15.989 | R5: 18.776 | S5: 21.37 | T5: 22.125 | U5: 22.869 | V5: 25.035 | W5: 28.505 | X5: 32.221 | Y5: 34.829
A6: % of revenue | B6: =IFERROR(B5/B3,"") | C6: =IFERROR(C5/C3,"") | D6: =IFERROR(D5/D3,"") | E6: =IFERROR(E5/E3,"") | F6: =IFERROR(F5/F3,"") | G6: =IFERROR(G5/G3,"") | H6: =IFERROR(H5/H3,"") | I6: =IFERROR(I5/I3,"") | ... Y6: =IFERROR(Y5/Y3,"")
A7: R&D Expense | B7: 19.103 | C7: 19.797 | D7: 19.042 | E7: 48.701 | F7: 21.34 | G7: 22.603 | H7: 24.664 | I7: 28.61 | J7: 31.83 | K7: 39.52 | L7: 41.113 | M7: 43.68 | N7: 48.328 | O7: 49.019 | P7: 48.986 | Q7: 52.388 | R7: 54.14 | S7: 60.88 | T7: 61.354 | U7: 62.885 | V7: 65.41 | W7: 71.488 | X7: 68.715 | Y7: 68.961
A8: % of revenue | B8: =IFERROR(B7/B3,"") | C8: =IFERROR(C7/C3,"") | D8: =IFERROR(D7/D3,"") | E8: =IFERROR(E7/E3,"") | F8: =IFERROR(F7/F3,"") | G8: =IFERROR(G7/G3,"") | H8: =IFERROR(H7/H3,"") | I8: =IFERROR(I7/I3,"") | ... Y8: =IFERROR(Y7/Y3,"")
A9: SG&A Expense | B9: 38.705 | C9: 39.645 | D9: 42.927 | E9: 119.677 | F9: 48.193 | G9: 58.163 | H9: 67.482 | I9: 80.57 | J9: 88.602 | K9: 113.793 | L9: 112.166 | M9: 112.911 | N9: 115.608 | O9: 129.797 | P9: 125.851 | Q9: 128.379 | R9: 149.911 | S9: 140.946 | T9: 141.181 | U9: 145.015 | V9: 158.674 | W9: 154.318 | X9: 155.773 | Y9: 159.991
A10: % of revenue | B10: =IFERROR(B9/B3,"") | C10: =IFERROR(C9/C3,"") | D10: =IFERROR(D9/D3,"") | E10: =IFERROR(E9/E3,"") | F10: =IFERROR(F9/F3,"") | G10: =IFERROR(G9/G3,"") | H10: =IFERROR(H9/H3,"") | I10: =IFERROR(I9/I3,"") | ... Y10: =IFERROR(Y9/Y3,"")
A11: Gross Profit | B11: 25.726 | C11: 30.55 | D11: 37.515 | E11: 39.922 | F11: 43.505 | G11: 50.935 | H11: 59.605 | I11: 68.623 | J11: 77.559 | K11: 88.011 | L11: 98.417 | M11: 108.669 | N11: 112.939 | O11: 124.885 | P11: 134.584 | Q11: 147.79 | R11: 150.411 | S11: 161.214 | T11: 173.922 | U11: 188.562 | V11: 189.474 | W11: 207.455 | X11: 212.132 | Y11: 225.573
A12: gross margin | B12: =IFERROR(B11/B3,"") | C12: =IFERROR(C11/C3,"") | D12: =IFERROR(D11/D3,"") | E12: =IFERROR(E11/E3,"") | F12: =IFERROR(F11/F3,"") | G12: =IFERROR(G11/G3,"") | H12: =IFERROR(H11/H3,"") | I12: =IFERROR(I11/I3,"") | ... Y12: =IFERROR(Y11/Y3,"")
A13: Operating Income | B13: -32.082 | C13: -28.892 | D13: -24.454 | E13: -128.456 | F13: -26.028 | G13: -29.831 | H13: -32.541 | I13: -40.057 | J13: -42.873 | K13: -65.302 | L13: -54.862 | M13: -47.996 | N13: -50.58 | O13: -54.057 | P13: -40.253 | Q13: -32.976999 | R13: -53.64 | S13: -41.005 | T13: -28.732 | U13: -19.338 | V13: -34.61 | W13: -18.351 | X13: -12.356 | Y13: -3.379
A14: operating margin | B14: =IFERROR(B13/B3,"") | C14: =IFERROR(C13/C3,"") | D14: =IFERROR(D13/D3,"") | E14: =IFERROR(E13/E3,"") | F14: =IFERROR(F13/F3,"") | G14: =IFERROR(G13/G3,"") | H14: =IFERROR(H13/H3,"") | I14: =IFERROR(I13/I3,"") | ... Y14: =IFERROR(Y13/Y3,"")
A15: Net Income | B15: -34.157 | C15: -9.391 | D15: -28.608 | E15: -120.038 | F15: -27.937 | G15: -40.189 | H15: -41.227 | I15: -45.785 | J15: -26.099 | K15: -59.024 | L15: -48.455 | M15: -38.733 | N15: -52.469 | O15: -50.08 | P15: -285.158 | Q15: -36.868 | R15: -55.233 | S15: 12.949 | T15: 29.565 | U15: 5.804 | V15: -35.875 | W15: -9.208 | X15: -8.276 | Y15: -2.6
A16: net margin | B16: =IFERROR(B15/B3,"") | C16: =IFERROR(C15/C3,"") | D16: =IFERROR(D15/D3,"") | E16: =IFERROR(E15/E3,"") | F16: =IFERROR(F15/F3,"") | G16: =IFERROR(G15/G3,"") | H16: =IFERROR(H15/H3,"") | I16: =IFERROR(I15/I3,"") | ... Y16: =IFERROR(Y15/Y3,"")
A17: Diluted Shares (M) | B17: 132.492 | C17: 132.492 | D17: 132.492 | E17: 132.492 | F17: 132.492 | G17: 143.015 | H17: 144.546 | I17: 144.929 | J17: 146.643 | K17: 147.797 | L17: 148.883 | M17: 150.133 | N17: 151.692 | O17: 153.644 | P17: 155.123 | Q17: 156.601 | R17: 158.157 | S17: 166.346 | T17: 164.25 | U17: 170.094 | V17: 164.491 | W17: 165.953 | X17: 165.965 | Y17: 165.8
A18: REVENUE BY SEGMENT — PRODUCT (% YoY, % of revenue)
A19: Subscription and Software | W19: 212.684 | X19: 223.262 | Y19: 428.758
A20: % YoY | F20: =IFERROR(F19/B19-1,"") | G20: =IFERROR(G19/C19-1,"") | H20: =IFERROR(H19/D19-1,"") | I20: =IFERROR(I19/E19-1,"") | J20: =IFERROR(J19/F19-1,"") | K20: =IFERROR(K19/G19-1,"") | L20: =IFERROR(L19/H19-1,"") | M20: =IFERROR(M19/I19-1,"") | ... Y20: =IFERROR(Y19/U19-1,"")
A21: % of revenue | B21: =IFERROR(B19/B3,"") | C21: =IFERROR(C19/C3,"") | D21: =IFERROR(D19/D3,"") | E21: =IFERROR(E19/E3,"") | F21: =IFERROR(F19/F3,"") | G21: =IFERROR(G19/G3,"") | H21: =IFERROR(H19/H3,"") | I21: =IFERROR(I19/I3,"") | ... Y21: =IFERROR(Y19/Y3,"")
A22: Subscription and Circulation | H22: 47.215 | I22: 54.822 | J22: 59.719 | K22: 66.896 | L22: 72.72 | M22: 75.94 | N22: 79.587 | O22: 86.659 | P22: 91.716 | Q22: 97.745 | R22: 103.673 | S22: 111.546 | T22: 118.525 | U22: 125.139 | V22: 130.296 | W22: 140.654 | X22: 146.379 | Y22: 151.13
A23: % YoY | F23: =IFERROR(F22/B22-1,"") | G23: =IFERROR(G22/C22-1,"") | H23: =IFERROR(H22/D22-1,"") | I23: =IFERROR(I22/E22-1,"") | J23: =IFERROR(J22/F22-1,"") | K23: =IFERROR(K22/G22-1,"") | L23: =IFERROR(L22/H22-1,"") | M23: =IFERROR(M22/I22-1,"") | ... Y23: =IFERROR(Y22/U22-1,"")
A24: % of revenue | B24: =IFERROR(B22/B3,"") | C24: =IFERROR(C22/C3,"") | D24: =IFERROR(D22/D3,"") | E24: =IFERROR(E22/E3,"") | F24: =IFERROR(F22/F3,"") | G24: =IFERROR(G22/G3,"") | H24: =IFERROR(H22/H3,"") | I24: =IFERROR(I22/I3,"") | ... Y24: =IFERROR(Y22/Y3,"")
A25: Subscription, Software As A Service | H25: 12.559 | I25: 14.799 | J25: 17.204 | K25: 22.04 | L25: 25.715 | M25: 29.115 | N25: 31.604 | O25: 35.437 | P25: 39.277 | Q25: 44.281 | R25: 47.506 | S25: 51.635 | T25: 56.732 | U25: 60.423 | V25: 64.185 | W25: 72.03 | X25: 76.883 | Y25: 83.147
A26: % YoY | F26: =IFERROR(F25/B25-1,"") | G26: =IFERROR(G25/C25-1,"") | H26: =IFERROR(H25/D25-1,"") | I26: =IFERROR(I25/E25-1,"") | J26: =IFERROR(J25/F25-1,"") | K26: =IFERROR(K25/G25-1,"") | L26: =IFERROR(L25/H25-1,"") | M26: =IFERROR(M25/I25-1,"") | ... Y26: =IFERROR(Y25/U25-1,"")
A27: % of revenue | B27: =IFERROR(B25/B3,"") | C27: =IFERROR(C25/C3,"") | D27: =IFERROR(D25/D3,"") | E27: =IFERROR(E25/E3,"") | F27: =IFERROR(F25/F3,"") | G27: =IFERROR(G25/G3,"") | H27: =IFERROR(H25/H3,"") | I27: =IFERROR(I25/I3,"") | ... Y27: =IFERROR(Y25/Y3,"")
A28: License, Professional Services, and Other | W28: 23.276 | X28: 21.091 | Y28: 46.153
A29: % YoY | F29: =IFERROR(F28/B28-1,"") | G29: =IFERROR(G28/C28-1,"") | H29: =IFERROR(H28/D28-1,"") | I29: =IFERROR(I28/E28-1,"") | J29: =IFERROR(J28/F28-1,"") | K29: =IFERROR(K28/G28-1,"") | L29: =IFERROR(L28/H28-1,"") | M29: =IFERROR(M28/I28-1,"") | ... Y29: =IFERROR(Y28/U28-1,"")
A30: % of revenue | B30: =IFERROR(B28/B3,"") | C30: =IFERROR(C28/C3,"") | D30: =IFERROR(D28/D3,"") | E30: =IFERROR(E28/E3,"") | F30: =IFERROR(F28/F3,"") | G30: =IFERROR(G28/G3,"") | H30: =IFERROR(H28/H3,"") | I30: =IFERROR(I28/I3,"") | ... Y30: =IFERROR(Y28/Y3,"")
A31: License | H31: 5.314 | I31: 6.414 | J31: 8.777 | K31: 10.009 | L31: 11.86 | M31: 15.4 | N31: 13.355 | O31: 14.624 | P31: 16.037 | Q31: 19.094 | R31: 14.837 | S31: 15.802 | T31: 16.655 | U31: 21.072 | V31: 15.028 | W31: 18.143 | X31: 15.525 | Y31: 20.174
A32: % YoY | F32: =IFERROR(F31/B31-1,"") | G32: =IFERROR(G31/C31-1,"") | H32: =IFERROR(H31/D31-1,"") | I32: =IFERROR(I31/E31-1,"") | J32: =IFERROR(J31/F31-1,"") | K32: =IFERROR(K31/G31-1,"") | L32: =IFERROR(L31/H31-1,"") | M32: =IFERROR(M31/I31-1,"") | ... Y32: =IFERROR(Y31/U31-1,"")
A33: % of revenue | B33: =IFERROR(B31/B3,"") | C33: =IFERROR(C31/C3,"") | D33: =IFERROR(D31/D3,"") | E33: =IFERROR(E31/E3,"") | F33: =IFERROR(F31/F3,"") | G33: =IFERROR(G31/G3,"") | H33: =IFERROR(H31/H3,"") | I33: =IFERROR(I31/I3,"") | ... Y33: =IFERROR(Y31/Y3,"")
A34: Professional Services and Other | H34: 1.712 | I34: 1.761 | J34: 1.707 | K34: 2.096 | L34: 2.686 | M34: 2.452 | N34: 2.332 | O34: 2.861 | P34: 2.638 | Q34: 2.659 | R34: 3.171 | S34: 3.601 | T34: 4.135 | U34: 4.797 | V34: 5 | W34: 5.133 | X34: 5.566 | Y34: 5.951
A35: % YoY | F35: =IFERROR(F34/B34-1,"") | G35: =IFERROR(G34/C34-1,"") | H35: =IFERROR(H34/D34-1,"") | I35: =IFERROR(I34/E34-1,"") | J35: =IFERROR(J34/F34-1,"") | K35: =IFERROR(K34/G34-1,"") | L35: =IFERROR(L34/H34-1,"") | M35: =IFERROR(M34/I34-1,"") | ... Y35: =IFERROR(Y34/U34-1,"")
A36: % of revenue | B36: =IFERROR(B34/B3,"") | C36: =IFERROR(C34/C3,"") | D36: =IFERROR(D34/D3,"") | E36: =IFERROR(E34/E3,"") | F36: =IFERROR(F34/F3,"") | G36: =IFERROR(G34/G3,"") | H36: =IFERROR(H34/H3,"") | I36: =IFERROR(I34/I3,"") | ... Y36: =IFERROR(Y34/Y3,"")
A37: REVENUE BY SEGMENT — GEOGRAPHY (% YoY, % of revenue)
A38: UNITED STATES | H38: 56.706 | I38: 64.294 | J38: 72.274 | K38: 84.123 | L38: 94.942 | M38: 101.636 | N38: 102.962 | O38: 114.054 | P38: 122.415 | Q38: 133.59 | R38: 137.526 | S38: 149.357 | T38: 159.013 | U38: 172.762 | V38: 176.886 | W38: 194.584 | X38: 201.391 | Y38: 214.487
A39: % YoY | F39: =IFERROR(F38/B38-1,"") | G39: =IFERROR(G38/C38-1,"") | H39: =IFERROR(H38/D38-1,"") | I39: =IFERROR(I38/E38-1,"") | J39: =IFERROR(J38/F38-1,"") | K39: =IFERROR(K38/G38-1,"") | L39: =IFERROR(L38/H38-1,"") | M39: =IFERROR(M38/I38-1,"") | ... Y39: =IFERROR(Y38/U38-1,"")
A40: % of revenue | B40: =IFERROR(B38/B3,"") | C40: =IFERROR(C38/C3,"") | D40: =IFERROR(D38/D3,"") | E40: =IFERROR(E38/E3,"") | F40: =IFERROR(F38/F3,"") | G40: =IFERROR(G38/G3,"") | H40: =IFERROR(H38/H3,"") | I40: =IFERROR(I38/I3,"") | ... Y40: =IFERROR(Y38/Y3,"")
...

Sheet Consensus
A1: Full consensus check — model vs Street (FMP estimates, $M)
A2: Fiscal year | B2: 2027 | C2: 2028 | D2: 2029 | E2: 2030 | F2: 2031
A3: EVERY AVAILABLE FMP CONSENSUS FIELD (consensus / model / % diff)
A4: Revenue — consensus | B4: 1110.1642 | C4: 1283.0617 | D4: 1463.5367 | E4: 1674.7 | F4: 1902.1
A5: model | B5: =Model!G16 | C5: =Model!H16 | D5: =Model!I16 | E5: =Model!J16 | F5: =Model!K16
A6: vs consensus | B6: =IFERROR(B5/B4-1,"") | C6: =IFERROR(C5/C4-1,"") | D6: =IFERROR(D5/D4-1,"") | E6: =IFERROR(E5/E4-1,"") | F6: =IFERROR(F5/F4-1,"")
A8: EBITDA* — consensus | B8: 304.35442 | C8: 351.75471 | D8: 401.23241 | E8: 459.12337 | F8: 521.46567
A9: model | B9: =Model!G29+Model!G34 | C9: =Model!H29+Model!H34 | D9: =Model!I29+Model!I34 | E9: =Model!J29+Model!J34 | F9: =Model!K29+Model!K34
A10: vs consensus | B10: =IFERROR(B9/B8-1,"") | C10: =IFERROR(C9/C8-1,"") | D10: =IFERROR(D9/D8-1,"") | E10: =IFERROR(E9/E8-1,"") | F10: =IFERROR(F9/F8-1,"")
A12: EBIT* — consensus | B12: 286.5597 | C12: 331.18864 | D12: 377.77353 | E12: 432.27977 | F12: 490.9771
A13: model | B13: =Model!G29 | C13: =Model!H29 | D13: =Model!I29 | E13: =Model!J29 | F13: =Model!K29
A14: vs consensus | B14: =IFERROR(B13/B12-1,"") | C14: =IFERROR(C13/C12-1,"") | D14: =IFERROR(D13/D12-1,"") | E14: =IFERROR(E13/E12-1,"") | F14: =IFERROR(F13/F12-1,"")
A16: SG&A — consensus | B16: 963.99293 | C16: 1114.1256 | D16: 1270.8382 | E16: 1454.1983 | F16: 1651.6574
A17: model | B17: =Model!G24 | C17: =Model!H24 | D17: =Model!I24 | E17: =Model!J24 | F17: =Model!K24
A18: vs consensus | B18: =IFERROR(B17/B16-1,"") | C18: =IFERROR(C17/C16-1,"") | D18: =IFERROR(D17/D16-1,"") | E18: =IFERROR(E17/E16-1,"") | F18: =IFERROR(F17/F16-1,"")
A20: Net income (NOPAT) — consensus | B20: 148.10914 | C20: 170.49546 | D20: 232.62072 | E20: 198.131 | F20: 248.7
A21: model | B21: =Model!G33 | C21: =Model!H33 | D21: =Model!I33 | E21: =Model!J33 | F21: =Model!K33
A22: vs consensus | B22: =IFERROR(B21/B20-1,"") | C22: =IFERROR(C21/C20-1,"") | D22: =IFERROR(D21/D20-1,"") | E22: =IFERROR(E21/E20-1,"") | F22: =IFERROR(F21/F20-1,"")
A24: EPS — consensus | B24: 0.80397 | C24: 0.98086 | D24: 1.12661 | E24: 1.195 | F24: 1.5
A25: model | B25: =Model!G33/Financials!Y17 | C25: =Model!H33/Financials!Y17 | D25: =Model!I33/Financials!Y17 | E25: =Model!J33/Financials!Y17 | F25: =Model!K33/Financials!Y17
A26: vs consensus | B26: =IFERROR(B25/B24-1,"") | C26: =IFERROR(C25/C24-1,"") | D26: =IFERROR(D25/D24-1,"") | E26: =IFERROR(E25/E24-1,"") | F26: =IFERROR(F25/F24-1,"")
A28: Defaults anchored to consensus revenue + net income (≈0% diff). Other rows show where the model sits vs Street.
A29: *FMP's EBITDA/EBIT estimates look unreliable for AMZN (it reports NI > EBIT) — don't over-read those two.

Sheet Valuation
A1: GitLab Inc. — DCF Valuation
A2: Current price | B2: =Dashboard!$B$48
A3: WACC | B3: =WACC!B14
A4: Terminal growth (g) | B4: =Dashboard!$B$46
A5: Tax rate | B5: =Dashboard!$B$31
A6: Terminal method | B6: =Dashboard!$B$43
A7: Exit basis | B7: =Dashboard!$B$44
A8: Exit multiple | B8: =Dashboard!$B$45
A11: Forecast year | C11: 2027 | D11: 2028 | E11: 2029 | F11: 2030 | G11: 2031 | H11: 2032 | I11: 2033 | J11: 2034 | K11: 2035 | L11: 2036
A12: FCFF ($M) | C12: =Model!G41 | D12: =Model!H41 | E12: =Model!I41 | F12: =Model!J41 | G12: =Model!K41 | H12: =Model!L41 | I12: =Model!M41 | J12: =Model!N41 | ... L12: =Model!P41
A13: PV factor | C13: =1/(1+$B$3)^1 | D13: =1/(1+$B$3)^2 | E13: =1/(1+$B$3)^3 | F13: =1/(1+$B$3)^4 | G13: =1/(1+$B$3)^5 | H13: =1/(1+$B$3)^6 | I13: =1/(1+$B$3)^7 | J13: =1/(1+$B$3)^8 | K13: =1/(1+$B$3)^9 | L13: =1/(1+$B$3)^10
A14: PV of FCFF ($M) | C14: =C12*C13 | D14: =D12*D13 | E14: =E12*E13 | F14: =F12*F13 | G14: =G12*G13 | H14: =H12*H13 | I14: =I12*I13 | J14: =J12*J13 | ... L14: =L12*L13
A16: Sum PV of FCFF | B16: =SUM(C14:L14)
A18: TERMINAL VALUE (exit multiple = default; perpetuity = cross-check)
A19: Terminal-year FCFF | B19: =L12
A20: Terminal revenue | B20: =Model!P16
A21: Terminal EBIT | B21: =Model!P29
A22: Terminal EBITDA | B22: =Model!P29+Model!P34
A23: Terminal metric (per exit basis) | B23: =IF($B$7="EV/EBITDA",B22,IF($B$7="EV/Sales",B20,IF($B$7="EV/EBIT",B21,B19)))
A24: TV (exit) = metric x multiple | B24: =B23*$B$8
A25: PV of TV — exit multiple | B25: =B24/(1+$B$3)^10
A26: TV (perpetuity) = FCFF(1+g)/(WACC-g) | B26: =B19*(1+$B$4)/($B$3-$B$4)
A27: PV of TV — perpetuity | B27: =B26/(1+$B$3)^10
A28: PV of TV — SELECTED | B28: =IF($B$6="Perpetuity",B27,B25)
A30: EQUITY BRIDGE -> VALUE / SHARE
A31: Operating value (enterprise value) | B31: =B16+B28
A32: + Cash & ST investments | B32: =Financials!Y48
A33: - Long-term debt | B33: =-Financials!Y53
A34: Equity value | B34: =B31+B32+B33
A35: Diluted shares (M) | B35: =Financials!Y17
A36: VALUE / SHARE | B36: =B34/B35*1.0
A38: CROSS-CHECKS & RETURN
A39: Terminal weight (% of EV) | B39: =B28/B31
A40: Implied perpetuity g (from exit multiple) | B40: =(B24*$B$3-B19)/(B24+B19)
A41: Implied exit EV/EBITDA (from perpetuity) | B41: =B26/B22
A42: Upside / (downside) to fair value | B42: =B36/$B$2-1
A44: Owner cashflow / share | B44: =-$B$2 | C44: =C12/B35 | D44: =D12/B35 | E44: =E12/B35 | F44: =F12/B35 | G44: =G12/B35 | H44: =H12/B35 | I44: =I12/B35 | J44: =J12/B35 | K44: =K12/B35 | L44: =L12/B35+B36
A45: IRR (buy at price, hold 10y) | B45: =IRR(B44:L44)

Sheet Monte Carlo
A1: Monte Carlo simulation (live) | H1: SIMULATION ENGINE — leave as-is | K1: cagr | L1: term margin | M1: wacc | N1: exit | O1: value/share
A2: 1,000 trials, recomputed in-sheet on every edit. Edit the yellow driver distributions to re-roll. Engine grid is to the right (cols H+). | H2: R0 (base revenue) | I2: =Model!F16 | K2: =MAX(-0.05,NORMINV(RAND(),$C$6,$D$6)) | L2: =MAX(0.02,NORMINV(RAND(),$C$7,$D$7)) | M2: =MIN(0.16,MAX(0.05,NORMINV(RAND(),$C$8,$D$8))) | N2: =MIN(24,MAX(5,NORMINV(RAND(),$C$9,$D$9))) | O2: =$I$8*(SUMPRODUCT(($I$2*(1+K2)^{1;2;3;4;5;6;7;8;9;10})*(($I$3+(L2-$I$3)*{1;2;3;4;5;6;7;8;9;10}/10)*(1-$I$7)+$I$4-$I$4*($I$5+(1.05-$I$5)*{1;2;3;4;5;6;7;8;9;10}/10)-(K2/(1+K2))*$I$6)/(1+M2)^{1;2;3;4;5;6;7;8;9;10})+$I$2*(1+K2)^10*(L2+$I$4)*N2/(1+M2)^10+$I$9-$I$10)/$I$11
H3: m0 (base op margin) | I3: =Model!F30 | K3: =MAX(-0.05,NORMINV(RAND(),$C$6,$D$6)) | L3: =MAX(0.02,NORMINV(RAND(),$C$7,$D$7)) | M3: =MIN(0.16,MAX(0.05,NORMINV(RAND(),$C$8,$D$8))) | N3: =MIN(24,MAX(5,NORMINV(RAND(),$C$9,$D$9))) | O3: =$I$8*(SUMPRODUCT(($I$2*(1+K3)^{1;2;3;4;5;6;7;8;9;10})*(($I$3+(L3-$I$3)*{1;2;3;4;5;6;7;8;9;10}/10)*(1-$I$7)+$I$4-$I$4*($I$5+(1.05-$I$5)*{1;2;3;4;5;6;7;8;9;10}/10)-(K3/(1+K3))*$I$6)/(1+M3)^{1;2;3;4;5;6;7;8;9;10})+$I$2*(1+K3)^10*(L3+$I$4)*N3/(1+M3)^10+$I$9-$I$10)/$I$11
A4: DRIVER DISTRIBUTIONS (yellow = edit; Opus-set defaults) | H4: da (D&A / revenue) | I4: 0.0098280613 | K4: =MAX(-0.05,NORMINV(RAND(),$C$6,$D$6)) | L4: =MAX(0.02,NORMINV(RAND(),$C$7,$D$7)) | M4: =MIN(0.16,MAX(0.05,NORMINV(RAND(),$C$8,$D$8))) | N4: =MIN(24,MAX(5,NORMINV(RAND(),$C$9,$D$9))) | O4: =$I$8*(SUMPRODUCT(($I$2*(1+K4)^{1;2;3;4;5;6;7;8;9;10})*(($I$3+(L4-$I$3)*{1;2;3;4;5;6;7;8;9;10}/10)*(1-$I$7)+$I$4-$I$4*($I$5+(1.05-$I$5)*{1;2;3;4;5;6;7;8;9;10}/10)-(K4/(1+K4))*$I$6)/(1+M4)^{1;2;3;4;5;6;7;8;9;10})+$I$2*(1+K4)^10*(L4+$I$4)*N4/(1+M4)^10+$I$9-$I$10)/$I$11
A5: Driver | B5: Dist | C5: Mean | D5: Std dev | H5: cda0 (2026 capex/D&A) | I5: 1.0915553 | K5: =MAX(-0.05,NORMINV(RAND(),$C$6,$D$6)) | L5: =MAX(0.02,NORMINV(RAND(),$C$7,$D$7)) | M5: =MIN(0.16,MAX(0.05,NORMINV(RAND(),$C$8,$D$8))) | N5: =MIN(24,MAX(5,NORMINV(RAND(),$C$9,$D$9))) | O5: =$I$8*(SUMPRODUCT(($I$2*(1+K5)^{1;2;3;4;5;6;7;8;9;10})*(($I$3+(L5-$I$3)*{1;2;3;4;5;6;7;8;9;10}/10)*(1-$I$7)+$I$4-$I$4*($I$5+(1.05-$I$5)*{1;2;3;4;5;6;7;8;9;10}/10)-(K5/(1+K5))*$I$6)/(1+M5)^{1;2;3;4;5;6;7;8;9;10})+$I$2*(1+K5)^10*(L5+$I$4)*N5/(1+M5)^10+$I$9-$I$10)/$I$11
A6: Revenue 10y CAGR | B6: Normal | C6: =(Model!P16/Model!F16)^(1/10)-1 | D6: 0.03 | H6: nwc (% incr revenue) | I6: 0.005 | K6: =MAX(-0.05,NORMINV(RAND(),$C$6,$D$6)) | L6: =MAX(0.02,NORMINV(RAND(),$C$7,$D$7)) | M6: =MIN(0.16,MAX(0.05,NORMINV(RAND(),$C$8,$D$8))) | N6: =MIN(24,MAX(5,NORMINV(RAND(),$C$9,$D$9))) | O6: =$I$8*(SUMPRODUCT(($I$2*(1+K6)^{1;2;3;4;5;6;7;8;9;10})*(($I$3+(L6-$I$3)*{1;2;3;4;5;6;7;8;9;10}/10)*(1-$I$7)+$I$4-$I$4*($I$5+(1.05-$I$5)*{1;2;3;4;5;6;7;8;9;10}/10)-(K6/(1+K6))*$I$6)/(1+M6)^{1;2;3;4;5;6;7;8;9;10})+$I$2*(1+K6)^10*(L6+$I$4)*N6/(1+M6)^10+$I$9-$I$10)/$I$11
A7: Terminal operating margin | B7: Normal | C7: =Dashboard!$B$30 | D7: 0.03 | H7: tax | I7: =Valuation!$B$5 | K7: =MAX(-0.05,NORMINV(RAND(),$C$6,$D$6)) | L7: =MAX(0.02,NORMINV(RAND(),$C$7,$D$7)) | M7: =MIN(0.16,MAX(0.05,NORMINV(RAND(),$C$8,$D$8))) | N7: =MIN(24,MAX(5,NORMINV(RAND(),$C$9,$D$9))) | O7: =$I$8*(SUMPRODUCT(($I$2*(1+K7)^{1;2;3;4;5;6;7;8;9;10})*(($I$3+(L7-$I$3)*{1;2;3;4;5;6;7;8;9;10}/10)*(1-$I$7)+$I$4-$I$4*($I$5+(1.05-$I$5)*{1;2;3;4;5;6;7;8;9;10}/10)-(K7/(1+K7))*$I$6)/(1+M7)^{1;2;3;4;5;6;7;8;9;10})+$I$2*(1+K7)^10*(L7+$I$4)*N7/(1+M7)^10+$I$9-$I$10)/$I$11
A8: WACC | B8: Normal | C8: =WACC!B14 | D8: 0.005 | H8: k (calibration) | I8: 1.2970969 | K8: =MAX(-0.05,NORMINV(RAND(),$C$6,$D$6)) | L8: =MAX(0.02,NORMINV(RAND(),$C$7,$D$7)) | M8: =MIN(0.16,MAX(0.05,NORMINV(RAND(),$C$8,$D$8))) | N8: =MIN(24,MAX(5,NORMINV(RAND(),$C$9,$D$9))) | O8: =$I$8*(SUMPRODUCT(($I$2*(1+K8)^{1;2;3;4;5;6;7;8;9;10})*(($I$3+(L8-$I$3)*{1;2;3;4;5;6;7;8;9;10}/10)*(1-$I$7)+$I$4-$I$4*($I$5+(1.05-$I$5)*{1;2;3;4;5;6;7;8;9;10}/10)-(K8/(1+K8))*$I$6)/(1+M8)^{1;2;3;4;5;6;7;8;9;10})+$I$2*(1+K8)^10*(L8+$I$4)*N8/(1+M8)^10+$I$9-$I$10)/$I$11
A9: Exit EV/EBITDA multiple | B9: Normal | C9: =Dashboard!$B$45 | D9: 1.5 | H9: cash | I9: =Financials!Y48 | K9: =MAX(-0.05,NORMINV(RAND(),$C$6,$D$6)) | L9: =MAX(0.02,NORMINV(RAND(),$C$7,$D$7)) | M9: =MIN(0.16,MAX(0.05,NORMINV(RAND(),$C$8,$D$8))) | N9: =MIN(24,MAX(5,NORMINV(RAND(),$C$9,$D$9))) | O9: =$I$8*(SUMPRODUCT(($I$2*(1+K9)^{1;2;3;4;5;6;7;8;9;10})*(($I$3+(L9-$I$3)*{1;2;3;4;5;6;7;8;9;10}/10)*(1-$I$7)+$I$4-$I$4*($I$5+(1.05-$I$5)*{1;2;3;4;5;6;7;8;9;10}/10)-(K9/(1+K9))*$I$6)/(1+M9)^{1;2;3;4;5;6;7;8;9;10})+$I$2*(1+K9)^10*(L9+$I$4)*N9/(1+M9)^10+$I$9-$I$10)/$I$11
H10: debt | I10: =Financials!Y53 | K10: =MAX(-0.05,NORMINV(RAND(),$C$6,$D$6)) | L10: =MAX(0.02,NORMINV(RAND(),$C$7,$D$7)) | M10: =MIN(0.16,MAX(0.05,NORMINV(RAND(),$C$8,$D$8))) | N10: =MIN(24,MAX(5,NORMINV(RAND(),$C$9,$D$9))) | O10: =$I$8*(SUMPRODUCT(($I$2*(1+K10)^{1;2;3;4;5;6;7;8;9;10})*(($I$3+(L10-$I$3)*{1;2;3;4;5;6;7;8;9;10}/10)*(1-$I$7)+$I$4-$I$4*($I$5+(1.05-$I$5)*{1;2;3;4;5;6;7;8;9;10}/10)-(K10/(1+K10))*$I$6)/(1+M10)^{1;2;3;4;5;6;7;8;9;10})+$I$2*(1+K10)^10*(L10+$I$4)*N10/(1+M10)^10+$I$9-$I$10)/$I$11
A11: SIMULATION OUTPUT — value / share (live) | H11: shares | I11: =Financials!Y17 | K11: =MAX(-0.05,NORMINV(RAND(),$C$6,$D$6)) | L11: =MAX(0.02,NORMINV(RAND(),$C$7,$D$7)) | M11: =MIN(0.16,MAX(0.05,NORMINV(RAND(),$C$8,$D$8))) | N11: =MIN(24,MAX(5,NORMINV(RAND(),$C$9,$D$9))) | O11: =$I$8*(SUMPRODUCT(($I$2*(1+K11)^{1;2;3;4;5;6;7;8;9;10})*(($I$3+(L11-$I$3)*{1;2;3;4;5;6;7;8;9;10}/10)*(1-$I$7)+$I$4-$I$4*($I$5+(1.05-$I$5)*{1;2;3;4;5;6;7;8;9;10}/10)-(K11/(1+K11))*$I$6)/(1+M11)^{1;2;3;4;5;6;7;8;9;10})+$I$2*(1+K11)^10*(L11+$I$4)*N11/(1+M11)^10+$I$9-$I$10)/$I$11
A12: Mean | B12: =AVERAGE($O$2:$O$1001) | K12: =MAX(-0.05,NORMINV(RAND(),$C$6,$D$6)) | L12: =MAX(0.02,NORMINV(RAND(),$C$7,$D$7)) | M12: =MIN(0.16,MAX(0.05,NORMINV(RAND(),$C$8,$D$8))) | N12: =MIN(24,MAX(5,NORMINV(RAND(),$C$9,$D$9))) | O12: =$I$8*(SUMPRODUCT(($I$2*(1+K12)^{1;2;3;4;5;6;7;8;9;10})*(($I$3+(L12-$I$3)*{1;2;3;4;5;6;7;8;9;10}/10)*(1-$I$7)+$I$4-$I$4*($I$5+(1.05-$I$5)*{1;2;3;4;5;6;7;8;9;10}/10)-(K12/(1+K12))*$I$6)/(1+M12)^{1;2;3;4;5;6;7;8;9;10})+$I$2*(1+K12)^10*(L12+$I$4)*N12/(1+M12)^10+$I$9-$I$10)/$I$11
A13: Median (P50) | B13: =MEDIAN($O$2:$O$1001) | K13: =MAX(-0.05,NORMINV(RAND(),$C$6,$D$6)) | L13: =MAX(0.02,NORMINV(RAND(),$C$7,$D$7)) | M13: =MIN(0.16,MAX(0.05,NORMINV(RAND(),$C$8,$D$8))) | N13: =MIN(24,MAX(5,NORMINV(RAND(),$C$9,$D$9))) | O13: =$I$8*(SUMPRODUCT(($I$2*(1+K13)^{1;2;3;4;5;6;7;8;9;10})*(($I$3+(L13-$I$3)*{1;2;3;4;5;6;7;8;9;10}/10)*(1-$I$7)+$I$4-$I$4*($I$5+(1.05-$I$5)*{1;2;3;4;5;6;7;8;9;10}/10)-(K13/(1+K13))*$I$6)/(1+M13)^{1;2;3;4;5;6;7;8;9;10})+$I$2*(1+K13)^10*(L13+$I$4)*N13/(1+M13)^10+$I$9-$I$10)/$I$11
A14: Std dev | B14: =STDEV($O$2:$O$1001) | K14: =MAX(-0.05,NORMINV(RAND(),$C$6,$D$6)) | L14: =MAX(0.02,NORMINV(RAND(),$C$7,$D$7)) | M14: =MIN(0.16,MAX(0.05,NORMINV(RAND(),$C$8,$D$8))) | N14: =MIN(24,MAX(5,NORMINV(RAND(),$C$9,$D$9))) | O14: =$I$8*(SUMPRODUCT(($I$2*(1+K14)^{1;2;3;4;5;6;7;8;9;10})*(($I$3+(L14-$I$3)*{1;2;3;4;5;6;7;8;9;10}/10)*(1-$I$7)+$I$4-$I$4*($I$5+(1.05-$I$5)*{1;2;3;4;5;6;7;8;9;10}/10)-(K14/(1+K14))*$I$6)/(1+M14)^{1;2;3;4;5;6;7;8;9;10})+$I$2*(1+K14)^10*(L14+$I$4)*N14/(1+M14)^10+$I$9-$I$10)/$I$11
A15: Min | B15: =MIN($O$2:$O$1001) | K15: =MAX(-0.05,NORMINV(RAND(),$C$6,$D$6)) | L15: =MAX(0.02,NORMINV(RAND(),$C$7,$D$7)) | M15: =MIN(0.16,MAX(0.05,NORMINV(RAND(),$C$8,$D$8))) | N15: =MIN(24,MAX(5,NORMINV(RAND(),$C$9,$D$9))) | O15: =$I$8*(SUMPRODUCT(($I$2*(1+K15)^{1;2;3;4;5;6;7;8;9;10})*(($I$3+(L15-$I$3)*{1;2;3;4;5;6;7;8;9;10}/10)*(1-$I$7)+$I$4-$I$4*($I$5+(1.05-$I$5)*{1;2;3;4;5;6;7;8;9;10}/10)-(K15/(1+K15))*$I$6)/(1+M15)^{1;2;3;4;5;6;7;8;9;10})+$I$2*(1+K15)^10*(L15+$I$4)*N15/(1+M15)^10+$I$9-$I$10)/$I$11
A16: Max | B16: =MAX($O$2:$O$1001) | K16: =MAX(-0.05,NORMINV(RAND(),$C$6,$D$6)) | L16: =MAX(0.02,NORMINV(RAND(),$C$7,$D$7)) | M16: =MIN(0.16,MAX(0.05,NORMINV(RAND(),$C$8,$D$8))) | N16: =MIN(24,MAX(5,NORMINV(RAND(),$C$9,$D$9))) | O16: =$I$8*(SUMPRODUCT(($I$2*(1+K16)^{1;2;3;4;5;6;7;8;9;10})*(($I$3+(L16-$I$3)*{1;2;3;4;5;6;7;8;9;10}/10)*(1-$I$7)+$I$4-$I$4*($I$5+(1.05-$I$5)*{1;2;3;4;5;6;7;8;9;10}/10)-(K16/(1+K16))*$I$6)/(1+M16)^{1;2;3;4;5;6;7;8;9;10})+$I$2*(1+K16)^10*(L16+$I$4)*N16/(1+M16)^10+$I$9-$I$10)/$I$11
A17: Current price | B17: =Valuation!$B$2 | K17: =MAX(-0.05,NORMINV(RAND(),$C$6,$D$6)) | L17: =MAX(0.02,NORMINV(RAND(),$C$7,$D$7)) | M17: =MIN(0.16,MAX(0.05,NORMINV(RAND(),$C$8,$D$8))) | N17: =MIN(24,MAX(5,NORMINV(RAND(),$C$9,$D$9))) | O17: =$I$8*(SUMPRODUCT(($I$2*(1+K17)^{1;2;3;4;5;6;7;8;9;10})*(($I$3+(L17-$I$3)*{1;2;3;4;5;6;7;8;9;10}/10)*(1-$I$7)+$I$4-$I$4*($I$5+(1.05-$I$5)*{1;2;3;4;5;6;7;8;9;10}/10)-(K17/(1+K17))*$I$6)/(1+M17)^{1;2;3;4;5;6;7;8;9;10})+$I$2*(1+K17)^10*(L17+$I$4)*N17/(1+M17)^10+$I$9-$I$10)/$I$11
A18: Base case (full model) | B18: =Valuation!B36 | K18: =MAX(-0.05,NORMINV(RAND(),$C$6,$D$6)) | L18: =MAX(0.02,NORMINV(RAND(),$C$7,$D$7)) | M18: =MIN(0.16,MAX(0.05,NORMINV(RAND(),$C$8,$D$8))) | N18: =MIN(24,MAX(5,NORMINV(RAND(),$C$9,$D$9))) | O18: =$I$8*(SUMPRODUCT(($I$2*(1+K18)^{1;2;3;4;5;6;7;8;9;10})*(($I$3+(L18-$I$3)*{1;2;3;4;5;6;7;8;9;10}/10)*(1-$I$7)+$I$4-$I$4*($I$5+(1.05-$I$5)*{1;2;3;4;5;6;7;8;9;10}/10)-(K18/(1+K18))*$I$6)/(1+M18)^{1;2;3;4;5;6;7;8;9;10})+$I$2*(1+K18)^10*(L18+$I$4)*N18/(1+M18)^10+$I$9-$I$10)/$I$11
K19: =MAX(-0.05,NORMINV(RAND(),$C$6,$D$6)) | L19: =MAX(0.02,NORMINV(RAND(),$C$7,$D$7)) | M19: =MIN(0.16,MAX(0.05,NORMINV(RAND(),$C$8,$D$8))) | N19: =MIN(24,MAX(5,NORMINV(RAND(),$C$9,$D$9))) | O19: =$I$8*(SUMPRODUCT(($I$2*(1+K19)^{1;2;3;4;5;6;7;8;9;10})*(($I$3+(L19-$I$3)*{1;2;3;4;5;6;7;8;9;10}/10)*(1-$I$7)+$I$4-$I$4*($I$5+(1.05-$I$5)*{1;2;3;4;5;6;7;8;9;10}/10)-(K19/(1+K19))*$I$6)/(1+M19)^{1;2;3;4;5;6;7;8;9;10})+$I$2*(1+K19)^10*(L19+$I$4)*N19/(1+M19)^10+$I$9-$I$10)/$I$11
A20: P(undervalued at current price) | B20: =COUNTIF($O$2:$O$1001,">"&Valuation!$B$2)/1000 | K20: =MAX(-0.05,NORMINV(RAND(),$C$6,$D$6)) | L20: =MAX(0.02,NORMINV(RAND(),$C$7,$D$7)) | M20: =MIN(0.16,MAX(0.05,NORMINV(RAND(),$C$8,$D$8))) | N20: =MIN(24,MAX(5,NORMINV(RAND(),$C$9,$D$9))) | O20: =$I$8*(SUMPRODUCT(($I$2*(1+K20)^{1;2;3;4;5;6;7;8;9;10})*(($I$3+(L20-$I$3)*{1;2;3;4;5;6;7;8;9;10}/10)*(1-$I$7)+$I$4-$I$4*($I$5+(1.05-$I$5)*{1;2;3;4;5;6;7;8;9;10}/10)-(K20/(1+K20))*$I$6)/(1+M20)^{1;2;3;4;5;6;7;8;9;10})+$I$2*(1+K20)^10*(L20+$I$4)*N20/(1+M20)^10+$I$9-$I$10)/$I$11
A21: P(>20% upside) | B21: =COUNTIF($O$2:$O$1001,">"&Valuation!$B$2*1.2)/1000 | K21: =MAX(-0.05,NORMINV(RAND(),$C$6,$D$6)) | L21: =MAX(0.02,NORMINV(RAND(),$C$7,$D$7)) | M21: =MIN(0.16,MAX(0.05,NORMINV(RAND(),$C$8,$D$8))) | N21: =MIN(24,MAX(5,NORMINV(RAND(),$C$9,$D$9))) | O21: =$I$8*(SUMPRODUCT(($I$2*(1+K21)^{1;2;3;4;5;6;7;8;9;10})*(($I$3+(L21-$I$3)*{1;2;3;4;5;6;7;8;9;10}/10)*(1-$I$7)+$I$4-$I$4*($I$5+(1.05-$I$5)*{1;2;3;4;5;6;7;8;9;10}/10)-(K21/(1+K21))*$I$6)/(1+M21)^{1;2;3;4;5;6;7;8;9;10})+$I$2*(1+K21)^10*(L21+$I$4)*N21/(1+M21)^10+$I$9-$I$10)/$I$11
K22: =MAX(-0.05,NORMINV(RAND(),$C$6,$D$6)) | L22: =MAX(0.02,NORMINV(RAND(),$C$7,$D$7)) | M22: =MIN(0.16,MAX(0.05,NORMINV(RAND(),$C$8,$D$8))) | N22: =MIN(24,MAX(5,NORMINV(RAND(),$C$9,$D$9))) | O22: =$I$8*(SUMPRODUCT(($I$2*(1+K22)^{1;2;3;4;5;6;7;8;9;10})*(($I$3+(L22-$I$3)*{1;2;3;4;5;6;7;8;9;10}/10)*(1-$I$7)+$I$4-$I$4*($I$5+(1.05-$I$5)*{1;2;3;4;5;6;7;8;9;10}/10)-(K22/(1+K22))*$I$6)/(1+M22)^{1;2;3;4;5;6;7;8;9;10})+$I$2*(1+K22)^10*(L22+$I$4)*N22/(1+M22)^10+$I$9-$I$10)/$I$11
A23: PERCENTILES (live) | K23: =MAX(-0.05,NORMINV(RAND(),$C$6,$D$6)) | L23: =MAX(0.02,NORMINV(RAND(),$C$7,$D$7)) | M23: =MIN(0.16,MAX(0.05,NORMINV(RAND(),$C$8,$D$8))) | N23: =MIN(24,MAX(5,NORMINV(RAND(),$C$9,$D$9))) | O23: =$I$8*(SUMPRODUCT(($I$2*(1+K23)^{1;2;3;4;5;6;7;8;9;10})*(($I$3+(L23-$I$3)*{1;2;3;4;5;6;7;8;9;10}/10)*(1-$I$7)+$I$4-$I$4*($I$5+(1.05-$I$5)*{1;2;3;4;5;6;7;8;9;10}/10)-(K23/(1+K23))*$I$6)/(1+M23)^{1;2;3;4;5;6;7;8;9;10})+$I$2*(1+K23)^10*(L23+$I$4)*N23/(1+M23)^10+$I$9-$I$10)/$I$11
A24: P5 | B24: =PERCENTILE($O$2:$O$1001,0.05) | K24: =MAX(-0.05,NORMINV(RAND(),$C$6,$D$6)) | L24: =MAX(0.02,NORMINV(RAND(),$C$7,$D$7)) | M24: =MIN(0.16,MAX(0.05,NORMINV(RAND(),$C$8,$D$8))) | N24: =MIN(24,MAX(5,NORMINV(RAND(),$C$9,$D$9))) | O24: =$I$8*(SUMPRODUCT(($I$2*(1+K24)^{1;2;3;4;5;6;7;8;9;10})*(($I$3+(L24-$I$3)*{1;2;3;4;5;6;7;8;9;10}/10)*(1-$I$7)+$I$4-$I$4*($I$5+(1.05-$I$5)*{1;2;3;4;5;6;7;8;9;10}/10)-(K24/(1+K24))*$I$6)/(1+M24)^{1;2;3;4;5;6;7;8;9;10})+$I$2*(1+K24)^10*(L24+$I$4)*N24/(1+M24)^10+$I$9-$I$10)/$I$11
A25: P10 | B25: =PERCENTILE($O$2:$O$1001,0.1) | K25: =MAX(-0.05,NORMINV(RAND(),$C$6,$D$6)) | L25: =MAX(0.02,NORMINV(RAND(),$C$7,$D$7)) | M25: =MIN(0.16,MAX(0.05,NORMINV(RAND(),$C$8,$D$8))) | N25: =MIN(24,MAX(5,NORMINV(RAND(),$C$9,$D$9))) | O25: =$I$8*(SUMPRODUCT(($I$2*(1+K25)^{1;2;3;4;5;6;7;8;9;10})*(($I$3+(L25-$I$3)*{1;2;3;4;5;6;7;8;9;10}/10)*(1-$I$7)+$I$4-$I$4*($I$5+(1.05-$I$5)*{1;2;3;4;5;6;7;8;9;10}/10)-(K25/(1+K25))*$I$6)/(1+M25)^{1;2;3;4;5;6;7;8;9;10})+$I$2*(1+K25)^10*(L25+$I$4)*N25/(1+M25)^10+$I$9-$I$10)/$I$11
A26: P25 | B26: =PERCENTILE($O$2:$O$1001,0.25) | K26: =MAX(-0.05,NORMINV(RAND(),$C$6,$D$6)) | L26: =MAX(0.02,NORMINV(RAND(),$C$7,$D$7)) | M26: =MIN(0.16,MAX(0.05,NORMINV(RAND(),$C$8,$D$8))) | N26: =MIN(24,MAX(5,NORMINV(RAND(),$C$9,$D$9))) | O26: =$I$8*(SUMPRODUCT(($I$2*(1+K26)^{1;2;3;4;5;6;7;8;9;10})*(($I$3+(L26-$I$3)*{1;2;3;4;5;6;7;8;9;10}/10)*(1-$I$7)+$I$4-$I$4*($I$5+(1.05-$I$5)*{1;2;3;4;5;6;7;8;9;10}/10)-(K26/(1+K26))*$I$6)/(1+M26)^{1;2;3;4;5;6;7;8;9;10})+$I$2*(1+K26)^10*(L26+$I$4)*N26/(1+M26)^10+$I$9-$I$10)/$I$11
A27: P50 | B27: =PERCENTILE($O$2:$O$1001,0.5) | K27: =MAX(-0.05,NORMINV(RAND(),$C$6,$D$6)) | L27: =MAX(0.02,NORMINV(RAND(),$C$7,$D$7)) | M27: =MIN(0.16,MAX(0.05,NORMINV(RAND(),$C$8,$D$8))) | N27: =MIN(24,MAX(5,NORMINV(RAND(),$C$9,$D$9))) | O27: =$I$8*(SUMPRODUCT(($I$2*(1+K27)^{1;2;3;4;5;6;7;8;9;10})*(($I$3+(L27-$I$3)*{1;2;3;4;5;6;7;8;9;10}/10)*(1-$I$7)+$I$4-$I$4*($I$5+(1.05-$I$5)*{1;2;3;4;5;6;7;8;9;10}/10)-(K27/(1+K27))*$I$6)/(1+M27)^{1;2;3;4;5;6;7;8;9;10})+$I$2*(1+K27)^10*(L27+$I$4)*N27/(1+M27)^10+$I$9-$I$10)/$I$11
A28: P75 | B28: =PERCENTILE($O$2:$O$1001,0.75) | K28: =MAX(-0.05,NORMINV(RAND(),$C$6,$D$6)) | L28: =MAX(0.02,NORMINV(RAND(),$C$7,$D$7)) | M28: =MIN(0.16,MAX(0.05,NORMINV(RAND(),$C$8,$D$8))) | N28: =MIN(24,MAX(5,NORMINV(RAND(),$C$9,$D$9))) | O28: =$I$8*(SUMPRODUCT(($I$2*(1+K28)^{1;2;3;4;5;6;7;8;9;10})*(($I$3+(L28-$I$3)*{1;2;3;4;5;6;7;8;9;10}/10)*(1-$I$7)+$I$4-$I$4*($I$5+(1.05-$I$5)*{1;2;3;4;5;6;7;8;9;10}/10)-(K28/(1+K28))*$I$6)/(1+M28)^{1;2;3;4;5;6;7;8;9;10})+$I$2*(1+K28)^10*(L28+$I$4)*N28/(1+M28)^10+$I$9-$I$10)/$I$11
A29: P90 | B29: =PERCENTILE($O$2:$O$1001,0.9) | K29: =MAX(-0.05,NORMINV(RAND(),$C$6,$D$6)) | L29: =MAX(0.02,NORMINV(RAND(),$C$7,$D$7)) | M29: =MIN(0.16,MAX(0.05,NORMINV(RAND(),$C$8,$D$8))) | N29: =MIN(24,MAX(5,NORMINV(RAND(),$C$9,$D$9))) | O29: =$I$8*(SUMPRODUCT(($I$2*(1+K29)^{1;2;3;4;5;6;7;8;9;10})*(($I$3+(L29-$I$3)*{1;2;3;4;5;6;7;8;9;10}/10)*(1-$I$7)+$I$4-$I$4*($I$5+(1.05-$I$5)*{1;2;3;4;5;6;7;8;9;10}/10)-(K29/(1+K29))*$I$6)/(1+M29)^{1;2;3;4;5;6;7;8;9;10})+$I$2*(1+K29)^10*(L29+$I$4)*N29/(1+M29)^10+$I$9-$I$10)/$I$11
A30: P95 | B30: =PERCENTILE($O$2:$O$1001,0.95) | K30: =MAX(-0.05,NORMINV(RAND(),$C$6,$D$6)) | L30: =MAX(0.02,NORMINV(RAND(),$C$7,$D$7)) | M30: =MIN(0.16,MAX(0.05,NORMINV(RAND(),$C$8,$D$8))) | N30: =MIN(24,MAX(5,NORMINV(RAND(),$C$9,$D$9))) | O30: =$I$8*(SUMPRODUCT(($I$2*(1+K30)^{1;2;3;4;5;6;7;8;9;10})*(($I$3+(L30-$I$3)*{1;2;3;4;5;6;7;8;9;10}/10)*(1-$I$7)+$I$4-$I$4*($I$5+(1.05-$I$5)*{1;2;3;4;5;6;7;8;9;10}/10)-(K30/(1+K30))*$I$6)/(1+M30)^{1;2;3;4;5;6;7;8;9;10})+$I$2*(1+K30)^10*(L30+$I$4)*N30/(1+M30)^10+$I$9-$I$10)/$I$11
K31: =MAX(-0.05,NORMINV(RAND(),$C$6,$D$6)) | L31: =MAX(0.02,NORMINV(RAND(),$C$7,$D$7)) | M31: =MIN(0.16,MAX(0.05,NORMINV(RAND(),$C$8,$D$8))) | N31: =MIN(24,MAX(5,NORMINV(RAND(),$C$9,$D$9))) | O31: =$I$8*(SUMPRODUCT(($I$2*(1+K31)^{1;2;3;4;5;6;7;8;9;10})*(($I$3+(L31-$I$3)*{1;2;3;4;5;6;7;8;9;10}/10)*(1-$I$7)+$I$4-$I$4*($I$5+(1.05-$I$5)*{1;2;3;4;5;6;7;8;9;10}/10)-(K31/(1+K31))*$I$6)/(1+M31)^{1;2;3;4;5;6;7;8;9;10})+$I$2*(1+K31)^10*(L31+$I$4)*N31/(1+M31)^10+$I$9-$I$10)/$I$11
A32: VALUE DISTRIBUTION (live histogram) | K32: =MAX(-0.05,NORMINV(RAND(),$C$6,$D$6)) | L32: =MAX(0.02,NORMINV(RAND(),$C$7,$D$7)) | M32: =MIN(0.16,MAX(0.05,NORMINV(RAND(),$C$8,$D$8))) | N32: =MIN(24,MAX(5,NORMINV(RAND(),$C$9,$D$9))) | O32: =$I$8*(SUMPRODUCT(($I$2*(1+K32)^{1;2;3;4;5;6;7;8;9;10})*(($I$3+(L32-$I$3)*{1;2;3;4;5;6;7;8;9;10}/10)*(1-$I$7)+$I$4-$I$4*($I$5+(1.05-$I$5)*{1;2;3;4;5;6;7;8;9;10}/10)-(K32/(1+K32))*$I$6)/(1+M32)^{1;2;3;4;5;6;7;8;9;10})+$I$2*(1+K32)^10*(L32+$I$4)*N32/(1+M32)^10+$I$9-$I$10)/$I$11
A33: Bin midpoint ($/sh) | B33: Count | K33: =MAX(-0.05,NORMINV(RAND(),$C$6,$D$6)) | L33: =MAX(0.02,NORMINV(RAND(),$C$7,$D$7)) | M33: =MIN(0.16,MAX(0.05,NORMINV(RAND(),$C$8,$D$8))) | N33: =MIN(24,MAX(5,NORMINV(RAND(),$C$9,$D$9))) | O33: =$I$8*(SUMPRODUCT(($I$2*(1+K33)^{1;2;3;4;5;6;7;8;9;10})*(($I$3+(L33-$I$3)*{1;2;3;4;5;6;7;8;9;10}/10)*(1-$I$7)+$I$4-$I$4*($I$5+(1.05-$I$5)*{1;2;3;4;5;6;7;8;9;10}/10)-(K33/(1+K33))*$I$6)/(1+M33)^{1;2;3;4;5;6;7;8;9;10})+$I$2*(1+K33)^10*(L33+$I$4)*N33/(1+M33)^10+$I$9-$I$10)/$I$11
A34: =$B$15+0.5*($B$16-$B$15)/15 | B34: =COUNTIFS($O$2:$O$1001,">="&($B$15+0*($B$16-$B$15)/15),$O$2:$O$1001,"<"&($B$15+1*($B$16-$B$15)/15)) | K34: =MAX(-0.05,NORMINV(RAND(),$C$6,$D$6)) | L34: =MAX(0.02,NORMINV(RAND(),$C$7,$D$7)) | M34: =MIN(0.16,MAX(0.05,NORMINV(RAND(),$C$8,$D$8))) | N34: =MIN(24,MAX(5,NORMINV(RAND(),$C$9,$D$9))) | O34: =$I$8*(SUMPRODUCT(($I$2*(1+K34)^{1;2;3;4;5;6;7;8;9;10})*(($I$3+(L34-$I$3)*{1;2;3;4;5;6;7;8;9;10}/10)*(1-$I$7)+$I$4-$I$4*($I$5+(1.05-$I$5)*{1;2;3;4;5;6;7;8;9;10}/10)-(K34/(1+K34))*$I$6)/(1+M34)^{1;2;3;4;5;6;7;8;9;10})+$I$2*(1+K34)^10*(L34+$I$4)*N34/(1+M34)^10+$I$9-$I$10)/$I$11
A35: =$B$15+1.5*($B$16-$B$15)/15 | B35: =COUNTIFS($O$2:$O$1001,">="&($B$15+1*($B$16-$B$15)/15),$O$2:$O$1001,"<"&($B$15+2*($B$16-$B$15)/15)) | K35: =MAX(-0.05,NORMINV(RAND(),$C$6,$D$6)) | L35: =MAX(0.02,NORMINV(RAND(),$C$7,$D$7)) | M35: =MIN(0.16,MAX(0.05,NORMINV(RAND(),$C$8,$D$8))) | N35: =MIN(24,MAX(5,NORMINV(RAND(),$C$9,$D$9))) | O35: =$I$8*(SUMPRODUCT(($I$2*(1+K35)^{1;2;3;4;5;6;7;8;9;10})*(($I$3+(L35-$I$3)*{1;2;3;4;5;6;7;8;9;10}/10)*(1-$I$7)+$I$4-$I$4*($I$5+(1.05-$I$5)*{1;2;3;4;5;6;7;8;9;10}/10)-(K35/(1+K35))*$I$6)/(1+M35)^{1;2;3;4;5;6;7;8;9;10})+$I$2*(1+K35)^10*(L35+$I$4)*N35/(1+M35)^10+$I$9-$I$10)/$I$11
A36: =$B$15+2.5*($B$16-$B$15)/15 | B36: =COUNTIFS($O$2:$O$1001,">="&($B$15+2*($B$16-$B$15)/15),$O$2:$O$1001,"<"&($B$15+3*($B$16-$B$15)/15)) | K36: =MAX(-0.05,NORMINV(RAND(),$C$6,$D$6)) | L36: =MAX(0.02,NORMINV(RAND(),$C$7,$D$7)) | M36: =MIN(0.16,MAX(0.05,NORMINV(RAND(),$C$8,$D$8))) | N36: =MIN(24,MAX(5,NORMINV(RAND(),$C$9,$D$9))) | O36: =$I$8*(SUMPRODUCT(($I$2*(1+K36)^{1;2;3;4;5;6;7;8;9;10})*(($I$3+(L36-$I$3)*{1;2;3;4;5;6;7;8;9;10}/10)*(1-$I$7)+$I$4-$I$4*($I$5+(1.05-$I$5)*{1;2;3;4;5;6;7;8;9;10}/10)-(K36/(1+K36))*$I$6)/(1+M36)^{1;2;3;4;5;6;7;8;9;10})+$I$2*(1+K36)^10*(L36+$I$4)*N36/(1+M36)^10+$I$9-$I$10)/$I$11
A37: =$B$15+3.5*($B$16-$B$15)/15 | B37: =COUNTIFS($O$2:$O$1001,">="&($B$15+3*($B$16-$B$15)/15),$O$2:$O$1001,"<"&($B$15+4*($B$16-$B$15)/15)) | K37: =MAX(-0.05,NORMINV(RAND(),$C$6,$D$6)) | L37: =MAX(0.02,NORMINV(RAND(),$C$7,$D$7)) | M37: =MIN(0.16,MAX(0.05,NORMINV(RAND(),$C$8,$D$8))) | N37: =MIN(24,MAX(5,NORMINV(RAND(),$C$9,$D$9))) | O37: =$I$8*(SUMPRODUCT(($I$2*(1+K37)^{1;2;3;4;5;6;7;8;9;10})*(($I$3+(L37-$I$3)*{1;2;3;4;5;6;7;8;9;10}/10)*(1-$I$7)+$I$4-$I$4*($I$5+(1.05-$I$5)*{1;2;3;4;5;6;7;8;9;10}/10)-(K37/(1+K37))*$I$6)/(1+M37)^{1;2;3;4;5;6;7;8;9;10})+$I$2*(1+K37)^10*(L37+$I$4)*N37/(1+M37)^10+$I$9-$I$10)/$I$11
A38: =$B$15+4.5*($B$16-$B$15)/15 | B38: =COUNTIFS($O$2:$O$1001,">="&($B$15+4*($B$16-$B$15)/15),$O$2:$O$1001,"<"&($B$15+5*($B$16-$B$15)/15)) | K38: =MAX(-0.05,NORMINV(RAND(),$C$6,$D$6)) | L38: =MAX(0.02,NORMINV(RAND(),$C$7,$D$7)) | M38: =MIN(0.16,MAX(0.05,NORMINV(RAND(),$C$8,$D$8))) | N38: =MIN(24,MAX(5,NORMINV(RAND(),$C$9,$D$9))) | O38: =$I$8*(SUMPRODUCT(($I$2*(1+K38)^{1;2;3;4;5;6;7;8;9;10})*(($I$3+(L38-$I$3)*{1;2;3;4;5;6;7;8;9;10}/10)*(1-$I$7)+$I$4-$I$4*($I$5+(1.05-$I$5)*{1;2;3;4;5;6;7;8;9;10}/10)-(K38/(1+K38))*$I$6)/(1+M38)^{1;2;3;4;5;6;7;8;9;10})+$I$2*(1+K38)^10*(L38+$I$4)*N38/(1+M38)^10+$I$9-$I$10)/$I$11
A39: =$B$15+5.5*($B$16-$B$15)/15 | B39: =COUNTIFS($O$2:$O$1001,">="&($B$15+5*($B$16-$B$15)/15),$O$2:$O$1001,"<"&($B$15+6*($B$16-$B$15)/15)) | K39: =MAX(-0.05,NORMINV(RAND(),$C$6,$D$6)) | L39: =MAX(0.02,NORMINV(RAND(),$C$7,$D$7)) | M39: =MIN(0.16,MAX(0.05,NORMINV(RAND(),$C$8,$D$8))) | N39: =MIN(24,MAX(5,NORMINV(RAND(),$C$9,$D$9))) | O39: =$I$8*(SUMPRODUCT(($I$2*(1+K39)^{1;2;3;4;5;6;7;8;9;10})*(($I$3+(L39-$I$3)*{1;2;3;4;5;6;7;8;9;10}/10)*(1-$I$7)+$I$4-$I$4*($I$5+(1.05-$I$5)*{1;2;3;4;5;6;7;8;9;10}/10)-(K39/(1+K39))*$I$6)/(1+M39)^{1;2;3;4;5;6;7;8;9;10})+$I$2*(1+K39)^10*(L39+$I$4)*N39/(1+M39)^10+$I$9-$I$10)/$I$11
A40: =$B$15+6.5*($B$16-$B$15)/15 | B40: =COUNTIFS($O$2:$O$1001,">="&($B$15+6*($B$16-$B$15)/15),$O$2:$O$1001,"<"&($B$15+7*($B$16-$B$15)/15)) | K40: =MAX(-0.05,NORMINV(RAND(),$C$6,$D$6)) | L40: =MAX(0.02,NORMINV(RAND(),$C$7,$D$7)) | M40: =MIN(0.16,MAX(0.05,NORMINV(RAND(),$C$8,$D$8))) | N40: =MIN(24,MAX(5,NORMINV(RAND(),$C$9,$D$9))) | O40: =$I$8*(SUMPRODUCT(($I$2*(1+K40)^{1;2;3;4;5;6;7;8;9;10})*(($I$3+(L40-$I$3)*{1;2;3;4;5;6;7;8;9;10}/10)*(1-$I$7)+$I$4-$I$4*($I$5+(1.05-$I$5)*{1;2;3;4;5;6;7;8;9;10}/10)-(K40/(1+K40))*$I$6)/(1+M40)^{1;2;3;4;5;6;7;8;9;10})+$I$2*(1+K40)^10*(L40+$I$4)*N40/(1+M40)^10+$I$9-$I$10)/$I$11
...
