Workbook

Sheet Cover
A1: Nintendo Co., Ltd. (NTDOY)
A2: DCF valuation — exit-multiple terminal · defaults anchored to consensus
A4: Last updated | B4: 2026-06-07
A5: Data pulled (FMP) | B5: Q4 2026
A6: Assumptions by | B6: Opus 4.8 — 2026-06-07
A8: VALUATION SUMMARY
A10: Fair value / share | B10: =Valuation!B36
A11: Current price | B11: =Valuation!$B$2
A12: Upside / (downside) | B12: =Valuation!B42
A13: Verdict | B13: =IF(Valuation!B36>Valuation!$B$2,"Undervalued","Overvalued")
A14: Monte Carlo P(undervalued) | B14: ='Monte Carlo'!B20
A15: KEY ASSUMPTIONS
A17: WACC (from WACC tab) | B17: =WACC!B14
A18: Terminal method | B18: =Valuation!$B$6
A19: Exit basis / multiple | B19: =Valuation!$B$7
A20: Exit multiple | B20: =Valuation!$B$8
A21: Terminal growth (g) | B21: =Valuation!$B$4
A22: Terminal weight | B22: =Valuation!B39
A23: Forecast horizon | B23: 10 years
A25: THE STORY (Opus)
A27: Nintendo is an asset-light, IP-rich console and software cash machine whose results swing with the hardware cycle; the FY2026 Switch 2 launch year compresses margins as ramp/marketing costs hit, while consensus shows revenue cresting near JPY2.7T in 2028-2029 before fading as the cycle matures. We fade revenue growth from ~5% near-term toward a 2.5% terminal rate and let operating margin recover via leverage from the diluted ~16% launch-year level back toward a normalized high-20s as software mix and installed-base monetization improve. Value rests on durable first-party IP, minimal capital intensity, and a fortress balance sheet, offset by the inherent lumpiness of a single-platform franchise.

Sheet Dashboard
A1: Nintendo Co., Ltd. (NTDOY) — Control Dashboard
A2: Edit the yellow cells; everything recomputes. Orange = a driver you've moved off consensus.
A4: VERDICT
A5: Fair value / share | B5: =Valuation!B36
A6: Current price | B6: =Dashboard!$B$48
A7: Upside / (downside) | B7: =Valuation!B42
A8: Verdict | B8: =IF(Valuation!B36>Dashboard!$B$48,"Undervalued","Overvalued")
A9: Monte Carlo P(undervalued) | B9: ='Monte Carlo'!B20
A11: GUARDRAIL SIGNALS (are my assumptions sane?)
A12: Signal | B12: Value | C12: Flag | D12: Healthy
A13: Terminal weight (% of EV) | B13: =Valuation!B39 | C13: =IF(Valuation!B39>0.9,"! high","ok") | D13: < 90%
A14: Implied g vs exit multiple | B14: =Valuation!B40 | C14: =IF(Valuation!B40>Dashboard!$B$46+0.02,"! rich","ok") | D14: near term g
A15: ROIC - WACC (2026) | B15: =Model!G36-WACC!B14 | C15: =IF(Model!G36-WACC!B14<0,"! destroys","creates") | D15: > 0
A16: Revenue vs consensus (2026) | B16: =Consensus!B6 | C16: =IF(ABS(Consensus!B6)>0.05,"! off-Street","on") | D16: +/- 5%
A17: MC P(undervalued) | B17: ='Monte Carlo'!B20 | C17: =IF('Monte Carlo'!B20<0.5,"! coin-flip","ok") | D17: context
A18: REVENUE DRIVERS — near-term & terminal growth per segment
A19: Segment | B19: Near-term | C19: Terminal | D19: Consensus | E19: Thesis claim
A20: Total company | B20: 0.05 | C20: 0.025 | D20: 0.05
A28: PROFITABILITY & TAX
A29: Near-term operating margin | B29: 0.22 | D29: 0.22 | E29: consensus-implied; ramps to terminal
A30: Terminal operating margin | B30: 0.29 | E30: AI/ads mix + operating leverage
A31: Tax rate | B31: 0.3
A33: CAPITAL INTENSITY
A34: 2026 capex ($M) | B34: 24492.472 | D34: 24492.472 | E34: ~last-year capex +10%; set to guidance
A35: Terminal capex / D&A | B35: 1.05 | E35: converges to ~1.0x as build-out matures
A37: DISCOUNT RATE & TERMINAL
A38: Risk-free rate (10Y) | B38: 0.043
A39: Equity risk premium | B39: 0.045
A40: Beta (levered) | B40: 0.158 | E40: FMP raw beta; Damodaran bottom-up ~1.2
A41: Pre-tax cost of debt | B41: 0.045
A42: WACC (computed) | B42: =WACC!B14
A43: Terminal method | B43: Exit multiple
A44: Exit basis | B44: EV/EBITDA
A45: Exit multiple | B45: 9.5
A46: Terminal growth (g) | B46: 0.025
A48: Current price | B48: 11.51

Sheet Color Code
A1: Color | B1: Meaning
A2: Black | B2: Formula-driven (same-sheet)
A3: Blue | B3: Hard-coded actuals (from FMP filings)
A4: Yellow | B4: An assumption you can change — edit these to drive the model
A5: Green | B5: A formula that links to another sheet
A6: Orange | B6: (Dashboard) an assumption you've moved off consensus — your active bet
A7: How to use | B7: Edit yellow cells (Model assumptions, WACC drivers, Valuation toggles). Everything else recomputes.

Sheet WACC
A1: WACC Calculator
A2: Risk-free rate (10Y) | B2: =Dashboard!$B$38
A3: Equity risk premium | B3: =Dashboard!$B$39
A4: Beta (levered) | B4: =Dashboard!$B$40
A5: Cost of equity (CAPM) | B5: =B2+B4*B3
A6: Pre-tax cost of debt | B6: =Dashboard!$B$41
A7: Tax rate | B7: =Dashboard!$B$31
A8: After-tax cost of debt | B8: =B6*(1-B7)
A9: Market cap (E) | B9: =Dashboard!$B$48*Financials!AC17
A10: Total debt (D) | B10: =Financials!AC24
A11: Equity weight | B11: =B9/(B9+B10)
A12: Debt weight | B12: =B10/(B9+B10)
A14: WACC | B14: =B11*B5+B12*B8
A16: Yellow = edit. CAPM cost of equity; market-value weights. Feeds Valuation!WACC.

Sheet Model
A1: $M unless noted | B1: FY2022A | C1: FY2023A | D1: FY2024A | E1: FY2025A | F1: FY2026A | G1: FY2027E | H1: FY2028E | I1: FY2029E | J1: FY2030E | K1: FY2031E | L1: FY2032E | M1: FY2033E | N1: FY2034E | O1: FY2035E | P1: FY2036E
A3: REVENUE BY SEGMENT (yellow = growth assumption; actuals link to Financials)
A4: Total company | B4: =SUM(Financials!J3:M3) | C4: =SUM(Financials!N3:Q3) | D4: =SUM(Financials!R3:U3) | E4: =SUM(Financials!V3:Y3) | F4: =SUM(Financials!Z3:AC3) | G4: =F4*(1+G5) | H4: =G4*(1+H5) | I4: =H4*(1+I5) | J4: =I4*(1+J5) | K4: =J4*(1+K5) | L4: =K4*(1+L5) | M4: =L4*(1+M5) | N4: =M4*(1+N5) | ... P4: =O4*(1+P5)
A5: growth % (interpolated from Dashboard) | C5: =IFERROR(C4/B4-1,"") | D5: =IFERROR(D4/C4-1,"") | E5: =IFERROR(E4/D4-1,"") | F5: =IFERROR(F4/E4-1,"") | G5: =Dashboard!$B$20+(Dashboard!$C$20-Dashboard!$B$20)*MAX(0,0-2)/7 | H5: =Dashboard!$B$20+(Dashboard!$C$20-Dashboard!$B$20)*MAX(0,1-2)/7 | I5: =Dashboard!$B$20+(Dashboard!$C$20-Dashboard!$B$20)*MAX(0,2-2)/7 | J5: =Dashboard!$B$20+(Dashboard!$C$20-Dashboard!$B$20)*MAX(0,3-2)/7 | K5: =Dashboard!$B$20+(Dashboard!$C$20-Dashboard!$B$20)*MAX(0,4-2)/7 | L5: =Dashboard!$B$20+(Dashboard!$C$20-Dashboard!$B$20)*MAX(0,5-2)/7 | M5: =Dashboard!$B$20+(Dashboard!$C$20-Dashboard!$B$20)*MAX(0,6-2)/7 | N5: =Dashboard!$B$20+(Dashboard!$C$20-Dashboard!$B$20)*MAX(0,7-2)/7 | O5: =Dashboard!$B$20+(Dashboard!$C$20-Dashboard!$B$20)*MAX(0,8-2)/7 | P5: =Dashboard!$B$20+(Dashboard!$C$20-Dashboard!$B$20)*MAX(0,9-2)/7
A6: Total revenue | B6: =B4 | C6: =C4 | D6: =D4 | E6: =E4 | F6: =F4 | G6: =G4 | H6: =H4 | I6: =I4 | ... P6: =P4
A7: growth % | C7: =IFERROR(C6/B6-1,"") | D7: =IFERROR(D6/C6-1,"") | E7: =IFERROR(E6/D6-1,"") | F7: =IFERROR(F6/E6-1,"") | G7: =IFERROR(G6/F6-1,"") | H7: =IFERROR(H6/G6-1,"") | I7: =IFERROR(I6/H6-1,"") | J7: =IFERROR(J6/I6-1,"") | ... P7: =IFERROR(P6/O6-1,"")
A9: COST STRUCTURE (yellow = % of revenue)
A10: Cost of revenue | B10: =SUM(Financials!J5:M5) | C10: =SUM(Financials!N5:Q5) | D10: =SUM(Financials!R5:U5) | E10: =SUM(Financials!V5:Y5) | F10: =SUM(Financials!Z5:AC5) | G10: =G6*G11 | H10: =H6*H11 | I10: =I6*I11 | J10: =J6*J11 | K10: =K6*K11 | L10: =L6*L11 | M10: =M6*M11 | N10: =N6*N11 | ... P10: =P6*P11
A11: % of revenue | B11: =IFERROR(B10/B6,"") | C11: =IFERROR(C10/C6,"") | D11: =IFERROR(D10/D6,"") | E11: =IFERROR(E10/E6,"") | F11: =IFERROR(F10/F6,"") | G11: 0.60672165 | H11: 0.60672165 | I11: 0.60672165 | J11: 0.60672165 | K11: 0.60672165 | L11: 0.60672165 | M11: 0.60672165 | N11: 0.60672165 | O11: 0.60672165 | P11: 0.60672165
A12: R&D / Technology | B12: =SUM(Financials!J7:M7) | C12: =SUM(Financials!N7:Q7) | D12: =SUM(Financials!R7:U7) | E12: =SUM(Financials!V7:Y7) | F12: =SUM(Financials!Z7:AC7) | G12: =G6*G13 | H12: =H6*H13 | I12: =I6*I13 | J12: =J6*J13 | K12: =K6*K13 | L12: =L6*L13 | M12: =M6*M13 | N12: =N6*N13 | ... P12: =P6*P13
A13: % of revenue | B13: =IFERROR(B12/B6,"") | C13: =IFERROR(C12/C6,"") | D13: =IFERROR(D12/D6,"") | E13: =IFERROR(E12/E6,"") | F13: =IFERROR(F12/F6,"") | G13: 0.038495462 | H13: 0.038495462 | I13: 0.038495462 | J13: 0.038495462 | K13: 0.038495462 | L13: 0.038495462 | M13: 0.038495462 | N13: 0.038495462 | O13: 0.038495462 | P13: 0.038495462
A14: SG&A | B14: =SUM(Financials!J9:M9) | C14: =SUM(Financials!N9:Q9) | D14: =SUM(Financials!R9:U9) | E14: =SUM(Financials!V9:Y9) | F14: =SUM(Financials!Z9:AC9) | G14: =G6*G15 | H14: =H6*H15 | I14: =I6*I15 | J14: =J6*J15 | K14: =K6*K15 | L14: =L6*L15 | M14: =M6*M15 | N14: =N6*N15 | ... P14: =P6*P15
A15: % of revenue | B15: =IFERROR(B14/B6,"") | C15: =IFERROR(C14/C6,"") | D15: =IFERROR(D14/D6,"") | E15: =IFERROR(E14/E6,"") | F15: =IFERROR(F14/F6,"") | G15: 0.19884789 | H15: 0.19884789 | I15: 0.19884789 | J15: 0.19884789 | K15: 0.19884789 | L15: 0.19884789 | M15: 0.19884789 | N15: 0.19884789 | O15: 0.19884789 | P15: 0.19884789
A16: Other opex (fulfilment, etc.) | B16: =B6-(B10+B12+B14)-SUM(Financials!J13:M13) | C16: =C6-(C10+C12+C14)-SUM(Financials!N13:Q13) | D16: =D6-(D10+D12+D14)-SUM(Financials!R13:U13) | E16: =E6-(E10+E12+E14)-SUM(Financials!V13:Y13) | F16: =F6-(F10+F12+F14)-SUM(Financials!Z13:AC13) | G16: =G6*(1-(Dashboard!$B$29+(Dashboard!$B$30-Dashboard!$B$29)*MIN(1,0/4)))-(G10+G12+G14) | H16: =H6*(1-(Dashboard!$B$29+(Dashboard!$B$30-Dashboard!$B$29)*MIN(1,1/4)))-(H10+H12+H14) | I16: =I6*(1-(Dashboard!$B$29+(Dashboard!$B$30-Dashboard!$B$29)*MIN(1,2/4)))-(I10+I12+I14) | J16: =J6*(1-(Dashboard!$B$29+(Dashboard!$B$30-Dashboard!$B$29)*MIN(1,3/4)))-(J10+J12+J14) | K16: =K6*(1-(Dashboard!$B$29+(Dashboard!$B$30-Dashboard!$B$29)*MIN(1,4/4)))-(K10+K12+K14) | L16: =L6*(1-(Dashboard!$B$29+(Dashboard!$B$30-Dashboard!$B$29)*MIN(1,5/4)))-(L10+L12+L14) | M16: =M6*(1-(Dashboard!$B$29+(Dashboard!$B$30-Dashboard!$B$29)*MIN(1,6/4)))-(M10+M12+M14) | N16: =N6*(1-(Dashboard!$B$29+(Dashboard!$B$30-Dashboard!$B$29)*MIN(1,7/4)))-(N10+N12+N14) | O16: =O6*(1-(Dashboard!$B$29+(Dashboard!$B$30-Dashboard!$B$29)*MIN(1,8/4)))-(O10+O12+O14) | P16: =P6*(1-(Dashboard!$B$29+(Dashboard!$B$30-Dashboard!$B$29)*MIN(1,9/4)))-(P10+P12+P14)
A17: % of revenue | B17: =IFERROR(B16/B6,"") | C17: =IFERROR(C16/C6,"") | D17: =IFERROR(D16/D6,"") | E17: =IFERROR(E16/E6,"") | F17: =IFERROR(F16/F6,"") | G17: =IFERROR(G16/G6,"") | H17: =IFERROR(H16/H6,"") | I17: =IFERROR(I16/I6,"") | ... P17: =IFERROR(P16/P6,"")
A19: Operating income (EBIT) | B19: =B6-(B10+B12+B14)-B16 | C19: =C6-(C10+C12+C14)-C16 | D19: =D6-(D10+D12+D14)-D16 | E19: =E6-(E10+E12+E14)-E16 | F19: =F6-(F10+F12+F14)-F16 | G19: =G6-(G10+G12+G14)-G16 | H19: =H6-(H10+H12+H14)-H16 | I19: =I6-(I10+I12+I14)-I16 | ... P19: =P6-(P10+P12+P14)-P16
A20: operating margin | B20: =IFERROR(B19/B6,"") | C20: =IFERROR(C19/C6,"") | D20: =IFERROR(D19/D6,"") | E20: =IFERROR(E19/E6,"") | F20: =IFERROR(F19/F6,"") | G20: =IFERROR(G19/G6,"") | H20: =IFERROR(H19/H6,"") | I20: =IFERROR(I19/I6,"") | ... P20: =IFERROR(P19/P6,"")
A22: FCF BRIDGE (NOPAT + D&A + SBC - dNWC - Capex)
A23: NOPAT = EBIT x (1 - tax) | B23: =B19*(1-Valuation!$B$5) | C23: =C19*(1-Valuation!$B$5) | D23: =D19*(1-Valuation!$B$5) | E23: =E19*(1-Valuation!$B$5) | F23: =F19*(1-Valuation!$B$5) | G23: =G19*(1-Valuation!$B$5) | H23: =H19*(1-Valuation!$B$5) | I23: =I19*(1-Valuation!$B$5) | ... P23: =P19*(1-Valuation!$B$5)
A24: + D&A | B24: =SUM(Financials!J27:M27) | C24: =SUM(Financials!N27:Q27) | D24: =SUM(Financials!R27:U27) | E24: =SUM(Financials!V27:Y27) | F24: =SUM(Financials!Z27:AC27) | G24: =G6*0.0000 | H24: =H6*0.0000 | I24: =I6*0.0000 | J24: =J6*0.0000 | K24: =K6*0.0000 | L24: =L6*0.0000 | M24: =M6*0.0000 | N24: =N6*0.0000 | ... P24: =P6*0.0000
A25: + SBC (non-cash) | B25: =SUM(Financials!J28:M28) | C25: =SUM(Financials!N28:Q28) | D25: =SUM(Financials!R28:U28) | E25: =SUM(Financials!V28:Y28) | F25: =SUM(Financials!Z28:AC28) | G25: =G6*0.0000 | H25: =H6*0.0000 | I25: =I6*0.0000 | J25: =J6*0.0000 | K25: =K6*0.0000 | L25: =L6*0.0000 | M25: =M6*0.0000 | N25: =N6*0.0000 | ... P25: =P6*0.0000
A26: - dNWC | G26: =(G6-F6)*0.0050 | H26: =(H6-G6)*0.0050 | I26: =(I6-H6)*0.0050 | J26: =(J6-I6)*0.0050 | K26: =(K6-J6)*0.0050 | L26: =(L6-K6)*0.0050 | M26: =(M6-L6)*0.0050 | N26: =(N6-M6)*0.0050 | ... P26: =(P6-O6)*0.0050
A27: - Capex | B27: =-SUM(Financials!J31:M31) | C27: =-SUM(Financials!N31:Q31) | D27: =-SUM(Financials!R31:U31) | E27: =-SUM(Financials!V31:Y31) | F27: =-SUM(Financials!Z31:AC31) | G27: =G24*G28 | H27: =H24*H28 | I27: =I24*I28 | J27: =J24*J28 | K27: =K24*K28 | L27: =L24*L28 | M27: =M24*M28 | N27: =N24*N28 | ... P27: =P24*P28
A28: Capex / D&A (from Dashboard: $cap'26 -> terminal) | B28: =IFERROR(B27/B24,"") | C28: =IFERROR(C27/C24,"") | D28: =IFERROR(D27/D24,"") | E28: =IFERROR(E27/E24,"") | F28: =IFERROR(F27/F24,"") | G28: =(Dashboard!$B$34/G24)+(Dashboard!$B$35-(Dashboard!$B$34/G24))*0/9 | H28: =(Dashboard!$B$34/G24)+(Dashboard!$B$35-(Dashboard!$B$34/G24))*1/9 | I28: =(Dashboard!$B$34/G24)+(Dashboard!$B$35-(Dashboard!$B$34/G24))*2/9 | J28: =(Dashboard!$B$34/G24)+(Dashboard!$B$35-(Dashboard!$B$34/G24))*3/9 | K28: =(Dashboard!$B$34/G24)+(Dashboard!$B$35-(Dashboard!$B$34/G24))*4/9 | L28: =(Dashboard!$B$34/G24)+(Dashboard!$B$35-(Dashboard!$B$34/G24))*5/9 | M28: =(Dashboard!$B$34/G24)+(Dashboard!$B$35-(Dashboard!$B$34/G24))*6/9 | N28: =(Dashboard!$B$34/G24)+(Dashboard!$B$35-(Dashboard!$B$34/G24))*7/9 | O28: =(Dashboard!$B$34/G24)+(Dashboard!$B$35-(Dashboard!$B$34/G24))*8/9 | P28: =(Dashboard!$B$34/G24)+(Dashboard!$B$35-(Dashboard!$B$34/G24))*9/9
A30: FCFF (firm) | B30: =B23+B24+B25-B26-B27 | C30: =C23+C24+C25-C26-C27 | D30: =D23+D24+D25-D26-D27 | E30: =E23+E24+E25-E26-E27 | F30: =F23+F24+F25-F26-F27 | G30: =G23+G24+G25-G26-G27 | H30: =H23+H24+H25-H26-H27 | I30: =I23+I24+I25-I26-I27 | ... P30: =P23+P24+P25-P26-P27
A31: Valuation FCF (FCFF - SBC) | B31: =B30-B25 | C31: =C30-C25 | D31: =D30-D25 | E31: =E30-E25 | F31: =F30-F25 | G31: =G30-G25 | H31: =H30-H25 | I31: =I30-I25 | ... P31: =P30-P25
A33: RETURNS ON CAPITAL & EFFICIENCY (is new revenue/capital earning its keep?)
A34: Invested capital (debt + equity - cash) | B34: =Financials!M25+Financials!M24-Financials!M19 | C34: =Financials!Q25+Financials!Q24-Financials!Q19 | D34: =Financials!U25+Financials!U24-Financials!U19 | E34: =Financials!Y25+Financials!Y24-Financials!Y19 | F34: =Financials!AC25+Financials!AC24-Financials!AC19 | G34: =F34+G27-G24+G26 | H34: =G34+H27-H24+H26 | I34: =H34+I27-I24+I26 | J34: =I34+J27-J24+J26 | K34: =J34+K27-K24+K26 | L34: =K34+L27-L24+L26 | M34: =L34+M27-M24+M26 | N34: =M34+N27-N24+N26 | ... P34: =O34+P27-P24+P26
A35: Book equity (year-end) | B35: =Financials!M25 | C35: =Financials!Q25 | D35: =Financials!U25 | E35: =Financials!Y25 | F35: =Financials!AC25 | G35: =F35+G23 | H35: =G35+H23 | I35: =H35+I23 | J35: =I35+J23 | K35: =J35+K23 | L35: =K35+L23 | M35: =L35+M23 | N35: =M35+N23 | ... P35: =O35+P23
A36: ROIC (NOPAT / beg. invested capital) | C36: =IFERROR(C23/B34,"") | D36: =IFERROR(D23/C34,"") | E36: =IFERROR(E23/D34,"") | F36: =IFERROR(F23/E34,"") | G36: =IFERROR(G23/F34,"") | H36: =IFERROR(H23/G34,"") | I36: =IFERROR(I23/H34,"") | J36: =IFERROR(J23/I34,"") | ... P36: =IFERROR(P23/O34,"")
A37: ROE (earnings / beg. equity) | C37: =IFERROR(SUM(Financials!N15:Q15)/B35,"") | D37: =IFERROR(SUM(Financials!R15:U15)/C35,"") | E37: =IFERROR(SUM(Financials!V15:Y15)/D35,"") | F37: =IFERROR(SUM(Financials!Z15:AC15)/E35,"") | G37: =IFERROR(G23/F35,"") | H37: =IFERROR(H23/G35,"") | I37: =IFERROR(I23/H35,"") | J37: =IFERROR(J23/I35,"") | K37: =IFERROR(K23/J35,"") | L37: =IFERROR(L23/K35,"") | M37: =IFERROR(M23/L35,"") | N37: =IFERROR(N23/M35,"") | ... P37: =IFERROR(P23/O35,"")
A38: ROIC - WACC spread (value created) | C38: =IFERROR(C36-WACC!$B$14,"") | D38: =IFERROR(D36-WACC!$B$14,"") | E38: =IFERROR(E36-WACC!$B$14,"") | F38: =IFERROR(F36-WACC!$B$14,"") | G38: =IFERROR(G36-WACC!$B$14,"") | H38: =IFERROR(H36-WACC!$B$14,"") | I38: =IFERROR(I36-WACC!$B$14,"") | J38: =IFERROR(J36-WACC!$B$14,"") | ... P38: =IFERROR(P36-WACC!$B$14,"")
A39: Incremental op margin (ΔEBIT / ΔRev) | C39: =IFERROR((C19-B19)/(C6-B6),"") | D39: =IFERROR((D19-C19)/(D6-C6),"") | E39: =IFERROR((E19-D19)/(E6-D6),"") | F39: =IFERROR((F19-E19)/(F6-E6),"") | G39: =IFERROR((G19-F19)/(G6-F6),"") | H39: =IFERROR((H19-G19)/(H6-G6),"") | I39: =IFERROR((I19-H19)/(I6-H6),"") | J39: =IFERROR((J19-I19)/(J6-I6),"") | ... P39: =IFERROR((P19-O19)/(P6-O6),"")
A40: ROIIC (ΔNOPAT / ΔInvested capital) | C40: =IFERROR((C23-B23)/(C34-B34),"") | D40: =IFERROR((D23-C23)/(D34-C34),"") | E40: =IFERROR((E23-D23)/(E34-D34),"") | F40: =IFERROR((F23-E23)/(F34-E34),"") | G40: =IFERROR((G23-F23)/(G34-F34),"") | H40: =IFERROR((H23-G23)/(H34-G34),"") | I40: =IFERROR((I23-H23)/(I34-H34),"") | J40: =IFERROR((J23-I23)/(J34-I34),"") | ... P40: =IFERROR((P23-O23)/(P34-O34),"")
A41: Sales-to-capital (ΔRev / ΔInvested capital) | C41: =IFERROR((C6-B6)/(C34-B34),"") | D41: =IFERROR((D6-C6)/(D34-C34),"") | E41: =IFERROR((E6-D6)/(E34-D34),"") | F41: =IFERROR((F6-E6)/(F34-E34),"") | G41: =IFERROR((G6-F6)/(G34-F34),"") | H41: =IFERROR((H6-G6)/(H34-G34),"") | I41: =IFERROR((I6-H6)/(I34-H34),"") | J41: =IFERROR((J6-I6)/(J34-I34),"") | ... P41: =IFERROR((P6-O6)/(P34-O34),"")
A42: Reinvestment rate (ΔInvested capital / NOPAT) | C42: =IFERROR((C34-B34)/C23,"") | D42: =IFERROR((D34-C34)/D23,"") | E42: =IFERROR((E34-D34)/E23,"") | F42: =IFERROR((F34-E34)/F23,"") | G42: =IFERROR((G34-F34)/G23,"") | H42: =IFERROR((H34-G34)/H23,"") | I42: =IFERROR((I34-H34)/I23,"") | J42: =IFERROR((J34-I34)/J23,"") | ... P42: =IFERROR((P34-O34)/P23,"")
A44: Blue/green = actual · Yellow = assumption · Black = formula

Sheet Financials
A1: Line Item ($M) | B1: Q1 2020 | C1: Q2 2020 | D1: Q3 2020 | E1: Q4 2020 | F1: Q1 2021 | G1: Q2 2021 | H1: Q3 2021 | I1: Q4 2021 | J1: Q1 2022 | K1: Q2 2022 | L1: Q3 2022 | M1: Q4 2022 | N1: Q1 2023 | O1: Q2 2023 | P1: Q3 2023 | Q1: Q4 2023 | R1: Q1 2024 | S1: Q2 2024 | T1: Q3 2024 | U1: Q4 2024 | V1: Q1 2025 | W1: Q2 2025 | X1: Q3 2025 | Y1: Q4 2025 | Z1: Q1 2026 | AA1: Q2 2026 | AB1: Q3 2026 | AC1: Q4 2026
A2: INCOME STATEMENT
A3: Revenue | B3: 172111 | C3: 271856 | D3: 578701 | E3: 285851 | F3: 358106 | G3: 411418 | H3: 634939 | I3: 354447 | J3: 322647 | K3: 301625 | L3: 695947 | M3: 375125 | N3: 307460 | O3: 349514 | P3: 638204 | Q3: 306499 | R3: 461341 | S3: 334896 | T3: 598559 | U3: 277069 | V3: 246638 | W3: 276661 | X3: 432919 | Y3: 208704 | Z3: 572363 | AA3: 536394 | AB3: 820874.19 | AC3: 414648.12
A4: % YoY | F4: =IFERROR(F3/B3-1,"") | G4: =IFERROR(G3/C3-1,"") | H4: =IFERROR(H3/D3-1,"") | I4: =IFERROR(I3/E3-1,"") | J4: =IFERROR(J3/F3-1,"") | K4: =IFERROR(K3/G3-1,"") | L4: =IFERROR(L3/H3-1,"") | M4: =IFERROR(M3/I3-1,"") | ... AC4: =IFERROR(AC3/Y3-1,"")
A5: Cost of Revenue | B5: 88693 | C5: 142171 | D5: 325714 | E5: 110239 | F5: 146561 | G5: 188894 | H5: 300191 | I5: 152791 | J5: 129779 | K5: 121766 | L5: 334642 | M5: 163112 | N5: 122861 | O5: 142502 | P5: 332149 | Q5: 118725 | R5: 180242 | S5: 143962 | T5: 292355 | U5: 100971 | V5: 94178 | W5: 111188 | X5: 185326 | Y5: 64062 | Z5: 387208 | AA5: 319364 | AB5: 501211.76 | AC5: 214541.26
A6: % of revenue | B6: =IFERROR(B5/B3,"") | C6: =IFERROR(C5/C3,"") | D6: =IFERROR(D5/D3,"") | E6: =IFERROR(E5/E3,"") | F6: =IFERROR(F5/F3,"") | G6: =IFERROR(G5/G3,"") | H6: =IFERROR(H5/H3,"") | I6: =IFERROR(I5/I3,"") | ... AC6: =IFERROR(AC5/AC3,"")
A7: R&D Expense | B7: 0 | C7: 0 | D7: 0 | E7: 84159 | F7: 0 | G7: 0 | H7: 0 | I7: 23096 | J7: 20343 | K7: 23845 | L7: 24781 | M7: 102199 | N7: 23768 | O7: 27553 | P7: 27057 | Q7: 31637 | R7: 29385 | S7: 30048 | T7: 32932 | U7: 45384 | V7: 0 | W7: 0 | X7: 0 | Y7: 143788 | Z7: 0 | AA7: 44277 | AB7: 45967.114 | AC7: 0
A8: % of revenue | B8: =IFERROR(B7/B3,"") | C8: =IFERROR(C7/C3,"") | D8: =IFERROR(D7/D3,"") | E8: =IFERROR(E7/E3,"") | F8: =IFERROR(F7/F3,"") | G8: =IFERROR(G7/G3,"") | H8: =IFERROR(H7/H3,"") | I8: =IFERROR(I7/I3,"") | ... AC8: =IFERROR(AC7/AC3,"")
A9: SG&A Expense | B9: 55989 | C9: 62891 | D9: 84279 | E9: 5085 | F9: 66808 | G9: 75836 | H9: 105063 | I9: 59035 | J9: 52773 | K9: 79651 | L9: 108713 | M9: 18199 | N9: 82950 | O9: 60719 | P9: 88845 | Q9: 62304 | R9: 95656 | S9: 66419 | T9: 88771 | U9: 66183 | V9: 97950 | W9: 98468 | X9: 121509 | Y9: 109687 | Z9: 128226 | AA9: 82962 | AB9: 115680.31 | AC9: 139286.69
A10: % of revenue | B10: =IFERROR(B9/B3,"") | C10: =IFERROR(C9/C3,"") | D10: =IFERROR(D9/D3,"") | E10: =IFERROR(E9/E3,"") | F10: =IFERROR(F9/F3,"") | G10: =IFERROR(G9/G3,"") | H10: =IFERROR(H9/H3,"") | I10: =IFERROR(I9/I3,"") | ... AC10: =IFERROR(AC9/AC3,"")
A11: Gross Profit | B11: 83418 | C11: 129685 | D11: 252987 | E11: 175612 | F11: 211545 | G11: 222524 | H11: 334748 | I11: 201656 | J11: 192868 | K11: 179859 | L11: 361305 | M11: 212013 | N11: 184599 | O11: 207012 | P11: 306055 | Q11: 187774 | R11: 281099 | S11: 190934 | T11: 306204 | U11: 176098 | V11: 152460 | W11: 165473 | X11: 247593 | Y11: 144642 | Z11: 185155 | AA11: 217030 | AB11: 319662.43 | AC11: 200106.86
A12: gross margin | B12: =IFERROR(B11/B3,"") | C12: =IFERROR(C11/C3,"") | D12: =IFERROR(D11/D3,"") | E12: =IFERROR(E11/E3,"") | F12: =IFERROR(F11/F3,"") | G12: =IFERROR(G11/G3,"") | H12: =IFERROR(H11/H3,"") | I12: =IFERROR(I11/I3,"") | ... AC12: =IFERROR(AC11/AC3,"")
A13: Operating Income | B13: 27428 | C13: 66794 | D13: 168708 | E13: 89440 | F13: 144737 | G13: 146687 | H13: 229684 | I13: 119526 | J13: 119752 | K13: 100207 | L13: 252592 | M13: 120209 | N13: 101647 | O13: 118740 | P13: 190154 | Q13: 93834 | R13: 185441 | S13: 94469 | T13: 184500 | U13: 64531 | V13: 54510 | W13: 67005 | X13: 126084 | Y13: 34955 | Z13: 56928 | AA13: 89792 | AB13: 158015.01 | AC13: 60820.177
A14: operating margin | B14: =IFERROR(B13/B3,"") | C14: =IFERROR(C13/C3,"") | D14: =IFERROR(D13/D3,"") | E14: =IFERROR(E13/E3,"") | F14: =IFERROR(F13/F3,"") | G14: =IFERROR(G13/G3,"") | H14: =IFERROR(H13/H3,"") | I14: =IFERROR(I13/I3,"") | ... AC14: =IFERROR(AC13/AC3,"")
A15: Net Income | B15: 16604 | C15: 45414 | D15: 134371 | E15: 62252 | F15: 106482 | G15: 106641 | H15: 163542 | I15: 103711 | J15: 92747 | K15: 79087 | L15: 195553 | M15: 110304 | N15: 118984 | O15: 111467 | P15: 115776 | Q15: 86541 | R15: 181019 | S15: 90279 | T15: 136743 | U15: 82561 | V15: 80954 | W15: 27704 | X15: 128531 | Y15: 41616 | Z15: 96032 | AA15: 104699 | AB15: 162814.11 | AC15: 66389.648
A16: net margin | B16: =IFERROR(B15/B3,"") | C16: =IFERROR(C15/C3,"") | D16: =IFERROR(D15/D3,"") | E16: =IFERROR(E15/E3,"") | F16: =IFERROR(F15/F3,"") | G16: =IFERROR(G15/G3,"") | H16: =IFERROR(H15/H3,"") | I16: =IFERROR(I15/I3,"") | ... AC16: =IFERROR(AC15/AC3,"")
A17: Diluted Shares (M) | B17: 4764.96 | C17: 4764.96 | D17: 4764.92 | E17: 4764.92 | F17: 4764.92 | G17: 4764.92 | H17: 4764.88 | I17: 4764.88 | J17: 4764.88 | K17: 4736.208 | L17: 4692.8923 | M17: 4693.4 | N17: 4672.712 | O17: 4656.8971 | P17: 4656.9177 | Q17: 4656.9174 | R17: 4656.916 | S17: 4656.9547 | T17: 4656.956 | U17: 4656.952 | V17: 4656.952 | W17: 4656.984 | X17: 4656.992 | Y17: 4656.992 | Z17: 4656.992 | AA17: 4657.024 | AB17: 4657.036 | AC17: 4632.252
A18: BALANCE SHEET
A19: Cash & ST Investments | B19: 906618 | C19: 925878 | D19: 1091169 | E19: 1216784 | F19: 1257327 | G19: 1389833 | H19: 1529137 | I19: 1742389 | J19: 1514177 | K19: 1469688 | L19: 1534270 | M19: 1710891 | N19: 1564777 | O19: 1654601 | P19: 1725650 | Q19: 1879365 | R19: 1952029 | S19: 2068614 | T19: 2010292 | U19: 2252705 | V19: 2163129 | W19: 2016373 | X19: 2154084 | Y19: 2058190 | Z19: 1909164 | AA19: 2115131 | AB19: 2295426.9 | AC19: 2226470.9
A20: Total Current Assets | B20: 1195534 | C20: 1358446 | D20: 1500427 | E20: 1501583 | F20: 1545765 | G20: 1768470 | H20: 1922688 | I20: 2020375 | J20: 1848880 | K20: 1930959 | L20: 2033051 | M20: 2126212 | N20: 2009748 | O20: 2179545 | P20: 2241859 | Q20: 2314513 | R20: 2455195 | S20: 2606440 | T20: 2521357 | U20: 2573302 | V20: 2574713 | W20: 2455907 | X20: 2764346 | Y20: 2752352 | Z20: 2819708 | AA20: 19978.143 | AB20: 3132598 | AC20: 3022837.9
A21: PP&E (net) | B21: 81039 | C21: 83095 | D21: 82791 | E21: 82866 | F21: 82380 | G21: 83252 | H21: 82415 | I21: 83569 | J21: 83638 | K21: 84039 | L21: 84187 | M21: 85164 | N21: 91849 | O21: 92728 | P21: 97640 | Q21: 99509 | R21: 103787 | S21: 106711 | T21: 106546 | U21: 108518 | V21: 111788 | W21: 110978 | X21: 112783 | Y21: 112612 | Z21: 112825 | AA21: 113993 | AB21: 127084.69 | AC21: 128002.77
A22: Total Assets | B22: 1597571 | C22: 1777072 | D22: 1898641 | E22: 1934087 | F22: 1975410 | G22: 2211580 | H22: 2328065 | I22: 2446918 | J22: 2298064 | K22: 2399649 | L22: 2507333 | M22: 2662384 | N22: 2586214 | O22: 2781207 | P22: 2785812 | Q22: 2854284 | R22: 2997942 | S22: 3170476 | T22: 3073719 | U22: 3151394 | V22: 3180510 | W22: 3071364 | X22: 3386868 | Y22: 3398515 | Z22: 3472673 | AA22: 3636187 | AB22: 3865983.3 | AC22: 3821816.3
A23: Total Current Liabilities | B23: 222247 | C23: 358165 | D23: 365865 | E23: 355683 | F23: 382151 | G23: 497967 | H23: 546488 | I23: 526331 | J23: 446761 | K23: 563610 | L23: 532787 | M23: 540726 | N23: 491072 | O23: 547624 | P23: 559517 | Q23: 533480 | R23: 573571 | S23: 638552 | T23: 529599 | U23: 479276 | V23: 524279 | W23: 465812 | X23: 621822 | Y23: 597646 | Z23: 694065 | AA23: 738007 | AB23: 791972.26 | AC23: 763444.89
A24: Long-term Debt | B24: 0 | C24: 0 | D24: 0 | E24: 0 | F24: 0 | G24: 0 | H24: 0 | I24: 0 | J24: 0 | K24: 0 | L24: 0 | M24: 0 | N24: 0 | O24: 0 | P24: 0 | Q24: 0 | R24: 0 | S24: 0 | T24: 0 | U24: 0 | V24: 0 | W24: 0 | X24: 0 | Y24: 0 | Z24: 0 | AA24: 0 | AB24: 0 | AC24: 0
A25: Total Equity | B25: 1344176 | C25: 1386450 | D25: 1498321 | E25: 1540686 | F25: 1553879 | G25: 1669640 | H25: 1736022 | I25: 1874370 | J25: 1804146 | K25: 1787814 | L25: 1924444 | M25: 2069042 | N25: 2035360 | O25: 2177754 | P25: 2172829 | Q25: 2266234 | R25: 2360572 | S25: 2467517 | T25: 2478369 | U25: 2603761 | V25: 2586682 | W25: 2538252 | X25: 2691544 | Y25: 2724327 | Z25: 2701388 | AA25: 2817260 | AB25: 2977281 | AC25: 2966837.1
A26: CASH FLOW
A27: D&A | B27: 0 | C27: 0 | D27: 0 | E27: 0 | F27: 0 | G27: 0 | H27: 0 | I27: 0 | J27: 0 | K27: 0 | L27: 0 | M27: 0 | N27: 0 | O27: 2795 | P27: 2822 | Q27: 2794 | R27: 7015 | S27: 3853 | T27: 3279 | U27: 0 | V27: 0 | W27: 0 | X27: 0 | Y27: 0 | Z27: 0
A28: Stock-based Compensation | B28: 0 | C28: 0 | D28: 0 | E28: 0 | F28: 0 | G28: 0 | H28: 0 | I28: 0 | J28: 0 | K28: 0 | L28: 0 | M28: 0 | N28: 0 | O28: 0 | P28: 0 | Q28: 0 | R28: 0 | S28: 0 | T28: 0 | U28: 0 | V28: 0 | W28: 0 | X28: 0 | Y28: 0 | Z28: 0
A29: Change in Working Capital | B29: 0 | C29: 0 | D29: 0 | E29: 0 | F29: 0 | G29: 0 | H29: 0 | I29: 0 | J29: 0 | K29: 0 | L29: 0 | M29: 0 | N29: 0 | O29: 0 | P29: 0 | Q29: 0 | R29: 0 | S29: 0 | T29: 0 | U29: 0 | V29: 0 | W29: 0 | X29: 0 | Y29: 0 | Z29: 0
A30: Operating Cash Flow | B30: 0 | C30: 0 | D30: 0 | E30: 0 | F30: 0 | G30: 0 | H30: 0 | I30: 0 | J30: 0 | K30: 0 | L30: 0 | M30: 0 | N30: 0 | O30: 5590 | P30: 5644 | Q30: 5588 | R30: 14030 | S30: 7706 | T30: 6558 | U30: 0 | V30: 0 | W30: 0 | X30: 0 | Y30: 0 | Z30: 0
A31: Capex | B31: 0 | C31: 0 | D31: 0 | E31: 0 | F31: 0 | G31: 0 | H31: 0 | I31: 0 | J31: 0 | K31: 0 | L31: 0 | M31: 0 | N31: 0 | O31: 0 | P31: 0 | Q31: 0 | R31: 0 | S31: 0 | T31: 0 | U31: 0 | V31: 0 | W31: 0 | X31: 0 | Y31: 0 | Z31: 0
A32: Free Cash Flow | B32: 0 | C32: 0 | D32: 0 | E32: 0 | F32: 0 | G32: 0 | H32: 0 | I32: 0 | J32: 0 | K32: 0 | L32: 0 | M32: 0 | N32: 0 | O32: 5590 | P32: 5644 | Q32: 5588 | R32: 14030 | S32: 7706 | T32: 6558 | U32: 0 | V32: 0 | W32: 0 | X32: 0 | Y32: 0 | Z32: 0
A34: Blue = hardcoded actuals from FMP filings. Same-sheet ratios are formulas.

Sheet Consensus
A1: Full consensus check — model vs Street (FMP estimates, $M)
A2: Fiscal year | B2: 2027 | C2: 2028 | D2: 2029 | E2: 2030 | F2: 2031
A3: EVERY AVAILABLE FMP CONSENSUS FIELD (consensus / model / % diff)
A4: Revenue — consensus | B4: 2449247.2 | C4: 2708457.5 | D4: 2722361.7 | E4: 2614521.7 | F4: 2208048.6
A5: model | B5: =Model!G6 | C5: =Model!H6 | D5: =Model!I6 | E5: =Model!J6 | F5: =Model!K6
A6: vs consensus | B6: =IFERROR(B5/B4-1,"") | C6: =IFERROR(C5/C4-1,"") | D6: =IFERROR(D5/D4-1,"") | E6: =IFERROR(E5/E4-1,"") | F6: =IFERROR(F5/F4-1,"")
A8: EBITDA* — consensus | B8: 808835.78 | C8: 894437 | D8: 899028.69 | E8: 863415.78 | F8: 729182.7
A9: model | B9: =Model!G19+Model!G24 | C9: =Model!H19+Model!H24 | D9: =Model!I19+Model!I24 | E9: =Model!J19+Model!J24 | F9: =Model!K19+Model!K24
A10: vs consensus | B10: =IFERROR(B9/B8-1,"") | C10: =IFERROR(C9/C8-1,"") | D10: =IFERROR(D9/D8-1,"") | E10: =IFERROR(E9/E8-1,"") | F10: =IFERROR(F9/F8-1,"")
A12: EBIT* — consensus | B12: 787369.17 | C12: 870698.52 | D12: 875168.35 | E12: 840500.61 | F12: 709830.1
A13: model | B13: =Model!G19 | C13: =Model!H19 | D13: =Model!I19 | E13: =Model!J19 | F13: =Model!K19
A14: vs consensus | B14: =IFERROR(B13/B12-1,"") | C14: =IFERROR(C13/C12-1,"") | D14: =IFERROR(D13/D12-1,"") | E14: =IFERROR(E13/E12-1,"") | F14: =IFERROR(F13/F12-1,"")
A16: SG&A — consensus | B16: 528467.59 | C16: 584396.71 | D16: 587396.77 | E16: 564128.43 | F16: 476424.8
A17: model | B17: =Model!G14 | C17: =Model!H14 | D17: =Model!I14 | E17: =Model!J14 | F17: =Model!K14
A18: vs consensus | B18: =IFERROR(B17/B16-1,"") | C18: =IFERROR(C17/C16-1,"") | D18: =IFERROR(D17/D16-1,"") | E18: =IFERROR(E17/E16-1,"") | F18: =IFERROR(F17/F16-1,"")
A20: Net income (NOPAT) — consensus | B20: 417062.51 | C20: 500518.69 | D20: 584400.94 | E20: 595464.51 | F20: 539507.29
A21: model | B21: =Model!G23 | C21: =Model!H23 | D21: =Model!I23 | E21: =Model!J23 | F21: =Model!K23
A22: vs consensus | B22: =IFERROR(B21/B20-1,"") | C22: =IFERROR(C21/C20-1,"") | D22: =IFERROR(D21/D20-1,"") | E22: =IFERROR(E21/E20-1,"") | F22: =IFERROR(F21/F20-1,"")
A24: EPS — consensus | B24: 89.62556 | C24: 107.56006 | D24: 125.58612 | E24: 127.96365 | F24: 115.9386
A25: model | B25: =Model!G23/Financials!AC17 | C25: =Model!H23/Financials!AC17 | D25: =Model!I23/Financials!AC17 | E25: =Model!J23/Financials!AC17 | F25: =Model!K23/Financials!AC17
A26: vs consensus | B26: =IFERROR(B25/B24-1,"") | C26: =IFERROR(C25/C24-1,"") | D26: =IFERROR(D25/D24-1,"") | E26: =IFERROR(E25/E24-1,"") | F26: =IFERROR(F25/F24-1,"")
A28: Defaults anchored to consensus revenue + net income (≈0% diff). Other rows show where the model sits vs Street.
A29: *FMP's EBITDA/EBIT estimates look unreliable for AMZN (it reports NI > EBIT) — don't over-read those two.

Sheet Valuation
A1: Nintendo Co., Ltd. — DCF Valuation
A2: Current price | B2: =Dashboard!$B$48
A3: WACC | B3: =WACC!B14
A4: Terminal growth (g) | B4: =Dashboard!$B$46
A5: Tax rate | B5: =Dashboard!$B$31
A6: Terminal method | B6: =Dashboard!$B$43
A7: Exit basis | B7: =Dashboard!$B$44
A8: Exit multiple | B8: =Dashboard!$B$45
A11: Forecast year | C11: 2027 | D11: 2028 | E11: 2029 | F11: 2030 | G11: 2031 | H11: 2032 | I11: 2033 | J11: 2034 | K11: 2035 | L11: 2036
A12: FCFF ($M) | C12: =Model!G31 | D12: =Model!H31 | E12: =Model!I31 | F12: =Model!J31 | G12: =Model!K31 | H12: =Model!L31 | I12: =Model!M31 | J12: =Model!N31 | ... L12: =Model!P31
A13: PV factor | C13: =1/(1+$B$3)^1 | D13: =1/(1+$B$3)^2 | E13: =1/(1+$B$3)^3 | F13: =1/(1+$B$3)^4 | G13: =1/(1+$B$3)^5 | H13: =1/(1+$B$3)^6 | I13: =1/(1+$B$3)^7 | J13: =1/(1+$B$3)^8 | K13: =1/(1+$B$3)^9 | L13: =1/(1+$B$3)^10
A14: PV of FCFF ($M) | C14: =C12*C13 | D14: =D12*D13 | E14: =E12*E13 | F14: =F12*F13 | G14: =G12*G13 | H14: =H12*H13 | I14: =I12*I13 | J14: =J12*J13 | ... L14: =L12*L13
A16: Sum PV of FCFF | B16: =SUM(C14:L14)
A18: TERMINAL VALUE (exit multiple = default; perpetuity = cross-check)
A19: Terminal-year FCFF | B19: =L12
A20: Terminal revenue | B20: =Model!P6
A21: Terminal EBIT | B21: =Model!P19
A22: Terminal EBITDA | B22: =Model!P19+Model!P24
A23: Terminal metric (per exit basis) | B23: =IF($B$7="EV/EBITDA",B22,IF($B$7="EV/Sales",B20,IF($B$7="EV/EBIT",B21,B19)))
A24: TV (exit) = metric x multiple | B24: =B23*$B$8
A25: PV of TV — exit multiple | B25: =B24/(1+$B$3)^10
A26: TV (perpetuity) = FCFF(1+g)/(WACC-g) | B26: =B19*(1+$B$4)/($B$3-$B$4)
A27: PV of TV — perpetuity | B27: =B26/(1+$B$3)^10
A28: PV of TV — SELECTED | B28: =IF($B$6="Perpetuity",B27,B25)
A30: EQUITY BRIDGE -> VALUE / SHARE
A31: Operating value (enterprise value) | B31: =B16+B28
A32: + Cash & ST investments | B32: =Financials!AC19
A33: - Long-term debt | B33: =-Financials!AC24
A34: Equity value | B34: =B31+B32+B33
A35: Diluted shares (M) | B35: =Financials!AC17
A36: VALUE / SHARE | B36: =B34/B35*0.0067
A38: CROSS-CHECKS & RETURN
A39: Terminal weight (% of EV) | B39: =B28/B31
A40: Implied perpetuity g (from exit multiple) | B40: =(B24*$B$3-B19)/(B24+B19)
A41: Implied exit EV/EBITDA (from perpetuity) | B41: =B26/B22
A42: Upside / (downside) to fair value | B42: =B36/$B$2-1
A44: Owner cashflow / share | B44: =-$B$2 | C44: =C12/B35 | D44: =D12/B35 | E44: =E12/B35 | F44: =F12/B35 | G44: =G12/B35 | H44: =H12/B35 | I44: =I12/B35 | J44: =J12/B35 | K44: =K12/B35 | L44: =L12/B35+B36
A45: IRR (buy at price, hold 10y) | B45: =IRR(B44:L44)

Sheet Monte Carlo
A1: Monte Carlo simulation (live) | H1: SIMULATION ENGINE — leave as-is | K1: cagr | L1: term margin | M1: wacc | N1: exit | O1: value/share
A2: 1,000 trials, recomputed in-sheet on every edit. Edit the yellow driver distributions to re-roll. Engine grid is to the right (cols H+). | H2: R0 (base revenue) | I2: =Model!F6 | K2: =MAX(-0.05,NORMINV(RAND(),$C$6,$D$6)) | L2: =MAX(0.02,NORMINV(RAND(),$C$7,$D$7)) | M2: =MIN(0.16,MAX(0.05,NORMINV(RAND(),$C$8,$D$8))) | N2: =MIN(24,MAX(5,NORMINV(RAND(),$C$9,$D$9))) | O2: =$I$8*(SUMPRODUCT(($I$2*(1+K2)^{1;2;3;4;5;6;7;8;9;10})*(($I$3+(L2-$I$3)*{1;2;3;4;5;6;7;8;9;10}/10)*(1-$I$7)+$I$4-$I$4*($I$5+(1.05-$I$5)*{1;2;3;4;5;6;7;8;9;10}/10)-(K2/(1+K2))*$I$6)/(1+M2)^{1;2;3;4;5;6;7;8;9;10})+$I$2*(1+K2)^10*(L2+$I$4)*N2/(1+M2)^10+$I$9-$I$10)/$I$11
H3: m0 (base op margin) | I3: =Model!F20 | K3: =MAX(-0.05,NORMINV(RAND(),$C$6,$D$6)) | L3: =MAX(0.02,NORMINV(RAND(),$C$7,$D$7)) | M3: =MIN(0.16,MAX(0.05,NORMINV(RAND(),$C$8,$D$8))) | N3: =MIN(24,MAX(5,NORMINV(RAND(),$C$9,$D$9))) | O3: =$I$8*(SUMPRODUCT(($I$2*(1+K3)^{1;2;3;4;5;6;7;8;9;10})*(($I$3+(L3-$I$3)*{1;2;3;4;5;6;7;8;9;10}/10)*(1-$I$7)+$I$4-$I$4*($I$5+(1.05-$I$5)*{1;2;3;4;5;6;7;8;9;10}/10)-(K3/(1+K3))*$I$6)/(1+M3)^{1;2;3;4;5;6;7;8;9;10})+$I$2*(1+K3)^10*(L3+$I$4)*N3/(1+M3)^10+$I$9-$I$10)/$I$11
A4: DRIVER DISTRIBUTIONS (yellow = edit; Opus-set defaults) | H4: da (D&A / revenue) | I4: 0 | K4: =MAX(-0.05,NORMINV(RAND(),$C$6,$D$6)) | L4: =MAX(0.02,NORMINV(RAND(),$C$7,$D$7)) | M4: =MIN(0.16,MAX(0.05,NORMINV(RAND(),$C$8,$D$8))) | N4: =MIN(24,MAX(5,NORMINV(RAND(),$C$9,$D$9))) | O4: =$I$8*(SUMPRODUCT(($I$2*(1+K4)^{1;2;3;4;5;6;7;8;9;10})*(($I$3+(L4-$I$3)*{1;2;3;4;5;6;7;8;9;10}/10)*(1-$I$7)+$I$4-$I$4*($I$5+(1.05-$I$5)*{1;2;3;4;5;6;7;8;9;10}/10)-(K4/(1+K4))*$I$6)/(1+M4)^{1;2;3;4;5;6;7;8;9;10})+$I$2*(1+K4)^10*(L4+$I$4)*N4/(1+M4)^10+$I$9-$I$10)/$I$11
A5: Driver | B5: Dist | C5: Mean | D5: Std dev | H5: cda0 (2026 capex/D&A) | I5: 24492.472 | K5: =MAX(-0.05,NORMINV(RAND(),$C$6,$D$6)) | L5: =MAX(0.02,NORMINV(RAND(),$C$7,$D$7)) | M5: =MIN(0.16,MAX(0.05,NORMINV(RAND(),$C$8,$D$8))) | N5: =MIN(24,MAX(5,NORMINV(RAND(),$C$9,$D$9))) | O5: =$I$8*(SUMPRODUCT(($I$2*(1+K5)^{1;2;3;4;5;6;7;8;9;10})*(($I$3+(L5-$I$3)*{1;2;3;4;5;6;7;8;9;10}/10)*(1-$I$7)+$I$4-$I$4*($I$5+(1.05-$I$5)*{1;2;3;4;5;6;7;8;9;10}/10)-(K5/(1+K5))*$I$6)/(1+M5)^{1;2;3;4;5;6;7;8;9;10})+$I$2*(1+K5)^10*(L5+$I$4)*N5/(1+M5)^10+$I$9-$I$10)/$I$11
A6: Revenue 10y CAGR | B6: Normal | C6: =(Model!P6/Model!F6)^(1/10)-1 | D6: 0.03 | H6: nwc (% incr revenue) | I6: 0.005 | K6: =MAX(-0.05,NORMINV(RAND(),$C$6,$D$6)) | L6: =MAX(0.02,NORMINV(RAND(),$C$7,$D$7)) | M6: =MIN(0.16,MAX(0.05,NORMINV(RAND(),$C$8,$D$8))) | N6: =MIN(24,MAX(5,NORMINV(RAND(),$C$9,$D$9))) | O6: =$I$8*(SUMPRODUCT(($I$2*(1+K6)^{1;2;3;4;5;6;7;8;9;10})*(($I$3+(L6-$I$3)*{1;2;3;4;5;6;7;8;9;10}/10)*(1-$I$7)+$I$4-$I$4*($I$5+(1.05-$I$5)*{1;2;3;4;5;6;7;8;9;10}/10)-(K6/(1+K6))*$I$6)/(1+M6)^{1;2;3;4;5;6;7;8;9;10})+$I$2*(1+K6)^10*(L6+$I$4)*N6/(1+M6)^10+$I$9-$I$10)/$I$11
A7: Terminal operating margin | B7: Normal | C7: =Dashboard!$B$30 | D7: 0.03 | H7: tax | I7: =Valuation!$B$5 | K7: =MAX(-0.05,NORMINV(RAND(),$C$6,$D$6)) | L7: =MAX(0.02,NORMINV(RAND(),$C$7,$D$7)) | M7: =MIN(0.16,MAX(0.05,NORMINV(RAND(),$C$8,$D$8))) | N7: =MIN(24,MAX(5,NORMINV(RAND(),$C$9,$D$9))) | O7: =$I$8*(SUMPRODUCT(($I$2*(1+K7)^{1;2;3;4;5;6;7;8;9;10})*(($I$3+(L7-$I$3)*{1;2;3;4;5;6;7;8;9;10}/10)*(1-$I$7)+$I$4-$I$4*($I$5+(1.05-$I$5)*{1;2;3;4;5;6;7;8;9;10}/10)-(K7/(1+K7))*$I$6)/(1+M7)^{1;2;3;4;5;6;7;8;9;10})+$I$2*(1+K7)^10*(L7+$I$4)*N7/(1+M7)^10+$I$9-$I$10)/$I$11
A8: WACC | B8: Normal | C8: =WACC!B14 | D8: 0.005 | H8: k (calibration) | I8: 0.0071483753 | K8: =MAX(-0.05,NORMINV(RAND(),$C$6,$D$6)) | L8: =MAX(0.02,NORMINV(RAND(),$C$7,$D$7)) | M8: =MIN(0.16,MAX(0.05,NORMINV(RAND(),$C$8,$D$8))) | N8: =MIN(24,MAX(5,NORMINV(RAND(),$C$9,$D$9))) | O8: =$I$8*(SUMPRODUCT(($I$2*(1+K8)^{1;2;3;4;5;6;7;8;9;10})*(($I$3+(L8-$I$3)*{1;2;3;4;5;6;7;8;9;10}/10)*(1-$I$7)+$I$4-$I$4*($I$5+(1.05-$I$5)*{1;2;3;4;5;6;7;8;9;10}/10)-(K8/(1+K8))*$I$6)/(1+M8)^{1;2;3;4;5;6;7;8;9;10})+$I$2*(1+K8)^10*(L8+$I$4)*N8/(1+M8)^10+$I$9-$I$10)/$I$11
A9: Exit EV/EBITDA multiple | B9: Normal | C9: =Dashboard!$B$45 | D9: 1.5 | H9: cash | I9: =Financials!AC19 | K9: =MAX(-0.05,NORMINV(RAND(),$C$6,$D$6)) | L9: =MAX(0.02,NORMINV(RAND(),$C$7,$D$7)) | M9: =MIN(0.16,MAX(0.05,NORMINV(RAND(),$C$8,$D$8))) | N9: =MIN(24,MAX(5,NORMINV(RAND(),$C$9,$D$9))) | O9: =$I$8*(SUMPRODUCT(($I$2*(1+K9)^{1;2;3;4;5;6;7;8;9;10})*(($I$3+(L9-$I$3)*{1;2;3;4;5;6;7;8;9;10}/10)*(1-$I$7)+$I$4-$I$4*($I$5+(1.05-$I$5)*{1;2;3;4;5;6;7;8;9;10}/10)-(K9/(1+K9))*$I$6)/(1+M9)^{1;2;3;4;5;6;7;8;9;10})+$I$2*(1+K9)^10*(L9+$I$4)*N9/(1+M9)^10+$I$9-$I$10)/$I$11
H10: debt | I10: =Financials!AC24 | K10: =MAX(-0.05,NORMINV(RAND(),$C$6,$D$6)) | L10: =MAX(0.02,NORMINV(RAND(),$C$7,$D$7)) | M10: =MIN(0.16,MAX(0.05,NORMINV(RAND(),$C$8,$D$8))) | N10: =MIN(24,MAX(5,NORMINV(RAND(),$C$9,$D$9))) | O10: =$I$8*(SUMPRODUCT(($I$2*(1+K10)^{1;2;3;4;5;6;7;8;9;10})*(($I$3+(L10-$I$3)*{1;2;3;4;5;6;7;8;9;10}/10)*(1-$I$7)+$I$4-$I$4*($I$5+(1.05-$I$5)*{1;2;3;4;5;6;7;8;9;10}/10)-(K10/(1+K10))*$I$6)/(1+M10)^{1;2;3;4;5;6;7;8;9;10})+$I$2*(1+K10)^10*(L10+$I$4)*N10/(1+M10)^10+$I$9-$I$10)/$I$11
A11: SIMULATION OUTPUT — value / share (live) | H11: shares | I11: =Financials!AC17 | K11: =MAX(-0.05,NORMINV(RAND(),$C$6,$D$6)) | L11: =MAX(0.02,NORMINV(RAND(),$C$7,$D$7)) | M11: =MIN(0.16,MAX(0.05,NORMINV(RAND(),$C$8,$D$8))) | N11: =MIN(24,MAX(5,NORMINV(RAND(),$C$9,$D$9))) | O11: =$I$8*(SUMPRODUCT(($I$2*(1+K11)^{1;2;3;4;5;6;7;8;9;10})*(($I$3+(L11-$I$3)*{1;2;3;4;5;6;7;8;9;10}/10)*(1-$I$7)+$I$4-$I$4*($I$5+(1.05-$I$5)*{1;2;3;4;5;6;7;8;9;10}/10)-(K11/(1+K11))*$I$6)/(1+M11)^{1;2;3;4;5;6;7;8;9;10})+$I$2*(1+K11)^10*(L11+$I$4)*N11/(1+M11)^10+$I$9-$I$10)/$I$11
A12: Mean | B12: =AVERAGE($O$2:$O$1001) | K12: =MAX(-0.05,NORMINV(RAND(),$C$6,$D$6)) | L12: =MAX(0.02,NORMINV(RAND(),$C$7,$D$7)) | M12: =MIN(0.16,MAX(0.05,NORMINV(RAND(),$C$8,$D$8))) | N12: =MIN(24,MAX(5,NORMINV(RAND(),$C$9,$D$9))) | O12: =$I$8*(SUMPRODUCT(($I$2*(1+K12)^{1;2;3;4;5;6;7;8;9;10})*(($I$3+(L12-$I$3)*{1;2;3;4;5;6;7;8;9;10}/10)*(1-$I$7)+$I$4-$I$4*($I$5+(1.05-$I$5)*{1;2;3;4;5;6;7;8;9;10}/10)-(K12/(1+K12))*$I$6)/(1+M12)^{1;2;3;4;5;6;7;8;9;10})+$I$2*(1+K12)^10*(L12+$I$4)*N12/(1+M12)^10+$I$9-$I$10)/$I$11
A13: Median (P50) | B13: =MEDIAN($O$2:$O$1001) | K13: =MAX(-0.05,NORMINV(RAND(),$C$6,$D$6)) | L13: =MAX(0.02,NORMINV(RAND(),$C$7,$D$7)) | M13: =MIN(0.16,MAX(0.05,NORMINV(RAND(),$C$8,$D$8))) | N13: =MIN(24,MAX(5,NORMINV(RAND(),$C$9,$D$9))) | O13: =$I$8*(SUMPRODUCT(($I$2*(1+K13)^{1;2;3;4;5;6;7;8;9;10})*(($I$3+(L13-$I$3)*{1;2;3;4;5;6;7;8;9;10}/10)*(1-$I$7)+$I$4-$I$4*($I$5+(1.05-$I$5)*{1;2;3;4;5;6;7;8;9;10}/10)-(K13/(1+K13))*$I$6)/(1+M13)^{1;2;3;4;5;6;7;8;9;10})+$I$2*(1+K13)^10*(L13+$I$4)*N13/(1+M13)^10+$I$9-$I$10)/$I$11
A14: Std dev | B14: =STDEV($O$2:$O$1001) | K14: =MAX(-0.05,NORMINV(RAND(),$C$6,$D$6)) | L14: =MAX(0.02,NORMINV(RAND(),$C$7,$D$7)) | M14: =MIN(0.16,MAX(0.05,NORMINV(RAND(),$C$8,$D$8))) | N14: =MIN(24,MAX(5,NORMINV(RAND(),$C$9,$D$9))) | O14: =$I$8*(SUMPRODUCT(($I$2*(1+K14)^{1;2;3;4;5;6;7;8;9;10})*(($I$3+(L14-$I$3)*{1;2;3;4;5;6;7;8;9;10}/10)*(1-$I$7)+$I$4-$I$4*($I$5+(1.05-$I$5)*{1;2;3;4;5;6;7;8;9;10}/10)-(K14/(1+K14))*$I$6)/(1+M14)^{1;2;3;4;5;6;7;8;9;10})+$I$2*(1+K14)^10*(L14+$I$4)*N14/(1+M14)^10+$I$9-$I$10)/$I$11
A15: Min | B15: =MIN($O$2:$O$1001) | K15: =MAX(-0.05,NORMINV(RAND(),$C$6,$D$6)) | L15: =MAX(0.02,NORMINV(RAND(),$C$7,$D$7)) | M15: =MIN(0.16,MAX(0.05,NORMINV(RAND(),$C$8,$D$8))) | N15: =MIN(24,MAX(5,NORMINV(RAND(),$C$9,$D$9))) | O15: =$I$8*(SUMPRODUCT(($I$2*(1+K15)^{1;2;3;4;5;6;7;8;9;10})*(($I$3+(L15-$I$3)*{1;2;3;4;5;6;7;8;9;10}/10)*(1-$I$7)+$I$4-$I$4*($I$5+(1.05-$I$5)*{1;2;3;4;5;6;7;8;9;10}/10)-(K15/(1+K15))*$I$6)/(1+M15)^{1;2;3;4;5;6;7;8;9;10})+$I$2*(1+K15)^10*(L15+$I$4)*N15/(1+M15)^10+$I$9-$I$10)/$I$11
A16: Max | B16: =MAX($O$2:$O$1001) | K16: =MAX(-0.05,NORMINV(RAND(),$C$6,$D$6)) | L16: =MAX(0.02,NORMINV(RAND(),$C$7,$D$7)) | M16: =MIN(0.16,MAX(0.05,NORMINV(RAND(),$C$8,$D$8))) | N16: =MIN(24,MAX(5,NORMINV(RAND(),$C$9,$D$9))) | O16: =$I$8*(SUMPRODUCT(($I$2*(1+K16)^{1;2;3;4;5;6;7;8;9;10})*(($I$3+(L16-$I$3)*{1;2;3;4;5;6;7;8;9;10}/10)*(1-$I$7)+$I$4-$I$4*($I$5+(1.05-$I$5)*{1;2;3;4;5;6;7;8;9;10}/10)-(K16/(1+K16))*$I$6)/(1+M16)^{1;2;3;4;5;6;7;8;9;10})+$I$2*(1+K16)^10*(L16+$I$4)*N16/(1+M16)^10+$I$9-$I$10)/$I$11
A17: Current price | B17: =Valuation!$B$2 | K17: =MAX(-0.05,NORMINV(RAND(),$C$6,$D$6)) | L17: =MAX(0.02,NORMINV(RAND(),$C$7,$D$7)) | M17: =MIN(0.16,MAX(0.05,NORMINV(RAND(),$C$8,$D$8))) | N17: =MIN(24,MAX(5,NORMINV(RAND(),$C$9,$D$9))) | O17: =$I$8*(SUMPRODUCT(($I$2*(1+K17)^{1;2;3;4;5;6;7;8;9;10})*(($I$3+(L17-$I$3)*{1;2;3;4;5;6;7;8;9;10}/10)*(1-$I$7)+$I$4-$I$4*($I$5+(1.05-$I$5)*{1;2;3;4;5;6;7;8;9;10}/10)-(K17/(1+K17))*$I$6)/(1+M17)^{1;2;3;4;5;6;7;8;9;10})+$I$2*(1+K17)^10*(L17+$I$4)*N17/(1+M17)^10+$I$9-$I$10)/$I$11
A18: Base case (full model) | B18: =Valuation!B36 | K18: =MAX(-0.05,NORMINV(RAND(),$C$6,$D$6)) | L18: =MAX(0.02,NORMINV(RAND(),$C$7,$D$7)) | M18: =MIN(0.16,MAX(0.05,NORMINV(RAND(),$C$8,$D$8))) | N18: =MIN(24,MAX(5,NORMINV(RAND(),$C$9,$D$9))) | O18: =$I$8*(SUMPRODUCT(($I$2*(1+K18)^{1;2;3;4;5;6;7;8;9;10})*(($I$3+(L18-$I$3)*{1;2;3;4;5;6;7;8;9;10}/10)*(1-$I$7)+$I$4-$I$4*($I$5+(1.05-$I$5)*{1;2;3;4;5;6;7;8;9;10}/10)-(K18/(1+K18))*$I$6)/(1+M18)^{1;2;3;4;5;6;7;8;9;10})+$I$2*(1+K18)^10*(L18+$I$4)*N18/(1+M18)^10+$I$9-$I$10)/$I$11
K19: =MAX(-0.05,NORMINV(RAND(),$C$6,$D$6)) | L19: =MAX(0.02,NORMINV(RAND(),$C$7,$D$7)) | M19: =MIN(0.16,MAX(0.05,NORMINV(RAND(),$C$8,$D$8))) | N19: =MIN(24,MAX(5,NORMINV(RAND(),$C$9,$D$9))) | O19: =$I$8*(SUMPRODUCT(($I$2*(1+K19)^{1;2;3;4;5;6;7;8;9;10})*(($I$3+(L19-$I$3)*{1;2;3;4;5;6;7;8;9;10}/10)*(1-$I$7)+$I$4-$I$4*($I$5+(1.05-$I$5)*{1;2;3;4;5;6;7;8;9;10}/10)-(K19/(1+K19))*$I$6)/(1+M19)^{1;2;3;4;5;6;7;8;9;10})+$I$2*(1+K19)^10*(L19+$I$4)*N19/(1+M19)^10+$I$9-$I$10)/$I$11
A20: P(undervalued at current price) | B20: =COUNTIF($O$2:$O$1001,">"&Valuation!$B$2)/1000 | K20: =MAX(-0.05,NORMINV(RAND(),$C$6,$D$6)) | L20: =MAX(0.02,NORMINV(RAND(),$C$7,$D$7)) | M20: =MIN(0.16,MAX(0.05,NORMINV(RAND(),$C$8,$D$8))) | N20: =MIN(24,MAX(5,NORMINV(RAND(),$C$9,$D$9))) | O20: =$I$8*(SUMPRODUCT(($I$2*(1+K20)^{1;2;3;4;5;6;7;8;9;10})*(($I$3+(L20-$I$3)*{1;2;3;4;5;6;7;8;9;10}/10)*(1-$I$7)+$I$4-$I$4*($I$5+(1.05-$I$5)*{1;2;3;4;5;6;7;8;9;10}/10)-(K20/(1+K20))*$I$6)/(1+M20)^{1;2;3;4;5;6;7;8;9;10})+$I$2*(1+K20)^10*(L20+$I$4)*N20/(1+M20)^10+$I$9-$I$10)/$I$11
A21: P(>20% upside) | B21: =COUNTIF($O$2:$O$1001,">"&Valuation!$B$2*1.2)/1000 | K21: =MAX(-0.05,NORMINV(RAND(),$C$6,$D$6)) | L21: =MAX(0.02,NORMINV(RAND(),$C$7,$D$7)) | M21: =MIN(0.16,MAX(0.05,NORMINV(RAND(),$C$8,$D$8))) | N21: =MIN(24,MAX(5,NORMINV(RAND(),$C$9,$D$9))) | O21: =$I$8*(SUMPRODUCT(($I$2*(1+K21)^{1;2;3;4;5;6;7;8;9;10})*(($I$3+(L21-$I$3)*{1;2;3;4;5;6;7;8;9;10}/10)*(1-$I$7)+$I$4-$I$4*($I$5+(1.05-$I$5)*{1;2;3;4;5;6;7;8;9;10}/10)-(K21/(1+K21))*$I$6)/(1+M21)^{1;2;3;4;5;6;7;8;9;10})+$I$2*(1+K21)^10*(L21+$I$4)*N21/(1+M21)^10+$I$9-$I$10)/$I$11
K22: =MAX(-0.05,NORMINV(RAND(),$C$6,$D$6)) | L22: =MAX(0.02,NORMINV(RAND(),$C$7,$D$7)) | M22: =MIN(0.16,MAX(0.05,NORMINV(RAND(),$C$8,$D$8))) | N22: =MIN(24,MAX(5,NORMINV(RAND(),$C$9,$D$9))) | O22: =$I$8*(SUMPRODUCT(($I$2*(1+K22)^{1;2;3;4;5;6;7;8;9;10})*(($I$3+(L22-$I$3)*{1;2;3;4;5;6;7;8;9;10}/10)*(1-$I$7)+$I$4-$I$4*($I$5+(1.05-$I$5)*{1;2;3;4;5;6;7;8;9;10}/10)-(K22/(1+K22))*$I$6)/(1+M22)^{1;2;3;4;5;6;7;8;9;10})+$I$2*(1+K22)^10*(L22+$I$4)*N22/(1+M22)^10+$I$9-$I$10)/$I$11
A23: PERCENTILES (live) | K23: =MAX(-0.05,NORMINV(RAND(),$C$6,$D$6)) | L23: =MAX(0.02,NORMINV(RAND(),$C$7,$D$7)) | M23: =MIN(0.16,MAX(0.05,NORMINV(RAND(),$C$8,$D$8))) | N23: =MIN(24,MAX(5,NORMINV(RAND(),$C$9,$D$9))) | O23: =$I$8*(SUMPRODUCT(($I$2*(1+K23)^{1;2;3;4;5;6;7;8;9;10})*(($I$3+(L23-$I$3)*{1;2;3;4;5;6;7;8;9;10}/10)*(1-$I$7)+$I$4-$I$4*($I$5+(1.05-$I$5)*{1;2;3;4;5;6;7;8;9;10}/10)-(K23/(1+K23))*$I$6)/(1+M23)^{1;2;3;4;5;6;7;8;9;10})+$I$2*(1+K23)^10*(L23+$I$4)*N23/(1+M23)^10+$I$9-$I$10)/$I$11
A24: P5 | B24: =PERCENTILE($O$2:$O$1001,0.05) | K24: =MAX(-0.05,NORMINV(RAND(),$C$6,$D$6)) | L24: =MAX(0.02,NORMINV(RAND(),$C$7,$D$7)) | M24: =MIN(0.16,MAX(0.05,NORMINV(RAND(),$C$8,$D$8))) | N24: =MIN(24,MAX(5,NORMINV(RAND(),$C$9,$D$9))) | O24: =$I$8*(SUMPRODUCT(($I$2*(1+K24)^{1;2;3;4;5;6;7;8;9;10})*(($I$3+(L24-$I$3)*{1;2;3;4;5;6;7;8;9;10}/10)*(1-$I$7)+$I$4-$I$4*($I$5+(1.05-$I$5)*{1;2;3;4;5;6;7;8;9;10}/10)-(K24/(1+K24))*$I$6)/(1+M24)^{1;2;3;4;5;6;7;8;9;10})+$I$2*(1+K24)^10*(L24+$I$4)*N24/(1+M24)^10+$I$9-$I$10)/$I$11
A25: P10 | B25: =PERCENTILE($O$2:$O$1001,0.1) | K25: =MAX(-0.05,NORMINV(RAND(),$C$6,$D$6)) | L25: =MAX(0.02,NORMINV(RAND(),$C$7,$D$7)) | M25: =MIN(0.16,MAX(0.05,NORMINV(RAND(),$C$8,$D$8))) | N25: =MIN(24,MAX(5,NORMINV(RAND(),$C$9,$D$9))) | O25: =$I$8*(SUMPRODUCT(($I$2*(1+K25)^{1;2;3;4;5;6;7;8;9;10})*(($I$3+(L25-$I$3)*{1;2;3;4;5;6;7;8;9;10}/10)*(1-$I$7)+$I$4-$I$4*($I$5+(1.05-$I$5)*{1;2;3;4;5;6;7;8;9;10}/10)-(K25/(1+K25))*$I$6)/(1+M25)^{1;2;3;4;5;6;7;8;9;10})+$I$2*(1+K25)^10*(L25+$I$4)*N25/(1+M25)^10+$I$9-$I$10)/$I$11
A26: P25 | B26: =PERCENTILE($O$2:$O$1001,0.25) | K26: =MAX(-0.05,NORMINV(RAND(),$C$6,$D$6)) | L26: =MAX(0.02,NORMINV(RAND(),$C$7,$D$7)) | M26: =MIN(0.16,MAX(0.05,NORMINV(RAND(),$C$8,$D$8))) | N26: =MIN(24,MAX(5,NORMINV(RAND(),$C$9,$D$9))) | O26: =$I$8*(SUMPRODUCT(($I$2*(1+K26)^{1;2;3;4;5;6;7;8;9;10})*(($I$3+(L26-$I$3)*{1;2;3;4;5;6;7;8;9;10}/10)*(1-$I$7)+$I$4-$I$4*($I$5+(1.05-$I$5)*{1;2;3;4;5;6;7;8;9;10}/10)-(K26/(1+K26))*$I$6)/(1+M26)^{1;2;3;4;5;6;7;8;9;10})+$I$2*(1+K26)^10*(L26+$I$4)*N26/(1+M26)^10+$I$9-$I$10)/$I$11
A27: P50 | B27: =PERCENTILE($O$2:$O$1001,0.5) | K27: =MAX(-0.05,NORMINV(RAND(),$C$6,$D$6)) | L27: =MAX(0.02,NORMINV(RAND(),$C$7,$D$7)) | M27: =MIN(0.16,MAX(0.05,NORMINV(RAND(),$C$8,$D$8))) | N27: =MIN(24,MAX(5,NORMINV(RAND(),$C$9,$D$9))) | O27: =$I$8*(SUMPRODUCT(($I$2*(1+K27)^{1;2;3;4;5;6;7;8;9;10})*(($I$3+(L27-$I$3)*{1;2;3;4;5;6;7;8;9;10}/10)*(1-$I$7)+$I$4-$I$4*($I$5+(1.05-$I$5)*{1;2;3;4;5;6;7;8;9;10}/10)-(K27/(1+K27))*$I$6)/(1+M27)^{1;2;3;4;5;6;7;8;9;10})+$I$2*(1+K27)^10*(L27+$I$4)*N27/(1+M27)^10+$I$9-$I$10)/$I$11
A28: P75 | B28: =PERCENTILE($O$2:$O$1001,0.75) | K28: =MAX(-0.05,NORMINV(RAND(),$C$6,$D$6)) | L28: =MAX(0.02,NORMINV(RAND(),$C$7,$D$7)) | M28: =MIN(0.16,MAX(0.05,NORMINV(RAND(),$C$8,$D$8))) | N28: =MIN(24,MAX(5,NORMINV(RAND(),$C$9,$D$9))) | O28: =$I$8*(SUMPRODUCT(($I$2*(1+K28)^{1;2;3;4;5;6;7;8;9;10})*(($I$3+(L28-$I$3)*{1;2;3;4;5;6;7;8;9;10}/10)*(1-$I$7)+$I$4-$I$4*($I$5+(1.05-$I$5)*{1;2;3;4;5;6;7;8;9;10}/10)-(K28/(1+K28))*$I$6)/(1+M28)^{1;2;3;4;5;6;7;8;9;10})+$I$2*(1+K28)^10*(L28+$I$4)*N28/(1+M28)^10+$I$9-$I$10)/$I$11
A29: P90 | B29: =PERCENTILE($O$2:$O$1001,0.9) | K29: =MAX(-0.05,NORMINV(RAND(),$C$6,$D$6)) | L29: =MAX(0.02,NORMINV(RAND(),$C$7,$D$7)) | M29: =MIN(0.16,MAX(0.05,NORMINV(RAND(),$C$8,$D$8))) | N29: =MIN(24,MAX(5,NORMINV(RAND(),$C$9,$D$9))) | O29: =$I$8*(SUMPRODUCT(($I$2*(1+K29)^{1;2;3;4;5;6;7;8;9;10})*(($I$3+(L29-$I$3)*{1;2;3;4;5;6;7;8;9;10}/10)*(1-$I$7)+$I$4-$I$4*($I$5+(1.05-$I$5)*{1;2;3;4;5;6;7;8;9;10}/10)-(K29/(1+K29))*$I$6)/(1+M29)^{1;2;3;4;5;6;7;8;9;10})+$I$2*(1+K29)^10*(L29+$I$4)*N29/(1+M29)^10+$I$9-$I$10)/$I$11
A30: P95 | B30: =PERCENTILE($O$2:$O$1001,0.95) | K30: =MAX(-0.05,NORMINV(RAND(),$C$6,$D$6)) | L30: =MAX(0.02,NORMINV(RAND(),$C$7,$D$7)) | M30: =MIN(0.16,MAX(0.05,NORMINV(RAND(),$C$8,$D$8))) | N30: =MIN(24,MAX(5,NORMINV(RAND(),$C$9,$D$9))) | O30: =$I$8*(SUMPRODUCT(($I$2*(1+K30)^{1;2;3;4;5;6;7;8;9;10})*(($I$3+(L30-$I$3)*{1;2;3;4;5;6;7;8;9;10}/10)*(1-$I$7)+$I$4-$I$4*($I$5+(1.05-$I$5)*{1;2;3;4;5;6;7;8;9;10}/10)-(K30/(1+K30))*$I$6)/(1+M30)^{1;2;3;4;5;6;7;8;9;10})+$I$2*(1+K30)^10*(L30+$I$4)*N30/(1+M30)^10+$I$9-$I$10)/$I$11
K31: =MAX(-0.05,NORMINV(RAND(),$C$6,$D$6)) | L31: =MAX(0.02,NORMINV(RAND(),$C$7,$D$7)) | M31: =MIN(0.16,MAX(0.05,NORMINV(RAND(),$C$8,$D$8))) | N31: =MIN(24,MAX(5,NORMINV(RAND(),$C$9,$D$9))) | O31: =$I$8*(SUMPRODUCT(($I$2*(1+K31)^{1;2;3;4;5;6;7;8;9;10})*(($I$3+(L31-$I$3)*{1;2;3;4;5;6;7;8;9;10}/10)*(1-$I$7)+$I$4-$I$4*($I$5+(1.05-$I$5)*{1;2;3;4;5;6;7;8;9;10}/10)-(K31/(1+K31))*$I$6)/(1+M31)^{1;2;3;4;5;6;7;8;9;10})+$I$2*(1+K31)^10*(L31+$I$4)*N31/(1+M31)^10+$I$9-$I$10)/$I$11
A32: VALUE DISTRIBUTION (live histogram) | K32: =MAX(-0.05,NORMINV(RAND(),$C$6,$D$6)) | L32: =MAX(0.02,NORMINV(RAND(),$C$7,$D$7)) | M32: =MIN(0.16,MAX(0.05,NORMINV(RAND(),$C$8,$D$8))) | N32: =MIN(24,MAX(5,NORMINV(RAND(),$C$9,$D$9))) | O32: =$I$8*(SUMPRODUCT(($I$2*(1+K32)^{1;2;3;4;5;6;7;8;9;10})*(($I$3+(L32-$I$3)*{1;2;3;4;5;6;7;8;9;10}/10)*(1-$I$7)+$I$4-$I$4*($I$5+(1.05-$I$5)*{1;2;3;4;5;6;7;8;9;10}/10)-(K32/(1+K32))*$I$6)/(1+M32)^{1;2;3;4;5;6;7;8;9;10})+$I$2*(1+K32)^10*(L32+$I$4)*N32/(1+M32)^10+$I$9-$I$10)/$I$11
A33: Bin midpoint ($/sh) | B33: Count | K33: =MAX(-0.05,NORMINV(RAND(),$C$6,$D$6)) | L33: =MAX(0.02,NORMINV(RAND(),$C$7,$D$7)) | M33: =MIN(0.16,MAX(0.05,NORMINV(RAND(),$C$8,$D$8))) | N33: =MIN(24,MAX(5,NORMINV(RAND(),$C$9,$D$9))) | O33: =$I$8*(SUMPRODUCT(($I$2*(1+K33)^{1;2;3;4;5;6;7;8;9;10})*(($I$3+(L33-$I$3)*{1;2;3;4;5;6;7;8;9;10}/10)*(1-$I$7)+$I$4-$I$4*($I$5+(1.05-$I$5)*{1;2;3;4;5;6;7;8;9;10}/10)-(K33/(1+K33))*$I$6)/(1+M33)^{1;2;3;4;5;6;7;8;9;10})+$I$2*(1+K33)^10*(L33+$I$4)*N33/(1+M33)^10+$I$9-$I$10)/$I$11
A34: =$B$15+0.5*($B$16-$B$15)/15 | B34: =COUNTIFS($O$2:$O$1001,">="&($B$15+0*($B$16-$B$15)/15),$O$2:$O$1001,"<"&($B$15+1*($B$16-$B$15)/15)) | K34: =MAX(-0.05,NORMINV(RAND(),$C$6,$D$6)) | L34: =MAX(0.02,NORMINV(RAND(),$C$7,$D$7)) | M34: =MIN(0.16,MAX(0.05,NORMINV(RAND(),$C$8,$D$8))) | N34: =MIN(24,MAX(5,NORMINV(RAND(),$C$9,$D$9))) | O34: =$I$8*(SUMPRODUCT(($I$2*(1+K34)^{1;2;3;4;5;6;7;8;9;10})*(($I$3+(L34-$I$3)*{1;2;3;4;5;6;7;8;9;10}/10)*(1-$I$7)+$I$4-$I$4*($I$5+(1.05-$I$5)*{1;2;3;4;5;6;7;8;9;10}/10)-(K34/(1+K34))*$I$6)/(1+M34)^{1;2;3;4;5;6;7;8;9;10})+$I$2*(1+K34)^10*(L34+$I$4)*N34/(1+M34)^10+$I$9-$I$10)/$I$11
A35: =$B$15+1.5*($B$16-$B$15)/15 | B35: =COUNTIFS($O$2:$O$1001,">="&($B$15+1*($B$16-$B$15)/15),$O$2:$O$1001,"<"&($B$15+2*($B$16-$B$15)/15)) | K35: =MAX(-0.05,NORMINV(RAND(),$C$6,$D$6)) | L35: =MAX(0.02,NORMINV(RAND(),$C$7,$D$7)) | M35: =MIN(0.16,MAX(0.05,NORMINV(RAND(),$C$8,$D$8))) | N35: =MIN(24,MAX(5,NORMINV(RAND(),$C$9,$D$9))) | O35: =$I$8*(SUMPRODUCT(($I$2*(1+K35)^{1;2;3;4;5;6;7;8;9;10})*(($I$3+(L35-$I$3)*{1;2;3;4;5;6;7;8;9;10}/10)*(1-$I$7)+$I$4-$I$4*($I$5+(1.05-$I$5)*{1;2;3;4;5;6;7;8;9;10}/10)-(K35/(1+K35))*$I$6)/(1+M35)^{1;2;3;4;5;6;7;8;9;10})+$I$2*(1+K35)^10*(L35+$I$4)*N35/(1+M35)^10+$I$9-$I$10)/$I$11
A36: =$B$15+2.5*($B$16-$B$15)/15 | B36: =COUNTIFS($O$2:$O$1001,">="&($B$15+2*($B$16-$B$15)/15),$O$2:$O$1001,"<"&($B$15+3*($B$16-$B$15)/15)) | K36: =MAX(-0.05,NORMINV(RAND(),$C$6,$D$6)) | L36: =MAX(0.02,NORMINV(RAND(),$C$7,$D$7)) | M36: =MIN(0.16,MAX(0.05,NORMINV(RAND(),$C$8,$D$8))) | N36: =MIN(24,MAX(5,NORMINV(RAND(),$C$9,$D$9))) | O36: =$I$8*(SUMPRODUCT(($I$2*(1+K36)^{1;2;3;4;5;6;7;8;9;10})*(($I$3+(L36-$I$3)*{1;2;3;4;5;6;7;8;9;10}/10)*(1-$I$7)+$I$4-$I$4*($I$5+(1.05-$I$5)*{1;2;3;4;5;6;7;8;9;10}/10)-(K36/(1+K36))*$I$6)/(1+M36)^{1;2;3;4;5;6;7;8;9;10})+$I$2*(1+K36)^10*(L36+$I$4)*N36/(1+M36)^10+$I$9-$I$10)/$I$11
A37: =$B$15+3.5*($B$16-$B$15)/15 | B37: =COUNTIFS($O$2:$O$1001,">="&($B$15+3*($B$16-$B$15)/15),$O$2:$O$1001,"<"&($B$15+4*($B$16-$B$15)/15)) | K37: =MAX(-0.05,NORMINV(RAND(),$C$6,$D$6)) | L37: =MAX(0.02,NORMINV(RAND(),$C$7,$D$7)) | M37: =MIN(0.16,MAX(0.05,NORMINV(RAND(),$C$8,$D$8))) | N37: =MIN(24,MAX(5,NORMINV(RAND(),$C$9,$D$9))) | O37: =$I$8*(SUMPRODUCT(($I$2*(1+K37)^{1;2;3;4;5;6;7;8;9;10})*(($I$3+(L37-$I$3)*{1;2;3;4;5;6;7;8;9;10}/10)*(1-$I$7)+$I$4-$I$4*($I$5+(1.05-$I$5)*{1;2;3;4;5;6;7;8;9;10}/10)-(K37/(1+K37))*$I$6)/(1+M37)^{1;2;3;4;5;6;7;8;9;10})+$I$2*(1+K37)^10*(L37+$I$4)*N37/(1+M37)^10+$I$9-$I$10)/$I$11
A38: =$B$15+4.5*($B$16-$B$15)/15 | B38: =COUNTIFS($O$2:$O$1001,">="&($B$15+4*($B$16-$B$15)/15),$O$2:$O$1001,"<"&($B$15+5*($B$16-$B$15)/15)) | K38: =MAX(-0.05,NORMINV(RAND(),$C$6,$D$6)) | L38: =MAX(0.02,NORMINV(RAND(),$C$7,$D$7)) | M38: =MIN(0.16,MAX(0.05,NORMINV(RAND(),$C$8,$D$8))) | N38: =MIN(24,MAX(5,NORMINV(RAND(),$C$9,$D$9))) | O38: =$I$8*(SUMPRODUCT(($I$2*(1+K38)^{1;2;3;4;5;6;7;8;9;10})*(($I$3+(L38-$I$3)*{1;2;3;4;5;6;7;8;9;10}/10)*(1-$I$7)+$I$4-$I$4*($I$5+(1.05-$I$5)*{1;2;3;4;5;6;7;8;9;10}/10)-(K38/(1+K38))*$I$6)/(1+M38)^{1;2;3;4;5;6;7;8;9;10})+$I$2*(1+K38)^10*(L38+$I$4)*N38/(1+M38)^10+$I$9-$I$10)/$I$11
A39: =$B$15+5.5*($B$16-$B$15)/15 | B39: =COUNTIFS($O$2:$O$1001,">="&($B$15+5*($B$16-$B$15)/15),$O$2:$O$1001,"<"&($B$15+6*($B$16-$B$15)/15)) | K39: =MAX(-0.05,NORMINV(RAND(),$C$6,$D$6)) | L39: =MAX(0.02,NORMINV(RAND(),$C$7,$D$7)) | M39: =MIN(0.16,MAX(0.05,NORMINV(RAND(),$C$8,$D$8))) | N39: =MIN(24,MAX(5,NORMINV(RAND(),$C$9,$D$9))) | O39: =$I$8*(SUMPRODUCT(($I$2*(1+K39)^{1;2;3;4;5;6;7;8;9;10})*(($I$3+(L39-$I$3)*{1;2;3;4;5;6;7;8;9;10}/10)*(1-$I$7)+$I$4-$I$4*($I$5+(1.05-$I$5)*{1;2;3;4;5;6;7;8;9;10}/10)-(K39/(1+K39))*$I$6)/(1+M39)^{1;2;3;4;5;6;7;8;9;10})+$I$2*(1+K39)^10*(L39+$I$4)*N39/(1+M39)^10+$I$9-$I$10)/$I$11
A40: =$B$15+6.5*($B$16-$B$15)/15 | B40: =COUNTIFS($O$2:$O$1001,">="&($B$15+6*($B$16-$B$15)/15),$O$2:$O$1001,"<"&($B$15+7*($B$16-$B$15)/15)) | K40: =MAX(-0.05,NORMINV(RAND(),$C$6,$D$6)) | L40: =MAX(0.02,NORMINV(RAND(),$C$7,$D$7)) | M40: =MIN(0.16,MAX(0.05,NORMINV(RAND(),$C$8,$D$8))) | N40: =MIN(24,MAX(5,NORMINV(RAND(),$C$9,$D$9))) | O40: =$I$8*(SUMPRODUCT(($I$2*(1+K40)^{1;2;3;4;5;6;7;8;9;10})*(($I$3+(L40-$I$3)*{1;2;3;4;5;6;7;8;9;10}/10)*(1-$I$7)+$I$4-$I$4*($I$5+(1.05-$I$5)*{1;2;3;4;5;6;7;8;9;10}/10)-(K40/(1+K40))*$I$6)/(1+M40)^{1;2;3;4;5;6;7;8;9;10})+$I$2*(1+K40)^10*(L40+$I$4)*N40/(1+M40)^10+$I$9-$I$10)/$I$11
...
