Workbook

Sheet Cover
A1: QUALCOMM Incorporated (QCOM)
A2: DCF valuation — exit-multiple terminal · defaults anchored to consensus
A4: Last updated | B4: 2026-07-08
A5: Data pulled (FMP) | B5: Q2 2026
A6: Assumptions by | B6: Opus 4.8 — values as of 2026-07-05 (provenance seeded)
A8: VALUATION SUMMARY
A10: Fair value / share | B10: =Valuation!B36
A11: Current price | B11: =Valuation!$B$2
A12: Upside / (downside) | B12: =Valuation!B42
A13: Verdict | B13: =IF(Valuation!B36>Valuation!$B$2,"Undervalued","Overvalued")
A14: Monte Carlo P(undervalued) | B14: ='Monte Carlo'!B20
A15: KEY ASSUMPTIONS
A17: WACC (from WACC tab) | B17: =WACC!B15
A18: Terminal method | B18: =Valuation!$B$6
A19: Exit basis / multiple | B19: =Valuation!$B$7
A20: Exit multiple | B20: =Valuation!$B$8
A21: Terminal growth (g) | B21: =Valuation!$B$4
A22: Terminal weight | B22: =Valuation!B39
A23: Forecast horizon | B23: 10 years
A25: THE STORY (Opus)
A27: (Opus narrative)

Sheet Dashboard
A1: QUALCOMM Incorporated (QCOM) — Control Dashboard
A2: Edit the yellow cells; everything recomputes. Orange = a driver you've moved off consensus.
A4: VERDICT
A5: Fair value / share | B5: =Valuation!B36
A6: Current price | B6: =Dashboard!$B$48
A7: Upside / (downside) | B7: =Valuation!B42
A8: Verdict | B8: =IF(Valuation!B36>Dashboard!$B$48,"Undervalued","Overvalued")
A9: Monte Carlo P(undervalued) | B9: ='Monte Carlo'!B20
A11: GUARDRAIL SIGNALS (are my assumptions sane?)
A12: Signal | B12: Value | C12: Flag | D12: Healthy
A13: Terminal weight (% of EV) | B13: =Valuation!B39 | C13: =IF(Valuation!B39>0.9,"! high","ok") | D13: < 90%
A14: Implied g vs exit multiple | B14: =Valuation!B40 | C14: =IF(Valuation!B40>Dashboard!$B$46+0.02,"! rich","ok") | D14: near term g
A15: ROIC - WACC (2026) | B15: =IF(Model!F36<=0,"n/a (neg. capital)",Model!G38-WACC!B15) | C15: =IF(Model!F36<=0,"n/a",IF(Model!G38-WACC!B15<0,"! destroys","creates")) | D15: > 0
A16: Revenue vs consensus (2026) | B16: =Consensus!B6 | C16: =IF(ABS(Consensus!B6)>0.05,"! off-Street","on") | D16: +/- 5%
A17: MC P(undervalued) | B17: ='Monte Carlo'!B20 | C17: =IF('Monte Carlo'!B20<0.5,"! coin-flip","ok") | D17: context
A18: REVENUE DRIVERS — near-term & terminal growth per segment
A19: Segment | B19: Near-term | C19: Terminal | D19: Consensus | E19: Thesis claim
A20: QCT | B20: 0.075954763 | C20: 0.05 | D20: 0.075954763
A21: QTL | B21: -0.05235948 | C21: 0.05 | D21: -0.05235948
A28: PROFITABILITY & TAX
A29: Near-term operating margin | B29: 0.37873824 | D29: 0.37873824 | E29: consensus-implied; ramps to terminal
A30: Terminal operating margin | B30: 0.39433971 | E30: AI/ads mix + operating leverage
A31: Tax rate | B31: 0.24
A33: CAPITAL INTENSITY
A34: 2026 capex ($M) | B34: 1311.2 | D34: 1311.2 | E34: ~last-year capex +10%; set to guidance
A35: Terminal capex / D&A | B35: 1.05 | E35: converges to ~1.0x as build-out matures
A37: DISCOUNT RATE & TERMINAL
A38: Risk-free rate (10Y) | B38: 0.043
A39: Equity risk premium | B39: 0.045
A40: Beta (levered) | B40: 1.596 | E40: FMP raw beta; Damodaran bottom-up ~1.2
A41: Pre-tax cost of debt | B41: 0.045
A42: WACC (computed) | B42: =WACC!B15
A43: Terminal method | B43: Exit multiple
A44: Exit basis | B44: EV/EBITDA
A45: Exit multiple | B45: 12
A46: Terminal growth (g) | B46: 0.045
A47: Country risk premium | B47: 0.0066272154 | E47: Damodaran country premiums, revenue-weighted (2026-01); 0 for US/mature
A48: Current price | B48: 176.25
A49: Growth fade curvature | B49: 4 | E49: convexity of the near->terminal growth fade, fit to consensus (1.0=linear); higher = faster early deceleration
A50: SCENARIOS — Bull / Bear offsets vs Base (edit the yellow Δs)
...

Sheet Assumptions
A1: QCOM — Assumptions & Reasoning
A2: Provenance of every Dashboard input. Read-only — regenerated by each build/refresh. Current is a live link to the Dashboard; Source / Opus value / Note are as of the last refresh_dcf run.
A4: Assumptions baseline | B4: seeded 2026-07-05 from the synced assumptions block (pass predates provenance tracking — may already include your edits)
A6: DASHBOARD INPUTS — value · source · reasoning
A7: Input | B7: Cell | C7: Current | D7: Source | E7: Opus value | F7: Note
A8: QCT — near-term growth | B8: B20 | C8: =Dashboard!B20 | D8: Opus | E8: 7.6%
A9: QCT — terminal growth | B9: C20 | C9: =Dashboard!C20 | D9: Opus | E9: 5.0%
A10: QTL — near-term growth | B10: B21 | C10: =Dashboard!B21 | D10: Opus | E10: -5.2%
A11: QTL — terminal growth | B11: C21 | C11: =Dashboard!C21 | D11: Opus | E11: 5.0%
A12: Near-term operating margin | B12: B29 | C12: =Dashboard!B29 | D12: Opus | E12: 37.9%
A13: Terminal operating margin | B13: B30 | C13: =Dashboard!B30 | D13: Opus | E13: 39.4%
A14: Tax rate | B14: B31 | C14: =Dashboard!B31 | D14: Opus | E14: 24.0%
A15: Terminal capex / D&A | B15: B35 | C15: =Dashboard!B35 | D15: Opus | E15: 1.1x
A16: Risk-free rate (10Y) | B16: B38 | C16: =Dashboard!B38 | D16: workbook (synced) | E16: — | F16: no Opus pass — value synced from this workbook
A17: Equity risk premium | B17: B39 | C17: =Dashboard!B39 | D17: workbook (synced) | E17: — | F17: no Opus pass — value synced from this workbook
A18: Beta (levered) | B18: B40 | C18: =Dashboard!B40 | D18: Opus | E18: 1.596
A19: Pre-tax cost of debt | B19: B41 | C19: =Dashboard!B41 | D19: Opus | E19: 4.5%
A20: Terminal method | B20: B43 | C20: =Dashboard!B43 | D20: Opus | E20: Exit multiple
A21: Exit basis | B21: B44 | C21: =Dashboard!B44 | D21: Opus | E21: EV/EBITDA
A22: Exit multiple | B22: B45 | C22: =Dashboard!B45 | D22: Opus | E22: 12.0x
A23: Terminal growth (g) | B23: B46 | C23: =Dashboard!B46 | D23: Opus | E23: 4.5%
A24: 2026 capex ($M) | B24: B34 | C24: =Dashboard!B34 | D24: workbook (synced) | E24: — | F24: last-year capex +10% unless set to guidance; edits not tracked
A25: Bull Δ — segment growth, near-term | B25: C52 | C25: =Dashboard!C52 | D25: seed default | E25: 3.0%
A26: Bear Δ — segment growth, near-term | B26: D52 | C26: =Dashboard!D52 | D26: seed default | E26: -3.0%
A27: Bull Δ — segment growth, terminal | B27: C53 | C27: =Dashboard!C53 | D27: seed default | E27: 1.0%
A28: Bear Δ — segment growth, terminal | B28: D53 | C28: =Dashboard!D53 | D28: seed default | E28: -1.0%
A29: Bull Δ — operating margin, near-term | B29: C54 | C29: =Dashboard!C54 | D29: seed default | E29: 1.0%
A30: Bear Δ — operating margin, near-term | B30: D54 | C30: =Dashboard!D54 | D30: seed default | E30: -1.0%
A31: Bull Δ — operating margin, terminal | B31: C55 | C31: =Dashboard!C55 | D31: seed default | E31: 2.0%
A32: Bear Δ — operating margin, terminal | B32: D55 | C32: =Dashboard!D55 | D32: seed default | E32: -2.0%
A33: Bull Δ — exit multiple | B33: C56 | C33: =Dashboard!C56 | D33: seed default | E33: 2.0x
A34: Bear Δ — exit multiple | B34: D56 | C34: =Dashboard!D56 | D34: seed default | E34: -2.0x
A35: Bull Δ — terminal growth (g) | B35: C57 | C35: =Dashboard!C57 | D35: seed default | E35: 0.5%
A36: Bear Δ — terminal growth (g) | B36: D57 | C36: =Dashboard!D57 | D36: seed default | E36: -0.5%

Sheet Color Code
A1: Color | B1: Meaning
A2: Black | B2: Formula-driven (same-sheet)
A3: Blue | B3: Hard-coded actuals (from FMP filings)
A4: Yellow | B4: An assumption you can change — edit these to drive the model
A5: Green | B5: A formula that links to another sheet
A6: Orange | B6: (Dashboard) an assumption you've moved off consensus — your active bet
A7: How to use | B7: Edit yellow cells (Model assumptions, WACC drivers, Valuation toggles). Everything else recomputes.

Sheet WACC
A1: WACC Calculator
A2: Risk-free rate (10Y) | B2: =Dashboard!$B$38
A3: Equity risk premium | B3: =Dashboard!$B$39
A4: Beta (levered) | B4: =Dashboard!$B$40
A5: Country risk premium | B5: =Dashboard!$B$47
A6: Cost of equity (CAPM) | B6: =B2+B4*B3+B5
A7: Pre-tax cost of debt | B7: =Dashboard!$B$41
A8: Tax rate | B8: =Dashboard!$B$31
A9: After-tax cost of debt | B9: =B7*(1-B8)
A10: Market cap (E) | B10: =Dashboard!$B$48*Financials!AC17
A11: Total debt (D) | B11: =Financials!AC31
A12: Equity weight | B12: =B10/(B10+B11)
A13: Debt weight | B13: =B11/(B10+B11)
A15: WACC | B15: =B12*B6+B13*B9
A17: Yellow = edit. CAPM cost of equity (incl. country risk premium); market-value weights. Feeds Valuation!WACC.

Sheet Model
A1: $M unless noted | B1: FY2021A | C1: FY2022A | D1: FY2023A | E1: FY2024A | F1: FY2025A | G1: FY2026E | H1: FY2027E | I1: FY2028E | J1: FY2029E | K1: FY2030E | L1: FY2031E | M1: FY2032E | N1: FY2033E | O1: FY2034E | P1: FY2035E
A3: REVENUE BY SEGMENT (yellow = growth assumption; actuals link to Financials)
A4: QCT | B4: =SUM(Financials!H19:K19) | C4: =SUM(Financials!L19:O19) | D4: =SUM(Financials!P19:S19) | E4: =SUM(Financials!T19:W19) | F4: =SUM(Financials!X19:AA19) | G4: =F4*(1+G5) | H4: =G4*(1+H5) | I4: =H4*(1+I5) | J4: =I4*(1+J5) | K4: =J4*(1+K5) | L4: =K4*(1+L5) | M4: =L4*(1+M5) | N4: =M4*(1+N5) | ... P4: =O4*(1+P5)
A5: growth % (convex fade; curvature from Dashboard) | C5: =IFERROR(C4/B4-1,"") | D5: =IFERROR(D4/C4-1,"") | E5: =IFERROR(E4/D4-1,"") | F5: =IFERROR(F4/E4-1,"") | G5: =Dashboard!$C$20+(Dashboard!$B$20-Dashboard!$C$20)*((9-0)/9)^Dashboard!$B$49 | H5: =Dashboard!$C$20+(Dashboard!$B$20-Dashboard!$C$20)*((9-1)/9)^Dashboard!$B$49 | I5: =Dashboard!$C$20+(Dashboard!$B$20-Dashboard!$C$20)*((9-2)/9)^Dashboard!$B$49 | J5: =Dashboard!$C$20+(Dashboard!$B$20-Dashboard!$C$20)*((9-3)/9)^Dashboard!$B$49 | K5: =Dashboard!$C$20+(Dashboard!$B$20-Dashboard!$C$20)*((9-4)/9)^Dashboard!$B$49 | L5: =Dashboard!$C$20+(Dashboard!$B$20-Dashboard!$C$20)*((9-5)/9)^Dashboard!$B$49 | M5: =Dashboard!$C$20+(Dashboard!$B$20-Dashboard!$C$20)*((9-6)/9)^Dashboard!$B$49 | N5: =Dashboard!$C$20+(Dashboard!$B$20-Dashboard!$C$20)*((9-7)/9)^Dashboard!$B$49 | O5: =Dashboard!$C$20+(Dashboard!$B$20-Dashboard!$C$20)*((9-8)/9)^Dashboard!$B$49 | P5: =Dashboard!$C$20+(Dashboard!$B$20-Dashboard!$C$20)*((9-9)/9)^Dashboard!$B$49
A6: QTL | B6: =SUM(Financials!H22:K22) | C6: =SUM(Financials!L22:O22) | D6: =SUM(Financials!P22:S22) | E6: =SUM(Financials!T22:W22) | F6: =SUM(Financials!X22:AA22) | G6: =F6*(1+G7) | H6: =G6*(1+H7) | I6: =H6*(1+I7) | J6: =I6*(1+J7) | K6: =J6*(1+K7) | L6: =K6*(1+L7) | M6: =L6*(1+M7) | N6: =M6*(1+N7) | ... P6: =O6*(1+P7)
A7: growth % (convex fade; curvature from Dashboard) | C7: =IFERROR(C6/B6-1,"") | D7: =IFERROR(D6/C6-1,"") | E7: =IFERROR(E6/D6-1,"") | F7: =IFERROR(F6/E6-1,"") | G7: =Dashboard!$C$21+(Dashboard!$B$21-Dashboard!$C$21)*((9-0)/9)^Dashboard!$B$49 | H7: =Dashboard!$C$21+(Dashboard!$B$21-Dashboard!$C$21)*((9-1)/9)^Dashboard!$B$49 | I7: =Dashboard!$C$21+(Dashboard!$B$21-Dashboard!$C$21)*((9-2)/9)^Dashboard!$B$49 | J7: =Dashboard!$C$21+(Dashboard!$B$21-Dashboard!$C$21)*((9-3)/9)^Dashboard!$B$49 | K7: =Dashboard!$C$21+(Dashboard!$B$21-Dashboard!$C$21)*((9-4)/9)^Dashboard!$B$49 | L7: =Dashboard!$C$21+(Dashboard!$B$21-Dashboard!$C$21)*((9-5)/9)^Dashboard!$B$49 | M7: =Dashboard!$C$21+(Dashboard!$B$21-Dashboard!$C$21)*((9-6)/9)^Dashboard!$B$49 | N7: =Dashboard!$C$21+(Dashboard!$B$21-Dashboard!$C$21)*((9-7)/9)^Dashboard!$B$49 | O7: =Dashboard!$C$21+(Dashboard!$B$21-Dashboard!$C$21)*((9-8)/9)^Dashboard!$B$49 | P7: =Dashboard!$C$21+(Dashboard!$B$21-Dashboard!$C$21)*((9-9)/9)^Dashboard!$B$49
A8: Total revenue | B8: =B4+B6 | C8: =C4+C6 | D8: =D4+D6 | E8: =E4+E6 | F8: =F4+F6 | G8: =G4+G6 | H8: =H4+H6 | I8: =I4+I6 | ... P8: =P4+P6
A9: growth % | C9: =IFERROR(C8/B8-1,"") | D9: =IFERROR(D8/C8-1,"") | E9: =IFERROR(E8/D8-1,"") | F9: =IFERROR(F8/E8-1,"") | G9: =IFERROR(G8/F8-1,"") | H9: =IFERROR(H8/G8-1,"") | I9: =IFERROR(I8/H8-1,"") | J9: =IFERROR(J8/I8-1,"") | ... P9: =IFERROR(P8/O8-1,"")
A11: COST STRUCTURE (yellow = % of revenue)
A12: Cost of revenue | B12: =SUM(Financials!H5:K5) | C12: =SUM(Financials!L5:O5) | D12: =SUM(Financials!P5:S5) | E12: =SUM(Financials!T5:W5) | F12: =SUM(Financials!X5:AA5) | G12: =G8*G13 | H12: =H8*H13 | I12: =I8*I13 | J12: =J8*J13 | K12: =K8*K13 | L12: =L8*L13 | M12: =M8*M13 | N12: =N8*N13 | ... P12: =P8*P13
A13: % of revenue | B13: =IFERROR(B12/B8,"") | C13: =IFERROR(C12/C8,"") | D13: =IFERROR(D12/D8,"") | E13: =IFERROR(E12/E8,"") | F13: =IFERROR(F12/F8,"") | G13: 0.44571403 | H13: 0.44571403 | I13: 0.44571403 | J13: 0.44571403 | K13: 0.44571403 | L13: 0.44571403 | M13: 0.44571403 | N13: 0.44571403 | O13: 0.44571403 | P13: 0.44571403
A14: R&D / Technology | B14: =SUM(Financials!H7:K7) | C14: =SUM(Financials!L7:O7) | D14: =SUM(Financials!P7:S7) | E14: =SUM(Financials!T7:W7) | F14: =SUM(Financials!X7:AA7) | G14: =G8*G15 | H14: =H8*H15 | I14: =I8*I15 | J14: =J8*J15 | K14: =K8*K15 | L14: =L8*L15 | M14: =M8*M15 | N14: =N8*N15 | ... P14: =P8*P15
A15: % of revenue | B15: =IFERROR(B14/B8,"") | C15: =IFERROR(C14/C8,"") | D15: =IFERROR(D14/D8,"") | E15: =IFERROR(E14/E8,"") | F15: =IFERROR(F14/F8,"") | G15: 0.2041821 | H15: 0.2041821 | I15: 0.2041821 | J15: 0.2041821 | K15: 0.2041821 | L15: 0.2041821 | M15: 0.2041821 | N15: 0.2041821 | O15: 0.2041821 | P15: 0.2041821
A16: SG&A | B16: =SUM(Financials!H9:K9) | C16: =SUM(Financials!L9:O9) | D16: =SUM(Financials!P9:S9) | E16: =SUM(Financials!T9:W9) | F16: =SUM(Financials!X9:AA9) | G16: =G8*G17 | H16: =H8*H17 | I16: =I8*I17 | J16: =J8*J17 | K16: =K8*K17 | L16: =L8*L17 | M16: =M8*M17 | N16: =N8*N17 | ... P16: =P8*P17
A17: % of revenue | B17: =IFERROR(B16/B8,"") | C17: =IFERROR(C16/C8,"") | D17: =IFERROR(D16/D8,"") | E17: =IFERROR(E16/E8,"") | F17: =IFERROR(F16/F8,"") | G17: 0.070228525 | H17: 0.070228525 | I17: 0.070228525 | J17: 0.070228525 | K17: 0.070228525 | L17: 0.070228525 | M17: 0.070228525 | N17: 0.070228525 | O17: 0.070228525 | P17: 0.070228525
A18: Other opex (fulfilment, etc.) | B18: =B8-(B12+B14+B16)-SUM(Financials!H13:K13) | C18: =C8-(C12+C14+C16)-SUM(Financials!L13:O13) | D18: =D8-(D12+D14+D16)-SUM(Financials!P13:S13) | E18: =E8-(E12+E14+E16)-SUM(Financials!T13:W13) | F18: =F8-(F12+F14+F16)-SUM(Financials!X13:AA13) | G18: =G8*(1-(Dashboard!$B$29+(Dashboard!$B$30-Dashboard!$B$29)*MIN(1,0/3)))-(G12+G14+G16) | H18: =H8*(1-(Dashboard!$B$29+(Dashboard!$B$30-Dashboard!$B$29)*MIN(1,1/3)))-(H12+H14+H16) | I18: =I8*(1-(Dashboard!$B$29+(Dashboard!$B$30-Dashboard!$B$29)*MIN(1,2/3)))-(I12+I14+I16) | J18: =J8*(1-(Dashboard!$B$29+(Dashboard!$B$30-Dashboard!$B$29)*MIN(1,3/3)))-(J12+J14+J16) | K18: =K8*(1-(Dashboard!$B$29+(Dashboard!$B$30-Dashboard!$B$29)*MIN(1,4/3)))-(K12+K14+K16) | L18: =L8*(1-(Dashboard!$B$29+(Dashboard!$B$30-Dashboard!$B$29)*MIN(1,5/3)))-(L12+L14+L16) | M18: =M8*(1-(Dashboard!$B$29+(Dashboard!$B$30-Dashboard!$B$29)*MIN(1,6/3)))-(M12+M14+M16) | N18: =N8*(1-(Dashboard!$B$29+(Dashboard!$B$30-Dashboard!$B$29)*MIN(1,7/3)))-(N12+N14+N16) | O18: =O8*(1-(Dashboard!$B$29+(Dashboard!$B$30-Dashboard!$B$29)*MIN(1,8/3)))-(O12+O14+O16) | P18: =P8*(1-(Dashboard!$B$29+(Dashboard!$B$30-Dashboard!$B$29)*MIN(1,9/3)))-(P12+P14+P16)
A19: % of revenue | B19: =IFERROR(B18/B8,"") | C19: =IFERROR(C18/C8,"") | D19: =IFERROR(D18/D8,"") | E19: =IFERROR(E18/E8,"") | F19: =IFERROR(F18/F8,"") | G19: =IFERROR(G18/G8,"") | H19: =IFERROR(H18/H8,"") | I19: =IFERROR(I18/I8,"") | ... P19: =IFERROR(P18/P8,"")
A21: Operating income (EBIT) | B21: =B8-(B12+B14+B16)-B18 | C21: =C8-(C12+C14+C16)-C18 | D21: =D8-(D12+D14+D16)-D18 | E21: =E8-(E12+E14+E16)-E18 | F21: =F8-(F12+F14+F16)-F18 | G21: =G8-(G12+G14+G16)-G18 | H21: =H8-(H12+H14+H16)-H18 | I21: =I8-(I12+I14+I16)-I18 | ... P21: =P8-(P12+P14+P16)-P18
A22: operating margin | B22: =IFERROR(B21/B8,"") | C22: =IFERROR(C21/C8,"") | D22: =IFERROR(D21/D8,"") | E22: =IFERROR(E21/E8,"") | F22: =IFERROR(F21/F8,"") | G22: =IFERROR(G21/G8,"") | H22: =IFERROR(H21/H8,"") | I22: =IFERROR(I21/I8,"") | ... P22: =IFERROR(P21/P8,"")
A24: FCF BRIDGE (NOPAT + D&A + SBC - dNWC - Capex)
A25: NOPAT = EBIT x (1 - tax) | B25: =B21*(1-Valuation!$B$5) | C25: =C21*(1-Valuation!$B$5) | D25: =D21*(1-Valuation!$B$5) | E25: =E21*(1-Valuation!$B$5) | F25: =F21*(1-Valuation!$B$5) | G25: =G21*(1-Valuation!$B$5) | H25: =H21*(1-Valuation!$B$5) | I25: =I21*(1-Valuation!$B$5) | ... P25: =P21*(1-Valuation!$B$5)
A26: + D&A | B26: =SUM(Financials!H34:K34) | C26: =SUM(Financials!L34:O34) | D26: =SUM(Financials!P34:S34) | E26: =SUM(Financials!T34:W34) | F26: =SUM(Financials!X34:AA34) | G26: =G8*0.0278 | H26: =H8*0.0278 | I26: =I8*0.0278 | J26: =J8*0.0278 | K26: =K8*0.0278 | L26: =L8*0.0278 | M26: =M8*0.0278 | N26: =N8*0.0278 | ... P26: =P8*0.0278
A27: + SBC (non-cash) | B27: =SUM(Financials!H35:K35) | C27: =SUM(Financials!L35:O35) | D27: =SUM(Financials!P35:S35) | E27: =SUM(Financials!T35:W35) | F27: =SUM(Financials!X35:AA35) | G27: =G8*(Dashboard!$B$65+(Dashboard!$B$66-Dashboard!$B$65)*0/9) | H27: =H8*(Dashboard!$B$65+(Dashboard!$B$66-Dashboard!$B$65)*1/9) | I27: =I8*(Dashboard!$B$65+(Dashboard!$B$66-Dashboard!$B$65)*2/9) | J27: =J8*(Dashboard!$B$65+(Dashboard!$B$66-Dashboard!$B$65)*3/9) | K27: =K8*(Dashboard!$B$65+(Dashboard!$B$66-Dashboard!$B$65)*4/9) | L27: =L8*(Dashboard!$B$65+(Dashboard!$B$66-Dashboard!$B$65)*5/9) | M27: =M8*(Dashboard!$B$65+(Dashboard!$B$66-Dashboard!$B$65)*6/9) | N27: =N8*(Dashboard!$B$65+(Dashboard!$B$66-Dashboard!$B$65)*7/9) | O27: =O8*(Dashboard!$B$65+(Dashboard!$B$66-Dashboard!$B$65)*8/9) | P27: =P8*(Dashboard!$B$65+(Dashboard!$B$66-Dashboard!$B$65)*9/9)
A28: - dNWC | G28: =(G8-F8)*0.0050 | H28: =(H8-G8)*0.0050 | I28: =(I8-H8)*0.0050 | J28: =(J8-I8)*0.0050 | K28: =(K8-J8)*0.0050 | L28: =(L8-K8)*0.0050 | M28: =(M8-L8)*0.0050 | N28: =(N8-M8)*0.0050 | ... P28: =(P8-O8)*0.0050
A29: - Capex | B29: =-SUM(Financials!H38:K38) | C29: =-SUM(Financials!L38:O38) | D29: =-SUM(Financials!P38:S38) | E29: =-SUM(Financials!T38:W38) | F29: =-SUM(Financials!X38:AA38) | G29: =G26*G30 | H29: =H26*H30 | I29: =I26*I30 | J29: =J26*J30 | K29: =K26*K30 | L29: =L26*L30 | M29: =M26*M30 | N29: =N26*N30 | ... P29: =P26*P30
A30: Capex / D&A (from Dashboard: $cap'26 -> terminal) | B30: =IFERROR(B29/B26,"") | C30: =IFERROR(C29/C26,"") | D30: =IFERROR(D29/D26,"") | E30: =IFERROR(E29/E26,"") | F30: =IFERROR(F29/F26,"") | G30: =(Dashboard!$B$34/G26)+(Dashboard!$B$35-(Dashboard!$B$34/G26))*0/9 | H30: =(Dashboard!$B$34/G26)+(Dashboard!$B$35-(Dashboard!$B$34/G26))*1/9 | I30: =(Dashboard!$B$34/G26)+(Dashboard!$B$35-(Dashboard!$B$34/G26))*2/9 | J30: =(Dashboard!$B$34/G26)+(Dashboard!$B$35-(Dashboard!$B$34/G26))*3/9 | K30: =(Dashboard!$B$34/G26)+(Dashboard!$B$35-(Dashboard!$B$34/G26))*4/9 | L30: =(Dashboard!$B$34/G26)+(Dashboard!$B$35-(Dashboard!$B$34/G26))*5/9 | M30: =(Dashboard!$B$34/G26)+(Dashboard!$B$35-(Dashboard!$B$34/G26))*6/9 | N30: =(Dashboard!$B$34/G26)+(Dashboard!$B$35-(Dashboard!$B$34/G26))*7/9 | O30: =(Dashboard!$B$34/G26)+(Dashboard!$B$35-(Dashboard!$B$34/G26))*8/9 | P30: =(Dashboard!$B$34/G26)+(Dashboard!$B$35-(Dashboard!$B$34/G26))*9/9
A32: FCFF (firm) | B32: =B25+B26+B27-B28-B29 | C32: =C25+C26+C27-C28-C29 | D32: =D25+D26+D27-D28-D29 | E32: =E25+E26+E27-E28-E29 | F32: =F25+F26+F27-F28-F29 | G32: =G25+G26+G27-G28-G29 | H32: =H25+H26+H27-H28-H29 | I32: =I25+I26+I27-I28-I29 | ... P32: =P25+P26+P27-P28-P29
A33: Valuation FCF (NOPAT + D&A - dNWC - Capex - after-tax SBC) | B33: =B32-B27-B27*(1-Valuation!$B$5) | C33: =C32-C27-C27*(1-Valuation!$B$5) | D33: =D32-D27-D27*(1-Valuation!$B$5) | E33: =E32-E27-E27*(1-Valuation!$B$5) | F33: =F32-F27-F27*(1-Valuation!$B$5) | G33: =G32-G27-G27*(1-Valuation!$B$5) | H33: =H32-H27-H27*(1-Valuation!$B$5) | I33: =I32-I27-I27*(1-Valuation!$B$5) | ... P33: =P32-P27-P27*(1-Valuation!$B$5)
A35: RETURNS ON CAPITAL & EFFICIENCY (is new revenue/capital earning its keep?)
A36: Invested capital (debt + equity - cash) | B36: =Financials!K32+Financials!K31-Financials!K26 | C36: =Financials!O32+Financials!O31-Financials!O26 | D36: =Financials!S32+Financials!S31-Financials!S26 | E36: =Financials!W32+Financials!W31-Financials!W26 | F36: =Financials!AA32+Financials!AA31-Financials!AA26 | G36: =F36+G29-G26+G28 | H36: =G36+H29-H26+H28 | I36: =H36+I29-I26+I28 | J36: =I36+J29-J26+J28 | K36: =J36+K29-K26+K28 | L36: =K36+L29-L26+L28 | M36: =L36+M29-M26+M28 | N36: =M36+N29-N26+N28 | ... P36: =O36+P29-P26+P28
A37: Book equity (year-end) | B37: =Financials!K32 | C37: =Financials!O32 | D37: =Financials!S32 | E37: =Financials!W32 | F37: =Financials!AA32 | G37: =F37+G25 | H37: =G37+H25 | I37: =H37+I25 | J37: =I37+J25 | K37: =J37+K25 | L37: =K37+L25 | M37: =L37+M25 | N37: =M37+N25 | ... P37: =O37+P25
A38: ROIC (NOPAT / beg. invested capital) | C38: =IFERROR(C25/B36,"") | D38: =IFERROR(D25/C36,"") | E38: =IFERROR(E25/D36,"") | F38: =IFERROR(F25/E36,"") | G38: =IFERROR(G25/F36,"") | H38: =IFERROR(H25/G36,"") | I38: =IFERROR(I25/H36,"") | J38: =IFERROR(J25/I36,"") | ... P38: =IFERROR(P25/O36,"")
A39: ROE (earnings / beg. equity) | C39: =IFERROR(SUM(Financials!L15:O15)/B37,"") | D39: =IFERROR(SUM(Financials!P15:S15)/C37,"") | E39: =IFERROR(SUM(Financials!T15:W15)/D37,"") | F39: =IFERROR(SUM(Financials!X15:AA15)/E37,"") | G39: =IFERROR(G25/F37,"") | H39: =IFERROR(H25/G37,"") | I39: =IFERROR(I25/H37,"") | J39: =IFERROR(J25/I37,"") | K39: =IFERROR(K25/J37,"") | L39: =IFERROR(L25/K37,"") | M39: =IFERROR(M25/L37,"") | N39: =IFERROR(N25/M37,"") | ... P39: =IFERROR(P25/O37,"")
A40: ROIC - WACC spread (value created) | C40: =IFERROR(C38-WACC!$B$15,"") | D40: =IFERROR(D38-WACC!$B$15,"") | E40: =IFERROR(E38-WACC!$B$15,"") | F40: =IFERROR(F38-WACC!$B$15,"") | G40: =IFERROR(G38-WACC!$B$15,"") | H40: =IFERROR(H38-WACC!$B$15,"") | I40: =IFERROR(I38-WACC!$B$15,"") | J40: =IFERROR(J38-WACC!$B$15,"") | ... P40: =IFERROR(P38-WACC!$B$15,"")
A41: Incremental op margin (ΔEBIT / ΔRev) | C41: =IFERROR((C21-B21)/(C8-B8),"") | D41: =IFERROR((D21-C21)/(D8-C8),"") | E41: =IFERROR((E21-D21)/(E8-D8),"") | F41: =IFERROR((F21-E21)/(F8-E8),"") | G41: =IFERROR((G21-F21)/(G8-F8),"") | H41: =IFERROR((H21-G21)/(H8-G8),"") | I41: =IFERROR((I21-H21)/(I8-H8),"") | J41: =IFERROR((J21-I21)/(J8-I8),"") | ... P41: =IFERROR((P21-O21)/(P8-O8),"")
A42: ROIIC (ΔNOPAT / ΔInvested capital) | C42: =IFERROR((C25-B25)/(C36-B36),"") | D42: =IFERROR((D25-C25)/(D36-C36),"") | E42: =IFERROR((E25-D25)/(E36-D36),"") | F42: =IFERROR((F25-E25)/(F36-E36),"") | G42: =IFERROR((G25-F25)/(G36-F36),"") | H42: =IFERROR((H25-G25)/(H36-G36),"") | I42: =IFERROR((I25-H25)/(I36-H36),"") | J42: =IFERROR((J25-I25)/(J36-I36),"") | ... P42: =IFERROR((P25-O25)/(P36-O36),"")
A43: Sales-to-capital (ΔRev / ΔInvested capital) | C43: =IFERROR((C8-B8)/(C36-B36),"") | D43: =IFERROR((D8-C8)/(D36-C36),"") | E43: =IFERROR((E8-D8)/(E36-D36),"") | F43: =IFERROR((F8-E8)/(F36-E36),"") | G43: =IFERROR((G8-F8)/(G36-F36),"") | H43: =IFERROR((H8-G8)/(H36-G36),"") | I43: =IFERROR((I8-H8)/(I36-H36),"") | J43: =IFERROR((J8-I8)/(J36-I36),"") | ... P43: =IFERROR((P8-O8)/(P36-O36),"")
A44: Reinvestment rate (ΔInvested capital / NOPAT) | C44: =IFERROR((C36-B36)/C25,"") | D44: =IFERROR((D36-C36)/D25,"") | E44: =IFERROR((E36-D36)/E25,"") | F44: =IFERROR((F36-E36)/F25,"") | G44: =IFERROR((G36-F36)/G25,"") | H44: =IFERROR((H36-G36)/H25,"") | I44: =IFERROR((I36-H36)/I25,"") | J44: =IFERROR((J36-I36)/J25,"") | ... P44: =IFERROR((P36-O36)/P25,"")
A46: Blue/green = actual · Yellow = assumption · Black = formula

Sheet Financials
A1: Line Item ($M) | B1: Q3 2019 | C1: Q4 2019 | D1: Q1 2020 | E1: Q2 2020 | F1: Q3 2020 | G1: Q4 2020 | H1: Q1 2021 | I1: Q2 2021 | J1: Q3 2021 | K1: Q4 2021 | L1: Q1 2022 | M1: Q2 2022 | N1: Q3 2022 | O1: Q4 2022 | P1: Q1 2023 | Q1: Q2 2023 | R1: Q3 2023 | S1: Q4 2023 | T1: Q1 2024 | U1: Q2 2024 | V1: Q3 2024 | W1: Q4 2024 | X1: Q1 2025 | Y1: Q2 2025 | Z1: Q3 2025 | AA1: Q4 2025 | AB1: Q1 2026 | AC1: Q2 2026
A2: INCOME STATEMENT
A3: Revenue | B3: 9635 | C3: 4814 | D3: 5077 | E3: 5216 | F3: 4893 | G3: 8346 | H3: 8235 | I3: 7935 | J3: 8060 | K3: 9336 | L3: 10705 | M3: 11164 | N3: 10936 | O3: 11395 | P3: 9463 | Q3: 9275 | R3: 8451 | S3: 8631 | T3: 9935 | U3: 9389 | V3: 9393 | W3: 10244 | X3: 11669 | Y3: 10979 | Z3: 10365 | AA3: 11271 | AB3: 12252 | AC3: 10599
A4: % YoY | F4: =IFERROR(F3/B3-1,"") | G4: =IFERROR(G3/C3-1,"") | H4: =IFERROR(H3/D3-1,"") | I4: =IFERROR(I3/E3-1,"") | J4: =IFERROR(J3/F3-1,"") | K4: =IFERROR(K3/G3-1,"") | L4: =IFERROR(L3/H3-1,"") | M4: =IFERROR(M3/I3-1,"") | ... AC4: =IFERROR(AC3/Y3-1,"")
A5: Cost of Revenue | B5: 2114 | C5: 2118 | D5: 2113 | E5: 2297 | F5: 2080 | G5: 2766 | H5: 3489 | I5: 3432 | J5: 3404 | K5: 3937 | L5: 4303 | M5: 4648 | N5: 4816 | O5: 4868 | P5: 4044 | Q5: 4153 | R5: 3792 | S5: 3880 | T5: 4312 | U5: 4106 | V5: 4174 | W5: 4467 | X5: 5161 | Y5: 4937 | Z5: 4606 | AA5: 5034 | AB5: 5568 | AC5: 4900
A6: % of revenue | B6: =IFERROR(B5/B3,"") | C6: =IFERROR(C5/C3,"") | D6: =IFERROR(D5/D3,"") | E6: =IFERROR(E5/E3,"") | F6: =IFERROR(F5/F3,"") | G6: =IFERROR(G5/G3,"") | H6: =IFERROR(H5/H3,"") | I6: =IFERROR(I5/I3,"") | ... AC6: =IFERROR(AC5/AC3,"")
A7: R&D Expense | B7: 1380 | C7: 1441 | D7: 1406 | E7: 1468 | F7: 1520 | G7: 1583 | H7: 1653 | I7: 1780 | J7: 1864 | K7: 1878 | L7: 1930 | M7: 2034 | N7: 2052 | O7: 2178 | P7: 2251 | Q7: 2210 | R7: 2222 | S7: 2135 | T7: 2096 | U7: 2236 | V7: 2259 | W7: 2302 | X7: 2230 | Y7: 2216 | Z7: 2226 | AA7: 2370 | AB7: 2453 | AC7: 2463
A8: % of revenue | B8: =IFERROR(B7/B3,"") | C8: =IFERROR(C7/C3,"") | D8: =IFERROR(D7/D3,"") | E8: =IFERROR(E7/E3,"") | F8: =IFERROR(F7/F3,"") | G8: =IFERROR(G7/G3,"") | H8: =IFERROR(H7/H3,"") | I8: =IFERROR(I7/I3,"") | ... AC8: =IFERROR(AC7/AC3,"")
A9: SG&A Expense | B9: 547 | C9: 548 | D9: 528 | E9: 483 | F9: 511 | G9: 551 | H9: 567 | I9: 557 | J9: 597 | K9: 619 | L9: 608 | M9: 624 | N9: 655 | O9: 683 | P9: 623 | Q9: 614 | R9: 618 | S9: 628 | T9: 627 | U9: 707 | V9: 664 | W9: 761 | X9: 723 | Y9: 706 | Z9: 771 | AA9: 910 | AB9: 865 | AC9: 898
A10: % of revenue | B10: =IFERROR(B9/B3,"") | C10: =IFERROR(C9/C3,"") | D10: =IFERROR(D9/D3,"") | E10: =IFERROR(E9/E3,"") | F10: =IFERROR(F9/F3,"") | G10: =IFERROR(G9/G3,"") | H10: =IFERROR(H9/H3,"") | I10: =IFERROR(I9/I3,"") | ... AC10: =IFERROR(AC9/AC3,"")
A11: Gross Profit | B11: 7521 | C11: 2696 | D11: 2964 | E11: 2919 | F11: 2813 | G11: 5580 | H11: 4746 | I11: 4503 | J11: 4656 | K11: 5399 | L11: 6402 | M11: 6516 | N11: 6120 | O11: 6527 | P11: 5419 | Q11: 5122 | R11: 4659 | S11: 4751 | T11: 5623 | U11: 5283 | V11: 5219 | W11: 5777 | X11: 6508 | Y11: 6042 | Z11: 5759 | AA11: 6237 | AB11: 6684 | AC11: 5699
A12: gross margin | B12: =IFERROR(B11/B3,"") | C12: =IFERROR(C11/C3,"") | D12: =IFERROR(D11/D3,"") | E12: =IFERROR(E11/E3,"") | F12: =IFERROR(F11/F3,"") | G12: =IFERROR(G11/G3,"") | H12: =IFERROR(H11/H3,"") | I12: =IFERROR(I11/I3,"") | ... AC12: =IFERROR(AC11/AC3,"")
A13: Operating Income | B13: 5317 | C13: 701 | D13: 1030 | E13: 991 | F13: 782 | G13: 3452 | H13: 2526 | I13: 2166 | J13: 2195 | K13: 2902 | L13: 3864 | M13: 3858 | N13: 4472 | O13: 3666 | P13: 2465 | Q13: 2090 | R13: 1823 | S13: 1410 | T13: 2928 | U13: 2340 | V13: 2221 | W13: 2582 | X13: 3555 | Y13: 3120 | Z13: 2762 | AA13: 2918 | AB13: 3366 | AC13: 2309
A14: operating margin | B14: =IFERROR(B13/B3,"") | C14: =IFERROR(C13/C3,"") | D14: =IFERROR(D13/D3,"") | E14: =IFERROR(E13/E3,"") | F14: =IFERROR(F13/F3,"") | G14: =IFERROR(G13/G3,"") | H14: =IFERROR(H13/H3,"") | I14: =IFERROR(I13/I3,"") | ... AC14: =IFERROR(AC13/AC3,"")
A15: Net Income | B15: 2149 | C15: 506 | D15: 925 | E15: 468 | F15: 845 | G15: 2960 | H15: 2455 | I15: 1762 | J15: 2027 | K15: 2798 | L15: 3399 | M15: 2934 | N15: 3730 | O15: 2873 | P15: 2235 | Q15: 1704 | R15: 1803 | S15: 1490 | T15: 2767 | U15: 2326 | V15: 2129 | W15: 2920 | X15: 3180 | Y15: 2812 | Z15: 2666 | AA15: -3117 | AB15: 3004 | AC15: 7370
A16: net margin | B16: =IFERROR(B15/B3,"") | C16: =IFERROR(C15/C3,"") | D16: =IFERROR(D15/D3,"") | E16: =IFERROR(E15/E3,"") | F16: =IFERROR(F15/F3,"") | G16: =IFERROR(G15/G3,"") | H16: =IFERROR(H15/H3,"") | I16: =IFERROR(I15/I3,"") | ... AC16: =IFERROR(AC15/AC3,"")
A17: Diluted Shares (M) | B17: 1231 | C17: 1211 | D17: 1159 | E17: 1151 | F17: 1139 | G17: 1148 | H17: 1156 | I17: 1151 | J17: 1145 | K17: 1144 | L17: 1142 | M17: 1140 | N17: 1134 | O17: 1131 | P17: 1131 | Q17: 1123 | R17: 1124 | S17: 1125 | T17: 1127 | U17: 1130 | V17: 1134 | W17: 1130 | X17: 1122 | Y17: 1115 | Z17: 1099 | AA17: 1105 | AB17: 1079 | AC17: 1072
A18: REVENUE BY SEGMENT — PRODUCT (% YoY, % of revenue)
A19: QCT | B19: 3567 | C19: 3611 | D19: 3618 | E19: 4100 | F19: 3807 | G19: 4968 | H19: 6533 | I19: 6281 | J19: 6472 | K19: 7733 | L19: 8847 | M19: 9548 | N19: 9378 | O19: 9904 | P19: 7892 | Q19: 7942 | R19: 7174 | S19: 7374 | T19: 8423 | U19: 8026 | V19: 8069 | W19: 8678 | X19: 10084 | Y19: 9469 | Z19: 8993 | AA19: 9821 | AB19: 10613 | AC19: 9076
A20: % YoY | F20: =IFERROR(F19/B19-1,"") | G20: =IFERROR(G19/C19-1,"") | H20: =IFERROR(H19/D19-1,"") | I20: =IFERROR(I19/E19-1,"") | J20: =IFERROR(J19/F19-1,"") | K20: =IFERROR(K19/G19-1,"") | L20: =IFERROR(L19/H19-1,"") | M20: =IFERROR(M19/I19-1,"") | ... AC20: =IFERROR(AC19/Y19-1,"")
A21: % of revenue | B21: =IFERROR(B19/B3,"") | C21: =IFERROR(C19/C3,"") | D21: =IFERROR(D19/D3,"") | E21: =IFERROR(E19/E3,"") | F21: =IFERROR(F19/F3,"") | G21: =IFERROR(G19/G3,"") | H21: =IFERROR(H19/H3,"") | I21: =IFERROR(I19/I3,"") | ... AC21: =IFERROR(AC19/AC3,"")
A22: QTL | B22: 1292 | C22: 1159 | D22: 1404 | E22: 1072 | F22: 1044 | G22: 1508 | H22: 1660 | I22: 1614 | J22: 1489 | K22: 1557 | L22: 1818 | M22: 1580 | N22: 1519 | O22: 1441 | P22: 1524 | Q22: 1290 | R22: 1230 | S22: 1262 | T22: 1460 | U22: 1318 | V22: 1273 | W22: 1521 | X22: 1535 | Y22: 1319 | Z22: 1318 | AA22: 1410 | AB22: 1592 | AC22: 1382
A23: % YoY | F23: =IFERROR(F22/B22-1,"") | G23: =IFERROR(G22/C22-1,"") | H23: =IFERROR(H22/D22-1,"") | I23: =IFERROR(I22/E22-1,"") | J23: =IFERROR(J22/F22-1,"") | K23: =IFERROR(K22/G22-1,"") | L23: =IFERROR(L22/H22-1,"") | M23: =IFERROR(M22/I22-1,"") | ... AC23: =IFERROR(AC22/Y22-1,"")
A24: % of revenue | B24: =IFERROR(B22/B3,"") | C24: =IFERROR(C22/C3,"") | D24: =IFERROR(D22/D3,"") | E24: =IFERROR(E22/E3,"") | F24: =IFERROR(F22/F3,"") | G24: =IFERROR(G22/G3,"") | H24: =IFERROR(H22/H3,"") | I24: =IFERROR(I22/I3,"") | ... AC24: =IFERROR(AC22/AC3,"")
A25: BALANCE SHEET
A26: Cash & ST Investments | B26: 14358 | C26: 12260 | D26: 11423 | E26: 9946 | F26: 10600 | G26: 11214 | H26: 12298 | I26: 11526 | J26: 12907 | K26: 12414 | L26: 11310 | M26: 11546 | N26: 6848 | O26: 6382 | P26: 8238 | Q26: 6676 | R26: 8631 | S26: 11324 | T26: 12054 | U26: 13851 | V26: 13032 | W26: 13300 | X26: 14305 | Y26: 13846 | Z26: 10011 | AA26: 12478 | AB26: 11822 | AC26: 9799
A27: Total Current Assets | B27: 19204 | C27: 16765 | D27: 16205 | E27: 15313 | F27: 15558 | G27: 18519 | H27: 19792 | I27: 18299 | J27: 19693 | K27: 20075 | L27: 20222 | M27: 21610 | N27: 18999 | O27: 20724 | P27: 21098 | Q27: 19073 | R27: 20476 | S27: 22464 | T27: 23439 | U27: 24232 | V27: 23332 | W27: 25231 | X27: 26065 | Y27: 26080 | Z27: 24913 | AA27: 25754 | AB27: 24608 | AC27: 23112
A28: PP&E (net) | B28: 3037 | C28: 3081 | D28: 3171 | E28: 3358 | F28: 3487 | G28: 3711 | H28: 4033 | I28: 4186 | J28: 4424 | K28: 4559 | L28: 4723 | M28: 4893 | N28: 5038 | O28: 5168 | P28: 5215 | Q28: 5281 | R28: 5216 | S28: 5042 | T28: 4907 | U28: 4724 | V28: 4744 | W28: 4665 | X28: 4460 | Y28: 4410 | Z28: 4496 | AA28: 4690 | AB28: 4893 | AC28: 5071
A29: Total Assets | B29: 34133 | C29: 32957 | D29: 33111 | E29: 31938 | F29: 32328 | G29: 35594 | H29: 37479 | I29: 37168 | J29: 38769 | K29: 41240 | L29: 42820 | M29: 44302 | N29: 47020 | O29: 49014 | P29: 50014 | Q29: 48362 | R29: 49002 | S29: 51040 | T29: 52135 | U29: 53167 | V29: 52741 | W29: 55154 | X29: 55575 | Y29: 55372 | Z29: 54862 | AA29: 50143 | AB29: 53034 | AC29: 57136
A30: Total Current Liabilities | B30: 10853 | C30: 8935 | D30: 9194 | E30: 9774 | F30: 7914 | G30: 8672 | H30: 9223 | I30: 9070 | J30: 11460 | K30: 11951 | L30: 12273 | M30: 13432 | N30: 11829 | O30: 11866 | P30: 10081 | Q30: 7866 | R30: 8463 | S30: 9628 | T30: 9169 | U30: 9143 | V30: 9747 | W30: 10504 | X30: 9954 | Y30: 9544 | Z30: 7800 | AA30: 9144 | AB30: 9822 | AC30: 9767
A31: Long-term Debt | B31: 13426 | C31: 13437 | D31: 13437 | E31: 13449 | F31: 15425 | G31: 15226 | H31: 15231 | I31: 15235 | J31: 13695 | K31: 13701 | L31: 13708 | M31: 12195 | N31: 13600 | O31: 13537 | P31: 15431 | Q31: 15486 | R31: 14530 | S31: 14484 | T31: 14566 | U31: 14543 | V31: 13190 | W31: 13270 | X31: 13212 | Y31: 13258 | Z31: 14788 | AA31: 15541 | AB31: 14817 | AC31: 14772
A32: Total Equity | B32: 5463 | C32: 4909 | D32: 4513 | E32: 3045 | F32: 3306 | G32: 6077 | H32: 7380 | I32: 7424 | J32: 8177 | K32: 9950 | L32: 11333 | M32: 13328 | N32: 16048 | O32: 18013 | P32: 18810 | Q32: 19698 | R32: 20670 | S32: 21581 | T32: 23058 | U32: 24469 | V32: 24670 | W32: 26274 | X32: 26880 | Y32: 27728 | Z32: 27209 | AA32: 21206 | AB32: 23073 | AC32: 27278
A33: CASH FLOW
A34: D&A | B34: 353 | C34: 350 | D34: 351 | E34: 340 | F34: 363 | G34: 339 | H34: 364 | I34: 387 | J34: 406 | K34: 425 | L34: 406 | M34: 428 | N34: 438 | O34: 490 | P34: 398 | Q34: 470 | R34: 479 | S34: 462 | T34: 437 | U34: 411 | V34: 419 | W34: 439 | X34: 436 | Y34: 397 | Z34: 398 | AA34: 0 | AB34: 393 | AC34: 413
A35: Stock-based Compensation | B35: 246 | C35: 339 | D35: 294 | E35: 309 | F35: 296 | G35: 313 | H35: 392 | I35: 422 | J35: 424 | K35: 425 | L35: 496 | M35: 498 | N35: 516 | O35: 521 | P35: 634 | Q35: 628 | R35: 614 | S35: 608 | T35: 602 | U35: 705 | V35: 644 | W35: 697 | X35: 759 | Y35: 702 | Z35: 659 | AA35: 0 | AB35: 0 | AC35: 1749
A36: Change in Working Capital | B36: -697 | C36: 319 | D36: -288 | E36: -61 | F36: 718 | G36: -1976 | H36: 124 | I36: 748 | J36: 841 | K36: -2174 | L36: -2388 | M36: -793 | N36: -2154 | O36: -2465 | P36: -4 | Q36: -929 | R36: 380 | S36: 1701 | T36: 189 | U36: 1168 | V36: 725 | W36: -859 | X36: 33 | Y36: -33 | Z36: -22 | AA36: 645 | AB36: 594 | AC36: -76
A37: Operating Cash Flow | B37: 4909 | C37: 1227 | D37: 1118 | E37: 1083 | F37: 1872 | G37: 1741 | H37: 3175 | I37: 2911 | J37: 3373 | K37: 1077 | L37: 2057 | M37: 2698 | N37: 2895 | O37: 1446 | P37: 3095 | Q37: 1457 | R37: 2657 | S37: 4090 | T37: 2949 | U37: 3554 | V37: 3052 | W37: 2647 | X37: 4587 | Y37: 2554 | Z37: 2875 | AA37: 3996 | AB37: 4965 | AC37: 2449
A38: Capex | B38: -248 | C38: -317 | D38: -296 | E38: -345 | F38: -418 | G38: -348 | H38: -469 | I38: -483 | J38: -506 | K38: -430 | L38: -583 | M38: -491 | N38: -554 | O38: -634 | P38: -398 | Q38: -453 | R38: -306 | S38: -293 | T38: -214 | U38: -184 | V38: -387 | W38: -256 | X38: -277 | Y38: -214 | Z38: -294 | AA38: -407 | AB38: -549 | AC38: -533
A39: Free Cash Flow | B39: 4661 | C39: 910 | D39: 822 | E39: 738 | F39: 1454 | G39: 1393 | H39: 2706 | I39: 2428 | J39: 2867 | K39: 647 | L39: 1474 | M39: 2207 | N39: 2341 | O39: 812 | P39: 2697 | Q39: 1004 | R39: 2351 | S39: 3797 | T39: 2735 | U39: 3370 | V39: 2665 | W39: 2391 | X39: 4310 | Y39: 2340 | Z39: 2581 | AA39: 3589 | AB39: 4416 | AC39: 1916
A41: Blue = hardcoded actuals from FMP filings. Same-sheet ratios are formulas.

Sheet Consensus
A1: Full consensus check — model vs Street (FMP estimates, $M)
A2: Fiscal year | B2: 2026 | C2: 2027 | D2: 2028 | E2: 2029
A3: EVERY AVAILABLE FMP CONSENSUS FIELD (consensus / model / % diff)
A4: Revenue — consensus | B4: 42507.14 | C4: 42578.011 | D4: 46426.004 | E4: 55231.9
A5: model | B5: =Model!G8 | C5: =Model!H8 | D5: =Model!I8 | E5: =Model!J8
A6: vs consensus | B6: =IFERROR(B5/B4-1,"") | C6: =IFERROR(C5/C4-1,"") | D6: =IFERROR(D5/D4-1,"") | E6: =IFERROR(E5/E4-1,"")
A8: EBITDA* — consensus | B8: 14204.034 | C8: 14227.716 | D8: 15513.547 | E8: 18456.094
A9: model | B9: =Model!G21+Model!G26 | C9: =Model!H21+Model!H26 | D9: =Model!I21+Model!I26 | E9: =Model!J21+Model!J26
A10: vs consensus | B10: =IFERROR(B9/B8-1,"") | C10: =IFERROR(C9/C8-1,"") | D10: =IFERROR(D9/D8-1,"") | E10: =IFERROR(E9/E8-1,"")
A12: EBIT* — consensus | B12: 12355.316 | C12: 12375.916 | D12: 13494.391 | E12: 16053.952
A13: model | B13: =Model!G21 | C13: =Model!H21 | D13: =Model!I21 | E13: =Model!J21
A14: vs consensus | B14: =IFERROR(B13/B12-1,"") | C14: =IFERROR(C13/C12-1,"") | D14: =IFERROR(D13/D12-1,"") | E14: =IFERROR(E13/E12-1,"")
A16: SG&A — consensus | B16: 2875.0838 | C16: 2879.8773 | D16: 3140.1466 | E16: 3735.7568
A17: model | B17: =Model!G16 | C17: =Model!H16 | D17: =Model!I16 | E17: =Model!J16
A18: vs consensus | B18: =IFERROR(B17/B16-1,"") | C18: =IFERROR(C17/C16-1,"") | D18: =IFERROR(D17/D16-1,"") | E18: =IFERROR(E17/E16-1,"")
A20: Net income (NOPAT) — consensus | B20: 12235.3 | C20: 12174.514 | D20: 13062.741 | E20: 16552.9
A21: model | B21: =Model!G25 | C21: =Model!H25 | D21: =Model!I25 | E21: =Model!J25
A22: vs consensus | B22: =IFERROR(B21/B20-1,"") | C22: =IFERROR(C21/C20-1,"") | D22: =IFERROR(D21/D20-1,"") | E22: =IFERROR(E21/E20-1,"")
A24: EPS — consensus | B24: 10.73442 | C24: 10.54373 | D24: 11.86172 | E24: 14.98
A25: model | B25: =Model!G25/Financials!AC17 | C25: =Model!H25/Financials!AC17 | D25: =Model!I25/Financials!AC17 | E25: =Model!J25/Financials!AC17
A26: vs consensus | B26: =IFERROR(B25/B24-1,"") | C26: =IFERROR(C25/C24-1,"") | D26: =IFERROR(D25/D24-1,"") | E26: =IFERROR(E25/E24-1,"")
A28: Defaults anchored to consensus revenue + net income (≈0% diff). Other rows show where the model sits vs Street.
A29: *FMP's EBITDA/EBIT estimates look unreliable for AMZN (it reports NI > EBIT) — don't over-read those two.

Sheet Valuation
A1: QUALCOMM Incorporated — DCF Valuation
A2: Current price | B2: =Dashboard!$B$48
A3: WACC | B3: =WACC!B15
A4: Terminal growth (g) | B4: =Dashboard!$B$46
A5: Tax rate | B5: =Dashboard!$B$31
A6: Terminal method | B6: =Dashboard!$B$43
A7: Exit basis | B7: =Dashboard!$B$44
A8: Exit multiple | B8: =Dashboard!$B$45
A11: Forecast year | C11: 2026 | D11: 2027 | E11: 2028 | F11: 2029 | G11: 2030 | H11: 2031 | I11: 2032 | J11: 2033 | K11: 2034 | L11: 2035
A12: FCFF ($M) | C12: =Model!G33 | D12: =Model!H33 | E12: =Model!I33 | F12: =Model!J33 | G12: =Model!K33 | H12: =Model!L33 | I12: =Model!M33 | J12: =Model!N33 | ... L12: =Model!P33
A13: PV factor | C13: =1/(1+$B$3)^1 | D13: =1/(1+$B$3)^2 | E13: =1/(1+$B$3)^3 | F13: =1/(1+$B$3)^4 | G13: =1/(1+$B$3)^5 | H13: =1/(1+$B$3)^6 | I13: =1/(1+$B$3)^7 | J13: =1/(1+$B$3)^8 | K13: =1/(1+$B$3)^9 | L13: =1/(1+$B$3)^10
A14: PV of FCFF ($M) | C14: =C12*C13 | D14: =D12*D13 | E14: =E12*E13 | F14: =F12*F13 | G14: =G12*G13 | H14: =H12*H13 | I14: =I12*I13 | J14: =J12*J13 | ... L14: =L12*L13
A16: Sum PV of FCFF | B16: =SUM(C14:L14)
A18: TERMINAL VALUE (exit multiple = default; perpetuity = cross-check)
A19: Terminal-year FCFF | B19: =L12
A20: Terminal revenue | B20: =Model!P8
A21: Terminal EBIT | B21: =Model!P21
A22: Terminal EBITDA (SBC-burdened) | B22: =Model!P21+Model!P26-Model!P27
A23: Terminal metric (per exit basis) | B23: =IF($B$7="EV/EBITDA",B22,IF($B$7="EV/Sales",B20,IF($B$7="EV/EBIT",B21,B19)))
A24: TV (exit) = metric x multiple | B24: =B23*$B$8
A25: PV of TV — exit multiple | B25: =B24/(1+$B$3)^10
A26: TV (perpetuity) = FCFF(1+g)/(WACC-g) | B26: =B19*(1+$B$4)/($B$3-$B$4)
A27: PV of TV — perpetuity | B27: =B26/(1+$B$3)^10
A28: PV of TV — SELECTED | B28: =IF($B$6="Perpetuity",B27,B25)
A30: EQUITY BRIDGE -> VALUE / SHARE
A31: Operating value (enterprise value) | B31: =B16+B28
A32: + Cash & ST investments | B32: =Financials!AC26
A33: - Long-term debt | B33: =-Financials!AC31
A34: Equity value | B34: =B31+B32+B33
A35: Diluted shares (M) | B35: =Financials!AC17
A36: VALUE / SHARE | B36: =B34/B35*1.0
A38: CROSS-CHECKS & RETURN
A39: Terminal weight (% of EV) | B39: =B28/B31
A40: Implied perpetuity g (from exit multiple) | B40: =(B24*$B$3-B19)/(B24+B19)
A41: Implied exit EV/EBITDA (from perpetuity) | B41: =B26/B22
A42: Upside / (downside) to fair value | B42: =B36/$B$2-1
A44: Owner cashflow / share | B44: =-$B$2 | C44: =C12/B35 | D44: =D12/B35 | E44: =E12/B35 | F44: =F12/B35 | G44: =G12/B35 | H44: =H12/B35 | I44: =I12/B35 | J44: =J12/B35 | K44: =K12/B35 | L44: =L12/B35+B36
A45: IRR (buy at price, hold 10y) | B45: =IRR(B44:L44)

Sheet Sensitivity
A1: Sensitivity — fair value / share (USD)
A2: WACC x exit multiple (EV/EBITDA). Static grid recomputed by every rebuild/refresh — edit the Dashboard, re-run refresh_dcf to update. Shaded = base case; green = above current price.
A4: EV/EBITDA x \ WACC | B4: 0.10012056 | C4: 0.10512056 | D4: 0.11012056 | E4: 0.11512056 | F4: 0.12012056 | G4: 0.12512056 | H4: 0.13012056
A5: 9 | B5: 175.65743 | C5: 169.49594 | D5: 163.60498 | E5: 157.97101 | F5: 152.58126 | G5: 147.42364 | H5: 142.48673
A6: 10 | B6: 186.02639 | C6: 179.4052 | D6: 173.07686 | E6: 167.02666 | F6: 161.24071 | G6: 155.70587 | H6: 150.40973
A7: 11 | B7: 196.39534 | C7: 189.31446 | D7: 182.54874 | E7: 176.08231 | F7: 169.90015 | G7: 163.9881 | H7: 158.33274
A8: 12 | B8: 206.7643 | C8: 199.22372 | D8: 192.02062 | E8: 185.13795 | F8: 178.5596 | G8: 172.27032 | H8: 166.25575
A9: 13 | B9: 217.13325 | C9: 209.13298 | D9: 201.49251 | E9: 194.1936 | F9: 187.21904 | G9: 180.55255 | H9: 174.17875
A10: 14 | B10: 227.5022 | C10: 219.04224 | D10: 210.96439 | E10: 203.24925 | F10: 195.87849 | G10: 188.83478 | H10: 182.10176
A11: 15 | B11: 237.87116 | C11: 228.95149 | D11: 220.43627 | E11: 212.3049 | F11: 204.53793 | G11: 197.117 | H11: 190.02476
A13: Current price | B13: 176.25
A14: Base WACC / multiple | B14: 0.11512056 | C14: 12

Sheet Monte Carlo
A1: Monte Carlo simulation (live) | H1: SIMULATION ENGINE — leave as-is | K1: cagr | L1: term margin | M1: wacc | N1: exit | O1: value/share
A2: 1,000 trials, recomputed in-sheet on every edit. Edit the yellow driver distributions to re-roll. Engine grid is to the right (cols H+). | H2: R0 (base revenue) | I2: =Model!F8 | K2: =MAX(-0.05,NORMINV(RAND(),$C$6,$D$6)) | L2: =MAX(0.02,NORMINV(RAND(),$C$7,$D$7)) | M2: =MIN(0.16,MAX(0.05,NORMINV(RAND(),$C$8,$D$8))) | N2: =MIN(24,MAX(5,NORMINV(RAND(),$C$9,$D$9))) | O2: =$I$8*(SUMPRODUCT(($I$2*(1+K2)^{1;2;3;4;5;6;7;8;9;10})*(($I$3+(L2-$I$3)*{1;2;3;4;5;6;7;8;9;10}/10)*(1-$I$7)+$I$4-$I$4*($I$5+(1.05-$I$5)*{1;2;3;4;5;6;7;8;9;10}/10)-(K2/(1+K2))*$I$6)/(1+M2)^{1;2;3;4;5;6;7;8;9;10})+$I$2*(1+K2)^10*(L2+$I$4)*N2/(1+M2)^10+$I$9-$I$10)/$I$11
H3: m0 (base op margin) | I3: =Model!F22 | K3: =MAX(-0.05,NORMINV(RAND(),$C$6,$D$6)) | L3: =MAX(0.02,NORMINV(RAND(),$C$7,$D$7)) | M3: =MIN(0.16,MAX(0.05,NORMINV(RAND(),$C$8,$D$8))) | N3: =MIN(24,MAX(5,NORMINV(RAND(),$C$9,$D$9))) | O3: =$I$8*(SUMPRODUCT(($I$2*(1+K3)^{1;2;3;4;5;6;7;8;9;10})*(($I$3+(L3-$I$3)*{1;2;3;4;5;6;7;8;9;10}/10)*(1-$I$7)+$I$4-$I$4*($I$5+(1.05-$I$5)*{1;2;3;4;5;6;7;8;9;10}/10)-(K3/(1+K3))*$I$6)/(1+M3)^{1;2;3;4;5;6;7;8;9;10})+$I$2*(1+K3)^10*(L3+$I$4)*N3/(1+M3)^10+$I$9-$I$10)/$I$11
A4: DRIVER DISTRIBUTIONS (yellow = edit; Opus-set defaults) | H4: da (D&A / revenue) | I4: 0.02779785 | K4: =MAX(-0.05,NORMINV(RAND(),$C$6,$D$6)) | L4: =MAX(0.02,NORMINV(RAND(),$C$7,$D$7)) | M4: =MIN(0.16,MAX(0.05,NORMINV(RAND(),$C$8,$D$8))) | N4: =MIN(24,MAX(5,NORMINV(RAND(),$C$9,$D$9))) | O4: =$I$8*(SUMPRODUCT(($I$2*(1+K4)^{1;2;3;4;5;6;7;8;9;10})*(($I$3+(L4-$I$3)*{1;2;3;4;5;6;7;8;9;10}/10)*(1-$I$7)+$I$4-$I$4*($I$5+(1.05-$I$5)*{1;2;3;4;5;6;7;8;9;10}/10)-(K4/(1+K4))*$I$6)/(1+M4)^{1;2;3;4;5;6;7;8;9;10})+$I$2*(1+K4)^10*(L4+$I$4)*N4/(1+M4)^10+$I$9-$I$10)/$I$11
A5: Driver | B5: Dist | C5: Mean | D5: Std dev | H5: cda0 (2026 capex/D&A) | I5: 1.1096751 | K5: =MAX(-0.05,NORMINV(RAND(),$C$6,$D$6)) | L5: =MAX(0.02,NORMINV(RAND(),$C$7,$D$7)) | M5: =MIN(0.16,MAX(0.05,NORMINV(RAND(),$C$8,$D$8))) | N5: =MIN(24,MAX(5,NORMINV(RAND(),$C$9,$D$9))) | O5: =$I$8*(SUMPRODUCT(($I$2*(1+K5)^{1;2;3;4;5;6;7;8;9;10})*(($I$3+(L5-$I$3)*{1;2;3;4;5;6;7;8;9;10}/10)*(1-$I$7)+$I$4-$I$4*($I$5+(1.05-$I$5)*{1;2;3;4;5;6;7;8;9;10}/10)-(K5/(1+K5))*$I$6)/(1+M5)^{1;2;3;4;5;6;7;8;9;10})+$I$2*(1+K5)^10*(L5+$I$4)*N5/(1+M5)^10+$I$9-$I$10)/$I$11
A6: Revenue 10y CAGR | B6: Normal | C6: =(Model!P8/Model!F8)^(1/10)-1 | D6: 0.03 | H6: nwc (% incr revenue) | I6: 0.005 | K6: =MAX(-0.05,NORMINV(RAND(),$C$6,$D$6)) | L6: =MAX(0.02,NORMINV(RAND(),$C$7,$D$7)) | M6: =MIN(0.16,MAX(0.05,NORMINV(RAND(),$C$8,$D$8))) | N6: =MIN(24,MAX(5,NORMINV(RAND(),$C$9,$D$9))) | O6: =$I$8*(SUMPRODUCT(($I$2*(1+K6)^{1;2;3;4;5;6;7;8;9;10})*(($I$3+(L6-$I$3)*{1;2;3;4;5;6;7;8;9;10}/10)*(1-$I$7)+$I$4-$I$4*($I$5+(1.05-$I$5)*{1;2;3;4;5;6;7;8;9;10}/10)-(K6/(1+K6))*$I$6)/(1+M6)^{1;2;3;4;5;6;7;8;9;10})+$I$2*(1+K6)^10*(L6+$I$4)*N6/(1+M6)^10+$I$9-$I$10)/$I$11
A7: Terminal operating margin | B7: Normal | C7: =Dashboard!$B$30 | D7: 0.03 | H7: tax | I7: =Valuation!$B$5 | K7: =MAX(-0.05,NORMINV(RAND(),$C$6,$D$6)) | L7: =MAX(0.02,NORMINV(RAND(),$C$7,$D$7)) | M7: =MIN(0.16,MAX(0.05,NORMINV(RAND(),$C$8,$D$8))) | N7: =MIN(24,MAX(5,NORMINV(RAND(),$C$9,$D$9))) | O7: =$I$8*(SUMPRODUCT(($I$2*(1+K7)^{1;2;3;4;5;6;7;8;9;10})*(($I$3+(L7-$I$3)*{1;2;3;4;5;6;7;8;9;10}/10)*(1-$I$7)+$I$4-$I$4*($I$5+(1.05-$I$5)*{1;2;3;4;5;6;7;8;9;10}/10)-(K7/(1+K7))*$I$6)/(1+M7)^{1;2;3;4;5;6;7;8;9;10})+$I$2*(1+K7)^10*(L7+$I$4)*N7/(1+M7)^10+$I$9-$I$10)/$I$11
A8: WACC | B8: Normal | C8: =WACC!B15 | D8: 0.005 | H8: k (calibration) | I8: 0.97726137 | K8: =MAX(-0.05,NORMINV(RAND(),$C$6,$D$6)) | L8: =MAX(0.02,NORMINV(RAND(),$C$7,$D$7)) | M8: =MIN(0.16,MAX(0.05,NORMINV(RAND(),$C$8,$D$8))) | N8: =MIN(24,MAX(5,NORMINV(RAND(),$C$9,$D$9))) | O8: =$I$8*(SUMPRODUCT(($I$2*(1+K8)^{1;2;3;4;5;6;7;8;9;10})*(($I$3+(L8-$I$3)*{1;2;3;4;5;6;7;8;9;10}/10)*(1-$I$7)+$I$4-$I$4*($I$5+(1.05-$I$5)*{1;2;3;4;5;6;7;8;9;10}/10)-(K8/(1+K8))*$I$6)/(1+M8)^{1;2;3;4;5;6;7;8;9;10})+$I$2*(1+K8)^10*(L8+$I$4)*N8/(1+M8)^10+$I$9-$I$10)/$I$11
A9: Exit EV/EBITDA multiple | B9: Normal | C9: =Dashboard!$B$45 | D9: 1.5 | H9: cash | I9: =Financials!AC26 | K9: =MAX(-0.05,NORMINV(RAND(),$C$6,$D$6)) | L9: =MAX(0.02,NORMINV(RAND(),$C$7,$D$7)) | M9: =MIN(0.16,MAX(0.05,NORMINV(RAND(),$C$8,$D$8))) | N9: =MIN(24,MAX(5,NORMINV(RAND(),$C$9,$D$9))) | O9: =$I$8*(SUMPRODUCT(($I$2*(1+K9)^{1;2;3;4;5;6;7;8;9;10})*(($I$3+(L9-$I$3)*{1;2;3;4;5;6;7;8;9;10}/10)*(1-$I$7)+$I$4-$I$4*($I$5+(1.05-$I$5)*{1;2;3;4;5;6;7;8;9;10}/10)-(K9/(1+K9))*$I$6)/(1+M9)^{1;2;3;4;5;6;7;8;9;10})+$I$2*(1+K9)^10*(L9+$I$4)*N9/(1+M9)^10+$I$9-$I$10)/$I$11
H10: debt | I10: =Financials!AC31 | K10: =MAX(-0.05,NORMINV(RAND(),$C$6,$D$6)) | L10: =MAX(0.02,NORMINV(RAND(),$C$7,$D$7)) | M10: =MIN(0.16,MAX(0.05,NORMINV(RAND(),$C$8,$D$8))) | N10: =MIN(24,MAX(5,NORMINV(RAND(),$C$9,$D$9))) | O10: =$I$8*(SUMPRODUCT(($I$2*(1+K10)^{1;2;3;4;5;6;7;8;9;10})*(($I$3+(L10-$I$3)*{1;2;3;4;5;6;7;8;9;10}/10)*(1-$I$7)+$I$4-$I$4*($I$5+(1.05-$I$5)*{1;2;3;4;5;6;7;8;9;10}/10)-(K10/(1+K10))*$I$6)/(1+M10)^{1;2;3;4;5;6;7;8;9;10})+$I$2*(1+K10)^10*(L10+$I$4)*N10/(1+M10)^10+$I$9-$I$10)/$I$11
A11: SIMULATION OUTPUT — value / share (live) | H11: shares | I11: =Financials!AC17 | K11: =MAX(-0.05,NORMINV(RAND(),$C$6,$D$6)) | L11: =MAX(0.02,NORMINV(RAND(),$C$7,$D$7)) | M11: =MIN(0.16,MAX(0.05,NORMINV(RAND(),$C$8,$D$8))) | N11: =MIN(24,MAX(5,NORMINV(RAND(),$C$9,$D$9))) | O11: =$I$8*(SUMPRODUCT(($I$2*(1+K11)^{1;2;3;4;5;6;7;8;9;10})*(($I$3+(L11-$I$3)*{1;2;3;4;5;6;7;8;9;10}/10)*(1-$I$7)+$I$4-$I$4*($I$5+(1.05-$I$5)*{1;2;3;4;5;6;7;8;9;10}/10)-(K11/(1+K11))*$I$6)/(1+M11)^{1;2;3;4;5;6;7;8;9;10})+$I$2*(1+K11)^10*(L11+$I$4)*N11/(1+M11)^10+$I$9-$I$10)/$I$11
A12: Mean | B12: =AVERAGE($O$2:$O$1001) | K12: =MAX(-0.05,NORMINV(RAND(),$C$6,$D$6)) | L12: =MAX(0.02,NORMINV(RAND(),$C$7,$D$7)) | M12: =MIN(0.16,MAX(0.05,NORMINV(RAND(),$C$8,$D$8))) | N12: =MIN(24,MAX(5,NORMINV(RAND(),$C$9,$D$9))) | O12: =$I$8*(SUMPRODUCT(($I$2*(1+K12)^{1;2;3;4;5;6;7;8;9;10})*(($I$3+(L12-$I$3)*{1;2;3;4;5;6;7;8;9;10}/10)*(1-$I$7)+$I$4-$I$4*($I$5+(1.05-$I$5)*{1;2;3;4;5;6;7;8;9;10}/10)-(K12/(1+K12))*$I$6)/(1+M12)^{1;2;3;4;5;6;7;8;9;10})+$I$2*(1+K12)^10*(L12+$I$4)*N12/(1+M12)^10+$I$9-$I$10)/$I$11
A13: Median (P50) | B13: =MEDIAN($O$2:$O$1001) | K13: =MAX(-0.05,NORMINV(RAND(),$C$6,$D$6)) | L13: =MAX(0.02,NORMINV(RAND(),$C$7,$D$7)) | M13: =MIN(0.16,MAX(0.05,NORMINV(RAND(),$C$8,$D$8))) | N13: =MIN(24,MAX(5,NORMINV(RAND(),$C$9,$D$9))) | O13: =$I$8*(SUMPRODUCT(($I$2*(1+K13)^{1;2;3;4;5;6;7;8;9;10})*(($I$3+(L13-$I$3)*{1;2;3;4;5;6;7;8;9;10}/10)*(1-$I$7)+$I$4-$I$4*($I$5+(1.05-$I$5)*{1;2;3;4;5;6;7;8;9;10}/10)-(K13/(1+K13))*$I$6)/(1+M13)^{1;2;3;4;5;6;7;8;9;10})+$I$2*(1+K13)^10*(L13+$I$4)*N13/(1+M13)^10+$I$9-$I$10)/$I$11
A14: Std dev | B14: =STDEV($O$2:$O$1001) | K14: =MAX(-0.05,NORMINV(RAND(),$C$6,$D$6)) | L14: =MAX(0.02,NORMINV(RAND(),$C$7,$D$7)) | M14: =MIN(0.16,MAX(0.05,NORMINV(RAND(),$C$8,$D$8))) | N14: =MIN(24,MAX(5,NORMINV(RAND(),$C$9,$D$9))) | O14: =$I$8*(SUMPRODUCT(($I$2*(1+K14)^{1;2;3;4;5;6;7;8;9;10})*(($I$3+(L14-$I$3)*{1;2;3;4;5;6;7;8;9;10}/10)*(1-$I$7)+$I$4-$I$4*($I$5+(1.05-$I$5)*{1;2;3;4;5;6;7;8;9;10}/10)-(K14/(1+K14))*$I$6)/(1+M14)^{1;2;3;4;5;6;7;8;9;10})+$I$2*(1+K14)^10*(L14+$I$4)*N14/(1+M14)^10+$I$9-$I$10)/$I$11
A15: Min | B15: =MIN($O$2:$O$1001) | K15: =MAX(-0.05,NORMINV(RAND(),$C$6,$D$6)) | L15: =MAX(0.02,NORMINV(RAND(),$C$7,$D$7)) | M15: =MIN(0.16,MAX(0.05,NORMINV(RAND(),$C$8,$D$8))) | N15: =MIN(24,MAX(5,NORMINV(RAND(),$C$9,$D$9))) | O15: =$I$8*(SUMPRODUCT(($I$2*(1+K15)^{1;2;3;4;5;6;7;8;9;10})*(($I$3+(L15-$I$3)*{1;2;3;4;5;6;7;8;9;10}/10)*(1-$I$7)+$I$4-$I$4*($I$5+(1.05-$I$5)*{1;2;3;4;5;6;7;8;9;10}/10)-(K15/(1+K15))*$I$6)/(1+M15)^{1;2;3;4;5;6;7;8;9;10})+$I$2*(1+K15)^10*(L15+$I$4)*N15/(1+M15)^10+$I$9-$I$10)/$I$11
A16: Max | B16: =MAX($O$2:$O$1001) | K16: =MAX(-0.05,NORMINV(RAND(),$C$6,$D$6)) | L16: =MAX(0.02,NORMINV(RAND(),$C$7,$D$7)) | M16: =MIN(0.16,MAX(0.05,NORMINV(RAND(),$C$8,$D$8))) | N16: =MIN(24,MAX(5,NORMINV(RAND(),$C$9,$D$9))) | O16: =$I$8*(SUMPRODUCT(($I$2*(1+K16)^{1;2;3;4;5;6;7;8;9;10})*(($I$3+(L16-$I$3)*{1;2;3;4;5;6;7;8;9;10}/10)*(1-$I$7)+$I$4-$I$4*($I$5+(1.05-$I$5)*{1;2;3;4;5;6;7;8;9;10}/10)-(K16/(1+K16))*$I$6)/(1+M16)^{1;2;3;4;5;6;7;8;9;10})+$I$2*(1+K16)^10*(L16+$I$4)*N16/(1+M16)^10+$I$9-$I$10)/$I$11
A17: Current price | B17: =Valuation!$B$2 | K17: =MAX(-0.05,NORMINV(RAND(),$C$6,$D$6)) | L17: =MAX(0.02,NORMINV(RAND(),$C$7,$D$7)) | M17: =MIN(0.16,MAX(0.05,NORMINV(RAND(),$C$8,$D$8))) | N17: =MIN(24,MAX(5,NORMINV(RAND(),$C$9,$D$9))) | O17: =$I$8*(SUMPRODUCT(($I$2*(1+K17)^{1;2;3;4;5;6;7;8;9;10})*(($I$3+(L17-$I$3)*{1;2;3;4;5;6;7;8;9;10}/10)*(1-$I$7)+$I$4-$I$4*($I$5+(1.05-$I$5)*{1;2;3;4;5;6;7;8;9;10}/10)-(K17/(1+K17))*$I$6)/(1+M17)^{1;2;3;4;5;6;7;8;9;10})+$I$2*(1+K17)^10*(L17+$I$4)*N17/(1+M17)^10+$I$9-$I$10)/$I$11
A18: Base case (full model) | B18: =Valuation!B36 | K18: =MAX(-0.05,NORMINV(RAND(),$C$6,$D$6)) | L18: =MAX(0.02,NORMINV(RAND(),$C$7,$D$7)) | M18: =MIN(0.16,MAX(0.05,NORMINV(RAND(),$C$8,$D$8))) | N18: =MIN(24,MAX(5,NORMINV(RAND(),$C$9,$D$9))) | O18: =$I$8*(SUMPRODUCT(($I$2*(1+K18)^{1;2;3;4;5;6;7;8;9;10})*(($I$3+(L18-$I$3)*{1;2;3;4;5;6;7;8;9;10}/10)*(1-$I$7)+$I$4-$I$4*($I$5+(1.05-$I$5)*{1;2;3;4;5;6;7;8;9;10}/10)-(K18/(1+K18))*$I$6)/(1+M18)^{1;2;3;4;5;6;7;8;9;10})+$I$2*(1+K18)^10*(L18+$I$4)*N18/(1+M18)^10+$I$9-$I$10)/$I$11
K19: =MAX(-0.05,NORMINV(RAND(),$C$6,$D$6)) | L19: =MAX(0.02,NORMINV(RAND(),$C$7,$D$7)) | M19: =MIN(0.16,MAX(0.05,NORMINV(RAND(),$C$8,$D$8))) | N19: =MIN(24,MAX(5,NORMINV(RAND(),$C$9,$D$9))) | O19: =$I$8*(SUMPRODUCT(($I$2*(1+K19)^{1;2;3;4;5;6;7;8;9;10})*(($I$3+(L19-$I$3)*{1;2;3;4;5;6;7;8;9;10}/10)*(1-$I$7)+$I$4-$I$4*($I$5+(1.05-$I$5)*{1;2;3;4;5;6;7;8;9;10}/10)-(K19/(1+K19))*$I$6)/(1+M19)^{1;2;3;4;5;6;7;8;9;10})+$I$2*(1+K19)^10*(L19+$I$4)*N19/(1+M19)^10+$I$9-$I$10)/$I$11
A20: P(undervalued at current price) | B20: =COUNTIF($O$2:$O$1001,">"&Valuation!$B$2)/1000 | K20: =MAX(-0.05,NORMINV(RAND(),$C$6,$D$6)) | L20: =MAX(0.02,NORMINV(RAND(),$C$7,$D$7)) | M20: =MIN(0.16,MAX(0.05,NORMINV(RAND(),$C$8,$D$8))) | N20: =MIN(24,MAX(5,NORMINV(RAND(),$C$9,$D$9))) | O20: =$I$8*(SUMPRODUCT(($I$2*(1+K20)^{1;2;3;4;5;6;7;8;9;10})*(($I$3+(L20-$I$3)*{1;2;3;4;5;6;7;8;9;10}/10)*(1-$I$7)+$I$4-$I$4*($I$5+(1.05-$I$5)*{1;2;3;4;5;6;7;8;9;10}/10)-(K20/(1+K20))*$I$6)/(1+M20)^{1;2;3;4;5;6;7;8;9;10})+$I$2*(1+K20)^10*(L20+$I$4)*N20/(1+M20)^10+$I$9-$I$10)/$I$11
A21: P(>20% upside) | B21: =COUNTIF($O$2:$O$1001,">"&Valuation!$B$2*1.2)/1000 | K21: =MAX(-0.05,NORMINV(RAND(),$C$6,$D$6)) | L21: =MAX(0.02,NORMINV(RAND(),$C$7,$D$7)) | M21: =MIN(0.16,MAX(0.05,NORMINV(RAND(),$C$8,$D$8))) | N21: =MIN(24,MAX(5,NORMINV(RAND(),$C$9,$D$9))) | O21: =$I$8*(SUMPRODUCT(($I$2*(1+K21)^{1;2;3;4;5;6;7;8;9;10})*(($I$3+(L21-$I$3)*{1;2;3;4;5;6;7;8;9;10}/10)*(1-$I$7)+$I$4-$I$4*($I$5+(1.05-$I$5)*{1;2;3;4;5;6;7;8;9;10}/10)-(K21/(1+K21))*$I$6)/(1+M21)^{1;2;3;4;5;6;7;8;9;10})+$I$2*(1+K21)^10*(L21+$I$4)*N21/(1+M21)^10+$I$9-$I$10)/$I$11
K22: =MAX(-0.05,NORMINV(RAND(),$C$6,$D$6)) | L22: =MAX(0.02,NORMINV(RAND(),$C$7,$D$7)) | M22: =MIN(0.16,MAX(0.05,NORMINV(RAND(),$C$8,$D$8))) | N22: =MIN(24,MAX(5,NORMINV(RAND(),$C$9,$D$9))) | O22: =$I$8*(SUMPRODUCT(($I$2*(1+K22)^{1;2;3;4;5;6;7;8;9;10})*(($I$3+(L22-$I$3)*{1;2;3;4;5;6;7;8;9;10}/10)*(1-$I$7)+$I$4-$I$4*($I$5+(1.05-$I$5)*{1;2;3;4;5;6;7;8;9;10}/10)-(K22/(1+K22))*$I$6)/(1+M22)^{1;2;3;4;5;6;7;8;9;10})+$I$2*(1+K22)^10*(L22+$I$4)*N22/(1+M22)^10+$I$9-$I$10)/$I$11
A23: PERCENTILES (live) | K23: =MAX(-0.05,NORMINV(RAND(),$C$6,$D$6)) | L23: =MAX(0.02,NORMINV(RAND(),$C$7,$D$7)) | M23: =MIN(0.16,MAX(0.05,NORMINV(RAND(),$C$8,$D$8))) | N23: =MIN(24,MAX(5,NORMINV(RAND(),$C$9,$D$9))) | O23: =$I$8*(SUMPRODUCT(($I$2*(1+K23)^{1;2;3;4;5;6;7;8;9;10})*(($I$3+(L23-$I$3)*{1;2;3;4;5;6;7;8;9;10}/10)*(1-$I$7)+$I$4-$I$4*($I$5+(1.05-$I$5)*{1;2;3;4;5;6;7;8;9;10}/10)-(K23/(1+K23))*$I$6)/(1+M23)^{1;2;3;4;5;6;7;8;9;10})+$I$2*(1+K23)^10*(L23+$I$4)*N23/(1+M23)^10+$I$9-$I$10)/$I$11
A24: P5 | B24: =PERCENTILE($O$2:$O$1001,0.05) | K24: =MAX(-0.05,NORMINV(RAND(),$C$6,$D$6)) | L24: =MAX(0.02,NORMINV(RAND(),$C$7,$D$7)) | M24: =MIN(0.16,MAX(0.05,NORMINV(RAND(),$C$8,$D$8))) | N24: =MIN(24,MAX(5,NORMINV(RAND(),$C$9,$D$9))) | O24: =$I$8*(SUMPRODUCT(($I$2*(1+K24)^{1;2;3;4;5;6;7;8;9;10})*(($I$3+(L24-$I$3)*{1;2;3;4;5;6;7;8;9;10}/10)*(1-$I$7)+$I$4-$I$4*($I$5+(1.05-$I$5)*{1;2;3;4;5;6;7;8;9;10}/10)-(K24/(1+K24))*$I$6)/(1+M24)^{1;2;3;4;5;6;7;8;9;10})+$I$2*(1+K24)^10*(L24+$I$4)*N24/(1+M24)^10+$I$9-$I$10)/$I$11
A25: P10 | B25: =PERCENTILE($O$2:$O$1001,0.1) | K25: =MAX(-0.05,NORMINV(RAND(),$C$6,$D$6)) | L25: =MAX(0.02,NORMINV(RAND(),$C$7,$D$7)) | M25: =MIN(0.16,MAX(0.05,NORMINV(RAND(),$C$8,$D$8))) | N25: =MIN(24,MAX(5,NORMINV(RAND(),$C$9,$D$9))) | O25: =$I$8*(SUMPRODUCT(($I$2*(1+K25)^{1;2;3;4;5;6;7;8;9;10})*(($I$3+(L25-$I$3)*{1;2;3;4;5;6;7;8;9;10}/10)*(1-$I$7)+$I$4-$I$4*($I$5+(1.05-$I$5)*{1;2;3;4;5;6;7;8;9;10}/10)-(K25/(1+K25))*$I$6)/(1+M25)^{1;2;3;4;5;6;7;8;9;10})+$I$2*(1+K25)^10*(L25+$I$4)*N25/(1+M25)^10+$I$9-$I$10)/$I$11
A26: P25 | B26: =PERCENTILE($O$2:$O$1001,0.25) | K26: =MAX(-0.05,NORMINV(RAND(),$C$6,$D$6)) | L26: =MAX(0.02,NORMINV(RAND(),$C$7,$D$7)) | M26: =MIN(0.16,MAX(0.05,NORMINV(RAND(),$C$8,$D$8))) | N26: =MIN(24,MAX(5,NORMINV(RAND(),$C$9,$D$9))) | O26: =$I$8*(SUMPRODUCT(($I$2*(1+K26)^{1;2;3;4;5;6;7;8;9;10})*(($I$3+(L26-$I$3)*{1;2;3;4;5;6;7;8;9;10}/10)*(1-$I$7)+$I$4-$I$4*($I$5+(1.05-$I$5)*{1;2;3;4;5;6;7;8;9;10}/10)-(K26/(1+K26))*$I$6)/(1+M26)^{1;2;3;4;5;6;7;8;9;10})+$I$2*(1+K26)^10*(L26+$I$4)*N26/(1+M26)^10+$I$9-$I$10)/$I$11
A27: P50 | B27: =PERCENTILE($O$2:$O$1001,0.5) | K27: =MAX(-0.05,NORMINV(RAND(),$C$6,$D$6)) | L27: =MAX(0.02,NORMINV(RAND(),$C$7,$D$7)) | M27: =MIN(0.16,MAX(0.05,NORMINV(RAND(),$C$8,$D$8))) | N27: =MIN(24,MAX(5,NORMINV(RAND(),$C$9,$D$9))) | O27: =$I$8*(SUMPRODUCT(($I$2*(1+K27)^{1;2;3;4;5;6;7;8;9;10})*(($I$3+(L27-$I$3)*{1;2;3;4;5;6;7;8;9;10}/10)*(1-$I$7)+$I$4-$I$4*($I$5+(1.05-$I$5)*{1;2;3;4;5;6;7;8;9;10}/10)-(K27/(1+K27))*$I$6)/(1+M27)^{1;2;3;4;5;6;7;8;9;10})+$I$2*(1+K27)^10*(L27+$I$4)*N27/(1+M27)^10+$I$9-$I$10)/$I$11
A28: P75 | B28: =PERCENTILE($O$2:$O$1001,0.75) | K28: =MAX(-0.05,NORMINV(RAND(),$C$6,$D$6)) | L28: =MAX(0.02,NORMINV(RAND(),$C$7,$D$7)) | M28: =MIN(0.16,MAX(0.05,NORMINV(RAND(),$C$8,$D$8))) | N28: =MIN(24,MAX(5,NORMINV(RAND(),$C$9,$D$9))) | O28: =$I$8*(SUMPRODUCT(($I$2*(1+K28)^{1;2;3;4;5;6;7;8;9;10})*(($I$3+(L28-$I$3)*{1;2;3;4;5;6;7;8;9;10}/10)*(1-$I$7)+$I$4-$I$4*($I$5+(1.05-$I$5)*{1;2;3;4;5;6;7;8;9;10}/10)-(K28/(1+K28))*$I$6)/(1+M28)^{1;2;3;4;5;6;7;8;9;10})+$I$2*(1+K28)^10*(L28+$I$4)*N28/(1+M28)^10+$I$9-$I$10)/$I$11
A29: P90 | B29: =PERCENTILE($O$2:$O$1001,0.9) | K29: =MAX(-0.05,NORMINV(RAND(),$C$6,$D$6)) | L29: =MAX(0.02,NORMINV(RAND(),$C$7,$D$7)) | M29: =MIN(0.16,MAX(0.05,NORMINV(RAND(),$C$8,$D$8))) | N29: =MIN(24,MAX(5,NORMINV(RAND(),$C$9,$D$9))) | O29: =$I$8*(SUMPRODUCT(($I$2*(1+K29)^{1;2;3;4;5;6;7;8;9;10})*(($I$3+(L29-$I$3)*{1;2;3;4;5;6;7;8;9;10}/10)*(1-$I$7)+$I$4-$I$4*($I$5+(1.05-$I$5)*{1;2;3;4;5;6;7;8;9;10}/10)-(K29/(1+K29))*$I$6)/(1+M29)^{1;2;3;4;5;6;7;8;9;10})+$I$2*(1+K29)^10*(L29+$I$4)*N29/(1+M29)^10+$I$9-$I$10)/$I$11
A30: P95 | B30: =PERCENTILE($O$2:$O$1001,0.95) | K30: =MAX(-0.05,NORMINV(RAND(),$C$6,$D$6)) | L30: =MAX(0.02,NORMINV(RAND(),$C$7,$D$7)) | M30: =MIN(0.16,MAX(0.05,NORMINV(RAND(),$C$8,$D$8))) | N30: =MIN(24,MAX(5,NORMINV(RAND(),$C$9,$D$9))) | O30: =$I$8*(SUMPRODUCT(($I$2*(1+K30)^{1;2;3;4;5;6;7;8;9;10})*(($I$3+(L30-$I$3)*{1;2;3;4;5;6;7;8;9;10}/10)*(1-$I$7)+$I$4-$I$4*($I$5+(1.05-$I$5)*{1;2;3;4;5;6;7;8;9;10}/10)-(K30/(1+K30))*$I$6)/(1+M30)^{1;2;3;4;5;6;7;8;9;10})+$I$2*(1+K30)^10*(L30+$I$4)*N30/(1+M30)^10+$I$9-$I$10)/$I$11
K31: =MAX(-0.05,NORMINV(RAND(),$C$6,$D$6)) | L31: =MAX(0.02,NORMINV(RAND(),$C$7,$D$7)) | M31: =MIN(0.16,MAX(0.05,NORMINV(RAND(),$C$8,$D$8))) | N31: =MIN(24,MAX(5,NORMINV(RAND(),$C$9,$D$9))) | O31: =$I$8*(SUMPRODUCT(($I$2*(1+K31)^{1;2;3;4;5;6;7;8;9;10})*(($I$3+(L31-$I$3)*{1;2;3;4;5;6;7;8;9;10}/10)*(1-$I$7)+$I$4-$I$4*($I$5+(1.05-$I$5)*{1;2;3;4;5;6;7;8;9;10}/10)-(K31/(1+K31))*$I$6)/(1+M31)^{1;2;3;4;5;6;7;8;9;10})+$I$2*(1+K31)^10*(L31+$I$4)*N31/(1+M31)^10+$I$9-$I$10)/$I$11
A32: VALUE DISTRIBUTION (live histogram) | K32: =MAX(-0.05,NORMINV(RAND(),$C$6,$D$6)) | L32: =MAX(0.02,NORMINV(RAND(),$C$7,$D$7)) | M32: =MIN(0.16,MAX(0.05,NORMINV(RAND(),$C$8,$D$8))) | N32: =MIN(24,MAX(5,NORMINV(RAND(),$C$9,$D$9))) | O32: =$I$8*(SUMPRODUCT(($I$2*(1+K32)^{1;2;3;4;5;6;7;8;9;10})*(($I$3+(L32-$I$3)*{1;2;3;4;5;6;7;8;9;10}/10)*(1-$I$7)+$I$4-$I$4*($I$5+(1.05-$I$5)*{1;2;3;4;5;6;7;8;9;10}/10)-(K32/(1+K32))*$I$6)/(1+M32)^{1;2;3;4;5;6;7;8;9;10})+$I$2*(1+K32)^10*(L32+$I$4)*N32/(1+M32)^10+$I$9-$I$10)/$I$11
A33: Bin midpoint ($/sh) | B33: Count | K33: =MAX(-0.05,NORMINV(RAND(),$C$6,$D$6)) | L33: =MAX(0.02,NORMINV(RAND(),$C$7,$D$7)) | M33: =MIN(0.16,MAX(0.05,NORMINV(RAND(),$C$8,$D$8))) | N33: =MIN(24,MAX(5,NORMINV(RAND(),$C$9,$D$9))) | O33: =$I$8*(SUMPRODUCT(($I$2*(1+K33)^{1;2;3;4;5;6;7;8;9;10})*(($I$3+(L33-$I$3)*{1;2;3;4;5;6;7;8;9;10}/10)*(1-$I$7)+$I$4-$I$4*($I$5+(1.05-$I$5)*{1;2;3;4;5;6;7;8;9;10}/10)-(K33/(1+K33))*$I$6)/(1+M33)^{1;2;3;4;5;6;7;8;9;10})+$I$2*(1+K33)^10*(L33+$I$4)*N33/(1+M33)^10+$I$9-$I$10)/$I$11
A34: =$B$15+0.5*($B$16-$B$15)/15 | B34: =COUNTIFS($O$2:$O$1001,">="&($B$15+0*($B$16-$B$15)/15),$O$2:$O$1001,"<"&($B$15+1*($B$16-$B$15)/15)) | K34: =MAX(-0.05,NORMINV(RAND(),$C$6,$D$6)) | L34: =MAX(0.02,NORMINV(RAND(),$C$7,$D$7)) | M34: =MIN(0.16,MAX(0.05,NORMINV(RAND(),$C$8,$D$8))) | N34: =MIN(24,MAX(5,NORMINV(RAND(),$C$9,$D$9))) | O34: =$I$8*(SUMPRODUCT(($I$2*(1+K34)^{1;2;3;4;5;6;7;8;9;10})*(($I$3+(L34-$I$3)*{1;2;3;4;5;6;7;8;9;10}/10)*(1-$I$7)+$I$4-$I$4*($I$5+(1.05-$I$5)*{1;2;3;4;5;6;7;8;9;10}/10)-(K34/(1+K34))*$I$6)/(1+M34)^{1;2;3;4;5;6;7;8;9;10})+$I$2*(1+K34)^10*(L34+$I$4)*N34/(1+M34)^10+$I$9-$I$10)/$I$11
A35: =$B$15+1.5*($B$16-$B$15)/15 | B35: =COUNTIFS($O$2:$O$1001,">="&($B$15+1*($B$16-$B$15)/15),$O$2:$O$1001,"<"&($B$15+2*($B$16-$B$15)/15)) | K35: =MAX(-0.05,NORMINV(RAND(),$C$6,$D$6)) | L35: =MAX(0.02,NORMINV(RAND(),$C$7,$D$7)) | M35: =MIN(0.16,MAX(0.05,NORMINV(RAND(),$C$8,$D$8))) | N35: =MIN(24,MAX(5,NORMINV(RAND(),$C$9,$D$9))) | O35: =$I$8*(SUMPRODUCT(($I$2*(1+K35)^{1;2;3;4;5;6;7;8;9;10})*(($I$3+(L35-$I$3)*{1;2;3;4;5;6;7;8;9;10}/10)*(1-$I$7)+$I$4-$I$4*($I$5+(1.05-$I$5)*{1;2;3;4;5;6;7;8;9;10}/10)-(K35/(1+K35))*$I$6)/(1+M35)^{1;2;3;4;5;6;7;8;9;10})+$I$2*(1+K35)^10*(L35+$I$4)*N35/(1+M35)^10+$I$9-$I$10)/$I$11
A36: =$B$15+2.5*($B$16-$B$15)/15 | B36: =COUNTIFS($O$2:$O$1001,">="&($B$15+2*($B$16-$B$15)/15),$O$2:$O$1001,"<"&($B$15+3*($B$16-$B$15)/15)) | K36: =MAX(-0.05,NORMINV(RAND(),$C$6,$D$6)) | L36: =MAX(0.02,NORMINV(RAND(),$C$7,$D$7)) | M36: =MIN(0.16,MAX(0.05,NORMINV(RAND(),$C$8,$D$8))) | N36: =MIN(24,MAX(5,NORMINV(RAND(),$C$9,$D$9))) | O36: =$I$8*(SUMPRODUCT(($I$2*(1+K36)^{1;2;3;4;5;6;7;8;9;10})*(($I$3+(L36-$I$3)*{1;2;3;4;5;6;7;8;9;10}/10)*(1-$I$7)+$I$4-$I$4*($I$5+(1.05-$I$5)*{1;2;3;4;5;6;7;8;9;10}/10)-(K36/(1+K36))*$I$6)/(1+M36)^{1;2;3;4;5;6;7;8;9;10})+$I$2*(1+K36)^10*(L36+$I$4)*N36/(1+M36)^10+$I$9-$I$10)/$I$11
