Workbook

Sheet Cover
A1: Rubrik, Inc. (RBRK)
A2: DCF valuation — exit-multiple terminal · defaults anchored to consensus
A4: Last updated | B4: 2026-07-08
A5: Data pulled (FMP) | B5: Q1 2027
A6: Assumptions by | B6: Opus 4.8 — values as of 2026-06-11 (provenance seeded)
A8: VALUATION SUMMARY
A10: Fair value / share | B10: =Valuation!B36
A11: Current price | B11: =Valuation!$B$2
A12: Upside / (downside) | B12: =Valuation!B42
A13: Verdict | B13: =IF(Valuation!B36>Valuation!$B$2,"Undervalued","Overvalued")
A14: Monte Carlo P(undervalued) | B14: ='Monte Carlo'!B20
A15: KEY ASSUMPTIONS
A17: WACC (from WACC tab) | B17: =WACC!B15
A18: Terminal method | B18: =Valuation!$B$6
A19: Exit basis / multiple | B19: =Valuation!$B$7
A20: Exit multiple | B20: =Valuation!$B$8
A21: Terminal growth (g) | B21: =Valuation!$B$4
A22: Terminal weight | B22: =Valuation!B39
A23: Forecast horizon | B23: 10 years
A25: THE STORY (Opus)
A27: Rubrik is a subscription-led cyber-resilience platform consolidating ransomware recovery and cloud data protection, with subscription ARR (96% of revenue) compounding in the low-50s% but decelerating toward a low-20s% blended pace consistent with consensus revenue of $1.6B (2027) scaling to $3.1B (2031). As the IPO-era CAC cycle normalizes and land-and-expand deepens NRR above 120%, operating leverage inflects from deeply negative FY26 margins to a mid-single-digit operating margin near-term, maturing toward a ~25% best-in-class infrastructure-software margin by year 10. Capex stays asset-light (~1.2% of revenue) and converges to maintenance levels (capex/D&A ~1.1x) as the model matures.

Sheet Dashboard
A1: Rubrik, Inc. (RBRK) — Control Dashboard
A2: Edit the yellow cells; everything recomputes. Orange = a driver you've moved off consensus.
A4: VERDICT
A5: Fair value / share | B5: =Valuation!B36
A6: Current price | B6: =Dashboard!$B$48
A7: Upside / (downside) | B7: =Valuation!B42
A8: Verdict | B8: =IF(Valuation!B36>Dashboard!$B$48,"Undervalued","Overvalued")
A9: Monte Carlo P(undervalued) | B9: ='Monte Carlo'!B20
A11: GUARDRAIL SIGNALS (are my assumptions sane?)
A12: Signal | B12: Value | C12: Flag | D12: Healthy
A13: Terminal weight (% of EV) | B13: =Valuation!B39 | C13: =IF(Valuation!B39>0.9,"! high","ok") | D13: < 90%
A14: Implied g vs exit multiple | B14: =Valuation!B40 | C14: =IF(Valuation!B40>Dashboard!$B$46+0.02,"! rich","ok") | D14: near term g
A15: ROIC - WACC (2026) | B15: =IF(Model!E34<=0,"n/a (neg. capital)",Model!F36-WACC!B15) | C15: =IF(Model!E34<=0,"n/a",IF(Model!F36-WACC!B15<0,"! destroys","creates")) | D15: > 0
A16: Revenue vs consensus (2026) | B16: =Consensus!B6 | C16: =IF(ABS(Consensus!B6)>0.05,"! off-Street","on") | D16: +/- 5%
A17: MC P(undervalued) | B17: ='Monte Carlo'!B20 | C17: =IF('Monte Carlo'!B20<0.5,"! coin-flip","ok") | D17: context
A18: REVENUE DRIVERS — near-term & terminal growth per segment
A19: Segment | B19: Near-term | C19: Terminal | D19: Consensus | E19: Thesis claim
A20: Total company | B20: 0.18806312 | C20: 0.05 | D20: 0.18806312
A28: PROFITABILITY & TAX
A29: Near-term operating margin | B29: 0.05 | D29: 0.05 | E29: consensus-implied; ramps to terminal
A30: Terminal operating margin | B30: 0.25 | E30: AI/ads mix + operating leverage
A31: Tax rate | B31: 0.25
A33: CAPITAL INTENSITY
A34: 2026 capex ($M) | B34: 19.282552 | D34: 19.282552 | E34: ~last-year capex +10%; set to guidance
A35: Terminal capex / D&A | B35: 1.05 | E35: converges to ~1.0x as build-out matures
A37: DISCOUNT RATE & TERMINAL
A38: Risk-free rate (10Y) | B38: 0.043
A39: Equity risk premium | B39: 0.045
A40: Beta (levered) | B40: 1.1 | E40: FMP raw beta; Damodaran bottom-up ~1.2
A41: Pre-tax cost of debt | B41: 0.045
A42: WACC (computed) | B42: =WACC!B15
A43: Terminal method | B43: Exit multiple
A44: Exit basis | B44: EV/Sales
A45: Exit multiple | B45: 6
A46: Terminal growth (g) | B46: 0.04
A47: Country risk premium | B47: 0 | E47: Damodaran country premiums, revenue-weighted (2026-01); 0 for US/mature
A48: Current price | B48: 84.245003
A49: Growth fade curvature | B49: 2 | E49: convexity of the near->terminal growth fade, fit to consensus (1.0=linear); higher = faster early deceleration
A50: SCENARIOS — Bull / Bear offsets vs Base (edit the yellow Δs)
A51: Scenario lever | B51: Base | C51: Bull Δ | D51: Bear Δ
...

Sheet Assumptions
A1: RBRK — Assumptions & Reasoning
A2: Provenance of every Dashboard input. Read-only — regenerated by each build/refresh. Current is a live link to the Dashboard; Source / Opus value / Note are as of the last refresh_dcf run.
A4: Assumptions baseline | B4: seeded 2026-06-11 from the synced assumptions block (pass predates provenance tracking — may already include your edits)
A6: THE STORY (Opus narrative)
A7: Rubrik is a subscription-led cyber-resilience platform consolidating ransomware recovery and cloud data protection, with subscription ARR (96% of revenue) compounding in the low-50s% but decelerating toward a low-20s% blended pace consistent with consensus revenue of $1.6B (2027) scaling to $3.1B (2031). As the IPO-era CAC cycle normalizes and land-and-expand deepens NRR above 120%, operating leverage inflects from deeply negative FY26 margins to a mid-single-digit operating margin near-term, maturing toward a ~25% best-in-class infrastructure-software margin by year 10. Capex stays asset-light (~1.2% of revenue) and converges to maintenance levels (capex/D&A ~1.1x) as the model matures.
A12: KEY JUDGMENTS (Opus reasoning)
A13: Growth is anchored to Street consensus near-term (~22% blended) rather than the unsustainable 52% subscription print, then faded to a 4% terminal rate near the risk-free anchor, with the tiny shrinking Maintenance line held flat. Terminal margin of 25% reflects normalized SaaS economics achievable via operating leverage but stops short of mature giants given continued reinvestment, and an EV/Sales exit of 6x is the basis the market actually applies to high-retention infrastructure SaaS, cross-checked as reasonable against a 25% terminal operating margin.
A18: DASHBOARD INPUTS — value · source · reasoning
A19: Input | B19: Cell | C19: Current | D19: Source | E19: Opus value | F19: Note
A20: Total company — near-term growth | B20: B20 | C20: =Dashboard!B20 | D20: builder default | E20: —
A21: Total company — terminal growth | B21: C20 | C21: =Dashboard!C20 | D21: builder default | E21: —
A22: Near-term operating margin | B22: B29 | C22: =Dashboard!B29 | D22: Opus | E22: 5.0%
A23: Terminal operating margin | B23: B30 | C23: =Dashboard!B30 | D23: Opus | E23: 25.0%
A24: Tax rate | B24: B31 | C24: =Dashboard!B31 | D24: Opus | E24: 25.0%
A25: Terminal capex / D&A | B25: B35 | C25: =Dashboard!B35 | D25: Opus | E25: 1.1x
A26: Risk-free rate (10Y) | B26: B38 | C26: =Dashboard!B38 | D26: Opus | E26: 4.3%
A27: Equity risk premium | B27: B39 | C27: =Dashboard!B39 | D27: Opus | E27: 4.5%
A28: Beta (levered) | B28: B40 | C28: =Dashboard!B40 | D28: Opus | E28: 1.100
A29: Pre-tax cost of debt | B29: B41 | C29: =Dashboard!B41 | D29: Opus | E29: 4.5%
A30: Terminal method | B30: B43 | C30: =Dashboard!B43 | D30: Opus | E30: Exit multiple
A31: Exit basis | B31: B44 | C31: =Dashboard!B44 | D31: Opus | E31: EV/Sales
A32: Exit multiple | B32: B45 | C32: =Dashboard!B45 | D32: Opus | E32: 6.0x
A33: Terminal growth (g) | B33: B46 | C33: =Dashboard!B46 | D33: Opus | E33: 4.0%
A34: 2026 capex ($M) | B34: B34 | C34: =Dashboard!B34 | D34: Opus | E34: — | F34: set from Opus 1% of FY1E revenue; edits not tracked (unit differs from the JSON)
A35: Bull Δ — segment growth, near-term | B35: C52 | C35: =Dashboard!C52 | D35: seed default | E35: 3.0%
A36: Bear Δ — segment growth, near-term | B36: D52 | C36: =Dashboard!D52 | D36: seed default | E36: -3.0%
A37: Bull Δ — segment growth, terminal | B37: C53 | C37: =Dashboard!C53 | D37: seed default | E37: 1.0%
A38: Bear Δ — segment growth, terminal | B38: D53 | C38: =Dashboard!D53 | D38: seed default | E38: -1.0%
A39: Bull Δ — operating margin, near-term | B39: C54 | C39: =Dashboard!C54 | D39: seed default | E39: 1.0%
A40: Bear Δ — operating margin, near-term | B40: D54 | C40: =Dashboard!D54 | D40: seed default | E40: -1.0%
A41: Bull Δ — operating margin, terminal | B41: C55 | C41: =Dashboard!C55 | D41: seed default | E41: 2.0%
A42: Bear Δ — operating margin, terminal | B42: D55 | C42: =Dashboard!D55 | D42: seed default | E42: -2.0%
A43: Bull Δ — exit multiple | B43: C56 | C43: =Dashboard!C56 | D43: seed default | E43: 2.0x
A44: Bear Δ — exit multiple | B44: D56 | C44: =Dashboard!D56 | D44: seed default | E44: -2.0x
A45: Bull Δ — terminal growth (g) | B45: C57 | C45: =Dashboard!C57 | D45: seed default | E45: 0.5%
A46: Bear Δ — terminal growth (g) | B46: D57 | C46: =Dashboard!D57 | D46: seed default | E46: -0.5%

Sheet Color Code
A1: Color | B1: Meaning
A2: Black | B2: Formula-driven (same-sheet)
A3: Blue | B3: Hard-coded actuals (from FMP filings)
A4: Yellow | B4: An assumption you can change — edit these to drive the model
A5: Green | B5: A formula that links to another sheet
A6: Orange | B6: (Dashboard) an assumption you've moved off consensus — your active bet
A7: How to use | B7: Edit yellow cells (Model assumptions, WACC drivers, Valuation toggles). Everything else recomputes.

Sheet WACC
A1: WACC Calculator
A2: Risk-free rate (10Y) | B2: =Dashboard!$B$38
A3: Equity risk premium | B3: =Dashboard!$B$39
A4: Beta (levered) | B4: =Dashboard!$B$40
A5: Country risk premium | B5: =Dashboard!$B$47
A6: Cost of equity (CAPM) | B6: =B2+B4*B3+B5
A7: Pre-tax cost of debt | B7: =Dashboard!$B$41
A8: Tax rate | B8: =Dashboard!$B$31
A9: After-tax cost of debt | B9: =B7*(1-B8)
A10: Market cap (E) | B10: =Dashboard!$B$48*Financials!R17
A11: Total debt (D) | B11: =Financials!R24
A12: Equity weight | B12: =B10/(B10+B11)
A13: Debt weight | B13: =B11/(B10+B11)
A15: WACC | B15: =B12*B6+B13*B9
A17: Yellow = edit. CAPM cost of equity (incl. country risk premium); market-value weights. Feeds Valuation!WACC.

Sheet Model
A1: $M unless noted | B1: FY2023A | C1: FY2024A | D1: FY2025A | E1: FY2026A | F1: FY2027E | G1: FY2028E | H1: FY2029E | I1: FY2030E | J1: FY2031E | K1: FY2032E | L1: FY2033E | M1: FY2034E | N1: FY2035E | O1: FY2036E
A3: REVENUE BY SEGMENT (yellow = growth assumption; actuals link to Financials)
A4: Total company | B4: =SUM(Financials!B3:E3) | C4: =SUM(Financials!F3:I3) | D4: =SUM(Financials!J3:M3) | E4: =SUM(Financials!N3:Q3) | F4: =E4*(1+F5) | G4: =F4*(1+G5) | H4: =G4*(1+H5) | I4: =H4*(1+I5) | J4: =I4*(1+J5) | K4: =J4*(1+K5) | L4: =K4*(1+L5) | M4: =L4*(1+M5) | ... O4: =N4*(1+O5)
A5: growth % (convex fade; curvature from Dashboard) | C5: =IFERROR(C4/B4-1,"") | D5: =IFERROR(D4/C4-1,"") | E5: =IFERROR(E4/D4-1,"") | F5: =Dashboard!$C$20+(Dashboard!$B$20-Dashboard!$C$20)*((9-0)/9)^Dashboard!$B$49 | G5: =Dashboard!$C$20+(Dashboard!$B$20-Dashboard!$C$20)*((9-1)/9)^Dashboard!$B$49 | H5: =Dashboard!$C$20+(Dashboard!$B$20-Dashboard!$C$20)*((9-2)/9)^Dashboard!$B$49 | I5: =Dashboard!$C$20+(Dashboard!$B$20-Dashboard!$C$20)*((9-3)/9)^Dashboard!$B$49 | J5: =Dashboard!$C$20+(Dashboard!$B$20-Dashboard!$C$20)*((9-4)/9)^Dashboard!$B$49 | K5: =Dashboard!$C$20+(Dashboard!$B$20-Dashboard!$C$20)*((9-5)/9)^Dashboard!$B$49 | L5: =Dashboard!$C$20+(Dashboard!$B$20-Dashboard!$C$20)*((9-6)/9)^Dashboard!$B$49 | M5: =Dashboard!$C$20+(Dashboard!$B$20-Dashboard!$C$20)*((9-7)/9)^Dashboard!$B$49 | N5: =Dashboard!$C$20+(Dashboard!$B$20-Dashboard!$C$20)*((9-8)/9)^Dashboard!$B$49 | O5: =Dashboard!$C$20+(Dashboard!$B$20-Dashboard!$C$20)*((9-9)/9)^Dashboard!$B$49
A6: Total revenue | B6: =B4 | C6: =C4 | D6: =D4 | E6: =E4 | F6: =F4 | G6: =G4 | H6: =H4 | I6: =I4 | ... O6: =O4
A7: growth % | C7: =IFERROR(C6/B6-1,"") | D7: =IFERROR(D6/C6-1,"") | E7: =IFERROR(E6/D6-1,"") | F7: =IFERROR(F6/E6-1,"") | G7: =IFERROR(G6/F6-1,"") | H7: =IFERROR(H6/G6-1,"") | I7: =IFERROR(I6/H6-1,"") | J7: =IFERROR(J6/I6-1,"") | ... O7: =IFERROR(O6/N6-1,"")
A9: COST STRUCTURE (yellow = % of revenue)
A10: Cost of revenue | B10: =SUM(Financials!B5:E5) | C10: =SUM(Financials!F5:I5) | D10: =SUM(Financials!J5:M5) | E10: =SUM(Financials!N5:Q5) | F10: =F6*F11 | G10: =G6*G11 | H10: =H6*H11 | I10: =I6*I11 | J10: =J6*J11 | K10: =K6*K11 | L10: =L6*L11 | M10: =M6*M11 | ... O10: =O6*O11
A11: % of revenue | B11: =IFERROR(B10/B6,"") | C11: =IFERROR(C10/C6,"") | D11: =IFERROR(D10/D6,"") | E11: =IFERROR(E10/E6,"") | F11: 0.1989658 | G11: 0.1989658 | H11: 0.1989658 | I11: 0.1989658 | J11: 0.1989658 | K11: 0.1989658 | L11: 0.1989658 | M11: 0.1989658 | N11: 0.1989658 | O11: 0.1989658
A12: R&D / Technology | B12: =SUM(Financials!B7:E7) | C12: =SUM(Financials!F7:I7) | D12: =SUM(Financials!J7:M7) | E12: =SUM(Financials!N7:Q7) | F12: =F6*F13 | G12: =G6*G13 | H12: =H6*H13 | I12: =I6*I13 | J12: =J6*J13 | K12: =K6*K13 | L12: =L6*L13 | M12: =M6*M13 | ... O12: =O6*O13
A13: % of revenue | B13: =IFERROR(B12/B6,"") | C13: =IFERROR(C12/C6,"") | D13: =IFERROR(D12/D6,"") | E13: =IFERROR(E12/E6,"") | F13: 0.28391168 | G13: 0.28391168 | H13: 0.28391168 | I13: 0.28391168 | J13: 0.28391168 | K13: 0.28391168 | L13: 0.28391168 | M13: 0.28391168 | N13: 0.28391168 | O13: 0.28391168
A14: SG&A | B14: =SUM(Financials!B9:E9) | C14: =SUM(Financials!F9:I9) | D14: =SUM(Financials!J9:M9) | E14: =SUM(Financials!N9:Q9) | F14: =F6*F15 | G14: =G6*G15 | H14: =H6*H15 | I14: =I6*I15 | J14: =J6*J15 | K14: =K6*K15 | L14: =L6*L15 | M14: =M6*M15 | ... O14: =O6*O15
A15: % of revenue | B15: =IFERROR(B14/B6,"") | C15: =IFERROR(C14/C6,"") | D15: =IFERROR(D14/D6,"") | E15: =IFERROR(E14/E6,"") | F15: 0.77955859 | G15: 0.77955859 | H15: 0.77955859 | I15: 0.77955859 | J15: 0.77955859 | K15: 0.77955859 | L15: 0.77955859 | M15: 0.77955859 | N15: 0.77955859 | O15: 0.77955859
A16: Other opex (fulfilment, etc.) | B16: =B6-(B10+B12+B14)-SUM(Financials!B13:E13) | C16: =C6-(C10+C12+C14)-SUM(Financials!F13:I13) | D16: =D6-(D10+D12+D14)-SUM(Financials!J13:M13) | E16: =E6-(E10+E12+E14)-SUM(Financials!N13:Q13) | F16: =F6*(1-(Dashboard!$B$29+(Dashboard!$B$30-Dashboard!$B$29)*MIN(1,0/4)))-(F10+F12+F14) | G16: =G6*(1-(Dashboard!$B$29+(Dashboard!$B$30-Dashboard!$B$29)*MIN(1,1/4)))-(G10+G12+G14) | H16: =H6*(1-(Dashboard!$B$29+(Dashboard!$B$30-Dashboard!$B$29)*MIN(1,2/4)))-(H10+H12+H14) | I16: =I6*(1-(Dashboard!$B$29+(Dashboard!$B$30-Dashboard!$B$29)*MIN(1,3/4)))-(I10+I12+I14) | J16: =J6*(1-(Dashboard!$B$29+(Dashboard!$B$30-Dashboard!$B$29)*MIN(1,4/4)))-(J10+J12+J14) | K16: =K6*(1-(Dashboard!$B$29+(Dashboard!$B$30-Dashboard!$B$29)*MIN(1,5/4)))-(K10+K12+K14) | L16: =L6*(1-(Dashboard!$B$29+(Dashboard!$B$30-Dashboard!$B$29)*MIN(1,6/4)))-(L10+L12+L14) | M16: =M6*(1-(Dashboard!$B$29+(Dashboard!$B$30-Dashboard!$B$29)*MIN(1,7/4)))-(M10+M12+M14) | N16: =N6*(1-(Dashboard!$B$29+(Dashboard!$B$30-Dashboard!$B$29)*MIN(1,8/4)))-(N10+N12+N14) | O16: =O6*(1-(Dashboard!$B$29+(Dashboard!$B$30-Dashboard!$B$29)*MIN(1,9/4)))-(O10+O12+O14)
A17: % of revenue | B17: =IFERROR(B16/B6,"") | C17: =IFERROR(C16/C6,"") | D17: =IFERROR(D16/D6,"") | E17: =IFERROR(E16/E6,"") | F17: =IFERROR(F16/F6,"") | G17: =IFERROR(G16/G6,"") | H17: =IFERROR(H16/H6,"") | I17: =IFERROR(I16/I6,"") | ... O17: =IFERROR(O16/O6,"")
A19: Operating income (EBIT) | B19: =B6-(B10+B12+B14)-B16 | C19: =C6-(C10+C12+C14)-C16 | D19: =D6-(D10+D12+D14)-D16 | E19: =E6-(E10+E12+E14)-E16 | F19: =F6-(F10+F12+F14)-F16 | G19: =G6-(G10+G12+G14)-G16 | H19: =H6-(H10+H12+H14)-H16 | I19: =I6-(I10+I12+I14)-I16 | ... O19: =O6-(O10+O12+O14)-O16
A20: operating margin | B20: =IFERROR(B19/B6,"") | C20: =IFERROR(C19/C6,"") | D20: =IFERROR(D19/D6,"") | E20: =IFERROR(E19/E6,"") | F20: =IFERROR(F19/F6,"") | G20: =IFERROR(G19/G6,"") | H20: =IFERROR(H19/H6,"") | I20: =IFERROR(I19/I6,"") | ... O20: =IFERROR(O19/O6,"")
A22: FCF BRIDGE (NOPAT + D&A + SBC - dNWC - Capex)
A23: NOPAT = EBIT x (1 - tax) | B23: =B19*(1-Valuation!$B$5) | C23: =C19*(1-Valuation!$B$5) | D23: =D19*(1-Valuation!$B$5) | E23: =E19*(1-Valuation!$B$5) | F23: =F19*(1-Valuation!$B$5) | G23: =G19*(1-Valuation!$B$5) | H23: =H19*(1-Valuation!$B$5) | I23: =I19*(1-Valuation!$B$5) | ... O23: =O19*(1-Valuation!$B$5)
A24: + D&A | B24: =SUM(Financials!B27:E27) | C24: =SUM(Financials!F27:I27) | D24: =SUM(Financials!J27:M27) | E24: =SUM(Financials!N27:Q27) | F24: =F6*0.0125 | G24: =G6*0.0125 | H24: =H6*0.0125 | I24: =I6*0.0125 | J24: =J6*0.0125 | K24: =K6*0.0125 | L24: =L6*0.0125 | M24: =M6*0.0125 | ... O24: =O6*0.0125
A25: + SBC (non-cash) | B25: =SUM(Financials!B28:E28) | C25: =SUM(Financials!F28:I28) | D25: =SUM(Financials!J28:M28) | E25: =SUM(Financials!N28:Q28) | F25: =F6*(Dashboard!$B$65+(Dashboard!$B$66-Dashboard!$B$65)*0/9) | G25: =G6*(Dashboard!$B$65+(Dashboard!$B$66-Dashboard!$B$65)*1/9) | H25: =H6*(Dashboard!$B$65+(Dashboard!$B$66-Dashboard!$B$65)*2/9) | I25: =I6*(Dashboard!$B$65+(Dashboard!$B$66-Dashboard!$B$65)*3/9) | J25: =J6*(Dashboard!$B$65+(Dashboard!$B$66-Dashboard!$B$65)*4/9) | K25: =K6*(Dashboard!$B$65+(Dashboard!$B$66-Dashboard!$B$65)*5/9) | L25: =L6*(Dashboard!$B$65+(Dashboard!$B$66-Dashboard!$B$65)*6/9) | M25: =M6*(Dashboard!$B$65+(Dashboard!$B$66-Dashboard!$B$65)*7/9) | N25: =N6*(Dashboard!$B$65+(Dashboard!$B$66-Dashboard!$B$65)*8/9) | O25: =O6*(Dashboard!$B$65+(Dashboard!$B$66-Dashboard!$B$65)*9/9)
A26: - dNWC | F26: =(F6-E6)*0.0050 | G26: =(G6-F6)*0.0050 | H26: =(H6-G6)*0.0050 | I26: =(I6-H6)*0.0050 | J26: =(J6-I6)*0.0050 | K26: =(K6-J6)*0.0050 | L26: =(L6-K6)*0.0050 | M26: =(M6-L6)*0.0050 | ... O26: =(O6-N6)*0.0050
A27: - Capex | B27: =-SUM(Financials!B31:E31) | C27: =-SUM(Financials!F31:I31) | D27: =-SUM(Financials!J31:M31) | E27: =-SUM(Financials!N31:Q31) | F27: =F24*F28 | G27: =G24*G28 | H27: =H24*H28 | I27: =I24*I28 | J27: =J24*J28 | K27: =K24*K28 | L27: =L24*L28 | M27: =M24*M28 | ... O27: =O24*O28
A28: Capex / D&A (from Dashboard: $cap'26 -> terminal) | B28: =IFERROR(B27/B24,"") | C28: =IFERROR(C27/C24,"") | D28: =IFERROR(D27/D24,"") | E28: =IFERROR(E27/E24,"") | F28: =(Dashboard!$B$34/F24)+(Dashboard!$B$35-(Dashboard!$B$34/F24))*0/9 | G28: =(Dashboard!$B$34/F24)+(Dashboard!$B$35-(Dashboard!$B$34/F24))*1/9 | H28: =(Dashboard!$B$34/F24)+(Dashboard!$B$35-(Dashboard!$B$34/F24))*2/9 | I28: =(Dashboard!$B$34/F24)+(Dashboard!$B$35-(Dashboard!$B$34/F24))*3/9 | J28: =(Dashboard!$B$34/F24)+(Dashboard!$B$35-(Dashboard!$B$34/F24))*4/9 | K28: =(Dashboard!$B$34/F24)+(Dashboard!$B$35-(Dashboard!$B$34/F24))*5/9 | L28: =(Dashboard!$B$34/F24)+(Dashboard!$B$35-(Dashboard!$B$34/F24))*6/9 | M28: =(Dashboard!$B$34/F24)+(Dashboard!$B$35-(Dashboard!$B$34/F24))*7/9 | N28: =(Dashboard!$B$34/F24)+(Dashboard!$B$35-(Dashboard!$B$34/F24))*8/9 | O28: =(Dashboard!$B$34/F24)+(Dashboard!$B$35-(Dashboard!$B$34/F24))*9/9
A30: FCFF (firm) | B30: =B23+B24+B25-B26-B27 | C30: =C23+C24+C25-C26-C27 | D30: =D23+D24+D25-D26-D27 | E30: =E23+E24+E25-E26-E27 | F30: =F23+F24+F25-F26-F27 | G30: =G23+G24+G25-G26-G27 | H30: =H23+H24+H25-H26-H27 | I30: =I23+I24+I25-I26-I27 | ... O30: =O23+O24+O25-O26-O27
A31: Valuation FCF (NOPAT + D&A - dNWC - Capex - after-tax SBC) | B31: =B30-B25-B25*(1-Valuation!$B$5) | C31: =C30-C25-C25*(1-Valuation!$B$5) | D31: =D30-D25-D25*(1-Valuation!$B$5) | E31: =E30-E25-E25*(1-Valuation!$B$5) | F31: =F30-F25-F25*(1-Valuation!$B$5) | G31: =G30-G25-G25*(1-Valuation!$B$5) | H31: =H30-H25-H25*(1-Valuation!$B$5) | I31: =I30-I25-I25*(1-Valuation!$B$5) | ... O31: =O30-O25-O25*(1-Valuation!$B$5)
A33: RETURNS ON CAPITAL & EFFICIENCY (is new revenue/capital earning its keep?)
A34: Invested capital (debt + equity - cash) | B34: =Financials!E25+Financials!E24-Financials!E19 | C34: =Financials!I25+Financials!I24-Financials!I19 | D34: =Financials!M25+Financials!M24-Financials!M19 | E34: =Financials!Q25+Financials!Q24-Financials!Q19 | F34: =E34+F27-F24+F26 | G34: =F34+G27-G24+G26 | H34: =G34+H27-H24+H26 | I34: =H34+I27-I24+I26 | J34: =I34+J27-J24+J26 | K34: =J34+K27-K24+K26 | L34: =K34+L27-L24+L26 | M34: =L34+M27-M24+M26 | ... O34: =N34+O27-O24+O26
A35: Book equity (year-end) | B35: =Financials!E25 | C35: =Financials!I25 | D35: =Financials!M25 | E35: =Financials!Q25 | F35: =E35+F23 | G35: =F35+G23 | H35: =G35+H23 | I35: =H35+I23 | J35: =I35+J23 | K35: =J35+K23 | L35: =K35+L23 | M35: =L35+M23 | ... O35: =N35+O23
A36: ROIC (NOPAT / beg. invested capital) | C36: =IFERROR(C23/B34,"") | D36: =IFERROR(D23/C34,"") | E36: =IFERROR(E23/D34,"") | F36: =IFERROR(F23/E34,"") | G36: =IFERROR(G23/F34,"") | H36: =IFERROR(H23/G34,"") | I36: =IFERROR(I23/H34,"") | J36: =IFERROR(J23/I34,"") | ... O36: =IFERROR(O23/N34,"")
A37: ROE (earnings / beg. equity) | C37: =IFERROR(SUM(Financials!F15:I15)/B35,"") | D37: =IFERROR(SUM(Financials!J15:M15)/C35,"") | E37: =IFERROR(SUM(Financials!N15:Q15)/D35,"") | F37: =IFERROR(F23/E35,"") | G37: =IFERROR(G23/F35,"") | H37: =IFERROR(H23/G35,"") | I37: =IFERROR(I23/H35,"") | J37: =IFERROR(J23/I35,"") | K37: =IFERROR(K23/J35,"") | L37: =IFERROR(L23/K35,"") | M37: =IFERROR(M23/L35,"") | ... O37: =IFERROR(O23/N35,"")
A38: ROIC - WACC spread (value created) | C38: =IFERROR(C36-WACC!$B$15,"") | D38: =IFERROR(D36-WACC!$B$15,"") | E38: =IFERROR(E36-WACC!$B$15,"") | F38: =IFERROR(F36-WACC!$B$15,"") | G38: =IFERROR(G36-WACC!$B$15,"") | H38: =IFERROR(H36-WACC!$B$15,"") | I38: =IFERROR(I36-WACC!$B$15,"") | J38: =IFERROR(J36-WACC!$B$15,"") | ... O38: =IFERROR(O36-WACC!$B$15,"")
A39: Incremental op margin (ΔEBIT / ΔRev) | C39: =IFERROR((C19-B19)/(C6-B6),"") | D39: =IFERROR((D19-C19)/(D6-C6),"") | E39: =IFERROR((E19-D19)/(E6-D6),"") | F39: =IFERROR((F19-E19)/(F6-E6),"") | G39: =IFERROR((G19-F19)/(G6-F6),"") | H39: =IFERROR((H19-G19)/(H6-G6),"") | I39: =IFERROR((I19-H19)/(I6-H6),"") | J39: =IFERROR((J19-I19)/(J6-I6),"") | ... O39: =IFERROR((O19-N19)/(O6-N6),"")
A40: ROIIC (ΔNOPAT / ΔInvested capital) | C40: =IFERROR((C23-B23)/(C34-B34),"") | D40: =IFERROR((D23-C23)/(D34-C34),"") | E40: =IFERROR((E23-D23)/(E34-D34),"") | F40: =IFERROR((F23-E23)/(F34-E34),"") | G40: =IFERROR((G23-F23)/(G34-F34),"") | H40: =IFERROR((H23-G23)/(H34-G34),"") | I40: =IFERROR((I23-H23)/(I34-H34),"") | J40: =IFERROR((J23-I23)/(J34-I34),"") | ... O40: =IFERROR((O23-N23)/(O34-N34),"")
A41: Sales-to-capital (ΔRev / ΔInvested capital) | C41: =IFERROR((C6-B6)/(C34-B34),"") | D41: =IFERROR((D6-C6)/(D34-C34),"") | E41: =IFERROR((E6-D6)/(E34-D34),"") | F41: =IFERROR((F6-E6)/(F34-E34),"") | G41: =IFERROR((G6-F6)/(G34-F34),"") | H41: =IFERROR((H6-G6)/(H34-G34),"") | I41: =IFERROR((I6-H6)/(I34-H34),"") | J41: =IFERROR((J6-I6)/(J34-I34),"") | ... O41: =IFERROR((O6-N6)/(O34-N34),"")
A42: Reinvestment rate (ΔInvested capital / NOPAT) | C42: =IFERROR((C34-B34)/C23,"") | D42: =IFERROR((D34-C34)/D23,"") | E42: =IFERROR((E34-D34)/E23,"") | F42: =IFERROR((F34-E34)/F23,"") | G42: =IFERROR((G34-F34)/G23,"") | H42: =IFERROR((H34-G34)/H23,"") | I42: =IFERROR((I34-H34)/I23,"") | J42: =IFERROR((J34-I34)/J23,"") | ... O42: =IFERROR((O34-N34)/O23,"")
A44: Blue/green = actual · Yellow = assumption · Black = formula

Sheet Financials
A1: Line Item ($M) | B1: Q1 2023 | C1: Q2 2023 | D1: Q3 2023 | E1: Q4 2023 | F1: Q1 2024 | G1: Q2 2024 | H1: Q3 2024 | I1: Q4 2024 | J1: Q1 2025 | K1: Q2 2025 | L1: Q3 2025 | M1: Q4 2025 | N1: Q1 2026 | O1: Q2 2026 | P1: Q3 2026 | Q1: Q4 2026 | R1: Q1 2027
A2: INCOME STATEMENT
A3: Revenue | B3: 132.15 | C3: 167.224 | D3: 164.73 | E3: 135.715 | F3: 135.74 | G3: 151.535 | H3: 165.604 | I3: 175.013 | J3: 187.315 | K3: 204.951 | L3: 236.178 | M3: 258.1 | N3: 278.481 | O3: 309.86 | P3: 350.166 | Q3: 377.684 | R3: 387.068
A4: % YoY | F4: =IFERROR(F3/B3-1,"") | G4: =IFERROR(G3/C3-1,"") | H4: =IFERROR(H3/D3-1,"") | I4: =IFERROR(I3/E3-1,"") | J4: =IFERROR(J3/F3-1,"") | K4: =IFERROR(K3/G3-1,"") | L4: =IFERROR(L3/H3-1,"") | M4: =IFERROR(M3/I3-1,"") | ... R4: =IFERROR(R3/N3-1,"")
A5: Cost of Revenue | B5: 40.757 | C5: 49.094 | D5: 54.079 | E5: 38.084 | F5: 35.891 | G5: 35.39 | H5: 33.708 | I5: 39.973 | J5: 95.979 | K5: 55.168 | L5: 56.146 | M5: 58.455 | N5: 60.483 | O5: 63.559 | P5: 65.739 | Q5: 72.096 | R5: 75.288
A6: % of revenue | B6: =IFERROR(B5/B3,"") | C6: =IFERROR(C5/C3,"") | D6: =IFERROR(D5/D3,"") | E6: =IFERROR(E5/E3,"") | F6: =IFERROR(F5/F3,"") | G6: =IFERROR(G5/G3,"") | H6: =IFERROR(H5/H3,"") | I6: =IFERROR(I5/I3,"") | ... R6: =IFERROR(R5/R3,"")
A7: R&D Expense | B7: 42.409 | C7: 43.778 | D7: 43.411 | E7: 45.459 | F7: 46.266 | G7: 49.762 | H7: 51.372 | I7: 59.127 | J7: 285.379 | K7: 86.228 | L7: 80.05 | M7: 79.958 | N7: 81.815 | O7: 92.107 | P7: 97.581 | Q7: 102.179 | R7: 114.34
A8: % of revenue | B8: =IFERROR(B7/B3,"") | C8: =IFERROR(C7/C3,"") | D8: =IFERROR(D7/D3,"") | E8: =IFERROR(E7/E3,"") | F8: =IFERROR(F7/F3,"") | G8: =IFERROR(G7/G3,"") | H8: =IFERROR(H7/H3,"") | I8: =IFERROR(I7/I3,"") | ... R8: =IFERROR(R7/R3,"")
A9: SG&A Expense | B9: 114.519 | C9: 132.491 | D9: 126.402 | E9: 130.884 | F9: 138.179 | G9: 139.903 | H9: 145.803 | I9: 159.024 | J9: 530.794 | K9: 231.848 | L9: 224.769 | M9: 235.802 | N9: 229.274 | O9: 248.657 | P9: 259.931 | Q9: 288.186 | R9: 250.08
A10: % of revenue | B10: =IFERROR(B9/B3,"") | C10: =IFERROR(C9/C3,"") | D10: =IFERROR(D9/D3,"") | E10: =IFERROR(E9/E3,"") | F10: =IFERROR(F9/F3,"") | G10: =IFERROR(G9/G3,"") | H10: =IFERROR(H9/H3,"") | I10: =IFERROR(I9/I3,"") | ... R10: =IFERROR(R9/R3,"")
A11: Gross Profit | B11: 91.393 | C11: 118.13 | D11: 110.651 | E11: 97.631 | F11: 99.849 | G11: 116.145 | H11: 131.896 | I11: 135.04 | J11: 91.336 | K11: 149.783 | L11: 180.032 | M11: 199.645 | N11: 217.998 | O11: 246.301 | P11: 284.427 | Q11: 305.588 | R11: 311.78
A12: gross margin | B12: =IFERROR(B11/B3,"") | C12: =IFERROR(C11/C3,"") | D12: =IFERROR(D11/D3,"") | E12: =IFERROR(E11/E3,"") | F12: =IFERROR(F11/F3,"") | G12: =IFERROR(G11/G3,"") | H12: =IFERROR(H11/H3,"") | I12: =IFERROR(I11/I3,"") | ... R12: =IFERROR(R11/R3,"")
A13: Operating Income | B13: -65.535 | C13: -58.139 | D13: -59.162 | E13: -78.712 | F13: -84.596 | G13: -73.52 | H13: -65.279 | I13: -83.111 | J13: -724.837 | K13: -168.293 | L13: -124.787 | M13: -116.115 | N13: -93.091 | O13: -94.463 | P13: -75.483 | Q13: -82.379 | R13: -52.634
A14: operating margin | B14: =IFERROR(B13/B3,"") | C14: =IFERROR(C13/C3,"") | D14: =IFERROR(D13/D3,"") | E14: =IFERROR(E13/E3,"") | F14: =IFERROR(F13/F3,"") | G14: =IFERROR(G13/G3,"") | H14: =IFERROR(H13/H3,"") | I14: =IFERROR(I13/I3,"") | ... R14: =IFERROR(R13/R3,"")
A15: Net Income | B15: -64.359 | C15: -64.359 | D15: -74.514 | E15: -74.514 | F15: -89.273 | G15: -81.121 | H15: -86.267 | I15: -97.497 | J15: -732.091 | K15: -176.93 | L15: -130.91 | M15: -114.889 | N15: -102.104 | O15: -95.929 | P15: -63.829 | Q15: -86.966 | R15: -41.853
A16: net margin | B16: =IFERROR(B15/B3,"") | C16: =IFERROR(C15/C3,"") | D16: =IFERROR(D15/D3,"") | E16: =IFERROR(E15/E3,"") | F16: =IFERROR(F15/F3,"") | G16: =IFERROR(G15/G3,"") | H16: =IFERROR(H15/H3,"") | I16: =IFERROR(I15/I3,"") | ... R16: =IFERROR(R15/R3,"")
A17: Diluted Shares (M) | B17: 175.93221 | C17: 175.93221 | D17: 175.93221 | E17: 175.93221 | F17: 175.93221 | G17: 175.93221 | H17: 175.93221 | I17: 175.93221 | J17: 176.58955 | K17: 179.851 | L17: 183.59 | M17: 188.048 | N17: 191.625 | O17: 194.89 | P17: 198.379 | Q17: 196.468 | R17: 203.668
A18: BALANCE SHEET
A19: Cash & ST Investments | D19: 295.913 | E19: 295.913 | G19: 262.225 | H19: 279.251 | I19: 279.251 | J19: 606.32 | K19: 601.341 | L19: 631.977 | M19: 705.144 | N19: 762.057 | O19: 1523.011 | P19: 1603.007 | Q19: 1675.775 | R19: 1749.4
A20: Total Current Assets | D20: 564.795 | E20: 507.271 | G20: 459.881 | H20: 548.713 | I20: 476.656 | J20: 778.413 | K20: 888.99 | L20: 943.691 | M20: 1077.641 | N20: 1116.895 | O20: 1928.971 | P20: 2066.697 | Q20: 2223.564 | R20: 2224
A21: PP&E (net) | D21: 83.009 | E21: 83.009 | G21: 78.3 | H21: 77.706 | I21: 77.706 | J21: 45.983 | K21: 46.204 | L21: 49.294 | M21: 53.194 | N21: 54.935 | O21: 58.335 | P21: 66.989 | Q21: 83.83 | R21: 83.83
A22: Total Assets | D22: 769.183 | E22: 769.183 | G22: 739.026 | H22: 873.61 | I22: 873.61 | J22: 1166.372 | K22: 1218.204 | L22: 1268.691 | M22: 1422.974 | N22: 1474.606 | O22: 2388.707 | P22: 2548.655 | Q22: 2766.536 | R22: 2768
A23: Total Current Liabilities | D23: 435.404 | E23: 435.404 | G23: 515.584 | H23: 656.281 | I23: 656.281 | J23: 738.045 | K23: 776.715 | L23: 816.556 | M23: 950.176 | N23: 961.289 | O23: 1060.493 | P23: 1162.844 | Q23: 1314.059 | R23: 1280
A24: Long-term Debt | D24: 206.347 | E24: 179.699 | G24: 186.061 | H24: 309.294 | I24: 287.042 | J24: 297.104 | K24: 306.804 | L24: 316.991 | M24: 322.341 | N24: 322.821 | O24: 1128.547 | P24: 1129.627 | Q24: 1130.721 | R24: 1132
A25: Total Equity | D25: -372.616 | E25: -372.616 | G25: -538.515 | H25: -704.544 | I25: -704.544 | J25: -514.598 | K25: -499.294 | L25: -521.087 | M25: -553.734 | N25: -556.53 | O25: -564.344 | P25: -524.409 | Q25: -519.562 | R25: -481.33
A26: CASH FLOW
A27: D&A | B27: 4.071 | C27: 4.071 | D27: 4.062 | E27: 4.062 | F27: 22.017 | G27: 25.615 | H27: 5.1215 | I27: 5.1215 | J27: 27.567 | K27: 29.01 | L27: 7.398 | M27: 7.326 | N27: 8.075 | O27: 8.419 | P27: 0 | Q27: 0 | R27: 12.08
A28: Stock-based Compensation | B28: 2.452 | C28: 2.452 | D28: 1.025 | E28: 1.025 | F28: 0.428 | G28: 1.204 | H28: 2.0415 | I28: 2.0415 | J28: 630.33 | K28: 105.018 | L28: 92.527 | M28: 86.038 | N28: 73.54 | O28: 0 | P28: 0 | Q28: 0 | R28: 73.368
A29: Change in Working Capital | B29: -41.8575 | C29: -41.8575 | D29: -36.5525 | E29: -36.5525 | F29: -23.447 | G29: -41.379 | H29: -0.021 | I29: -0.021 | J29: 33.24 | K29: 6.32 | L29: 23.229 | M29: 78.927 | N29: 35.13 | O29: 31.741 | P29: 26.841 | Q29: 54.465 | R29: 54.465
A30: Operating Cash Flow | B30: -24.9955 | C30: -24.9955 | D30: 34.639 | E30: 34.639 | F30: -17.457 | G30: -6.748 | H30: 6.917 | I30: 12.77 | J30: -31.387 | K30: -27.083 | L30: 23.095 | M30: 83.597 | N30: 39.655 | O30: 63.543 | P30: 86.665 | Q30: 94.948 | R30: 81.69
A31: Capex | B31: -4.9245 | C31: -4.9245 | D31: -7.584 | E31: -7.584 | F31: -5.789 | G31: -6.7 | H31: -1.468 | I31: -4.057 | J31: -5.742 | K31: -4.929 | L31: -7.527 | M31: -5.589 | N31: -2.85 | O31: -7.181 | P31: 2.409 | Q31: -7.54 | R31: -4.28
A32: Free Cash Flow | B32: -29.92 | C32: -29.92 | D32: 27.055 | E32: 27.055 | F32: -23.246 | G32: -13.448 | H32: 5.449 | I32: 8.713 | J32: -37.129 | K32: -32.012 | L32: 15.568 | M32: 78.008 | N32: 36.805 | O32: 56.362 | P32: 89.074 | Q32: 87.408 | R32: 87.408
A34: Blue = hardcoded actuals from FMP filings. Same-sheet ratios are formulas.

Sheet Consensus
A1: Full consensus check — model vs Street (FMP estimates, $M)
A2: Fiscal year | B2: 2027 | C2: 2028 | D2: 2029 | E2: 2030 | F2: 2031
A3: EVERY AVAILABLE FMP CONSENSUS FIELD (consensus / model / % diff)
A4: Revenue — consensus | B4: 1606.8793 | C4: 1964.9849 | D4: 2356.5817 | E4: 2722.7168 | F4: 3109.2
A5: model | B5: =Model!F6 | C5: =Model!G6 | D5: =Model!H6 | E5: =Model!I6 | F5: =Model!J6
A6: vs consensus | B6: =IFERROR(B5/B4-1,"") | C6: =IFERROR(C5/C4-1,"") | D6: =IFERROR(D5/D4-1,"") | E6: =IFERROR(E5/E4-1,"") | F6: =IFERROR(F5/F4-1,"")
A8: EBITDA* — consensus | B8: -644.70323 | C8: -788.38035 | D8: -945.49467 | E8: -1092.3933 | F8: -1247.456
A9: model | B9: =Model!F19+Model!F24 | C9: =Model!G19+Model!G24 | D9: =Model!H19+Model!H24 | E9: =Model!I19+Model!I24 | F9: =Model!J19+Model!J24
A10: vs consensus | B10: =IFERROR(B9/B8-1,"") | C10: =IFERROR(C9/C8-1,"") | D10: =IFERROR(D9/D8-1,"") | E10: =IFERROR(E9/E8-1,"") | F10: =IFERROR(F9/F8-1,"")
A12: EBIT* — consensus | B12: -854.21115 | C12: -1044.5787 | D12: -1252.7502 | E12: -1447.3862 | F12: -1652.8393
A13: model | B13: =Model!F19 | C13: =Model!G19 | D13: =Model!H19 | E13: =Model!I19 | F13: =Model!J19
A14: vs consensus | B14: =IFERROR(B13/B12-1,"") | C14: =IFERROR(C13/C12-1,"") | D14: =IFERROR(D13/D12-1,"") | E14: =IFERROR(E13/E12-1,"") | F14: =IFERROR(F13/F12-1,"")
A16: SG&A — consensus | B16: 1408.4086 | C16: 1722.2833 | D16: 2065.5128 | E16: 2386.4254 | F16: 2725.1728
A17: model | B17: =Model!F14 | C17: =Model!G14 | D17: =Model!H14 | E17: =Model!I14 | F17: =Model!J14
A18: vs consensus | B18: =IFERROR(B17/B16-1,"") | C18: =IFERROR(C17/C16-1,"") | D18: =IFERROR(D17/D16-1,"") | E18: =IFERROR(E17/E16-1,"") | F18: =IFERROR(F17/F16-1,"")
A20: Net income (NOPAT) — consensus | B20: 50.956922 | C20: 120.24627 | D20: -5.34452 | E20: 240.97783 | F20: 312.38412
A21: model | B21: =Model!F23 | C21: =Model!G23 | D21: =Model!H23 | E21: =Model!I23 | F21: =Model!J23
A22: vs consensus | B22: =IFERROR(B21/B20-1,"") | C22: =IFERROR(C21/C20-1,"") | D22: =IFERROR(D21/D20-1,"") | E22: =IFERROR(E21/E20-1,"") | F22: =IFERROR(F21/F20-1,"")
A24: EPS — consensus | B24: 0.17291 | C24: 0.56769 | D24: 1.18621 | E24: 1.22655 | F24: 1.59
A25: model | B25: =Model!F23/Financials!R17 | C25: =Model!G23/Financials!R17 | D25: =Model!H23/Financials!R17 | E25: =Model!I23/Financials!R17 | F25: =Model!J23/Financials!R17
A26: vs consensus | B26: =IFERROR(B25/B24-1,"") | C26: =IFERROR(C25/C24-1,"") | D26: =IFERROR(D25/D24-1,"") | E26: =IFERROR(E25/E24-1,"") | F26: =IFERROR(F25/F24-1,"")
A28: Defaults anchored to consensus revenue + net income (≈0% diff). Other rows show where the model sits vs Street.
A29: *FMP's EBITDA/EBIT estimates look unreliable for AMZN (it reports NI > EBIT) — don't over-read those two.

Sheet Valuation
A1: Rubrik, Inc. — DCF Valuation
A2: Current price | B2: =Dashboard!$B$48
A3: WACC | B3: =WACC!B15
A4: Terminal growth (g) | B4: =Dashboard!$B$46
A5: Tax rate | B5: =Dashboard!$B$31
A6: Terminal method | B6: =Dashboard!$B$43
A7: Exit basis | B7: =Dashboard!$B$44
A8: Exit multiple | B8: =Dashboard!$B$45
A11: Forecast year | C11: 2027 | D11: 2028 | E11: 2029 | F11: 2030 | G11: 2031 | H11: 2032 | I11: 2033 | J11: 2034 | K11: 2035 | L11: 2036
A12: FCFF ($M) | C12: =Model!F31 | D12: =Model!G31 | E12: =Model!H31 | F12: =Model!I31 | G12: =Model!J31 | H12: =Model!K31 | I12: =Model!L31 | J12: =Model!M31 | ... L12: =Model!O31
A13: PV factor | C13: =1/(1+$B$3)^1 | D13: =1/(1+$B$3)^2 | E13: =1/(1+$B$3)^3 | F13: =1/(1+$B$3)^4 | G13: =1/(1+$B$3)^5 | H13: =1/(1+$B$3)^6 | I13: =1/(1+$B$3)^7 | J13: =1/(1+$B$3)^8 | K13: =1/(1+$B$3)^9 | L13: =1/(1+$B$3)^10
A14: PV of FCFF ($M) | C14: =C12*C13 | D14: =D12*D13 | E14: =E12*E13 | F14: =F12*F13 | G14: =G12*G13 | H14: =H12*H13 | I14: =I12*I13 | J14: =J12*J13 | ... L14: =L12*L13
A16: Sum PV of FCFF | B16: =SUM(C14:L14)
A18: TERMINAL VALUE (exit multiple = default; perpetuity = cross-check)
A19: Terminal-year FCFF | B19: =L12
A20: Terminal revenue | B20: =Model!O6
A21: Terminal EBIT | B21: =Model!O19
A22: Terminal EBITDA (SBC-burdened) | B22: =Model!O19+Model!O24-Model!O25
A23: Terminal metric (per exit basis) | B23: =IF($B$7="EV/EBITDA",B22,IF($B$7="EV/Sales",B20,IF($B$7="EV/EBIT",B21,B19)))
A24: TV (exit) = metric x multiple | B24: =B23*$B$8
A25: PV of TV — exit multiple | B25: =B24/(1+$B$3)^10
A26: TV (perpetuity) = FCFF(1+g)/(WACC-g) | B26: =B19*(1+$B$4)/($B$3-$B$4)
A27: PV of TV — perpetuity | B27: =B26/(1+$B$3)^10
A28: PV of TV — SELECTED | B28: =IF($B$6="Perpetuity",B27,B25)
A30: EQUITY BRIDGE -> VALUE / SHARE
A31: Operating value (enterprise value) | B31: =B16+B28
A32: + Cash & ST investments | B32: =Financials!R19
A33: - Long-term debt | B33: =-Financials!R24
A34: Equity value | B34: =B31+B32+B33
A35: Diluted shares (M) | B35: =Financials!R17
A36: VALUE / SHARE | B36: =B34/B35*1.0
A38: CROSS-CHECKS & RETURN
A39: Terminal weight (% of EV) | B39: =B28/B31
A40: Implied perpetuity g (from exit multiple) | B40: =(B24*$B$3-B19)/(B24+B19)
A41: Implied exit EV/EBITDA (from perpetuity) | B41: =B26/B22
A42: Upside / (downside) to fair value | B42: =B36/$B$2-1
A44: Owner cashflow / share | B44: =-$B$2 | C44: =C12/B35 | D44: =D12/B35 | E44: =E12/B35 | F44: =F12/B35 | G44: =G12/B35 | H44: =H12/B35 | I44: =I12/B35 | J44: =J12/B35 | K44: =K12/B35 | L44: =L12/B35+B36
A45: IRR (buy at price, hold 10y) | B45: =IRR(B44:L44)

Sheet Sensitivity
A1: Sensitivity — fair value / share (USD)
A2: WACC x exit multiple (EV/Sales). Static grid recomputed by every rebuild/refresh — edit the Dashboard, re-run refresh_dcf to update. Shaded = base case; green = above current price.
A4: EV/Sales x \ WACC | B4: 0.073863862 | C4: 0.078863862 | D4: 0.083863862 | E4: 0.088863862 | F4: 0.093863862 | G4: 0.098863862 | H4: 0.10386386
A5: 3 | B5: 36.85689 | C5: 35.462968 | D5: 34.134965 | E5: 32.869427 | F5: 31.663097 | G5: 30.512903 | H5: 29.415947
A6: 4 | B6: 44.901529 | C6: 43.142458 | D6: 41.467455 | E6: 39.872086 | F6: 38.352172 | G6: 36.903772 | H6: 35.523168
A7: 5 | B7: 52.946168 | C7: 50.821947 | D7: 48.799944 | E7: 46.874745 | F7: 45.041247 | G7: 43.294641 | H7: 41.63039
A8: 6 | B8: 60.990807 | C8: 58.501437 | D8: 56.132434 | E8: 53.877404 | F8: 51.730322 | G8: 49.68551 | H8: 47.737611
A9: 7 | B9: 69.035445 | C9: 66.180927 | D9: 63.464924 | E9: 60.880063 | F9: 58.419398 | G9: 56.076379 | H9: 53.844833
A10: 8 | B10: 77.080084 | C10: 73.860417 | D10: 70.797414 | E10: 67.882722 | F10: 65.108473 | G10: 62.467248 | H10: 59.952054
A11: 9 | B11: 85.124723 | C11: 81.539907 | D11: 78.129904 | E11: 74.885382 | F11: 71.797548 | G11: 68.858117 | H11: 66.059276
A13: Current price | B13: 84.245003
A14: Base WACC / multiple | B14: 0.088863862 | C14: 6

Sheet Monte Carlo
A1: Monte Carlo simulation (live) | H1: SIMULATION ENGINE — leave as-is | K1: cagr | L1: term margin | M1: wacc | N1: exit | O1: value/share
A2: 1,000 trials, recomputed in-sheet on every edit. Edit the yellow driver distributions to re-roll. Engine grid is to the right (cols H+). | H2: R0 (base revenue) | I2: =Model!E6 | K2: =MAX(-0.05,NORMINV(RAND(),$C$6,$D$6)) | L2: =MAX(0.02,NORMINV(RAND(),$C$7,$D$7)) | M2: =MIN(0.16,MAX(0.05,NORMINV(RAND(),$C$8,$D$8))) | N2: =MIN(24,MAX(5,NORMINV(RAND(),$C$9,$D$9))) | O2: =$I$8*(SUMPRODUCT(($I$2*(1+K2)^{1;2;3;4;5;6;7;8;9;10})*(($I$3+(L2-$I$3)*{1;2;3;4;5;6;7;8;9;10}/10)*(1-$I$7)+$I$4-$I$4*($I$5+(1.05-$I$5)*{1;2;3;4;5;6;7;8;9;10}/10)-(K2/(1+K2))*$I$6)/(1+M2)^{1;2;3;4;5;6;7;8;9;10})+$I$2*(1+K2)^10*(L2+$I$4)*N2/(1+M2)^10+$I$9-$I$10)/$I$11
H3: m0 (base op margin) | I3: =Model!E20 | K3: =MAX(-0.05,NORMINV(RAND(),$C$6,$D$6)) | L3: =MAX(0.02,NORMINV(RAND(),$C$7,$D$7)) | M3: =MIN(0.16,MAX(0.05,NORMINV(RAND(),$C$8,$D$8))) | N3: =MIN(24,MAX(5,NORMINV(RAND(),$C$9,$D$9))) | O3: =$I$8*(SUMPRODUCT(($I$2*(1+K3)^{1;2;3;4;5;6;7;8;9;10})*(($I$3+(L3-$I$3)*{1;2;3;4;5;6;7;8;9;10}/10)*(1-$I$7)+$I$4-$I$4*($I$5+(1.05-$I$5)*{1;2;3;4;5;6;7;8;9;10}/10)-(K3/(1+K3))*$I$6)/(1+M3)^{1;2;3;4;5;6;7;8;9;10})+$I$2*(1+K3)^10*(L3+$I$4)*N3/(1+M3)^10+$I$9-$I$10)/$I$11
A4: DRIVER DISTRIBUTIONS (yellow = edit; Opus-set defaults) | H4: da (D&A / revenue) | I4: 0.012531616 | K4: =MAX(-0.05,NORMINV(RAND(),$C$6,$D$6)) | L4: =MAX(0.02,NORMINV(RAND(),$C$7,$D$7)) | M4: =MIN(0.16,MAX(0.05,NORMINV(RAND(),$C$8,$D$8))) | N4: =MIN(24,MAX(5,NORMINV(RAND(),$C$9,$D$9))) | O4: =$I$8*(SUMPRODUCT(($I$2*(1+K4)^{1;2;3;4;5;6;7;8;9;10})*(($I$3+(L4-$I$3)*{1;2;3;4;5;6;7;8;9;10}/10)*(1-$I$7)+$I$4-$I$4*($I$5+(1.05-$I$5)*{1;2;3;4;5;6;7;8;9;10}/10)-(K4/(1+K4))*$I$6)/(1+M4)^{1;2;3;4;5;6;7;8;9;10})+$I$2*(1+K4)^10*(L4+$I$4)*N4/(1+M4)^10+$I$9-$I$10)/$I$11
A5: Driver | B5: Dist | C5: Mean | D5: Std dev | H5: cda0 (2026 capex/D&A) | I5: 0.95757803 | K5: =MAX(-0.05,NORMINV(RAND(),$C$6,$D$6)) | L5: =MAX(0.02,NORMINV(RAND(),$C$7,$D$7)) | M5: =MIN(0.16,MAX(0.05,NORMINV(RAND(),$C$8,$D$8))) | N5: =MIN(24,MAX(5,NORMINV(RAND(),$C$9,$D$9))) | O5: =$I$8*(SUMPRODUCT(($I$2*(1+K5)^{1;2;3;4;5;6;7;8;9;10})*(($I$3+(L5-$I$3)*{1;2;3;4;5;6;7;8;9;10}/10)*(1-$I$7)+$I$4-$I$4*($I$5+(1.05-$I$5)*{1;2;3;4;5;6;7;8;9;10}/10)-(K5/(1+K5))*$I$6)/(1+M5)^{1;2;3;4;5;6;7;8;9;10})+$I$2*(1+K5)^10*(L5+$I$4)*N5/(1+M5)^10+$I$9-$I$10)/$I$11
A6: Revenue 10y CAGR | B6: Normal | C6: =(Model!O6/Model!E6)^(1/10)-1 | D6: 0.03 | H6: nwc (% incr revenue) | I6: 0.005 | K6: =MAX(-0.05,NORMINV(RAND(),$C$6,$D$6)) | L6: =MAX(0.02,NORMINV(RAND(),$C$7,$D$7)) | M6: =MIN(0.16,MAX(0.05,NORMINV(RAND(),$C$8,$D$8))) | N6: =MIN(24,MAX(5,NORMINV(RAND(),$C$9,$D$9))) | O6: =$I$8*(SUMPRODUCT(($I$2*(1+K6)^{1;2;3;4;5;6;7;8;9;10})*(($I$3+(L6-$I$3)*{1;2;3;4;5;6;7;8;9;10}/10)*(1-$I$7)+$I$4-$I$4*($I$5+(1.05-$I$5)*{1;2;3;4;5;6;7;8;9;10}/10)-(K6/(1+K6))*$I$6)/(1+M6)^{1;2;3;4;5;6;7;8;9;10})+$I$2*(1+K6)^10*(L6+$I$4)*N6/(1+M6)^10+$I$9-$I$10)/$I$11
A7: Terminal operating margin | B7: Normal | C7: =Dashboard!$B$30 | D7: 0.03 | H7: tax | I7: =Valuation!$B$5 | K7: =MAX(-0.05,NORMINV(RAND(),$C$6,$D$6)) | L7: =MAX(0.02,NORMINV(RAND(),$C$7,$D$7)) | M7: =MIN(0.16,MAX(0.05,NORMINV(RAND(),$C$8,$D$8))) | N7: =MIN(24,MAX(5,NORMINV(RAND(),$C$9,$D$9))) | O7: =$I$8*(SUMPRODUCT(($I$2*(1+K7)^{1;2;3;4;5;6;7;8;9;10})*(($I$3+(L7-$I$3)*{1;2;3;4;5;6;7;8;9;10}/10)*(1-$I$7)+$I$4-$I$4*($I$5+(1.05-$I$5)*{1;2;3;4;5;6;7;8;9;10}/10)-(K7/(1+K7))*$I$6)/(1+M7)^{1;2;3;4;5;6;7;8;9;10})+$I$2*(1+K7)^10*(L7+$I$4)*N7/(1+M7)^10+$I$9-$I$10)/$I$11
A8: WACC | B8: Normal | C8: =WACC!B15 | D8: 0.005 | H8: k (calibration) | I8: 3.5502312 | K8: =MAX(-0.05,NORMINV(RAND(),$C$6,$D$6)) | L8: =MAX(0.02,NORMINV(RAND(),$C$7,$D$7)) | M8: =MIN(0.16,MAX(0.05,NORMINV(RAND(),$C$8,$D$8))) | N8: =MIN(24,MAX(5,NORMINV(RAND(),$C$9,$D$9))) | O8: =$I$8*(SUMPRODUCT(($I$2*(1+K8)^{1;2;3;4;5;6;7;8;9;10})*(($I$3+(L8-$I$3)*{1;2;3;4;5;6;7;8;9;10}/10)*(1-$I$7)+$I$4-$I$4*($I$5+(1.05-$I$5)*{1;2;3;4;5;6;7;8;9;10}/10)-(K8/(1+K8))*$I$6)/(1+M8)^{1;2;3;4;5;6;7;8;9;10})+$I$2*(1+K8)^10*(L8+$I$4)*N8/(1+M8)^10+$I$9-$I$10)/$I$11
A9: Exit EV/EBITDA multiple | B9: Normal | C9: =Dashboard!$B$45 | D9: 1.5 | H9: cash | I9: =Financials!R19 | K9: =MAX(-0.05,NORMINV(RAND(),$C$6,$D$6)) | L9: =MAX(0.02,NORMINV(RAND(),$C$7,$D$7)) | M9: =MIN(0.16,MAX(0.05,NORMINV(RAND(),$C$8,$D$8))) | N9: =MIN(24,MAX(5,NORMINV(RAND(),$C$9,$D$9))) | O9: =$I$8*(SUMPRODUCT(($I$2*(1+K9)^{1;2;3;4;5;6;7;8;9;10})*(($I$3+(L9-$I$3)*{1;2;3;4;5;6;7;8;9;10}/10)*(1-$I$7)+$I$4-$I$4*($I$5+(1.05-$I$5)*{1;2;3;4;5;6;7;8;9;10}/10)-(K9/(1+K9))*$I$6)/(1+M9)^{1;2;3;4;5;6;7;8;9;10})+$I$2*(1+K9)^10*(L9+$I$4)*N9/(1+M9)^10+$I$9-$I$10)/$I$11
H10: debt | I10: =Financials!R24 | K10: =MAX(-0.05,NORMINV(RAND(),$C$6,$D$6)) | L10: =MAX(0.02,NORMINV(RAND(),$C$7,$D$7)) | M10: =MIN(0.16,MAX(0.05,NORMINV(RAND(),$C$8,$D$8))) | N10: =MIN(24,MAX(5,NORMINV(RAND(),$C$9,$D$9))) | O10: =$I$8*(SUMPRODUCT(($I$2*(1+K10)^{1;2;3;4;5;6;7;8;9;10})*(($I$3+(L10-$I$3)*{1;2;3;4;5;6;7;8;9;10}/10)*(1-$I$7)+$I$4-$I$4*($I$5+(1.05-$I$5)*{1;2;3;4;5;6;7;8;9;10}/10)-(K10/(1+K10))*$I$6)/(1+M10)^{1;2;3;4;5;6;7;8;9;10})+$I$2*(1+K10)^10*(L10+$I$4)*N10/(1+M10)^10+$I$9-$I$10)/$I$11
A11: SIMULATION OUTPUT — value / share (live) | H11: shares | I11: =Financials!R17 | K11: =MAX(-0.05,NORMINV(RAND(),$C$6,$D$6)) | L11: =MAX(0.02,NORMINV(RAND(),$C$7,$D$7)) | M11: =MIN(0.16,MAX(0.05,NORMINV(RAND(),$C$8,$D$8))) | N11: =MIN(24,MAX(5,NORMINV(RAND(),$C$9,$D$9))) | O11: =$I$8*(SUMPRODUCT(($I$2*(1+K11)^{1;2;3;4;5;6;7;8;9;10})*(($I$3+(L11-$I$3)*{1;2;3;4;5;6;7;8;9;10}/10)*(1-$I$7)+$I$4-$I$4*($I$5+(1.05-$I$5)*{1;2;3;4;5;6;7;8;9;10}/10)-(K11/(1+K11))*$I$6)/(1+M11)^{1;2;3;4;5;6;7;8;9;10})+$I$2*(1+K11)^10*(L11+$I$4)*N11/(1+M11)^10+$I$9-$I$10)/$I$11
A12: Mean | B12: =AVERAGE($O$2:$O$1001) | K12: =MAX(-0.05,NORMINV(RAND(),$C$6,$D$6)) | L12: =MAX(0.02,NORMINV(RAND(),$C$7,$D$7)) | M12: =MIN(0.16,MAX(0.05,NORMINV(RAND(),$C$8,$D$8))) | N12: =MIN(24,MAX(5,NORMINV(RAND(),$C$9,$D$9))) | O12: =$I$8*(SUMPRODUCT(($I$2*(1+K12)^{1;2;3;4;5;6;7;8;9;10})*(($I$3+(L12-$I$3)*{1;2;3;4;5;6;7;8;9;10}/10)*(1-$I$7)+$I$4-$I$4*($I$5+(1.05-$I$5)*{1;2;3;4;5;6;7;8;9;10}/10)-(K12/(1+K12))*$I$6)/(1+M12)^{1;2;3;4;5;6;7;8;9;10})+$I$2*(1+K12)^10*(L12+$I$4)*N12/(1+M12)^10+$I$9-$I$10)/$I$11
A13: Median (P50) | B13: =MEDIAN($O$2:$O$1001) | K13: =MAX(-0.05,NORMINV(RAND(),$C$6,$D$6)) | L13: =MAX(0.02,NORMINV(RAND(),$C$7,$D$7)) | M13: =MIN(0.16,MAX(0.05,NORMINV(RAND(),$C$8,$D$8))) | N13: =MIN(24,MAX(5,NORMINV(RAND(),$C$9,$D$9))) | O13: =$I$8*(SUMPRODUCT(($I$2*(1+K13)^{1;2;3;4;5;6;7;8;9;10})*(($I$3+(L13-$I$3)*{1;2;3;4;5;6;7;8;9;10}/10)*(1-$I$7)+$I$4-$I$4*($I$5+(1.05-$I$5)*{1;2;3;4;5;6;7;8;9;10}/10)-(K13/(1+K13))*$I$6)/(1+M13)^{1;2;3;4;5;6;7;8;9;10})+$I$2*(1+K13)^10*(L13+$I$4)*N13/(1+M13)^10+$I$9-$I$10)/$I$11
A14: Std dev | B14: =STDEV($O$2:$O$1001) | K14: =MAX(-0.05,NORMINV(RAND(),$C$6,$D$6)) | L14: =MAX(0.02,NORMINV(RAND(),$C$7,$D$7)) | M14: =MIN(0.16,MAX(0.05,NORMINV(RAND(),$C$8,$D$8))) | N14: =MIN(24,MAX(5,NORMINV(RAND(),$C$9,$D$9))) | O14: =$I$8*(SUMPRODUCT(($I$2*(1+K14)^{1;2;3;4;5;6;7;8;9;10})*(($I$3+(L14-$I$3)*{1;2;3;4;5;6;7;8;9;10}/10)*(1-$I$7)+$I$4-$I$4*($I$5+(1.05-$I$5)*{1;2;3;4;5;6;7;8;9;10}/10)-(K14/(1+K14))*$I$6)/(1+M14)^{1;2;3;4;5;6;7;8;9;10})+$I$2*(1+K14)^10*(L14+$I$4)*N14/(1+M14)^10+$I$9-$I$10)/$I$11
A15: Min | B15: =MIN($O$2:$O$1001) | K15: =MAX(-0.05,NORMINV(RAND(),$C$6,$D$6)) | L15: =MAX(0.02,NORMINV(RAND(),$C$7,$D$7)) | M15: =MIN(0.16,MAX(0.05,NORMINV(RAND(),$C$8,$D$8))) | N15: =MIN(24,MAX(5,NORMINV(RAND(),$C$9,$D$9))) | O15: =$I$8*(SUMPRODUCT(($I$2*(1+K15)^{1;2;3;4;5;6;7;8;9;10})*(($I$3+(L15-$I$3)*{1;2;3;4;5;6;7;8;9;10}/10)*(1-$I$7)+$I$4-$I$4*($I$5+(1.05-$I$5)*{1;2;3;4;5;6;7;8;9;10}/10)-(K15/(1+K15))*$I$6)/(1+M15)^{1;2;3;4;5;6;7;8;9;10})+$I$2*(1+K15)^10*(L15+$I$4)*N15/(1+M15)^10+$I$9-$I$10)/$I$11
A16: Max | B16: =MAX($O$2:$O$1001) | K16: =MAX(-0.05,NORMINV(RAND(),$C$6,$D$6)) | L16: =MAX(0.02,NORMINV(RAND(),$C$7,$D$7)) | M16: =MIN(0.16,MAX(0.05,NORMINV(RAND(),$C$8,$D$8))) | N16: =MIN(24,MAX(5,NORMINV(RAND(),$C$9,$D$9))) | O16: =$I$8*(SUMPRODUCT(($I$2*(1+K16)^{1;2;3;4;5;6;7;8;9;10})*(($I$3+(L16-$I$3)*{1;2;3;4;5;6;7;8;9;10}/10)*(1-$I$7)+$I$4-$I$4*($I$5+(1.05-$I$5)*{1;2;3;4;5;6;7;8;9;10}/10)-(K16/(1+K16))*$I$6)/(1+M16)^{1;2;3;4;5;6;7;8;9;10})+$I$2*(1+K16)^10*(L16+$I$4)*N16/(1+M16)^10+$I$9-$I$10)/$I$11
A17: Current price | B17: =Valuation!$B$2 | K17: =MAX(-0.05,NORMINV(RAND(),$C$6,$D$6)) | L17: =MAX(0.02,NORMINV(RAND(),$C$7,$D$7)) | M17: =MIN(0.16,MAX(0.05,NORMINV(RAND(),$C$8,$D$8))) | N17: =MIN(24,MAX(5,NORMINV(RAND(),$C$9,$D$9))) | O17: =$I$8*(SUMPRODUCT(($I$2*(1+K17)^{1;2;3;4;5;6;7;8;9;10})*(($I$3+(L17-$I$3)*{1;2;3;4;5;6;7;8;9;10}/10)*(1-$I$7)+$I$4-$I$4*($I$5+(1.05-$I$5)*{1;2;3;4;5;6;7;8;9;10}/10)-(K17/(1+K17))*$I$6)/(1+M17)^{1;2;3;4;5;6;7;8;9;10})+$I$2*(1+K17)^10*(L17+$I$4)*N17/(1+M17)^10+$I$9-$I$10)/$I$11
A18: Base case (full model) | B18: =Valuation!B36 | K18: =MAX(-0.05,NORMINV(RAND(),$C$6,$D$6)) | L18: =MAX(0.02,NORMINV(RAND(),$C$7,$D$7)) | M18: =MIN(0.16,MAX(0.05,NORMINV(RAND(),$C$8,$D$8))) | N18: =MIN(24,MAX(5,NORMINV(RAND(),$C$9,$D$9))) | O18: =$I$8*(SUMPRODUCT(($I$2*(1+K18)^{1;2;3;4;5;6;7;8;9;10})*(($I$3+(L18-$I$3)*{1;2;3;4;5;6;7;8;9;10}/10)*(1-$I$7)+$I$4-$I$4*($I$5+(1.05-$I$5)*{1;2;3;4;5;6;7;8;9;10}/10)-(K18/(1+K18))*$I$6)/(1+M18)^{1;2;3;4;5;6;7;8;9;10})+$I$2*(1+K18)^10*(L18+$I$4)*N18/(1+M18)^10+$I$9-$I$10)/$I$11
K19: =MAX(-0.05,NORMINV(RAND(),$C$6,$D$6)) | L19: =MAX(0.02,NORMINV(RAND(),$C$7,$D$7)) | M19: =MIN(0.16,MAX(0.05,NORMINV(RAND(),$C$8,$D$8))) | N19: =MIN(24,MAX(5,NORMINV(RAND(),$C$9,$D$9))) | O19: =$I$8*(SUMPRODUCT(($I$2*(1+K19)^{1;2;3;4;5;6;7;8;9;10})*(($I$3+(L19-$I$3)*{1;2;3;4;5;6;7;8;9;10}/10)*(1-$I$7)+$I$4-$I$4*($I$5+(1.05-$I$5)*{1;2;3;4;5;6;7;8;9;10}/10)-(K19/(1+K19))*$I$6)/(1+M19)^{1;2;3;4;5;6;7;8;9;10})+$I$2*(1+K19)^10*(L19+$I$4)*N19/(1+M19)^10+$I$9-$I$10)/$I$11
A20: P(undervalued at current price) | B20: =COUNTIF($O$2:$O$1001,">"&Valuation!$B$2)/1000 | K20: =MAX(-0.05,NORMINV(RAND(),$C$6,$D$6)) | L20: =MAX(0.02,NORMINV(RAND(),$C$7,$D$7)) | M20: =MIN(0.16,MAX(0.05,NORMINV(RAND(),$C$8,$D$8))) | N20: =MIN(24,MAX(5,NORMINV(RAND(),$C$9,$D$9))) | O20: =$I$8*(SUMPRODUCT(($I$2*(1+K20)^{1;2;3;4;5;6;7;8;9;10})*(($I$3+(L20-$I$3)*{1;2;3;4;5;6;7;8;9;10}/10)*(1-$I$7)+$I$4-$I$4*($I$5+(1.05-$I$5)*{1;2;3;4;5;6;7;8;9;10}/10)-(K20/(1+K20))*$I$6)/(1+M20)^{1;2;3;4;5;6;7;8;9;10})+$I$2*(1+K20)^10*(L20+$I$4)*N20/(1+M20)^10+$I$9-$I$10)/$I$11
A21: P(>20% upside) | B21: =COUNTIF($O$2:$O$1001,">"&Valuation!$B$2*1.2)/1000 | K21: =MAX(-0.05,NORMINV(RAND(),$C$6,$D$6)) | L21: =MAX(0.02,NORMINV(RAND(),$C$7,$D$7)) | M21: =MIN(0.16,MAX(0.05,NORMINV(RAND(),$C$8,$D$8))) | N21: =MIN(24,MAX(5,NORMINV(RAND(),$C$9,$D$9))) | O21: =$I$8*(SUMPRODUCT(($I$2*(1+K21)^{1;2;3;4;5;6;7;8;9;10})*(($I$3+(L21-$I$3)*{1;2;3;4;5;6;7;8;9;10}/10)*(1-$I$7)+$I$4-$I$4*($I$5+(1.05-$I$5)*{1;2;3;4;5;6;7;8;9;10}/10)-(K21/(1+K21))*$I$6)/(1+M21)^{1;2;3;4;5;6;7;8;9;10})+$I$2*(1+K21)^10*(L21+$I$4)*N21/(1+M21)^10+$I$9-$I$10)/$I$11
K22: =MAX(-0.05,NORMINV(RAND(),$C$6,$D$6)) | L22: =MAX(0.02,NORMINV(RAND(),$C$7,$D$7)) | M22: =MIN(0.16,MAX(0.05,NORMINV(RAND(),$C$8,$D$8))) | N22: =MIN(24,MAX(5,NORMINV(RAND(),$C$9,$D$9))) | O22: =$I$8*(SUMPRODUCT(($I$2*(1+K22)^{1;2;3;4;5;6;7;8;9;10})*(($I$3+(L22-$I$3)*{1;2;3;4;5;6;7;8;9;10}/10)*(1-$I$7)+$I$4-$I$4*($I$5+(1.05-$I$5)*{1;2;3;4;5;6;7;8;9;10}/10)-(K22/(1+K22))*$I$6)/(1+M22)^{1;2;3;4;5;6;7;8;9;10})+$I$2*(1+K22)^10*(L22+$I$4)*N22/(1+M22)^10+$I$9-$I$10)/$I$11
A23: PERCENTILES (live) | K23: =MAX(-0.05,NORMINV(RAND(),$C$6,$D$6)) | L23: =MAX(0.02,NORMINV(RAND(),$C$7,$D$7)) | M23: =MIN(0.16,MAX(0.05,NORMINV(RAND(),$C$8,$D$8))) | N23: =MIN(24,MAX(5,NORMINV(RAND(),$C$9,$D$9))) | O23: =$I$8*(SUMPRODUCT(($I$2*(1+K23)^{1;2;3;4;5;6;7;8;9;10})*(($I$3+(L23-$I$3)*{1;2;3;4;5;6;7;8;9;10}/10)*(1-$I$7)+$I$4-$I$4*($I$5+(1.05-$I$5)*{1;2;3;4;5;6;7;8;9;10}/10)-(K23/(1+K23))*$I$6)/(1+M23)^{1;2;3;4;5;6;7;8;9;10})+$I$2*(1+K23)^10*(L23+$I$4)*N23/(1+M23)^10+$I$9-$I$10)/$I$11
A24: P5 | B24: =PERCENTILE($O$2:$O$1001,0.05) | K24: =MAX(-0.05,NORMINV(RAND(),$C$6,$D$6)) | L24: =MAX(0.02,NORMINV(RAND(),$C$7,$D$7)) | M24: =MIN(0.16,MAX(0.05,NORMINV(RAND(),$C$8,$D$8))) | N24: =MIN(24,MAX(5,NORMINV(RAND(),$C$9,$D$9))) | O24: =$I$8*(SUMPRODUCT(($I$2*(1+K24)^{1;2;3;4;5;6;7;8;9;10})*(($I$3+(L24-$I$3)*{1;2;3;4;5;6;7;8;9;10}/10)*(1-$I$7)+$I$4-$I$4*($I$5+(1.05-$I$5)*{1;2;3;4;5;6;7;8;9;10}/10)-(K24/(1+K24))*$I$6)/(1+M24)^{1;2;3;4;5;6;7;8;9;10})+$I$2*(1+K24)^10*(L24+$I$4)*N24/(1+M24)^10+$I$9-$I$10)/$I$11
A25: P10 | B25: =PERCENTILE($O$2:$O$1001,0.1) | K25: =MAX(-0.05,NORMINV(RAND(),$C$6,$D$6)) | L25: =MAX(0.02,NORMINV(RAND(),$C$7,$D$7)) | M25: =MIN(0.16,MAX(0.05,NORMINV(RAND(),$C$8,$D$8))) | N25: =MIN(24,MAX(5,NORMINV(RAND(),$C$9,$D$9))) | O25: =$I$8*(SUMPRODUCT(($I$2*(1+K25)^{1;2;3;4;5;6;7;8;9;10})*(($I$3+(L25-$I$3)*{1;2;3;4;5;6;7;8;9;10}/10)*(1-$I$7)+$I$4-$I$4*($I$5+(1.05-$I$5)*{1;2;3;4;5;6;7;8;9;10}/10)-(K25/(1+K25))*$I$6)/(1+M25)^{1;2;3;4;5;6;7;8;9;10})+$I$2*(1+K25)^10*(L25+$I$4)*N25/(1+M25)^10+$I$9-$I$10)/$I$11
A26: P25 | B26: =PERCENTILE($O$2:$O$1001,0.25) | K26: =MAX(-0.05,NORMINV(RAND(),$C$6,$D$6)) | L26: =MAX(0.02,NORMINV(RAND(),$C$7,$D$7)) | M26: =MIN(0.16,MAX(0.05,NORMINV(RAND(),$C$8,$D$8))) | N26: =MIN(24,MAX(5,NORMINV(RAND(),$C$9,$D$9))) | O26: =$I$8*(SUMPRODUCT(($I$2*(1+K26)^{1;2;3;4;5;6;7;8;9;10})*(($I$3+(L26-$I$3)*{1;2;3;4;5;6;7;8;9;10}/10)*(1-$I$7)+$I$4-$I$4*($I$5+(1.05-$I$5)*{1;2;3;4;5;6;7;8;9;10}/10)-(K26/(1+K26))*$I$6)/(1+M26)^{1;2;3;4;5;6;7;8;9;10})+$I$2*(1+K26)^10*(L26+$I$4)*N26/(1+M26)^10+$I$9-$I$10)/$I$11
A27: P50 | B27: =PERCENTILE($O$2:$O$1001,0.5) | K27: =MAX(-0.05,NORMINV(RAND(),$C$6,$D$6)) | L27: =MAX(0.02,NORMINV(RAND(),$C$7,$D$7)) | M27: =MIN(0.16,MAX(0.05,NORMINV(RAND(),$C$8,$D$8))) | N27: =MIN(24,MAX(5,NORMINV(RAND(),$C$9,$D$9))) | O27: =$I$8*(SUMPRODUCT(($I$2*(1+K27)^{1;2;3;4;5;6;7;8;9;10})*(($I$3+(L27-$I$3)*{1;2;3;4;5;6;7;8;9;10}/10)*(1-$I$7)+$I$4-$I$4*($I$5+(1.05-$I$5)*{1;2;3;4;5;6;7;8;9;10}/10)-(K27/(1+K27))*$I$6)/(1+M27)^{1;2;3;4;5;6;7;8;9;10})+$I$2*(1+K27)^10*(L27+$I$4)*N27/(1+M27)^10+$I$9-$I$10)/$I$11
A28: P75 | B28: =PERCENTILE($O$2:$O$1001,0.75) | K28: =MAX(-0.05,NORMINV(RAND(),$C$6,$D$6)) | L28: =MAX(0.02,NORMINV(RAND(),$C$7,$D$7)) | M28: =MIN(0.16,MAX(0.05,NORMINV(RAND(),$C$8,$D$8))) | N28: =MIN(24,MAX(5,NORMINV(RAND(),$C$9,$D$9))) | O28: =$I$8*(SUMPRODUCT(($I$2*(1+K28)^{1;2;3;4;5;6;7;8;9;10})*(($I$3+(L28-$I$3)*{1;2;3;4;5;6;7;8;9;10}/10)*(1-$I$7)+$I$4-$I$4*($I$5+(1.05-$I$5)*{1;2;3;4;5;6;7;8;9;10}/10)-(K28/(1+K28))*$I$6)/(1+M28)^{1;2;3;4;5;6;7;8;9;10})+$I$2*(1+K28)^10*(L28+$I$4)*N28/(1+M28)^10+$I$9-$I$10)/$I$11
A29: P90 | B29: =PERCENTILE($O$2:$O$1001,0.9) | K29: =MAX(-0.05,NORMINV(RAND(),$C$6,$D$6)) | L29: =MAX(0.02,NORMINV(RAND(),$C$7,$D$7)) | M29: =MIN(0.16,MAX(0.05,NORMINV(RAND(),$C$8,$D$8))) | N29: =MIN(24,MAX(5,NORMINV(RAND(),$C$9,$D$9))) | O29: =$I$8*(SUMPRODUCT(($I$2*(1+K29)^{1;2;3;4;5;6;7;8;9;10})*(($I$3+(L29-$I$3)*{1;2;3;4;5;6;7;8;9;10}/10)*(1-$I$7)+$I$4-$I$4*($I$5+(1.05-$I$5)*{1;2;3;4;5;6;7;8;9;10}/10)-(K29/(1+K29))*$I$6)/(1+M29)^{1;2;3;4;5;6;7;8;9;10})+$I$2*(1+K29)^10*(L29+$I$4)*N29/(1+M29)^10+$I$9-$I$10)/$I$11
A30: P95 | B30: =PERCENTILE($O$2:$O$1001,0.95) | K30: =MAX(-0.05,NORMINV(RAND(),$C$6,$D$6)) | L30: =MAX(0.02,NORMINV(RAND(),$C$7,$D$7)) | M30: =MIN(0.16,MAX(0.05,NORMINV(RAND(),$C$8,$D$8))) | N30: =MIN(24,MAX(5,NORMINV(RAND(),$C$9,$D$9))) | O30: =$I$8*(SUMPRODUCT(($I$2*(1+K30)^{1;2;3;4;5;6;7;8;9;10})*(($I$3+(L30-$I$3)*{1;2;3;4;5;6;7;8;9;10}/10)*(1-$I$7)+$I$4-$I$4*($I$5+(1.05-$I$5)*{1;2;3;4;5;6;7;8;9;10}/10)-(K30/(1+K30))*$I$6)/(1+M30)^{1;2;3;4;5;6;7;8;9;10})+$I$2*(1+K30)^10*(L30+$I$4)*N30/(1+M30)^10+$I$9-$I$10)/$I$11
K31: =MAX(-0.05,NORMINV(RAND(),$C$6,$D$6)) | L31: =MAX(0.02,NORMINV(RAND(),$C$7,$D$7)) | M31: =MIN(0.16,MAX(0.05,NORMINV(RAND(),$C$8,$D$8))) | N31: =MIN(24,MAX(5,NORMINV(RAND(),$C$9,$D$9))) | O31: =$I$8*(SUMPRODUCT(($I$2*(1+K31)^{1;2;3;4;5;6;7;8;9;10})*(($I$3+(L31-$I$3)*{1;2;3;4;5;6;7;8;9;10}/10)*(1-$I$7)+$I$4-$I$4*($I$5+(1.05-$I$5)*{1;2;3;4;5;6;7;8;9;10}/10)-(K31/(1+K31))*$I$6)/(1+M31)^{1;2;3;4;5;6;7;8;9;10})+$I$2*(1+K31)^10*(L31+$I$4)*N31/(1+M31)^10+$I$9-$I$10)/$I$11
A32: VALUE DISTRIBUTION (live histogram) | K32: =MAX(-0.05,NORMINV(RAND(),$C$6,$D$6)) | L32: =MAX(0.02,NORMINV(RAND(),$C$7,$D$7)) | M32: =MIN(0.16,MAX(0.05,NORMINV(RAND(),$C$8,$D$8))) | N32: =MIN(24,MAX(5,NORMINV(RAND(),$C$9,$D$9))) | O32: =$I$8*(SUMPRODUCT(($I$2*(1+K32)^{1;2;3;4;5;6;7;8;9;10})*(($I$3+(L32-$I$3)*{1;2;3;4;5;6;7;8;9;10}/10)*(1-$I$7)+$I$4-$I$4*($I$5+(1.05-$I$5)*{1;2;3;4;5;6;7;8;9;10}/10)-(K32/(1+K32))*$I$6)/(1+M32)^{1;2;3;4;5;6;7;8;9;10})+$I$2*(1+K32)^10*(L32+$I$4)*N32/(1+M32)^10+$I$9-$I$10)/$I$11
A33: Bin midpoint ($/sh) | B33: Count | K33: =MAX(-0.05,NORMINV(RAND(),$C$6,$D$6)) | L33: =MAX(0.02,NORMINV(RAND(),$C$7,$D$7)) | M33: =MIN(0.16,MAX(0.05,NORMINV(RAND(),$C$8,$D$8))) | N33: =MIN(24,MAX(5,NORMINV(RAND(),$C$9,$D$9))) | O33: =$I$8*(SUMPRODUCT(($I$2*(1+K33)^{1;2;3;4;5;6;7;8;9;10})*(($I$3+(L33-$I$3)*{1;2;3;4;5;6;7;8;9;10}/10)*(1-$I$7)+$I$4-$I$4*($I$5+(1.05-$I$5)*{1;2;3;4;5;6;7;8;9;10}/10)-(K33/(1+K33))*$I$6)/(1+M33)^{1;2;3;4;5;6;7;8;9;10})+$I$2*(1+K33)^10*(L33+$I$4)*N33/(1+M33)^10+$I$9-$I$10)/$I$11
A34: =$B$15+0.5*($B$16-$B$15)/15 | B34: =COUNTIFS($O$2:$O$1001,">="&($B$15+0*($B$16-$B$15)/15),$O$2:$O$1001,"<"&($B$15+1*($B$16-$B$15)/15)) | K34: =MAX(-0.05,NORMINV(RAND(),$C$6,$D$6)) | L34: =MAX(0.02,NORMINV(RAND(),$C$7,$D$7)) | M34: =MIN(0.16,MAX(0.05,NORMINV(RAND(),$C$8,$D$8))) | N34: =MIN(24,MAX(5,NORMINV(RAND(),$C$9,$D$9))) | O34: =$I$8*(SUMPRODUCT(($I$2*(1+K34)^{1;2;3;4;5;6;7;8;9;10})*(($I$3+(L34-$I$3)*{1;2;3;4;5;6;7;8;9;10}/10)*(1-$I$7)+$I$4-$I$4*($I$5+(1.05-$I$5)*{1;2;3;4;5;6;7;8;9;10}/10)-(K34/(1+K34))*$I$6)/(1+M34)^{1;2;3;4;5;6;7;8;9;10})+$I$2*(1+K34)^10*(L34+$I$4)*N34/(1+M34)^10+$I$9-$I$10)/$I$11
A35: =$B$15+1.5*($B$16-$B$15)/15 | B35: =COUNTIFS($O$2:$O$1001,">="&($B$15+1*($B$16-$B$15)/15),$O$2:$O$1001,"<"&($B$15+2*($B$16-$B$15)/15)) | K35: =MAX(-0.05,NORMINV(RAND(),$C$6,$D$6)) | L35: =MAX(0.02,NORMINV(RAND(),$C$7,$D$7)) | M35: =MIN(0.16,MAX(0.05,NORMINV(RAND(),$C$8,$D$8))) | N35: =MIN(24,MAX(5,NORMINV(RAND(),$C$9,$D$9))) | O35: =$I$8*(SUMPRODUCT(($I$2*(1+K35)^{1;2;3;4;5;6;7;8;9;10})*(($I$3+(L35-$I$3)*{1;2;3;4;5;6;7;8;9;10}/10)*(1-$I$7)+$I$4-$I$4*($I$5+(1.05-$I$5)*{1;2;3;4;5;6;7;8;9;10}/10)-(K35/(1+K35))*$I$6)/(1+M35)^{1;2;3;4;5;6;7;8;9;10})+$I$2*(1+K35)^10*(L35+$I$4)*N35/(1+M35)^10+$I$9-$I$10)/$I$11
A36: =$B$15+2.5*($B$16-$B$15)/15 | B36: =COUNTIFS($O$2:$O$1001,">="&($B$15+2*($B$16-$B$15)/15),$O$2:$O$1001,"<"&($B$15+3*($B$16-$B$15)/15)) | K36: =MAX(-0.05,NORMINV(RAND(),$C$6,$D$6)) | L36: =MAX(0.02,NORMINV(RAND(),$C$7,$D$7)) | M36: =MIN(0.16,MAX(0.05,NORMINV(RAND(),$C$8,$D$8))) | N36: =MIN(24,MAX(5,NORMINV(RAND(),$C$9,$D$9))) | O36: =$I$8*(SUMPRODUCT(($I$2*(1+K36)^{1;2;3;4;5;6;7;8;9;10})*(($I$3+(L36-$I$3)*{1;2;3;4;5;6;7;8;9;10}/10)*(1-$I$7)+$I$4-$I$4*($I$5+(1.05-$I$5)*{1;2;3;4;5;6;7;8;9;10}/10)-(K36/(1+K36))*$I$6)/(1+M36)^{1;2;3;4;5;6;7;8;9;10})+$I$2*(1+K36)^10*(L36+$I$4)*N36/(1+M36)^10+$I$9-$I$10)/$I$11
A37: =$B$15+3.5*($B$16-$B$15)/15 | B37: =COUNTIFS($O$2:$O$1001,">="&($B$15+3*($B$16-$B$15)/15),$O$2:$O$1001,"<"&($B$15+4*($B$16-$B$15)/15)) | K37: =MAX(-0.05,NORMINV(RAND(),$C$6,$D$6)) | L37: =MAX(0.02,NORMINV(RAND(),$C$7,$D$7)) | M37: =MIN(0.16,MAX(0.05,NORMINV(RAND(),$C$8,$D$8))) | N37: =MIN(24,MAX(5,NORMINV(RAND(),$C$9,$D$9))) | O37: =$I$8*(SUMPRODUCT(($I$2*(1+K37)^{1;2;3;4;5;6;7;8;9;10})*(($I$3+(L37-$I$3)*{1;2;3;4;5;6;7;8;9;10}/10)*(1-$I$7)+$I$4-$I$4*($I$5+(1.05-$I$5)*{1;2;3;4;5;6;7;8;9;10}/10)-(K37/(1+K37))*$I$6)/(1+M37)^{1;2;3;4;5;6;7;8;9;10})+$I$2*(1+K37)^10*(L37+$I$4)*N37/(1+M37)^10+$I$9-$I$10)/$I$11
A38: =$B$15+4.5*($B$16-$B$15)/15 | B38: =COUNTIFS($O$2:$O$1001,">="&($B$15+4*($B$16-$B$15)/15),$O$2:$O$1001,"<"&($B$15+5*($B$16-$B$15)/15)) | K38: =MAX(-0.05,NORMINV(RAND(),$C$6,$D$6)) | L38: =MAX(0.02,NORMINV(RAND(),$C$7,$D$7)) | M38: =MIN(0.16,MAX(0.05,NORMINV(RAND(),$C$8,$D$8))) | N38: =MIN(24,MAX(5,NORMINV(RAND(),$C$9,$D$9))) | O38: =$I$8*(SUMPRODUCT(($I$2*(1+K38)^{1;2;3;4;5;6;7;8;9;10})*(($I$3+(L38-$I$3)*{1;2;3;4;5;6;7;8;9;10}/10)*(1-$I$7)+$I$4-$I$4*($I$5+(1.05-$I$5)*{1;2;3;4;5;6;7;8;9;10}/10)-(K38/(1+K38))*$I$6)/(1+M38)^{1;2;3;4;5;6;7;8;9;10})+$I$2*(1+K38)^10*(L38+$I$4)*N38/(1+M38)^10+$I$9-$I$10)/$I$11
A39: =$B$15+5.5*($B$16-$B$15)/15 | B39: =COUNTIFS($O$2:$O$1001,">="&($B$15+5*($B$16-$B$15)/15),$O$2:$O$1001,"<"&($B$15+6*($B$16-$B$15)/15)) | K39: =MAX(-0.05,NORMINV(RAND(),$C$6,$D$6)) | L39: =MAX(0.02,NORMINV(RAND(),$C$7,$D$7)) | M39: =MIN(0.16,MAX(0.05,NORMINV(RAND(),$C$8,$D$8))) | N39: =MIN(24,MAX(5,NORMINV(RAND(),$C$9,$D$9))) | O39: =$I$8*(SUMPRODUCT(($I$2*(1+K39)^{1;2;3;4;5;6;7;8;9;10})*(($I$3+(L39-$I$3)*{1;2;3;4;5;6;7;8;9;10}/10)*(1-$I$7)+$I$4-$I$4*($I$5+(1.05-$I$5)*{1;2;3;4;5;6;7;8;9;10}/10)-(K39/(1+K39))*$I$6)/(1+M39)^{1;2;3;4;5;6;7;8;9;10})+$I$2*(1+K39)^10*(L39+$I$4)*N39/(1+M39)^10+$I$9-$I$10)/$I$11
A40: =$B$15+6.5*($B$16-$B$15)/15 | B40: =COUNTIFS($O$2:$O$1001,">="&($B$15+6*($B$16-$B$15)/15),$O$2:$O$1001,"<"&($B$15+7*($B$16-$B$15)/15)) | K40: =MAX(-0.05,NORMINV(RAND(),$C$6,$D$6)) | L40: =MAX(0.02,NORMINV(RAND(),$C$7,$D$7)) | M40: =MIN(0.16,MAX(0.05,NORMINV(RAND(),$C$8,$D$8))) | N40: =MIN(24,MAX(5,NORMINV(RAND(),$C$9,$D$9))) | O40: =$I$8*(SUMPRODUCT(($I$2*(1+K40)^{1;2;3;4;5;6;7;8;9;10})*(($I$3+(L40-$I$3)*{1;2;3;4;5;6;7;8;9;10}/10)*(1-$I$7)+$I$4-$I$4*($I$5+(1.05-$I$5)*{1;2;3;4;5;6;7;8;9;10}/10)-(K40/(1+K40))*$I$6)/(1+M40)^{1;2;3;4;5;6;7;8;9;10})+$I$2*(1+K40)^10*(L40+$I$4)*N40/(1+M40)^10+$I$9-$I$10)/$I$11
...
