Workbook

Sheet Cover
A1: Sea Limited (SE)
A2: DCF valuation — exit-multiple terminal · defaults anchored to consensus
A4: Last updated | B4: 2026-06-05
A5: Data pulled (FMP) | B5: Q1 2026
A6: Assumptions by | B6: Opus 4.8 — 2026-06-05
A8: VALUATION SUMMARY
A10: Fair value / share | B10: =Valuation!B36
A11: Current price | B11: =Valuation!$B$2
A12: Upside / (downside) | B12: =Valuation!B42
A13: Verdict | B13: =IF(Valuation!B36>Valuation!$B$2,"Undervalued","Overvalued")
A14: Monte Carlo P(undervalued) | B14: ='Monte Carlo'!B20
A15: KEY ASSUMPTIONS
A17: WACC (from WACC tab) | B17: =WACC!B14
A18: Terminal method | B18: =Valuation!$B$6
A19: Exit basis / multiple | B19: =Valuation!$B$7
A20: Exit multiple | B20: =Valuation!$B$8
A21: Terminal growth (g) | B21: =Valuation!$B$4
A22: Terminal weight | B22: =Valuation!B39
A23: Forecast horizon | B23: 10 years
A25: THE STORY (Opus)
A27: (Opus narrative)

Sheet Dashboard
A1: Sea Limited (SE) — Control Dashboard
A2: Edit the yellow cells; everything recomputes. Orange = a driver you've moved off consensus.
A4: VERDICT
A5: Fair value / share | B5: =Valuation!B36
A6: Current price | B6: =Dashboard!$B$48
A7: Upside / (downside) | B7: =Valuation!B42
A8: Verdict | B8: =IF(Valuation!B36>Dashboard!$B$48,"Undervalued","Overvalued")
A9: Monte Carlo P(undervalued) | B9: ='Monte Carlo'!B20
A11: GUARDRAIL SIGNALS (are my assumptions sane?)
A12: Signal | B12: Value | C12: Flag | D12: Healthy
A13: Terminal weight (% of EV) | B13: =Valuation!B39 | C13: =IF(Valuation!B39>0.9,"! high","ok") | D13: < 90%
A14: Implied g vs exit multiple | B14: =Valuation!B40 | C14: =IF(Valuation!B40>Dashboard!$B$46+0.02,"! rich","ok") | D14: near term g
A15: ROIC - WACC (2026) | B15: =Model!G36-WACC!B14 | C15: =IF(Model!G36-WACC!B14<0,"! destroys","creates") | D15: > 0
A16: Revenue vs consensus (2026) | B16: =Consensus!B6 | C16: =IF(ABS(Consensus!B6)>0.05,"! off-Street","on") | D16: +/- 5%
A17: MC P(undervalued) | B17: ='Monte Carlo'!B20 | C17: =IF('Monte Carlo'!B20<0.5,"! coin-flip","ok") | D17: context
A18: REVENUE DRIVERS — near-term & terminal growth per segment
A19: Segment | B19: Near-term | C19: Terminal | D19: Consensus | E19: Thesis claim
A20: Total company | B20: 0.17624357 | C20: 0.05 | D20: 0.17624357
A28: PROFITABILITY & TAX
A29: Near-term operating margin | B29: 0.099021458 | D29: 0.099021458 | E29: consensus-implied; ramps to terminal
A30: Terminal operating margin | B30: 0.15236973 | E30: AI/ads mix + operating leverage
A31: Tax rate | B31: 0.24
A33: CAPITAL INTENSITY
A34: 2026 capex ($M) | B34: 2010.151 | D34: 2010.151 | E34: ~last-year capex +10%; set to guidance
A35: Terminal capex / D&A | B35: 1.05 | E35: converges to ~1.0x as build-out matures
A37: DISCOUNT RATE & TERMINAL
A38: Risk-free rate (10Y) | B38: 0.043
A39: Equity risk premium | B39: 0.045
A40: Beta (levered) | B40: 1.573 | E40: FMP raw beta; Damodaran bottom-up ~1.2
A41: Pre-tax cost of debt | B41: 0.045
A42: WACC (computed) | B42: =WACC!B14
A43: Terminal method | B43: Exit multiple
A44: Exit basis | B44: EV/EBITDA
A45: Exit multiple | B45: 12
A46: Terminal growth (g) | B46: 0.045
A48: Current price | B48: 88.470001

Sheet Color Code
A1: Color | B1: Meaning
A2: Black | B2: Formula-driven (same-sheet)
A3: Blue | B3: Hard-coded actuals (from FMP filings)
A4: Yellow | B4: An assumption you can change — edit these to drive the model
A5: Green | B5: A formula that links to another sheet
A6: Orange | B6: (Dashboard) an assumption you've moved off consensus — your active bet
A7: How to use | B7: Edit yellow cells (Model assumptions, WACC drivers, Valuation toggles). Everything else recomputes.

Sheet WACC
A1: WACC Calculator
A2: Risk-free rate (10Y) | B2: =Dashboard!$B$38
A3: Equity risk premium | B3: =Dashboard!$B$39
A4: Beta (levered) | B4: =Dashboard!$B$40
A5: Cost of equity (CAPM) | B5: =B2+B4*B3
A6: Pre-tax cost of debt | B6: =Dashboard!$B$41
A7: Tax rate | B7: =Dashboard!$B$31
A8: After-tax cost of debt | B8: =B6*(1-B7)
A9: Market cap (E) | B9: =Dashboard!$B$48*Financials!AC17
A10: Total debt (D) | B10: =Financials!AC24
A11: Equity weight | B11: =B9/(B9+B10)
A12: Debt weight | B12: =B10/(B9+B10)
A14: WACC | B14: =B11*B5+B12*B8
A16: Yellow = edit. CAPM cost of equity; market-value weights. Feeds Valuation!WACC.

Sheet Model
A1: $M unless noted | B1: FY2021A | C1: FY2022A | D1: FY2023A | E1: FY2024A | F1: FY2025A | G1: FY2026E | H1: FY2027E | I1: FY2028E | J1: FY2029E | K1: FY2030E | L1: FY2031E | M1: FY2032E | N1: FY2033E | O1: FY2034E | P1: FY2035E
A3: REVENUE BY SEGMENT (yellow = growth assumption; actuals link to Financials)
A4: Total company | B4: =SUM(Financials!I3:L3) | C4: =SUM(Financials!M3:P3) | D4: =SUM(Financials!Q3:T3) | E4: =SUM(Financials!U3:X3) | F4: =SUM(Financials!Y3:AB3) | G4: =F4*(1+G5) | H4: =G4*(1+H5) | I4: =H4*(1+I5) | J4: =I4*(1+J5) | K4: =J4*(1+K5) | L4: =K4*(1+L5) | M4: =L4*(1+M5) | N4: =M4*(1+N5) | ... P4: =O4*(1+P5)
A5: growth % (interpolated from Dashboard) | C5: =IFERROR(C4/B4-1,"") | D5: =IFERROR(D4/C4-1,"") | E5: =IFERROR(E4/D4-1,"") | F5: =IFERROR(F4/E4-1,"") | G5: =Dashboard!$B$20+(Dashboard!$C$20-Dashboard!$B$20)*MAX(0,0-2)/7 | H5: =Dashboard!$B$20+(Dashboard!$C$20-Dashboard!$B$20)*MAX(0,1-2)/7 | I5: =Dashboard!$B$20+(Dashboard!$C$20-Dashboard!$B$20)*MAX(0,2-2)/7 | J5: =Dashboard!$B$20+(Dashboard!$C$20-Dashboard!$B$20)*MAX(0,3-2)/7 | K5: =Dashboard!$B$20+(Dashboard!$C$20-Dashboard!$B$20)*MAX(0,4-2)/7 | L5: =Dashboard!$B$20+(Dashboard!$C$20-Dashboard!$B$20)*MAX(0,5-2)/7 | M5: =Dashboard!$B$20+(Dashboard!$C$20-Dashboard!$B$20)*MAX(0,6-2)/7 | N5: =Dashboard!$B$20+(Dashboard!$C$20-Dashboard!$B$20)*MAX(0,7-2)/7 | O5: =Dashboard!$B$20+(Dashboard!$C$20-Dashboard!$B$20)*MAX(0,8-2)/7 | P5: =Dashboard!$B$20+(Dashboard!$C$20-Dashboard!$B$20)*MAX(0,9-2)/7
A6: Total revenue | B6: =B4 | C6: =C4 | D6: =D4 | E6: =E4 | F6: =F4 | G6: =G4 | H6: =H4 | I6: =I4 | ... P6: =P4
A7: growth % | C7: =IFERROR(C6/B6-1,"") | D7: =IFERROR(D6/C6-1,"") | E7: =IFERROR(E6/D6-1,"") | F7: =IFERROR(F6/E6-1,"") | G7: =IFERROR(G6/F6-1,"") | H7: =IFERROR(H6/G6-1,"") | I7: =IFERROR(I6/H6-1,"") | J7: =IFERROR(J6/I6-1,"") | ... P7: =IFERROR(P6/O6-1,"")
A9: COST STRUCTURE (yellow = % of revenue)
A10: Cost of revenue | B10: =SUM(Financials!I5:L5) | C10: =SUM(Financials!M5:P5) | D10: =SUM(Financials!Q5:T5) | E10: =SUM(Financials!U5:X5) | F10: =SUM(Financials!Y5:AB5) | G10: =G6*G11 | H10: =H6*H11 | I10: =I6*I11 | J10: =J6*J11 | K10: =K6*K11 | L10: =L6*L11 | M10: =M6*M11 | N10: =N6*N11 | ... P10: =P6*P11
A11: % of revenue | B11: =IFERROR(B10/B6,"") | C11: =IFERROR(C10/C6,"") | D11: =IFERROR(D10/D6,"") | E11: =IFERROR(E10/E6,"") | F11: =IFERROR(F10/F6,"") | G11: 0.55342543 | H11: 0.55342543 | I11: 0.55342543 | J11: 0.55342543 | K11: 0.55342543 | L11: 0.55342543 | M11: 0.55342543 | N11: 0.55342543 | O11: 0.55342543 | P11: 0.55342543
A12: R&D / Technology | B12: =SUM(Financials!I7:L7) | C12: =SUM(Financials!M7:P7) | D12: =SUM(Financials!Q7:T7) | E12: =SUM(Financials!U7:X7) | F12: =SUM(Financials!Y7:AB7) | G12: =G6*G13 | H12: =H6*H13 | I12: =I6*I13 | J12: =J6*J13 | K12: =K6*K13 | L12: =L6*L13 | M12: =M6*M13 | N12: =N6*N13 | ... P12: =P6*P13
A13: % of revenue | B13: =IFERROR(B12/B6,"") | C13: =IFERROR(C12/C6,"") | D13: =IFERROR(D12/D6,"") | E13: =IFERROR(E12/E6,"") | F13: =IFERROR(F12/F6,"") | G13: 0.050445782 | H13: 0.050445782 | I13: 0.050445782 | J13: 0.050445782 | K13: 0.050445782 | L13: 0.050445782 | M13: 0.050445782 | N13: 0.050445782 | O13: 0.050445782 | P13: 0.050445782
A14: SG&A | B14: =SUM(Financials!I9:L9) | C14: =SUM(Financials!M9:P9) | D14: =SUM(Financials!Q9:T9) | E14: =SUM(Financials!U9:X9) | F14: =SUM(Financials!Y9:AB9) | G14: =G6*G15 | H14: =H6*H15 | I14: =I6*I15 | J14: =J6*J15 | K14: =K6*K15 | L14: =L6*L15 | M14: =M6*M15 | N14: =N6*N15 | ... P14: =P6*P15
A15: % of revenue | B15: =IFERROR(B14/B6,"") | C15: =IFERROR(C14/C6,"") | D15: =IFERROR(D14/D6,"") | E15: =IFERROR(E14/E6,"") | F15: =IFERROR(F14/F6,"") | G15: 0.27216777 | H15: 0.27216777 | I15: 0.27216777 | J15: 0.27216777 | K15: 0.27216777 | L15: 0.27216777 | M15: 0.27216777 | N15: 0.27216777 | O15: 0.27216777 | P15: 0.27216777
A16: Other opex (fulfilment, etc.) | B16: =B6-(B10+B12+B14)-SUM(Financials!I13:L13) | C16: =C6-(C10+C12+C14)-SUM(Financials!M13:P13) | D16: =D6-(D10+D12+D14)-SUM(Financials!Q13:T13) | E16: =E6-(E10+E12+E14)-SUM(Financials!U13:X13) | F16: =F6-(F10+F12+F14)-SUM(Financials!Y13:AB13) | G16: =G6*(1-(Dashboard!$B$29+(Dashboard!$B$30-Dashboard!$B$29)*MIN(1,0/4)))-(G10+G12+G14) | H16: =H6*(1-(Dashboard!$B$29+(Dashboard!$B$30-Dashboard!$B$29)*MIN(1,1/4)))-(H10+H12+H14) | I16: =I6*(1-(Dashboard!$B$29+(Dashboard!$B$30-Dashboard!$B$29)*MIN(1,2/4)))-(I10+I12+I14) | J16: =J6*(1-(Dashboard!$B$29+(Dashboard!$B$30-Dashboard!$B$29)*MIN(1,3/4)))-(J10+J12+J14) | K16: =K6*(1-(Dashboard!$B$29+(Dashboard!$B$30-Dashboard!$B$29)*MIN(1,4/4)))-(K10+K12+K14) | L16: =L6*(1-(Dashboard!$B$29+(Dashboard!$B$30-Dashboard!$B$29)*MIN(1,5/4)))-(L10+L12+L14) | M16: =M6*(1-(Dashboard!$B$29+(Dashboard!$B$30-Dashboard!$B$29)*MIN(1,6/4)))-(M10+M12+M14) | N16: =N6*(1-(Dashboard!$B$29+(Dashboard!$B$30-Dashboard!$B$29)*MIN(1,7/4)))-(N10+N12+N14) | O16: =O6*(1-(Dashboard!$B$29+(Dashboard!$B$30-Dashboard!$B$29)*MIN(1,8/4)))-(O10+O12+O14) | P16: =P6*(1-(Dashboard!$B$29+(Dashboard!$B$30-Dashboard!$B$29)*MIN(1,9/4)))-(P10+P12+P14)
A17: % of revenue | B17: =IFERROR(B16/B6,"") | C17: =IFERROR(C16/C6,"") | D17: =IFERROR(D16/D6,"") | E17: =IFERROR(E16/E6,"") | F17: =IFERROR(F16/F6,"") | G17: =IFERROR(G16/G6,"") | H17: =IFERROR(H16/H6,"") | I17: =IFERROR(I16/I6,"") | ... P17: =IFERROR(P16/P6,"")
A19: Operating income (EBIT) | B19: =B6-(B10+B12+B14)-B16 | C19: =C6-(C10+C12+C14)-C16 | D19: =D6-(D10+D12+D14)-D16 | E19: =E6-(E10+E12+E14)-E16 | F19: =F6-(F10+F12+F14)-F16 | G19: =G6-(G10+G12+G14)-G16 | H19: =H6-(H10+H12+H14)-H16 | I19: =I6-(I10+I12+I14)-I16 | ... P19: =P6-(P10+P12+P14)-P16
A20: operating margin | B20: =IFERROR(B19/B6,"") | C20: =IFERROR(C19/C6,"") | D20: =IFERROR(D19/D6,"") | E20: =IFERROR(E19/E6,"") | F20: =IFERROR(F19/F6,"") | G20: =IFERROR(G19/G6,"") | H20: =IFERROR(H19/H6,"") | I20: =IFERROR(I19/I6,"") | ... P20: =IFERROR(P19/P6,"")
A22: FCF BRIDGE (NOPAT + D&A + SBC - dNWC - Capex)
A23: NOPAT = EBIT x (1 - tax) | B23: =B19*(1-Valuation!$B$5) | C23: =C19*(1-Valuation!$B$5) | D23: =D19*(1-Valuation!$B$5) | E23: =E19*(1-Valuation!$B$5) | F23: =F19*(1-Valuation!$B$5) | G23: =G19*(1-Valuation!$B$5) | H23: =H19*(1-Valuation!$B$5) | I23: =I19*(1-Valuation!$B$5) | ... P23: =P19*(1-Valuation!$B$5)
A24: + D&A | B24: =SUM(Financials!I27:L27) | C24: =SUM(Financials!M27:P27) | D24: =SUM(Financials!Q27:T27) | E24: =SUM(Financials!U27:X27) | F24: =SUM(Financials!Y27:AB27) | G24: =G6*0.0044 | H24: =H6*0.0044 | I24: =I6*0.0044 | J24: =J6*0.0044 | K24: =K6*0.0044 | L24: =L6*0.0044 | M24: =M6*0.0044 | N24: =N6*0.0044 | ... P24: =P6*0.0044
A25: + SBC (non-cash) | B25: =SUM(Financials!I28:L28) | C25: =SUM(Financials!M28:P28) | D25: =SUM(Financials!Q28:T28) | E25: =SUM(Financials!U28:X28) | F25: =SUM(Financials!Y28:AB28) | G25: =G6*0.0222 | H25: =H6*0.0212 | I25: =I6*0.0202 | J25: =J6*0.0192 | K25: =K6*0.0182 | L25: =L6*0.0173 | M25: =M6*0.0163 | N25: =N6*0.0153 | O25: =O6*0.0143 | P25: =P6*0.0133
A26: - dNWC | G26: =(G6-F6)*0.0050 | H26: =(H6-G6)*0.0050 | I26: =(I6-H6)*0.0050 | J26: =(J6-I6)*0.0050 | K26: =(K6-J6)*0.0050 | L26: =(L6-K6)*0.0050 | M26: =(M6-L6)*0.0050 | N26: =(N6-M6)*0.0050 | ... P26: =(P6-O6)*0.0050
A27: - Capex | B27: =-SUM(Financials!I31:L31) | C27: =-SUM(Financials!M31:P31) | D27: =-SUM(Financials!Q31:T31) | E27: =-SUM(Financials!U31:X31) | F27: =-SUM(Financials!Y31:AB31) | G27: =G24*G28 | H27: =H24*H28 | I27: =I24*I28 | J27: =J24*J28 | K27: =K24*K28 | L27: =L24*L28 | M27: =M24*M28 | N27: =N24*N28 | ... P27: =P24*P28
A28: Capex / D&A (from Dashboard: $cap'26 -> terminal) | B28: =IFERROR(B27/B24,"") | C28: =IFERROR(C27/C24,"") | D28: =IFERROR(D27/D24,"") | E28: =IFERROR(E27/E24,"") | F28: =IFERROR(F27/F24,"") | G28: =(Dashboard!$B$34/G24)+(Dashboard!$B$35-(Dashboard!$B$34/G24))*0/9 | H28: =(Dashboard!$B$34/G24)+(Dashboard!$B$35-(Dashboard!$B$34/G24))*1/9 | I28: =(Dashboard!$B$34/G24)+(Dashboard!$B$35-(Dashboard!$B$34/G24))*2/9 | J28: =(Dashboard!$B$34/G24)+(Dashboard!$B$35-(Dashboard!$B$34/G24))*3/9 | K28: =(Dashboard!$B$34/G24)+(Dashboard!$B$35-(Dashboard!$B$34/G24))*4/9 | L28: =(Dashboard!$B$34/G24)+(Dashboard!$B$35-(Dashboard!$B$34/G24))*5/9 | M28: =(Dashboard!$B$34/G24)+(Dashboard!$B$35-(Dashboard!$B$34/G24))*6/9 | N28: =(Dashboard!$B$34/G24)+(Dashboard!$B$35-(Dashboard!$B$34/G24))*7/9 | O28: =(Dashboard!$B$34/G24)+(Dashboard!$B$35-(Dashboard!$B$34/G24))*8/9 | P28: =(Dashboard!$B$34/G24)+(Dashboard!$B$35-(Dashboard!$B$34/G24))*9/9
A30: FCFF (firm) | B30: =B23+B24+B25-B26-B27 | C30: =C23+C24+C25-C26-C27 | D30: =D23+D24+D25-D26-D27 | E30: =E23+E24+E25-E26-E27 | F30: =F23+F24+F25-F26-F27 | G30: =G23+G24+G25-G26-G27 | H30: =H23+H24+H25-H26-H27 | I30: =I23+I24+I25-I26-I27 | ... P30: =P23+P24+P25-P26-P27
A31: Valuation FCF (FCFF - SBC) | B31: =B30-B25 | C31: =C30-C25 | D31: =D30-D25 | E31: =E30-E25 | F31: =F30-F25 | G31: =G30-G25 | H31: =H30-H25 | I31: =I30-I25 | ... P31: =P30-P25
A33: RETURNS ON CAPITAL & EFFICIENCY (is new revenue/capital earning its keep?)
A34: Invested capital (debt + equity - cash) | B34: =Financials!L25+Financials!L24-Financials!L19 | C34: =Financials!P25+Financials!P24-Financials!P19 | D34: =Financials!T25+Financials!T24-Financials!T19 | E34: =Financials!X25+Financials!X24-Financials!X19 | F34: =Financials!AB25+Financials!AB24-Financials!AB19 | G34: =F34+G27-G24+G26 | H34: =G34+H27-H24+H26 | I34: =H34+I27-I24+I26 | J34: =I34+J27-J24+J26 | K34: =J34+K27-K24+K26 | L34: =K34+L27-L24+L26 | M34: =L34+M27-M24+M26 | N34: =M34+N27-N24+N26 | ... P34: =O34+P27-P24+P26
A35: Book equity (year-end) | B35: =Financials!L25 | C35: =Financials!P25 | D35: =Financials!T25 | E35: =Financials!X25 | F35: =Financials!AB25 | G35: =F35+G23 | H35: =G35+H23 | I35: =H35+I23 | J35: =I35+J23 | K35: =J35+K23 | L35: =K35+L23 | M35: =L35+M23 | N35: =M35+N23 | ... P35: =O35+P23
A36: ROIC (NOPAT / beg. invested capital) | C36: =IFERROR(C23/B34,"") | D36: =IFERROR(D23/C34,"") | E36: =IFERROR(E23/D34,"") | F36: =IFERROR(F23/E34,"") | G36: =IFERROR(G23/F34,"") | H36: =IFERROR(H23/G34,"") | I36: =IFERROR(I23/H34,"") | J36: =IFERROR(J23/I34,"") | ... P36: =IFERROR(P23/O34,"")
A37: ROE (earnings / beg. equity) | C37: =IFERROR(SUM(Financials!M15:P15)/B35,"") | D37: =IFERROR(SUM(Financials!Q15:T15)/C35,"") | E37: =IFERROR(SUM(Financials!U15:X15)/D35,"") | F37: =IFERROR(SUM(Financials!Y15:AB15)/E35,"") | G37: =IFERROR(G23/F35,"") | H37: =IFERROR(H23/G35,"") | I37: =IFERROR(I23/H35,"") | J37: =IFERROR(J23/I35,"") | K37: =IFERROR(K23/J35,"") | L37: =IFERROR(L23/K35,"") | M37: =IFERROR(M23/L35,"") | N37: =IFERROR(N23/M35,"") | ... P37: =IFERROR(P23/O35,"")
A38: ROIC - WACC spread (value created) | C38: =IFERROR(C36-WACC!$B$14,"") | D38: =IFERROR(D36-WACC!$B$14,"") | E38: =IFERROR(E36-WACC!$B$14,"") | F38: =IFERROR(F36-WACC!$B$14,"") | G38: =IFERROR(G36-WACC!$B$14,"") | H38: =IFERROR(H36-WACC!$B$14,"") | I38: =IFERROR(I36-WACC!$B$14,"") | J38: =IFERROR(J36-WACC!$B$14,"") | ... P38: =IFERROR(P36-WACC!$B$14,"")
A39: Incremental op margin (ΔEBIT / ΔRev) | C39: =IFERROR((C19-B19)/(C6-B6),"") | D39: =IFERROR((D19-C19)/(D6-C6),"") | E39: =IFERROR((E19-D19)/(E6-D6),"") | F39: =IFERROR((F19-E19)/(F6-E6),"") | G39: =IFERROR((G19-F19)/(G6-F6),"") | H39: =IFERROR((H19-G19)/(H6-G6),"") | I39: =IFERROR((I19-H19)/(I6-H6),"") | J39: =IFERROR((J19-I19)/(J6-I6),"") | ... P39: =IFERROR((P19-O19)/(P6-O6),"")
A40: ROIIC (ΔNOPAT / ΔInvested capital) | C40: =IFERROR((C23-B23)/(C34-B34),"") | D40: =IFERROR((D23-C23)/(D34-C34),"") | E40: =IFERROR((E23-D23)/(E34-D34),"") | F40: =IFERROR((F23-E23)/(F34-E34),"") | G40: =IFERROR((G23-F23)/(G34-F34),"") | H40: =IFERROR((H23-G23)/(H34-G34),"") | I40: =IFERROR((I23-H23)/(I34-H34),"") | J40: =IFERROR((J23-I23)/(J34-I34),"") | ... P40: =IFERROR((P23-O23)/(P34-O34),"")
A41: Sales-to-capital (ΔRev / ΔInvested capital) | C41: =IFERROR((C6-B6)/(C34-B34),"") | D41: =IFERROR((D6-C6)/(D34-C34),"") | E41: =IFERROR((E6-D6)/(E34-D34),"") | F41: =IFERROR((F6-E6)/(F34-E34),"") | G41: =IFERROR((G6-F6)/(G34-F34),"") | H41: =IFERROR((H6-G6)/(H34-G34),"") | I41: =IFERROR((I6-H6)/(I34-H34),"") | J41: =IFERROR((J6-I6)/(J34-I34),"") | ... P41: =IFERROR((P6-O6)/(P34-O34),"")
A42: Reinvestment rate (ΔInvested capital / NOPAT) | C42: =IFERROR((C34-B34)/C23,"") | D42: =IFERROR((D34-C34)/D23,"") | E42: =IFERROR((E34-D34)/E23,"") | F42: =IFERROR((F34-E34)/F23,"") | G42: =IFERROR((G34-F34)/G23,"") | H42: =IFERROR((H34-G34)/H23,"") | I42: =IFERROR((I34-H34)/I23,"") | J42: =IFERROR((J34-I34)/J23,"") | ... P42: =IFERROR((P34-O34)/P23,"")
A44: Blue/green = actual · Yellow = assumption · Black = formula

Sheet Financials
A1: Line Item ($M) | B1: Q2 2019 | C1: Q3 2019 | D1: Q4 2019 | E1: Q1 2020 | F1: Q2 2020 | G1: Q3 2020 | H1: Q4 2020 | I1: Q1 2021 | J1: Q2 2021 | K1: Q3 2021 | L1: Q4 2021 | M1: Q1 2022 | N1: Q2 2022 | O1: Q3 2022 | P1: Q4 2022 | Q1: Q1 2023 | R1: Q2 2023 | S1: Q3 2023 | T1: Q4 2023 | U1: Q1 2024 | V1: Q2 2024 | W1: Q3 2024 | X1: Q4 2024 | Y1: Q1 2025 | Z1: Q2 2025 | AA1: Q3 2025 | AB1: Q4 2025 | AC1: Q1 2026
A2: INCOME STATEMENT
A3: Revenue | B3: 436.151 | C3: 610.137 | D3: 777.224 | E3: 714.92 | F3: 882.034 | G3: 1212.16 | H3: 1566.55 | I3: 1763.644 | J3: 2280.548 | K3: 2688.884 | L3: 3222.114 | M3: 2899.571 | N3: 2942.599 | O3: 3155.951 | P3: 3451.584 | Q3: 3041.104 | R3: 3095.66 | S3: 3310.168 | T3: 3616.628 | U3: 3734.329 | V3: 3806.868 | W3: 4328.233 | X3: 4950.436 | Y3: 4841.1 | Z3: 5259.477 | AA3: 5986.024 | AB3: 6851.868 | AC3: 7097.489
A4: % YoY | F4: =IFERROR(F3/B3-1,"") | G4: =IFERROR(G3/C3-1,"") | H4: =IFERROR(H3/D3-1,"") | I4: =IFERROR(I3/E3-1,"") | J4: =IFERROR(J3/F3-1,"") | K4: =IFERROR(K3/G3-1,"") | L4: =IFERROR(L3/H3-1,"") | M4: =IFERROR(M3/I3-1,"") | ... AC4: =IFERROR(AC3/Y3-1,"")
A5: Cost of Revenue | B5: 338.707 | C5: 406.969 | D5: 512.372 | E5: 508.12 | F5: 681.208 | G5: 804.593 | H5: 1032.838 | I5: 1118.235 | J5: 1349.654 | K5: 1680.18 | L5: 1911.386 | M5: 1729.543 | N5: 1852.381 | O5: 1928.233 | P5: 1754.271 | Q5: 1624.414 | R5: 1644.782 | S5: 1868.876 | T5: 2091.841 | U5: 2180.579 | V5: 2222.051 | W5: 2467.172 | X5: 2744.976 | Y5: 2604.907 | Z5: 2849.667 | AA5: 3386.67 | AB5: 3853.488 | AC5: 3951.907
A6: % of revenue | B6: =IFERROR(B5/B3,"") | C6: =IFERROR(C5/C3,"") | D6: =IFERROR(D5/D3,"") | E6: =IFERROR(E5/E3,"") | F6: =IFERROR(F5/F3,"") | G6: =IFERROR(G5/G3,"") | H6: =IFERROR(H5/H3,"") | I6: =IFERROR(I5/I3,"") | ... AC6: =IFERROR(AC5/AC3,"")
A7: R&D Expense | B7: 35.059 | C7: 43.599 | D7: 49.467 | E7: 64.586 | F7: 75.347 | G7: 104.345 | H7: 109.507 | I7: 141.13 | J7: 172.563 | K7: 231.368 | L7: 286.642 | M7: 340.408 | N7: 370.926 | O7: 420.972 | P7: 244.195 | Q7: 320.512 | R7: 283.297 | S7: 280.511 | T7: 279.806 | U7: 304.379 | V7: 298.465 | W7: 301.99 | X7: 301.216 | Y7: 295.858 | Z7: 297.428 | AA7: 286.275 | AB7: 277.588 | AC7: 296.669
A8: % of revenue | B8: =IFERROR(B7/B3,"") | C8: =IFERROR(C7/C3,"") | D8: =IFERROR(D7/D3,"") | E8: =IFERROR(E7/E3,"") | F8: =IFERROR(F7/F3,"") | G8: =IFERROR(G7/G3,"") | H8: =IFERROR(H7/H3,"") | I8: =IFERROR(I7/I3,"") | ... AC8: =IFERROR(AC7/AC3,"")
A9: SG&A Expense | B9: 299.341 | C9: 351.016 | D9: 451.445 | E9: 435.249 | F9: 530.896 | G9: 667.718 | H9: 854.227 | I9: 927.78 | J9: 1164.354 | K9: 1304.449 | L9: 1538.455 | M9: 1320.841 | N9: 1449.812 | O9: 1221.839 | P9: 487.354 | Q9: 733.52 | R9: 788.77 | S9: 1191.621 | T9: 1200.036 | U9: 1060.489 | V9: 1078.606 | W9: 1185.312 | X9: 1415.985 | Y9: 1236.888 | Z9: 1332.837 | AA9: 1490.326 | AB9: 2183.061 | AC9: 2283.526
A10: % of revenue | B10: =IFERROR(B9/B3,"") | C10: =IFERROR(C9/C3,"") | D10: =IFERROR(D9/D3,"") | E10: =IFERROR(E9/E3,"") | F10: =IFERROR(F9/F3,"") | G10: =IFERROR(G9/G3,"") | H10: =IFERROR(H9/H3,"") | I10: =IFERROR(I9/I3,"") | ... AC10: =IFERROR(AC9/AC3,"")
A11: Gross Profit | B11: 97.444 | C11: 203.168 | D11: 264.852 | E11: 206.8 | F11: 200.826 | G11: 407.567 | H11: 533.712 | I11: 645.409 | J11: 930.894 | K11: 1008.704 | L11: 1310.728 | M11: 1170.028 | N11: 1090.218 | O11: 1227.718 | P11: 1697.313 | Q11: 1416.69 | R11: 1450.878 | S11: 1441.292 | T11: 1524.787 | U11: 1553.75 | V11: 1584.817 | W11: 1861.061 | X11: 2205.46 | Y11: 2236.193 | Z11: 2409.81 | AA11: 2599.354 | AB11: 2998.38 | AC11: 3145.582
A12: gross margin | B12: =IFERROR(B11/B3,"") | C12: =IFERROR(C11/C3,"") | D12: =IFERROR(D11/D3,"") | E12: =IFERROR(E11/E3,"") | F12: =IFERROR(F11/F3,"") | G12: =IFERROR(G11/G3,"") | H12: =IFERROR(H11/H3,"") | I12: =IFERROR(I11/I3,"") | ... AC12: =IFERROR(AC11/AC3,"")
A13: Operating Income | B13: -234.519 | C13: -187.462 | D13: -230.045 | E13: -267.719 | F13: -372.808 | G13: -305.473 | H13: -357.325 | I13: -348.413 | J13: -334.016 | K13: -458.556 | L13: -442.075 | M13: -498.032 | N13: -836.696 | O13: -495.644 | P13: 342.864 | Q13: 125.224 | R13: 283.813 | S13: -127.74 | T13: -56.519 | U13: 71.092 | V13: 82.894 | W13: 202.415 | X13: 305.751 | Y13: 456.404 | Z13: 487.719 | AA13: 475.946 | AB13: 537.731 | AC13: 565.387
A14: operating margin | B14: =IFERROR(B13/B3,"") | C14: =IFERROR(C13/C3,"") | D14: =IFERROR(D13/D3,"") | E14: =IFERROR(E13/E3,"") | F14: =IFERROR(F13/F3,"") | G14: =IFERROR(G13/G3,"") | H14: =IFERROR(H13/H3,"") | I14: =IFERROR(I13/I3,"") | ... AC14: =IFERROR(AC13/AC3,"")
A15: Net Income | B15: -281.067 | C15: -207.588 | D15: -283.789 | E15: -281.513 | F15: -392.961 | G15: -419.99 | H15: -523.592 | I15: -422.69 | J15: -433.442 | K15: -573.019 | L15: -617.608 | M15: -579.809 | N15: -931.199 | O15: -569.275 | P15: 426.798 | Q15: 88.075 | R15: 330.983 | S15: -143.978 | T15: -109.74 | U15: -23.663 | V15: 79.911 | W15: 153.324 | X15: 237.308 | Y15: 403.05 | Z15: 414.204 | AA15: 372.04174 | AB15: 397.099 | AC15: 427.937
A16: net margin | B16: =IFERROR(B15/B3,"") | C16: =IFERROR(C15/C3,"") | D16: =IFERROR(D15/D3,"") | E16: =IFERROR(E15/E3,"") | F16: =IFERROR(F15/F3,"") | G16: =IFERROR(G15/G3,"") | H16: =IFERROR(H15/H3,"") | I16: =IFERROR(I15/I3,"") | ... AC16: =IFERROR(AC15/AC3,"")
A17: Diluted Shares (M) | B17: 444.96805 | C17: 463.24465 | D17: 460.32566 | E17: 462.19405 | F17: 466.49586 | G17: 491.13972 | H17: 494.80509 | I17: 514.7809 | J17: 523.24765 | K17: 538.66668 | L17: 553.63548 | M17: 556.21742 | N17: 557.44513 | O17: 558.44225 | P17: 611.93869 | Q17: 598.69148 | R17: 598.72273 | S17: 564.75884 | T17: 569.52767 | U17: 570.93776 | V17: 574.34001 | W17: 574.34001 | X17: 610.13678 | Y17: 634.63771 | Z17: 592.01993 | AA17: 635.57288 | AB17: 639.52691 | AC17: 636.17278
A18: BALANCE SHEET
A19: Cash & ST Investments | B19: 2317.03 | C19: 2306.603 | D19: 3221.312 | E19: 2630.17 | F19: 3447.522 | G19: 3551.359 | H19: 6292.979 | I19: 6062.272 | J19: 5607.524 | K19: 11832.25 | L19: 10159.043 | M19: 8800.517 | N19: 7780.742 | O19: 7295.678 | P19: 6894.117 | Q19: 6589.123 | R19: 5699.336 | S19: 5982.621 | T19: 5358.7 | U19: 5401.795 | V19: 6033.949 | W19: 7913.288 | X19: 8620.576 | Y19: 8426.244 | Z19: 9410.722 | AA19: 9902.005 | AB19: 12788.914 | AC19: 12760.814
A20: Total Current Assets | B20: 3249.718 | C20: 3317.787 | D20: 4410.139 | E20: 4050.583 | F20: 5251.034 | G20: 5563.087 | H20: 8939.004 | I20: 9025.872 | J20: 9397.098 | K20: 16003.7 | L20: 15135.397 | M20: 13829.896 | N20: 12972.111 | O20: 12577.864 | P20: 12688.012 | Q20: 12440.328 | R20: 11475.827 | S20: 11973.946 | T20: 11773.934 | U20: 12381.266 | V20: 12880.717 | W20: 15554.195 | X20: 16857.668 | Y20: 17779.3 | Z20: 19740.334 | AA20: 21082.769 | AB20: 23249.495 | AC20: 23935.932
A21: PP&E (net) | B21: 425.935 | C21: 463.149 | D21: 501.585 | E21: 468.324 | F21: 523.453 | G21: 552.469 | H21: 620.956 | I21: 628.6 | J21: 830.195 | K21: 1353.29 | L21: 1679.643 | M21: 2101.537 | N21: 2214.729 | O21: 2457.168 | P21: 2345.735 | Q21: 2372.402 | R21: 2308.351 | S21: 2243.783 | T21: 2247.9902 | U21: 2058.4732 | V21: 2188.689 | W21: 2327.665 | X21: 2152.484 | Y21: 2248.314 | Z21: 2371.202 | AA21: 2518.048 | AB21: 2732.035 | AC21: 2838.282
A22: Total Assets | B22: 4019.109 | C22: 4081.901 | D22: 5224.169 | E22: 5232.824 | F22: 6604.269 | G22: 6960.576 | H22: 10455.671 | I22: 10922.595 | J22: 11523.047 | K22: 18548.724 | L22: 18756.025 | M22: 18334.639 | N22: 17467.717 | O22: 17282.288 | P22: 17002.796 | Q22: 17243.922 | R22: 17652.316 | S22: 18025.11 | T22: 18883.232 | U22: 19095.04 | V22: 19570.02 | W22: 21691.69 | X22: 22625.469 | Y22: 23843.073 | Z22: 25440.41 | AA22: 26751.302 | AB22: 29370.979 | AC22: 30590.229
A23: Total Current Liabilities | B23: 1721.755 | C23: 2051.73 | D23: 2362.366 | E23: 2428.617 | F23: 2986.93 | G23: 3772.539 | H23: 4636.067 | I23: 5077.603 | J23: 5883.597 | K23: 6420.986 | L23: 7176.436 | M23: 6854.085 | N23: 6739.794 | O23: 7051.355 | P23: 6935.692 | Q23: 6660.22 | R23: 6575.723 | S23: 7030.823 | T23: 8168.941 | U23: 8487.205 | V23: 8617.171 | W23: 9589.419 | X23: 11296.152 | Y23: 11801.267 | Z23: 12730.163 | AA23: 14691.059 | AB23: 14680.55 | AC23: 15169.013
A24: Long-term Debt | B24: 439.602 | C24: 446.569 | D24: 1356.69 | E24: 1374.835 | F24: 2109.176 | G24: 1920.942 | H24: 1840.406 | I24: 1757.583 | J24: 1282.496 | K24: 3503.456 | L24: 3475.708 | M24: 4175.377 | N24: 4177.291 | O24: 4148.004 | P24: 3338.75 | Q24: 3340.24 | R24: 3391.733 | S24: 3439.744 | T24: 3069.108 | U24: 2897.32 | V24: 2861.284 | W24: 2897.667 | X24: 1728.258 | Y24: 1659.794 | Z24: 1538.064 | AA24: 294.634 | AB24: 510.396 | AC24: 702.838
A25: Total Equity | B25: 1433.413 | C25: 1252.468 | D25: 1162.424 | E25: 920.601 | F25: 853.793 | G25: 741.235 | H25: 3382.912 | I25: 3403.703 | J25: 3560.167 | K25: 7787.257 | L25: 7398.697 | M25: 6261.22 | N25: 5373.224 | O25: 4897.211 | P25: 5715.705 | Q25: 6093.291 | R25: 6511.528 | S25: 6467.325 | T25: 6593.807 | U25: 6667.0754 | V25: 6867.266 | W25: 7916.407 | X25: 8372.335 | Y25: 8963.418 | Z25: 9676.846 | AA25: 10195.716 | AB25: 12526.503 | AC25: 12853.167
A26: CASH FLOW
A27: D&A | B27: -25.543 | C27: 107.907 | D27: 34.581 | E27: 38.249 | F27: 64.385 | G27: 192.774 | H27: 53.098 | I27: 56.909 | J27: 104.469 | K27: -119.067 | L27: 83.615921 | M27: 89.517979 | N27: 102.92629 | O27: 119.57994 | P27: 7.536 | Q27: 120.45622 | R27: 111.36892 | S27: 107.3344 | T27: 102.1911 | U27: 102.05148 | V27: 0 | W27: 0 | X27: 0 | Y27: 88.877 | Z27: 2.412 | AA27: -91.289 | AB27: 99.794
A28: Stock-based Compensation | B28: -16.199 | C28: 82.134 | D28: 34.935 | E28: 41.316 | F28: 75.87 | G28: 196.399 | H28: 93.847 | I28: 102.075 | J28: 112.485 | K28: 122.967 | L28: 470.324 | M28: 135.006 | N28: 184.108 | O28: 195.755 | P28: 705.896 | Q28: 198.881 | R28: 179.577 | S28: 174.904 | T28: 685.03 | U28: 181.081 | V28: 0 | W28: 0 | X28: 0 | Y28: 167.792 | Z28: 161.892 | AA28: 179.201 | AB28: 0
A29: Change in Working Capital | B29: 0 | C29: 30.287 | D29: 153.806 | E29: -11.755 | F29: 169.523 | G29: 71.328 | H29: 452.143 | I29: 0 | J29: 272.463 | K29: -272.463 | L29: 756.606 | M29: 0 | N29: 0 | O29: 0 | P29: -315.082 | Q29: 0 | R29: 0 | S29: 0 | T29: 255.29 | U29: 0 | V29: 0 | W29: 0 | X29: 699.051 | Y29: 0 | Z29: 0 | AA29: 0 | AB29: 0
A30: Operating Cash Flow | B30: 25.545 | C30: 89.933 | D30: -27.798 | E30: -223.679 | F30: 298.125 | G30: 295.978 | H30: 185.444 | I30: 318.279 | J30: 132.447 | K30: 62.747 | L30: -304.824 | M30: -723.651 | N30: -485.47 | O30: -166.262 | P30: 319.691 | Q30: 605.536 | R30: 595.48 | S30: 599.839 | T30: 281.11432 | U30: 467.47012 | V30: 616.434 | W30: 1170.076 | X30: 1020.982 | Y30: 756.931 | Z30: 1615.735 | AA30: 1175.447 | AB30: 1476.41
A31: Capex | B31: 0 | C31: -197.493 | D31: -43.848 | E31: -50.782 | F31: -53.872 | G31: -219.172 | H31: -126.701 | I31: 0 | J31: -242.866 | K31: 242.866 | L31: -772.177 | M31: 0 | N31: 0 | O31: 0 | P31: -924.178 | Q31: -101 | R31: -32 | S31: -44 | T31: -16.677758 | U31: -27 | V31: -64 | W31: 90.771 | X31: -317.924 | Y31: 0 | Z31: -216 | AA31: -135 | AB31: -1476.41
A32: Free Cash Flow | B32: 25.545 | C32: -107.56 | D32: -71.646 | E32: -274.461 | F32: 244.253 | G32: 76.806 | H32: 58.743 | I32: 318.279 | J32: -110.419 | K32: 305.613 | L32: -1077.001 | M32: -723.651 | N32: -485.47 | O32: -166.262 | P32: -604.487 | Q32: 504.536 | R32: 563.48 | S32: 555.839 | T32: 264.43656 | U32: 440.47012 | V32: 552.434 | W32: 1260.847 | X32: 703.058 | Y32: 756.931 | Z32: 1399.735 | AA32: 1040.447 | AB32: 0
A34: Blue = hardcoded actuals from FMP filings. Same-sheet ratios are formulas.

Sheet Consensus
A1: Full consensus check — model vs Street (FMP estimates, $M)
A2: Fiscal year | B2: 2026 | C2: 2027 | D2: 2028 | E2: 2029 | F2: 2030
A3: EVERY AVAILABLE FMP CONSENSUS FIELD (consensus / model / % diff)
A4: Revenue — consensus | B4: 30109.414 | C4: 36409.764 | D4: 41950.091 | E4: 46092.2 | F4: 51090.8
A5: model | B5: =Model!G6 | C5: =Model!H6 | D5: =Model!I6 | E5: =Model!J6 | F5: =Model!K6
A6: vs consensus | B6: =IFERROR(B5/B4-1,"") | C6: =IFERROR(C5/C4-1,"") | D6: =IFERROR(D5/D4-1,"") | E6: =IFERROR(E5/E4-1,"") | F6: =IFERROR(F5/F4-1,"")
A8: EBITDA* — consensus | B8: 97.64722 | C8: 118.07976 | D8: 136.04748 | E8: 149.48066 | F8: 165.69152
A9: model | B9: =Model!G19+Model!G24 | C9: =Model!H19+Model!H24 | D9: =Model!I19+Model!I24 | E9: =Model!J19+Model!J24 | F9: =Model!K19+Model!K24
A10: vs consensus | B10: =IFERROR(B9/B8-1,"") | C10: =IFERROR(C9/C8-1,"") | D10: =IFERROR(D9/D8-1,"") | E10: =IFERROR(E9/E8-1,"") | F10: =IFERROR(F9/F8-1,"")
A12: EBIT* — consensus | B12: -621.0545 | C12: -751.00923 | D12: -865.28727 | E12: -950.72485 | F12: -1053.8289
A13: model | B13: =Model!G19 | C13: =Model!H19 | D13: =Model!I19 | E13: =Model!J19 | F13: =Model!K19
A14: vs consensus | B14: =IFERROR(B13/B12-1,"") | C14: =IFERROR(C13/C12-1,"") | D14: =IFERROR(D13/D12-1,"") | E14: =IFERROR(E13/E12-1,"") | F14: =IFERROR(F13/F12-1,"")
A16: SG&A — consensus | B16: 10588.321 | C16: 12803.912 | D16: 14752.231 | E16: 16208.851 | F16: 17966.666
A17: model | B17: =Model!G14 | C17: =Model!H14 | D17: =Model!I14 | E17: =Model!J14 | F17: =Model!K14
A18: vs consensus | B18: =IFERROR(B17/B16-1,"") | C18: =IFERROR(C17/C16-1,"") | D18: =IFERROR(D17/D16-1,"") | E18: =IFERROR(E17/E16-1,"") | F18: =IFERROR(F17/F16-1,"")
A20: Net income (NOPAT) — consensus | B20: 2265.9234 | C20: 2752.405 | D20: 3501.0199 | E20: 2572.0554 | F20: 5916.3656
A21: model | B21: =Model!G23 | C21: =Model!H23 | D21: =Model!I23 | E21: =Model!J23 | F21: =Model!K23
A22: vs consensus | B22: =IFERROR(B21/B20-1,"") | C22: =IFERROR(C21/C20-1,"") | D22: =IFERROR(D21/D20-1,"") | E22: =IFERROR(E21/E20-1,"") | F22: =IFERROR(F21/F20-1,"")
A24: EPS — consensus | B24: 3.55034 | C24: 4.83319 | D24: 6.07231 | E24: 4.03 | F24: 9.27
A25: model | B25: =Model!G23/Financials!AC17 | C25: =Model!H23/Financials!AC17 | D25: =Model!I23/Financials!AC17 | E25: =Model!J23/Financials!AC17 | F25: =Model!K23/Financials!AC17
A26: vs consensus | B26: =IFERROR(B25/B24-1,"") | C26: =IFERROR(C25/C24-1,"") | D26: =IFERROR(D25/D24-1,"") | E26: =IFERROR(E25/E24-1,"") | F26: =IFERROR(F25/F24-1,"")
A28: Defaults anchored to consensus revenue + net income (≈0% diff). Other rows show where the model sits vs Street.
A29: *FMP's EBITDA/EBIT estimates look unreliable for AMZN (it reports NI > EBIT) — don't over-read those two.

Sheet Valuation
A1: Sea Limited — DCF Valuation
A2: Current price | B2: =Dashboard!$B$48
A3: WACC | B3: =WACC!B14
A4: Terminal growth (g) | B4: =Dashboard!$B$46
A5: Tax rate | B5: =Dashboard!$B$31
A6: Terminal method | B6: =Dashboard!$B$43
A7: Exit basis | B7: =Dashboard!$B$44
A8: Exit multiple | B8: =Dashboard!$B$45
A11: Forecast year | C11: 2026 | D11: 2027 | E11: 2028 | F11: 2029 | G11: 2030 | H11: 2031 | I11: 2032 | J11: 2033 | K11: 2034 | L11: 2035
A12: FCFF ($M) | C12: =Model!G31 | D12: =Model!H31 | E12: =Model!I31 | F12: =Model!J31 | G12: =Model!K31 | H12: =Model!L31 | I12: =Model!M31 | J12: =Model!N31 | ... L12: =Model!P31
A13: PV factor | C13: =1/(1+$B$3)^1 | D13: =1/(1+$B$3)^2 | E13: =1/(1+$B$3)^3 | F13: =1/(1+$B$3)^4 | G13: =1/(1+$B$3)^5 | H13: =1/(1+$B$3)^6 | I13: =1/(1+$B$3)^7 | J13: =1/(1+$B$3)^8 | K13: =1/(1+$B$3)^9 | L13: =1/(1+$B$3)^10
A14: PV of FCFF ($M) | C14: =C12*C13 | D14: =D12*D13 | E14: =E12*E13 | F14: =F12*F13 | G14: =G12*G13 | H14: =H12*H13 | I14: =I12*I13 | J14: =J12*J13 | ... L14: =L12*L13
A16: Sum PV of FCFF | B16: =SUM(C14:L14)
A18: TERMINAL VALUE (exit multiple = default; perpetuity = cross-check)
A19: Terminal-year FCFF | B19: =L12
A20: Terminal revenue | B20: =Model!P6
A21: Terminal EBIT | B21: =Model!P19
A22: Terminal EBITDA | B22: =Model!P19+Model!P24
A23: Terminal metric (per exit basis) | B23: =IF($B$7="EV/EBITDA",B22,IF($B$7="EV/Sales",B20,IF($B$7="EV/EBIT",B21,B19)))
A24: TV (exit) = metric x multiple | B24: =B23*$B$8
A25: PV of TV — exit multiple | B25: =B24/(1+$B$3)^10
A26: TV (perpetuity) = FCFF(1+g)/(WACC-g) | B26: =B19*(1+$B$4)/($B$3-$B$4)
A27: PV of TV — perpetuity | B27: =B26/(1+$B$3)^10
A28: PV of TV — SELECTED | B28: =IF($B$6="Perpetuity",B27,B25)
A30: EQUITY BRIDGE -> VALUE / SHARE
A31: Operating value (enterprise value) | B31: =B16+B28
A32: + Cash & ST investments | B32: =Financials!AC19
A33: - Long-term debt | B33: =-Financials!AC24
A34: Equity value | B34: =B31+B32+B33
A35: Diluted shares (M) | B35: =Financials!AC17
A36: VALUE / SHARE | B36: =B34/B35*1.0
A38: CROSS-CHECKS & RETURN
A39: Terminal weight (% of EV) | B39: =B28/B31
A40: Implied perpetuity g (from exit multiple) | B40: =(B24*$B$3-B19)/(B24+B19)
A41: Implied exit EV/EBITDA (from perpetuity) | B41: =B26/B22
A42: Upside / (downside) to fair value | B42: =B36/$B$2-1
A44: Owner cashflow / share | B44: =-$B$2 | C44: =C12/B35 | D44: =D12/B35 | E44: =E12/B35 | F44: =F12/B35 | G44: =G12/B35 | H44: =H12/B35 | I44: =I12/B35 | J44: =J12/B35 | K44: =K12/B35 | L44: =L12/B35+B36
A45: IRR (buy at price, hold 10y) | B45: =IRR(B44:L44)

Sheet Monte Carlo
A1: Monte Carlo simulation (live) | H1: SIMULATION ENGINE — leave as-is | K1: cagr | L1: term margin | M1: wacc | N1: exit | O1: value/share
A2: 1,000 trials, recomputed in-sheet on every edit. Edit the yellow driver distributions to re-roll. Engine grid is to the right (cols H+). | H2: R0 (base revenue) | I2: =Model!F6 | K2: =MAX(-0.05,NORMINV(RAND(),$C$6,$D$6)) | L2: =MAX(0.02,NORMINV(RAND(),$C$7,$D$7)) | M2: =MIN(0.16,MAX(0.05,NORMINV(RAND(),$C$8,$D$8))) | N2: =MIN(24,MAX(5,NORMINV(RAND(),$C$9,$D$9))) | O2: =$I$8*(SUMPRODUCT(($I$2*(1+K2)^{1;2;3;4;5;6;7;8;9;10})*(($I$3+(L2-$I$3)*{1;2;3;4;5;6;7;8;9;10}/10)*(1-$I$7)+$I$4-$I$4*($I$5+(1.05-$I$5)*{1;2;3;4;5;6;7;8;9;10}/10)-(K2/(1+K2))*$I$6)/(1+M2)^{1;2;3;4;5;6;7;8;9;10})+$I$2*(1+K2)^10*(L2+$I$4)*N2/(1+M2)^10+$I$9-$I$10)/$I$11
H3: m0 (base op margin) | I3: =Model!F20 | K3: =MAX(-0.05,NORMINV(RAND(),$C$6,$D$6)) | L3: =MAX(0.02,NORMINV(RAND(),$C$7,$D$7)) | M3: =MIN(0.16,MAX(0.05,NORMINV(RAND(),$C$8,$D$8))) | N3: =MIN(24,MAX(5,NORMINV(RAND(),$C$9,$D$9))) | O3: =$I$8*(SUMPRODUCT(($I$2*(1+K3)^{1;2;3;4;5;6;7;8;9;10})*(($I$3+(L3-$I$3)*{1;2;3;4;5;6;7;8;9;10}/10)*(1-$I$7)+$I$4-$I$4*($I$5+(1.05-$I$5)*{1;2;3;4;5;6;7;8;9;10}/10)-(K3/(1+K3))*$I$6)/(1+M3)^{1;2;3;4;5;6;7;8;9;10})+$I$2*(1+K3)^10*(L3+$I$4)*N3/(1+M3)^10+$I$9-$I$10)/$I$11
A4: DRIVER DISTRIBUTIONS (yellow = edit; Opus-set defaults) | H4: da (D&A / revenue) | I4: 0.0043505083 | K4: =MAX(-0.05,NORMINV(RAND(),$C$6,$D$6)) | L4: =MAX(0.02,NORMINV(RAND(),$C$7,$D$7)) | M4: =MIN(0.16,MAX(0.05,NORMINV(RAND(),$C$8,$D$8))) | N4: =MIN(24,MAX(5,NORMINV(RAND(),$C$9,$D$9))) | O4: =$I$8*(SUMPRODUCT(($I$2*(1+K4)^{1;2;3;4;5;6;7;8;9;10})*(($I$3+(L4-$I$3)*{1;2;3;4;5;6;7;8;9;10}/10)*(1-$I$7)+$I$4-$I$4*($I$5+(1.05-$I$5)*{1;2;3;4;5;6;7;8;9;10}/10)-(K4/(1+K4))*$I$6)/(1+M4)^{1;2;3;4;5;6;7;8;9;10})+$I$2*(1+K4)^10*(L4+$I$4)*N4/(1+M4)^10+$I$9-$I$10)/$I$11
A5: Driver | B5: Dist | C5: Mean | D5: Std dev | H5: cda0 (2026 capex/D&A) | I5: 15.345688 | K5: =MAX(-0.05,NORMINV(RAND(),$C$6,$D$6)) | L5: =MAX(0.02,NORMINV(RAND(),$C$7,$D$7)) | M5: =MIN(0.16,MAX(0.05,NORMINV(RAND(),$C$8,$D$8))) | N5: =MIN(24,MAX(5,NORMINV(RAND(),$C$9,$D$9))) | O5: =$I$8*(SUMPRODUCT(($I$2*(1+K5)^{1;2;3;4;5;6;7;8;9;10})*(($I$3+(L5-$I$3)*{1;2;3;4;5;6;7;8;9;10}/10)*(1-$I$7)+$I$4-$I$4*($I$5+(1.05-$I$5)*{1;2;3;4;5;6;7;8;9;10}/10)-(K5/(1+K5))*$I$6)/(1+M5)^{1;2;3;4;5;6;7;8;9;10})+$I$2*(1+K5)^10*(L5+$I$4)*N5/(1+M5)^10+$I$9-$I$10)/$I$11
A6: Revenue 10y CAGR | B6: Normal | C6: =(Model!P6/Model!F6)^(1/10)-1 | D6: 0.03 | H6: nwc (% incr revenue) | I6: 0.005 | K6: =MAX(-0.05,NORMINV(RAND(),$C$6,$D$6)) | L6: =MAX(0.02,NORMINV(RAND(),$C$7,$D$7)) | M6: =MIN(0.16,MAX(0.05,NORMINV(RAND(),$C$8,$D$8))) | N6: =MIN(24,MAX(5,NORMINV(RAND(),$C$9,$D$9))) | O6: =$I$8*(SUMPRODUCT(($I$2*(1+K6)^{1;2;3;4;5;6;7;8;9;10})*(($I$3+(L6-$I$3)*{1;2;3;4;5;6;7;8;9;10}/10)*(1-$I$7)+$I$4-$I$4*($I$5+(1.05-$I$5)*{1;2;3;4;5;6;7;8;9;10}/10)-(K6/(1+K6))*$I$6)/(1+M6)^{1;2;3;4;5;6;7;8;9;10})+$I$2*(1+K6)^10*(L6+$I$4)*N6/(1+M6)^10+$I$9-$I$10)/$I$11
A7: Terminal operating margin | B7: Normal | C7: =Dashboard!$B$30 | D7: 0.03 | H7: tax | I7: =Valuation!$B$5 | K7: =MAX(-0.05,NORMINV(RAND(),$C$6,$D$6)) | L7: =MAX(0.02,NORMINV(RAND(),$C$7,$D$7)) | M7: =MIN(0.16,MAX(0.05,NORMINV(RAND(),$C$8,$D$8))) | N7: =MIN(24,MAX(5,NORMINV(RAND(),$C$9,$D$9))) | O7: =$I$8*(SUMPRODUCT(($I$2*(1+K7)^{1;2;3;4;5;6;7;8;9;10})*(($I$3+(L7-$I$3)*{1;2;3;4;5;6;7;8;9;10}/10)*(1-$I$7)+$I$4-$I$4*($I$5+(1.05-$I$5)*{1;2;3;4;5;6;7;8;9;10}/10)-(K7/(1+K7))*$I$6)/(1+M7)^{1;2;3;4;5;6;7;8;9;10})+$I$2*(1+K7)^10*(L7+$I$4)*N7/(1+M7)^10+$I$9-$I$10)/$I$11
A8: WACC | B8: Normal | C8: =WACC!B14 | D8: 0.005 | H8: k (calibration) | I8: 1.0599687 | K8: =MAX(-0.05,NORMINV(RAND(),$C$6,$D$6)) | L8: =MAX(0.02,NORMINV(RAND(),$C$7,$D$7)) | M8: =MIN(0.16,MAX(0.05,NORMINV(RAND(),$C$8,$D$8))) | N8: =MIN(24,MAX(5,NORMINV(RAND(),$C$9,$D$9))) | O8: =$I$8*(SUMPRODUCT(($I$2*(1+K8)^{1;2;3;4;5;6;7;8;9;10})*(($I$3+(L8-$I$3)*{1;2;3;4;5;6;7;8;9;10}/10)*(1-$I$7)+$I$4-$I$4*($I$5+(1.05-$I$5)*{1;2;3;4;5;6;7;8;9;10}/10)-(K8/(1+K8))*$I$6)/(1+M8)^{1;2;3;4;5;6;7;8;9;10})+$I$2*(1+K8)^10*(L8+$I$4)*N8/(1+M8)^10+$I$9-$I$10)/$I$11
A9: Exit EV/EBITDA multiple | B9: Normal | C9: =Dashboard!$B$45 | D9: 1.5 | H9: cash | I9: =Financials!AC19 | K9: =MAX(-0.05,NORMINV(RAND(),$C$6,$D$6)) | L9: =MAX(0.02,NORMINV(RAND(),$C$7,$D$7)) | M9: =MIN(0.16,MAX(0.05,NORMINV(RAND(),$C$8,$D$8))) | N9: =MIN(24,MAX(5,NORMINV(RAND(),$C$9,$D$9))) | O9: =$I$8*(SUMPRODUCT(($I$2*(1+K9)^{1;2;3;4;5;6;7;8;9;10})*(($I$3+(L9-$I$3)*{1;2;3;4;5;6;7;8;9;10}/10)*(1-$I$7)+$I$4-$I$4*($I$5+(1.05-$I$5)*{1;2;3;4;5;6;7;8;9;10}/10)-(K9/(1+K9))*$I$6)/(1+M9)^{1;2;3;4;5;6;7;8;9;10})+$I$2*(1+K9)^10*(L9+$I$4)*N9/(1+M9)^10+$I$9-$I$10)/$I$11
H10: debt | I10: =Financials!AC24 | K10: =MAX(-0.05,NORMINV(RAND(),$C$6,$D$6)) | L10: =MAX(0.02,NORMINV(RAND(),$C$7,$D$7)) | M10: =MIN(0.16,MAX(0.05,NORMINV(RAND(),$C$8,$D$8))) | N10: =MIN(24,MAX(5,NORMINV(RAND(),$C$9,$D$9))) | O10: =$I$8*(SUMPRODUCT(($I$2*(1+K10)^{1;2;3;4;5;6;7;8;9;10})*(($I$3+(L10-$I$3)*{1;2;3;4;5;6;7;8;9;10}/10)*(1-$I$7)+$I$4-$I$4*($I$5+(1.05-$I$5)*{1;2;3;4;5;6;7;8;9;10}/10)-(K10/(1+K10))*$I$6)/(1+M10)^{1;2;3;4;5;6;7;8;9;10})+$I$2*(1+K10)^10*(L10+$I$4)*N10/(1+M10)^10+$I$9-$I$10)/$I$11
A11: SIMULATION OUTPUT — value / share (live) | H11: shares | I11: =Financials!AC17 | K11: =MAX(-0.05,NORMINV(RAND(),$C$6,$D$6)) | L11: =MAX(0.02,NORMINV(RAND(),$C$7,$D$7)) | M11: =MIN(0.16,MAX(0.05,NORMINV(RAND(),$C$8,$D$8))) | N11: =MIN(24,MAX(5,NORMINV(RAND(),$C$9,$D$9))) | O11: =$I$8*(SUMPRODUCT(($I$2*(1+K11)^{1;2;3;4;5;6;7;8;9;10})*(($I$3+(L11-$I$3)*{1;2;3;4;5;6;7;8;9;10}/10)*(1-$I$7)+$I$4-$I$4*($I$5+(1.05-$I$5)*{1;2;3;4;5;6;7;8;9;10}/10)-(K11/(1+K11))*$I$6)/(1+M11)^{1;2;3;4;5;6;7;8;9;10})+$I$2*(1+K11)^10*(L11+$I$4)*N11/(1+M11)^10+$I$9-$I$10)/$I$11
A12: Mean | B12: =AVERAGE($O$2:$O$1001) | K12: =MAX(-0.05,NORMINV(RAND(),$C$6,$D$6)) | L12: =MAX(0.02,NORMINV(RAND(),$C$7,$D$7)) | M12: =MIN(0.16,MAX(0.05,NORMINV(RAND(),$C$8,$D$8))) | N12: =MIN(24,MAX(5,NORMINV(RAND(),$C$9,$D$9))) | O12: =$I$8*(SUMPRODUCT(($I$2*(1+K12)^{1;2;3;4;5;6;7;8;9;10})*(($I$3+(L12-$I$3)*{1;2;3;4;5;6;7;8;9;10}/10)*(1-$I$7)+$I$4-$I$4*($I$5+(1.05-$I$5)*{1;2;3;4;5;6;7;8;9;10}/10)-(K12/(1+K12))*$I$6)/(1+M12)^{1;2;3;4;5;6;7;8;9;10})+$I$2*(1+K12)^10*(L12+$I$4)*N12/(1+M12)^10+$I$9-$I$10)/$I$11
A13: Median (P50) | B13: =MEDIAN($O$2:$O$1001) | K13: =MAX(-0.05,NORMINV(RAND(),$C$6,$D$6)) | L13: =MAX(0.02,NORMINV(RAND(),$C$7,$D$7)) | M13: =MIN(0.16,MAX(0.05,NORMINV(RAND(),$C$8,$D$8))) | N13: =MIN(24,MAX(5,NORMINV(RAND(),$C$9,$D$9))) | O13: =$I$8*(SUMPRODUCT(($I$2*(1+K13)^{1;2;3;4;5;6;7;8;9;10})*(($I$3+(L13-$I$3)*{1;2;3;4;5;6;7;8;9;10}/10)*(1-$I$7)+$I$4-$I$4*($I$5+(1.05-$I$5)*{1;2;3;4;5;6;7;8;9;10}/10)-(K13/(1+K13))*$I$6)/(1+M13)^{1;2;3;4;5;6;7;8;9;10})+$I$2*(1+K13)^10*(L13+$I$4)*N13/(1+M13)^10+$I$9-$I$10)/$I$11
A14: Std dev | B14: =STDEV($O$2:$O$1001) | K14: =MAX(-0.05,NORMINV(RAND(),$C$6,$D$6)) | L14: =MAX(0.02,NORMINV(RAND(),$C$7,$D$7)) | M14: =MIN(0.16,MAX(0.05,NORMINV(RAND(),$C$8,$D$8))) | N14: =MIN(24,MAX(5,NORMINV(RAND(),$C$9,$D$9))) | O14: =$I$8*(SUMPRODUCT(($I$2*(1+K14)^{1;2;3;4;5;6;7;8;9;10})*(($I$3+(L14-$I$3)*{1;2;3;4;5;6;7;8;9;10}/10)*(1-$I$7)+$I$4-$I$4*($I$5+(1.05-$I$5)*{1;2;3;4;5;6;7;8;9;10}/10)-(K14/(1+K14))*$I$6)/(1+M14)^{1;2;3;4;5;6;7;8;9;10})+$I$2*(1+K14)^10*(L14+$I$4)*N14/(1+M14)^10+$I$9-$I$10)/$I$11
A15: Min | B15: =MIN($O$2:$O$1001) | K15: =MAX(-0.05,NORMINV(RAND(),$C$6,$D$6)) | L15: =MAX(0.02,NORMINV(RAND(),$C$7,$D$7)) | M15: =MIN(0.16,MAX(0.05,NORMINV(RAND(),$C$8,$D$8))) | N15: =MIN(24,MAX(5,NORMINV(RAND(),$C$9,$D$9))) | O15: =$I$8*(SUMPRODUCT(($I$2*(1+K15)^{1;2;3;4;5;6;7;8;9;10})*(($I$3+(L15-$I$3)*{1;2;3;4;5;6;7;8;9;10}/10)*(1-$I$7)+$I$4-$I$4*($I$5+(1.05-$I$5)*{1;2;3;4;5;6;7;8;9;10}/10)-(K15/(1+K15))*$I$6)/(1+M15)^{1;2;3;4;5;6;7;8;9;10})+$I$2*(1+K15)^10*(L15+$I$4)*N15/(1+M15)^10+$I$9-$I$10)/$I$11
A16: Max | B16: =MAX($O$2:$O$1001) | K16: =MAX(-0.05,NORMINV(RAND(),$C$6,$D$6)) | L16: =MAX(0.02,NORMINV(RAND(),$C$7,$D$7)) | M16: =MIN(0.16,MAX(0.05,NORMINV(RAND(),$C$8,$D$8))) | N16: =MIN(24,MAX(5,NORMINV(RAND(),$C$9,$D$9))) | O16: =$I$8*(SUMPRODUCT(($I$2*(1+K16)^{1;2;3;4;5;6;7;8;9;10})*(($I$3+(L16-$I$3)*{1;2;3;4;5;6;7;8;9;10}/10)*(1-$I$7)+$I$4-$I$4*($I$5+(1.05-$I$5)*{1;2;3;4;5;6;7;8;9;10}/10)-(K16/(1+K16))*$I$6)/(1+M16)^{1;2;3;4;5;6;7;8;9;10})+$I$2*(1+K16)^10*(L16+$I$4)*N16/(1+M16)^10+$I$9-$I$10)/$I$11
A17: Current price | B17: =Valuation!$B$2 | K17: =MAX(-0.05,NORMINV(RAND(),$C$6,$D$6)) | L17: =MAX(0.02,NORMINV(RAND(),$C$7,$D$7)) | M17: =MIN(0.16,MAX(0.05,NORMINV(RAND(),$C$8,$D$8))) | N17: =MIN(24,MAX(5,NORMINV(RAND(),$C$9,$D$9))) | O17: =$I$8*(SUMPRODUCT(($I$2*(1+K17)^{1;2;3;4;5;6;7;8;9;10})*(($I$3+(L17-$I$3)*{1;2;3;4;5;6;7;8;9;10}/10)*(1-$I$7)+$I$4-$I$4*($I$5+(1.05-$I$5)*{1;2;3;4;5;6;7;8;9;10}/10)-(K17/(1+K17))*$I$6)/(1+M17)^{1;2;3;4;5;6;7;8;9;10})+$I$2*(1+K17)^10*(L17+$I$4)*N17/(1+M17)^10+$I$9-$I$10)/$I$11
A18: Base case (full model) | B18: =Valuation!B36 | K18: =MAX(-0.05,NORMINV(RAND(),$C$6,$D$6)) | L18: =MAX(0.02,NORMINV(RAND(),$C$7,$D$7)) | M18: =MIN(0.16,MAX(0.05,NORMINV(RAND(),$C$8,$D$8))) | N18: =MIN(24,MAX(5,NORMINV(RAND(),$C$9,$D$9))) | O18: =$I$8*(SUMPRODUCT(($I$2*(1+K18)^{1;2;3;4;5;6;7;8;9;10})*(($I$3+(L18-$I$3)*{1;2;3;4;5;6;7;8;9;10}/10)*(1-$I$7)+$I$4-$I$4*($I$5+(1.05-$I$5)*{1;2;3;4;5;6;7;8;9;10}/10)-(K18/(1+K18))*$I$6)/(1+M18)^{1;2;3;4;5;6;7;8;9;10})+$I$2*(1+K18)^10*(L18+$I$4)*N18/(1+M18)^10+$I$9-$I$10)/$I$11
K19: =MAX(-0.05,NORMINV(RAND(),$C$6,$D$6)) | L19: =MAX(0.02,NORMINV(RAND(),$C$7,$D$7)) | M19: =MIN(0.16,MAX(0.05,NORMINV(RAND(),$C$8,$D$8))) | N19: =MIN(24,MAX(5,NORMINV(RAND(),$C$9,$D$9))) | O19: =$I$8*(SUMPRODUCT(($I$2*(1+K19)^{1;2;3;4;5;6;7;8;9;10})*(($I$3+(L19-$I$3)*{1;2;3;4;5;6;7;8;9;10}/10)*(1-$I$7)+$I$4-$I$4*($I$5+(1.05-$I$5)*{1;2;3;4;5;6;7;8;9;10}/10)-(K19/(1+K19))*$I$6)/(1+M19)^{1;2;3;4;5;6;7;8;9;10})+$I$2*(1+K19)^10*(L19+$I$4)*N19/(1+M19)^10+$I$9-$I$10)/$I$11
A20: P(undervalued at current price) | B20: =COUNTIF($O$2:$O$1001,">"&Valuation!$B$2)/1000 | K20: =MAX(-0.05,NORMINV(RAND(),$C$6,$D$6)) | L20: =MAX(0.02,NORMINV(RAND(),$C$7,$D$7)) | M20: =MIN(0.16,MAX(0.05,NORMINV(RAND(),$C$8,$D$8))) | N20: =MIN(24,MAX(5,NORMINV(RAND(),$C$9,$D$9))) | O20: =$I$8*(SUMPRODUCT(($I$2*(1+K20)^{1;2;3;4;5;6;7;8;9;10})*(($I$3+(L20-$I$3)*{1;2;3;4;5;6;7;8;9;10}/10)*(1-$I$7)+$I$4-$I$4*($I$5+(1.05-$I$5)*{1;2;3;4;5;6;7;8;9;10}/10)-(K20/(1+K20))*$I$6)/(1+M20)^{1;2;3;4;5;6;7;8;9;10})+$I$2*(1+K20)^10*(L20+$I$4)*N20/(1+M20)^10+$I$9-$I$10)/$I$11
A21: P(>20% upside) | B21: =COUNTIF($O$2:$O$1001,">"&Valuation!$B$2*1.2)/1000 | K21: =MAX(-0.05,NORMINV(RAND(),$C$6,$D$6)) | L21: =MAX(0.02,NORMINV(RAND(),$C$7,$D$7)) | M21: =MIN(0.16,MAX(0.05,NORMINV(RAND(),$C$8,$D$8))) | N21: =MIN(24,MAX(5,NORMINV(RAND(),$C$9,$D$9))) | O21: =$I$8*(SUMPRODUCT(($I$2*(1+K21)^{1;2;3;4;5;6;7;8;9;10})*(($I$3+(L21-$I$3)*{1;2;3;4;5;6;7;8;9;10}/10)*(1-$I$7)+$I$4-$I$4*($I$5+(1.05-$I$5)*{1;2;3;4;5;6;7;8;9;10}/10)-(K21/(1+K21))*$I$6)/(1+M21)^{1;2;3;4;5;6;7;8;9;10})+$I$2*(1+K21)^10*(L21+$I$4)*N21/(1+M21)^10+$I$9-$I$10)/$I$11
K22: =MAX(-0.05,NORMINV(RAND(),$C$6,$D$6)) | L22: =MAX(0.02,NORMINV(RAND(),$C$7,$D$7)) | M22: =MIN(0.16,MAX(0.05,NORMINV(RAND(),$C$8,$D$8))) | N22: =MIN(24,MAX(5,NORMINV(RAND(),$C$9,$D$9))) | O22: =$I$8*(SUMPRODUCT(($I$2*(1+K22)^{1;2;3;4;5;6;7;8;9;10})*(($I$3+(L22-$I$3)*{1;2;3;4;5;6;7;8;9;10}/10)*(1-$I$7)+$I$4-$I$4*($I$5+(1.05-$I$5)*{1;2;3;4;5;6;7;8;9;10}/10)-(K22/(1+K22))*$I$6)/(1+M22)^{1;2;3;4;5;6;7;8;9;10})+$I$2*(1+K22)^10*(L22+$I$4)*N22/(1+M22)^10+$I$9-$I$10)/$I$11
A23: PERCENTILES (live) | K23: =MAX(-0.05,NORMINV(RAND(),$C$6,$D$6)) | L23: =MAX(0.02,NORMINV(RAND(),$C$7,$D$7)) | M23: =MIN(0.16,MAX(0.05,NORMINV(RAND(),$C$8,$D$8))) | N23: =MIN(24,MAX(5,NORMINV(RAND(),$C$9,$D$9))) | O23: =$I$8*(SUMPRODUCT(($I$2*(1+K23)^{1;2;3;4;5;6;7;8;9;10})*(($I$3+(L23-$I$3)*{1;2;3;4;5;6;7;8;9;10}/10)*(1-$I$7)+$I$4-$I$4*($I$5+(1.05-$I$5)*{1;2;3;4;5;6;7;8;9;10}/10)-(K23/(1+K23))*$I$6)/(1+M23)^{1;2;3;4;5;6;7;8;9;10})+$I$2*(1+K23)^10*(L23+$I$4)*N23/(1+M23)^10+$I$9-$I$10)/$I$11
A24: P5 | B24: =PERCENTILE($O$2:$O$1001,0.05) | K24: =MAX(-0.05,NORMINV(RAND(),$C$6,$D$6)) | L24: =MAX(0.02,NORMINV(RAND(),$C$7,$D$7)) | M24: =MIN(0.16,MAX(0.05,NORMINV(RAND(),$C$8,$D$8))) | N24: =MIN(24,MAX(5,NORMINV(RAND(),$C$9,$D$9))) | O24: =$I$8*(SUMPRODUCT(($I$2*(1+K24)^{1;2;3;4;5;6;7;8;9;10})*(($I$3+(L24-$I$3)*{1;2;3;4;5;6;7;8;9;10}/10)*(1-$I$7)+$I$4-$I$4*($I$5+(1.05-$I$5)*{1;2;3;4;5;6;7;8;9;10}/10)-(K24/(1+K24))*$I$6)/(1+M24)^{1;2;3;4;5;6;7;8;9;10})+$I$2*(1+K24)^10*(L24+$I$4)*N24/(1+M24)^10+$I$9-$I$10)/$I$11
A25: P10 | B25: =PERCENTILE($O$2:$O$1001,0.1) | K25: =MAX(-0.05,NORMINV(RAND(),$C$6,$D$6)) | L25: =MAX(0.02,NORMINV(RAND(),$C$7,$D$7)) | M25: =MIN(0.16,MAX(0.05,NORMINV(RAND(),$C$8,$D$8))) | N25: =MIN(24,MAX(5,NORMINV(RAND(),$C$9,$D$9))) | O25: =$I$8*(SUMPRODUCT(($I$2*(1+K25)^{1;2;3;4;5;6;7;8;9;10})*(($I$3+(L25-$I$3)*{1;2;3;4;5;6;7;8;9;10}/10)*(1-$I$7)+$I$4-$I$4*($I$5+(1.05-$I$5)*{1;2;3;4;5;6;7;8;9;10}/10)-(K25/(1+K25))*$I$6)/(1+M25)^{1;2;3;4;5;6;7;8;9;10})+$I$2*(1+K25)^10*(L25+$I$4)*N25/(1+M25)^10+$I$9-$I$10)/$I$11
A26: P25 | B26: =PERCENTILE($O$2:$O$1001,0.25) | K26: =MAX(-0.05,NORMINV(RAND(),$C$6,$D$6)) | L26: =MAX(0.02,NORMINV(RAND(),$C$7,$D$7)) | M26: =MIN(0.16,MAX(0.05,NORMINV(RAND(),$C$8,$D$8))) | N26: =MIN(24,MAX(5,NORMINV(RAND(),$C$9,$D$9))) | O26: =$I$8*(SUMPRODUCT(($I$2*(1+K26)^{1;2;3;4;5;6;7;8;9;10})*(($I$3+(L26-$I$3)*{1;2;3;4;5;6;7;8;9;10}/10)*(1-$I$7)+$I$4-$I$4*($I$5+(1.05-$I$5)*{1;2;3;4;5;6;7;8;9;10}/10)-(K26/(1+K26))*$I$6)/(1+M26)^{1;2;3;4;5;6;7;8;9;10})+$I$2*(1+K26)^10*(L26+$I$4)*N26/(1+M26)^10+$I$9-$I$10)/$I$11
A27: P50 | B27: =PERCENTILE($O$2:$O$1001,0.5) | K27: =MAX(-0.05,NORMINV(RAND(),$C$6,$D$6)) | L27: =MAX(0.02,NORMINV(RAND(),$C$7,$D$7)) | M27: =MIN(0.16,MAX(0.05,NORMINV(RAND(),$C$8,$D$8))) | N27: =MIN(24,MAX(5,NORMINV(RAND(),$C$9,$D$9))) | O27: =$I$8*(SUMPRODUCT(($I$2*(1+K27)^{1;2;3;4;5;6;7;8;9;10})*(($I$3+(L27-$I$3)*{1;2;3;4;5;6;7;8;9;10}/10)*(1-$I$7)+$I$4-$I$4*($I$5+(1.05-$I$5)*{1;2;3;4;5;6;7;8;9;10}/10)-(K27/(1+K27))*$I$6)/(1+M27)^{1;2;3;4;5;6;7;8;9;10})+$I$2*(1+K27)^10*(L27+$I$4)*N27/(1+M27)^10+$I$9-$I$10)/$I$11
A28: P75 | B28: =PERCENTILE($O$2:$O$1001,0.75) | K28: =MAX(-0.05,NORMINV(RAND(),$C$6,$D$6)) | L28: =MAX(0.02,NORMINV(RAND(),$C$7,$D$7)) | M28: =MIN(0.16,MAX(0.05,NORMINV(RAND(),$C$8,$D$8))) | N28: =MIN(24,MAX(5,NORMINV(RAND(),$C$9,$D$9))) | O28: =$I$8*(SUMPRODUCT(($I$2*(1+K28)^{1;2;3;4;5;6;7;8;9;10})*(($I$3+(L28-$I$3)*{1;2;3;4;5;6;7;8;9;10}/10)*(1-$I$7)+$I$4-$I$4*($I$5+(1.05-$I$5)*{1;2;3;4;5;6;7;8;9;10}/10)-(K28/(1+K28))*$I$6)/(1+M28)^{1;2;3;4;5;6;7;8;9;10})+$I$2*(1+K28)^10*(L28+$I$4)*N28/(1+M28)^10+$I$9-$I$10)/$I$11
A29: P90 | B29: =PERCENTILE($O$2:$O$1001,0.9) | K29: =MAX(-0.05,NORMINV(RAND(),$C$6,$D$6)) | L29: =MAX(0.02,NORMINV(RAND(),$C$7,$D$7)) | M29: =MIN(0.16,MAX(0.05,NORMINV(RAND(),$C$8,$D$8))) | N29: =MIN(24,MAX(5,NORMINV(RAND(),$C$9,$D$9))) | O29: =$I$8*(SUMPRODUCT(($I$2*(1+K29)^{1;2;3;4;5;6;7;8;9;10})*(($I$3+(L29-$I$3)*{1;2;3;4;5;6;7;8;9;10}/10)*(1-$I$7)+$I$4-$I$4*($I$5+(1.05-$I$5)*{1;2;3;4;5;6;7;8;9;10}/10)-(K29/(1+K29))*$I$6)/(1+M29)^{1;2;3;4;5;6;7;8;9;10})+$I$2*(1+K29)^10*(L29+$I$4)*N29/(1+M29)^10+$I$9-$I$10)/$I$11
A30: P95 | B30: =PERCENTILE($O$2:$O$1001,0.95) | K30: =MAX(-0.05,NORMINV(RAND(),$C$6,$D$6)) | L30: =MAX(0.02,NORMINV(RAND(),$C$7,$D$7)) | M30: =MIN(0.16,MAX(0.05,NORMINV(RAND(),$C$8,$D$8))) | N30: =MIN(24,MAX(5,NORMINV(RAND(),$C$9,$D$9))) | O30: =$I$8*(SUMPRODUCT(($I$2*(1+K30)^{1;2;3;4;5;6;7;8;9;10})*(($I$3+(L30-$I$3)*{1;2;3;4;5;6;7;8;9;10}/10)*(1-$I$7)+$I$4-$I$4*($I$5+(1.05-$I$5)*{1;2;3;4;5;6;7;8;9;10}/10)-(K30/(1+K30))*$I$6)/(1+M30)^{1;2;3;4;5;6;7;8;9;10})+$I$2*(1+K30)^10*(L30+$I$4)*N30/(1+M30)^10+$I$9-$I$10)/$I$11
K31: =MAX(-0.05,NORMINV(RAND(),$C$6,$D$6)) | L31: =MAX(0.02,NORMINV(RAND(),$C$7,$D$7)) | M31: =MIN(0.16,MAX(0.05,NORMINV(RAND(),$C$8,$D$8))) | N31: =MIN(24,MAX(5,NORMINV(RAND(),$C$9,$D$9))) | O31: =$I$8*(SUMPRODUCT(($I$2*(1+K31)^{1;2;3;4;5;6;7;8;9;10})*(($I$3+(L31-$I$3)*{1;2;3;4;5;6;7;8;9;10}/10)*(1-$I$7)+$I$4-$I$4*($I$5+(1.05-$I$5)*{1;2;3;4;5;6;7;8;9;10}/10)-(K31/(1+K31))*$I$6)/(1+M31)^{1;2;3;4;5;6;7;8;9;10})+$I$2*(1+K31)^10*(L31+$I$4)*N31/(1+M31)^10+$I$9-$I$10)/$I$11
A32: VALUE DISTRIBUTION (live histogram) | K32: =MAX(-0.05,NORMINV(RAND(),$C$6,$D$6)) | L32: =MAX(0.02,NORMINV(RAND(),$C$7,$D$7)) | M32: =MIN(0.16,MAX(0.05,NORMINV(RAND(),$C$8,$D$8))) | N32: =MIN(24,MAX(5,NORMINV(RAND(),$C$9,$D$9))) | O32: =$I$8*(SUMPRODUCT(($I$2*(1+K32)^{1;2;3;4;5;6;7;8;9;10})*(($I$3+(L32-$I$3)*{1;2;3;4;5;6;7;8;9;10}/10)*(1-$I$7)+$I$4-$I$4*($I$5+(1.05-$I$5)*{1;2;3;4;5;6;7;8;9;10}/10)-(K32/(1+K32))*$I$6)/(1+M32)^{1;2;3;4;5;6;7;8;9;10})+$I$2*(1+K32)^10*(L32+$I$4)*N32/(1+M32)^10+$I$9-$I$10)/$I$11
A33: Bin midpoint ($/sh) | B33: Count | K33: =MAX(-0.05,NORMINV(RAND(),$C$6,$D$6)) | L33: =MAX(0.02,NORMINV(RAND(),$C$7,$D$7)) | M33: =MIN(0.16,MAX(0.05,NORMINV(RAND(),$C$8,$D$8))) | N33: =MIN(24,MAX(5,NORMINV(RAND(),$C$9,$D$9))) | O33: =$I$8*(SUMPRODUCT(($I$2*(1+K33)^{1;2;3;4;5;6;7;8;9;10})*(($I$3+(L33-$I$3)*{1;2;3;4;5;6;7;8;9;10}/10)*(1-$I$7)+$I$4-$I$4*($I$5+(1.05-$I$5)*{1;2;3;4;5;6;7;8;9;10}/10)-(K33/(1+K33))*$I$6)/(1+M33)^{1;2;3;4;5;6;7;8;9;10})+$I$2*(1+K33)^10*(L33+$I$4)*N33/(1+M33)^10+$I$9-$I$10)/$I$11
A34: =$B$15+0.5*($B$16-$B$15)/15 | B34: =COUNTIFS($O$2:$O$1001,">="&($B$15+0*($B$16-$B$15)/15),$O$2:$O$1001,"<"&($B$15+1*($B$16-$B$15)/15)) | K34: =MAX(-0.05,NORMINV(RAND(),$C$6,$D$6)) | L34: =MAX(0.02,NORMINV(RAND(),$C$7,$D$7)) | M34: =MIN(0.16,MAX(0.05,NORMINV(RAND(),$C$8,$D$8))) | N34: =MIN(24,MAX(5,NORMINV(RAND(),$C$9,$D$9))) | O34: =$I$8*(SUMPRODUCT(($I$2*(1+K34)^{1;2;3;4;5;6;7;8;9;10})*(($I$3+(L34-$I$3)*{1;2;3;4;5;6;7;8;9;10}/10)*(1-$I$7)+$I$4-$I$4*($I$5+(1.05-$I$5)*{1;2;3;4;5;6;7;8;9;10}/10)-(K34/(1+K34))*$I$6)/(1+M34)^{1;2;3;4;5;6;7;8;9;10})+$I$2*(1+K34)^10*(L34+$I$4)*N34/(1+M34)^10+$I$9-$I$10)/$I$11
A35: =$B$15+1.5*($B$16-$B$15)/15 | B35: =COUNTIFS($O$2:$O$1001,">="&($B$15+1*($B$16-$B$15)/15),$O$2:$O$1001,"<"&($B$15+2*($B$16-$B$15)/15)) | K35: =MAX(-0.05,NORMINV(RAND(),$C$6,$D$6)) | L35: =MAX(0.02,NORMINV(RAND(),$C$7,$D$7)) | M35: =MIN(0.16,MAX(0.05,NORMINV(RAND(),$C$8,$D$8))) | N35: =MIN(24,MAX(5,NORMINV(RAND(),$C$9,$D$9))) | O35: =$I$8*(SUMPRODUCT(($I$2*(1+K35)^{1;2;3;4;5;6;7;8;9;10})*(($I$3+(L35-$I$3)*{1;2;3;4;5;6;7;8;9;10}/10)*(1-$I$7)+$I$4-$I$4*($I$5+(1.05-$I$5)*{1;2;3;4;5;6;7;8;9;10}/10)-(K35/(1+K35))*$I$6)/(1+M35)^{1;2;3;4;5;6;7;8;9;10})+$I$2*(1+K35)^10*(L35+$I$4)*N35/(1+M35)^10+$I$9-$I$10)/$I$11
A36: =$B$15+2.5*($B$16-$B$15)/15 | B36: =COUNTIFS($O$2:$O$1001,">="&($B$15+2*($B$16-$B$15)/15),$O$2:$O$1001,"<"&($B$15+3*($B$16-$B$15)/15)) | K36: =MAX(-0.05,NORMINV(RAND(),$C$6,$D$6)) | L36: =MAX(0.02,NORMINV(RAND(),$C$7,$D$7)) | M36: =MIN(0.16,MAX(0.05,NORMINV(RAND(),$C$8,$D$8))) | N36: =MIN(24,MAX(5,NORMINV(RAND(),$C$9,$D$9))) | O36: =$I$8*(SUMPRODUCT(($I$2*(1+K36)^{1;2;3;4;5;6;7;8;9;10})*(($I$3+(L36-$I$3)*{1;2;3;4;5;6;7;8;9;10}/10)*(1-$I$7)+$I$4-$I$4*($I$5+(1.05-$I$5)*{1;2;3;4;5;6;7;8;9;10}/10)-(K36/(1+K36))*$I$6)/(1+M36)^{1;2;3;4;5;6;7;8;9;10})+$I$2*(1+K36)^10*(L36+$I$4)*N36/(1+M36)^10+$I$9-$I$10)/$I$11
A37: =$B$15+3.5*($B$16-$B$15)/15 | B37: =COUNTIFS($O$2:$O$1001,">="&($B$15+3*($B$16-$B$15)/15),$O$2:$O$1001,"<"&($B$15+4*($B$16-$B$15)/15)) | K37: =MAX(-0.05,NORMINV(RAND(),$C$6,$D$6)) | L37: =MAX(0.02,NORMINV(RAND(),$C$7,$D$7)) | M37: =MIN(0.16,MAX(0.05,NORMINV(RAND(),$C$8,$D$8))) | N37: =MIN(24,MAX(5,NORMINV(RAND(),$C$9,$D$9))) | O37: =$I$8*(SUMPRODUCT(($I$2*(1+K37)^{1;2;3;4;5;6;7;8;9;10})*(($I$3+(L37-$I$3)*{1;2;3;4;5;6;7;8;9;10}/10)*(1-$I$7)+$I$4-$I$4*($I$5+(1.05-$I$5)*{1;2;3;4;5;6;7;8;9;10}/10)-(K37/(1+K37))*$I$6)/(1+M37)^{1;2;3;4;5;6;7;8;9;10})+$I$2*(1+K37)^10*(L37+$I$4)*N37/(1+M37)^10+$I$9-$I$10)/$I$11
A38: =$B$15+4.5*($B$16-$B$15)/15 | B38: =COUNTIFS($O$2:$O$1001,">="&($B$15+4*($B$16-$B$15)/15),$O$2:$O$1001,"<"&($B$15+5*($B$16-$B$15)/15)) | K38: =MAX(-0.05,NORMINV(RAND(),$C$6,$D$6)) | L38: =MAX(0.02,NORMINV(RAND(),$C$7,$D$7)) | M38: =MIN(0.16,MAX(0.05,NORMINV(RAND(),$C$8,$D$8))) | N38: =MIN(24,MAX(5,NORMINV(RAND(),$C$9,$D$9))) | O38: =$I$8*(SUMPRODUCT(($I$2*(1+K38)^{1;2;3;4;5;6;7;8;9;10})*(($I$3+(L38-$I$3)*{1;2;3;4;5;6;7;8;9;10}/10)*(1-$I$7)+$I$4-$I$4*($I$5+(1.05-$I$5)*{1;2;3;4;5;6;7;8;9;10}/10)-(K38/(1+K38))*$I$6)/(1+M38)^{1;2;3;4;5;6;7;8;9;10})+$I$2*(1+K38)^10*(L38+$I$4)*N38/(1+M38)^10+$I$9-$I$10)/$I$11
A39: =$B$15+5.5*($B$16-$B$15)/15 | B39: =COUNTIFS($O$2:$O$1001,">="&($B$15+5*($B$16-$B$15)/15),$O$2:$O$1001,"<"&($B$15+6*($B$16-$B$15)/15)) | K39: =MAX(-0.05,NORMINV(RAND(),$C$6,$D$6)) | L39: =MAX(0.02,NORMINV(RAND(),$C$7,$D$7)) | M39: =MIN(0.16,MAX(0.05,NORMINV(RAND(),$C$8,$D$8))) | N39: =MIN(24,MAX(5,NORMINV(RAND(),$C$9,$D$9))) | O39: =$I$8*(SUMPRODUCT(($I$2*(1+K39)^{1;2;3;4;5;6;7;8;9;10})*(($I$3+(L39-$I$3)*{1;2;3;4;5;6;7;8;9;10}/10)*(1-$I$7)+$I$4-$I$4*($I$5+(1.05-$I$5)*{1;2;3;4;5;6;7;8;9;10}/10)-(K39/(1+K39))*$I$6)/(1+M39)^{1;2;3;4;5;6;7;8;9;10})+$I$2*(1+K39)^10*(L39+$I$4)*N39/(1+M39)^10+$I$9-$I$10)/$I$11
A40: =$B$15+6.5*($B$16-$B$15)/15 | B40: =COUNTIFS($O$2:$O$1001,">="&($B$15+6*($B$16-$B$15)/15),$O$2:$O$1001,"<"&($B$15+7*($B$16-$B$15)/15)) | K40: =MAX(-0.05,NORMINV(RAND(),$C$6,$D$6)) | L40: =MAX(0.02,NORMINV(RAND(),$C$7,$D$7)) | M40: =MIN(0.16,MAX(0.05,NORMINV(RAND(),$C$8,$D$8))) | N40: =MIN(24,MAX(5,NORMINV(RAND(),$C$9,$D$9))) | O40: =$I$8*(SUMPRODUCT(($I$2*(1+K40)^{1;2;3;4;5;6;7;8;9;10})*(($I$3+(L40-$I$3)*{1;2;3;4;5;6;7;8;9;10}/10)*(1-$I$7)+$I$4-$I$4*($I$5+(1.05-$I$5)*{1;2;3;4;5;6;7;8;9;10}/10)-(K40/(1+K40))*$I$6)/(1+M40)^{1;2;3;4;5;6;7;8;9;10})+$I$2*(1+K40)^10*(L40+$I$4)*N40/(1+M40)^10+$I$9-$I$10)/$I$11
...
