Workbook

Sheet Cover
A1: TC Energy Corporation (TRP)
A2: DCF valuation — exit-multiple terminal · defaults anchored to consensus
A4: Last updated | B4: 2026-07-08
A5: Data pulled (FMP) | B5: Q1 2026
A6: Assumptions by | B6: builder defaults (consensus-anchored; no Opus pass)
A8: VALUATION SUMMARY
A10: Fair value / share | B10: =Valuation!B36
A11: Current price | B11: =Valuation!$B$2
A12: Upside / (downside) | B12: =Valuation!B42
A13: Verdict | B13: =IF(Valuation!B36>Valuation!$B$2,"Undervalued","Overvalued")
A14: Monte Carlo P(undervalued) | B14: ='Monte Carlo'!B20
A15: KEY ASSUMPTIONS
A17: WACC (from WACC tab) | B17: =WACC!B15
A18: Terminal method | B18: =Valuation!$B$6
A19: Exit basis / multiple | B19: =Valuation!$B$7
A20: Exit multiple | B20: =Valuation!$B$8
A21: Terminal growth (g) | B21: =Valuation!$B$4
A22: Terminal weight | B22: =Valuation!B39
A23: Forecast horizon | B23: 10 years
A25: THE STORY (Opus)
A27: (Opus narrative)

Sheet Dashboard
A1: TC Energy Corporation (TRP) — Control Dashboard
A2: Edit the yellow cells; everything recomputes. Orange = a driver you've moved off consensus.
A4: VERDICT
A5: Fair value / share | B5: =Valuation!B36
A6: Current price | B6: =Dashboard!$B$48
A7: Upside / (downside) | B7: =Valuation!B42
A8: Verdict | B8: =IF(Valuation!B36>Dashboard!$B$48,"Undervalued","Overvalued")
A9: Monte Carlo P(undervalued) | B9: ='Monte Carlo'!B20
A11: GUARDRAIL SIGNALS (are my assumptions sane?)
A12: Signal | B12: Value | C12: Flag | D12: Healthy
A13: Terminal weight (% of EV) | B13: =Valuation!B39 | C13: =IF(Valuation!B39>0.9,"! high","ok") | D13: < 90%
A14: Implied g vs exit multiple | B14: =Valuation!B40 | C14: =IF(Valuation!B40>Dashboard!$B$46+0.02,"! rich","ok") | D14: near term g
A15: ROIC - WACC (2026) | B15: =IF(Model!F34<=0,"n/a (neg. capital)",Model!G36-WACC!B15) | C15: =IF(Model!F34<=0,"n/a",IF(Model!G36-WACC!B15<0,"! destroys","creates")) | D15: > 0
A16: Revenue vs consensus (2026) | B16: =Consensus!B6 | C16: =IF(ABS(Consensus!B6)>0.05,"! off-Street","on") | D16: +/- 5%
A17: MC P(undervalued) | B17: ='Monte Carlo'!B20 | C17: =IF('Monte Carlo'!B20<0.5,"! coin-flip","ok") | D17: context
A18: REVENUE DRIVERS — near-term & terminal growth per segment
A19: Segment | B19: Near-term | C19: Terminal | D19: Consensus | E19: Thesis claim
A20: Total company | B20: 0.047047763 | C20: 0.05 | D20: 0.047047763
A28: PROFITABILITY & TAX
A29: Near-term operating margin | B29: 0.33368994 | D29: 0.33368994 | E29: consensus-implied; ramps to terminal
A30: Terminal operating margin | B30: 0.34875766 | E30: AI/ads mix + operating leverage
A31: Tax rate | B31: 0.24
A33: CAPITAL INTENSITY
A34: 2026 capex ($M) | B34: 5814.6 | D34: 5814.6 | E34: ~last-year capex +10%; set to guidance
A35: Terminal capex / D&A | B35: 1.05 | E35: converges to ~1.0x as build-out matures
A37: DISCOUNT RATE & TERMINAL
A38: Risk-free rate (10Y) | B38: 0.043
A39: Equity risk premium | B39: 0.045
A40: Beta (levered) | B40: 0.971 | E40: FMP raw beta; Damodaran bottom-up ~1.2
A41: Pre-tax cost of debt | B41: 0.045
A42: WACC (computed) | B42: =WACC!B15
A43: Terminal method | B43: Exit multiple
A44: Exit basis | B44: EV/EBITDA
A45: Exit multiple | B45: 12
A46: Terminal growth (g) | B46: 0.045
A47: Country risk premium | B47: 0 | E47: Damodaran country premiums, revenue-weighted (2026-01); 0 for US/mature
A48: Current price | B48: 68.199997
A49: Growth fade curvature | B49: 4 | E49: convexity of the near->terminal growth fade, fit to consensus (1.0=linear); higher = faster early deceleration
A50: SCENARIOS — Bull / Bear offsets vs Base (edit the yellow Δs)
A51: Scenario lever | B51: Base | C51: Bull Δ | D51: Bear Δ
...

Sheet Assumptions
A1: TRP — Assumptions & Reasoning
A2: Provenance of every Dashboard input. Read-only — regenerated by each build/refresh. Current is a live link to the Dashboard; Source / Opus value / Note are as of the last refresh_dcf run.
A4: Assumptions baseline | B4: no Opus assumptions file — every input is a builder default
A6: DASHBOARD INPUTS — value · source · reasoning
A7: Input | B7: Cell | C7: Current | D7: Source | E7: Opus value | F7: Note
A8: Total company — near-term growth | B8: B20 | C8: =Dashboard!B20 | D8: builder default | E8: —
A9: Total company — terminal growth | B9: C20 | C9: =Dashboard!C20 | D9: builder default | E9: —
A10: Near-term operating margin | B10: B29 | C10: =Dashboard!B29 | D10: builder default | E10: —
A11: Terminal operating margin | B11: B30 | C11: =Dashboard!B30 | D11: builder default | E11: —
A12: Tax rate | B12: B31 | C12: =Dashboard!B31 | D12: builder default | E12: —
A13: Terminal capex / D&A | B13: B35 | C13: =Dashboard!B35 | D13: builder default | E13: —
A14: Risk-free rate (10Y) | B14: B38 | C14: =Dashboard!B38 | D14: builder default | E14: —
A15: Equity risk premium | B15: B39 | C15: =Dashboard!B39 | D15: builder default | E15: —
A16: Beta (levered) | B16: B40 | C16: =Dashboard!B40 | D16: builder default | E16: —
A17: Pre-tax cost of debt | B17: B41 | C17: =Dashboard!B41 | D17: builder default | E17: —
A18: Terminal method | B18: B43 | C18: =Dashboard!B43 | D18: builder default | E18: —
A19: Exit basis | B19: B44 | C19: =Dashboard!B44 | D19: builder default | E19: —
A20: Exit multiple | B20: B45 | C20: =Dashboard!B45 | D20: builder default | E20: —
A21: Terminal growth (g) | B21: B46 | C21: =Dashboard!B46 | D21: builder default | E21: —
A22: 2026 capex ($M) | B22: B34 | C22: =Dashboard!B34 | D22: builder default | E22: — | F22: last-year capex +10% unless set to guidance; edits not tracked
A23: Bull Δ — segment growth, near-term | B23: C52 | C23: =Dashboard!C52 | D23: seed default | E23: 3.0%
A24: Bear Δ — segment growth, near-term | B24: D52 | C24: =Dashboard!D52 | D24: seed default | E24: -3.0%
A25: Bull Δ — segment growth, terminal | B25: C53 | C25: =Dashboard!C53 | D25: seed default | E25: 1.0%
A26: Bear Δ — segment growth, terminal | B26: D53 | C26: =Dashboard!D53 | D26: seed default | E26: -1.0%
A27: Bull Δ — operating margin, near-term | B27: C54 | C27: =Dashboard!C54 | D27: seed default | E27: 1.0%
A28: Bear Δ — operating margin, near-term | B28: D54 | C28: =Dashboard!D54 | D28: seed default | E28: -1.0%
A29: Bull Δ — operating margin, terminal | B29: C55 | C29: =Dashboard!C55 | D29: seed default | E29: 2.0%
A30: Bear Δ — operating margin, terminal | B30: D55 | C30: =Dashboard!D55 | D30: seed default | E30: -2.0%
A31: Bull Δ — exit multiple | B31: C56 | C31: =Dashboard!C56 | D31: seed default | E31: 2.0x
A32: Bear Δ — exit multiple | B32: D56 | C32: =Dashboard!D56 | D32: seed default | E32: -2.0x
A33: Bull Δ — terminal growth (g) | B33: C57 | C33: =Dashboard!C57 | D33: seed default | E33: 0.5%
A34: Bear Δ — terminal growth (g) | B34: D57 | C34: =Dashboard!D57 | D34: seed default | E34: -0.5%

Sheet Color Code
A1: Color | B1: Meaning
A2: Black | B2: Formula-driven (same-sheet)
A3: Blue | B3: Hard-coded actuals (from FMP filings)
A4: Yellow | B4: An assumption you can change — edit these to drive the model
A5: Green | B5: A formula that links to another sheet
A6: Orange | B6: (Dashboard) an assumption you've moved off consensus — your active bet
A7: How to use | B7: Edit yellow cells (Model assumptions, WACC drivers, Valuation toggles). Everything else recomputes.

Sheet WACC
A1: WACC Calculator
A2: Risk-free rate (10Y) | B2: =Dashboard!$B$38
A3: Equity risk premium | B3: =Dashboard!$B$39
A4: Beta (levered) | B4: =Dashboard!$B$40
A5: Country risk premium | B5: =Dashboard!$B$47
A6: Cost of equity (CAPM) | B6: =B2+B4*B3+B5
A7: Pre-tax cost of debt | B7: =Dashboard!$B$41
A8: Tax rate | B8: =Dashboard!$B$31
A9: After-tax cost of debt | B9: =B7*(1-B8)
A10: Market cap (E) | B10: =Dashboard!$B$48*Financials!AC17
A11: Total debt (D) | B11: =Financials!AC24
A12: Equity weight | B12: =B10/(B10+B11)
A13: Debt weight | B13: =B11/(B10+B11)
A15: WACC | B15: =B12*B6+B13*B9
A17: Yellow = edit. CAPM cost of equity (incl. country risk premium); market-value weights. Feeds Valuation!WACC.

Sheet Model
A1: $M unless noted | B1: FY2021A | C1: FY2022A | D1: FY2023A | E1: FY2024A | F1: FY2025A | G1: FY2026E | H1: FY2027E | I1: FY2028E | J1: FY2029E | K1: FY2030E | L1: FY2031E | M1: FY2032E | N1: FY2033E | O1: FY2034E | P1: FY2035E
A3: REVENUE BY SEGMENT (yellow = growth assumption; actuals link to Financials)
A4: Total company | B4: =SUM(Financials!I3:L3) | C4: =SUM(Financials!M3:P3) | D4: =SUM(Financials!Q3:T3) | E4: =SUM(Financials!U3:X3) | F4: =SUM(Financials!Y3:AB3) | G4: =F4*(1+G5) | H4: =G4*(1+H5) | I4: =H4*(1+I5) | J4: =I4*(1+J5) | K4: =J4*(1+K5) | L4: =K4*(1+L5) | M4: =L4*(1+M5) | N4: =M4*(1+N5) | ... P4: =O4*(1+P5)
A5: growth % (convex fade; curvature from Dashboard) | C5: =IFERROR(C4/B4-1,"") | D5: =IFERROR(D4/C4-1,"") | E5: =IFERROR(E4/D4-1,"") | F5: =IFERROR(F4/E4-1,"") | G5: =Dashboard!$C$20+(Dashboard!$B$20-Dashboard!$C$20)*((9-0)/9)^Dashboard!$B$49 | H5: =Dashboard!$C$20+(Dashboard!$B$20-Dashboard!$C$20)*((9-1)/9)^Dashboard!$B$49 | I5: =Dashboard!$C$20+(Dashboard!$B$20-Dashboard!$C$20)*((9-2)/9)^Dashboard!$B$49 | J5: =Dashboard!$C$20+(Dashboard!$B$20-Dashboard!$C$20)*((9-3)/9)^Dashboard!$B$49 | K5: =Dashboard!$C$20+(Dashboard!$B$20-Dashboard!$C$20)*((9-4)/9)^Dashboard!$B$49 | L5: =Dashboard!$C$20+(Dashboard!$B$20-Dashboard!$C$20)*((9-5)/9)^Dashboard!$B$49 | M5: =Dashboard!$C$20+(Dashboard!$B$20-Dashboard!$C$20)*((9-6)/9)^Dashboard!$B$49 | N5: =Dashboard!$C$20+(Dashboard!$B$20-Dashboard!$C$20)*((9-7)/9)^Dashboard!$B$49 | O5: =Dashboard!$C$20+(Dashboard!$B$20-Dashboard!$C$20)*((9-8)/9)^Dashboard!$B$49 | P5: =Dashboard!$C$20+(Dashboard!$B$20-Dashboard!$C$20)*((9-9)/9)^Dashboard!$B$49
A6: Total revenue | B6: =B4 | C6: =C4 | D6: =D4 | E6: =E4 | F6: =F4 | G6: =G4 | H6: =H4 | I6: =I4 | ... P6: =P4
A7: growth % | C7: =IFERROR(C6/B6-1,"") | D7: =IFERROR(D6/C6-1,"") | E7: =IFERROR(E6/D6-1,"") | F7: =IFERROR(F6/E6-1,"") | G7: =IFERROR(G6/F6-1,"") | H7: =IFERROR(H6/G6-1,"") | I7: =IFERROR(I6/H6-1,"") | J7: =IFERROR(J6/I6-1,"") | ... P7: =IFERROR(P6/O6-1,"")
A9: COST STRUCTURE (yellow = % of revenue)
A10: Cost of revenue | B10: =SUM(Financials!I5:L5) | C10: =SUM(Financials!M5:P5) | D10: =SUM(Financials!Q5:T5) | E10: =SUM(Financials!U5:X5) | F10: =SUM(Financials!Y5:AB5) | G10: =G6*G11 | H10: =H6*H11 | I10: =I6*I11 | J10: =J6*J11 | K10: =K6*K11 | L10: =L6*L11 | M10: =M6*M11 | N10: =N6*N11 | ... P10: =P6*P11
A11: % of revenue | B11: =IFERROR(B10/B6,"") | C11: =IFERROR(C10/C6,"") | D11: =IFERROR(D10/D6,"") | E11: =IFERROR(E10/E6,"") | F11: =IFERROR(F10/F6,"") | G11: 0.50151821 | H11: 0.50151821 | I11: 0.50151821 | J11: 0.50151821 | K11: 0.50151821 | L11: 0.50151821 | M11: 0.50151821 | N11: 0.50151821 | O11: 0.50151821 | P11: 0.50151821
A12: R&D / Technology | B12: =SUM(Financials!I7:L7) | C12: =SUM(Financials!M7:P7) | D12: =SUM(Financials!Q7:T7) | E12: =SUM(Financials!U7:X7) | F12: =SUM(Financials!Y7:AB7) | G12: =G6*G13 | H12: =H6*H13 | I12: =I6*I13 | J12: =J6*J13 | K12: =K6*K13 | L12: =L6*L13 | M12: =M6*M13 | N12: =N6*N13 | ... P12: =P6*P13
A13: % of revenue | B13: =IFERROR(B12/B6,"") | C13: =IFERROR(C12/C6,"") | D13: =IFERROR(D12/D6,"") | E13: =IFERROR(E12/E6,"") | F13: =IFERROR(F12/F6,"") | G13: 0 | H13: 0 | I13: 0 | J13: 0 | K13: 0 | L13: 0 | M13: 0 | N13: 0 | O13: 0 | P13: 0
A14: SG&A | B14: =SUM(Financials!I9:L9) | C14: =SUM(Financials!M9:P9) | D14: =SUM(Financials!Q9:T9) | E14: =SUM(Financials!U9:X9) | F14: =SUM(Financials!Y9:AB9) | G14: =G6*G15 | H14: =H6*H15 | I14: =I6*I15 | J14: =J6*J15 | K14: =K6*K15 | L14: =L6*L15 | M14: =M6*M15 | N14: =N6*N15 | ... P14: =P6*P15
A15: % of revenue | B15: =IFERROR(B14/B6,"") | C15: =IFERROR(C14/C6,"") | D15: =IFERROR(D14/D6,"") | E15: =IFERROR(E14/E6,"") | F15: =IFERROR(F14/F6,"") | G15: 0 | H15: 0 | I15: 0 | J15: 0 | K15: 0 | L15: 0 | M15: 0 | N15: 0 | O15: 0 | P15: 0
A16: Other opex (fulfilment, etc.) | B16: =B6-(B10+B12+B14)-SUM(Financials!I13:L13) | C16: =C6-(C10+C12+C14)-SUM(Financials!M13:P13) | D16: =D6-(D10+D12+D14)-SUM(Financials!Q13:T13) | E16: =E6-(E10+E12+E14)-SUM(Financials!U13:X13) | F16: =F6-(F10+F12+F14)-SUM(Financials!Y13:AB13) | G16: =G6*(1-(Dashboard!$B$29+(Dashboard!$B$30-Dashboard!$B$29)*MIN(1,0/4)))-(G10+G12+G14) | H16: =H6*(1-(Dashboard!$B$29+(Dashboard!$B$30-Dashboard!$B$29)*MIN(1,1/4)))-(H10+H12+H14) | I16: =I6*(1-(Dashboard!$B$29+(Dashboard!$B$30-Dashboard!$B$29)*MIN(1,2/4)))-(I10+I12+I14) | J16: =J6*(1-(Dashboard!$B$29+(Dashboard!$B$30-Dashboard!$B$29)*MIN(1,3/4)))-(J10+J12+J14) | K16: =K6*(1-(Dashboard!$B$29+(Dashboard!$B$30-Dashboard!$B$29)*MIN(1,4/4)))-(K10+K12+K14) | L16: =L6*(1-(Dashboard!$B$29+(Dashboard!$B$30-Dashboard!$B$29)*MIN(1,5/4)))-(L10+L12+L14) | M16: =M6*(1-(Dashboard!$B$29+(Dashboard!$B$30-Dashboard!$B$29)*MIN(1,6/4)))-(M10+M12+M14) | N16: =N6*(1-(Dashboard!$B$29+(Dashboard!$B$30-Dashboard!$B$29)*MIN(1,7/4)))-(N10+N12+N14) | O16: =O6*(1-(Dashboard!$B$29+(Dashboard!$B$30-Dashboard!$B$29)*MIN(1,8/4)))-(O10+O12+O14) | P16: =P6*(1-(Dashboard!$B$29+(Dashboard!$B$30-Dashboard!$B$29)*MIN(1,9/4)))-(P10+P12+P14)
A17: % of revenue | B17: =IFERROR(B16/B6,"") | C17: =IFERROR(C16/C6,"") | D17: =IFERROR(D16/D6,"") | E17: =IFERROR(E16/E6,"") | F17: =IFERROR(F16/F6,"") | G17: =IFERROR(G16/G6,"") | H17: =IFERROR(H16/H6,"") | I17: =IFERROR(I16/I6,"") | ... P17: =IFERROR(P16/P6,"")
A19: Operating income (EBIT) | B19: =B6-(B10+B12+B14)-B16 | C19: =C6-(C10+C12+C14)-C16 | D19: =D6-(D10+D12+D14)-D16 | E19: =E6-(E10+E12+E14)-E16 | F19: =F6-(F10+F12+F14)-F16 | G19: =G6-(G10+G12+G14)-G16 | H19: =H6-(H10+H12+H14)-H16 | I19: =I6-(I10+I12+I14)-I16 | ... P19: =P6-(P10+P12+P14)-P16
A20: operating margin | B20: =IFERROR(B19/B6,"") | C20: =IFERROR(C19/C6,"") | D20: =IFERROR(D19/D6,"") | E20: =IFERROR(E19/E6,"") | F20: =IFERROR(F19/F6,"") | G20: =IFERROR(G19/G6,"") | H20: =IFERROR(H19/H6,"") | I20: =IFERROR(I19/I6,"") | ... P20: =IFERROR(P19/P6,"")
A22: FCF BRIDGE (NOPAT + D&A + SBC - dNWC - Capex)
A23: NOPAT = EBIT x (1 - tax) | B23: =B19*(1-Valuation!$B$5) | C23: =C19*(1-Valuation!$B$5) | D23: =D19*(1-Valuation!$B$5) | E23: =E19*(1-Valuation!$B$5) | F23: =F19*(1-Valuation!$B$5) | G23: =G19*(1-Valuation!$B$5) | H23: =H19*(1-Valuation!$B$5) | I23: =I19*(1-Valuation!$B$5) | ... P23: =P19*(1-Valuation!$B$5)
A24: + D&A | B24: =SUM(Financials!I27:L27) | C24: =SUM(Financials!M27:P27) | D24: =SUM(Financials!Q27:T27) | E24: =SUM(Financials!U27:X27) | F24: =SUM(Financials!Y27:AB27) | G24: =G6*0.1829 | H24: =H6*0.1829 | I24: =I6*0.1829 | J24: =J6*0.1829 | K24: =K6*0.1829 | L24: =L6*0.1829 | M24: =M6*0.1829 | N24: =N6*0.1829 | ... P24: =P6*0.1829
A25: + SBC (non-cash) | B25: =SUM(Financials!I28:L28) | C25: =SUM(Financials!M28:P28) | D25: =SUM(Financials!Q28:T28) | E25: =SUM(Financials!U28:X28) | F25: =SUM(Financials!Y28:AB28) | G25: =G6*(Dashboard!$B$65+(Dashboard!$B$66-Dashboard!$B$65)*0/9) | H25: =H6*(Dashboard!$B$65+(Dashboard!$B$66-Dashboard!$B$65)*1/9) | I25: =I6*(Dashboard!$B$65+(Dashboard!$B$66-Dashboard!$B$65)*2/9) | J25: =J6*(Dashboard!$B$65+(Dashboard!$B$66-Dashboard!$B$65)*3/9) | K25: =K6*(Dashboard!$B$65+(Dashboard!$B$66-Dashboard!$B$65)*4/9) | L25: =L6*(Dashboard!$B$65+(Dashboard!$B$66-Dashboard!$B$65)*5/9) | M25: =M6*(Dashboard!$B$65+(Dashboard!$B$66-Dashboard!$B$65)*6/9) | N25: =N6*(Dashboard!$B$65+(Dashboard!$B$66-Dashboard!$B$65)*7/9) | O25: =O6*(Dashboard!$B$65+(Dashboard!$B$66-Dashboard!$B$65)*8/9) | P25: =P6*(Dashboard!$B$65+(Dashboard!$B$66-Dashboard!$B$65)*9/9)
A26: - dNWC | G26: =(G6-F6)*0.0050 | H26: =(H6-G6)*0.0050 | I26: =(I6-H6)*0.0050 | J26: =(J6-I6)*0.0050 | K26: =(K6-J6)*0.0050 | L26: =(L6-K6)*0.0050 | M26: =(M6-L6)*0.0050 | N26: =(N6-M6)*0.0050 | ... P26: =(P6-O6)*0.0050
A27: - Capex | B27: =-SUM(Financials!I31:L31) | C27: =-SUM(Financials!M31:P31) | D27: =-SUM(Financials!Q31:T31) | E27: =-SUM(Financials!U31:X31) | F27: =-SUM(Financials!Y31:AB31) | G27: =G24*G28 | H27: =H24*H28 | I27: =I24*I28 | J27: =J24*J28 | K27: =K24*K28 | L27: =L24*L28 | M27: =M24*M28 | N27: =N24*N28 | ... P27: =P24*P28
A28: Capex / D&A (from Dashboard: $cap'26 -> terminal) | B28: =IFERROR(B27/B24,"") | C28: =IFERROR(C27/C24,"") | D28: =IFERROR(D27/D24,"") | E28: =IFERROR(E27/E24,"") | F28: =IFERROR(F27/F24,"") | G28: =(Dashboard!$B$34/G24)+(Dashboard!$B$35-(Dashboard!$B$34/G24))*0/9 | H28: =(Dashboard!$B$34/G24)+(Dashboard!$B$35-(Dashboard!$B$34/G24))*1/9 | I28: =(Dashboard!$B$34/G24)+(Dashboard!$B$35-(Dashboard!$B$34/G24))*2/9 | J28: =(Dashboard!$B$34/G24)+(Dashboard!$B$35-(Dashboard!$B$34/G24))*3/9 | K28: =(Dashboard!$B$34/G24)+(Dashboard!$B$35-(Dashboard!$B$34/G24))*4/9 | L28: =(Dashboard!$B$34/G24)+(Dashboard!$B$35-(Dashboard!$B$34/G24))*5/9 | M28: =(Dashboard!$B$34/G24)+(Dashboard!$B$35-(Dashboard!$B$34/G24))*6/9 | N28: =(Dashboard!$B$34/G24)+(Dashboard!$B$35-(Dashboard!$B$34/G24))*7/9 | O28: =(Dashboard!$B$34/G24)+(Dashboard!$B$35-(Dashboard!$B$34/G24))*8/9 | P28: =(Dashboard!$B$34/G24)+(Dashboard!$B$35-(Dashboard!$B$34/G24))*9/9
A30: FCFF (firm) | B30: =B23+B24+B25-B26-B27 | C30: =C23+C24+C25-C26-C27 | D30: =D23+D24+D25-D26-D27 | E30: =E23+E24+E25-E26-E27 | F30: =F23+F24+F25-F26-F27 | G30: =G23+G24+G25-G26-G27 | H30: =H23+H24+H25-H26-H27 | I30: =I23+I24+I25-I26-I27 | ... P30: =P23+P24+P25-P26-P27
A31: Valuation FCF (NOPAT + D&A - dNWC - Capex - after-tax SBC) | B31: =B30-B25-B25*(1-Valuation!$B$5) | C31: =C30-C25-C25*(1-Valuation!$B$5) | D31: =D30-D25-D25*(1-Valuation!$B$5) | E31: =E30-E25-E25*(1-Valuation!$B$5) | F31: =F30-F25-F25*(1-Valuation!$B$5) | G31: =G30-G25-G25*(1-Valuation!$B$5) | H31: =H30-H25-H25*(1-Valuation!$B$5) | I31: =I30-I25-I25*(1-Valuation!$B$5) | ... P31: =P30-P25-P25*(1-Valuation!$B$5)
A33: RETURNS ON CAPITAL & EFFICIENCY (is new revenue/capital earning its keep?)
A34: Invested capital (debt + equity - cash) | B34: =Financials!L25+Financials!L24-Financials!L19 | C34: =Financials!P25+Financials!P24-Financials!P19 | D34: =Financials!T25+Financials!T24-Financials!T19 | E34: =Financials!X25+Financials!X24-Financials!X19 | F34: =Financials!AB25+Financials!AB24-Financials!AB19 | G34: =F34+G27-G24+G26 | H34: =G34+H27-H24+H26 | I34: =H34+I27-I24+I26 | J34: =I34+J27-J24+J26 | K34: =J34+K27-K24+K26 | L34: =K34+L27-L24+L26 | M34: =L34+M27-M24+M26 | N34: =M34+N27-N24+N26 | ... P34: =O34+P27-P24+P26
A35: Book equity (year-end) | B35: =Financials!L25 | C35: =Financials!P25 | D35: =Financials!T25 | E35: =Financials!X25 | F35: =Financials!AB25 | G35: =F35+G23 | H35: =G35+H23 | I35: =H35+I23 | J35: =I35+J23 | K35: =J35+K23 | L35: =K35+L23 | M35: =L35+M23 | N35: =M35+N23 | ... P35: =O35+P23
A36: ROIC (NOPAT / beg. invested capital) | C36: =IFERROR(C23/B34,"") | D36: =IFERROR(D23/C34,"") | E36: =IFERROR(E23/D34,"") | F36: =IFERROR(F23/E34,"") | G36: =IFERROR(G23/F34,"") | H36: =IFERROR(H23/G34,"") | I36: =IFERROR(I23/H34,"") | J36: =IFERROR(J23/I34,"") | ... P36: =IFERROR(P23/O34,"")
A37: ROE (earnings / beg. equity) | C37: =IFERROR(SUM(Financials!M15:P15)/B35,"") | D37: =IFERROR(SUM(Financials!Q15:T15)/C35,"") | E37: =IFERROR(SUM(Financials!U15:X15)/D35,"") | F37: =IFERROR(SUM(Financials!Y15:AB15)/E35,"") | G37: =IFERROR(G23/F35,"") | H37: =IFERROR(H23/G35,"") | I37: =IFERROR(I23/H35,"") | J37: =IFERROR(J23/I35,"") | K37: =IFERROR(K23/J35,"") | L37: =IFERROR(L23/K35,"") | M37: =IFERROR(M23/L35,"") | N37: =IFERROR(N23/M35,"") | ... P37: =IFERROR(P23/O35,"")
A38: ROIC - WACC spread (value created) | C38: =IFERROR(C36-WACC!$B$15,"") | D38: =IFERROR(D36-WACC!$B$15,"") | E38: =IFERROR(E36-WACC!$B$15,"") | F38: =IFERROR(F36-WACC!$B$15,"") | G38: =IFERROR(G36-WACC!$B$15,"") | H38: =IFERROR(H36-WACC!$B$15,"") | I38: =IFERROR(I36-WACC!$B$15,"") | J38: =IFERROR(J36-WACC!$B$15,"") | ... P38: =IFERROR(P36-WACC!$B$15,"")
A39: Incremental op margin (ΔEBIT / ΔRev) | C39: =IFERROR((C19-B19)/(C6-B6),"") | D39: =IFERROR((D19-C19)/(D6-C6),"") | E39: =IFERROR((E19-D19)/(E6-D6),"") | F39: =IFERROR((F19-E19)/(F6-E6),"") | G39: =IFERROR((G19-F19)/(G6-F6),"") | H39: =IFERROR((H19-G19)/(H6-G6),"") | I39: =IFERROR((I19-H19)/(I6-H6),"") | J39: =IFERROR((J19-I19)/(J6-I6),"") | ... P39: =IFERROR((P19-O19)/(P6-O6),"")
A40: ROIIC (ΔNOPAT / ΔInvested capital) | C40: =IFERROR((C23-B23)/(C34-B34),"") | D40: =IFERROR((D23-C23)/(D34-C34),"") | E40: =IFERROR((E23-D23)/(E34-D34),"") | F40: =IFERROR((F23-E23)/(F34-E34),"") | G40: =IFERROR((G23-F23)/(G34-F34),"") | H40: =IFERROR((H23-G23)/(H34-G34),"") | I40: =IFERROR((I23-H23)/(I34-H34),"") | J40: =IFERROR((J23-I23)/(J34-I34),"") | ... P40: =IFERROR((P23-O23)/(P34-O34),"")
A41: Sales-to-capital (ΔRev / ΔInvested capital) | C41: =IFERROR((C6-B6)/(C34-B34),"") | D41: =IFERROR((D6-C6)/(D34-C34),"") | E41: =IFERROR((E6-D6)/(E34-D34),"") | F41: =IFERROR((F6-E6)/(F34-E34),"") | G41: =IFERROR((G6-F6)/(G34-F34),"") | H41: =IFERROR((H6-G6)/(H34-G34),"") | I41: =IFERROR((I6-H6)/(I34-H34),"") | J41: =IFERROR((J6-I6)/(J34-I34),"") | ... P41: =IFERROR((P6-O6)/(P34-O34),"")
A42: Reinvestment rate (ΔInvested capital / NOPAT) | C42: =IFERROR((C34-B34)/C23,"") | D42: =IFERROR((D34-C34)/D23,"") | E42: =IFERROR((E34-D34)/E23,"") | F42: =IFERROR((F34-E34)/F23,"") | G42: =IFERROR((G34-F34)/G23,"") | H42: =IFERROR((H34-G34)/H23,"") | I42: =IFERROR((I34-H34)/I23,"") | J42: =IFERROR((J34-I34)/J23,"") | ... P42: =IFERROR((P34-O34)/P23,"")
A44: Blue/green = actual · Yellow = assumption · Black = formula

Sheet Financials
A1: Line Item ($M) | B1: Q2 2019 | C1: Q3 2019 | D1: Q4 2019 | E1: Q1 2020 | F1: Q2 2020 | G1: Q3 2020 | H1: Q4 2020 | I1: Q1 2021 | J1: Q2 2021 | K1: Q3 2021 | L1: Q4 2021 | M1: Q1 2022 | N1: Q2 2022 | O1: Q3 2022 | P1: Q4 2022 | Q1: Q1 2023 | R1: Q2 2023 | S1: Q3 2023 | T1: Q4 2023 | U1: Q1 2024 | V1: Q2 2024 | W1: Q3 2024 | X1: Q4 2024 | Y1: Q1 2025 | Z1: Q2 2025 | AA1: Q3 2025 | AB1: Q4 2025 | AC1: Q1 2026
A2: INCOME STATEMENT
A3: Revenue | B3: 3372 | C3: 3133 | D3: 3263 | E3: 3418 | F3: 3089 | G3: 3195 | H3: 3297 | I3: 3381 | J3: 3182 | K3: 3240 | L3: 3584 | M3: 3500 | N3: 3637 | O3: 3799 | P3: 4041 | Q3: 3928 | R3: 3830 | S3: 3940 | T3: 4236 | U3: 3509 | V3: 3327 | W3: 4083 | X3: 1360 | Y3: 3623 | Z3: 3744 | AA3: 3704 | AB3: 4071.6791 | AC3: 4243.9392
A4: % YoY | F4: =IFERROR(F3/B3-1,"") | G4: =IFERROR(G3/C3-1,"") | H4: =IFERROR(H3/D3-1,"") | I4: =IFERROR(I3/E3-1,"") | J4: =IFERROR(J3/F3-1,"") | K4: =IFERROR(K3/G3-1,"") | L4: =IFERROR(L3/H3-1,"") | M4: =IFERROR(M3/I3-1,"") | ... AC4: =IFERROR(AC3/Y3-1,"")
A5: Cost of Revenue | B5: 1642 | C5: 1592 | D5: 1719 | E5: 1550 | F5: 1568 | G5: 1649 | H5: 1701 | I5: 1531 | J5: 1592 | K5: 1770 | L5: 1814 | M5: 1760 | N5: 1981 | O5: 2123 | P5: 2186 | Q5: 1821 | R5: 2018 | S5: 2139 | T5: 2204 | U5: 1705 | V5: 1754 | W5: 2241 | X5: 585 | Y5: 1738 | Z5: 1902 | AA5: 1906 | AB5: 2048.3294 | AC5: 1837.737
A6: % of revenue | B6: =IFERROR(B5/B3,"") | C6: =IFERROR(C5/C3,"") | D6: =IFERROR(D5/D3,"") | E6: =IFERROR(E5/E3,"") | F6: =IFERROR(F5/F3,"") | G6: =IFERROR(G5/G3,"") | H6: =IFERROR(H5/H3,"") | I6: =IFERROR(I5/I3,"") | ... AC6: =IFERROR(AC5/AC3,"")
A7: R&D Expense | B7: 0 | C7: 0 | D7: 0 | E7: 0 | F7: 0 | G7: 0 | H7: 0 | I7: 0 | J7: 0 | K7: 0 | L7: 0 | M7: 0 | N7: 0 | O7: 0 | P7: 0 | Q7: 0 | R7: 0 | S7: 0 | T7: 0 | U7: 0 | V7: 0 | W7: 0 | X7: 0 | Y7: 0 | Z7: 0 | AA7: 0 | AB7: 0 | AC7: 0
A8: % of revenue | B8: =IFERROR(B7/B3,"") | C8: =IFERROR(C7/C3,"") | D8: =IFERROR(D7/D3,"") | E8: =IFERROR(E7/E3,"") | F8: =IFERROR(F7/F3,"") | G8: =IFERROR(G7/G3,"") | H8: =IFERROR(H7/H3,"") | I8: =IFERROR(I7/I3,"") | ... AC8: =IFERROR(AC7/AC3,"")
A9: SG&A Expense | B9: 0 | C9: 0 | D9: 0 | E9: 0 | F9: 0 | G9: 0 | H9: 0 | I9: 0 | J9: 0 | K9: 0 | L9: 0 | M9: 0 | N9: 0 | O9: 0 | P9: 0 | Q9: 0 | R9: 0 | S9: 0 | T9: 0 | U9: 0 | V9: 0 | W9: 0 | X9: 0 | Y9: 0 | Z9: 0 | AA9: 0 | AB9: 0 | AC9: 0
A10: % of revenue | B10: =IFERROR(B9/B3,"") | C10: =IFERROR(C9/C3,"") | D10: =IFERROR(D9/D3,"") | E10: =IFERROR(E9/E3,"") | F10: =IFERROR(F9/F3,"") | G10: =IFERROR(G9/G3,"") | H10: =IFERROR(H9/H3,"") | I10: =IFERROR(I9/I3,"") | ... AC10: =IFERROR(AC9/AC3,"")
A11: Gross Profit | B11: 1730 | C11: 1541 | D11: 1544 | E11: 1868 | F11: 1521 | G11: 1546 | H11: 1596 | I11: 1850 | J11: 1590 | K11: 1470 | L11: 1770 | M11: 1740 | N11: 1656 | O11: 1676 | P11: 1855 | Q11: 2107 | R11: 1812 | S11: 1801 | T11: 2032 | U11: 1804 | V11: 1573 | W11: 1842 | X11: 775 | Y11: 1885 | Z11: 1842 | AA11: 1798 | AB11: 2023.3498 | AC11: 2406.2022
A12: gross margin | B12: =IFERROR(B11/B3,"") | C12: =IFERROR(C11/C3,"") | D12: =IFERROR(D11/D3,"") | E12: =IFERROR(E11/E3,"") | F12: =IFERROR(F11/F3,"") | G12: =IFERROR(G11/G3,"") | H12: =IFERROR(H11/H3,"") | I12: =IFERROR(I11/I3,"") | ... AC12: =IFERROR(AC11/AC3,"")
A13: Operating Income | B13: 1549 | C13: 1363 | D13: 1363 | E13: 1692 | F13: 1322 | G13: 1372 | H13: 1418 | I13: 1654 | J13: 1394 | K13: 1279 | L13: 1579 | M13: 1533 | N13: 1443 | O13: 1462 | P13: 1641 | Q13: 1880 | R13: 1590 | S13: 1583 | T13: 1802 | U13: 1608 | V13: 1363 | W13: 1607 | X13: 652 | Y13: 1661 | Z13: 1624 | AA13: 1583 | AB13: 1799.5323 | AC13: 2211.7009
A14: operating margin | B14: =IFERROR(B13/B3,"") | C14: =IFERROR(C13/C3,"") | D14: =IFERROR(D13/D3,"") | E14: =IFERROR(E13/E3,"") | F14: =IFERROR(F13/F3,"") | G14: =IFERROR(G13/G3,"") | H14: =IFERROR(H13/H3,"") | I14: =IFERROR(I13/I3,"") | ... AC14: =IFERROR(AC13/AC3,"")
A15: Net Income | B15: 1166 | C15: 780 | D15: 1149 | E15: 1189 | F15: 1321 | G15: 943 | H15: 1163 | I15: -1019 | J15: 1014 | K15: 810 | L15: 1150 | M15: 389 | N15: 922 | O15: 862 | P15: -1425 | Q15: 1336 | R15: 273 | S15: -174 | T15: 1487 | U15: 1226 | V15: 990 | W15: 1483 | X15: 999 | Y15: 1006 | Z15: 861 | AA15: 637 | AB15: 1014.1728 | AC15: 929.39561
A16: net margin | B16: =IFERROR(B15/B3,"") | C16: =IFERROR(C15/C3,"") | D16: =IFERROR(D15/D3,"") | E16: =IFERROR(E15/E3,"") | F16: =IFERROR(F15/F3,"") | G16: =IFERROR(G15/G3,"") | H16: =IFERROR(H15/H3,"") | I16: =IFERROR(I15/I3,"") | ... AC16: =IFERROR(AC15/AC3,"")
A17: Diluted Shares (M) | B17: 928 | C17: 933 | D17: 938 | E17: 940 | F17: 940 | G17: 940 | H17: 940 | I17: 953 | J17: 979 | K17: 979 | L17: 981 | M17: 981 | N17: 984 | O17: 1000 | P17: 1016 | Q17: 1021 | R17: 1027 | S17: 1035 | T17: 1037 | U17: 1037 | V17: 1037 | W17: 1037 | X17: 1038 | Y17: 1040 | Z17: 1040 | AA17: 1040 | AB17: 1041 | AC17: 1042
A18: BALANCE SHEET
A19: Cash & ST Investments | B19: 964 | C19: 2455 | D19: 1523 | E19: 2708 | F19: 2380 | G19: 1493 | H19: 1530 | I19: 2501 | J19: 3098 | K19: 3037 | L19: 673 | M19: 1497 | N19: 2044 | O19: 2862 | P19: 620 | Q19: 4481 | R19: 1694 | S19: 3276 | T19: 3678 | U19: 3193 | V19: 2474 | W19: 3797 | X19: 801 | Y19: 1962 | Z19: 1422 | AA19: 1802 | AB19: 260.787 | AC19: 1085.799
A20: Total Current Assets | B20: 5676 | C20: 8274 | D20: 7651 | E20: 8970 | F20: 5704 | G20: 5124 | H20: 5201 | I20: 7266 | J20: 8345 | K20: 8721 | L20: 7423 | M20: 8470 | N20: 9259 | O20: 8900 | P20: 7332 | Q20: 10318 | R20: 7623 | S20: 9620 | T20: 11372 | U20: 11885 | V20: 10460 | W20: 17093 | X20: 5733 | Y20: 7272 | Z20: 7137 | AA20: 7778 | AB20: 6310.853 | AC20: 6845.645
A21: PP&E (net) | B21: 66685 | C21: 64962 | D21: 67204 | E21: 72273 | F21: 69880 | G21: 70544 | H21: 70006 | I21: 67185 | J21: 67192 | K21: 69284 | L21: 70224 | M21: 70482 | N21: 72609 | O21: 77127 | P21: 77934 | Q21: 79460 | R21: 79939 | S21: 82798 | T21: 71948 | U21: 84296 | V21: 86006 | W21: 86501 | X21: 80142 | Y21: 80468 | Z21: 77575 | AA21: 79468 | AB21: 70996.096 | AC21: 72207.121
A22: Total Assets | B22: 98429 | C22: 99611 | D22: 99279 | E22: 107811 | F22: 101797 | G22: 101862 | H22: 100300 | I22: 99949 | J22: 101201 | K22: 104523 | L22: 104218 | M22: 105182 | N22: 109133 | O22: 116802 | P22: 114348 | Q22: 119201 | R22: 117033 | S22: 122649 | T22: 125034 | U22: 128026 | V22: 127966 | W22: 135292 | X22: 118243 | Y22: 120545 | Z22: 116837 | AA22: 120234 | AB22: 118654.23 | AC22: 121140.25
A23: Total Current Liabilities | B23: 12966 | C23: 11027 | D23: 12899 | E23: 17513 | F23: 9780 | G23: 10068 | H23: 11987 | I23: 8979 | J23: 13721 | K23: 16979 | L23: 13041 | M23: 13923 | N23: 14482 | O23: 16765 | P23: 16907 | Q23: 13958 | R23: 12590 | S23: 11134 | T23: 11817 | U23: 12708 | V23: 13800 | W23: 13083 | X23: 10511 | Y23: 10324 | Z23: 11742 | AA23: 12299 | AB23: 9950.884 | AC23: 10529.14
A24: Long-term Debt | B24: 42377 | C24: 45160 | D24: 42894 | E24: 44073 | F24: 46436 | G24: 45695 | H24: 43411 | I24: 48527 | J24: 44590 | K24: 44045 | L24: 46280 | M24: 46808 | N24: 50064 | O24: 51552 | P24: 50140 | Q24: 56738 | R24: 56381 | S24: 63228 | T24: 60263 | U24: 61103 | V24: 59740 | W24: 67558 | X24: 56024 | Y24: 57990 | Z24: 53890 | AA24: 56102 | AB24: 57774.879 | AC24: 58312.306
A25: Total Equity | B25: 30014 | C25: 30558 | D25: 30763 | E25: 32237 | F25: 32458 | G25: 32202 | H25: 31398 | I25: 31499 | J25: 32009 | K25: 32393 | L25: 33271 | M25: 32818 | N25: 32655 | O25: 35773 | P25: 33990 | Q25: 34573 | R25: 33838 | S25: 33642 | T25: 29553 | U25: 30101 | V25: 30120 | W25: 30456 | X25: 27592 | Y25: 27693 | Z25: 27520 | AA25: 27465 | AB25: 27272.756 | AC25: 27601.145
A26: CASH FLOW
A27: D&A | B27: 621 | C27: 610 | D27: 625 | E27: 630 | F27: 635 | G27: 673 | H27: 652 | I27: 645 | J27: 633 | K27: 610 | L27: 634 | M27: 626 | N27: 493.05845 | O27: 471.8578 | P27: 670 | Q27: 677 | R27: 694 | S27: 690 | T27: 717 | U27: 468.757 | V27: 462.5331 | W27: 464.1234 | X27: 639 | Y27: 678 | Z27: 671 | AA27: 701 | AB27: 719 | AC27: 519.77916
A28: Stock-based Compensation | B28: 0 | C28: 0 | D28: 13 | E28: 0 | F28: 0 | G28: 0 | H28: 0 | I28: 0 | J28: 0 | K28: 0 | L28: 0 | M28: 0 | N28: 0 | O28: 0 | P28: 0 | Q28: 0 | R28: 0 | S28: 0 | T28: 0 | U28: 0 | V28: 0 | W28: 0 | X28: 0 | Y28: 0 | Z28: 0 | AA28: 0 | AB28: 0 | AC28: 0
A29: Change in Working Capital | B29: 47 | C29: 140 | D29: -36 | E29: -371 | F29: 64 | G29: 120 | H29: -140 | I29: -232 | J29: -27 | K29: 227 | L29: -255 | M29: 40 | N29: -479.85846 | O29: 48.4142 | P29: -128 | Q29: 60 | R29: -177 | S29: 102 | T29: 222 | U29: -253.9408 | V29: -125.6804 | W29: 150.02715 | X29: 512 | Y29: -590 | Z29: 209 | AA29: 130 | AB29: -252 | AC29: 186.20028
A30: Operating Cash Flow | B30: 1722 | C30: 1585 | D30: 1826 | E30: 1723 | F30: 1613 | G30: 1783 | H30: 1939 | I30: 1666 | J30: 1711 | K30: 1712 | L30: 1801 | M30: 1707 | N30: 756.28178 | O30: 2099.8756 | P30: 2025 | Q30: 2074 | R30: 1510 | S30: 1824 | T30: 1860 | U30: 1529.5504 | V30: 1209.3085 | W30: 1791.4572 | X30: 2084 | Y30: 1359 | Z30: 2173 | AA30: 1920 | AB30: 1894 | AC30: 1871.3488
A31: Capex | B31: -1788 | C31: -2002 | D31: -2206 | E31: -2118 | F31: -1990 | G31: -2063 | H31: -1964 | I31: -1645 | J31: -1214 | K31: -1446 | L31: -1619 | M31: -1521 | N31: -980.68161 | O31: -1327.4162 | P31: -2119 | Q31: -1963 | R31: -2044 | S31: -2060 | T31: -2082 | U31: -1165.6178 | V31: -974.0231 | W31: -1297.7718 | X31: -1649 | Y31: -1564 | Z31: -1115 | AA31: -1257 | AB31: -1350 | AC31: -769.2444
A32: Free Cash Flow | B32: -66 | C32: -417 | D32: -380 | E32: -395 | F32: -377 | G32: -280 | H32: -25 | I32: 21 | J32: 497 | K32: 266 | L32: 182 | M32: 186 | N32: -224.39983 | O32: 772.4594 | P32: -94 | Q32: 111 | R32: -534 | S32: -236 | T32: -222 | U32: 363.9326 | V32: 235.2854 | W32: 493.6854 | X32: 435 | Y32: -205 | Z32: 1058 | AA32: 663 | AB32: 544 | AC32: 1102.1044
A34: Blue = hardcoded actuals from FMP filings. Same-sheet ratios are formulas.

Sheet Consensus
A1: Full consensus check — model vs Street (FMP estimates, $M)
A2: Fiscal year | B2: 2026 | C2: 2027 | D2: 2028 | E2: 2029 | F2: 2030
A3: EVERY AVAILABLE FMP CONSENSUS FIELD (consensus / model / % diff)
A4: Revenue — consensus | B4: 16146.871 | C4: 16870.254 | D4: 17537.314 | E4: 18485.099 | F4: 19049.611
A5: model | B5: =Model!G6 | C5: =Model!H6 | D5: =Model!I6 | E5: =Model!J6 | F5: =Model!K6
A6: vs consensus | B6: =IFERROR(B5/B4-1,"") | C6: =IFERROR(C5/C4-1,"") | D6: =IFERROR(D5/D4-1,"") | E6: =IFERROR(E5/E4-1,"") | F6: =IFERROR(F5/F4-1,"")
A8: EBITDA* — consensus | B8: 9746.5865 | C8: 10183.236 | D8: 10585.887 | E8: 11157.99 | F8: 11498.741
A9: model | B9: =Model!G19+Model!G24 | C9: =Model!H19+Model!H24 | D9: =Model!I19+Model!I24 | E9: =Model!J19+Model!J24 | F9: =Model!K19+Model!K24
A10: vs consensus | B10: =IFERROR(B9/B8-1,"") | C10: =IFERROR(C9/C8-1,"") | D10: =IFERROR(D9/D8-1,"") | E10: =IFERROR(E9/E8-1,"") | F10: =IFERROR(F9/F8-1,"")
A12: EBIT* — consensus | B12: 6541.9604 | C12: 6835.0417 | D12: 7105.3032 | E12: 7489.3017 | F12: 7718.0156
A13: model | B13: =Model!G19 | C13: =Model!H19 | D13: =Model!I19 | E13: =Model!J19 | F13: =Model!K19
A14: vs consensus | B14: =IFERROR(B13/B12-1,"") | C14: =IFERROR(C13/C12-1,"") | D14: =IFERROR(D13/D12-1,"") | E14: =IFERROR(E13/E12-1,"") | F14: =IFERROR(F13/F12-1,"")
A16: SG&A — consensus | B16: 0 | C16: 0 | D16: 0 | E16: 0 | F16: 0
A17: model | B17: =Model!G14 | C17: =Model!H14 | D17: =Model!I14 | E17: =Model!J14 | F17: =Model!K14
A18: vs consensus | B18: =IFERROR(B17/B16-1,"") | C18: =IFERROR(C17/C16-1,"") | D18: =IFERROR(D17/D16-1,"") | E18: =IFERROR(E17/E16-1,"") | F18: =IFERROR(F17/F16-1,"")
A20: Net income (NOPAT) — consensus | B20: 4094.9168 | C20: 4426.3492 | D20: 4494.282 | E20: 4626.4608 | F20: 5049.2104
A21: model | B21: =Model!G23 | C21: =Model!H23 | D21: =Model!I23 | E21: =Model!J23 | F21: =Model!K23
A22: vs consensus | B22: =IFERROR(B21/B20-1,"") | C22: =IFERROR(C21/C20-1,"") | D22: =IFERROR(D21/D20-1,"") | E22: =IFERROR(E21/E20-1,"") | F22: =IFERROR(F21/F20-1,"")
A24: EPS — consensus | B24: 3.69553 | C24: 3.91616 | D24: 4.10959 | E24: 4.44852 | F24: 4.85501
A25: model | B25: =Model!G23/Financials!AC17 | C25: =Model!H23/Financials!AC17 | D25: =Model!I23/Financials!AC17 | E25: =Model!J23/Financials!AC17 | F25: =Model!K23/Financials!AC17
A26: vs consensus | B26: =IFERROR(B25/B24-1,"") | C26: =IFERROR(C25/C24-1,"") | D26: =IFERROR(D25/D24-1,"") | E26: =IFERROR(E25/E24-1,"") | F26: =IFERROR(F25/F24-1,"")
A28: Defaults anchored to consensus revenue + net income (≈0% diff). Other rows show where the model sits vs Street.
A29: *FMP's EBITDA/EBIT estimates look unreliable for AMZN (it reports NI > EBIT) — don't over-read those two.

Sheet Valuation
A1: TC Energy Corporation — DCF Valuation
A2: Current price | B2: =Dashboard!$B$48
A3: WACC | B3: =WACC!B15
A4: Terminal growth (g) | B4: =Dashboard!$B$46
A5: Tax rate | B5: =Dashboard!$B$31
A6: Terminal method | B6: =Dashboard!$B$43
A7: Exit basis | B7: =Dashboard!$B$44
A8: Exit multiple | B8: =Dashboard!$B$45
A11: Forecast year | C11: 2026 | D11: 2027 | E11: 2028 | F11: 2029 | G11: 2030 | H11: 2031 | I11: 2032 | J11: 2033 | K11: 2034 | L11: 2035
A12: FCFF ($M) | C12: =Model!G31 | D12: =Model!H31 | E12: =Model!I31 | F12: =Model!J31 | G12: =Model!K31 | H12: =Model!L31 | I12: =Model!M31 | J12: =Model!N31 | ... L12: =Model!P31
A13: PV factor | C13: =1/(1+$B$3)^1 | D13: =1/(1+$B$3)^2 | E13: =1/(1+$B$3)^3 | F13: =1/(1+$B$3)^4 | G13: =1/(1+$B$3)^5 | H13: =1/(1+$B$3)^6 | I13: =1/(1+$B$3)^7 | J13: =1/(1+$B$3)^8 | K13: =1/(1+$B$3)^9 | L13: =1/(1+$B$3)^10
A14: PV of FCFF ($M) | C14: =C12*C13 | D14: =D12*D13 | E14: =E12*E13 | F14: =F12*F13 | G14: =G12*G13 | H14: =H12*H13 | I14: =I12*I13 | J14: =J12*J13 | ... L14: =L12*L13
A16: Sum PV of FCFF | B16: =SUM(C14:L14)
A18: TERMINAL VALUE (exit multiple = default; perpetuity = cross-check)
A19: Terminal-year FCFF | B19: =L12
A20: Terminal revenue | B20: =Model!P6
A21: Terminal EBIT | B21: =Model!P19
A22: Terminal EBITDA (SBC-burdened) | B22: =Model!P19+Model!P24-Model!P25
A23: Terminal metric (per exit basis) | B23: =IF($B$7="EV/EBITDA",B22,IF($B$7="EV/Sales",B20,IF($B$7="EV/EBIT",B21,B19)))
A24: TV (exit) = metric x multiple | B24: =B23*$B$8
A25: PV of TV — exit multiple | B25: =B24/(1+$B$3)^10
A26: TV (perpetuity) = FCFF(1+g)/(WACC-g) | B26: =B19*(1+$B$4)/($B$3-$B$4)
A27: PV of TV — perpetuity | B27: =B26/(1+$B$3)^10
A28: PV of TV — SELECTED | B28: =IF($B$6="Perpetuity",B27,B25)
A30: EQUITY BRIDGE -> VALUE / SHARE
A31: Operating value (enterprise value) | B31: =B16+B28
A32: + Cash & ST investments | B32: =Financials!AC19
A33: - Long-term debt | B33: =-Financials!AC24
A34: Equity value | B34: =B31+B32+B33
A35: Diluted shares (M) | B35: =Financials!AC17
A36: VALUE / SHARE | B36: =B34/B35*0.73
A38: CROSS-CHECKS & RETURN
A39: Terminal weight (% of EV) | B39: =B28/B31
A40: Implied perpetuity g (from exit multiple) | B40: =(B24*$B$3-B19)/(B24+B19)
A41: Implied exit EV/EBITDA (from perpetuity) | B41: =B26/B22
A42: Upside / (downside) to fair value | B42: =B36/$B$2-1
A44: Owner cashflow / share | B44: =-$B$2 | C44: =C12/B35 | D44: =D12/B35 | E44: =E12/B35 | F44: =F12/B35 | G44: =G12/B35 | H44: =H12/B35 | I44: =I12/B35 | J44: =J12/B35 | K44: =K12/B35 | L44: =L12/B35+B36
A45: IRR (buy at price, hold 10y) | B45: =IRR(B44:L44)

Sheet Sensitivity
A1: Sensitivity — fair value / share (USD)
A2: WACC x exit multiple (EV/EBITDA). Static grid recomputed by every rebuild/refresh — edit the Dashboard, re-run refresh_dcf to update. Shaded = base case; green = above current price.
A4: EV/EBITDA x \ WACC | B4: 0.0480346 | C4: 0.0530346 | D4: 0.0580346 | E4: 0.0630346 | F4: 0.0680346 | G4: 0.0730346 | H4: 0.0780346
A5: 9 | B5: 28.945436 | C5: 26.01754 | D5: 23.23278 | E5: 20.583429 | F5: 18.062209 | G5: 15.66227 | H5: 13.377159
A6: 10 | B6: 34.654149 | C6: 31.460911 | D6: 28.424314 | E6: 25.535882 | F6: 22.787637 | G6: 20.172068 | H6: 17.682102
A7: 11 | B7: 40.362862 | C7: 36.904283 | D7: 33.615848 | E7: 30.488336 | F7: 27.513066 | G7: 24.681867 | H7: 21.987045
A8: 12 | B8: 46.071575 | C8: 42.347655 | D8: 38.807382 | E8: 35.440789 | F8: 32.238494 | G8: 29.191666 | H8: 26.291988
A9: 13 | B9: 51.780287 | C9: 47.791026 | D9: 43.998916 | E9: 40.393243 | F9: 36.963922 | G9: 33.701464 | H9: 30.596931
A10: 14 | B10: 57.489 | C10: 53.234398 | D10: 49.19045 | E10: 45.345696 | F10: 41.689351 | G10: 38.211263 | H10: 34.901874
A11: 15 | B11: 63.197713 | C11: 58.67777 | D11: 54.381984 | E11: 50.298149 | F11: 46.414779 | G11: 42.721061 | H11: 39.206817
A13: Current price | B13: 68.199997
A14: Base WACC / multiple | B14: 0.0630346 | C14: 12

Sheet Monte Carlo
A1: Monte Carlo simulation (live) | H1: SIMULATION ENGINE — leave as-is | K1: cagr | L1: term margin | M1: wacc | N1: exit | O1: value/share
A2: 1,000 trials, recomputed in-sheet on every edit. Edit the yellow driver distributions to re-roll. Engine grid is to the right (cols H+). | H2: R0 (base revenue) | I2: =Model!F6 | K2: =MAX(-0.05,NORMINV(RAND(),$C$6,$D$6)) | L2: =MAX(0.02,NORMINV(RAND(),$C$7,$D$7)) | M2: =MIN(0.16,MAX(0.05,NORMINV(RAND(),$C$8,$D$8))) | N2: =MIN(24,MAX(5,NORMINV(RAND(),$C$9,$D$9))) | O2: =$I$8*(SUMPRODUCT(($I$2*(1+K2)^{1;2;3;4;5;6;7;8;9;10})*(($I$3+(L2-$I$3)*{1;2;3;4;5;6;7;8;9;10}/10)*(1-$I$7)+$I$4-$I$4*($I$5+(1.05-$I$5)*{1;2;3;4;5;6;7;8;9;10}/10)-(K2/(1+K2))*$I$6)/(1+M2)^{1;2;3;4;5;6;7;8;9;10})+$I$2*(1+K2)^10*(L2+$I$4)*N2/(1+M2)^10+$I$9-$I$10)/$I$11
H3: m0 (base op margin) | I3: =Model!F20 | K3: =MAX(-0.05,NORMINV(RAND(),$C$6,$D$6)) | L3: =MAX(0.02,NORMINV(RAND(),$C$7,$D$7)) | M3: =MIN(0.16,MAX(0.05,NORMINV(RAND(),$C$8,$D$8))) | N3: =MIN(24,MAX(5,NORMINV(RAND(),$C$9,$D$9))) | O3: =$I$8*(SUMPRODUCT(($I$2*(1+K3)^{1;2;3;4;5;6;7;8;9;10})*(($I$3+(L3-$I$3)*{1;2;3;4;5;6;7;8;9;10}/10)*(1-$I$7)+$I$4-$I$4*($I$5+(1.05-$I$5)*{1;2;3;4;5;6;7;8;9;10}/10)-(K3/(1+K3))*$I$6)/(1+M3)^{1;2;3;4;5;6;7;8;9;10})+$I$2*(1+K3)^10*(L3+$I$4)*N3/(1+M3)^10+$I$9-$I$10)/$I$11
A4: DRIVER DISTRIBUTIONS (yellow = edit; Opus-set defaults) | H4: da (D&A / revenue) | I4: 0.18286064 | K4: =MAX(-0.05,NORMINV(RAND(),$C$6,$D$6)) | L4: =MAX(0.02,NORMINV(RAND(),$C$7,$D$7)) | M4: =MIN(0.16,MAX(0.05,NORMINV(RAND(),$C$8,$D$8))) | N4: =MIN(24,MAX(5,NORMINV(RAND(),$C$9,$D$9))) | O4: =$I$8*(SUMPRODUCT(($I$2*(1+K4)^{1;2;3;4;5;6;7;8;9;10})*(($I$3+(L4-$I$3)*{1;2;3;4;5;6;7;8;9;10}/10)*(1-$I$7)+$I$4-$I$4*($I$5+(1.05-$I$5)*{1;2;3;4;5;6;7;8;9;10}/10)-(K4/(1+K4))*$I$6)/(1+M4)^{1;2;3;4;5;6;7;8;9;10})+$I$2*(1+K4)^10*(L4+$I$4)*N4/(1+M4)^10+$I$9-$I$10)/$I$11
A5: Driver | B5: Dist | C5: Mean | D5: Std dev | H5: cda0 (2026 capex/D&A) | I5: 1.9692971 | K5: =MAX(-0.05,NORMINV(RAND(),$C$6,$D$6)) | L5: =MAX(0.02,NORMINV(RAND(),$C$7,$D$7)) | M5: =MIN(0.16,MAX(0.05,NORMINV(RAND(),$C$8,$D$8))) | N5: =MIN(24,MAX(5,NORMINV(RAND(),$C$9,$D$9))) | O5: =$I$8*(SUMPRODUCT(($I$2*(1+K5)^{1;2;3;4;5;6;7;8;9;10})*(($I$3+(L5-$I$3)*{1;2;3;4;5;6;7;8;9;10}/10)*(1-$I$7)+$I$4-$I$4*($I$5+(1.05-$I$5)*{1;2;3;4;5;6;7;8;9;10}/10)-(K5/(1+K5))*$I$6)/(1+M5)^{1;2;3;4;5;6;7;8;9;10})+$I$2*(1+K5)^10*(L5+$I$4)*N5/(1+M5)^10+$I$9-$I$10)/$I$11
A6: Revenue 10y CAGR | B6: Normal | C6: =(Model!P6/Model!F6)^(1/10)-1 | D6: 0.03 | H6: nwc (% incr revenue) | I6: 0.005 | K6: =MAX(-0.05,NORMINV(RAND(),$C$6,$D$6)) | L6: =MAX(0.02,NORMINV(RAND(),$C$7,$D$7)) | M6: =MIN(0.16,MAX(0.05,NORMINV(RAND(),$C$8,$D$8))) | N6: =MIN(24,MAX(5,NORMINV(RAND(),$C$9,$D$9))) | O6: =$I$8*(SUMPRODUCT(($I$2*(1+K6)^{1;2;3;4;5;6;7;8;9;10})*(($I$3+(L6-$I$3)*{1;2;3;4;5;6;7;8;9;10}/10)*(1-$I$7)+$I$4-$I$4*($I$5+(1.05-$I$5)*{1;2;3;4;5;6;7;8;9;10}/10)-(K6/(1+K6))*$I$6)/(1+M6)^{1;2;3;4;5;6;7;8;9;10})+$I$2*(1+K6)^10*(L6+$I$4)*N6/(1+M6)^10+$I$9-$I$10)/$I$11
A7: Terminal operating margin | B7: Normal | C7: =Dashboard!$B$30 | D7: 0.015 | H7: tax | I7: =Valuation!$B$5 | K7: =MAX(-0.05,NORMINV(RAND(),$C$6,$D$6)) | L7: =MAX(0.02,NORMINV(RAND(),$C$7,$D$7)) | M7: =MIN(0.16,MAX(0.05,NORMINV(RAND(),$C$8,$D$8))) | N7: =MIN(24,MAX(5,NORMINV(RAND(),$C$9,$D$9))) | O7: =$I$8*(SUMPRODUCT(($I$2*(1+K7)^{1;2;3;4;5;6;7;8;9;10})*(($I$3+(L7-$I$3)*{1;2;3;4;5;6;7;8;9;10}/10)*(1-$I$7)+$I$4-$I$4*($I$5+(1.05-$I$5)*{1;2;3;4;5;6;7;8;9;10}/10)-(K7/(1+K7))*$I$6)/(1+M7)^{1;2;3;4;5;6;7;8;9;10})+$I$2*(1+K7)^10*(L7+$I$4)*N7/(1+M7)^10+$I$9-$I$10)/$I$11
A8: WACC | B8: Normal | C8: =WACC!B15 | D8: 0.005 | H8: k (calibration) | I8: 0.65090823 | K8: =MAX(-0.05,NORMINV(RAND(),$C$6,$D$6)) | L8: =MAX(0.02,NORMINV(RAND(),$C$7,$D$7)) | M8: =MIN(0.16,MAX(0.05,NORMINV(RAND(),$C$8,$D$8))) | N8: =MIN(24,MAX(5,NORMINV(RAND(),$C$9,$D$9))) | O8: =$I$8*(SUMPRODUCT(($I$2*(1+K8)^{1;2;3;4;5;6;7;8;9;10})*(($I$3+(L8-$I$3)*{1;2;3;4;5;6;7;8;9;10}/10)*(1-$I$7)+$I$4-$I$4*($I$5+(1.05-$I$5)*{1;2;3;4;5;6;7;8;9;10}/10)-(K8/(1+K8))*$I$6)/(1+M8)^{1;2;3;4;5;6;7;8;9;10})+$I$2*(1+K8)^10*(L8+$I$4)*N8/(1+M8)^10+$I$9-$I$10)/$I$11
A9: Exit EV/EBITDA multiple | B9: Normal | C9: =Dashboard!$B$45 | D9: 1.5 | H9: cash | I9: =Financials!AC19 | K9: =MAX(-0.05,NORMINV(RAND(),$C$6,$D$6)) | L9: =MAX(0.02,NORMINV(RAND(),$C$7,$D$7)) | M9: =MIN(0.16,MAX(0.05,NORMINV(RAND(),$C$8,$D$8))) | N9: =MIN(24,MAX(5,NORMINV(RAND(),$C$9,$D$9))) | O9: =$I$8*(SUMPRODUCT(($I$2*(1+K9)^{1;2;3;4;5;6;7;8;9;10})*(($I$3+(L9-$I$3)*{1;2;3;4;5;6;7;8;9;10}/10)*(1-$I$7)+$I$4-$I$4*($I$5+(1.05-$I$5)*{1;2;3;4;5;6;7;8;9;10}/10)-(K9/(1+K9))*$I$6)/(1+M9)^{1;2;3;4;5;6;7;8;9;10})+$I$2*(1+K9)^10*(L9+$I$4)*N9/(1+M9)^10+$I$9-$I$10)/$I$11
H10: debt | I10: =Financials!AC24 | K10: =MAX(-0.05,NORMINV(RAND(),$C$6,$D$6)) | L10: =MAX(0.02,NORMINV(RAND(),$C$7,$D$7)) | M10: =MIN(0.16,MAX(0.05,NORMINV(RAND(),$C$8,$D$8))) | N10: =MIN(24,MAX(5,NORMINV(RAND(),$C$9,$D$9))) | O10: =$I$8*(SUMPRODUCT(($I$2*(1+K10)^{1;2;3;4;5;6;7;8;9;10})*(($I$3+(L10-$I$3)*{1;2;3;4;5;6;7;8;9;10}/10)*(1-$I$7)+$I$4-$I$4*($I$5+(1.05-$I$5)*{1;2;3;4;5;6;7;8;9;10}/10)-(K10/(1+K10))*$I$6)/(1+M10)^{1;2;3;4;5;6;7;8;9;10})+$I$2*(1+K10)^10*(L10+$I$4)*N10/(1+M10)^10+$I$9-$I$10)/$I$11
A11: SIMULATION OUTPUT — value / share (live) | H11: shares | I11: =Financials!AC17 | K11: =MAX(-0.05,NORMINV(RAND(),$C$6,$D$6)) | L11: =MAX(0.02,NORMINV(RAND(),$C$7,$D$7)) | M11: =MIN(0.16,MAX(0.05,NORMINV(RAND(),$C$8,$D$8))) | N11: =MIN(24,MAX(5,NORMINV(RAND(),$C$9,$D$9))) | O11: =$I$8*(SUMPRODUCT(($I$2*(1+K11)^{1;2;3;4;5;6;7;8;9;10})*(($I$3+(L11-$I$3)*{1;2;3;4;5;6;7;8;9;10}/10)*(1-$I$7)+$I$4-$I$4*($I$5+(1.05-$I$5)*{1;2;3;4;5;6;7;8;9;10}/10)-(K11/(1+K11))*$I$6)/(1+M11)^{1;2;3;4;5;6;7;8;9;10})+$I$2*(1+K11)^10*(L11+$I$4)*N11/(1+M11)^10+$I$9-$I$10)/$I$11
A12: Mean | B12: =AVERAGE($O$2:$O$1001) | K12: =MAX(-0.05,NORMINV(RAND(),$C$6,$D$6)) | L12: =MAX(0.02,NORMINV(RAND(),$C$7,$D$7)) | M12: =MIN(0.16,MAX(0.05,NORMINV(RAND(),$C$8,$D$8))) | N12: =MIN(24,MAX(5,NORMINV(RAND(),$C$9,$D$9))) | O12: =$I$8*(SUMPRODUCT(($I$2*(1+K12)^{1;2;3;4;5;6;7;8;9;10})*(($I$3+(L12-$I$3)*{1;2;3;4;5;6;7;8;9;10}/10)*(1-$I$7)+$I$4-$I$4*($I$5+(1.05-$I$5)*{1;2;3;4;5;6;7;8;9;10}/10)-(K12/(1+K12))*$I$6)/(1+M12)^{1;2;3;4;5;6;7;8;9;10})+$I$2*(1+K12)^10*(L12+$I$4)*N12/(1+M12)^10+$I$9-$I$10)/$I$11
A13: Median (P50) | B13: =MEDIAN($O$2:$O$1001) | K13: =MAX(-0.05,NORMINV(RAND(),$C$6,$D$6)) | L13: =MAX(0.02,NORMINV(RAND(),$C$7,$D$7)) | M13: =MIN(0.16,MAX(0.05,NORMINV(RAND(),$C$8,$D$8))) | N13: =MIN(24,MAX(5,NORMINV(RAND(),$C$9,$D$9))) | O13: =$I$8*(SUMPRODUCT(($I$2*(1+K13)^{1;2;3;4;5;6;7;8;9;10})*(($I$3+(L13-$I$3)*{1;2;3;4;5;6;7;8;9;10}/10)*(1-$I$7)+$I$4-$I$4*($I$5+(1.05-$I$5)*{1;2;3;4;5;6;7;8;9;10}/10)-(K13/(1+K13))*$I$6)/(1+M13)^{1;2;3;4;5;6;7;8;9;10})+$I$2*(1+K13)^10*(L13+$I$4)*N13/(1+M13)^10+$I$9-$I$10)/$I$11
A14: Std dev | B14: =STDEV($O$2:$O$1001) | K14: =MAX(-0.05,NORMINV(RAND(),$C$6,$D$6)) | L14: =MAX(0.02,NORMINV(RAND(),$C$7,$D$7)) | M14: =MIN(0.16,MAX(0.05,NORMINV(RAND(),$C$8,$D$8))) | N14: =MIN(24,MAX(5,NORMINV(RAND(),$C$9,$D$9))) | O14: =$I$8*(SUMPRODUCT(($I$2*(1+K14)^{1;2;3;4;5;6;7;8;9;10})*(($I$3+(L14-$I$3)*{1;2;3;4;5;6;7;8;9;10}/10)*(1-$I$7)+$I$4-$I$4*($I$5+(1.05-$I$5)*{1;2;3;4;5;6;7;8;9;10}/10)-(K14/(1+K14))*$I$6)/(1+M14)^{1;2;3;4;5;6;7;8;9;10})+$I$2*(1+K14)^10*(L14+$I$4)*N14/(1+M14)^10+$I$9-$I$10)/$I$11
A15: Min | B15: =MIN($O$2:$O$1001) | K15: =MAX(-0.05,NORMINV(RAND(),$C$6,$D$6)) | L15: =MAX(0.02,NORMINV(RAND(),$C$7,$D$7)) | M15: =MIN(0.16,MAX(0.05,NORMINV(RAND(),$C$8,$D$8))) | N15: =MIN(24,MAX(5,NORMINV(RAND(),$C$9,$D$9))) | O15: =$I$8*(SUMPRODUCT(($I$2*(1+K15)^{1;2;3;4;5;6;7;8;9;10})*(($I$3+(L15-$I$3)*{1;2;3;4;5;6;7;8;9;10}/10)*(1-$I$7)+$I$4-$I$4*($I$5+(1.05-$I$5)*{1;2;3;4;5;6;7;8;9;10}/10)-(K15/(1+K15))*$I$6)/(1+M15)^{1;2;3;4;5;6;7;8;9;10})+$I$2*(1+K15)^10*(L15+$I$4)*N15/(1+M15)^10+$I$9-$I$10)/$I$11
A16: Max | B16: =MAX($O$2:$O$1001) | K16: =MAX(-0.05,NORMINV(RAND(),$C$6,$D$6)) | L16: =MAX(0.02,NORMINV(RAND(),$C$7,$D$7)) | M16: =MIN(0.16,MAX(0.05,NORMINV(RAND(),$C$8,$D$8))) | N16: =MIN(24,MAX(5,NORMINV(RAND(),$C$9,$D$9))) | O16: =$I$8*(SUMPRODUCT(($I$2*(1+K16)^{1;2;3;4;5;6;7;8;9;10})*(($I$3+(L16-$I$3)*{1;2;3;4;5;6;7;8;9;10}/10)*(1-$I$7)+$I$4-$I$4*($I$5+(1.05-$I$5)*{1;2;3;4;5;6;7;8;9;10}/10)-(K16/(1+K16))*$I$6)/(1+M16)^{1;2;3;4;5;6;7;8;9;10})+$I$2*(1+K16)^10*(L16+$I$4)*N16/(1+M16)^10+$I$9-$I$10)/$I$11
A17: Current price | B17: =Valuation!$B$2 | K17: =MAX(-0.05,NORMINV(RAND(),$C$6,$D$6)) | L17: =MAX(0.02,NORMINV(RAND(),$C$7,$D$7)) | M17: =MIN(0.16,MAX(0.05,NORMINV(RAND(),$C$8,$D$8))) | N17: =MIN(24,MAX(5,NORMINV(RAND(),$C$9,$D$9))) | O17: =$I$8*(SUMPRODUCT(($I$2*(1+K17)^{1;2;3;4;5;6;7;8;9;10})*(($I$3+(L17-$I$3)*{1;2;3;4;5;6;7;8;9;10}/10)*(1-$I$7)+$I$4-$I$4*($I$5+(1.05-$I$5)*{1;2;3;4;5;6;7;8;9;10}/10)-(K17/(1+K17))*$I$6)/(1+M17)^{1;2;3;4;5;6;7;8;9;10})+$I$2*(1+K17)^10*(L17+$I$4)*N17/(1+M17)^10+$I$9-$I$10)/$I$11
A18: Base case (full model) | B18: =Valuation!B36 | K18: =MAX(-0.05,NORMINV(RAND(),$C$6,$D$6)) | L18: =MAX(0.02,NORMINV(RAND(),$C$7,$D$7)) | M18: =MIN(0.16,MAX(0.05,NORMINV(RAND(),$C$8,$D$8))) | N18: =MIN(24,MAX(5,NORMINV(RAND(),$C$9,$D$9))) | O18: =$I$8*(SUMPRODUCT(($I$2*(1+K18)^{1;2;3;4;5;6;7;8;9;10})*(($I$3+(L18-$I$3)*{1;2;3;4;5;6;7;8;9;10}/10)*(1-$I$7)+$I$4-$I$4*($I$5+(1.05-$I$5)*{1;2;3;4;5;6;7;8;9;10}/10)-(K18/(1+K18))*$I$6)/(1+M18)^{1;2;3;4;5;6;7;8;9;10})+$I$2*(1+K18)^10*(L18+$I$4)*N18/(1+M18)^10+$I$9-$I$10)/$I$11
K19: =MAX(-0.05,NORMINV(RAND(),$C$6,$D$6)) | L19: =MAX(0.02,NORMINV(RAND(),$C$7,$D$7)) | M19: =MIN(0.16,MAX(0.05,NORMINV(RAND(),$C$8,$D$8))) | N19: =MIN(24,MAX(5,NORMINV(RAND(),$C$9,$D$9))) | O19: =$I$8*(SUMPRODUCT(($I$2*(1+K19)^{1;2;3;4;5;6;7;8;9;10})*(($I$3+(L19-$I$3)*{1;2;3;4;5;6;7;8;9;10}/10)*(1-$I$7)+$I$4-$I$4*($I$5+(1.05-$I$5)*{1;2;3;4;5;6;7;8;9;10}/10)-(K19/(1+K19))*$I$6)/(1+M19)^{1;2;3;4;5;6;7;8;9;10})+$I$2*(1+K19)^10*(L19+$I$4)*N19/(1+M19)^10+$I$9-$I$10)/$I$11
A20: P(undervalued at current price) | B20: =COUNTIF($O$2:$O$1001,">"&Valuation!$B$2)/1000 | K20: =MAX(-0.05,NORMINV(RAND(),$C$6,$D$6)) | L20: =MAX(0.02,NORMINV(RAND(),$C$7,$D$7)) | M20: =MIN(0.16,MAX(0.05,NORMINV(RAND(),$C$8,$D$8))) | N20: =MIN(24,MAX(5,NORMINV(RAND(),$C$9,$D$9))) | O20: =$I$8*(SUMPRODUCT(($I$2*(1+K20)^{1;2;3;4;5;6;7;8;9;10})*(($I$3+(L20-$I$3)*{1;2;3;4;5;6;7;8;9;10}/10)*(1-$I$7)+$I$4-$I$4*($I$5+(1.05-$I$5)*{1;2;3;4;5;6;7;8;9;10}/10)-(K20/(1+K20))*$I$6)/(1+M20)^{1;2;3;4;5;6;7;8;9;10})+$I$2*(1+K20)^10*(L20+$I$4)*N20/(1+M20)^10+$I$9-$I$10)/$I$11
A21: P(>20% upside) | B21: =COUNTIF($O$2:$O$1001,">"&Valuation!$B$2*1.2)/1000 | K21: =MAX(-0.05,NORMINV(RAND(),$C$6,$D$6)) | L21: =MAX(0.02,NORMINV(RAND(),$C$7,$D$7)) | M21: =MIN(0.16,MAX(0.05,NORMINV(RAND(),$C$8,$D$8))) | N21: =MIN(24,MAX(5,NORMINV(RAND(),$C$9,$D$9))) | O21: =$I$8*(SUMPRODUCT(($I$2*(1+K21)^{1;2;3;4;5;6;7;8;9;10})*(($I$3+(L21-$I$3)*{1;2;3;4;5;6;7;8;9;10}/10)*(1-$I$7)+$I$4-$I$4*($I$5+(1.05-$I$5)*{1;2;3;4;5;6;7;8;9;10}/10)-(K21/(1+K21))*$I$6)/(1+M21)^{1;2;3;4;5;6;7;8;9;10})+$I$2*(1+K21)^10*(L21+$I$4)*N21/(1+M21)^10+$I$9-$I$10)/$I$11
K22: =MAX(-0.05,NORMINV(RAND(),$C$6,$D$6)) | L22: =MAX(0.02,NORMINV(RAND(),$C$7,$D$7)) | M22: =MIN(0.16,MAX(0.05,NORMINV(RAND(),$C$8,$D$8))) | N22: =MIN(24,MAX(5,NORMINV(RAND(),$C$9,$D$9))) | O22: =$I$8*(SUMPRODUCT(($I$2*(1+K22)^{1;2;3;4;5;6;7;8;9;10})*(($I$3+(L22-$I$3)*{1;2;3;4;5;6;7;8;9;10}/10)*(1-$I$7)+$I$4-$I$4*($I$5+(1.05-$I$5)*{1;2;3;4;5;6;7;8;9;10}/10)-(K22/(1+K22))*$I$6)/(1+M22)^{1;2;3;4;5;6;7;8;9;10})+$I$2*(1+K22)^10*(L22+$I$4)*N22/(1+M22)^10+$I$9-$I$10)/$I$11
A23: PERCENTILES (live) | K23: =MAX(-0.05,NORMINV(RAND(),$C$6,$D$6)) | L23: =MAX(0.02,NORMINV(RAND(),$C$7,$D$7)) | M23: =MIN(0.16,MAX(0.05,NORMINV(RAND(),$C$8,$D$8))) | N23: =MIN(24,MAX(5,NORMINV(RAND(),$C$9,$D$9))) | O23: =$I$8*(SUMPRODUCT(($I$2*(1+K23)^{1;2;3;4;5;6;7;8;9;10})*(($I$3+(L23-$I$3)*{1;2;3;4;5;6;7;8;9;10}/10)*(1-$I$7)+$I$4-$I$4*($I$5+(1.05-$I$5)*{1;2;3;4;5;6;7;8;9;10}/10)-(K23/(1+K23))*$I$6)/(1+M23)^{1;2;3;4;5;6;7;8;9;10})+$I$2*(1+K23)^10*(L23+$I$4)*N23/(1+M23)^10+$I$9-$I$10)/$I$11
A24: P5 | B24: =PERCENTILE($O$2:$O$1001,0.05) | K24: =MAX(-0.05,NORMINV(RAND(),$C$6,$D$6)) | L24: =MAX(0.02,NORMINV(RAND(),$C$7,$D$7)) | M24: =MIN(0.16,MAX(0.05,NORMINV(RAND(),$C$8,$D$8))) | N24: =MIN(24,MAX(5,NORMINV(RAND(),$C$9,$D$9))) | O24: =$I$8*(SUMPRODUCT(($I$2*(1+K24)^{1;2;3;4;5;6;7;8;9;10})*(($I$3+(L24-$I$3)*{1;2;3;4;5;6;7;8;9;10}/10)*(1-$I$7)+$I$4-$I$4*($I$5+(1.05-$I$5)*{1;2;3;4;5;6;7;8;9;10}/10)-(K24/(1+K24))*$I$6)/(1+M24)^{1;2;3;4;5;6;7;8;9;10})+$I$2*(1+K24)^10*(L24+$I$4)*N24/(1+M24)^10+$I$9-$I$10)/$I$11
A25: P10 | B25: =PERCENTILE($O$2:$O$1001,0.1) | K25: =MAX(-0.05,NORMINV(RAND(),$C$6,$D$6)) | L25: =MAX(0.02,NORMINV(RAND(),$C$7,$D$7)) | M25: =MIN(0.16,MAX(0.05,NORMINV(RAND(),$C$8,$D$8))) | N25: =MIN(24,MAX(5,NORMINV(RAND(),$C$9,$D$9))) | O25: =$I$8*(SUMPRODUCT(($I$2*(1+K25)^{1;2;3;4;5;6;7;8;9;10})*(($I$3+(L25-$I$3)*{1;2;3;4;5;6;7;8;9;10}/10)*(1-$I$7)+$I$4-$I$4*($I$5+(1.05-$I$5)*{1;2;3;4;5;6;7;8;9;10}/10)-(K25/(1+K25))*$I$6)/(1+M25)^{1;2;3;4;5;6;7;8;9;10})+$I$2*(1+K25)^10*(L25+$I$4)*N25/(1+M25)^10+$I$9-$I$10)/$I$11
A26: P25 | B26: =PERCENTILE($O$2:$O$1001,0.25) | K26: =MAX(-0.05,NORMINV(RAND(),$C$6,$D$6)) | L26: =MAX(0.02,NORMINV(RAND(),$C$7,$D$7)) | M26: =MIN(0.16,MAX(0.05,NORMINV(RAND(),$C$8,$D$8))) | N26: =MIN(24,MAX(5,NORMINV(RAND(),$C$9,$D$9))) | O26: =$I$8*(SUMPRODUCT(($I$2*(1+K26)^{1;2;3;4;5;6;7;8;9;10})*(($I$3+(L26-$I$3)*{1;2;3;4;5;6;7;8;9;10}/10)*(1-$I$7)+$I$4-$I$4*($I$5+(1.05-$I$5)*{1;2;3;4;5;6;7;8;9;10}/10)-(K26/(1+K26))*$I$6)/(1+M26)^{1;2;3;4;5;6;7;8;9;10})+$I$2*(1+K26)^10*(L26+$I$4)*N26/(1+M26)^10+$I$9-$I$10)/$I$11
A27: P50 | B27: =PERCENTILE($O$2:$O$1001,0.5) | K27: =MAX(-0.05,NORMINV(RAND(),$C$6,$D$6)) | L27: =MAX(0.02,NORMINV(RAND(),$C$7,$D$7)) | M27: =MIN(0.16,MAX(0.05,NORMINV(RAND(),$C$8,$D$8))) | N27: =MIN(24,MAX(5,NORMINV(RAND(),$C$9,$D$9))) | O27: =$I$8*(SUMPRODUCT(($I$2*(1+K27)^{1;2;3;4;5;6;7;8;9;10})*(($I$3+(L27-$I$3)*{1;2;3;4;5;6;7;8;9;10}/10)*(1-$I$7)+$I$4-$I$4*($I$5+(1.05-$I$5)*{1;2;3;4;5;6;7;8;9;10}/10)-(K27/(1+K27))*$I$6)/(1+M27)^{1;2;3;4;5;6;7;8;9;10})+$I$2*(1+K27)^10*(L27+$I$4)*N27/(1+M27)^10+$I$9-$I$10)/$I$11
A28: P75 | B28: =PERCENTILE($O$2:$O$1001,0.75) | K28: =MAX(-0.05,NORMINV(RAND(),$C$6,$D$6)) | L28: =MAX(0.02,NORMINV(RAND(),$C$7,$D$7)) | M28: =MIN(0.16,MAX(0.05,NORMINV(RAND(),$C$8,$D$8))) | N28: =MIN(24,MAX(5,NORMINV(RAND(),$C$9,$D$9))) | O28: =$I$8*(SUMPRODUCT(($I$2*(1+K28)^{1;2;3;4;5;6;7;8;9;10})*(($I$3+(L28-$I$3)*{1;2;3;4;5;6;7;8;9;10}/10)*(1-$I$7)+$I$4-$I$4*($I$5+(1.05-$I$5)*{1;2;3;4;5;6;7;8;9;10}/10)-(K28/(1+K28))*$I$6)/(1+M28)^{1;2;3;4;5;6;7;8;9;10})+$I$2*(1+K28)^10*(L28+$I$4)*N28/(1+M28)^10+$I$9-$I$10)/$I$11
A29: P90 | B29: =PERCENTILE($O$2:$O$1001,0.9) | K29: =MAX(-0.05,NORMINV(RAND(),$C$6,$D$6)) | L29: =MAX(0.02,NORMINV(RAND(),$C$7,$D$7)) | M29: =MIN(0.16,MAX(0.05,NORMINV(RAND(),$C$8,$D$8))) | N29: =MIN(24,MAX(5,NORMINV(RAND(),$C$9,$D$9))) | O29: =$I$8*(SUMPRODUCT(($I$2*(1+K29)^{1;2;3;4;5;6;7;8;9;10})*(($I$3+(L29-$I$3)*{1;2;3;4;5;6;7;8;9;10}/10)*(1-$I$7)+$I$4-$I$4*($I$5+(1.05-$I$5)*{1;2;3;4;5;6;7;8;9;10}/10)-(K29/(1+K29))*$I$6)/(1+M29)^{1;2;3;4;5;6;7;8;9;10})+$I$2*(1+K29)^10*(L29+$I$4)*N29/(1+M29)^10+$I$9-$I$10)/$I$11
A30: P95 | B30: =PERCENTILE($O$2:$O$1001,0.95) | K30: =MAX(-0.05,NORMINV(RAND(),$C$6,$D$6)) | L30: =MAX(0.02,NORMINV(RAND(),$C$7,$D$7)) | M30: =MIN(0.16,MAX(0.05,NORMINV(RAND(),$C$8,$D$8))) | N30: =MIN(24,MAX(5,NORMINV(RAND(),$C$9,$D$9))) | O30: =$I$8*(SUMPRODUCT(($I$2*(1+K30)^{1;2;3;4;5;6;7;8;9;10})*(($I$3+(L30-$I$3)*{1;2;3;4;5;6;7;8;9;10}/10)*(1-$I$7)+$I$4-$I$4*($I$5+(1.05-$I$5)*{1;2;3;4;5;6;7;8;9;10}/10)-(K30/(1+K30))*$I$6)/(1+M30)^{1;2;3;4;5;6;7;8;9;10})+$I$2*(1+K30)^10*(L30+$I$4)*N30/(1+M30)^10+$I$9-$I$10)/$I$11
K31: =MAX(-0.05,NORMINV(RAND(),$C$6,$D$6)) | L31: =MAX(0.02,NORMINV(RAND(),$C$7,$D$7)) | M31: =MIN(0.16,MAX(0.05,NORMINV(RAND(),$C$8,$D$8))) | N31: =MIN(24,MAX(5,NORMINV(RAND(),$C$9,$D$9))) | O31: =$I$8*(SUMPRODUCT(($I$2*(1+K31)^{1;2;3;4;5;6;7;8;9;10})*(($I$3+(L31-$I$3)*{1;2;3;4;5;6;7;8;9;10}/10)*(1-$I$7)+$I$4-$I$4*($I$5+(1.05-$I$5)*{1;2;3;4;5;6;7;8;9;10}/10)-(K31/(1+K31))*$I$6)/(1+M31)^{1;2;3;4;5;6;7;8;9;10})+$I$2*(1+K31)^10*(L31+$I$4)*N31/(1+M31)^10+$I$9-$I$10)/$I$11
A32: VALUE DISTRIBUTION (live histogram) | K32: =MAX(-0.05,NORMINV(RAND(),$C$6,$D$6)) | L32: =MAX(0.02,NORMINV(RAND(),$C$7,$D$7)) | M32: =MIN(0.16,MAX(0.05,NORMINV(RAND(),$C$8,$D$8))) | N32: =MIN(24,MAX(5,NORMINV(RAND(),$C$9,$D$9))) | O32: =$I$8*(SUMPRODUCT(($I$2*(1+K32)^{1;2;3;4;5;6;7;8;9;10})*(($I$3+(L32-$I$3)*{1;2;3;4;5;6;7;8;9;10}/10)*(1-$I$7)+$I$4-$I$4*($I$5+(1.05-$I$5)*{1;2;3;4;5;6;7;8;9;10}/10)-(K32/(1+K32))*$I$6)/(1+M32)^{1;2;3;4;5;6;7;8;9;10})+$I$2*(1+K32)^10*(L32+$I$4)*N32/(1+M32)^10+$I$9-$I$10)/$I$11
A33: Bin midpoint ($/sh) | B33: Count | K33: =MAX(-0.05,NORMINV(RAND(),$C$6,$D$6)) | L33: =MAX(0.02,NORMINV(RAND(),$C$7,$D$7)) | M33: =MIN(0.16,MAX(0.05,NORMINV(RAND(),$C$8,$D$8))) | N33: =MIN(24,MAX(5,NORMINV(RAND(),$C$9,$D$9))) | O33: =$I$8*(SUMPRODUCT(($I$2*(1+K33)^{1;2;3;4;5;6;7;8;9;10})*(($I$3+(L33-$I$3)*{1;2;3;4;5;6;7;8;9;10}/10)*(1-$I$7)+$I$4-$I$4*($I$5+(1.05-$I$5)*{1;2;3;4;5;6;7;8;9;10}/10)-(K33/(1+K33))*$I$6)/(1+M33)^{1;2;3;4;5;6;7;8;9;10})+$I$2*(1+K33)^10*(L33+$I$4)*N33/(1+M33)^10+$I$9-$I$10)/$I$11
A34: =$B$15+0.5*($B$16-$B$15)/15 | B34: =COUNTIFS($O$2:$O$1001,">="&($B$15+0*($B$16-$B$15)/15),$O$2:$O$1001,"<"&($B$15+1*($B$16-$B$15)/15)) | K34: =MAX(-0.05,NORMINV(RAND(),$C$6,$D$6)) | L34: =MAX(0.02,NORMINV(RAND(),$C$7,$D$7)) | M34: =MIN(0.16,MAX(0.05,NORMINV(RAND(),$C$8,$D$8))) | N34: =MIN(24,MAX(5,NORMINV(RAND(),$C$9,$D$9))) | O34: =$I$8*(SUMPRODUCT(($I$2*(1+K34)^{1;2;3;4;5;6;7;8;9;10})*(($I$3+(L34-$I$3)*{1;2;3;4;5;6;7;8;9;10}/10)*(1-$I$7)+$I$4-$I$4*($I$5+(1.05-$I$5)*{1;2;3;4;5;6;7;8;9;10}/10)-(K34/(1+K34))*$I$6)/(1+M34)^{1;2;3;4;5;6;7;8;9;10})+$I$2*(1+K34)^10*(L34+$I$4)*N34/(1+M34)^10+$I$9-$I$10)/$I$11
A35: =$B$15+1.5*($B$16-$B$15)/15 | B35: =COUNTIFS($O$2:$O$1001,">="&($B$15+1*($B$16-$B$15)/15),$O$2:$O$1001,"<"&($B$15+2*($B$16-$B$15)/15)) | K35: =MAX(-0.05,NORMINV(RAND(),$C$6,$D$6)) | L35: =MAX(0.02,NORMINV(RAND(),$C$7,$D$7)) | M35: =MIN(0.16,MAX(0.05,NORMINV(RAND(),$C$8,$D$8))) | N35: =MIN(24,MAX(5,NORMINV(RAND(),$C$9,$D$9))) | O35: =$I$8*(SUMPRODUCT(($I$2*(1+K35)^{1;2;3;4;5;6;7;8;9;10})*(($I$3+(L35-$I$3)*{1;2;3;4;5;6;7;8;9;10}/10)*(1-$I$7)+$I$4-$I$4*($I$5+(1.05-$I$5)*{1;2;3;4;5;6;7;8;9;10}/10)-(K35/(1+K35))*$I$6)/(1+M35)^{1;2;3;4;5;6;7;8;9;10})+$I$2*(1+K35)^10*(L35+$I$4)*N35/(1+M35)^10+$I$9-$I$10)/$I$11
A36: =$B$15+2.5*($B$16-$B$15)/15 | B36: =COUNTIFS($O$2:$O$1001,">="&($B$15+2*($B$16-$B$15)/15),$O$2:$O$1001,"<"&($B$15+3*($B$16-$B$15)/15)) | K36: =MAX(-0.05,NORMINV(RAND(),$C$6,$D$6)) | L36: =MAX(0.02,NORMINV(RAND(),$C$7,$D$7)) | M36: =MIN(0.16,MAX(0.05,NORMINV(RAND(),$C$8,$D$8))) | N36: =MIN(24,MAX(5,NORMINV(RAND(),$C$9,$D$9))) | O36: =$I$8*(SUMPRODUCT(($I$2*(1+K36)^{1;2;3;4;5;6;7;8;9;10})*(($I$3+(L36-$I$3)*{1;2;3;4;5;6;7;8;9;10}/10)*(1-$I$7)+$I$4-$I$4*($I$5+(1.05-$I$5)*{1;2;3;4;5;6;7;8;9;10}/10)-(K36/(1+K36))*$I$6)/(1+M36)^{1;2;3;4;5;6;7;8;9;10})+$I$2*(1+K36)^10*(L36+$I$4)*N36/(1+M36)^10+$I$9-$I$10)/$I$11
A37: =$B$15+3.5*($B$16-$B$15)/15 | B37: =COUNTIFS($O$2:$O$1001,">="&($B$15+3*($B$16-$B$15)/15),$O$2:$O$1001,"<"&($B$15+4*($B$16-$B$15)/15)) | K37: =MAX(-0.05,NORMINV(RAND(),$C$6,$D$6)) | L37: =MAX(0.02,NORMINV(RAND(),$C$7,$D$7)) | M37: =MIN(0.16,MAX(0.05,NORMINV(RAND(),$C$8,$D$8))) | N37: =MIN(24,MAX(5,NORMINV(RAND(),$C$9,$D$9))) | O37: =$I$8*(SUMPRODUCT(($I$2*(1+K37)^{1;2;3;4;5;6;7;8;9;10})*(($I$3+(L37-$I$3)*{1;2;3;4;5;6;7;8;9;10}/10)*(1-$I$7)+$I$4-$I$4*($I$5+(1.05-$I$5)*{1;2;3;4;5;6;7;8;9;10}/10)-(K37/(1+K37))*$I$6)/(1+M37)^{1;2;3;4;5;6;7;8;9;10})+$I$2*(1+K37)^10*(L37+$I$4)*N37/(1+M37)^10+$I$9-$I$10)/$I$11
A38: =$B$15+4.5*($B$16-$B$15)/15 | B38: =COUNTIFS($O$2:$O$1001,">="&($B$15+4*($B$16-$B$15)/15),$O$2:$O$1001,"<"&($B$15+5*($B$16-$B$15)/15)) | K38: =MAX(-0.05,NORMINV(RAND(),$C$6,$D$6)) | L38: =MAX(0.02,NORMINV(RAND(),$C$7,$D$7)) | M38: =MIN(0.16,MAX(0.05,NORMINV(RAND(),$C$8,$D$8))) | N38: =MIN(24,MAX(5,NORMINV(RAND(),$C$9,$D$9))) | O38: =$I$8*(SUMPRODUCT(($I$2*(1+K38)^{1;2;3;4;5;6;7;8;9;10})*(($I$3+(L38-$I$3)*{1;2;3;4;5;6;7;8;9;10}/10)*(1-$I$7)+$I$4-$I$4*($I$5+(1.05-$I$5)*{1;2;3;4;5;6;7;8;9;10}/10)-(K38/(1+K38))*$I$6)/(1+M38)^{1;2;3;4;5;6;7;8;9;10})+$I$2*(1+K38)^10*(L38+$I$4)*N38/(1+M38)^10+$I$9-$I$10)/$I$11
A39: =$B$15+5.5*($B$16-$B$15)/15 | B39: =COUNTIFS($O$2:$O$1001,">="&($B$15+5*($B$16-$B$15)/15),$O$2:$O$1001,"<"&($B$15+6*($B$16-$B$15)/15)) | K39: =MAX(-0.05,NORMINV(RAND(),$C$6,$D$6)) | L39: =MAX(0.02,NORMINV(RAND(),$C$7,$D$7)) | M39: =MIN(0.16,MAX(0.05,NORMINV(RAND(),$C$8,$D$8))) | N39: =MIN(24,MAX(5,NORMINV(RAND(),$C$9,$D$9))) | O39: =$I$8*(SUMPRODUCT(($I$2*(1+K39)^{1;2;3;4;5;6;7;8;9;10})*(($I$3+(L39-$I$3)*{1;2;3;4;5;6;7;8;9;10}/10)*(1-$I$7)+$I$4-$I$4*($I$5+(1.05-$I$5)*{1;2;3;4;5;6;7;8;9;10}/10)-(K39/(1+K39))*$I$6)/(1+M39)^{1;2;3;4;5;6;7;8;9;10})+$I$2*(1+K39)^10*(L39+$I$4)*N39/(1+M39)^10+$I$9-$I$10)/$I$11
A40: =$B$15+6.5*($B$16-$B$15)/15 | B40: =COUNTIFS($O$2:$O$1001,">="&($B$15+6*($B$16-$B$15)/15),$O$2:$O$1001,"<"&($B$15+7*($B$16-$B$15)/15)) | K40: =MAX(-0.05,NORMINV(RAND(),$C$6,$D$6)) | L40: =MAX(0.02,NORMINV(RAND(),$C$7,$D$7)) | M40: =MIN(0.16,MAX(0.05,NORMINV(RAND(),$C$8,$D$8))) | N40: =MIN(24,MAX(5,NORMINV(RAND(),$C$9,$D$9))) | O40: =$I$8*(SUMPRODUCT(($I$2*(1+K40)^{1;2;3;4;5;6;7;8;9;10})*(($I$3+(L40-$I$3)*{1;2;3;4;5;6;7;8;9;10}/10)*(1-$I$7)+$I$4-$I$4*($I$5+(1.05-$I$5)*{1;2;3;4;5;6;7;8;9;10}/10)-(K40/(1+K40))*$I$6)/(1+M40)^{1;2;3;4;5;6;7;8;9;10})+$I$2*(1+K40)^10*(L40+$I$4)*N40/(1+M40)^10+$I$9-$I$10)/$I$11
...
