Workbook
Name a: #REF!
Name A283.: Daloopa!$A$587
Name EC_Pub_New: #REF!
Name EC_Pub_QTR: #REF!
Name EC_Pub_QTR_CV: #REF!
Name IQ_CH: 110000
Name IQ_CQ: 5000
Name IQ_CY: 10000
Name IQ_DAILY: 500000
Name IQ_FH: 100000
Name IQ_FQ: 500
Name IQ_FY: 1000
Name IQ_LTM: 2000
Name IQ_MONTH: 15000
Name IQ_NTM: 6000
Name IQ_WEEK: 50000
Name IQ_YTD: 3000

Sheet How to Use 
A1: Instructions
A2: Tab | B2: Details
A3: Color Code | B3: Just familiarize yourself with the color code conventions used in this file. I will maintain these color code conventions in every model.
A4: Model | B4: The most important worksheet in this file is the "Model" Worksheet.
B5: If you want to change the assumptions, just change the cells that are filled yellow. Since the rest of the cells are formula driven, they will automatically be changed.
B6: I have made a few comments here and there whenever I thought it might be helpful for subscribers
B7: Please let me know asap if you think there has been any error/mistake (conceptual or otherwise) in the model
A9: Financials | B9: All three statements are in this worksheet. Balance sheet and cash flow related assumptions are mostly on this worksheet.
A10: Valuation | B10: Just change the current stock price and choose your multiple to run your valuation estimates.
A11: Daloopa | B11: database from company filings. Feel free to sign up for this by clicking below link (not a paid promotion; I don't get paid if you do so but I do get complimentary access to it)
B12: https://daloopa.com/?utm_source=MBI&utm_medium=Organic&utm_campaign=SourceLink
A13: E-commerce data | B13: Worksheet copied from US census Bureau which was used in "Model" worksheet.

Sheet Color Code
A1: Color | B1: Meaning
A2: Black | B2: Formula driven (both historical and forecasts)
A3: Blue | B3: Hard coded numbers (Actual for Historical, estimated for forecasts)
A4: Yellow | B4: Indication that there has been explicit assumption made in these cells. Change the numbers in these cells to drive your narrative.

Sheet Model
B1: 2015 | C1: 2016 | D1: 2017 | E1: 2018 | F1: 2019 | G1: 2020 | H1: 2021 | I1: 2022 | J1: 2023 | K1: 2024 | L1: 2025 | M1: 2026 | N1: 2027 | O1: 2028 | P1: 2029 | Q1: 2030
A2: US e-commerce (Bn) | D2: 461.034 | E2: 498.363 | F2: 561.727 | G2: 798.487 | H2: 936.592 | I2: 997.477 | J2: 1087.017 | K2: 1170.03 | L2: =L6*L4 -> 1261.2506 | M2: =M6*M4 -> 1356.8914 | N2: =N6*N4 -> 1457.1356 | O2: =O6*O4 -> 1562.1732 | P2: =P6*P4 -> 1672.2016 | Q2: =Q6*Q4 -> 1787.4258
A3: Growth | E3: =E2/D2-1 -> 0.080967998 | F3: =F2/E2-1 -> 0.12714427 | G3: =G2/F2-1 -> 0.42148588 | H3: =H2/G2-1 -> 0.17295836 | I3: =I2/H2-1 -> 0.065006961 | J3: =J2/I2-1 -> 0.089766481 | K3: =K2/J2-1 -> 0.076367711 | L3: =L2/K2-1 -> 0.077964338 | ... Q3: =Q2/P2-1 -> 0.068905674
A4: US Retail Sales (Bn) | D4: 5046.021 | E4: 5161.163 | F4: 5307.334 | G4: 5467.268 | H4: 6399.684 | I4: 6916.099 | J4: 7073.37 | K4: 7264.688 | L4: =K4*(1+L5) -> 7482.6286 | M4: =L4*(1+M5) -> 7707.1075 | N4: =M4*(1+N5) -> 7938.3207 | O4: =N4*(1+O5) -> 8176.4703 | P4: =O4*(1+P5) -> 8421.7645 | Q4: =P4*(1+Q5) -> 8674.4174
A5: Growth | E5: =E4/D4-1 -> 0.022818375 | F5: =F4/E4-1 -> 0.02832133 | G5: =G4/F4-1 -> 0.030134527 | H5: =H4/G4-1 -> 0.17054514 | I5: =I4/H4-1 -> 0.080693828 | J5: =J4/I4-1 -> 0.022739842 | K5: =K4/J4-1 -> 0.027047645 | L5: 0.03 | M5: 0.03 | N5: 0.03 | O5: 0.03 | P5: 0.03 | Q5: 0.03
A6: Penetration | D6: =D2/D4 -> 0.09136585 | E6: =E2/E4 -> 0.096560213 | F6: =F2/F4 -> 0.10583977 | G6: =G2/G4 -> 0.14604863 | H6: =H2/H4 -> 0.14634973 | I6: =I2/I4 -> 0.14422538 | J6: =J2/J4 -> 0.15367738 | K6: =K2/K4 -> 0.16105716 | L6: =K6+L7/10000 -> 0.16855716 | M6: =L6+M7/10000 -> 0.17605716 | N6: =M6+N7/10000 -> 0.18355716 | O6: =N6+O7/10000 -> 0.19105716 | P6: =O6+P7/10000 -> 0.19855716 | Q6: =P6+Q7/10000 -> 0.20605716
A7: Increase | E7: =(E6-D6)*10000 -> 51.943628 | F7: =(F6-E6)*10000 -> 92.795549 | G7: =(G6-F6)*10000 -> 402.08862 | H7: =(H6-G6)*10000 -> 3.0109625 | I7: =(I6-H6)*10000 -> -21.243469 | J7: =(J6-I6)*10000 -> 94.520053 | K7: =(K6-J6)*10000 -> 73.797733 | L7: 75 | M7: 75 | N7: 75 | O7: 75 | P7: 75 | Q7: 75
A9: Online Stores | C9: =Financials!B9 -> 91431 | D9: =Financials!C9 -> 108354 | E9: =Financials!D9 -> 122987 | F9: =Financials!E9 -> 141247 | G9: =Financials!F9 -> 197346 | H9: =Financials!G9 -> 222075 | I9: =Financials!H9 -> 220004 | J9: =Financials!I9 -> 231872 | ... L9: =Financials!K9 -> 269287 | M9: =L9*(1+M11) -> 290829.96 | N9: =M9*(1+N11) -> 314096.36 | O9: =N9*(1+O11) -> 339224.07 | P9: =O9*(1+P11) -> 364665.87 | Q9: =P9*(1+Q11) -> 390192.48
A10: Growth $ | E10: =E9-D9 -> 14633 | F10: =F9-E9 -> 18260 | G10: =G9-F9 -> 56099 | H10: =H9-G9 -> 24729 | I10: =I9-H9 -> -2071 | J10: =J9-I9 -> 11868 | K10: =K9-J9 -> 15157 | L10: =L9-K9 -> 22258 | ... Q10: =Q9-P9 -> 25526.611
A11: Growth % | E11: =E9/D9-1 -> 0.13504808 | F11: =F9/E9-1 -> 0.14847098 | G11: =G9/F9-1 -> 0.3971695 | H11: =H9/G9-1 -> 0.12530783 | I11: =I9/H9-1 -> -0.0093256783 | J11: =J9/I9-1 -> 0.053944474 | K11: =K9/J9-1 -> 0.065367962 | L11: =L9/K9-1 -> 0.090102781 | M11: 0.08 | N11: 0.08 | O11: 0.08 | P11: 0.075 | Q11: 0.07
A13: 3P Seller Services | C13: =Financials!B17 -> 22993 | D13: =Financials!C17 -> 31881 | E13: =Financials!D17 -> 42745 | F13: =Financials!E17 -> 53762 | G13: =Financials!F17 -> 80461 | H13: =Financials!G17 -> 103366 | I13: =Financials!H17 -> 117716 | J13: =Financials!I17 -> 140053 | ... L13: =Financials!K17 -> 172162 | M13: =M17*M18 -> 186783.86 | N13: =N17*N18 -> 202113.47 | O13: =O17*O18 -> 218173.4 | P13: =P17*P18 -> 235520.22 | Q13: =Q17*Q18 -> 254299.08
A14: =A10 -> Growth $ | E14: =E13-D13 -> 10864 | F14: =F13-E13 -> 11017 | G14: =G13-F13 -> 26699 | H14: =H13-G13 -> 22905 | I14: =I13-H13 -> 14350 | J14: =J13-I13 -> 22337 | K14: =K13-J13 -> 16093 | L14: =L13-K13 -> 16016 | ... Q14: =Q13-P13 -> 18778.863
A15: =A11 -> Growth % | E15: =E13/D13-1 -> 0.34076723 | F15: =F13/E13-1 -> 0.25773775 | G15: =G13/F13-1 -> 0.49661471 | H15: =H13/G13-1 -> 0.28467208 | I15: =I13/H13-1 -> 0.13882708 | J15: =J13/I13-1 -> 0.1897533 | K15: =K13/J13-1 -> 0.1149065 | L15: =L13/K13-1 -> 0.10257067 | ... Q15: =Q13/P13-1 -> 0.079733547
A16: 3P mix | D16: 0.56 | E16: 0.58 | F16: =E16+1.5% -> 0.595 | G16: =F16+1.5% -> 0.61 | H16: =G16+1.5% -> 0.625 | I16: =H16+1.5% -> 0.64 | J16: =I16+1.5% -> 0.655 | K16: =J16+1.5% -> 0.67 | L16: =K16 -> 0.67 | M16: =M18/M24 -> 0.67100637 | N16: =N18/N24 -> 0.67142923 | O16: =O18/O24 -> 0.67131888 | P16: =P18/P24 -> 0.67224184 | Q16: =Q18/Q24 -> 0.67423398
A17: AMZN take rate | D17: =D13/D18 -> 0.23118073 | E17: =E13/E18 -> 0.25167925 | F17: =F13/F18 -> 0.25908021 | G17: =G13/G18 -> 0.26067049 | H17: =H13/H18 -> 0.27927322 | I17: =I13/I18 -> 0.30097294 | J17: =J13/J18 -> 0.31814266 | K17: =K13/K18 -> 0.31133078 | L17: =L13/L18 -> 0.31489158 | M17: =L17 -> 0.31489158 | N17: =M17 -> 0.31489158 | O17: =N17 -> 0.31489158 | P17: =O17 -> 0.31489158 | Q17: =P17 -> 0.31489158
A18: 3P GMV | D18: =D24-D9 -> 137905.09 | E18: =E24-E9 -> 169839.19 | F18: =F24-F9 -> 207511.02 | G18: =G24-G9 -> 308669.38 | H18: =H24-H9 -> 370125 | I18: =I24-I9 -> 391118.22 | J18: =J24-J9 -> 440220.75 | K18: =K24-K9 -> 501543.73 | ... Q18: =Q24-Q9 -> 807576.64
A20: North America revenue | D20: =Daloopa!BJ67 -> 106110 | E20: =Daloopa!BK67 -> 141366 | F20: =Daloopa!BL67 -> 170773 | G20: =Daloopa!BM67 -> 236282 | H20: =Daloopa!BN67 -> 279833 | I20: =Daloopa!BO67 -> 315880 | J20: =Daloopa!BP67 -> 352828 | K20: =Daloopa!BQ67 -> 387497 | L20: =Daloopa!BR67 -> 426305
A21: International revenue | D21: =Daloopa!BJ75 -> 54297 | E21: =Daloopa!BK75 -> 65866 | F21: =Daloopa!BL75 -> 74723 | G21: =Daloopa!BM75 -> 104412 | H21: =Daloopa!BN75 -> 127787 | I21: =Daloopa!BO75 -> 118007 | J21: =Daloopa!BP75 -> 131200 | K21: =Daloopa!BQ75 -> 142906 | L21: =Daloopa!BR75 -> 161894
A22: NA as % of AMZN ex AWS revenue | D22: =D20/(D20+D21) -> 0.6615048 | E22: =E20/(E20+E21) -> 0.68216299 | F22: =F20/(F20+F21) -> 0.69562437 | G22: =G20/(G20+G21) -> 0.69353144 | H22: =H20/(H20+H21) -> 0.68650459 | I22: =I20/(I20+I21) -> 0.72802366 | J22: =J20/(J20+J21) -> 0.7289413 | K22: =K20/(K20+K21) -> 0.73057091 | L22: =L20/(L20+L21) -> 0.72476322 | M22: =M153 -> 0.71976322 | N22: =N153 -> 0.71476322 | O22: =O153 -> 0.70976322 | P22: =P153 -> 0.70476322 | Q22: =Q153 -> 0.69976322
A24: AMZN GMV | D24: =D9/(1-D16) -> 246259.09 | E24: =E9/(1-E16) -> 292826.19 | F24: =F9/(1-F16) -> 348758.02 | G24: =G9/(1-G16) -> 506015.38 | H24: =H9/(1-H16) -> 592200 | I24: =I9/(1-I16) -> 611122.22 | J24: =J9/(1-J16) -> 672092.75 | K24: =K9/(1-K16) -> 748572.73 | L24: =L9/(1-L16) -> 816021.21 | M24: =M26/M22 -> 883998.76 | N24: =N26/N22 -> 955947.35 | O24: =O26/O22 -> 1032076.5 | P24: =P26/P22 -> 1112606.5 | Q24: =Q26/Q22 -> 1197769.1
A25: Growth | E25: =E24/D24-1 -> 0.18909799 | F25: =F24/E24-1 -> 0.19100694 | G25: =G24/F24-1 -> 0.45090679 | H25: =H24/G24-1 -> 0.17032015 | I25: =I24/H24-1 -> 0.031952418 | J25: =J24/I24-1 -> 0.099768147 | K25: =K24/J24-1 -> 0.11379378 | L25: =L24/K24-1 -> 0.090102781 | ... Q25: =Q24/P24-1 -> 0.076543298
A26: AMZN GMV (US) | D26: =D24*D22 -> 162901.57 | E26: =E24*E22 -> 199755.19 | F26: =F24*F22 -> 242604.58 | G26: =G24*G22 -> 350937.58 | H26: =H24*H22 -> 406548.02 | I26: =I24*I22 -> 444911.43 | J26: =J24*J22 -> 489916.17 | K26: =K24*K22 -> 546885.46 | L26: =L24*L22 -> 591422.16 | M26: =M28*M2*1000 -> 636269.79 | N26: =N28*N2*1000 -> 683276 | O26: =O28*O2*1000 -> 732529.94 | P26: =P28*P2*1000 -> 784124.17 | Q26: =Q28*Q2*1000 -> 838154.77
A27: Growth | E27: =E26/D26-1 -> 0.22623243 | F27: =F26/E26-1 -> 0.21450953 | G27: =G26/F26-1 -> 0.44654143 | H27: =H26/G26-1 -> 0.15846248 | I27: =I26/H26-1 -> 0.094363805 | J27: =J26/I26-1 -> 0.10115436 | K27: =K26/J26-1 -> 0.11628375 | L27: =L26/K26-1 -> 0.081436988 | ... Q27: =Q26/P26-1 -> 0.068905674
A28: AMZN US e-com market share | D28: =D26/(D2*1000) -> 0.3533396 | E28: =E26/(E2*1000) -> 0.40082267 | F28: =F26/(F2*1000) -> 0.43189055 | G28: =G26/(G2*1000) -> 0.43950318 | H28: =H26/(H2*1000) -> 0.43407163 | I28: =I26/(I2*1000) -> 0.44603679 | J28: =J26/(J2*1000) -> 0.4506978 | K28: =K26/(K2*1000) -> 0.46741148 | L28: =L26/(L2*1000) -> 0.46891724 | M28: =L28 -> 0.46891724 | N28: =M28 -> 0.46891724 | O28: =N28 -> 0.46891724 | P28: =O28 -> 0.46891724 | Q28: =P28 -> 0.46891724
A29: AMZN International GMV | D29: =D24-D26 -> 83357.521 | E29: =E24-E26 -> 93071.002 | F29: =F24-F26 -> 106153.44 | G29: =G24-G26 -> 155077.81 | H29: =H24-H26 -> 185651.98 | I29: =I24-I26 -> 166210.79 | J29: =J24-J26 -> 182176.59 | K29: =K24-K26 -> 201687.27 | ... Q29: =Q24-Q26 -> 359614.35
A30: Growth | E30: =E29/D29-1 -> 0.11652795 | F30: =F29/E29-1 -> 0.14056411 | G30: =G29/F29-1 -> 0.46088343 | H30: =H29/G29-1 -> 0.19715378 | I30: =I29/H29-1 -> -0.10471849 | J30: =J29/I29-1 -> 0.096057542 | K30: =K29/J29-1 -> 0.10709765 | L30: =L29/K29-1 -> 0.11360053 | ... Q30: =Q29/P29-1 -> 0.094775161
A32: Physical stores | C32: =Financials!B13 -> 0 | D32: =Financials!C13 -> 5798 | E32: =Financials!D13 -> 17224 | F32: =Financials!E13 -> 17192 | G32: =Financials!F13 -> 16227 | H32: =Financials!G13 -> 17075 | I32: =Financials!H13 -> 18963 | J32: =Financials!I13 -> 20030 | ... L32: =Financials!K13 -> 22561 | M32: =L32*(1+M34) -> 23914.66 | N32: =M32*(1+N34) -> 25349.54 | O32: =N32*(1+O34) -> 26870.512 | P32: =O32*(1+P34) -> 28482.743 | Q32: =P32*(1+Q34) -> 30191.707
A33: Growth $ | E33: =E32-D32 -> 11426 | F33: =F32-E32 -> -32 | G33: =G32-F32 -> -965 | H33: =H32-G32 -> 848 | I33: =I32-H32 -> 1888 | J33: =J32-I32 -> 1067 | K33: =K32-J32 -> 1185 | L33: =L32-K32 -> 1346 | ... Q33: =Q32-P32 -> 1708.9646
A34: Growth % | E34: =E32/D32-1 -> 1.9706795 | F34: =F32/E32-1 -> -0.0018578727 | G34: =G32/F32-1 -> -0.056130758 | H34: =H32/G32-1 -> 0.052258581 | I34: =I32/H32-1 -> 0.11057101 | J34: =J32/I32-1 -> 0.056267468 | K34: =K32/J32-1 -> 0.059161258 | L34: =L32/K32-1 -> 0.063445675 | M34: 0.06 | N34: 0.06 | O34: 0.06 | P34: 0.06 | Q34: 0.06
A36: Subscription services | C36: =Financials!B21 -> 6394 | D36: =Financials!C21 -> 9721 | E36: =Financials!D21 -> 14168 | F36: =Financials!E21 -> 19210 | G36: =Financials!F21 -> 25207 | H36: =Financials!G21 -> 31768 | I36: =Financials!H21 -> 35218 | J36: =Financials!I21 -> 40209 | ... L36: =Financials!K21 -> 49619 | M36: =M50+M52+M54 -> 54854.401 | N36: =N50+N52+N54 -> 59420.961 | O36: =O50+O52+O54 -> 63440.099 | P36: =P50+P52+P54 -> 67259.897 | Q36: =Q50+Q52+Q54 -> 71204.078
A37: Growth $ | E37: =E36-D36 -> 4447 | F37: =F36-E36 -> 5042 | G37: =G36-F36 -> 5997 | H37: =H36-G36 -> 6561 | I37: =I36-H36 -> 3450 | J37: =J36-I36 -> 4991 | K37: =K36-J36 -> 4165 | L37: =L36-K36 -> 5245 | ... Q37: =Q36-P36 -> 3944.1809
A38: Growth % | E38: =E36/D36-1 -> 0.45746322 | F38: =F36/E36-1 -> 0.35587239 | G38: =G36/F36-1 -> 0.31218116 | H38: =H36/G36-1 -> 0.26028484 | I38: =I36/H36-1 -> 0.10859985 | J38: =J36/I36-1 -> 0.1417173 | K38: =K36/J36-1 -> 0.10358377 | L38: =L36/K36-1 -> 0.11819985 | ... Q38: =Q36/P36-1 -> 0.0586409
A40: AMZN Prime Members (US) | D40: 92 | E40: 101 | F40: 112 | G40: 142 | H40: 172 | I40: 173 | J40: 175 | K40: 185 | L40: 195 | M40: =L40+M41 -> 203 | N40: =M40+N41 -> 209 | O40: =N40+O41 -> 213 | P40: =O40+P41 -> 217 | Q40: =P40+Q41 -> 221
A41: Increase YoY | E41: =E40-D40 -> 9 | F41: =F40-E40 -> 11 | G41: =G40-F40 -> 30 | H41: =H40-G40 -> 30 | I41: =I40-H40 -> 1 | J41: =J40-I40 -> 2 | K41: =K40-J40 -> 10 | L41: =L40-K40 -> 10 | M41: =L41-2 -> 8 | N41: =M41-2 -> 6 | O41: =N41-2 -> 4 | P41: =O41 -> 4 | Q41: =P41 -> 4
A42: AMZN Prime Members (Global) | D42: 100 | E42: 125 | F42: 150 | G42: 200 | H42: =H43+H40 -> 245 | I42: =I43+I40 -> 256 | J42: =J43+J40 -> 268 | K42: =K43+K40 -> 293 | L42: =L43+L40 -> 323 | M42: =M43+M40 -> 346 | N42: =N43+N40 -> 364 | O42: =O43+O40 -> 378 | ... Q42: =Q43+Q40 -> 406
A43: AMZN international | D43: =D42-D40 -> 8 | E43: =E42-E40 -> 24 | F43: =F42-F40 -> 38 | G43: =G42-G40 -> 58 | H43: =G43+H44 -> 73 | I43: =H43+I44 -> 83 | J43: =I43+J44 -> 93 | K43: =J43+K44 -> 108 | L43: =K43+L44 -> 128 | M43: =L43+M44 -> 143 | N43: =M43+N44 -> 155 | O43: =N43+O44 -> 165 | ... Q43: =P43+Q44 -> 185
A44: Increase YoY | E44: =E43-D43 -> 16 | F44: =F43-E43 -> 14 | G44: =G43-F43 -> 20 | H44: 15 | I44: 10 | J44: 10 | K44: 15 | L44: 20 | M44: 15 | N44: 12 | O44: 10 | P44: 10 | Q44: 10
A46: Subscription Revenue per Global Prime member | E46: =E36/AVERAGE(D42:E42) -> 125.93778 | F46: =F36/AVERAGE(E42:F42) -> 139.70909 | G46: =G36/AVERAGE(F42:G42) -> 144.04 | H46: =H36/AVERAGE(G42:H42) -> 142.77753 | I46: =I36/AVERAGE(H42:I42) -> 140.59082 | J46: =J36/AVERAGE(I42:J42) -> 153.46947 | K46: =K36/AVERAGE(J42:K42) -> 158.19608 | L46: =L36/AVERAGE(K42:L42) -> 161.10065 | ... Q46: =Q36/AVERAGE(P42:Q42) -> 178.45634
A47: Growth | F47: =F46/E46-1 -> 0.10935014 | G47: =G46/F46-1 -> 0.030999479 | H47: =H46/G46-1 -> -0.0087647314 | I47: =I46/H46-1 -> -0.015315503 | J47: =J46/I46-1 -> 0.091603758 | K47: =K46/J46-1 -> 0.030798392 | L47: =L46/K46-1 -> 0.018360575 | M47: =M46/L46-1 -> 0.017930353 | ... Q47: =Q46/P46-1 -> 0.021495606
A49: US Prime Price Per Member | D49: 99 | E49: 119 | F49: 119 | G49: 119 | H49: 119 | I49: 129 | J49: 139 | K49: 139 | L49: =K49*1.03 -> 143.17 | M49: =L49*1.03 -> 147.4651 | N49: =M49*1.03 -> 151.88905 | O49: =N49*1.03 -> 156.44572 | P49: =O49*1.03 -> 161.1391 | Q49: =P49*1.03 -> 165.97327
...

Sheet Financials
B1: 2016 | C1: 2017 | D1: 2018 | E1: 2019 | F1: 2020 | G1: 2021 | H1: 2022 | I1: 2023 | J1: 2024 | K1: 2025 | L1: 2026 | M1: 2027 | N1: 2028 | O1: 2029 | P1: 2030
A2: Revenue | B2: =Daloopa!BI62 -> 135987 | C2: =Daloopa!BJ62 -> 177866 | D2: =Daloopa!BK62 -> 232887 | E2: =Daloopa!BL62 -> 280522 | F2: =Daloopa!BM62 -> 386064 | G2: =Daloopa!BN62 -> 469822 | H2: =Daloopa!BO62 -> 513983 | I2: =I38 -> 574785 | J2: =J38 -> 637959 | K2: =K38 -> 716924 | L2: =L38 -> 812238.6 | M2: =M38 -> 931504.08 | N2: =N38 -> 1047761.1 | O2: =O38 -> 1151692.9 | P2: =P38 -> 1255187.4
A3: Growth $ | C3: =C2-B2 -> 41879 | D3: =D2-C2 -> 55021 | E3: =E2-D2 -> 47635 | F3: =F2-E2 -> 105542 | G3: =G2-F2 -> 83758 | H3: =H2-G2 -> 44161 | I3: =I2-H2 -> 60802 | J3: =J2-I2 -> 63174 | ... P3: =P2-O2 -> 103494.54
A4: Growth % | C4: =C2/B2-1 -> 0.30796326 | D4: =D2/C2-1 -> 0.30933962 | E4: =E2/D2-1 -> 0.20454126 | F4: =F2/E2-1 -> 0.37623431 | G4: =G2/F2-1 -> 0.21695367 | H4: =H2/G2-1 -> 0.093995173 | I4: =I2/H2-1 -> 0.11829574 | J4: =J2/I2-1 -> 0.10990892 | ... P4: =P2/O2-1 -> 0.089862967
A5: Consensus (as of Feb 08, 2026) | L5: 805040 | M5: 895471 | N5: 1008977 | O5: 1103636 | P5: 1215335
A7: Segments
A9: Online Stores | B9: =Daloopa!BI54 -> 91431 | C9: =Daloopa!BJ54 -> 108354 | D9: =Daloopa!BK54 -> 122987 | E9: =Daloopa!BL54 -> 141247 | F9: =Daloopa!BM54 -> 197346 | G9: =Daloopa!BN54 -> 222075 | H9: =Daloopa!BO54 -> 220004 | I9: =Daloopa!BP54 -> 231872 | ... K9: =Daloopa!BR54 -> 269287 | L9: =Model!M9 -> 290829.96 | M9: =Model!N9 -> 314096.36 | N9: =Model!O9 -> 339224.07 | O9: =Model!P9 -> 364665.87 | P9: =Model!Q9 -> 390192.48
A10: Growth | C10: =C9-B9 -> 16923 | D10: =D9-C9 -> 14633 | E10: =E9-D9 -> 18260 | F10: =F9-E9 -> 56099 | G10: =G9-F9 -> 24729 | H10: =H9-G9 -> -2071 | I10: =I9-H9 -> 11868 | J10: =J9-I9 -> 15157 | ... P10: =P9-O9 -> 25526.611
A11: Growth % | C11: =C9/B9-1 -> 0.1850904 | D11: =D9/C9-1 -> 0.13504808 | E11: =E9/D9-1 -> 0.14847098 | F11: =F9/E9-1 -> 0.3971695 | G11: =G9/F9-1 -> 0.12530783 | H11: =H9/G9-1 -> -0.0093256783 | I11: =I9/H9-1 -> 0.053944474 | J11: =J9/I9-1 -> 0.065367962 | ... P11: =P9/O9-1 -> 0.07
A13: Physical Stores | B13: =Daloopa!BI55 -> 0 | C13: =Daloopa!BJ55 -> 5798 | D13: =Daloopa!BK55 -> 17224 | E13: =Daloopa!BL55 -> 17192 | F13: =Daloopa!BM55 -> 16227 | G13: =Daloopa!BN55 -> 17075 | H13: =Daloopa!BO55 -> 18963 | I13: =Daloopa!BP55 -> 20030 | ... K13: =Daloopa!BR55 -> 22561 | L13: =Model!M32 -> 23914.66 | M13: =Model!N32 -> 25349.54 | N13: =Model!O32 -> 26870.512 | O13: =Model!P32 -> 28482.743 | P13: =Model!Q32 -> 30191.707
A14: =A10 -> Growth | D14: =D13-C13 -> 11426 | E14: =E13-D13 -> -32 | F14: =F13-E13 -> -965 | G14: =G13-F13 -> 848 | H14: =H13-G13 -> 1888 | I14: =I13-H13 -> 1067 | J14: =J13-I13 -> 1185 | K14: =K13-J13 -> 1346 | ... P14: =P13-O13 -> 1708.9646
A15: =A11 -> Growth % | D15: =D13/C13-1 -> 1.9706795 | E15: =E13/D13-1 -> -0.0018578727 | F15: =F13/E13-1 -> -0.056130758 | G15: =G13/F13-1 -> 0.052258581 | H15: =H13/G13-1 -> 0.11057101 | I15: =I13/H13-1 -> 0.056267468 | J15: =J13/I13-1 -> 0.059161258 | K15: =K13/J13-1 -> 0.063445675 | ... P15: =P13/O13-1 -> 0.06
A17: 3P Seller Services | B17: =Daloopa!BI56 -> 22993 | C17: =Daloopa!BJ56 -> 31881 | D17: =Daloopa!BK56 -> 42745 | E17: =Daloopa!BL56 -> 53762 | F17: =Daloopa!BM56 -> 80461 | G17: =Daloopa!BN56 -> 103366 | H17: =Daloopa!BO56 -> 117716 | I17: =Daloopa!BP56 -> 140053 | ... K17: =Daloopa!BR56 -> 172162 | L17: =Model!M13 -> 186783.86 | M17: =Model!N13 -> 202113.47 | N17: =Model!O13 -> 218173.4 | O17: =Model!P13 -> 235520.22 | P17: =Model!Q13 -> 254299.08
A18: =A14 -> Growth | C18: =C17-B17 -> 8888 | D18: =D17-C17 -> 10864 | E18: =E17-D17 -> 11017 | F18: =F17-E17 -> 26699 | G18: =G17-F17 -> 22905 | H18: =H17-G17 -> 14350 | I18: =I17-H17 -> 22337 | J18: =J17-I17 -> 16093 | ... P18: =P17-O17 -> 18778.863
A19: =A15 -> Growth % | C19: =C17/B17-1 -> 0.38655243 | D19: =D17/C17-1 -> 0.34076723 | E19: =E17/D17-1 -> 0.25773775 | F19: =F17/E17-1 -> 0.49661471 | G19: =G17/F17-1 -> 0.28467208 | H19: =H17/G17-1 -> 0.13882708 | I19: =I17/H17-1 -> 0.1897533 | J19: =J17/I17-1 -> 0.1149065 | ... P19: =P17/O17-1 -> 0.079733547
A21: Subscription Services | B21: =Daloopa!BI57 -> 6394 | C21: =Daloopa!BJ57 -> 9721 | D21: =Daloopa!BK57 -> 14168 | E21: =Daloopa!BL57 -> 19210 | F21: =Daloopa!BM57 -> 25207 | G21: =Daloopa!BN57 -> 31768 | H21: =Daloopa!BO57 -> 35218 | I21: =Daloopa!BP57 -> 40209 | ... K21: =Daloopa!BR57 -> 49619 | L21: =Model!M36 -> 54854.401 | M21: =Model!N36 -> 59420.961 | N21: =Model!O36 -> 63440.099 | O21: =Model!P36 -> 67259.897 | P21: =Model!Q36 -> 71204.078
A22: =A18 -> Growth | C22: =C21-B21 -> 3327 | D22: =D21-C21 -> 4447 | E22: =E21-D21 -> 5042 | F22: =F21-E21 -> 5997 | G22: =G21-F21 -> 6561 | H22: =H21-G21 -> 3450 | I22: =I21-H21 -> 4991 | J22: =J21-I21 -> 4165 | ... P22: =P21-O21 -> 3944.1809
A23: =A19 -> Growth % | D23: =D21/C21-1 -> 0.45746322 | E23: =E21/D21-1 -> 0.35587239 | F23: =F21/E21-1 -> 0.31218116 | G23: =G21/F21-1 -> 0.26028484 | H23: =H21/G21-1 -> 0.10859985 | I23: =I21/H21-1 -> 0.1417173 | J23: =J21/I21-1 -> 0.10358377 | K23: =K21/J21-1 -> 0.11819985 | ... P23: =P21/O21-1 -> 0.0586409
A25: Advertising Services | B25: =B29*95% -> 2802.5 | C25: =C29*95% -> 4420.35 | D25: =D29*95% -> 9602.6 | E25: =E29*95% -> 13380.75 | F25: =F29*95% -> 20380.35 | G25: =Daloopa!BN58 -> 31160 | H25: =Daloopa!BO58 -> 37739 | I25: =Daloopa!BP58 -> 46906 | J25: =Daloopa!BQ58 -> 56214 | K25: =Daloopa!BR58 -> 68635 | L25: =Model!M57 -> 78593.036 | M25: =Model!N57 -> 88506.222 | N25: =Model!O57 -> 98704.89 | O25: =Model!P57 -> 109204.08 | P25: =Model!Q57 -> 120019.62
A26: =A22 -> Growth | C26: =C25-B25 -> 1617.85 | D26: =D25-C25 -> 5182.25 | E26: =E25-D25 -> 3778.15 | F26: =F25-E25 -> 6999.6 | G26: =G25-F25 -> 10779.65 | H26: =H25-G25 -> 6579 | I26: =I25-H25 -> 9167 | J26: =J25-I25 -> 9308 | ... P26: =P25-O25 -> 10815.536
A27: =A23 -> Growth % | C27: =C25/B25-1 -> 0.57728814 | D27: =D25/C25-1 -> 1.1723619 | E27: =E25/D25-1 -> 0.39345073 | F27: =F25/E25-1 -> 0.52310969 | G27: =G25/F25-1 -> 0.52892369 | H27: =H25/G25-1 -> 0.21113607 | I27: =I25/H25-1 -> 0.24290522 | J27: =J25/I25-1 -> 0.19843943 | ... P27: =P25/O25-1 -> 0.099039672
A29: Others | B29: =Daloopa!BI60 -> 2950 | C29: =Daloopa!BJ60 -> 4653 | D29: =Daloopa!BK60 -> 10108 | E29: =Daloopa!BL60 -> 14085 | F29: =Daloopa!BM60 -> 21453 | G29: =Daloopa!BN61 -> 2176 | H29: =Daloopa!BO61 -> 4247 | I29: =Daloopa!BP61 -> 4958 | J29: =Daloopa!BQ61 -> 5425 | K29: =Daloopa!BR61 -> 5935
A30: Others, excludind ads | B30: =B29-B25 -> 147.5 | C30: =C29-C25 -> 232.65 | D30: =D29-D25 -> 505.4 | E30: =E29-E25 -> 704.25 | F30: =F29-F25 -> 1072.65 | G30: =G29 -> 2176 | H30: =H29 -> 4247 | I30: =I29 -> 4958 | J30: =J29 -> 5425 | K30: =K29 -> 5935 | L30: =Model!M76 -> 6935 | M30: =Model!N76 -> 8435 | N30: =Model!O76 -> 9935 | O30: =Model!P76 -> 11435 | P30: =Model!Q76 -> 12935
A31: =A26 -> Growth | C31: =C30-B30 -> 85.15 | D31: =D30-C30 -> 272.75 | E31: =E30-D30 -> 198.85 | F31: =F30-E30 -> 368.4 | G31: =G30-F30 -> 1103.35 | H31: =H30-G30 -> 2071 | I31: =I30-H30 -> 711 | J31: =J30-I30 -> 467 | ... P31: =P30-O30 -> 1500
A32: =A27 -> Growth % | C32: =C30/B30-1 -> 0.57728814 | D32: =D30/C30-1 -> 1.1723619 | E32: =E30/D30-1 -> 0.39345073 | F32: =F30/E30-1 -> 0.52310969 | G32: =G30/F30-1 -> 1.0286207 | H32: =H30/G30-1 -> 0.95174632 | I32: =I30/H30-1 -> 0.16741229 | J32: =J30/I30-1 -> 0.094191206 | ... P32: =P30/O30-1 -> 0.13117621
A34: AWS | B34: =Daloopa!BI59 -> 12219 | C34: =Daloopa!BJ59 -> 17459 | D34: =Daloopa!BK59 -> 25655 | E34: =Daloopa!BL59 -> 35026 | F34: =Daloopa!BM59 -> 45370 | G34: =Daloopa!BN59 -> 62202 | H34: =Daloopa!BO59 -> 80096 | I34: =Daloopa!BP59 -> 90757 | ... K34: =Daloopa!BR59 -> 128725 | L34: =Model!M71 -> 170327.68 | M34: =Model!N71 -> 233582.53 | N34: =Model!O71 -> 291413.12 | O34: =Model!P71 -> 335125.09 | P34: =Model!Q71 -> 376345.48
A35: =A31 -> Growth | C35: =C34-B34 -> 5240 | D35: =D34-C34 -> 8196 | E35: =E34-D34 -> 9371 | F35: =F34-E34 -> 10344 | G35: =G34-F34 -> 16832 | H35: =H34-G34 -> 17894 | I35: =I34-H34 -> 10661 | J35: =J34-I34 -> 16799 | ... P35: =P34-O34 -> 41220.386
A36: =A32 -> Growth % | C36: =C34/B34-1 -> 0.42884033 | D36: =D34/C34-1 -> 0.46944269 | E36: =E34/D34-1 -> 0.36526993 | F36: =F34/E34-1 -> 0.29532347 | G36: =G34/F34-1 -> 0.37099405 | H36: =H34/G34-1 -> 0.28767564 | I36: =I34/H34-1 -> 0.13310278 | J36: =J34/I34-1 -> 0.18509867 | ... P36: =P34/O34-1 -> 0.123
A38: Total revenues | B38: =B34+B30+B25+B21+B17+B13+B9 -> 135987 | C38: =C34+C30+C25+C21+C17+C13+C9 -> 177866 | D38: =D34+D30+D25+D21+D17+D13+D9 -> 232887 | E38: =E34+E30+E25+E21+E17+E13+E9 -> 280522 | F38: =F34+F30+F25+F21+F17+F13+F9 -> 386064 | G38: =G34+G30+G25+G21+G17+G13+G9 -> 469822 | H38: =H34+H30+H25+H21+H17+H13+H9 -> 513983 | I38: =I34+I30+I25+I21+I17+I13+I9 -> 574785 | ... P38: =P34+P30+P25+P21+P17+P13+P9 -> 1255187.4
A39: Growth | C39: =C38-B38 -> 41879 | D39: =D38-C38 -> 55021 | E39: =E38-D38 -> 47635 | F39: =F38-E38 -> 105542 | G39: =G38-F38 -> 83758 | H39: =H38-G38 -> 44161 | I39: =I38-H38 -> 60802 | J39: =J38-I38 -> 63174 | ... P39: =P38-O38 -> 103494.54
A40: Growth % | C40: =C38/B38-1 -> 0.30796326 | D40: =D38/C38-1 -> 0.30933962 | E40: =E38/D38-1 -> 0.20454126 | F40: =F38/E38-1 -> 0.37623431 | G40: =G38/F38-1 -> 0.21695367 | H40: =H38/G38-1 -> 0.093995173 | I40: =I38/H38-1 -> 0.11829574 | J40: =J38/I38-1 -> 0.10990892 | ... P40: =P38/O38-1 -> 0.089862967
A42: Cost of Sales | C42: =Model!D82 -> 111934 | D42: =Model!E82 -> 139156 | E42: =Model!F82 -> 165536 | F42: =Model!G82 -> 233307 | G42: =Model!H82 -> 272344 | H42: =Model!I82 -> 288831 | I42: =Model!J82 -> 304739 | J42: =Model!K82 -> 326288 | ... P42: =Model!Q82 -> 493814.42
A43: As % of revenue | C43: =C42/(C2-C34) -> 0.69781244 | D43: =D42/(D2-D34) -> 0.67149861 | E43: =E42/(E2-E34) -> 0.67429205 | F43: =F42/(F2-F34) -> 0.68479926 | G43: =G42/(G2-G34) -> 0.66813208 | H43: =H42/(H2-H34) -> 0.66568254 | I43: =I42/(I2-I34) -> 0.62958961 | J43: =J42/(J2-J34) -> 0.61516997 | ... P43: =P42/(P2-P34) -> 0.56189217
A45: Fulfilment | C45: =Model!D94 -> 25249 | D45: =Model!E94 -> 34027 | E45: =Model!F94 -> 40232 | F45: =Model!G94 -> 58517 | G45: =Model!H94 -> 75111 | H45: =Model!I94 -> 84299 | I45: =Model!J94 -> 90619 | J45: =Model!K94 -> 98505 | ... P45: =Model!Q94 -> 152764.86
A46: As % of revenue | C46: =C45/C2 -> 0.14195518 | D46: =D45/D2 -> 0.14610949 | E46: =E45/E2 -> 0.14341834 | F46: =F45/F2 -> 0.15157331 | G46: =G45/G2 -> 0.15987119 | H46: =H45/H2 -> 0.16401126 | I46: =I45/I2 -> 0.15765721 | J46: =J45/J2 -> 0.15440647 | ... P46: =P45/P2 -> 0.12170681
A48: Sales & Marketing | C48: =Model!D104 -> 10069 | D48: =Model!E104 -> 13814 | E48: =Model!F104 -> 18878 | F48: =Model!G104 -> 22008 | G48: =Model!H104 -> 32551 | H48: =Model!I104 -> 42238 | I48: =Model!J104 -> 44370 | J48: =Model!K104 -> 43907 | K48: =Model!L104 -> 47129
A49: As % of revenue | C49: =C48/C2 -> 0.056610032 | D49: =D48/D2 -> 0.059316321 | E49: =E48/E2 -> 0.06729597 | F49: =F48/F2 -> 0.057006092 | G49: =G48/G2 -> 0.069283686 | H49: =H48/H2 -> 0.082177815 | I49: =I48/I2 -> 0.077194081 | J49: =J48/J2 -> 0.068824172 | K49: =K48/K2 -> 0.065737791
A51: Technology & Content | C51: =Model!D108 -> 22620 | D51: =Model!E108 -> 28837 | E51: =Model!F108 -> 35931 | F51: =Model!G108 -> 42740 | G51: =Model!H108 -> 56052 | H51: =Model!I108 -> 73213 | I51: =Model!J108 -> 85622 | J51: =Model!K108 -> 88544 | K51: =Model!L108 -> 108521
A52: As % of revenue | C52: =C51/C2 -> 0.12717439 | D52: =D51/D2 -> 0.123824 | E52: =E51/E2 -> 0.12808621 | F52: =F51/F2 -> 0.11070703 | G52: =G51/G2 -> 0.11930476 | H52: =H51/H2 -> 0.14244245 | I52: =I51/I2 -> 0.14896353 | J52: =J51/J2 -> 0.13879262 | K52: =K51/K2 -> 0.1513703
A54: General & Administrative | C54: =Model!D111 -> 3674 | D54: =Model!E111 -> 4336 | E54: =Model!F111 -> 5203 | F54: =Model!G111 -> 6668 | G54: =Model!H111 -> 8823 | H54: =Model!I111 -> 11891 | I54: =Model!J111 -> 11816 | J54: =Model!K111 -> 11359 | K54: =Model!L111 -> 11172
...

Sheet Valuation
A1: Items | C1: 2021 | D1: 2022 | E1: 2023 | F1: 2024 | G1: 2025 | H1: 2026 | I1: 2027 | J1: 2028 | K1: 2029 | L1: 2030
A2: FCF
A3: OCF | C3: =Financials!G98 -> 46327 | D3: =Financials!H98 -> 46752 | E3: =Financials!I98 -> 84946 | F3: =Financials!J98 -> 115877 | G3: =Financials!K98 -> 144747 | H3: =Financials!L98 -> 163319.7 | I3: =Financials!M98 -> 221911.67 | J3: =Financials!N98 -> 269946.55 | ... L3: =Financials!P98 -> 379705.15
A4: Capex | C4: =Financials!G101+Financials!G104 -> -55396 | D4: =Financials!H101+Financials!H104 -> -58321 | E4: =Financials!I101+Financials!I104 -> -48133 | F4: =Financials!J101+Financials!J104 -> -77658 | G4: =Financials!K101+Financials!K104 -> -128320 | H4: =Financials!L101+Financials!L104 -> -189802.57 | I4: =Financials!M101+Financials!M104 -> -178657.17 | J4: =Financials!N101+Financials!N104 -> -186214.22 | ... L4: =Financials!P101+Financials!P104 -> -119815.2 | Q4: Terminal Multiple
A5: FCF | C5: =C3+C4 -> -9069 | D5: =D3+D4 -> -11569 | E5: =E3+E4 -> 36813 | F5: =F3+F4 -> 38219 | G5: =G3+G4 -> 16427 | H5: =H3+H4 -> -26482.874 | I5: =I3+I4 -> 43254.502 | J5: =J3+J4 -> 83732.33 | K5: =K3+K4 -> 168741.26 | L5: =L3+L4-Financials!P83 -> 225807.21 | Q5: 10
A6: FCF/share | C6: =C5/C14 -> -0.88048544 | D6: =D5/D14 -> -1.1354402 | E6: =E5/E14 -> 3.5086733 | F6: =F5/F14 -> 3.5648727 | G6: =G5/G14 -> 1.5172255 | H6: =H5/H14 -> -2.4244852 | I6: =I5/I14 -> 3.9727945 | J6: =J5/J14 -> 7.8091754 | ... L6: =L5/L14 -> 23.370727 | Q6: =Q5+0.5 -> 10.5
A7: Terminal FCF multiple | L7: 14.5 | Q7: =Q6+0.5 -> 11
A8: Terminal Stock price | L8: =L7*L6 -> 338.87554 | Q8: =Q7+0.5 -> 11.5
A9: Current price* | B9: 210.32 | Q9: =Q8+0.5 -> 12
A10: Dividend/share | E10: 0 | F10: 0 | G10: 0 | H10: 0 | I10: 0 | J10: 0 | K10: 0 | L10: 0 | Q10: =Q9+0.5 -> 12.5
A11: Cash flow | G11: =-B9 -> -210.32 | H11: =H10+H8 -> 0 | I11: =I10+I8 -> 0 | J11: =J10+J8 -> 0 | K11: =K10+K8 -> 0 | L11: =L10+L8 -> 338.87554 | Q11: =Q10+0.5 -> 13
Q12: =Q11+0.5 -> 13.5
A13: IRR | B13: =IRR(F11:L11) -> 0.10009941 | Q13: =Q12+0.5 -> 14
A14: #diluted shares outstanding | C14: =Financials!G178 -> 10300 | D14: =Financials!H178 -> 10189 | E14: =Financials!I178 -> 10492 | F14: =Financials!J178 -> 10721 | G14: =Financials!K178 -> 10827 | H14: =Financials!L178 -> 10923.092 | I14: =Financials!M178 -> 10887.677 | J14: =Financials!N178 -> 10722.301 | ... L14: =Financials!P178 -> 9661.9678 | Q14: =Q13+0.5 -> 14.5
Q15: =Q14+0.5 -> 15
A16: *Closing price of February 06, 2026 | Q16: =Q15+0.5 -> 15.5
Q17: =Q16+0.5 -> 16
A18: Stock price | E18: =B9 -> 210.32 | F18: =B9 -> 210.32 | G18: =F18 -> 210.32 | H18: =G18*(1.1)^(11/12) -> 229.52176 | I18: =H18*1.1 -> 252.47394 | J18: =I18*1.1 -> 277.72133 | K18: =J18*1.1 -> 305.49346 | L18: =K18*1.1 -> 336.04281 | Q18: =Q17+0.5 -> 16.5
Q19: =Q18+0.5 -> 17
Q20: =Q19+0.5 -> 17.5
Q21: =Q20+0.5 -> 18
Q22: =Q21+0.5 -> 18.5
Q23: =Q22+0.5 -> 19
Q24: =Q23+0.5 -> 19.5
Q25: =Q24+0.5 -> 20
Q26: =Q25+0.5 -> 20.5
Q27: =Q26+0.5 -> 21
Q28: =Q27+0.5 -> 21.5
Q29: =Q28+0.5 -> 22
Q30: =Q29+0.5 -> 22.5
Q31: =Q30+0.5 -> 23
Q32: =Q31+1 -> 24
Q33: =Q32+1 -> 25
Q34: =Q33+1 -> 26
Q35: =Q34+1 -> 27
Q36: =Q35+1 -> 28
Q37: =Q36+1 -> 29
Q38: =Q37+1 -> 30
Q39: =Q38+1 -> 31
Q40: =Q39+1 -> 32

Sheet Daloopa
A1: Calendar | B1: Unit | C1: Source | D1: Tag Id | E1: 2013Q1 | F1: 2013Q2 | G1: 2013Q3 | H1: 2013Q4 | I1: 2014Q1 | J1: 2014Q2 | K1: 2014Q3 | L1: 2014Q4 | M1: 2015Q1 | N1: 2015Q2 | O1: 2015Q3 | P1: 2015Q4 | Q1: 2016Q1 | R1: 2016Q2 | S1: 2016Q3 | T1: 2016Q4 | U1: 2017Q1 | V1: 2017Q2 | W1: 2017Q3 | X1: 2017Q4 | Y1: 2018Q1 | Z1: 2018Q2 | AA1: 2018Q3 | AB1: 2018Q4 | AC1: 2019Q1 | AD1: 2019Q2 | AE1: 2019Q3 | AF1: 2019Q4 | AG1: 2020Q1 | AH1: 2020Q2 | AI1: 2020Q3 | AJ1: 2020Q4 | AK1: 2021Q1 | AL1: 2021Q2 | AM1: 2021Q3 | AN1: 2021Q4 | AO1: 2022Q1 | AP1: 2022Q2 | AQ1: 2022Q3 | AR1: 2022Q4 | AS1: 2023Q1 | AT1: 2023Q2 | AU1: 2023Q3 | AV1: 2023Q4 | AW1: 2024Q1 | AX1: 2024Q2 | AY1: 2024Q3 | AZ1: 2024Q4 | BA1: 2025Q1 | BB1: 2025Q2 | BC1: 2025Q3 | BD1: 2025Q4 | BF1: 2013FY | BG1: 2014FY | BH1: 2015FY | BI1: 2016FY | BJ1: 2017FY | BK1: 2018FY | BL1: 2019FY | BM1: 2020FY | BN1: 2021FY | BO1: 2022FY | BP1: 2023FY | BQ1: 2024FY | BR1: 2025FY
A2: Fiscal | E2: 2013Q1 | F2: 2013Q2 | G2: 2013Q3 | H2: 2013Q4 | I2: 2014Q1 | J2: 2014Q2 | K2: 2014Q3 | L2: 2014Q4 | M2: 2015Q1 | N2: 2015Q2 | O2: 2015Q3 | P2: 2015Q4 | Q2: 2016Q1 | R2: 2016Q2 | S2: 2016Q3 | T2: 2016Q4 | U2: 2017Q1 | V2: 2017Q2 | W2: 2017Q3 | X2: 2017Q4 | Y2: 2018Q1 | Z2: 2018Q2 | AA2: 2018Q3 | AB2: 2018Q4 | AC2: 2019Q1 | AD2: 2019Q2 | AE2: 2019Q3 | AF2: 2019Q4 | AG2: 2020Q1 | AH2: 2020Q2 | AI2: 2020Q3 | AJ2: 2020Q4 | AK2: 2021Q1 | AL2: 2021Q2 | AM2: 2021Q3 | AN2: 2021Q4 | AO2: 2022Q1 | AP2: 2022Q2 | AQ2: 2022Q3 | AR2: 2022Q4 | AS2: 2023Q1 | AT2: 2023Q2 | AU2: 2023Q3 | AV2: 2023Q4 | AW2: 2024Q1 | AX2: 2024Q2 | AY2: 2024Q3 | AZ2: 2024Q4 | BF2: 2013FY | BG2: 2014FY | BH2: 2015FY | BI2: 2016FY | BJ2: 2017FY | BK2: 2018FY | BL2: 2019FY | BM2: 2020FY | BN2: 2021FY | BO2: 2022FY | BP2: 2023FY | BQ2: 2024FY | BR2: 2025FY
A3: Fiscal Date | E3: 41364 | F3: 41455 | G3: 41547 | H3: 41639 | I3: 41729 | J3: 41820 | K3: 41912 | L3: 42004 | M3: 42094 | N3: 42185 | O3: 42277 | P3: 42369 | Q3: 42460 | R3: 42551 | S3: 42643 | T3: 42735 | U3: 42825 | V3: 42916 | W3: 43008 | X3: 43100 | Y3: 43190 | Z3: 43281 | AA3: 43373 | AB3: 43465 | AC3: 43555 | AD3: 43646 | AE3: 43738 | AF3: 43830 | AG3: 43921 | AH3: 44012 | AI3: 44104 | AJ3: 44196 | AK3: 44286 | AL3: 44377 | AM3: 44469 | AN3: 44561 | AO3: 44651 | AP3: 44742 | AQ3: 44834 | AR3: 44926
A4: Documents
A5: 10-Q/10-K | E5: 10-Q | F5: 10-Q | G5: 10-Q | H5: 10-K | I5: 10-Q | J5: 10-Q | K5: 10-Q | L5: 10-K | M5: 10-Q | N5: 10-Q | O5: 10-Q | P5: 10-K | Q5: 10-Q | R5: 10-Q | S5: 10-Q | T5: 10-K | U5: 10-Q | V5: 10-Q | W5: 10-Q | X5: 10-K | Y5: 10-Q | Z5: 10-Q | AA5: 10-Q | AB5: 10-K | AC5: 10-Q | AD5: 10-Q | AE5: 10-Q | AF5: 10-K | AG5: 10-Q | AH5: 10-Q | AI5: 10-Q | AJ5: 10-K | AK5: 10-Q | AL5: 10-Q | AM5: 10-Q | AN5: 10-K | AO5: 10-Q | AP5: 10-Q | AQ5: 10-Q | AR5: 10-K
A6: 8-K | E6: EX-99.1 | F6: EX-99.1 | G6: EX-99.1 | H6: EX-99.1 | I6: EX-99.1 | J6: EX-99.1 | K6: EX-99.1 | L6: EX-99.1 | M6: EX-99.1 | N6: EX-99.1 | O6: EX-99.1 | P6: EX-99.1 | Q6: EX-99.1 | R6: EX-99.1 | S6: EX-99.1 | T6: EX-99.1 | U6: EX-99.1 | V6: EX-99.1 | W6: EX-99.1 | X6: EX-99.1 | Y6: EX-99.1 | Z6: EX-99.1 | AA6: EX-99.1 | AB6: EX-99.1 | AC6: EX-99.1 | AD6: EX-99.1 | AE6: EX-99.1 | AF6: EX-99.1 | AG6: EX-99.1 | AH6: EX-99.1 | AI6: EX-99.1 | AJ6: EX-99.1 | AK6: EX-99.1 | AL6: EX-99.1 | AM6: EX-99.1 | AN6: EX-99.1 | AO6: EX-99.1 | AP6: EX-99.1 | AQ6: EX-99.1 | AR6: EX-99.1
A8: Guidance
A9: Quarterly
A10: Net sales - high | B10: Billion | C10: 8-K | D10: 85882 | E10: 16.2 | F10: 17.15 | G10: 26.5 | H10: 19.9 | I10: 19.8 | J10: 21.5 | K10: 30.3 | L10: 22.9 | M10: 22.8 | N10: 25.5 | O10: 36.75 | P10: 29 | Q10: 30.5 | R10: 33.5 | S10: 45.5 | T10: 35.75 | U10: 37.75 | V10: 41.75 | W10: 60.5 | X10: 50.75 | Y10: 54 | Z10: 57.5 | AA10: 72.5 | AB10: 60 | AC10: 63.5 | AD10: 70 | AE10: 86.5 | AF10: 73 | AG10: 81 | AH10: 93 | AI10: 121 | AJ10: 106 | AK10: 116 | AL10: 112 | AM10: 140 | AN10: 117 | AO10: 121 | AP10: 130 | AQ10: 148 | AR10: 126 | AS10: 133 | AT10: 143 | AU10: 167 | AV10: 143.5 | AW10: 149 | AX10: 158.5 | AY10: 188.5 | AZ10: 155.5 | BA10: 164 | BB10: 179.5 | BC10: 213 | BD10: 178.5 | BR10: 178.5
A11: Net sales - low | B11: Billion | C11: 8-K | D11: 85883 | E11: 14.5 | F11: 15.45 | G11: 23.5 | H11: 18.2 | I11: 18.1 | J11: 19.7 | K11: 27.3 | L11: 20.9 | M11: 20.6 | N11: 23.3 | O11: 33.5 | P11: 26.5 | Q11: 28 | R11: 31 | S11: 42 | T11: 33.25 | U11: 35.25 | V11: 39.25 | W11: 56 | X11: 47.75 | Y11: 51 | Z11: 54 | AA11: 66.5 | AB11: 56 | AC11: 59.5 | AD11: 66 | AE11: 80 | AF11: 69 | AG11: 75 | AH11: 87 | AI11: 112 | AJ11: 100 | AK11: 110 | AL11: 106 | AM11: 130 | AN11: 112 | AO11: 116 | AP11: 125 | AQ11: 140 | AR11: 121 | AS11: 127 | AT11: 138 | AU11: 160 | AV11: 138 | AW11: 144 | AX11: 154 | AY11: 181.5 | AZ11: 151 | BA11: 159 | BB11: 174 | BC11: 206 | BD11: 173.5 | BR11: 173.5
A12: Net sales percentage - high | B12: Percent | C12: 8-K | D12: 85884 | E12: 0.26 | F12: 0.24 | G12: 0.25 | H12: 0.24 | I12: 0.26 | J12: 0.26 | K12: 0.18 | L12: 0.16 | M12: 0.18 | N12: 0.24 | O12: 0.25 | P12: 0.28 | Q12: 0.32 | R12: 0.32 | S12: 0.27 | T12: 0.23 | U12: 0.24 | V12: 0.28 | W12: 0.38 | X12: 0.42 | Y12: 0.42 | Z12: 0.31 | AA12: 0.2 | AB12: 0.18 | AC12: 0.2 | AD12: 0.24 | AE12: 0.2 | AF12: 0.22 | AG12: 0.28 | AH12: 0.33 | AI12: 0.38 | AJ12: 0.4 | AK12: 0.3 | AL12: 0.16 | AM12: 0.12 | AN12: 0.08 | AO12: 0.07 | AP12: 0.17 | AQ12: 0.08 | AR12: 0.08 | AS12: 0.1 | AT12: 0.13 | AU12: 0.12 | AV12: 0.13 | AW12: 0.11 | AX12: 0.11 | AY12: 0.11 | AZ12: 0.09 | BA12: 0.11 | BB12: 0.13 | BC12: 0.13 | BD12: 0.15 | BR12: 0.15
A13: Net sales percentage - low | B13: Percent | C13: 8-K | D13: 85885 | E13: 0.13 | F13: 0.12 | G13: 0.1 | H13: 0.13 | I13: 0.15 | J13: 0.15 | K13: 0.07 | L13: 0.06 | M13: 0.07 | N13: 0.13 | O13: 0.14 | P13: 0.17 | Q13: 0.21 | R13: 0.22 | S13: 0.17 | T13: 0.14 | U13: 0.16 | V13: 0.2 | W13: 0.28 | X13: 0.34 | Y13: 0.34 | Z13: 0.23 | AA13: 0.1 | AB13: 0.1 | AC13: 0.13 | AD13: 0.17 | AE13: 0.11 | AF13: 0.16 | AG13: 0.18 | AH13: 0.24 | AI13: 0.28 | AJ13: 0.33 | AK13: 0.24 | AL13: 0.1 | AM13: 0.04 | AN13: 0.03 | AO13: 0.03 | AP13: 0.13 | AQ13: 0.02 | AR13: 0.04 | AS13: 0.05 | AT13: 0.09 | AU13: 0.07 | AV13: 0.08 | AW13: 0.07 | AX13: 0.08 | AY13: 0.07 | AZ13: 0.05 | BA13: 0.07 | BB13: 0.1 | BC13: 0.1 | BD13: 0.11 | BR13: 0.11
A14: Impact on sales from foreign exchange rates | B14: Billion | C14: 8-K | D14: 85886 | T14: -0.73 | U14: -0.72 | V14: -0.125 | W14: 1.2 | X14: 1.2 | Y14: 1.2 | AZ14: -2.1
A15: Impact on sales from foreign exchange rates (basis point) | B15: Actual | C15: 8-K | D15: 85887 | S15: 60 | T15: 250 | U15: 240 | V15: 40 | W15: 270 | X15: 330 | Y15: 320 | Z15: 30 | AA15: 80 | AB15: 210 | AC15: 150 | AD15: 30 | AE15: 80 | AF15: 5 | AG15: -70 | AH15: -20 | AI15: 90 | AJ15: 300 | AK15: 200 | AL15: 70 | AM15: -60 | AN15: -150 | AO15: -200 | AP15: -390 | AQ15: -460 | AR15: -210 | AS15: -30 | AT15: 120 | AU15: 40 | AV15: 40 | AW15: -60 | AX15: -90 | AY15: -10 | AZ15: -150 | BA15: -10 | BB15: 130 | BC15: 190 | BD15: 180 | BR15: 180
A16: Basis points of impact to YoY growth rate from whole foods market | B16: Actual | C16: 8-K | D16: 85888 | W16: 1000
A17: Operating income - high | B17: Billion | C17: 8-K | D17: 2636319 | E17: 0.01 | F17: -0.065 | G17: 0.5 | H17: 0.2 | I17: -0.055 | J17: -0.41 | K17: 0.43 | L17: 0.05 | M17: 0.05 | N17: 0.07 | O17: 1.28 | P17: 0.7 | Q17: 0.975 | R17: 0.65 | S17: 1.25 | T17: 0.9 | U17: 1.075 | V17: 0.3 | W17: 1.65 | X17: 1 | Y17: 1.9 | Z17: 2.4 | AA17: 3.6 | AB17: 3.3 | AC17: 3.6 | AD17: 3.1 | AE17: 2.9 | AF17: 4.2 | AG17: 1.5 | AH17: 5 | AI17: 4.5 | AJ17: 6.5 | AK17: 8 | AL17: 6 | AM17: 3 | AN17: 6 | AO17: 3 | AP17: 3.5 | AQ17: 4 | AR17: 4 | AS17: 5.5 | AT17: 8.5 | AU17: 11 | AV17: 12 | AW17: 14 | AX17: 15 | AY17: 20 | AZ17: 18 | BA17: 17.5 | BB17: 20.5 | BC17: 26 | BD17: 21.5 | BR17: 21.5
A18: Operating income - low | B18: Billion | C18: 8-K | D18: 2636320 | E18: -0.34 | F18: -0.44 | G18: -0.5 | H18: -0.2 | I18: -0.455 | J18: -0.81 | K18: -0.57 | L18: -0.45 | M18: -0.5 | N18: -0.48 | O18: 0.08 | P18: 0.1 | Q18: 0.375 | R18: 0.05 | S18: 0 | T18: 0.25 | U18: 0.425 | V18: -0.4 | W18: 0.3 | X18: 0.3 | Y18: 1.1 | Z18: 1.4 | AA18: 2.1 | AB18: 2.3 | AC18: 2.6 | AD18: 2.1 | AE18: 1.2 | AF18: 3 | AG18: -1.5 | AH18: 2 | AI18: 1 | AJ18: 3 | AK18: 4.5 | AL18: 2.5 | AM18: 0 | AN18: 3 | AO18: -1 | AP18: 0 | AQ18: 0 | AR18: 0 | AS18: 2 | AT18: 5.5 | AU18: 7 | AV18: 8 | AW18: 10 | AX18: 11.5 | AY18: 16 | AZ18: 14 | BA18: 13 | BB18: 15.5 | BC18: 21 | BD18: 16.5 | BR18: 16.5
A19: Cost related to COVID-19 | B19: Billion | C19: 8-K | D19: 142241 | AG19: 4 | AH19: 2 | AI19: 4 | AJ19: 2 | AK19: 1.5 | AL19: 1
A20: Stock-based compensation and other operating expense (income) | B20: Million | C20: 8-K | D20: 85891 | E20: 340 | F20: 340 | G20: 350 | H20: 350 | I20: 455 | J20: 410 | K20: 470 | L20: 450 | M20: 600 | N20: 580 | O20: 620 | P20: 600 | Q20: 825
A21: Depreciation expenses | B21: Million | C21: 8-K | D21: 85892 | AF21: -800 | AN21: -1000 | AV21: 900
A22: Investments over next year to help delivery service partners (DSP) | B22: Million | C22: 8-K | D22: 3516099 | AQ22: 450
A24: Long-term
A25: Investments over next 5 years to electrify its transport network in Europe (in Billions) | B25: Billion | C25: 8-K | D25: 3516100 | AQ25: 1
A27: KPIs
A28: Prime customers around the world | B28: Million | C28: 8-K | D28: 1182673 | Y28: 100 | Z28: 100 | AF28: 150 | AK28: 200 | AN28: 200
A29: Audible customers downloaded listening hours | B29: Million | C29: PRIVATE | D29: 1139137 | BF29: 600
A30: Smart home devices controllable by Alexa | B30: Actual | C30: 8-K | D30: 1139139 | X30: 4000 | Z30: 13000 | AA30: 20000 | AB30: 28000 | AD30: 60000 | AE30: 85000
A31: Unique brands compatible with Alexa | B31: Actual | C31: 8-K | D31: 1139140 | X31: 1200 | Z31: 2500 | AA31: 3500 | AB31: 4500 | AD31: 7400 | AE31: 9500
A32: Total unearned revenue | B32: Billion | C32: 10-K | D32: 2127453 | AF32: 10.2 | AJ32: 11.6 | AN32: 14 | AR32: 16.1 | AT32: 2.7 | AU32: 2.7 | AV32: 20.6 | AX32: 6.7 | AY32: 7 | AZ32: 24.6
A34: Segmental breakdown
A35: Net sales
A36: Online stores | B36: Million | C36: 8-K | D36: 2640310 | Q36: 19916 | R36: 20378 | S36: 21590 | T36: 29548 | U36: 22826 | V36: 23754 | W36: 26392 | X36: 35383 | Y36: 26939 | Z36: 27165 | AA36: 29061 | AB36: 39822 | AC36: 29498 | AD36: 31053 | AE36: 35039 | AF36: 45657 | AG36: 36652 | AH36: 45896 | AI36: 48350 | AJ36: 66451 | AK36: 52901 | AL36: 53157 | AM36: 49942 | AN36: 66075 | AO36: 51129 | AP36: 50855 | AQ36: 53489 | AR36: 64531 | AS36: 51096 | AT36: 52966 | AU36: 57267 | AV36: 70543 | AW36: 54670 | AX36: 55392 | AY36: 61411 | AZ36: 75556 | BA36: 57407 | BB36: 61485 | BC36: 67407 | BD36: 82988 | BI36: =SUM(Q36,R36,S36,T36) -> 91432 | BJ36: =SUM(U36,V36,W36,X36) -> 108355 | BK36: =SUM(Y36,Z36,AA36,AB36) -> 122987 | BL36: =SUM(AC36,AD36,AE36,AF36) -> 141247 | BM36: =SUM(AG36,AH36,AI36,AJ36) -> 197349 | BN36: =SUM(AK36,AL36,AM36,AN36) -> 222075 | BO36: =SUM(AO36,AP36,AQ36,AR36) -> 220004 | BP36: 231872 | BQ36: 247029 | BR36: 269287
A37: Online stores - Y/Y growth (decline), excluding F/X | B37: Percent | C37: 8-K | D37: 85896 | Q37: 0.21 | R37: 0.22 | S37: 0.2 | T37: 0.16 | U37: 0.16 | V37: 0.18 | W37: 0.22 | X37: 0.17 | Y37: 0.13 | Z37: 0.12 | AA37: 0.11 | AB37: 0.14 | AC37: 0.12 | AD37: 0.16 | AE37: 0.22 | AF37: 0.15 | AG37: 0.25 | AH37: 0.49 | AI37: 0.37 | AJ37: 0.43 | AK37: 0.41 | AL37: 0.13 | AM37: 0.03 | AN37: 0.01 | AO37: -0.01 | AP37: 0 | AQ37: 0.13 | AR37: 0.02 | AS37: 0.03 | AT37: 0.05 | AU37: 0.06 | AV37: 0.08 | AW37: 0.07 | AX37: 0.06 | AY37: 0.08 | AZ37: 0.08 | BA37: 0.06 | BB37: 0.1 | BC37: 0.08 | BD37: 0.08
A38: Physical stores | B38: Million | C38: 8-K | D38: 2640311 | U38: 0 | V38: 0 | W38: 1276 | X38: 4522 | Y38: 4263 | Z38: 4312 | AA38: 4248 | AB38: 4401 | AC38: 4307 | AD38: 4330 | AE38: 4192 | AF38: 4363 | AG38: 4640 | AH38: 3774 | AI38: 3788 | AJ38: 4022 | AK38: 3920 | AL38: 4198 | AM38: 4269 | AN38: 4688 | AO38: 4591 | AP38: 4721 | AQ38: 4694 | AR38: 4957 | AS38: 4895 | AT38: 5024 | AU38: 4959 | AV38: 5152 | AW38: 5202 | AX38: 5206 | AY38: 5228 | AZ38: 5579 | BA38: 5533 | BB38: 5595 | BC38: 5578 | BD38: 5855 | BJ38: =SUM(U38,V38,W38,X38) -> 5798 | BK38: =SUM(Y38,Z38,AA38,AB38) -> 17224 | BL38: =SUM(AC38,AD38,AE38,AF38) -> 17192 | BM38: =SUM(AG38,AH38,AI38,AJ38) -> 16224 | BN38: =SUM(AK38,AL38,AM38,AN38) -> 17075 | BO38: =SUM(AO38,AP38,AQ38,AR38) -> 18963 | BP38: 20030 | BQ38: 21215 | BR38: 22561
A39: Physical stores - Y/Y growth, excluding F/X | B39: Percent | C39: 8-K | D39: 85898 | Y39: 0 | Z39: 0 | AA39: 0 | AB39: -0.03 | AC39: 0.01 | AD39: 0.01 | AE39: -0.01 | AF39: -0.01 | AG39: 0.08 | AH39: -0.13 | AI39: -0.1 | AJ39: -0.07 | AK39: -0.16 | AL39: 0.1 | AM39: 0.12 | AN39: 0.16 | AO39: 0.16 | AP39: 0.13 | AQ39: 0.1 | AR39: 0.06 | AS39: 0.07 | AT39: 0.07 | AU39: 0.06 | AV39: 0.04 | AW39: 0.06 | AX39: 0.04 | AY39: 0.05 | AZ39: 0.08 | BA39: 0.06 | BB39: 0.07 | BC39: 0.07 | BD39: 0.05
A40: Third-party seller services | B40: Million | C40: 8-K | D40: 2640312 | Q40: 4801 | R40: 5083 | S40: 5652 | T40: 7456 | U40: 6438 | V40: 6991 | W40: 7928 | X40: 10523 | Y40: 9265 | Z40: 9702 | AA40: 10395 | AB40: 13383 | AC40: 11141 | AD40: 11962 | AE40: 13212 | AF40: 17446 | AG40: 14479 | AH40: 18195 | AI40: 20436 | AJ40: 27327 | AK40: 23709 | AL40: 25085 | AM40: 24252 | AN40: 30320 | AO40: 25335 | AP40: 27376 | AQ40: 28666 | AR40: 36339 | AS40: 29820 | AT40: 32332 | AU40: 34342 | AV40: 43559 | AW40: 34596 | AX40: 36201 | AY40: 37864 | AZ40: 47485 | BA40: 36512 | BB40: 40348 | BC40: 42486 | BD40: 52816 | BI40: =SUM(Q40,R40,S40,T40) -> 22992 | BJ40: =SUM(U40,V40,W40,X40) -> 31880 | BK40: =SUM(Y40,Z40,AA40,AB40) -> 42745 | BL40: =SUM(AC40,AD40,AE40,AF40) -> 53761 | BM40: =SUM(AG40,AH40,AI40,AJ40) -> 80437 | BN40: =SUM(AK40,AL40,AM40,AN40) -> 103366 | BO40: =SUM(AO40,AP40,AQ40,AR40) -> 117716 | BP40: 140053 | BQ40: 156146 | BR40: 172162
A41: Third-party seller services - Y/Y growth, excluding F/X | B41: Percent | C41: 8-K | D41: 85900 | Q41: 0.46 | R41: 0.48 | S41: 0.46 | T41: 0.39 | U41: 0.36 | V41: 0.4 | W41: 0.4 | X41: 0.38 | Y41: 0.39 | Z41: 0.36 | AA41: 0.32 | AB41: 0.28 | AC41: 0.23 | AD41: 0.25 | AE41: 0.28 | AF41: 0.31 | AG41: 0.31 | AH41: 0.53 | AI41: 0.53 | AJ41: 0.54 | AK41: 0.6 | AL41: 0.34 | AM41: 0.18 | AN41: 0.12 | AO41: 0.09 | AP41: 0.13 | AQ41: 0.23 | AR41: 0.24 | AS41: 0.2 | AT41: 0.18 | AU41: 0.18 | AV41: 0.19 | AW41: 0.16 | AX41: 0.13 | AY41: 0.1 | AZ41: 0.09 | BA41: 0.07 | BB41: 0.1 | BC41: 0.11 | BD41: 0.1
A42: Subscription services | B42: Million | C42: 8-K | D42: 2640313 | Q42: 1300 | R42: 1431 | S42: 1532 | T42: 2130 | U42: 1939 | V42: 2165 | W42: 2441 | X42: 3177 | Y42: 3102 | Z42: 3408 | AA42: 3698 | AB42: 3959 | AC42: 4342 | AD42: 4676 | AE42: 4957 | AF42: 5235 | AG42: 5556 | AH42: 6018 | AI42: 6572 | AJ42: 7061 | AK42: 7580 | AL42: 7917 | AM42: 8148 | AN42: 8123 | AO42: 8410 | AP42: 8716 | AQ42: 8903 | AR42: 9189 | AS42: 9657 | AT42: 9894 | AU42: 10170 | AV42: 10488 | AW42: 10722 | AX42: 10866 | AY42: 11278 | AZ42: 11508 | BA42: 11715 | BB42: 12208 | BC42: 12574 | BD42: 13122 | BI42: =SUM(Q42,R42,S42,T42) -> 6393 | BJ42: =SUM(U42,V42,W42,X42) -> 9722 | BK42: =SUM(Y42,Z42,AA42,AB42) -> 14167 | BL42: =SUM(AC42,AD42,AE42,AF42) -> 19210 | BM42: =SUM(AG42,AH42,AI42,AJ42) -> 25207 | BN42: =SUM(AK42,AL42,AM42,AN42) -> 31768 | BO42: =SUM(AO42,AP42,AQ42,AR42) -> 35218 | BP42: 40209 | BQ42: 44374 | BR42: 49619
A43: Subscription services - Y/Y growth, excluding F/X | B43: Percent | C43: 8-K | D43: 85902 | Q43: 0.56 | R43: 0.52 | S43: 0.47 | T43: 0.33 | U43: 0.52 | V43: 0.53 | W43: 0.59 | X43: 0.47 | Y43: 0.56 | Z43: 0.55 | AA43: 0.52 | AB43: 0.26 | AC43: 0.42 | AD43: 0.39 | AE43: 0.35 | AF43: 0.32 | AG43: 0.29 | AH43: 0.3 | AI43: 0.32 | AJ43: 0.34 | AK43: 0.34 | AL43: 0.28 | AM43: 0.23 | AN43: 0.16 | AO43: 0.13 | AP43: 0.14 | AQ43: 0.14 | AR43: 0.17 | AS43: 0.17 | AT43: 0.14 | AU43: 0.13 | AV43: 0.13 | AW43: 0.11 | AX43: 0.11 | AY43: 0.11 | AZ43: 0.1 | BA43: 0.11 | BB43: 0.11 | BC43: 0.1 | BD43: 0.12
A44: Advertising services | B44: Million | C44: 8-K | D44: 2489617 | AN44: 9716 | AO44: 7877 | AP44: 8757 | AQ44: 9548 | AR44: 11557 | AS44: 9509 | AT44: 10683 | AU44: 12060 | AV44: 14654 | AW44: 11824 | AX44: 12771 | AY44: 14331 | AZ44: 17288 | BA44: 13921 | BB44: 15694 | BC44: 17703 | BD44: 21317 | BO44: 37739 | BP44: 46906 | BQ44: 56214 | BR44: 68635
...
