Workbook
Name a: Daloopa!$A$2
Name IQ_CH: 110000
Name IQ_CQ: 5000
Name IQ_CY: 10000
Name IQ_DAILY: 500000
Name IQ_FH: 100000
Name IQ_FQ: 500
Name IQ_FY: 1000
Name IQ_LTM: 2000
Name IQ_MONTH: 15000
Name IQ_NTM: 6000
Name IQ_WEEK: 50000
Name IQ_YTD: 3000

Sheet How to Use 
A1: Instructions
A2: Tab | B2: Details
A3: Color Code | B3: Just familiarize yourself with the color code conventions used in this file. I will maintain these color code conventions in every model.
A4: Model | B4: The most important worksheet in this file is the "Model" Worksheet.
B5: If you want to change the assumptions, just change the cells that are filled yellow. Since the rest of the cells are formula driven, they will automatically be changed.
B6: I have made a few comments here and there whenever I thought it might be helpful for subscribers
B7: Please let me know asap if you think there has been any error/mistake (conceptual or otherwise) in the model
A9: Segment | B9: Alphabet only reported these segments from 2019, and operating income by segments from 2020. 2017-2018 as well as 2023-2030 are my personal estimates.
A10: Valuation | B10: Just change the current stock price and choose your multiple to run your valuation estimates.
A11: Daloopa | B11: database from company filings. Feel free to sign up for this by clicking below link (not a paid promotion; I don't get paid if you do so but I do get complimentary access to it)
B12: https://daloopa.com/?utm_source=MBI&utm_medium=Organic&utm_campaign=SourceLink

Sheet Color Code
A1: Color | B1: Meaning
A2: Black | B2: Formula driven (both historical and forecasts)
A3: Blue | B3: Hard coded numbers (Actual for Historical, estimated for forecasts)
A4: Yellow | B4: Indication that there has been explicit assumption made in these cells. Change the numbers in these cells to drive your narrative.

Sheet Model
B1: 2016 | C1: 2017 | D1: 2018 | E1: 2019 | F1: 2020 | G1: 2021 | H1: 2022 | I1: 2023 | J1: 2024 | K1: 2025 | L1: 2026 | M1: 2027 | N1: 2028 | O1: 2029 | P1: 2030
A2: Revenue | B2: =Daloopa!AW275 -> 90272 | C2: =Daloopa!AX275 -> 110855 | D2: =Daloopa!AY275 -> 136819 | E2: =Daloopa!AZ275 -> 161857 | F2: =Daloopa!BA275 -> 182527 | G2: =Daloopa!BB275 -> 257637 | H2: =Daloopa!BC275 -> 282836 | I2: =I42 -> 299512.45 | J2: =J42 -> 325856.97 | K2: =K42 -> 361873.68 | L2: =L42 -> 394974.85 | M2: =M42 -> 428349.53 | N2: =N42 -> 460460.35 | O2: =O42 -> 490454.91 | P2: =P42 -> 520370.4
A3: Growth $ | C3: =C2-B2 -> 20583 | D3: =D2-C2 -> 25964 | E3: =E2-D2 -> 25038 | F3: =F2-E2 -> 20670 | G3: =G2-F2 -> 75110 | H3: =H2-G2 -> 25199 | I3: =I2-H2 -> 16676.45 | J3: =J2-I2 -> 26344.52 | ... P3: =P2-O2 -> 29915.487
A4: Growth % | C4: =C2/B2-1 -> 0.2280109 | D4: =D2/C2-1 -> 0.23421587 | E4: =E2/D2-1 -> 0.1830009 | F4: =F2/E2-1 -> 0.12770532 | G4: =G2/F2-1 -> 0.41150076 | H4: =H2/G2-1 -> 0.097808156 | I4: =I2/H2-1 -> 0.058961554 | J4: =J2/I2-1 -> 0.087958013 | ... P4: =P2/O2-1 -> 0.060995387
A6: Segments
A8: Google Search & Other | C8: =C28-C12-C16-C24 -> 69210 | D8: =D28-D12-D16-D24 -> 85161 | E8: =Daloopa!AZ80 -> 98115 | F8: =Daloopa!BA80 -> 104062 | G8: =Daloopa!BB80 -> 148951 | H8: =Daloopa!BC80 -> 162450 | I8: =H8*(1+I10) -> 170572.5 | J8: =I8*(1+J10) -> 182512.58 | K8: =J8*(1+K10) -> 200763.83 | L8: =K8*(1+L10) -> 216824.94 | M8: =L8*(1+M10) -> 232002.68 | N8: =M8*(1+N10) -> 245922.85 | O8: =N8*(1+O10) -> 258218.99 | P8: =O8*(1+P10) -> 271129.94
A9: Growth | D9: =D8-C8 -> 15951 | E9: =E8-D8 -> 12954 | F9: =F8-E8 -> 5947 | G9: =G8-F8 -> 44889 | H9: =H8-G8 -> 13499 | I9: =I8-H8 -> 8122.5 | J9: =J8-I8 -> 11940.075 | K9: =K8-J8 -> 18251.258 | ... P9: =P8-O8 -> 12910.949
A10: Growth % | D10: =D8/C8-1 -> 0.23047248 | E10: =E8/D8-1 -> 0.15211188 | F10: =F8/E8-1 -> 0.060612547 | G10: =G8/F8-1 -> 0.43136784 | H10: =H8/G8-1 -> 0.090627119 | I10: 0.05 | J10: 0.07 | K10: 0.1 | L10: 0.08 | M10: 0.07 | N10: 0.06 | O10: 0.05 | P10: 0.05
A12: YouTube Ads | C12: =D12-D13 -> 9649 | D12: =E12-E13 -> 12149 | E12: =Daloopa!AZ81 -> 15149 | F12: =Daloopa!BA81 -> 19772 | G12: =Daloopa!BB81 -> 28845 | H12: =Daloopa!BC81 -> 29243 | I12: =H12*(1+I14) -> 30705.15 | J12: =I12*(1+J14) -> 33775.665 | K12: =J12*(1+K14) -> 37828.745 | L12: =K12*(1+L14) -> 41989.907 | M12: =L12*(1+M14) -> 46188.897 | N12: =M12*(1+N14) -> 50345.898 | O12: =N12*(1+O14) -> 54373.57 | P12: =O12*(1+P14) -> 58179.72
A13: =A9 -> Growth | D13: 2500 | E13: 3000 | F13: =F12-E12 -> 4623 | G13: =G12-F12 -> 9073 | H13: =H12-G12 -> 398 | I13: =I12-H12 -> 1462.15 | J13: =J12-I12 -> 3070.515 | K13: =K12-J12 -> 4053.0798 | L13: =L12-K12 -> 4161.1619 | M13: =M12-L12 -> 4198.9907 | ... P13: =P12-O12 -> 3806.1499
A14: =A10 -> Growth % | D14: =D12/C12-1 -> 0.25909421 | E14: =E12/D12-1 -> 0.2469339 | F14: =F12/E12-1 -> 0.30516866 | G14: =G12/F12-1 -> 0.45888125 | H14: =H12/G12-1 -> 0.013797885 | I14: 0.05 | J14: 0.1 | K14: 0.12 | L14: 0.11 | M14: 0.1 | N14: 0.09 | O14: 0.08 | P14: 0.07
A16: Google Network | C16: =Daloopa!AX84 -> 17587 | D16: =Daloopa!AY84 -> 19982 | E16: =Daloopa!AZ84 -> 21547 | F16: =Daloopa!BA84 -> 23090 | G16: =Daloopa!BB84 -> 31701 | H16: =Daloopa!BC84 -> 32780 | I16: =H16*(1+I18) -> 34091.2 | J16: =I16*(1+J18) -> 35795.76 | K16: =J16*(1+K18) -> 37585.548 | L16: =K16*(1+L18) -> 39088.97 | M16: =L16*(1+M18) -> 40652.529 | N16: =M16*(1+N18) -> 42278.63 | O16: =N16*(1+O18) -> 43969.775 | P16: =O16*(1+P18) -> 45288.868
A17: =A13 -> Growth | D17: =D16-C16 -> 2395 | E17: =E16-D16 -> 1565 | F17: =F16-E16 -> 1543 | G17: =G16-F16 -> 8611 | H17: =H16-G16 -> 1079 | I17: =I16-H16 -> 1311.2 | J17: =J16-I16 -> 1704.56 | K17: =K16-J16 -> 1789.788 | ... P17: =P16-O16 -> 1319.0933
A18: =A14 -> Growth % | D18: =D16/C16-1 -> 0.13618013 | E18: =E16/D16-1 -> 0.078320488 | F18: =F16/E16-1 -> 0.071610897 | G18: =G16/F16-1 -> 0.37293201 | H18: =H16/G16-1 -> 0.034036781 | I18: 0.04 | J18: 0.05 | K18: 0.05 | L18: 0.04 | M18: 0.04 | N18: 0.04 | O18: 0.04 | P18: 0.03
A20: Google Advertising | C20: =C8+C12+C16 -> 96446 | D20: =D8+D12+D16 -> 117292 | E20: =E8+E12+E16 -> 134811 | F20: =F8+F12+F16 -> 146924 | G20: =G8+G12+G16 -> 209497 | H20: =H8+H12+H16 -> 224473 | I20: =I8+I12+I16 -> 235368.85 | J20: =J8+J12+J16 -> 252084 | ... P20: =P8+P12+P16 -> 374598.53
A21: =A17 -> Growth | D21: =D20-C20 -> 20846 | E21: =E20-D20 -> 17519 | F21: =F20-E20 -> 12113 | G21: =G20-F20 -> 62573 | H21: =H20-G20 -> 14976 | I21: =I20-H20 -> 10895.85 | J21: =J20-I20 -> 16715.15 | K21: =K20-J20 -> 24094.125 | ... P21: =P20-O20 -> 18036.193
A22: =A18 -> Growth % | D22: =D20/C20-1 -> 0.21614168 | E22: =E20/D20-1 -> 0.14936228 | F22: =F20/E20-1 -> 0.089851718 | G22: =G20/F20-1 -> 0.42588685 | H22: =H20/G20-1 -> 0.071485511 | I22: =I20/H20-1 -> 0.048539691 | J22: =J20/I20-1 -> 0.071016832 | K22: =K20/J20-1 -> 0.095579748 | ... P22: =P20/O20-1 -> 0.050583561
A24: Google Other | C24: =D24-D25 -> 11014 | D24: =E24-E25 -> 13514 | E24: =Daloopa!AZ88 -> 17014 | F24: =Daloopa!BA88 -> 21711 | G24: =Daloopa!BB88 -> 28032 | H24: =Daloopa!BC88 -> 29055 | I24: =H24*(1+I26) -> 31379.4 | J24: =I24*(1+J26) -> 34517.34 | K24: =J24*(1+K26) -> 38659.421 | L24: =K24*(1+L26) -> 42525.363 | M24: =L24*(1+M26) -> 46777.899 | N24: =M24*(1+N26) -> 50987.91 | O24: =N24*(1+O26) -> 55066.943 | P24: =O24*(1+P26) -> 58921.629
A25: =A21 -> Growth | D25: 2500 | E25: 3500 | F25: =F24-E24 -> 4697 | G25: =G24-F24 -> 6321 | H25: =H24-G24 -> 1023 | I25: =I24-H24 -> 2324.4 | J25: =J24-I24 -> 3137.94 | K25: =K24-J24 -> 4142.0808 | L25: =L24-K24 -> 3865.9421 | M25: =M24-L24 -> 4252.5363 | ... P25: =P24-O24 -> 3854.686
A26: =A22 -> Growth % | F26: =F24/E24-1 -> 0.27606677 | G26: =G24/F24-1 -> 0.29114274 | H26: =H24/G24-1 -> 0.036494007 | I26: 0.08 | J26: 0.1 | K26: 0.12 | L26: 0.1 | M26: 0.1 | N26: 0.09 | O26: 0.08 | P26: 0.07
A28: Google Services | C28: =C2-C32-C36 -> 107460 | D28: =D2-D32-D36 -> 130806 | E28: =E20+E24 -> 151825 | F28: =F20+F24 -> 168635 | G28: =G20+G24 -> 237529 | H28: =H20+H24 -> 253528 | I28: =I20+I24 -> 266748.25 | J28: =J20+J24 -> 286601.34 | K28: =K20+K24 -> 314837.55 | L28: =L20+L24 -> 340429.18 | ... P28: =P20+P24 -> 433520.15
A29: =A25 -> Growth | D29: =D28-C28 -> 23346 | E29: =E28-D28 -> 21019 | F29: =F28-E28 -> 16810 | G29: =G28-F28 -> 68894 | H29: =H28-G28 -> 15999 | I29: =I28-H28 -> 13220.25 | J29: =J28-I28 -> 19853.09 | K29: =K28-J28 -> 28236.206 | ... P29: =P28-O28 -> 21890.879
A30: =A26 -> Growth % | F30: =F28/E28-1 -> 0.11071958 | G30: =G28/F28-1 -> 0.40853915 | H30: =H28/G28-1 -> 0.067355986 | I30: =I28/H28-1 -> 0.052145128 | J30: =J28/I28-1 -> 0.074426318 | K30: =K28/J28-1 -> 0.098520845 | L30: =L28/K28-1 -> 0.081285199 | M30: =M28/L28-1 -> 0.07400315 | ... P30: =P28/O28-1 -> 0.053181054
A32: Google Cloud | C32: =D32-D33 -> 2918 | D32: =E32-E33 -> 5418 | E32: 8918 | F32: =Daloopa!BA93 -> 13059 | G32: =Daloopa!BB93 -> 19206 | H32: =Daloopa!BC93 -> 26280 | I32: =H32*(1+I34) -> 31536 | J32: =I32*(1+J34) -> 37843.2 | K32: =J32*(1+K34) -> 45411.84 | L32: =K32*(1+L34) -> 52677.734 | M32: =L32*(1+M34) -> 60579.395 | N32: =M32*(1+N34) -> 68454.716 | O32: =N32*(1+O34) -> 75984.735 | P32: =O32*(1+P34) -> 83583.208
A33: =A29 -> Growth | D33: 2500 | E33: 3500 | F33: =F32-E32 -> 4141 | G33: =G32-F32 -> 6147 | H33: =H32-G32 -> 7074 | I33: =I32-H32 -> 5256 | J33: =J32-I32 -> 6307.2 | K33: =K32-J32 -> 7568.64 | L33: =L32-K32 -> 7265.8944 | M33: =M32-L32 -> 7901.6602 | ... P33: =P32-O32 -> 7598.4735
A34: =A30 -> Growth % | F34: =F32/E32-1 -> 0.46434178 | G34: =G32/F32-1 -> 0.47070986 | H34: =H32/G32-1 -> 0.3683224 | I34: 0.2 | J34: 0.2 | K34: 0.2 | L34: 0.16 | M34: 0.15 | N34: 0.13 | O34: 0.11 | P34: 0.1
A36: Other bets | C36: 477 | D36: 595 | E36: =Daloopa!AZ94 -> 659 | F36: =Daloopa!BA94 -> 657 | G36: =Daloopa!BB94 -> 753 | H36: =Daloopa!BC94 -> 1068 | I36: =H36*(1+I38) -> 1228.2 | J36: =I36*(1+J38) -> 1412.43 | K36: =J36*(1+K38) -> 1624.2945 | L36: =K36*(1+L38) -> 1867.9387 | M36: =L36*(1+M38) -> 2148.1295 | N36: =M36*(1+N38) -> 2470.3489 | O36: =N36*(1+O38) -> 2840.9012 | P36: =O36*(1+P38) -> 3267.0364
A37: =A33 -> Growth | D37: =D36-C36 -> 118 | E37: =E36-D36 -> 64 | F37: =F36-E36 -> -2 | G37: =G36-F36 -> 96 | H37: =H36-G36 -> 315 | I37: =I36-H36 -> 160.2 | J37: =J36-I36 -> 184.23 | K37: =K36-J36 -> 211.8645 | ... P37: =P36-O36 -> 426.13518
A38: =A34 -> Growth % | F38: =F36/E36-1 -> -0.0030349014 | G38: =G36/F36-1 -> 0.14611872 | H38: =H36/G36-1 -> 0.41832669 | I38: 0.15 | J38: 0.15 | K38: 0.15 | L38: 0.15 | M38: 0.15 | N38: 0.15 | O38: 0.15 | P38: 0.15
A40: Hedging Gains | E40: =Daloopa!AZ95 -> 455 | F40: =Daloopa!BA95 -> 176 | G40: =Daloopa!BB95 -> 149 | H40: =Daloopa!BC95 -> 1960
A42: Total revenues | C42: =C28+C32+C36+C40 -> 110855 | D42: =D28+D32+D36+D40 -> 136819 | E42: =E28+E32+E36+E40 -> 161857 | F42: =F28+F32+F36+F40 -> 182527 | G42: =G28+G32+G36+G40 -> 257637 | H42: =H28+H32+H36+H40 -> 282836 | I42: =I28+I32+I36+I40 -> 299512.45 | J42: =J28+J32+J36+J40 -> 325856.97 | ... P42: =P28+P32+P36+P40 -> 520370.4
A43: Growth | D43: =D42-C42 -> 25964 | E43: =E42-D42 -> 25038 | F43: =F42-E42 -> 20670 | G43: =G42-F42 -> 75110 | H43: =H42-G42 -> 25199 | I43: =I42-H42 -> 16676.45 | J43: =J42-I42 -> 26344.52 | K43: =K42-J42 -> 36016.711 | ... P43: =P42-O42 -> 29915.487
A44: Growth % | D44: =D42/C42-1 -> 0.23421587 | E44: =E42/D42-1 -> 0.1830009 | F44: =F42/E42-1 -> 0.12770532 | G44: =G42/F42-1 -> 0.41150076 | H44: =H42/G42-1 -> 0.097808156 | I44: =I42/H42-1 -> 0.058961554 | J44: =J42/I42-1 -> 0.087958013 | K44: =K42/J42-1 -> 0.1105292 | ... P44: =P42/O42-1 -> 0.060995387
A46: Cost of revenue | B46: =Daloopa!AW279 -> 35138 | C46: =Daloopa!AX279 -> 45583 | D46: =Daloopa!AY279 -> 59549 | E46: =Daloopa!AZ279 -> 71896 | F46: =Daloopa!BA279 -> 84732 | G46: =Daloopa!BB279 -> 110939 | H46: =Daloopa!BC279 -> 126203 | I46: =Segment!H28 -> 134742.37 | J46: =Segment!I28 -> 146942.56 | K46: =Segment!J28 -> 163256.16 | L46: =Segment!K28 -> 178732.58 | M46: =Segment!L28 -> 194461.47 | N46: =Segment!M28 -> 207393.29 | O46: =Segment!N28 -> 219334.47 | P46: =Segment!O28 -> 230854.86
A47: As % of revenue | B47: =B46/B2 -> 0.38924583 | C47: =C46/C2 -> 0.4111948 | D47: =D46/D2 -> 0.43523926 | E47: =E46/E2 -> 0.44419457 | F47: =F46/F2 -> 0.46421625 | G47: =G46/G2 -> 0.43060197 | H47: =H46/H2 -> 0.44620557 | I47: =I46/I2 -> 0.44987234 | ... P47: =P46/P2 -> 0.44363566
A49: Gross Profit | B49: =B2-B46 -> 55134 | C49: =C2-C46 -> 65272 | D49: =D2-D46 -> 77270 | E49: =E2-E46 -> 89961 | F49: =F2-F46 -> 97795 | G49: =G2-G46 -> 146698 | H49: =H2-H46 -> 156633 | I49: =I2-I46 -> 164770.08 | ... P49: =P2-P46 -> 289515.54
A50: Gross Margin | B50: =B49/B2 -> 0.61075417 | C50: =C49/C2 -> 0.5888052 | D50: =D49/D2 -> 0.56476074 | E50: =E49/E2 -> 0.55580543 | F50: =F49/F2 -> 0.53578375 | G50: =G49/G2 -> 0.56939803 | H50: =H49/H2 -> 0.55379443 | I50: =I49/I2 -> 0.55012766 | ... P50: =P49/P2 -> 0.55636434
A52: R&D | B52: =Daloopa!AW280 -> 13948 | C52: =Daloopa!AX280 -> 16625 | D52: =Daloopa!AY280 -> 21419 | E52: =Daloopa!AZ280 -> 26018 | F52: =Daloopa!BA280 -> 27573 | G52: =Daloopa!BB280 -> 31562 | H52: =Daloopa!BC280 -> 39500 | I52: =Segment!H76 -> 43000 | J52: =Segment!I76 -> 46500 | K52: =Segment!J76 -> 50000 | L52: =Segment!K76 -> 53500 | M52: =Segment!L76 -> 57000 | N52: =Segment!M76 -> 60500 | O52: =Segment!N76 -> 64000 | P52: =Segment!O76 -> 67500
A53: As % of revenue | B53: =B52/B2 -> 0.15451081 | C53: =C52/C2 -> 0.14997068 | D53: =D52/D2 -> 0.15654989 | E53: =E52/E2 -> 0.16074683 | F53: =F52/F2 -> 0.15106258 | G53: =G52/G2 -> 0.1225057 | H53: =H52/H2 -> 0.1396569 | I53: =I52/I2 -> 0.14356665 | ... P53: =P52/P2 -> 0.1297153
A55: Sales & Marketing | B55: =Daloopa!AW281 -> 10485 | C55: =Daloopa!AX281 -> 12893 | D55: =Daloopa!AY281 -> 16333 | E55: =Daloopa!AZ281 -> 18464 | F55: =Daloopa!BA281 -> 17946 | G55: =Daloopa!BB281 -> 22912 | H55: =Daloopa!BC281 -> 26567 | I55: =Segment!H91 -> 29167 | J55: =Segment!I91 -> 31767 | K55: =Segment!J91 -> 34367 | L55: =Segment!K91 -> 36967 | M55: =Segment!L91 -> 39567 | N55: =Segment!M91 -> 42167 | O55: =Segment!N91 -> 44767 | P55: =Segment!O91 -> 47367
...

Sheet Segment
A1: Segment | B1: 2017 | C1: 2018 | D1: 2019 | E1: 2020 | F1: 2021 | G1: 2022 | H1: 2023 | I1: 2024 | J1: 2025 | K1: 2026 | L1: 2027 | M1: 2028 | N1: 2029 | O1: 2030
A3: Revenue
A4: =Model!A8 -> Google Search & Other | B4: =Model!C8 -> 69210 | C4: =Model!D8 -> 85161 | D4: =Model!E8 -> 98115 | E4: =Model!F8 -> 104062 | F4: =Model!G8 -> 148951 | G4: =Model!H8 -> 162450 | H4: =Model!I8 -> 170572.5 | I4: =Model!J8 -> 182512.58 | ... O4: =Model!P8 -> 271129.94
A5: =Model!A12 -> YouTube Ads | B5: =Model!C12 -> 9649 | C5: =Model!D12 -> 12149 | D5: =Model!E12 -> 15149 | E5: =Model!F12 -> 19772 | F5: =Model!G12 -> 28845 | G5: =Model!H12 -> 29243 | H5: =Model!I12 -> 30705.15 | I5: =Model!J12 -> 33775.665 | ... O5: =Model!P12 -> 58179.72
A6: =Model!A16 -> Google Network | B6: =Model!C16 -> 17587 | C6: =Model!D16 -> 19982 | D6: =Model!E16 -> 21547 | E6: =Model!F16 -> 23090 | F6: =Model!G16 -> 31701 | G6: =Model!H16 -> 32780 | H6: =Model!I16 -> 34091.2 | I6: =Model!J16 -> 35795.76 | ... O6: =Model!P16 -> 45288.868
A7: =Model!A20 -> Google Advertising | B7: =B4+B5+B6 -> 96446 | C7: =C4+C5+C6 -> 117292 | D7: =D4+D5+D6 -> 134811 | E7: =E4+E5+E6 -> 146924 | F7: =F4+F5+F6 -> 209497 | G7: =G4+G5+G6 -> 224473 | H7: =H4+H5+H6 -> 235368.85 | I7: =I4+I5+I6 -> 252084 | ... O7: =O4+O5+O6 -> 374598.53
A8: Google Other | B8: =Model!C24 -> 11014 | C8: =Model!D24 -> 13514 | D8: =Model!E24 -> 17014 | E8: =Model!F24 -> 21711 | F8: =Model!G24 -> 28032 | G8: =Model!H24 -> 29055 | H8: =Model!I24 -> 31379.4 | I8: =Model!J24 -> 34517.34 | ... O8: =Model!P24 -> 58921.629
A9: =Model!A28 -> Google Services | B9: =B7+B8 -> 107460 | C9: =C7+C8 -> 130806 | D9: =D7+D8 -> 151825 | E9: =E7+E8 -> 168635 | F9: =F7+F8 -> 237529 | G9: =G7+G8 -> 253528 | H9: =H7+H8 -> 266748.25 | I9: =I7+I8 -> 286601.34 | ... O9: =O7+O8 -> 433520.15
A10: =Model!A32 -> Google Cloud | B10: =Model!C32 -> 2918 | C10: =Model!D32 -> 5418 | D10: =Model!E32 -> 8918 | E10: =Model!F32 -> 13059 | F10: =Model!G32 -> 19206 | G10: =Model!H32 -> 26280 | H10: =Model!I32 -> 31536 | I10: =Model!J32 -> 37843.2 | ... O10: =Model!P32 -> 83583.208
A11: =Model!A36 -> Other bets | B11: =Model!C36 -> 477 | C11: =Model!D36 -> 595 | D11: =Model!E36 -> 659 | E11: =Model!F36 -> 657 | F11: =Model!G36 -> 753 | G11: =Model!H36 -> 1068 | H11: =Model!I36 -> 1228.2 | I11: =Model!J36 -> 1412.43 | ... O11: =Model!P36 -> 3267.0364
A12: =Model!A40 -> Hedging Gains | B12: =Model!C40 -> 0 | C12: =Model!D40 -> 0 | D12: =Model!E40 -> 455 | E12: =Model!F40 -> 176 | F12: =Model!G40 -> 149 | G12: =Model!H40 -> 1960 | H12: =Model!I40 -> 0 | I12: =Model!J40 -> 0 | ... O12: =Model!P40 -> 0
A13: =Model!A42 -> Total revenues | B13: =Model!C2 -> 110855 | C13: =Model!D2 -> 136819 | D13: =Model!E2 -> 161857 | E13: =Model!F2 -> 182527 | F13: =Model!G2 -> 257637 | G13: =Model!H2 -> 282836 | H13: =Model!I2 -> 299512.45 | I13: =Model!J2 -> 325856.97 | ... O13: =Model!P2 -> 520370.4
A15: Operating Income | B15: =Model!C70 -> 26146 | C15: =Model!D70 -> 26321 | D15: =Model!E70 -> 34231 | E15: =E18+E20+E22+E24 -> 41224 | F15: =F18+F20+F22+F24 -> 78714 | G15: =G18+G20+G22+G24 -> 74842 | H15: =H18+H20+H22+H24 -> 75590.601 | I15: =I18+I20+I22+I24 -> 82136.392 | J15: =J18+J20+J22+J24 -> 94157.142 | K15: =K18+K20+K22+K24 -> 104125.98 | L15: =L18+L20+L22+L24 -> 114119.85 | ... O15: =O18+O20+O22+O24 -> 146868.33
A16: Operating Margin | B16: =B15/Model!C2 -> 0.23585765 | C16: =C15/Model!D2 -> 0.19237825 | D16: =D15/Model!E2 -> 0.21148915 | E16: =E15/Model!F2 -> 0.22585152 | F16: =F15/Model!G2 -> 0.30552289 | G16: =G15/Model!H2 -> 0.26461271 | H16: =H15/Model!I2 -> 0.25237883 | I16: =I15/Model!J2 -> 0.25206271 | ... O16: =O15/Model!P2 -> 0.28223806
A17: Operating Income Breakdown
A18: =A9 -> Google Services | B18: =B9-B130 -> 36469.54 | C18: =C9-C130 -> 41223.44 | D18: =D9-D130 -> 47217.72 | E18: =Daloopa!BA108 -> 54606 | F18: =Daloopa!BB108 -> 91855 | G18: =Daloopa!BC108 -> 86572 | H18: =H9-H130 -> 86825.5 | I18: =I9-I130 -> 92446.502 | J18: =J9-J130 -> 102704.67 | K18: =K9-K130 -> 111028.63 | L18: =L9-L130 -> 118865.36 | M18: =M9-M130 -> 128226.22 | N18: =N9-N130 -> 136633.95 | O18: =O9-O130 -> 145264.47
A19: Margin | B19: =B18/B9 -> 0.33937782 | C19: =C18/C9 -> 0.31514946 | D19: =D18/D9 -> 0.31100096 | E19: =E18/E9 -> 0.32381178 | F19: =F18/F9 -> 0.38671068 | G19: =G18/G9 -> 0.34146919 | H19: =H18/H9 -> 0.32549604 | I19: =I18/I9 -> 0.3225613 | ... O19: =O18/O9 -> 0.33508123
A20: =A10 -> Google Cloud | B20: =B10-B134 -> -2130.14 | C20: =C10-C134 -> -3142.44 | D20: =D10-D134 -> -4013.1 | E20: =Daloopa!BA109 -> -5607 | F20: =Daloopa!BB109 -> -3099 | G20: =Daloopa!BC109 -> -2968 | H20: =H10-H134 -> -2187.88 | I20: =I10-I134 -> -738.608 | J20: =J10-J134 -> 1609.44 | K20: =K10-K134 -> 3786.4367 | L20: =L10-L134 -> 6440.0307 | M20: =M10-M134 -> 9114.8275 | N20: =N10-N134 -> 11588.152 | O20: =O10-O134 -> 14147.046
A21: Margin | B21: =B20/B10 -> -0.73 | C21: =C20/C10 -> -0.58 | D21: =D20/D10 -> -0.45 | E21: =E20/E10 -> -0.42935906 | F21: =F20/F10 -> -0.16135583 | G21: =G20/G10 -> -0.1129376 | H21: =H20/H10 -> -0.06937722 | I21: =I20/I10 -> -0.019517588 | ... O21: =O20/O10 -> 0.16925703
A22: =A11 -> Other bets | B22: =Daloopa!AX110 -> -3355 | C22: =Daloopa!AY110 -> -3358 | D22: =Daloopa!AZ110 -> -4824 | E22: =Daloopa!BA110 -> -4476 | F22: =Daloopa!BB110 -> -5281 | G22: =Daloopa!BC110 -> -6083 | H22: =H11-H138 -> -6379.536 | I22: =I11-I138 -> -6705.4878 | J22: =J11-J138 -> -7008.5951 | K22: =K11-K138 -> -7284.7956 | L22: =L11-L138 -> -7529.3223 | M22: =M11-M138 -> -7785.9907 | N22: =N11-N138 -> -8013.6593 | O22: =O11-O138 -> -8207.9781
A23: Margin | B23: =B22/B11 -> -7.033543 | C23: =C22/C11 -> -5.6436975 | D23: =D22/D11 -> -7.3201821 | E23: =E22/E11 -> -6.8127854 | F23: =F22/F11 -> -7.0132802 | G23: =G22/G11 -> -5.6956929 | H23: =H22/H11 -> -5.1942159 | I23: =I22/I11 -> -4.7474833 | ... O23: =O22/O11 -> -2.512362
A24: Corporate Costs | B24: =-B109 -> -2500 | C24: =-C109 -> -3000 | D24: =-D109 -> -3000 | E24: =Daloopa!BA111 -> -3299 | F24: =Daloopa!BB111 -> -4761 | G24: =Daloopa!BC111 -> -2679 | H24: =-H140 -> -2667.4825 | I24: =-I140 -> -2866.0134 | J24: =-J140 -> -3148.3755 | K24: =-K140 -> -3404.2918 | L24: =-L140 -> -3656.2201 | M24: =-M140 -> -3895.3528 | N24: =-N140 -> -4116.2928 | O24: =-O140 -> -4335.2015
A26: Cost Structure: Google Services
A28: Cost of Revenue | B28: =Model!C46 -> 45583 | C28: =Model!D46 -> 59549 | D28: =Model!E46 -> 71896 | E28: =Model!F46 -> 84732 | F28: =Model!G46 -> 110939 | G28: =Model!H46 -> 126203 | H28: =H70 -> 134742.37 | I28: =I70 -> 146942.56 | J28: =J70 -> 163256.16 | K28: =K70 -> 178732.58 | L28: =L70 -> 194461.47 | M28: =M70 -> 207393.29 | N28: =N70 -> 219334.47 | O28: =O70 -> 230854.86
A29: As % of revenue | B29: =B28/B13 -> 0.4111948 | C29: =C28/C13 -> 0.43523926 | D29: =D28/D13 -> 0.44419457 | E29: =E28/E13 -> 0.46421625 | F29: =F28/F13 -> 0.43060197 | G29: =G28/G13 -> 0.44620557 | H29: =H28/H13 -> 0.44987234 | I29: =I28/I13 -> 0.45094191 | ... O29: =O28/O13 -> 0.44363566
A31: Traffic Acquisition Cost (TAC) | B31: =Daloopa!AX1175 -> 21672 | C31: =Daloopa!AY1175 -> 26726 | D31: =Daloopa!AZ1175 -> 30089 | E31: =Daloopa!BA1175 -> 32778 | F31: =Daloopa!BB1175 -> 45566 | G31: =Daloopa!BC1175 -> 48955 | H31: =H33+H36 -> 51347.141 | I31: =I33+I36 -> 54653.494 | J31: =J33+J36 -> 59084.654 | K31: =K33+K36 -> 62990.89 | L31: =L33+L36 -> 66823.113 | M31: =M33+M36 -> 70517.418 | N31: =N33+N36 -> 74009.785 | O31: =O33+O36 -> 77374.622
A32: As % of Google Services revenue | B32: =B31/B9 -> 0.20167504 | C32: =C31/C9 -> 0.20431784 | D32: =D31/D9 -> 0.19818212 | E32: =E31/E9 -> 0.19437246 | F32: =F31/F9 -> 0.19183342 | G32: =G31/G9 -> 0.19309504 | H32: =H31/H9 -> 0.19249289 | I32: =I31/I9 -> 0.19069518 | ... O32: =O31/O9 -> 0.17847987
A33: Google Network | B33: =B34*B6 -> 12645.053 | C33: =C34*C6 -> 14147.256 | D33: =D34*D6 -> 14867.43 | E33: =E34*E6 -> 15932.1 | F33: =F34*F6 -> 21873.69 | G33: =G34*G6 -> 22618.2 | H33: =H34*H6 -> 23522.928 | I33: =I34*I6 -> 24699.074 | ... O33: =O34*O6 -> 31249.319
A34: As % of related revenue | B34: 0.719 | C34: 0.708 | D34: 0.69 | E34: =D34 -> 0.69 | F34: =E34 -> 0.69 | G34: =F34 -> 0.69 | H34: =G34 -> 0.69 | I34: =H34 -> 0.69 | J34: =I34 -> 0.69 | K34: =J34 -> 0.69 | L34: =K34 -> 0.69 | ... O34: =N34 -> 0.69
A36: TAC (ex Network) | B36: =B31-B33 -> 9026.947 | C36: =C31-C33 -> 12578.744 | D36: =D31-D33 -> 15221.57 | E36: =E31-E33 -> 16845.9 | F36: =F31-F33 -> 23692.31 | G36: =G31-G33 -> 26336.8 | H36: =H37*H4 -> 27824.213 | I36: =I37*I4 -> 29954.42 | J36: =J37*J4 -> 33150.626 | K36: =K37*K4 -> 36019.501 | L36: =L37*L4 -> 38772.869 | M36: =M37*M4 -> 41345.163 | N36: =N37*N4 -> 43670.641 | O36: =O37*O4 -> 46125.303
A37: As % of Search & other revenue | B37: =B36/B4 -> 0.13042836 | C37: =C36/C4 -> 0.14770545 | D37: =D36/D4 -> 0.15514009 | E37: =E36/E4 -> 0.1618833 | F37: =F36/F4 -> 0.1590611 | G37: =G36/G4 -> 0.1621225 | H37: =G37+0.1% -> 0.1631225 | I37: =H37+0.1% -> 0.1641225 | J37: =I37+0.1% -> 0.1651225 | K37: =J37+0.1% -> 0.1661225 | L37: =K37+0.1% -> 0.1671225 | M37: =L37+0.1% -> 0.1681225 | N37: =M37+0.1% -> 0.1691225 | O37: =N37+0.1% -> 0.1701225
A39: Cost of revenue, ex TAC | B39: =B28-B31 -> 23911 | C39: =C28-C31 -> 32823 | D39: =D28-D31 -> 41807 | E39: =E28-E31 -> 51954 | F39: =F28-F31 -> 65373 | G39: =G28-G31 -> 77248 | H39: =H28-H31 -> 83395.226 | I39: =I28-I31 -> 92289.07 | ... O39: =O28-O31 -> 153480.24
A41: YouTube Ads | B41: =B42*B5 -> 7236.75 | C41: =C42*C5 -> 9111.75 | D41: =D42*D5 -> 11361.75 | E41: =E42*E5 -> 14829 | F41: =F42*F5 -> 21633.75 | G41: =G42*G5 -> 21932.25 | H41: =H42*H5 -> 23028.863 | I41: =I42*I5 -> 25331.749 | ... O41: =O42*O5 -> 43634.79
A42: As % of related revenue | B42: 0.75 | C42: 0.75 | D42: 0.75 | E42: 0.75 | F42: 0.75 | G42: 0.75 | H42: 0.75 | I42: 0.75 | J42: 0.75 | K42: 0.75 | L42: 0.75 | M42: 0.75 | N42: 0.75 | O42: 0.75
A44: Google Other | B44: =B49+B50 -> 4570.81 | C44: =C49+C50 -> 5756.964 | D44: =D49+D50 -> 7435.118 | E44: =E49+E50 -> 10801.222 | F44: =F49+F50 -> 12109.824 | G44: =G49+G50 -> 14934.27 | H44: =H49+H50 -> 15901.511 | I44: =I49+I50 -> 17241.411 | ... O44: =O49+O50 -> 28282.382
A45: As % of related revenue | B45: =B44/B8 -> 0.415 | C45: =C44/C8 -> 0.426 | D45: =D44/D8 -> 0.437 | E45: =E44/E8 -> 0.4975 | F45: =F44/F8 -> 0.432 | G45: =G44/G8 -> 0.514 | H45: =H44/H8 -> 0.50675 | I45: =I44/I8 -> 0.4995 | ... O45: =O44/O8 -> 0.48
A46: PlayStore Mix in Other revenue | B46: 0.7 | C46: 0.68 | D46: 0.66 | E46: 0.55 | F46: 0.6 | G46: 0.52 | H46: =G46-0.5% -> 0.515 | I46: =H46-0.5% -> 0.51 | J46: =I46-0.5% -> 0.505 | K46: =J46-0.5% -> 0.5 | L46: =K46-0.5% -> 0.495 | M46: =L46-0.5% -> 0.49 | N46: =M46-0.5% -> 0.485 | O46: =N46-0.5% -> 0.48
A47: PlayStore revenue | B47: =B46*B8 -> 7709.8 | C47: =C46*C8 -> 9189.52 | D47: =D46*D8 -> 11229.24 | E47: =E46*E8 -> 11941.05 | F47: =F46*F8 -> 16819.2 | G47: =G46*G8 -> 15108.6 | H47: =H46*H8 -> 16160.391 | I47: =I46*I8 -> 17603.843 | ... O47: =O46*O8 -> 28282.382
A48: Playstore Cost of revenue % of revenue | B48: 0.25 | C48: 0.25 | D48: 0.25 | E48: 0.25 | F48: 0.22 | G48: 0.25 | H48: =G48-1% -> 0.24 | I48: =H48-1% -> 0.23 | J48: =I48-1% -> 0.22 | K48: =J48 -> 0.22 | L48: =K48 -> 0.22 | M48: =L48 -> 0.22 | N48: =M48 -> 0.22 | O48: =N48 -> 0.22
A49: Playstore Cost of revenue | B49: =B8*B46*B48 -> 1927.45 | C49: =C8*C46*C48 -> 2297.38 | D49: =D8*D46*D48 -> 2807.31 | E49: =E8*E46*E48 -> 2985.2625 | F49: =F8*F46*F48 -> 3700.224 | G49: =G8*G46*G48 -> 3777.15 | H49: =H8*H46*H48 -> 3878.4938 | I49: =I8*I46*I48 -> 4048.884 | ... O49: =O8*O46*O48 -> 6222.124
...

Sheet Valuation
A1: Items | C1: 2021 | D1: 2022 | E1: 2023 | F1: 2024 | G1: 2025 | H1: 2026 | I1: 2027 | J1: 2028 | K1: 2029 | L1: 2030
A2: FCF
A3: OCF | C3: =Model!G104 -> 90766 | D3: =Model!H104 -> 90854 | E3: =Model!I104 -> 114264.57 | F3: =Model!J104 -> 118771.57 | G3: =Model!K104 -> 133628.69 | H3: =Model!L104 -> 146450.42 | I3: =Model!M104 -> 159458.35 | J3: =Model!N104 -> 172953.4 | ... L3: =Model!P104 -> 199123.63
A4: Capex | C4: =Model!G107 -> -24640 | D4: =Model!H107 -> -31485 | E4: =Model!I107 -> -32975.715 | F4: =Model!J107 -> -36527.908 | G4: =Model!K107 -> -41289.056 | H4: =Model!L107 -> -41270.204 | I4: =Model!M107 -> -40469.771 | J4: =Model!N107 -> -41475.268 | ... L4: =Model!P107 -> -38746.149 | O4: Terminal Multiple
A5: FCF | C5: =C3+C4 -> 66126 | D5: =D3+D4 -> 59369 | E5: =E3+E4 -> 81288.85 | F5: =F3+F4 -> 82243.661 | G5: =G3+G4 -> 92339.638 | H5: =H3+H4 -> 105180.21 | I5: =I3+I4 -> 118988.57 | J5: =J3+J4 -> 131478.13 | K5: =K3+K4 -> 146940.1 | L5: =L3+L4-Model!P89 -> 124992.29 | O5: 7
A6: FCF/share | C6: =C5/C14 -> 4.9164824 | D6: =D5/D14 -> 4.5855411 | E6: =E5/E14 -> 6.5296435 | F6: =F5/F14 -> 6.8467296 | G6: =G5/G14 -> 8.0141073 | H6: =H5/H14 -> 9.5558049 | I6: =I5/I14 -> 11.365944 | J6: =J5/J14 -> 13.249066 | ... L6: =L5/L14 -> 14.213707 | O6: =O5+1 -> 8
A7: Terminal FCF multiple | L7: 14 | O7: =O6+1 -> 9
A8: Terminal Stock price | L8: =L7*L6 -> 198.9919 | O8: =O7+1 -> 10
A9: Current price* | B9: 92.66 | O9: =O8+1 -> 11
A10: Dividend/share | C10: 0 | D10: 0 | E10: 0 | F10: 0 | G10: 0 | H10: 0 | I10: 0 | J10: 0 | K10: 0 | L10: 0 | O10: =O9+1 -> 12
A11: Cash flow | D11: =-B9 -> -92.66 | E11: =E10+E8 -> 0 | F11: =F10+F8 -> 0 | G11: =G10+G8 -> 0 | H11: =H10+H8 -> 0 | I11: =I10+I8 -> 0 | J11: =J10+J8 -> 0 | K11: =K10+K8 -> 0 | L11: =L10+L8 -> 198.9919 | O11: =O10+1 -> 13
O12: =O11+1 -> 14
A13: IRR | B13: =IRR(D11:L11) -> 0.10025383 | O13: =O12+1 -> 15
A14: #diluted shares outstanding | C14: =Model!G193 -> 13449.86 | D14: =Model!H193 -> 12947 | E14: =Model!I193 -> 12449.202 | F14: =Model!J193 -> 12012.109 | G14: =Model!K193 -> 11522.136 | H14: =Model!L193 -> 11006.944 | I14: =Model!M193 -> 10468.869 | J14: =Model!N193 -> 9923.5772 | ... L14: =Model!P193 -> 8793.7857 | O14: =O13+1 -> 16
O15: =O14+1 -> 17
A16: *Closing price of March 09, 2023 | O16: =O15+1 -> 18
O17: =O16+1 -> 19
A18: Stock price | D18: =B9 -> 92.66 | E18: =D18*1.1 -> 101.926 | F18: =E18*1.1 -> 112.1186 | G18: =F18*1.1 -> 123.33046 | H18: =G18*1.1 -> 135.66351 | I18: =H18*1.1 -> 149.22986 | J18: =I18*1.1 -> 164.15284 | K18: =J18*1.1 -> 180.56813 | L18: =K18*1.1 -> 198.62494 | O18: =O17+1 -> 20
O19: =O18+1 -> 21
O20: =O19+1 -> 22
O21: =O20+1 -> 23
O22: =O21+1 -> 24
O23: =O22+1 -> 25
O24: =O23+1 -> 26
O25: =O24+1 -> 27
O26: =O25+1 -> 28
O27: =O26+1 -> 29
O28: =O27+1 -> 30
O29: =O28+1 -> 31
O30: =O29+1 -> 32
... O40: =O39+1 -> 42

Sheet Daloopa
A1: Calendar | B1: Unit | C1: Source | D1: Tag Id | E1: 2013Q1 | F1: 2013Q2 | G1: 2013Q3 | H1: 2013Q4 | I1: 2014Q1 | J1: 2014Q2 | K1: 2014Q3 | L1: 2014Q4 | M1: 2015Q1 | N1: 2015Q2 | O1: 2015Q3 | P1: 2015Q4 | Q1: 2016Q1 | R1: 2016Q2 | S1: 2016Q3 | T1: 2016Q4 | U1: 2017Q1 | V1: 2017Q2 | W1: 2017Q3 | X1: 2017Q4 | Y1: 2018Q1 | Z1: 2018Q2 | AA1: 2018Q3 | AB1: 2018Q4 | AC1: 2019Q1 | AD1: 2019Q2 | AE1: 2019Q3 | AF1: 2019Q4 | AG1: 2020Q1 | AH1: 2020Q2 | AI1: 2020Q3 | AJ1: 2020Q4 | AK1: 2021Q1 | AL1: 2021Q2 | AM1: 2021Q3 | AN1: 2021Q4 | AO1: 2022Q1 | AP1: 2022Q2 | AQ1: 2022Q3 | AR1: 2022Q4 | AT1: 2013FY | AU1: 2014FY | AV1: 2015FY | AW1: 2016FY | AX1: 2017FY | AY1: 2018FY | AZ1: 2019FY | BA1: 2020FY | BB1: 2021FY | BC1: 2022FY
A2: Fiscal | E2: 2013Q1 | F2: 2013Q2 | G2: 2013Q3 | H2: 2013Q4 | I2: 2014Q1 | J2: 2014Q2 | K2: 2014Q3 | L2: 2014Q4 | M2: 2015Q1 | N2: 2015Q2 | O2: 2015Q3 | P2: 2015Q4 | Q2: 2016Q1 | R2: 2016Q2 | S2: 2016Q3 | T2: 2016Q4 | U2: 2017Q1 | V2: 2017Q2 | W2: 2017Q3 | X2: 2017Q4 | Y2: 2018Q1 | Z2: 2018Q2 | AA2: 2018Q3 | AB2: 2018Q4 | AC2: 2019Q1 | AD2: 2019Q2 | AE2: 2019Q3 | AF2: 2019Q4 | AG2: 2020Q1 | AH2: 2020Q2 | AI2: 2020Q3 | AJ2: 2020Q4 | AK2: 2021Q1 | AL2: 2021Q2 | AM2: 2021Q3 | AN2: 2021Q4 | AO2: 2022Q1 | AP2: 2022Q2 | AQ2: 2022Q3 | AR2: 2022Q4 | AT2: 2013FY | AU2: 2014FY | AV2: 2015FY | AW2: 2016FY | AX2: 2017FY | AY2: 2018FY | AZ2: 2019FY | BA2: 2020FY | BB2: 2021FY | BC2: 2022FY
A3: Fiscal Date | E3: 41364 | F3: 41455 | G3: 41547 | H3: 41639 | I3: 41729 | J3: 41820 | K3: 41912 | L3: 42004 | M3: 42094 | N3: 42185 | O3: 42277 | P3: 42369 | Q3: 42460 | R3: 42551 | S3: 42643 | T3: 42735 | U3: 42825 | V3: 42916 | W3: 43008 | X3: 43100 | Y3: 43190 | Z3: 43281 | AA3: 43373 | AB3: 43465 | AC3: 43555 | AD3: 43646 | AE3: 43738 | AF3: 43830 | AG3: 43921 | AH3: 44012 | AI3: 44104 | AJ3: 44196 | AK3: 44286 | AL3: 44377 | AM3: 44469 | AN3: 44561 | AO3: 44651 | AP3: 44742 | AQ3: 44834 | AR3: 44926
A4: Documents
A5: 10Q 10K | E5: 10-Q | F5: 10-Q | G5: 10-Q | H5: 10-K | I5: 10-Q | J5: 10-Q | K5: 10-Q | L5: 10-K | M5: 10-Q | N5: 10-Q | O5: 10-Q | P5: 10-K | Q5: 10-Q | R5: 10-Q | S5: 10-Q | T5: 10-K | U5: 10-Q | V5: 10-Q | W5: 10-Q | X5: 10-K | Y5: 10-Q | Z5: 10-Q | AA5: 10-Q | AB5: 10-K | AC5: 10-Q | AD5: 10-Q | AE5: 10-Q | AF5: 10-K | AG5: 10-Q | AH5: 10-Q | AI5: 10-Q | AJ5: 10-K | AK5: 10-Q | AL5: 10-Q | AM5: 10-Q | AN5: 10-K | AO5: 10-Q | AP5: 10-Q | AQ5: 10-Q | AR5: 10-K
A6: 10K | P6: 10-K
A7: 8K | E7: EX-99.1 | F7: EX-99.1 | G7: EX-99.1 | H7: EX-99.1 | I7: EX-99.1 | J7: EX-99.1 | K7: EX-99.1 | L7: EX-99.1 | M7: EX-99.1 | N7: EX-99.1 | O7: EX-99.1 | P7: EX-99.1 | Q7: EX-99.1 | R7: EX-99.1 | S7: EX-99.1 | T7: EX-99.1 | U7: EX-99.1 | V7: EX-99.1 | W7: EX-99.1 | X7: EX-99.1 | Y7: EX-99.1 | Z7: EX-99.1 | AA7: EX-99.1 | AB7: EX-99.1 | AC7: EX-99.1 | AD7: EX-99.1 | AE7: EX-99.1 | AF7: EX-99.1 | AG7: EX-99.1 | AH7: EX-99.1 | AI7: EX-99.1 | AJ7: EX-99.1 | AK7: EX-99.1 | AL7: EX-99.1 | AM7: EX-99.01 | AN7: EX-99.1 | AO7: EX-99.1 | AP7: EX-99.1 | AQ7: EX-99.1 | AR7: EX-99.1
A8: Earnings transcripts | M8: Earnings | N8: Earnings | O8: Earnings | P8: Earnings | Q8: Earnings | R8: Earnings | S8: Earnings | T8: Earnings | U8: Earnings | V8: Earnings | W8: Earnings | X8: Earnings | Y8: Earnings | Z8: Earnings | AA8: Earnings | AB8: Earnings | AC8: Earnings | AD8: Earnings | AE8: Earnings | AF8: Earnings | AG8: Earnings
A9: Conference transcripts | Q9: Alphabet Inc at Morgan Stanley Technology, Media & Telecom Conference | T9: Alphabet Inc at Credit Suisse Technology, Media, and Telecom Conference | U9: Alphabet Inc at Morgan Stanley Technology, Media & Telecom Conference | V9: Alphabet Inc Annual Shareholders Meeting | W9: Alphabet Inc at Citi Global Technology Conference | X9: Alphabet Inc at Credit Suisse Technology, Media and Telecom Conference | Y9: Alphabet Inc at Morgan Stanley Technology, Media & Telecom Conference | Z9: Alphabet Inc Annual Shareholders Meeting | AC9: Alphabet Inc at Morgan Stanley Technology, Media & Telecom Conference | AD9: Alphabet Inc Annual Shareholders Meeting | AG9: Alphabet Inc at Morgan Stanley Technology, Media & Telecom Conference
A10: Conference transcripts | T10: Alphabet Inc at Phocuswright Conference | U10: Alphabet Inc at Goldman Sachs Technology Conference | Y10: Alphabet Inc at Goldman Sachs Technology & Internet Conference | Z10: Alphabet Inc at Red Hat, Inc., the 14th annual Red Hat Summit | AC10: Alphabet Inc at Goldman Sachs Technology & Internet Conference | AG10: Alphabet Inc at Goldman Sachs Technology & Internet Conference
A11: Conference transcripts | AG11: Salesforce.Com Inc, UnitedHealth Group Inc, Alphabet Inc, Color, and Novartis AG at JPMorgan Healthcare Conference Panel
A12: Earning Brief | M12: Earnings Summary | N12: Earnings Summary | O12: Earnings Summary | P12: Earnings Summary | Q12: Earnings Summary | R12: Earnings Summary | S12: Earnings Summary | T12: Earnings Summary | U12: Earnings Summary | V12: Earnings Summary | W12: Earnings Summary | X12: Earnings Summary | Y12: Earnings Summary | Z12: Earnings Summary | AA12: Earnings Summary | AB12: Earnings Summary | AC12: Earnings Summary | AD12: Earnings Summary | AE12: Earnings Summary | AF12: Earnings Summary | AG12: Earnings Summary
A14: Guidance
A15: Annual
A16: Impact on operating result | B16: Billion | C16: 8-K | D16: 2690429 | AJ16: 2.1
A18: Additional information for Fiscal year
A19: Employee severance and related charges-Low | B19: Billion | C19: 8-K | D19: 3814027 | AR19: 1.9
A20: Employee severance and related charges-High | B20: Billion | C20: 8-K | D20: 3814028 | AR20: 2.3
A21: Reduction in depreciation- approx | B21: Billion | C21: 8-K | D21: 3814030 | AR21: 3.4
A23: Quarterly
A24: Exit costs relating to office space reductions-approx | B24: Billion | C24: 8-K | D24: 3814029 | AR24: 0.5
A26: KPIs
A27: Deferred revenue recognized as revenue | B27: Billion | C27: 10-K | D27: 3501224 | AJ27: 1.8 | AK27: 1.3 | AL27: 0.5 | AM27: 0.3 | AN27: 0.2 | AO27: 1.4 | AP27: 0.7 | AQ27: 0.3 | AR27: 0.1 | BA27: 1.8 | BB27: 2.3 | BC27: 2.5
A29: Remaining performance obligations | B29: Billion | C29: 10-K | D29: 3321078 | AF29: 11.4 | AG29: 12.8 | AH29: 14.8 | AI29: 19 | AJ29: 29.8 | AK29: 30.7 | AL29: 35.3 | AM29: 37.1 | AN29: 51 | AO29: 50.5 | AP29: 51.2 | AQ29: 52.4 | AR29: 64.3
A31: Revenue
A32: Increase (decrease) in Google service segment revenue | B32: Billion | C32: 10-K | D32: 3501225 | AK32: 13 | AL32: 22.1 | AM32: 17.3 | AO32: 10.3 | AP32: 5.8 | AQ32: 1.5 | AR32: =BC32-SUM(AO32,AP32,AQ32) -> -1.6 | BA32: 16.8 | BC32: 16
A33: Increase (decrease) in Google cloud segment revenue | B33: Billion | C33: 10-K | D33: 3501226 | AK33: 1.3 | AL33: 1.6 | AM33: 1.5 | AO33: 1.8 | AP33: 1.6 | AQ33: 1.9 | AR33: =BC33-SUM(AO33,AP33,AQ33) -> 1.8 | BA33: 4.1 | BC33: 7.1
A35: Traffic acquisition costs (TAC) to Google network members and distribution partners
A36: TAC to Google network members | B36: Million | C36: 8-K | D36: 2621598 | I36: 2387 | J36: 2400 | K36: 2421 | L36: 2656 | M36: 2432 | N36: 2432 | O36: 2514 | P36: 2864 | Q36: 2571 | R36: 2623 | S36: 2623 | T36: 3082 | U36: 2824 | V36: 3042 | W36: 3101 | X36: 3674 | Y36: 3386 | Z36: 3411 | AA36: 3427 | AB36: 3930 | AC36: 3477 | AD36: 3621 | AE36: 3634 | AT36: 9293 | AU36: 9864 | AV36: 10242 | AW36: 10899 | AX36: 12641 | AY36: 14154
A37: TAC to distribution partners | B37: Million | C37: 8-K | D37: 2621599 | I37: 845 | J37: 893 | K37: 927 | L37: 968 | M37: 913 | N37: 945 | O37: 1052 | P37: 1191 | Q37: 1217 | R37: 1352 | S37: 1559 | T37: 1766 | U37: 1805 | V37: 2049 | W37: 2401 | X37: 2776 | Y37: 2902 | Z37: 3009 | AA37: 3155 | AB37: 3506 | AC37: 3383 | AD37: 3617 | AE37: 3856 | AT37: 2965 | AU37: 3633 | AV37: 4101 | AW37: 5894 | AX37: 9031 | AY37: 12572
A38: Total TAC | B38: Million | C38: 8-K | D38: 2621600 | E38: 2960 | F38: 3010 | G38: 2970 | H38: 3310 | I38: =SUM(I36:I37) -> 3232 | J38: =SUM(J36:J37) -> 3293 | K38: =SUM(K36:K37) -> 3348 | L38: =SUM(L36:L37) -> 3624 | M38: =SUM(M36:M37) -> 3345 | N38: =SUM(N36:N37) -> 3377 | O38: =SUM(O36:O37) -> 3566 | P38: =SUM(P36:P37) -> 4055 | ... AE38: =SUM(AE36:AE37) -> 7490 | AF38: 8501 | AG38: 7452 | AH38: 6694 | AI38: 8166 | AJ38: 10466 | AK38: 9712 | AL38: 10929 | AM38: 11498 | AN38: 13427 | AO38: 11990 | AP38: 12214 | AQ38: 11826 | AR38: 12925 | AT38: =SUM(AT36:AT37) -> 12258 | AU38: =SUM(AU36:AU37) -> 13497 | AV38: =SUM(AV36:AV37) -> 14343 | AW38: =SUM(AW36:AW37) -> 16793 | AX38: =SUM(AX36:AX37) -> 21672 | AY38: =SUM(AY36:AY37) -> 26726 | AZ38: 30100 | BA38: 32800 | BB38: 45566 | BC38: =SUM(AO38,AP38,AQ38,AR38) -> 48955
A40: TAC to Google network members as % of Google network members' properties revenues | B40: Percent | C40: 8-K | D40: 13994 | I40: 0.68 | J40: 0.67 | K40: 0.68 | L40: 0.68 | M40: 0.68 | N40: 0.67 | O40: 0.68 | P40: 0.69 | Q40: 0.7 | R40: 0.7 | S40: 0.7 | T40: 0.7 | U40: 0.7 | V40: 0.72 | W40: 0.71 | X40: 0.74 | Y40: 0.73 | Z40: 0.71 | AA40: 0.7 | AB40: 0.7 | AC40: 0.69 | AD40: 0.69 | AE40: 0.69 | AW40: 0.699 | AX40: 0.719 | AY40: 0.708
A41: TAC to distribution partners as % of Google properties revenues | B41: Percent | C41: 8-K | D41: 13996 | I41: 0.08 | J41: 0.08 | K41: 0.08 | L41: 0.08 | M41: 0.08 | N41: 0.08 | O41: 0.08 | P41: 0.08 | Q41: 0.08 | R41: 0.09 | S41: 0.1 | T41: 0.1 | U41: 0.1 | V41: 0.11 | W41: 0.12 | X41: 0.12 | Y41: 0.13 | Z41: 0.13 | AA41: 0.13 | AB41: 0.13 | AC41: 0.13 | AD41: 0.13 | AE41: 0.13 | AW41: 0.092 | AX41: 0.116 | AY41: 0.131
A42: Total TAC as % of advertising revenues | B42: Percent | C42: 10-K | D42: 13999 | I42: 0.23 | J42: 0.23 | K42: 0.23 | L42: 0.22 | M42: 0.22 | N42: 0.21 | O42: 0.21 | P42: 0.21 | Q42: 0.21 | R42: 0.21 | S42: 0.21 | T42: 0.22 | U42: 0.22 | V42: 0.22 | W42: 0.23 | X42: 0.24 | Y42: 0.24 | Z42: 0.23 | AA42: 0.23 | AB42: 0.23 | AC42: 0.22 | AD42: 0.22 | AE42: 0.22 | AT42: 0.24 | AU42: 0.226 | AV42: 0.213 | AW42: 0.212 | AX42: 0.227 | AY42: 0.23 | AZ42: 0.223
A44: Monetization metrics information (QoQ)
A45: Aggregate paid clicks | B45: Percent | C45: 8-K | D45: 14002 | M45: -0.01 | N45: 0.07 | O45: 0.06 | P45: 0.17 | Q45: -0.03 | R45: 0.07 | S45: 0.09 | T45: 0.2 | U45: 0.02 | V45: 0.12 | W45: 0.06 | X45: 0.18
A46: Paid clicks on Google properties | B46: Percent | C46: 8-K | D46: 14004 | M46: -0.03 | N46: 0.1 | O46: 0.07 | P46: 0.22 | Q46: -0.04 | R46: 0.09 | S46: 0.11 | T46: 0.23 | U46: 0.01 | V46: 0.15 | W46: 0.07 | X46: 0.19 | Y46: 0.08 | Z46: 0.15 | AA46: 0.1 | AB46: 0.22 | AC46: -0.09 | AD46: 0.06 | AE46: 0.01
A47: Paid clicks on Google network members' properties | B47: Percent | C47: 8-K | D47: 14007 | M47: 0.04 | N47: -0.02 | O47: 0 | P47: 0.01 | Q47: 0.04 | R47: -0.03 | S47: 0.01 | T47: 0.06 | U47: 0.06 | V47: -0.05 | W47: 0.02 | X47: 0.09
A49: Aggregate cost per click | B49: Percent | C49: 8-K | D49: 14010 | M49: -0.05 | N49: -0.04 | O49: -0.01 | P49: -0.05 | Q49: 0 | R49: -0.01 | S49: -0.05 | T49: -0.09 | U49: -0.04 | V49: -0.06 | W49: 0.01 | X49: -0.06
A50: Cost-per-click on Google properties | B50: Percent | C50: 8-K | D50: 14013 | M50: -0.03 | N50: -0.05 | O50: -0.02 | P50: -0.08 | Q50: 0.02 | R50: -0.02 | S50: -0.06 | T50: -0.11 | U50: -0.03 | V50: -0.08 | W50: 0.01 | X50: -0.07 | Y50: -0.07 | Z50: -0.1 | AA50: -0.07 | AB50: -0.09 | AC50: 0.05 | AD50: -0.01 | AE50: 0.03
...
