Workbook
Name IQ_CH: 110000
Name IQ_CQ: 5000
Name IQ_CY: 10000
Name IQ_DAILY: 500000
Name IQ_FH: 100000
Name IQ_FQ: 500
Name IQ_FY: 1000
Name IQ_LTM: 2000
Name IQ_MONTH: 15000
Name IQ_NTM: 6000
Name IQ_WEEK: 50000
Name IQ_YTD: 3000

Sheet How to Use 
A1: Instructions
A2: Tab | B2: Details
A3: Color Code | B3: Just familiarize yourself with the color code conventions used in this file. I will maintain these color code conventions in every model.
A4: Model | B4: The most important worksheet in this file is the "Model" Worksheet.
B5: If you want to change the assumptions, just change the cells that are filled yellow. Since the rest of the cells are formula driven, they will automatically be changed.
B6: I have made a few comments here and there whenever I thought it might be helpful for subscribers
B7: Please let me know asap if you think there has been any error/mistake (conceptual or otherwise) in the model
B8: If you want to see consolidated numbers for Meta, you will find it here
A9: PP&E | B9: Granular analysis on PP&E to estimate capex and depreciation expense
A10: Valuation | B10: Just change the current stock price and choose your multiple to run your valuation estimates.
A11: FOA | B11: Family of Apss. Linked with Model worksheet. It's just easier to see what's going on within FOA on a single worksheet here.
A12: RL | B12: Reality Labs modeling. If you want to change modeling within RL, do it here.
A13: Quarterly Data | B13: Quarterly database. Some numbers on Model worksheet may be tracked with some data on this worksheet.

Sheet Color Code
A1: Color | B1: Meaning
A2: Black | B2: Formula driven (both historical and forecasts)
A3: Blue | B3: Hard coded numbers (Actual for Historical, estimated for forecasts)
A4: Yellow | B4: Indication that there has been explicit assumption made in these cells. Change the numbers in these cells to drive your narrative.

Sheet Daloopa
A1: Calendar | B1: Unit | C1: Source | D1: Tag Id | E1: 2013Q1 | F1: 2013Q2 | G1: 2013Q3 | H1: 2013Q4 | I1: 2014Q1 | J1: 2014Q2 | K1: 2014Q3 | L1: 2014Q4 | M1: 2015Q1 | N1: 2015Q2 | O1: 2015Q3 | P1: 2015Q4 | Q1: 2016Q1 | R1: 2016Q2 | S1: 2016Q3 | T1: 2016Q4 | U1: 2017Q1 | V1: 2017Q2 | W1: 2017Q3 | X1: 2017Q4 | Y1: 2018Q1 | Z1: 2018Q2 | AA1: 2018Q3 | AB1: 2018Q4 | AC1: 2019Q1 | AD1: 2019Q2 | AE1: 2019Q3 | AF1: 2019Q4 | AG1: 2020Q1 | AH1: 2020Q2 | AI1: 2020Q3 | AJ1: 2020Q4 | AK1: 2021Q1 | AL1: 2021Q2 | AM1: 2021Q3 | AN1: 2021Q4 | AO1: 2022Q1 | AP1: 2022Q2 | AQ1: 2022Q3 | AR1: 2022Q4 | AS1: 2023Q1 | AT1: 2023Q2 | AU1: 2023Q3 | AV1: 2023Q4 | AW1: 2024Q1 | AX1: 2024Q2 | AY1: 2024Q3 | AZ1: 2024Q4 | BA1: 2025Q1 | BB1: 2025Q2 | BC1: 2025Q3 | BD1: 2025Q4 | BF1: 2013FY | BG1: 2014FY | BH1: 2015FY | BI1: 2016FY | BJ1: 2017FY | BK1: 2018FY | BL1: 2019FY | BM1: 2020FY | BN1: 2021FY | BO1: 2022FY | BP1: 2023FY | BQ1: 2024FY | BR1: 2025FY
A2: Fiscal | E2: 2013Q1 | F2: 2013Q2 | G2: 2013Q3 | H2: 2013Q4 | I2: 2014Q1 | J2: 2014Q2 | K2: 2014Q3 | L2: 2014Q4 | M2: 2015Q1 | N2: 2015Q2 | O2: 2015Q3 | P2: 2015Q4 | Q2: 2016Q1 | R2: 2016Q2 | S2: 2016Q3 | T2: 2016Q4 | U2: 2017Q1 | V2: 2017Q2 | W2: 2017Q3 | X2: 2017Q4 | Y2: 2018Q1 | Z2: 2018Q2 | AA2: 2018Q3 | AB2: 2018Q4 | AC2: 2019Q1 | AD2: 2019Q2 | AE2: 2019Q3 | AF2: 2019Q4 | AG2: 2020Q1 | AH2: 2020Q2 | AI2: 2020Q3 | AJ2: 2020Q4 | AK2: 2021Q1 | AL2: 2021Q2 | AM2: 2021Q3 | AN2: 2021Q4 | AO2: 2022Q1 | AP2: 2022Q2 | AQ2: 2022Q3 | AR2: 2022Q4 | AS2: 2023Q1 | AT2: 2023Q2 | AU2: 2023Q3 | AV2: 2023Q4 | AW2: 2024Q1 | AX2: 2024Q2 | AY2: 2024Q3 | AZ2: 2024Q4 | BA2: 2025Q1 | BB2: 2025Q2 | BC2: 2025Q3 | BD2: 2025Q4 | BF2: 2013FY | BG2: 2014FY | BH2: 2015FY | BI2: 2016FY | BJ2: 2017FY | BK2: 2018FY | BL2: 2019FY | BM2: 2020FY | BN2: 2021FY | BO2: 2022FY | BP2: 2023FY | BQ2: 2024FY | BR2: 2025FY
A3: Fiscal Date | E3: 41364 | F3: 41455 | G3: 41547 | H3: 41639 | I3: 41729 | J3: 41820 | K3: 41912 | L3: 42004 | M3: 42094 | N3: 42185 | O3: 42277 | P3: 42369 | Q3: 42460 | R3: 42551 | S3: 42643 | T3: 42735 | U3: 42825 | V3: 42916 | W3: 43008 | X3: 43100 | Y3: 43190 | Z3: 43281 | AA3: 43373 | AB3: 43465 | AC3: 43555 | AD3: 43646 | AE3: 43738 | AF3: 43830 | AG3: 43921 | AH3: 44012 | AI3: 44104 | AJ3: 44196 | AK3: 44286 | AL3: 44377 | AM3: 44469 | AN3: 44561 | AO3: 44651 | AP3: 44742 | AQ3: 44834 | AR3: 44926 | AS3: 45016 | AT3: 45107 | AU3: 45199 | AV3: 45291 | AW3: 45382 | AX3: 45473 | AY3: 45565 | AZ3: 45657 | BA3: 45747 | BB3: 45838 | BC3: 45930 | BD3: 46022
A4: Documents
A5: 10Q/10K | E5: 10-Q | F5: 10-Q | G5: 10-Q | H5: 10-K | I5: 10-Q | J5: 10-Q | K5: 10-Q | L5: 10-K | M5: 10-Q | N5: 10-Q | O5: 10-Q | P5: 10-K | Q5: 10-Q | R5: 10-Q | S5: 10-Q | T5: 10-K | U5: 10-Q | V5: 10-Q | W5: 10-Q | X5: 10-K | Y5: 10-Q | Z5: 10-Q | AA5: 10-Q | AB5: 10-K | AC5: 10-Q | AD5: 10-Q | AE5: 10-Q | AF5: 10-K | AG5: 10-Q | AH5: 10-Q | AI5: 10-Q | AJ5: 10-K | AK5: 10-Q | AL5: 10-Q | AM5: 10-Q | AN5: 10-K | AO5: 10-Q | AP5: 10-Q | AQ5: 10-Q | AR5: 10-K | AS5: 10-Q | AT5: 10-Q | AU5: 10-Q | AV5: 10-K | AW5: 10-Q | AX5: 10-Q | AY5: 10-Q | AZ5: 10-K | BA5: 10-Q | BB5: 10-Q | BC5: 10-Q | BD5: 10-K
A6: 8-K | E6: EX-99.1 | F6: EX-99.1 | G6: EX-99.1 | H6: EX-99.1 | I6: EX-99.1 | J6: EX-99.1 | K6: EX-99.1 | L6: EX-99.1 | M6: EX-99.1 | N6: EX-99.1 | O6: EX-99.1 | P6: EX-99.1 | Q6: EX-99.1 | R6: EX-99.1 | S6: EX-99.1 | T6: EX-99.1 | U6: EX-99.1 | V6: EX-99.1 | W6: EX-99.1 | X6: EX-99.1 | Y6: EX-99.1 | Z6: EX-99.1 | AA6: EX-99.1 | AB6: EX-99.1 | AC6: EX-99.1 | AD6: EX-99.1 | AE6: EX-99.1 | AF6: EX-99.1 | AG6: EX-99.1 | AH6: EX-99.1 | AI6: EX-99.1 | AJ6: EX-99.1 | AK6: EX-99.1 | AL6: EX-99.1 | AM6: EX-99.1 | AN6: EX-99.1 | AO6: EX-99.1 | AP6: EX-99.1 | AQ6: EX-99.1 | AR6: EX-99.1 | AS6: EX-99.1 | AT6: EX-99.1 | AU6: EX-99.1 | AV6: EX-99.1 | AW6: EX-99.1 | AX6: EX-99.1 | AZ6: EX-99.1 | BC6: EX-99.1 | BD6: EX-99.1
A7: News article | AY7: News Article | AZ7: News Article | BA7: News Article | BB7: News Article | BD7: News Article
A8: Transcript | AW8: Earnings | AX8: Earnings | AY8: Earnings | AZ8: Earnings
A9: Private | AT9: PRIVATE
A11: Guidance
A12: Quarter
A13: Total revenue - low | B13: Billion | C13: News Article | D13: 2541430 | AM13: 31.5 | AN13: 27 | AO13: 28 | AP13: 26 | AQ13: 30 | AR13: 26 | AS13: 29.5 | AT13: 32 | AU13: 36.5 | AV13: 34.5 | AW13: 36.5 | AX13: 38.5 | AY13: 45 | AZ13: 39.5 | BA13: 42.5 | BB13: 47.5 | BC13: 56 | BD13: 53.5 | BN13: 27 | BO13: 26 | BP13: 34.5 | BQ13: 39.5 | BR13: 53.5
A14: Total revenue - high | B14: Billion | C14: News Article | D14: 2541431 | AM14: 34 | AN14: 29 | AO14: 30 | AP14: 28.5 | AQ14: 32.5 | AR14: 28.5 | AS14: 32 | AT14: 34.5 | AU14: 40 | AV14: 37 | AW14: 39 | AX14: 41 | AY14: 48 | AZ14: 41.8 | BA14: 45.5 | BB14: 50.5 | BC14: 59 | BD14: 56.5 | BN14: 29 | BO14: 28.5 | BP14: 37 | BQ14: 41.8 | BR14: 56.5
A15: Total revenue YOY growth-low | B15: Percent | C15: 8-K | D15: 6882821 | AZ15: 0.08 | BQ15: 0.08
A16: Total revenue YOY growth-High | B16: Percent | C16: 8-K | D16: 6882820 | AZ16: 0.15 | BQ16: 0.15
A17: Total revenue growth on basis of constant currency-Low | B17: Percent | C17: 8-K | D17: 6882819 | AZ17: 0.11 | BQ17: 0.11
A18: Total revenue growth on basis of constant currency-High | B18: Percent | C18: 8-K | D18: 6882818 | AZ18: 0.18 | BQ18: 0.18
A19: Foreign currency impact | B19: Percent | C19: News Article | D19: 3669082 | AO19: 0.03 | AP19: 0.06 | AQ19: 0.07 | AR19: 0.02 | AS19: 0.01 | AT19: -0.03 | AU19: -0.02 | AW19: 0.01 | AX19: 0.02 | AZ19: 0.03 | BA19: 0.01 | BB19: 0.01 | BC19: 0.01 | BD19: 0.04 | BO19: 0.02 | BQ19: 0.03 | BR19: 0.04
A20: Advertising revenue growth rate (YoY) | B20: Percent | C20: 8-K | D20: 2541432 | AG20: -0.17 | AH20: 0.1
A21: Tax rate-Low | B21: Percent | C21: 8-K | D21: 7735518 | BC21: 0.12
A22: Tax rate-High | B22: Percent | C22: 8-K | D22: 7735519 | BC22: 0.15
A24: Annual
A25: Total expenses - low | B25: Billion | C25: News Article | D25: 2635932 | AG25: 52 | AH25: 52 | AI25: 53 | AJ25: 68 | AK25: 70 | AL25: 70 | AM25: 70 | AN25: 90 | AO25: 87 | AP25: 85 | AQ25: 85 | AR25: 89 | AS25: 86 | AT25: 88 | AU25: 87 | AV25: 94 | AW25: 96 | AX25: 96 | AY25: 96 | AZ25: 114 | BA25: 113 | BB25: 114 | BC25: 116 | BD25: 162 | BM25: 68 | BN25: 90 | BO25: 89 | BP25: 94 | BQ25: 114 | BR25: 162
A26: Total expenses - high | B26: Billion | C26: News Article | D26: 2635933 | AG26: 56 | AH26: 55 | AI26: 54 | AJ26: 73 | AK26: 73 | AL26: 73 | AM26: 71 | AN26: 95 | AO26: 92 | AP26: 88 | AQ26: 87 | AR26: 95 | AS26: 90 | AT26: 91 | AU26: 89 | AV26: 99 | AW26: 99 | AX26: 99 | AY26: 98 | AZ26: 119 | BA26: 118 | BB26: 118 | BC26: 118 | BD26: 169 | BM26: 73 | BN26: 95 | BO26: 95 | BP26: 99 | BQ26: 119 | BR26: 169
A27: Restructuring costs related to facilities consolidation charges-low | B27: Billion | C27: 8-K | D27: 4237278 | AS27: 3
A28: Restructuring costs related to facilities consolidation charges-high | B28: Billion | C28: 8-K | D28: 4237279 | AS28: 5
A29: Restructuring costs related to facilities consolidation charges-Approx | B29: Billion | C29: 8-K | D29: 4625528 | AT29: 4 | AU29: 3.5
A30: Capital expenditures, including principal payments on finance leases - low | B30: Billion | C30: News Article | D30: 3669083 | AN30: 29 | AO30: 29 | AP30: 30 | AQ30: 32 | BD30: 115 | BN30: 29 | BR30: 115
A31: Capital expenditures, including principal payments on finance leases - high | B31: Billion | C31: News Article | D31: 3669084 | AN31: 34 | AO31: 34 | AP31: 34 | AQ31: 33 | BD31: 135 | BN31: 34 | BR31: 135
A32: Capital expenditures - low | B32: Billion | C32: 8-K | D32: 3669085 | AG32: 14 | AJ32: 21 | AK32: 19 | AL32: 19 | AR32: 30 | AS32: 30 | AT32: 27 | AU32: 27 | AV32: 30 | AW32: 35 | AX32: 37 | AY32: 38 | AZ32: 60 | BA32: 64 | BB32: 66 | BC32: 70 | BM32: 21 | BO32: 30 | BP32: 30 | BQ32: 60
A33: Capital expenditures - high | B33: Billion | C33: 8-K | D33: 3669086 | AG33: 16 | AJ33: 23 | AK33: 21 | AL33: 21 | AR33: 33 | AS33: 33 | AT33: 30 | AU33: 29 | AV33: 37 | AW33: 40 | AX33: 40 | AY33: 40 | AZ33: 65 | BA33: 72 | BB33: 72 | BC33: 72 | BM33: 23 | BO33: 33 | BP33: 37 | BQ33: 65
A34: Capital expenditures - approx. | B34: Billion | C34: 8-K | D34: 2399729 | AH34: 16 | AI34: 16 | AM34: 19
A35: Reduction in operating profit due to investment in Facebook Reality Labs | B35: Billion | C35: 8-K | D35: 2076062 | AM35: -10
A36: Restructuring charges related to consolidating our office facilities footprint | B36: Billion | C36: 8-K | D36: 3815475 | AR36: 1 | BO36: 1
A37: Tax rate | B37: Percent | C37: 8-K | D37: 4237280 | AS37: 0.2
A38: Tax rate -Low | B38: Percent | C38: News Article | D38: 6882817 | AZ38: 0.12 | BA38: 0.12 | BD38: 0.13 | BQ38: 0.12 | BR38: 0.13
A39: Tax rate -High | B39: Percent | C39: News Article | D39: 6882816 | AZ39: 0.15 | BA39: 0.15 | BD39: 0.16 | BQ39: 0.15 | BR39: 0.16
A41: Next year
A42: Total expenses - low | B42: Billion | C42: 8-K | D42: 2635936 | AI42: 68 | AM42: 91 | AQ42: 96 | AU42: 94
A43: Total expenses - high | B43: Billion | C43: 8-K | D43: 2635937 | AI43: 73 | AM43: 97 | AQ43: 101 | AU43: 99
...

Sheet Model
C1: 2017 | D1: 2018 | E1: 2019 | F1: 2020 | G1: 2021 | H1: 2022 | I1: 2023 | J1: 2024 | K1: 2025 | L1: 2026 | M1: 2027 | N1: 2028 | O1: 2029 | P1: 2030
A2: Revenue | C2: =Daloopa!BJ244 -> 40653 | D2: =Daloopa!BK244 -> 55838 | E2: =Daloopa!BL244 -> 70697 | F2: =Daloopa!BM244 -> 85965 | G2: =Daloopa!BN244 -> 117929 | H2: =Daloopa!BO244 -> 116609 | I2: =Daloopa!BP244 -> 134902 | J2: =Daloopa!BQ244 -> 164501 | K2: =Daloopa!BR244 -> 200966 | L2: =L45+L57 -> 250111.93 | M2: =M45+M57 -> 297787.79 | N2: =N45+N57 -> 355540.95 | O2: =O45+O57 -> 413799.28 | P2: =P45+P57 -> 475992.56
A3: Growth $ | D3: =D2-C2 -> 15185 | E3: =E2-D2 -> 14859 | F3: =F2-E2 -> 15268 | G3: =G2-F2 -> 31964 | H3: =H2-G2 -> -1320 | I3: =I2-H2 -> 18293 | J3: =J2-I2 -> 29599 | K3: =K2-J2 -> 36465 | ... P3: =P2-O2 -> 62193.275
A4: Growth % | D4: =D2/C2-1 -> 0.37352717 | E4: =E2/D2-1 -> 0.2661091 | F4: =F2/E2-1 -> 0.2159639 | G4: =G2/F2-1 -> 0.37182574 | H4: =H2/G2-1 -> -0.011193176 | I4: =I2/H2-1 -> 0.15687468 | J4: =J2/I2-1 -> 0.21941113 | K4: =K2/J2-1 -> 0.22167038 | ... P4: =P2/O2-1 -> 0.15029817
A5: Consensus (Feb 01, 2026) | L5: 250923 | M5: 292277 | N5: 341285 | O5: 384459 | P5: 433848
A6: Consensus incremental growth | L6: =L5-K2 -> 49957 | M6: =M5-L2 -> 42165.071 | N6: =N5-M2 -> 43497.213 | O6: =O5-N2 -> 28918.052 | P6: =P5-O2 -> 20048.715
A8: DAP | E8: ='Quarterly Data'!E12 -> 2260 | F8: ='Quarterly Data'!I12 -> 2600 | G8: ='Quarterly Data'!M12 -> 2820 | H8: ='Quarterly Data'!Q12 -> 2960 | I8: ='Quarterly Data'!U12 -> 3190 | J8: ='Quarterly Data'!Y12 -> 3350 | K8: =Daloopa!BD49*1000 -> 3580 | L8: =K8+L9 -> 3730 | M8: =L8+M9 -> 3880 | N8: =M8+N9 -> 4030 | O8: =N8+O9 -> 4180 | P8: =O8+P9 -> 4330
A9: Growth YoY | F9: =F8-E8 -> 340 | G9: =G8-F8 -> 220 | H9: =H8-G8 -> 140 | I9: =I8-H8 -> 230 | J9: =J8-I8 -> 160 | K9: =K8-J8 -> 230 | L9: 150 | M9: 150 | N9: 150 | O9: 150 | P9: 150
A11: FOA
A12: Ad Revenue by Geography
A13: UCAN | C13: =Daloopa!BJ213 -> 19484 | D13: =Daloopa!BK213 -> 26489 | E13: =Daloopa!BL213 -> 33493 | F13: =Daloopa!BM213 -> 40576 | G13: =Daloopa!BN213 -> 53419 | H13: =Daloopa!BO213 -> 52583 | I13: =Daloopa!BP213 -> 59581 | J13: =Daloopa!BQ213 -> 70415 | K13: =Daloopa!BR213 -> 85278 | L13: =K13*(1+L15) -> 104039.16 | M13: =L13*(1+M15) -> 119645.03 | N13: =M13*(1+N15) -> 137591.79 | O13: =N13*(1+O15) -> 154102.8 | P13: =O13*(1+P15) -> 169513.08
A14: Growth $ | C14: =C13-B13 -> 19484 | D14: =D13-C13 -> 7005 | E14: =E13-D13 -> 7004 | F14: =F13-E13 -> 7083 | G14: =G13-F13 -> 12843 | H14: =H13-G13 -> -836 | I14: =I13-H13 -> 6998 | J14: =J13-I13 -> 10834 | ... P14: =P13-O13 -> 15410.28
A15: Growth % | C15: =C13/B13-1 -> #DIV/0! | D15: =D13/C13-1 -> 0.35952576 | E15: =E13/D13-1 -> 0.26441164 | F15: =F13/E13-1 -> 0.21147703 | G15: =G13/F13-1 -> 0.31651715 | H15: =H13/G13-1 -> -0.015649862 | I15: =I13/H13-1 -> 0.13308484 | J15: =J13/I13-1 -> 0.18183649 | K15: =K13/J13-1 -> 0.21107719 | L15: 0.22 | M15: 0.15 | N15: 0.15 | O15: 0.12 | P15: 0.1
A17: Europe | C17: =Daloopa!BJ212 -> 9708 | D17: =Daloopa!BK212 -> 13592 | E17: =Daloopa!BL212 -> 16780 | F17: =Daloopa!BM212 -> 20455 | G17: =Daloopa!BN212 -> 28573 | H17: =Daloopa!BO212 -> 25335 | I17: =Daloopa!BP212 -> 30417 | J17: =Daloopa!BQ212 -> 37974 | K17: =Daloopa!BR212 -> 47163 | L17: =K17*(1+L19) -> 57538.86 | M17: =L17*(1+M19) -> 66169.689 | N17: =M17*(1+N19) -> 76095.142 | O17: =N17*(1+O19) -> 85226.559 | P17: =O17*(1+P19) -> 93749.215
A18: Growth $ | C18: =C17-B17 -> 9708 | D18: =D17-C17 -> 3884 | E18: =E17-D17 -> 3188 | F18: =F17-E17 -> 3675 | G18: =G17-F17 -> 8118 | H18: =H17-G17 -> -3238 | I18: =I17-H17 -> 5082 | J18: =J17-I17 -> 7557 | ... P18: =P17-O17 -> 8522.6559
A19: Growth % | C19: =C17/B17-1 -> #DIV/0! | D19: =D17/C17-1 -> 0.40008241 | E19: =E17/D17-1 -> 0.23454974 | F19: =F17/E17-1 -> 0.21901073 | G19: =G17/F17-1 -> 0.39687118 | H19: =H17/G17-1 -> -0.11332377 | I19: =I17/H17-1 -> 0.20059207 | J19: =J17/I17-1 -> 0.24844659 | K19: =K17/J17-1 -> 0.24198136 | L19: 0.22 | M19: 0.15 | N19: 0.15 | O19: 0.12 | P19: 0.1
A21: Asia Pacific | C21: =Daloopa!BJ211 -> 6716 | D21: =Daloopa!BK211 -> 9525 | E21: =Daloopa!BL211 -> 12540 | F21: =Daloopa!BM211 -> 15453 | G21: =Daloopa!BN211 -> 21468 | H21: =Daloopa!BO211 -> 23181 | I21: =Daloopa!BP211 -> 26473 | J21: =Daloopa!BQ211 -> 32121 | K21: =Daloopa!BR211 -> 38285 | L21: =K21*(1+L23) -> 47856.25 | M21: =L21*(1+M23) -> 58384.625 | N21: =M21*(1+N23) -> 70061.55 | O21: =N21*(1+O23) -> 84073.86 | P21: =O21*(1+P23) -> 99207.155
A22: Growth $ | C22: =C21-B21 -> 6716 | D22: =D21-C21 -> 2809 | E22: =E21-D21 -> 3015 | F22: =F21-E21 -> 2913 | G22: =G21-F21 -> 6015 | H22: =H21-G21 -> 1713 | I22: =I21-H21 -> 3292 | J22: =J21-I21 -> 5648 | ... P22: =P21-O21 -> 15133.295
A23: Growth % | C23: =C21/B21-1 -> #DIV/0! | D23: =D21/C21-1 -> 0.41825491 | E23: =E21/D21-1 -> 0.31653543 | F23: =F21/E21-1 -> 0.23229665 | G23: =G21/F21-1 -> 0.38924481 | H23: =H21/G21-1 -> 0.079793181 | I23: =I21/H21-1 -> 0.14201286 | J23: =J21/I21-1 -> 0.21334945 | K23: =K21/J21-1 -> 0.19189938 | L23: 0.25 | M23: 0.22 | N23: 0.2 | O23: 0.2 | P23: 0.18
A25: Rest of the World | C25: =Daloopa!BJ210 -> 4034 | D25: =Daloopa!BK210 -> 5406 | E25: =Daloopa!BL210 -> 6842 | F25: =Daloopa!BM210 -> 7685 | G25: =Daloopa!BN210 -> 11474 | H25: =Daloopa!BO210 -> 12542 | I25: =Daloopa!BP210 -> 15477 | J25: =Daloopa!BQ210 -> 20122 | K25: =Daloopa!BR210 -> 25448 | L25: =K25*(1+L27) -> 33082.4 | M25: =L25*(1+M27) -> 41353 | N25: =M25*(1+N27) -> 50657.425 | O25: =N25*(1+O27) -> 60788.91 | P25: =O25*(1+P27) -> 71730.914
A26: Growth $ | C26: =C25-B25 -> 4034 | D26: =D25-C25 -> 1372 | E26: =E25-D25 -> 1436 | F26: =F25-E25 -> 843 | G26: =G25-F25 -> 3789 | H26: =H25-G25 -> 1068 | I26: =I25-H25 -> 2935 | J26: =J25-I25 -> 4645 | ... P26: =P25-O25 -> 10942.004
A27: Growth % | C27: =C25/B25-1 -> #DIV/0! | D27: =D25/C25-1 -> 0.34010907 | E27: =E25/D25-1 -> 0.26563078 | F27: =F25/E25-1 -> 0.12320959 | G27: =G25/F25-1 -> 0.49303839 | H27: =H25/G25-1 -> 0.093080007 | I27: =I25/H25-1 -> 0.23401371 | J27: =J25/I25-1 -> 0.30012276 | K27: =K25/J25-1 -> 0.26468542 | L27: 0.3 | M27: 0.25 | N27: =M27-2.5% -> 0.225 | O27: 0.2 | P27: 0.18
A29: Advertising Revenue | C29: =C13+C17+C21+C25 -> 39942 | D29: 55013 | E29: 69655 | F29: 84169 | G29: =G13+G17+G21+G25 -> 114934 | H29: =H13+H17+H21+H25 -> 113641 | I29: =I13+I17+I21+I25 -> 131948 | J29: =J13+J17+J21+J25 -> 160632 | K29: =K13+K17+K21+K25 -> 196174 | L29: =L13+L17+L21+L25 -> 242516.67 | M29: =M13+M17+M21+M25 -> 285552.35 | N29: =N13+N17+N21+N25 -> 334405.91 | ... P29: =P13+P17+P21+P25 -> 434200.37
A30: Growth $ | D30: =D29-C29 -> 15071 | E30: =E29-D29 -> 14642 | F30: =F29-E29 -> 14514 | G30: =G29-F29 -> 30765 | H30: =H29-G29 -> -1293 | I30: =I29-H29 -> 18307 | J30: =J29-I29 -> 28684 | K30: =K29-J29 -> 35542 | ... P30: =P29-O29 -> 50008.235
A31: Growth | D31: =D29/C29-1 -> 0.37732212 | E31: =E29/D29-1 -> 0.26615527 | F31: =F29/E29-1 -> 0.20836982 | G31: =G29/F29-1 -> 0.36551462 | H31: =H29/G29-1 -> -0.011249935 | I31: =I29/H29-1 -> 0.16109503 | J31: =J29/I29-1 -> 0.21738867 | K31: =K29/J29-1 -> 0.22126351 | ... P31: =P29/O29-1 -> 0.13016465
A32: Overall ARPU (DAP) | F32: =F29/AVERAGE(E8:F8) -> 34.637449 | G32: =G29/AVERAGE(F8:G8) -> 42.41107 | H32: =H29/AVERAGE(G8:H8) -> 39.322145 | I32: =I29/AVERAGE(H8:I8) -> 42.909919 | J32: =J29/AVERAGE(I8:J8) -> 49.122936 | K32: =K29/AVERAGE(J8:K8) -> 56.615873 | L32: =L29/AVERAGE(K8:L8) -> 66.35203 | M32: =M29/AVERAGE(L8:M8) -> 75.046609 | ... P32: =P29/AVERAGE(O8:P8) -> 102.04474
A33: Growth % | G33: =G32/F32-1 -> 0.22442824 | H33: =H32/G32-1 -> -0.072832984 | I33: =I32/H32-1 -> 0.09124053 | J33: =J32/I32-1 -> 0.1447921 | K33: =K32/J32-1 -> 0.15253439 | L33: =L32/K32-1 -> 0.17196868 | M33: =M32/L32-1 -> 0.13103712 | N33: =N32/M32-1 -> 0.12666908 | ... P33: =P32/O32-1 -> 0.090323359
A35: FOA Ad revenue mix
A36: UCAN | C36: =C13/C29 -> 0.48780732 | D36: =D13/D29 -> 0.48150437 | E36: =E13/E29 -> 0.48084129 | F36: =F13/F29 -> 0.48207772 | G36: =G13/G29 -> 0.46477979 | H36: =H13/H29 -> 0.46271152 | I36: =I13/I29 -> 0.4515491 | J36: =J13/J29 -> 0.43836222 | ... P36: =P13/P29 -> 0.3904029
A37: Europe | C37: =C17/C29 -> 0.24305243 | D37: =D17/D29 -> 0.24706887 | E37: =E17/E29 -> 0.24090159 | F37: =F17/F29 -> 0.24302297 | G37: =G17/G29 -> 0.24860355 | H37: =H17/H29 -> 0.2229389 | I37: =I17/I29 -> 0.23052263 | J37: =J17/J29 -> 0.23640371 | ... P37: =P17/P29 -> 0.21591234
A38: Asia Pacific | C38: =C21/C29 -> 0.16814381 | D38: =D21/D29 -> 0.17314089 | E38: =E21/E29 -> 0.18003015 | F38: =F21/F29 -> 0.18359491 | G38: =G21/G29 -> 0.18678546 | H38: =H21/H29 -> 0.20398448 | I38: =I21/I29 -> 0.20063207 | J38: =J21/J29 -> 0.19996638 | ... P38: =P21/P29 -> 0.22848243
A39: Rest of the World | C39: =C25/C29 -> 0.10099644 | D39: =D25/D29 -> 0.098267682 | E39: =E25/E29 -> 0.098226976 | F39: =F25/F29 -> 0.091304399 | G39: =G25/G29 -> 0.099831207 | H39: =H25/H29 -> 0.1103651 | I39: =I25/I29 -> 0.11729621 | J39: =J25/J29 -> 0.12526769 | ... P39: =P25/P29 -> 0.16520233
A41: Other revenue | C41: =711-125 -> 586 | D41: =825-250 -> 575 | E41: =Daloopa!BL152 -> 541 | F41: =Daloopa!BM152 -> 657 | G41: =Daloopa!BN152 -> 721 | H41: =Daloopa!BO152 -> 808 | I41: =Daloopa!BP152 -> 1058 | J41: =Daloopa!BQ152 -> 1722 | K41: =Daloopa!BR152 -> 2584 | L41: =K41*(1+L43) -> 3876 | M41: =L41*(1+M43) -> 6201.6 | N41: =M41*(1+N43) -> 10542.72 | O41: =N41*(1+O43) -> 15814.08 | P41: =O41*(1+P43) -> 23721.12
A42: Growth $ | D42: =D41-C41 -> -11 | E42: =E41-D41 -> -34 | F42: =F41-E41 -> 116 | G42: =G41-F41 -> 64 | H42: =H41-G41 -> 87 | I42: =I41-H41 -> 250 | J42: =J41-I41 -> 664 | K42: =K41-J41 -> 862 | ... P42: =P41-O41 -> 7907.04
A43: Growth % | D43: =D41/C41-1 -> -0.018771331 | E43: =E41/D41-1 -> -0.059130435 | F43: =F41/E41-1 -> 0.21441774 | G43: =G41/F41-1 -> 0.097412481 | H43: =H41/G41-1 -> 0.12066574 | I43: =I41/H41-1 -> 0.30940594 | J43: =J41/I41-1 -> 0.62759924 | K43: =K41/J41-1 -> 0.50058072 | L43: 0.5 | M43: 0.6 | N43: 0.7 | O43: 0.5 | P43: 0.5
A45: FOA Revenue | C45: =C29+C41 -> 40528 | D45: =D29+D41 -> 55588 | E45: =E29+E41 -> 70196 | F45: =F29+F41 -> 84826 | G45: =G29+G41 -> 115655 | H45: =H29+H41 -> 114449 | I45: =I29+I41 -> 133006 | J45: =J29+J41 -> 162354 | ... P45: =P29+P41 -> 457921.49
A46: Growth | D46: =D45/C45-1 -> 0.37159495 | E46: =E45/D45-1 -> 0.26279053 | F46: =F45/E45-1 -> 0.20841643 | G46: =G45/F45-1 -> 0.3634381 | H46: =H45/G45-1 -> -0.010427565 | I46: =I45/H45-1 -> 0.16214209 | J46: =J45/I45-1 -> 0.2206517 | K46: =K45/J45-1 -> 0.22422607 | ... P46: =P45/O45-1 -> 0.14478594
A47: Growth $ | D47: =D45-C45 -> 15060 | E47: =E45-D45 -> 14608 | F47: =F45-E45 -> 14630 | G47: =G45-F45 -> 30829 | H47: =H45-G45 -> -1206 | I47: =I45-H45 -> 18557 | J47: =J45-I45 -> 29348 | K47: =K45-J45 -> 36404 | ... P47: =P45-O45 -> 57915.275
A49: Instagram revenue | D49: 11300 | E49: 17900 | F49: 22000 | G49: 32400 | H49: =H51*H45 -> 34351.127 | I49: =I51*I45 -> 42581.01 | J49: =J51*J45 -> 55223.663 | K49: =K51*K45 -> 70587.618 | L49: =L51*L45 -> 91200.653 | M49: =M51*M45 -> 112367.15 | N49: =N51*N45 -> 138028.96 | O49: =O51*O45 -> 166059.99 | P49: =P51*P45 -> 196971.97
A50: Growth | E50: =E49/D49-1 -> 0.5840708 | F50: =F49/E49-1 -> 0.22905028 | G50: =G49/F49-1 -> 0.47272727 | H50: =H49/G49-1 -> 0.060219966 | I50: =I49/H49-1 -> 0.23958118 | J50: =J49/I49-1 -> 0.29690823 | K50: =K49/J49-1 -> 0.27821326 | L50: =L49/K49-1 -> 0.29202055 | ... P50: =P49/O49-1 -> 0.18614944
...

Sheet PP&E
A1: Items | B1: 2013 | C1: 2014 | D1: 2015 | E1: 2016 | F1: =Model!C1 -> 2017 | G1: =Model!D1 -> 2018 | H1: =Model!E1 -> 2019 | I1: =Model!F1 -> 2020 | J1: =Model!G1 -> 2021 | K1: =Model!H1 -> 2022 | L1: =Model!I1 -> 2023 | M1: =Model!J1 -> 2024 | ... S1: =Model!P1 -> 2030
A2: Land | B2: =Daloopa!BF521 -> 45 | C2: =Daloopa!BG521 -> 153 | D2: =Daloopa!BH521 -> 596 | E2: =Daloopa!BI521 -> 696 | F2: =Daloopa!BJ521 -> 798 | G2: =Daloopa!BK521 -> 899 | H2: =Daloopa!BL521 -> 1097 | I2: =Daloopa!BM521 -> 1326 | ... N2: =Daloopa!BR521 -> 3687 | O2: =N2+O3 -> 4687 | P2: =O2+P3 -> 5687 | Q2: =P2+Q3 -> 6687 | R2: =Q2+R3 -> 7687 | S2: =R2+S3 -> 8687
A3: Increase | C3: =C2-B2 -> 108 | D3: =D2-C2 -> 443 | E3: =E2-D2 -> 100 | F3: =F2-E2 -> 102 | G3: =G2-F2 -> 101 | H3: =H2-G2 -> 198 | I3: =I2-H2 -> 229 | J3: =J2-I2 -> 362 | ... N3: =N2-M2 -> 1126 | O3: 1000 | P3: 1000 | Q3: 1000 | R3: 1000 | S3: 1000
A4: Buildings | B4: =Daloopa!BF522 -> 1071 | C4: =Daloopa!BG522 -> 1420 | D4: =Daloopa!BH522 -> 2273 | E4: =Daloopa!BI522 -> 3109 | F4: =Daloopa!BJ522 -> 4909 | G4: =Daloopa!BK522 -> 7401 | H4: =Daloopa!BL522 -> 11226 | I4: =Daloopa!BM522 -> 17360 | ... N4: =Daloopa!BR522 -> 55568 | O4: =N4+O5 -> 65568 | P4: =O4+P5 -> 75568 | Q4: =P4+Q5 -> 85568 | R4: =Q4+R5 -> 95568 | S4: =R4+S5 -> 105568
A5: Increase | C5: =C4-B4 -> 349 | D5: =D4-C4 -> 853 | E5: =E4-D4 -> 836 | F5: =F4-E4 -> 1800 | G5: =G4-F4 -> 2492 | H5: =H4-G4 -> 3825 | I5: =I4-H4 -> 6134 | J5: =J4-I4 -> 5171 | ... N5: =N4-M4 -> 8492 | O5: 10000 | P5: 10000 | Q5: 10000 | R5: 10000 | S5: 10000
A6: Leasehold improvements | B6: =Daloopa!BF523 -> 203 | C6: =Daloopa!BG523 -> 304 | D6: =Daloopa!BH523 -> 447 | E6: =Daloopa!BI523 -> 531 | F6: =Daloopa!BJ523 -> 959 | G6: =Daloopa!BK523 -> 1841 | H6: =Daloopa!BL523 -> 3112 | I6: =Daloopa!BM523 -> 4321 | ... N6: =Daloopa!BR523 -> 8346 | O6: =N6+O7 -> 9346 | P6: =O6+P7 -> 10346 | Q6: =P6+Q7 -> 11346 | R6: =Q6+R7 -> 12346 | S6: =R6+S7 -> 13346
A7: Increase | C7: =C6-B6 -> 101 | D7: =D6-C6 -> 143 | E7: =E6-D6 -> 84 | F7: =F6-E6 -> 428 | G7: =G6-F6 -> 882 | H7: =H6-G6 -> 1271 | I7: =I6-H6 -> 1209 | J7: =J6-I6 -> 1474 | ... N7: =N6-M6 -> 1053 | O7: 1000 | P7: 1000 | Q7: 1000 | R7: 1000 | S7: 1000
A9: Network equipment | B9: =Daloopa!BF524 -> 2351 | C9: =Daloopa!BG524 -> 3020 | D9: =Daloopa!BH524 -> 3633 | E9: =Daloopa!BI524 -> 5179 | F9: =Daloopa!BJ524 -> 7998 | G9: =Daloopa!BK524 -> 13017 | H9: =Daloopa!BL524 -> 17004 | I9: =Daloopa!BM524 -> 22003 | ... N9: =Daloopa!BR524 -> 0
A10: Servers and network assets | B10: =Daloopa!BF525 -> 0 | C10: =Daloopa!BG525 -> 0 | D10: =Daloopa!BH525 -> 0 | E10: =Daloopa!BI525 -> 0 | F10: =Daloopa!BJ525 -> 0 | G10: =Daloopa!BK525 -> 0 | H10: =Daloopa!BL525 -> 0 | I10: =Daloopa!BM525 -> 0 | ... N10: =Daloopa!BR525 -> 98040
A11: Computer software, office equipment and other | B11: =Daloopa!BF526 -> 95 | C11: =Daloopa!BG526 -> 149 | D11: =Daloopa!BH526 -> 248 | E11: =Daloopa!BI526 -> 398 | F11: =Daloopa!BJ526 -> 681 | G11: =Daloopa!BK526 -> 1187 | H11: =Daloopa!BL526 -> 1813 | I11: =Daloopa!BM526 -> 2458 | ... N11: =Daloopa!BR526 -> 0
A12: Equipment and other | B12: =Daloopa!BF527 -> 0 | C12: =Daloopa!BG527 -> 0 | D12: =Daloopa!BH527 -> 0 | E12: =Daloopa!BI527 -> 0 | F12: =Daloopa!BJ527 -> 0 | G12: =Daloopa!BK527 -> 0 | H12: =Daloopa!BL527 -> 0 | I12: =Daloopa!BM527 -> 0 | ... N12: =Daloopa!BR527 -> 9377
A13: Sub-total Servers and Network Assets | B13: =B9+B10+B11+B12 -> 2446 | C13: =C9+C10+C11+C12 -> 3169 | D13: =D9+D10+D11+D12 -> 3881 | E13: =E9+E10+E11+E12 -> 5577 | F13: =F9+F10+F11+F12 -> 8679 | G13: =G9+G10+G11+G12 -> 14204 | H13: =H9+H10+H11+H12 -> 18817 | I13: =I9+I10+I11+I12 -> 24461 | ... N13: =N9+N10+N11+N12 -> 107417 | O13: =N13+O14 -> 207417 | P13: =O13+P14 -> 287417 | Q13: =P13+Q14 -> 367417 | R13: =Q13+R14 -> 447417 | S13: =R13+S14 -> 527417
A14: Increase | C14: =C13-B13 -> 723 | D14: =D13-C13 -> 712 | E14: =E13-D13 -> 1696 | F14: =F13-E13 -> 3102 | G14: =G13-F13 -> 5525 | H14: =H13-G13 -> 4613 | I14: =I13-H13 -> 5644 | J14: =J13-I13 -> 5887 | ... N14: =N13-M13 -> 31870 | O14: 100000 | P14: 80000 | Q14: 80000 | R14: 80000 | S14: 80000
A16: Finance lease right of use assets | B16: =Daloopa!BF528 -> 0 | C16: =Daloopa!BG528 -> 0 | D16: =Daloopa!BH528 -> 0 | E16: =Daloopa!BI528 -> 0 | F16: =Daloopa!BJ528 -> 0 | G16: =Daloopa!BK528 -> 0 | H16: =Daloopa!BL528 -> 1635 | I16: =Daloopa!BM528 -> 2295 | ... N16: =Daloopa!BR528 -> 8187 | O16: =N16+O17 -> 11187 | P16: =O16+P17 -> 14187 | Q16: =P16+Q17 -> 17187 | R16: =Q16+R17 -> 20187 | S16: =R16+S17 -> 23187
A17: Increase | I17: =I16-H16 -> 660 | J17: =J16-I16 -> 545 | K17: =K16-J16 -> 513 | L17: =L16-K16 -> 832 | M17: =M16-L16 -> 1199 | N17: =N16-M16 -> 2803 | O17: 3000 | P17: 3000 | Q17: 3000 | R17: 3000 | S17: 3000
A18: Construction in progress | B18: =Daloopa!BF529 -> 377 | C18: =Daloopa!BG529 -> 738 | D18: =Daloopa!BH529 -> 622 | E18: =Daloopa!BI529 -> 1890 | F18: =Daloopa!BJ529 -> 2992 | G18: =Daloopa!BK529 -> 7228 | H18: =Daloopa!BL529 -> 10099 | I18: =Daloopa!BM529 -> 11288 | ... N18: =Daloopa!BR529 -> 50521 | O18: =N18+O19 -> 60521 | P18: =O18+P19 -> 55521 | Q18: =P18+Q19 -> 50521 | R18: =Q18+R19 -> 45521 | S18: =R18+S19 -> 35521
A19: Increase | C19: =C18-B18 -> 361 | D19: =D18-C18 -> -116 | E19: =E18-D18 -> 1268 | F19: =F18-E18 -> 1102 | G19: =G18-F18 -> 4236 | H19: =H18-G18 -> 2871 | I19: =I18-H18 -> 1189 | J19: =J18-I18 -> 3399 | ... N19: =N18-M18 -> 23719 | O19: 10000 | P19: -5000 | Q19: -5000 | R19: -5000 | S19: -10000
A20: Property and equipment, gross | B20: =B2+B4+B6+B16+B18+B13 -> 4142 | C20: =C2+C4+C6+C16+C18+C13 -> 5784 | D20: =D2+D4+D6+D16+D18+D13 -> 7819 | E20: =E2+E4+E6+E16+E18+E13 -> 11803 | F20: =F2+F4+F6+F16+F18+F13 -> 18337 | G20: =G2+G4+G6+G16+G18+G13 -> 31573 | H20: =H2+H4+H6+H16+H18+H13 -> 45986 | I20: =I2+I4+I6+I16+I18+I13 -> 61051 | ... S20: =S2+S4+S6+S16+S18+S13 -> 713726
B21: =[1]Sheet1!BB458 -> 0 | C21: =[1]Sheet1!BC458 -> 0 | D21: =[1]Sheet1!BD458 -> 0 | E21: =[1]Sheet1!BE458 -> 0 | F21: =[1]Sheet1!BF458 -> 0 | G21: =[1]Sheet1!BG458 -> 0 | H21: =[1]Sheet1!BH458 -> 0 | I21: =[1]Sheet1!BI458 -> 0 | ... L21: =[1]Sheet1!BL458 -> 0
A22: Less: Accumulated depreciation | B22: =Daloopa!BF532 -> -1260 | C22: =Daloopa!BG532 -> -1817 | D22: =Daloopa!BH532 -> -2132 | E22: =Daloopa!BI532 -> -3212 | F22: =Daloopa!BJ532 -> -4616 | G22: =Daloopa!BK532 -> -6890 | H22: =Daloopa!BL532 -> -10663 | I22: =Daloopa!BM532 -> -15418 | ... N22: =Daloopa!BR532 -> -57326 | O22: =N22-O45 -> -85554.845 | P22: =O22-P45 -> -127898.87 | Q22: =P22-Q45 -> -184104.54 | R22: =Q22-R45 -> -255111.88 | S22: =R22-S45 -> -338748.29
A23: Property and equipment, net | B23: =B20+B22 -> 2882 | C23: =C20+C22 -> 3967 | D23: =D20+D22 -> 5687 | E23: =E20+E22 -> 8591 | F23: =F20+F22 -> 13721 | G23: =G20+G22 -> 24683 | H23: =H20+H22 -> 35323 | I23: =I20+I22 -> 45633 | ... S23: =S20+S22 -> 374977.71
A25: Capex | O25: =O23-N23+O45 -> 125000 | P25: =P23-O23+P45 -> 90000 | Q25: =Q23-P23+Q45 -> 90000 | R25: =R23-Q23+R45 -> 90000 | S25: =S23-R23+S45 -> 85000
A27: PP&E Mix (as % of Gross PP&E)
A28: Land | B28: =B2/B$20 -> 0.010864317 | C28: =C2/C$20 -> 0.026452282 | D28: =D2/D$20 -> 0.076224581 | E28: =E2/E$20 -> 0.058968059 | F28: =F2/F$20 -> 0.043518569 | G28: =G2/G$20 -> 0.028473696 | H28: =H2/H$20 -> 0.023855086 | I28: =I2/I$20 -> 0.021719546 | ... S28: =S2/S$20 -> 0.012171337
A29: Buildings | B29: =B4/B$20 -> 0.25857074 | C29: =C4/C$20 -> 0.24550484 | D29: =D4/D$20 -> 0.29070214 | E29: =E4/E$20 -> 0.26340761 | F29: =F4/F$20 -> 0.26771009 | G29: =G4/G$20 -> 0.23440915 | H29: =H4/H$20 -> 0.24411777 | I29: =I4/I$20 -> 0.28435243 | ... S29: =S4/S$20 -> 0.1479111
A30: Leasehold improvements | B30: =B6/B$20 -> 0.04901014 | C30: =C6/C$20 -> 0.052558783 | D30: =D6/D$20 -> 0.057168436 | E30: =E6/E$20 -> 0.044988562 | F30: =F6/F$20 -> 0.052298631 | G30: =G6/G$20 -> 0.058309315 | H30: =H6/H$20 -> 0.06767277 | I30: =I6/I$20 -> 0.070776891 | ... S30: =S6/S$20 -> 0.018699053
A31: Land, buildings, and lease improvement | B31: =B28+B29+B30 -> 0.3184452 | C31: =C28+C29+C30 -> 0.32451591 | D31: =D28+D29+D30 -> 0.42409515 | E31: =E28+E29+E30 -> 0.36736423 | F31: =F28+F29+F30 -> 0.36352729 | G31: =G28+G29+G30 -> 0.32119216 | H31: =H28+H29+H30 -> 0.33564563 | I31: =I28+I29+I30 -> 0.37684886 | ... S31: =S28+S29+S30 -> 0.17878149
A33: Network equipment | B33: =B9/B$20 -> 0.56760019 | C33: =C9/C$20 -> 0.52213001 | D33: =D9/D$20 -> 0.46463742 | E33: =E9/E$20 -> 0.43878675 | F33: =F9/F$20 -> 0.43616731 | G33: =G9/G$20 -> 0.41228265 | H33: =H9/H$20 -> 0.36976471 | I33: =I9/I$20 -> 0.3604036 | ... S33: =S9/S$20 -> 0
A34: Servers and network assets | B34: =B10/B$20 -> 0 | C34: =C10/C$20 -> 0 | D34: =D10/D$20 -> 0 | E34: =E10/E$20 -> 0 | F34: =F10/F$20 -> 0 | G34: =G10/G$20 -> 0 | H34: =H10/H$20 -> 0 | I34: =I10/I$20 -> 0 | ... S34: =S10/S$20 -> 0
A35: Computer software, office equipment and other | B35: =B11/B$20 -> 0.02293578 | C35: =C11/C$20 -> 0.025760719 | D35: =D11/D$20 -> 0.031717611 | E35: =E11/E$20 -> 0.033720241 | F35: =F11/F$20 -> 0.037138027 | G35: =G11/G$20 -> 0.037595414 | H35: =H11/H$20 -> 0.039425042 | I35: =I11/I$20 -> 0.040261421 | ... S35: =S11/S$20 -> 0
A36: Equipment and other | B36: =B12/B$20 -> 0 | C36: =C12/C$20 -> 0 | D36: =D12/D$20 -> 0 | E36: =E12/E$20 -> 0 | F36: =F12/F$20 -> 0 | G36: =G12/G$20 -> 0 | H36: =H12/H$20 -> 0 | I36: =I12/I$20 -> 0 | ... S36: =S12/S$20 -> 0
A37: Sub-total Servers and Network Assets | B37: =B13/B20 -> 0.59053597 | C37: =C13/C20 -> 0.54789073 | D37: =D13/D20 -> 0.49635503 | E37: =E13/E20 -> 0.47250699 | F37: =F13/F20 -> 0.47330534 | G37: =G13/G20 -> 0.44987806 | H37: =H13/H20 -> 0.40918975 | I37: =I13/I20 -> 0.40066502 | ... S37: =S13/S20 -> 0.73896285
A39: Finance lease right of use assets | B39: =B16/B$20 -> 0 | C39: =C16/C$20 -> 0 | D39: =D16/D$20 -> 0 | E39: =E16/E$20 -> 0 | F39: =F16/F$20 -> 0 | G39: =G16/G$20 -> 0 | H39: =H16/H$20 -> 0.035554299 | I39: =I16/I$20 -> 0.037591522 | ... S39: =S16/S$20 -> 0.032487257
A40: Construction in progress | B40: =B18/B$20 -> 0.091018831 | C40: =C18/C$20 -> 0.12759336 | D40: =D18/D$20 -> 0.079549815 | E40: =E18/E$20 -> 0.16012878 | F40: =F18/F$20 -> 0.16316737 | G40: =G18/G$20 -> 0.22892978 | H40: =H18/H$20 -> 0.21961032 | I40: =I18/I$20 -> 0.1848946 | ... S40: =S18/S$20 -> 0.049768399
A41: Property and equipment, gross | B41: =B20/B$20 -> 1 | C41: =C20/C$20 -> 1 | D41: =D20/D$20 -> 1 | E41: =E20/E$20 -> 1 | F41: =F20/F$20 -> 1 | G41: =G20/G$20 -> 1 | H41: =H20/H$20 -> 1 | I41: =I20/I$20 -> 1 | ... S41: =S20/S$20 -> 1
A43: Depreciable Gross PP&E | B43: =B20-B2-B18 -> 3720 | C43: =C20-C2-C18 -> 4893 | D43: =D20-D2-D18 -> 6601 | E43: =E20-E2-E18 -> 9217 | F43: =F20-F2-F18 -> 14547 | G43: =G20-G2-G18 -> 23446 | H43: =H20-H2-H18 -> 34790 | I43: =I20-I2-I18 -> 48437 | ... S43: =S20-S2-S18 -> 669518
A45: Depreciation expense | B45: 857 | C45: 923 | D45: 1220 | E45: 1590 | F45: 2330 | G45: =Model!D70 -> 3680 | H45: =Model!E70 -> 5180 | I45: =Model!F70 -> 6390 | J45: =Model!G70 -> 7560 | K45: =Model!H70 -> 8500 | L45: =Model!I70 -> 11020 | M45: =Model!J70 -> 15290 | N45: =Model!K70 -> 18000 | O45: =O46*AVERAGE(N43:O43) -> 28228.845 | P45: =P46*AVERAGE(O43:P43) -> 42344.021 | Q45: =Q46*AVERAGE(P43:Q43) -> 56205.679 | R45: =R46*AVERAGE(Q43:R43) -> 71007.336 | S45: =S46*AVERAGE(R43:S43) -> 83636.404
A46: As % of avg gross PP&E ex land and construction in progress | C46: =C45/AVERAGE(B43:C43) -> 0.21432718 | D46: =D45/AVERAGE(C43:D43) -> 0.21228467 | E46: =E45/AVERAGE(D43:E43) -> 0.20103679 | F46: =F45/AVERAGE(E43:F43) -> 0.19609493 | G46: =G45/AVERAGE(F43:G43) -> 0.1937199 | H46: =H45/AVERAGE(G43:H43) -> 0.17789683 | I46: =I45/AVERAGE(H43:I43) -> 0.15355594 | J46: =J45/AVERAGE(I43:J43) -> 0.1375158 | ... N46: =N45/AVERAGE(M43:N43) -> 0.11435178 | O46: =N46+0.5% -> 0.11935178 | P46: =O46+0.5% -> 0.12435178 | Q46: =P46+0.5% -> 0.12935178 | R46: =Q46+0.5% -> 0.13435178 | S46: =R46 -> 0.13435178

Sheet Valuation
A1: Items | C1: 2021 | D1: 2022 | E1: 2023 | F1: 2024 | G1: 2025 | H1: 2026 | I1: 2027 | J1: 2028 | K1: 2029 | L1: 2030 | M1: Terminal P/E
A2: FCF
A3: OCF | C3: =Model!G167 -> 57683 | D3: =Model!H167 -> 50475 | E3: =Model!I167 -> 71113 | F3: =Model!J167 -> 91328 | G3: =Model!K167 -> 115800 | H3: =Model!L167 -> 136942.73 | I3: =Model!M167 -> 160888.02 | J3: =Model!N167 -> 201594.13 | ... L3: =Model!P167 -> 291568.87
A4: Capex | C4: =Model!G170 -> -18567 | D4: =Model!H170 -> -31431 | E4: =Model!I170 -> -27266 | F4: =Model!J170 -> -37256 | G4: =Model!K170 -> -69691 | H4: =Model!L170 -> -125000 | I4: =Model!M170 -> -90000 | J4: =Model!N170 -> -90000 | ... L4: =Model!P170 -> -85000 | O4: Terminal Multiple
A5: FCF | C5: =C3+C4 -> 39116 | D5: =D3+D4 -> 19044 | E5: =E3+E4 -> 43847 | F5: =F3+F4 -> 54072 | G5: =G3+G4 -> 46109 | H5: =H3+H4 -> 11942.728 | I5: =I3+I4 -> 70888.02 | J5: =J3+J4 -> 111594.13 | K5: =K3+K4 -> 153480.26 | L5: =L3+L4-Model!P152 -> 157919.81 | O5: 10
A6: FCF/share | C6: =C5/C14 -> 13.681707 | D6: =D5/D14 -> 7.0481125 | E6: =E5/E14 -> 16.678205 | F6: =F5/F14 -> 20.685539 | G6: =G5/G14 -> 17.913364 | H6: =H5/H14 -> 4.5782308 | I6: =I5/I14 -> 27.473373 | J6: =J5/J14 -> 44.0485 | ... L6: =L5/L14 -> 66.932689 | O6: =O5+0.5 -> 10.5
A7: Terminal FCF multiple | L7: 16.5 | M7: =L8/Model!P136 -> 16.40605 | O7: =O6+0.5 -> 11
A8: Terminal Stock price | L8: =L7*L6 -> 1104.3894 | O8: =O7+0.5 -> 11.5
A9: Current price* | B9: 695 | O9: =O8+0.5 -> 12
A10: Dividend/share | E10: 0 | H10: =-Model!L182/Valuation!H14 -> 2.7897457 | I10: =-Model!M182/Valuation!I14 -> 3.3106732 | J10: =-Model!N182/Valuation!J14 -> 4.1434088 | K10: =-Model!O182/Valuation!K14 -> 5.1574691 | L10: =-Model!P182/Valuation!L14 -> 6.7315981 | O10: =O9+0.5 -> 12.5
A11: Cash flow | G11: =-B9 -> -695 | H11: =H10+H8 -> 2.7897457 | I11: =I10+I8 -> 3.3106732 | J11: =J10+J8 -> 4.1434088 | K11: =K10+K8 -> 5.1574691 | L11: =L10+L8 -> 1111.121 | O11: =O10+0.5 -> 13
O12: =O11+0.5 -> 13.5
A13: IRR | B13: =IRR(G11:L11) -> 0.10216992 | O13: =O12+0.5 -> 14
A14: #diluted shares outstanding | C14: =Model!G252 -> 2859 | D14: =Model!H252 -> 2702 | E14: =Model!I252 -> 2629 | F14: =Model!J252 -> 2614 | G14: =Model!K252 -> 2574 | H14: =Model!L252 -> 2608.5903 | I14: =Model!M252 -> 2580.2445 | J14: =Model!N252 -> 2533.4377 | ... L14: =Model!P252 -> 2359.3825 | O14: =O13+0.5 -> 14.5
O15: =O14+0.5 -> 15
A16: *prices as of February 02, 2026 | O16: =O15+0.5 -> 15.5
O17: =O16+0.5 -> 16
A18: Stock price | F18: =B9 -> 695 | G18: =B9 -> 695 | H18: =G18*(1.1)^(11/12) -> 758.452 | I18: =H18*1.1 -> 834.2972 | J18: =I18*1.1 -> 917.72692 | K18: =J18*1.1 -> 1009.4996 | L18: =K18*1.1 -> 1110.4496 | O18: =O17+0.5 -> 16.5
O19: =O18+0.5 -> 17
O20: =O19+1 -> 18
O21: =O20+1 -> 19
O22: =O21+1 -> 20
O23: =O22+1 -> 21
O24: =O23+1 -> 22
O25: =O24+1 -> 23
O26: =O25+1 -> 24
O27: =O26+1 -> 25
O28: =O27+1 -> 26
O29: =O28+1 -> 27
O30: =O29+1 -> 28
O31: =O30+1 -> 29
... O40: =O39+1 -> 38

Sheet FOA
A1: FOA | B1: =Model!C1 -> 2017 | C1: =Model!D1 -> 2018 | D1: =Model!E1 -> 2019 | E1: =Model!F1 -> 2020 | F1: =Model!G1 -> 2021 | G1: =Model!H1 -> 2022 | H1: =Model!I1 -> 2023 | I1: =Model!J1 -> 2024 | ... O1: =Model!P1 -> 2030
A2: Revenue | B2: =Model!C45 -> 40528 | C2: =Model!D45 -> 55588 | D2: =Model!E45 -> 70196 | E2: =Model!F45 -> 84826 | F2: =Model!G45 -> 115655 | G2: =Model!H45 -> 114449 | H2: =Model!I45 -> 133006 | I2: =Model!J45 -> 162354 | ... O2: =Model!P45 -> 457921.49
A3: Growth $ | C3: =C2-B2 -> 15060 | D3: =D2-C2 -> 14608 | E3: =E2-D2 -> 14630 | F3: =F2-E2 -> 30829 | G3: =G2-F2 -> -1206 | H3: =H2-G2 -> 18557 | I3: =I2-H2 -> 29348 | J3: =J2-I2 -> 36404 | ... O3: =O2-N2 -> 57915.275
A4: Growth % | C4: =C2/B2-1 -> 0.37159495 | D4: =D2/C2-1 -> 0.26279053 | E4: =E2/D2-1 -> 0.20841643 | F4: =F2/E2-1 -> 0.3634381 | G4: =G2/F2-1 -> -0.010427565 | H4: =H2/G2-1 -> 0.16214209 | I4: =I2/H2-1 -> 0.2206517 | J4: =J2/I2-1 -> 0.22422607 | ... O4: =O2/N2-1 -> 0.14478594
A6: Cost of Revenue | B6: =Model!C63 -> 5268.64 | C6: =Model!D63 -> 8894.08 | D6: =Model!E63 -> 12119.85 | E6: =Model!F63 -> 15339.9 | F6: =Model!G63 -> 19945.4 | G6: =Model!H63 -> 21680.25 | H6: =Model!I63 -> 24274.75 | I6: =Model!J63 -> 28221 | ... O6: =Model!P63 -> 116438.25
A7: As % of revenue | B7: =B6/B2 -> 0.13 | C7: =C6/C2 -> 0.16 | D7: =D6/D2 -> 0.17265727 | E7: =E6/E2 -> 0.1808396 | F7: =F6/F2 -> 0.17245601 | G7: =G6/G2 -> 0.18943154 | H7: =H6/H2 -> 0.18250868 | I7: =I6/I2 -> 0.17382387 | ... O7: =O6/O2 -> 0.25427558
A8: Gross Profit | B8: =B2-B6 -> 35259.36 | C8: =C2-C6 -> 46693.92 | D8: =D2-D6 -> 58076.15 | E8: =E2-E6 -> 69486.1 | F8: =F2-F6 -> 95709.6 | G8: =G2-G6 -> 92768.75 | H8: =H2-H6 -> 108731.25 | I8: =I2-I6 -> 134133 | ... O8: =O2-O6 -> 341483.24
A9: Gross Margin | B9: =B8/B2 -> 0.87 | C9: =C8/C2 -> 0.84 | D9: =D8/D2 -> 0.82734273 | E9: =E8/E2 -> 0.8191604 | F9: =F8/F2 -> 0.82754399 | G9: =G8/G2 -> 0.81056846 | H9: =H8/H2 -> 0.81749132 | I9: =I8/I2 -> 0.82617613 | ... O9: =O8/O2 -> 0.74572442
A11: Operating expenses (estimated)*
A13: R&D | B13: =Model!C81 -> 7295.04 | C13: =Model!D81 -> 9449.96 | D13: =Model!E81 -> 10600 | E13: =Model!F81 -> 13437 | F13: =Model!G81 -> 17685 | G13: =Model!H81 -> 23434 | H13: =Model!I81 -> 23936 | I13: =Model!J81 -> 28849 | ... O13: =Model!P81 -> 100742.73
A14: As % of revenue | B14: =B13/B2 -> 0.18 | C14: =C13/C2 -> 0.17 | D14: =D13/D2 -> 0.15100576 | E14: =E13/E2 -> 0.15840662 | F14: =F13/F2 -> 0.15291168 | G14: =G13/G2 -> 0.20475496 | H14: =H13/H2 -> 0.17996181 | I14: =I13/I2 -> 0.17769196 | ... O14: =O13/O2 -> 0.22
A16: S&M | B16: =Model!C91 -> 4458.08 | C16: =Model!D91 -> 7226.44 | D16: =Model!E91 -> 9201 | E16: =Model!F91 -> 10891 | F16: =Model!G91 -> 12643 | G16: =Model!H91 -> 13074 | H16: =Model!I91 -> 9906 | I16: =Model!J91 -> 9293 | ... O16: =Model!P91 -> 16142.436
A17: =A14 -> As % of revenue | B17: =B16/B2 -> 0.11 | C17: =C16/C2 -> 0.13 | D17: =D16/D2 -> 0.13107584 | E17: =E16/E2 -> 0.12839224 | F17: =F16/F2 -> 0.1093165 | G17: =G16/G2 -> 0.11423429 | H17: =H16/H2 -> 0.074477843 | I17: =I16/I2 -> 0.057239119 | ... O17: =O16/O2 -> 0.035251537
A19: G&A | B19: =Model!C101 -> 2431.68 | C19: =Model!D101 -> 3335.28 | D19: =Model!E101-5000 -> 4790 | E19: =Model!F101 -> 5864 | F19: =Model!G101 -> 8429 | G19: =Model!H101 -> 9507 | H19: =Model!I101 -> 9773 | I19: =Model!J101 -> 8490 | J19: =Model!K101 -> 10652 | K19: =Model!L101 -> 12958.483 | L19: =Model!M101 -> 15052.406 | ... O19: =Model!P101 -> 22251.692
A20: =A17 -> As % of revenue | B20: =B19/B2 -> 0.06 | C20: =C19/C2 -> 0.06 | D20: =D19/D2 -> 0.068237506 | E20: =E19/E2 -> 0.069129748 | F20: =F19/F2 -> 0.07288055 | G20: =G19/G2 -> 0.083067567 | H20: =H19/H2 -> 0.073477888 | I20: =I19/I2 -> 0.052293137 | ... O20: =O19/O2 -> 0.048592811
A22: Total Costs | B22: =B13+B6+B16+B19 -> 19453.44 | C22: =C13+C6+C16+C19 -> 28905.76 | D22: =D13+D6+D16+D19 -> 36710.85 | E22: =E13+E6+E16+E19 -> 45531.9 | F22: =F13+F6+F16+F19 -> 58702.4 | G22: =G13+G6+G16+G19 -> 67695.25 | H22: =H13+H6+H16+H19 -> 67889.75 | I22: =I13+I6+I16+I19 -> 74853 | ... O22: =O13+O6+O16+O19 -> 255575.11
A23: As % of revenue | B23: =B22/B2 -> 0.48 | C23: =C22/C2 -> 0.52 | D23: =D22/D2 -> 0.52297638 | E23: =E22/E2 -> 0.53676821 | F23: =F22/F2 -> 0.50756474 | G23: =G22/G2 -> 0.59148835 | H23: =H22/H2 -> 0.51042622 | I23: =I22/I2 -> 0.46104808 | ... O23: =O22/O2 -> 0.55811993
A25: EBIT | B25: =B8-B13-B16-B19 -> 21074.56 | C25: =C8-C13-C16-C19 -> 26682.24 | D25: =D8-D13-D16-D19 -> 33485.15 | E25: =E8-E13-E16-E19 -> 39294.1 | F25: =F8-F13-F16-F19 -> 56952.6 | G25: =G8-G13-G16-G19 -> 46753.75 | H25: =H8-H13-H16-H19 -> 65116.25 | I25: =I8-I13-I16-I19 -> 87501 | ... O25: =O8-O13-O16-O19 -> 202346.38
A26: EBIT Margin | B26: =B25/B2 -> 0.52 | C26: =C25/C2 -> 0.48 | D26: =D25/D2 -> 0.47702362 | E26: =E25/E2 -> 0.46323179 | F26: =F25/F2 -> 0.49243526 | G26: =G25/G2 -> 0.40851165 | H26: =H25/H2 -> 0.48957378 | I26: =I25/I2 -> 0.53895192 | ... O26: =O25/O2 -> 0.44188007
A28: *adjusted for FTC penalty in 2019 and restructuring expenses in 2022

Sheet RL
B1: 2019 | C1: 2020 | D1: 2021 | E1: 2022 | F1: 2023 | G1: 2024 | H1: 2025 | I1: 2026 | J1: 2027 | K1: 2028 | L1: 2029 | M1: 2030
A3: VR+Horizon
A5: Hardware revenue | B5: =B6*B9 -> 500 | C5: =C6*C9 -> 1125 | D5: =D6*D9 -> 2250 | E5: =E6*E9 -> 1800 | F5: =F6*F9 -> 1400 | G5: =G6*G9 -> 1400 | H5: =H6*H9 -> 750 | I5: =I6*I9 -> 900 | ... M5: =M6*M9 -> 900
A6: Unit Sold | B6: 2.5 | C6: 4.5 | D6: 7.5 | E6: 4.5 | F6: 3.5 | G6: 4 | H6: 2.5 | I6: 3 | J6: 3 | K6: 3 | L6: 3 | M6: 3
A7: Install base | C7: =B6+C6 -> 7 | D7: =C6+D6 -> 12 | E7: =D6+E6 -> 12 | F7: =E6+F6 -> 8 | G7: =F6+G6 -> 7.5 | H7: =G6+H6 -> 6.5 | I7: =H6+I6 -> 5.5 | J7: =I6+J6 -> 6 | ... M7: =L6+M6 -> 6
A9: Price | B9: 200 | C9: 250 | D9: 300 | E9: 400 | F9: 400 | G9: 350 | H9: 300 | I9: 300 | J9: 300 | K9: 300 | L9: 300 | M9: 300
A11: Software revenue | B11: 1 | C11: 14 | D11: 24 | E11: 325 | F11: 400 | G11: 560 | H11: 710 | I11: =I12*AVERAGE(H7:I7) -> 818.57143 | J11: =J12*AVERAGE(I7:J7) -> 1014.4643 | K11: =K12*AVERAGE(J7:K7) -> 1118.5714 | L11: =L12*AVERAGE(K7:L7) -> 1178.5714 | M11: =M12*AVERAGE(L7:M7) -> 1238.5714
A12: Per installed base | D12: =D11/AVERAGE(C7:D7) -> 2.5263158 | E12: =E11/AVERAGE(D7:E7) -> 27.083333 | F12: =F11/AVERAGE(E7:F7) -> 40 | G12: =G11/AVERAGE(F7:G7) -> 72.258065 | H12: =H11/AVERAGE(G7:H7) -> 101.42857 | I12: =H12+I13 -> 136.42857 | J12: =I12+J13 -> 176.42857 | K12: =J12+K13 -> 186.42857 | L12: =K12+L13 -> 196.42857 | M12: =L12+M13 -> 206.42857
A13: Increase $ | E13: =E12-D12 -> 24.557018 | F13: =F12-E12 -> 12.916667 | G13: =G12-F12 -> 32.258065 | H13: =H12-G12 -> 29.170507 | I13: 35 | J13: 40 | K13: 10 | L13: 10 | M13: 10
A15: Advertising | H15: =H18*AVERAGE(G16:H16) -> 0 | I15: =I18*AVERAGE(H16:I16) -> 0.6875 | J15: =J18*AVERAGE(I16:J16) -> 4.375 | K15: =K18*AVERAGE(J16:K16) -> 11.25 | L15: =L18*AVERAGE(K16:L16) -> 27 | M15: =M18*AVERAGE(L16:M16) -> 45
A16: MAU | G16: =G17*G7 -> 0 | H16: =H17*H7 -> 0 | I16: =I17*I7 -> 0.275 | J16: =J17*J7 -> 0.6 | K16: =K17*K7 -> 0.9 | L16: =L17*L7 -> 1.8 | M16: =M17*M7 -> 1.8
A17: As % of install base | I17: =H17+5% -> 0.05 | J17: =I17+5% -> 0.1 | K17: =J17+5% -> 0.15 | L17: 0.3 | M17: 0.3
A18: ARPU | I18: =H18+5 -> 5 | J18: =I18+5 -> 10 | K18: =J18+5 -> 15 | L18: =K18+5 -> 20 | M18: =L18+5 -> 25
A20: Total VR revenue | B20: =B5+B11 -> 501 | C20: =C5+C11 -> 1139 | D20: =D5+D11 -> 2274 | E20: =E5+E11 -> 2125 | F20: =F5+F11 -> 1800 | G20: =G15+G11+G5 -> 1960 | H20: =H15+H11+H5 -> 1460 | I20: =I15+I11+I5 -> 1719.2589 | J20: =J15+J11+J5 -> 1918.8393 | K20: =K15+K11+K5 -> 2029.8214 | L20: =L15+L11+L5 -> 2105.5714 | M20: =M15+M11+M5 -> 2183.5714
A22: Cost of Revenue | B22: =B23+B25+B27 -> 650.15 | C22: =C23+C25+C27 -> 1352.1 | D22: =D23+D25+D27 -> 2703.6 | E22: =E23+E25+E27 -> 2028.75 | F22: =F23+F25+F27 -> 1600 | G22: =G23+G25+G27 -> 1624 | H22: =H23+H25+H27 -> 856.5 | I22: =I23+I25+I27 -> 1023.0607 | ... M22: =M23+M25+M27 -> 1094.7857
A23: Hardware | B23: =B24*B5 -> 650 | C23: =C24*C5 -> 1350 | D23: =D24*D5 -> 2700 | E23: =E24*E5 -> 1980 | F23: =F24*F5 -> 1540 | G23: =G24*G5 -> 1540 | H23: =H24*H5 -> 750 | I23: =I24*I5 -> 900 | ... M23: =M24*M5 -> 900
A24: As % of revenue | B24: 1.3 | C24: 1.2 | D24: 1.2 | E24: 1.1 | F24: 1.1 | G24: 1.1 | H24: 1 | I24: 1 | J24: 1 | K24: 1 | L24: 1 | M24: 1
A25: Software | B25: =B26*B11 -> 0.15 | C25: =C26*C11 -> 2.1 | D25: =D26*D11 -> 3.6 | E25: =E26*E11 -> 48.75 | F25: =F26*F11 -> 60 | G25: =G26*G11 -> 84 | H25: =H26*H11 -> 106.5 | I25: =I26*I11 -> 122.78571 | ... M25: =M26*M11 -> 185.78571
A26: =A24 -> As % of revenue | B26: 0.15 | C26: 0.15 | D26: 0.15 | E26: 0.15 | F26: 0.15 | G26: 0.15 | H26: 0.15 | I26: 0.15 | J26: 0.15 | K26: 0.15 | L26: 0.15 | M26: 0.15
A27: Advertising | H27: =H28*H15 -> 0 | I27: =I28*I15 -> 0.275 | J27: =J28*J15 -> 1.3125 | K27: =K28*K15 -> 2.8125 | L27: =L28*L15 -> 5.4 | M27: =M28*M15 -> 9
A28: As % of revenue | B28: 0 | C28: 0 | D28: 0 | E28: 0 | F28: 0 | G28: 0 | H28: 0.5 | I28: 0.4 | J28: 0.3 | K28: 0.25 | L28: 0.2 | M28: 0.2
A30: Gross Profit | B30: =B20-B22 -> -149.15 | C30: =C20-C22 -> -213.1 | D30: =D20-D22 -> -429.6 | E30: =E20-E22 -> 96.25 | F30: =F20-F22 -> 200 | G30: =G20-G22 -> 336 | H30: =H20-H22 -> 603.5 | I30: =I20-I22 -> 696.19821 | ... M30: =M20-M22 -> 1088.7857
A31: Gross Margin | B31: =B30/B20 -> -0.29770459 | C31: =C30/C20 -> -0.18709394 | D31: =D30/D20 -> -0.18891821 | E31: =E30/E20 -> 0.045294118 | F31: =F30/F20 -> 0.11111111 | G31: =G30/G20 -> 0.17142857 | H31: =H30/H20 -> 0.41335616 | I31: =I30/I20 -> 0.40494087 | ... M31: =M30/M20 -> 0.4986261
A34: AR
A36: =A5 -> Hardware revenue | E36: =E37*E40 -> 30 | F36: =F37*F40 -> 87.5 | G36: =G37*G40 -> 190 | H36: =H37*H40 -> 750 | I36: =I37*I40 -> 2000 | J36: =J37*J40 -> 4000 | K36: =K37*K40 -> 8000 | L36: =L37*L40 -> 10000 | M36: =M37*M40 -> 12000
A37: =A6 -> Unit Sold | E37: 0.2 | F37: 0.5 | G37: 1 | H37: 3 | I37: 5 | J37: =I37+5 -> 10 | K37: 20 | L37: 25 | M37: 30
A38: Install base | I38: =H37+I37 -> 8 | J38: =I37+J37 -> 15 | K38: =J37+K37 -> 30 | L38: =K37+L37 -> 45 | M38: =L37+M37 -> 55
A40: =A9 -> Price | E40: 150 | F40: 175 | G40: 190 | H40: 250 | I40: 400 | J40: 400 | K40: 400 | L40: 400 | M40: 400
A42: =A11 -> Software revenue | J42: =J43*AVERAGE(I38:J38) -> 115 | K42: =K43*AVERAGE(J38:K38) -> 562.5 | L42: =L43*AVERAGE(K38:L38) -> 1687.5 | M42: =M43*AVERAGE(L38:M38) -> 3750
A43: Per device | J43: =J44 -> 10 | K43: =J43+K44 -> 25 | L43: =K43+L44 -> 45 | M43: =L43+M44 -> 75
A44: Increase | J44: 10 | K44: 15 | L44: 20 | M44: 30
A46: =A15 -> Advertising | M46: =AVERAGE(L47:M47)*M49 -> 137.5
A47: MAU | M47: =M48*M38 -> 5.5
A48: As % of install base | M48: 0.1
A49: ARPU | M49: 25
A51: Total AR revenue | B51: =B36+B42+B46 -> 0 | C51: =C36+C42+C46 -> 0 | D51: =D36+D42+D46 -> 0 | E51: =E36+E42+E46 -> 30 | F51: =F36+F42+F46 -> 87.5 | G51: =G36+G42+G46 -> 190 | H51: =H36+H42+H46 -> 750 | I51: =I36+I42+I46 -> 2000 | ... M51: =M36+M42+M46 -> 15887.5
A53: Cost of Revenue | B53: =B54+B56+B58 -> 0 | C53: =C54+C56+C58 -> 0 | D53: =D54+D56+D58 -> 0 | E53: =E54+E56+E58 -> 45 | F53: =F54+F56+F58 -> 131.25 | G53: =G54+G56+G58 -> 285 | H53: =H54+H56+H58 -> 1125 | I53: =I54+I56+I58 -> 2400 | ... M53: =M54+M56+M58 -> 7790
A54: Hardware | E54: =E55*E36 -> 45 | F54: =F55*F36 -> 131.25 | G54: =G55*G36 -> 285 | H54: =H55*H36 -> 1125 | I54: =I55*I36 -> 2400 | J54: =J55*J36 -> 4000 | K54: =K55*K36 -> 7200 | L54: =L55*L36 -> 8000 | M54: =M55*M36 -> 7200
A55: As % of revenue | E55: 1.5 | F55: 1.5 | G55: 1.5 | H55: 1.5 | I55: 1.2 | J55: 1 | K55: 0.9 | L55: 0.8 | M55: 0.6
A56: Software | J56: =J57*J42 -> 17.25 | K56: =K57*K42 -> 84.375 | L56: =L57*L42 -> 253.125 | M56: =M57*M42 -> 562.5
...

Sheet Quarterly Data
B1: 1Q'19 | C1: 2Q'19 | D1: 3Q'19 | E1: 4Q'19 | F1: 1Q'20 | G1: 2Q'20 | H1: 3Q'20 | I1: 4Q'20 | J1: 1Q'21 | K1: 2Q'21 | L1: 3Q'21 | M1: 4Q'21 | N1: 1Q'22 | O1: 2Q'22 | P1: 3Q'22 | Q1: 4Q'22 | R1: 1Q'23 | S1: 2Q'23 | T1: 3Q'23 | U1: 4Q'23 | V1: 1Q'24 | W1: 2Q'24 | X1: 3Q'24 | Y1: 4Q'24
A2: Facebook (includes Messenger)
A4: DAU | B4: =B21+B22+B23+B24 -> 1558 | C4: =C21+C22+C23+C24 -> 1587 | D4: =D21+D22+D23+D24 -> 1621 | E4: =E21+E22+E23+E24 -> 1651 | F4: =F21+F22+F23+F24 -> 1723 | G4: =G21+G22+G23+G24 -> 1785 | H4: =H21+H22+H23+H24 -> 1821 | I4: =I21+I22+I23+I24 -> 1845 | ... Q4: =Q21+Q22+Q23+Q24 -> 2000 | R4: 2037 | S4: 2064 | T4: 2085 | U4: 2110 | AC4: GOOG | AD4: 0.0297
A5: Growth QoQ | C5: =C4-B4 -> 29 | D5: =D4-C4 -> 34 | E5: =E4-D4 -> 30 | F5: =F4-E4 -> 72 | G5: =G4-F4 -> 62 | H5: =H4-G4 -> 36 | I5: =I4-H4 -> 24 | J5: =J4-I4 -> 32 | ... U5: =U4-T4 -> 25
A6: DAU/MAU | B6: =B4/B7 -> 0.65572391 | C6: =C4/C7 -> 0.65741508 | D6: =D4/D7 -> 0.66190282 | E6: =E4/E7 -> 0.66119343 | F6: =F4/F7 -> 0.66192854 | G6: =G4/G7 -> 0.66111111 | H6: =H4/H7 -> 0.66459854 | I6: =I4/I7 -> 0.65963532 | ... U6: =U4/U7 -> 0.68841762
A7: MAU | B7: =B27+B28+B29+B30 -> 2376 | C7: =C27+C28+C29+C30 -> 2414 | D7: =D27+D28+D29+D30 -> 2449 | E7: =E27+E28+E29+E30 -> 2497 | F7: =F27+F28+F29+F30 -> 2603 | G7: =G27+G28+G29+G30 -> 2700 | H7: =H27+H28+H29+H30 -> 2740 | I7: =I27+I28+I29+I30 -> 2797 | ... Q7: =Q27+Q28+Q29+Q30 -> 2964 | R7: 2989 | S7: 3030 | T7: 3049 | U7: 3065
A8: Growth QoQ | C8: =C7-B7 -> 38 | D8: =D7-C7 -> 35 | E8: =E7-D7 -> 48 | F8: =F7-E7 -> 106 | G8: =G7-F7 -> 97 | H8: =H7-G7 -> 40 | I8: =I7-H7 -> 57 | J8: =J7-I7 -> 55 | ... U8: =U7-T7 -> 16
A10: Family of Apps
A12: DAP | B12: 2100 | C12: 2140 | D12: 2200 | E12: 2260 | F12: 2360 | G12: 2470 | H12: 2540 | I12: 2600 | J12: 2720 | K12: 2760 | L12: 2810 | M12: 2820 | N12: 2870 | O12: 2880 | P12: 2930 | Q12: 2960 | R12: 3002 | S12: 3007 | T12: 3140 | U12: 3190 | V12: 3240 | W12: 3270 | X12: 3290 | Y12: 3350
A13: Growth QoQ | C13: =C12-B12 -> 40 | D13: =D12-C12 -> 60 | E13: =E12-D12 -> 60 | F13: =F12-E12 -> 100 | G13: =G12-F12 -> 110 | H13: =H12-G12 -> 70 | I13: =I12-H12 -> 60 | J13: =J12-I12 -> 120 | ... Y13: =Y12-X12 -> 60
A14: DAP/DAU | B14: =B12/B4 -> 1.3478819 | C14: =C12/C4 -> 1.3484562 | D14: =D12/D4 -> 1.3571869 | E14: =E12/E4 -> 1.3688674 | F14: =F12/F4 -> 1.369704 | G14: =G12/G4 -> 1.3837535 | H14: =H12/H4 -> 1.394838 | I14: =I12/I4 -> 1.4092141 | ... U14: =U12/U4 -> 1.5118483
A15: DAP/MAP | B15: =B12/B16 -> 0.78066914 | C15: =C12/C16 -> 0.77536232 | D15: =D12/D16 -> 0.78014184 | E15: =E12/E16 -> 0.78200692 | F15: =F12/F16 -> 0.78929766 | G15: =G12/G16 -> 0.7866242 | H15: =H12/H16 -> 0.79127726 | I15: =I12/I16 -> 0.78787879 | ... U15: =U12/U16 -> 0.80150754
A16: MAP | B16: 2690 | C16: 2760 | D16: 2820 | E16: 2890 | F16: 2990 | G16: 3140 | H16: 3210 | I16: 3300 | J16: 3450 | K16: 3510 | L16: 3580 | M16: 3590 | N16: 3640 | O16: 3650 | P16: 3710 | Q16: 3740 | R16: 3810 | S16: 3880 | T16: 3960 | U16: 3980
A17: Implied IG+WhatsApp only DAU | B17: =B12-B4 -> 542 | C17: =C12-C4 -> 553 | D17: =D12-D4 -> 579 | E17: =E12-E4 -> 609 | F17: =F12-F4 -> 637 | G17: =G12-G4 -> 685 | H17: =H12-H4 -> 719 | I17: =I12-I4 -> 755 | ... U17: =U12-U4 -> 1080
A18: Growth QoQ | C18: =C17-B17 -> 11 | D18: =D17-C17 -> 26 | E18: =E17-D17 -> 30 | F18: =F17-E17 -> 28 | G18: =G17-F17 -> 48 | H18: =H17-G17 -> 34 | I18: =I17-H17 -> 36 | J18: =J17-I17 -> 88 | ... U18: =U17-T17 -> 25
A20: DAU Mix
A21: US & Canada | B21: 186 | C21: 187 | D21: 189 | E21: 190 | F21: 195 | G21: 198 | H21: 196 | I21: 195 | J21: 195 | K21: 195 | L21: 196 | M21: 195 | N21: 196 | O21: 197 | P21: 197 | Q21: 199 | R21: 200 | S21: 202 | T21: 203 | U21: 205
A22: Europe | B22: 282 | C22: 286 | D22: 286 | E22: 288 | F22: 294 | G22: 305 | H22: 305 | I22: 308 | J22: 309 | K22: 307 | L22: 308 | M22: 309 | N22: 307 | O22: 303 | P22: 303 | Q22: 304 | R22: 307 | S22: 307 | T22: 307 | U22: 308
A23: Asia-Pacific | B23: 600 | C23: 615 | D23: 627 | E23: 641 | F23: 678 | G23: 699 | H23: 727 | I23: 744 | J23: 760 | K23: 788 | L23: 805 | M23: 806 | N23: 827 | O23: 836 | P23: 845 | Q23: 854 | R23: 873 | S23: 891 | T23: 899 | U23: 914
A24: Rest of the World | B24: 490 | C24: 499 | D24: 519 | E24: 532 | F24: 556 | G24: 583 | H24: 593 | I24: 598 | J24: 613 | K24: 618 | L24: 622 | M24: 619 | N24: 629 | O24: 631 | P24: 638 | Q24: 643 | R24: 657 | S24: 665 | T24: 676 | U24: 683
L25: =SUM(L21:L24) -> 1931 | M25: =SUM(M21:M24) -> 1929 | N25: =SUM(N21:N24) -> 1959 | O25: =SUM(O21:O24) -> 1967 | P25: =SUM(P21:P24) -> 1983 | Q25: =SUM(Q21:Q24) -> 2000 | R25: =SUM(R21:R24) -> 2037 | S25: =SUM(S21:S24) -> 2065 | ... U25: =SUM(U21:U24) -> 2110
A26: MAU Mix
A27: =A21 -> US & Canada | B27: 243 | C27: 244 | D27: 247 | E27: 248 | F27: 253 | G27: 256 | H27: 255 | I27: 258 | J27: 259 | K27: 259 | L27: 261 | M27: 262 | N27: 263 | O27: 264 | P27: 266 | Q27: 266 | R27: 269 | S27: 270 | T27: 271 | U27: 272
A28: =A22 -> Europe | B28: 384 | C28: 385 | D28: 387 | E28: 394 | F28: 406 | G28: 410 | H28: 413 | I28: 419 | J28: 423 | K28: 420 | L28: 423 | M28: 427 | N28: 418 | O28: 407 | P28: 408 | Q28: 407 | R28: 411 | S28: 409 | T28: 408 | U28: 408
A29: =A23 -> Asia-Pacific | B29: 981 | C29: 1003 | D29: 1013 | E29: 1038 | F29: 1093 | G29: 1142 | H29: 1166 | I29: 1199 | J29: 1230 | K29: 1265 | L29: 1278 | M29: 1278 | N29: 1297 | O29: 1305 | P29: 1312 | Q29: 1312 | R29: 1324 | S29: 1349 | T29: 1357 | U29: 1367
A30: =A24 -> Rest of the World | B30: 768 | C30: 782 | D30: 802 | E30: 817 | F30: 851 | G30: 892 | H30: 906 | I30: 921 | J30: 940 | K30: 951 | L30: 949 | M30: 945 | N30: 957 | O30: 959 | P30: 971 | Q30: 979 | R30: 986 | S30: 1002 | T30: 1013 | U30: 1018
B31: =SUM(B27:B30) -> 2376 | C31: =SUM(C27:C30) -> 2414 | D31: =SUM(D27:D30) -> 2449 | E31: =SUM(E27:E30) -> 2497 | F31: =SUM(F27:F30) -> 2603 | G31: =SUM(G27:G30) -> 2700 | H31: =SUM(H27:H30) -> 2740 | I31: =SUM(I27:I30) -> 2797 | ... U31: =SUM(U27:U30) -> 3065
A32: DAU/MAU
A33: =A27 -> US & Canada | B33: =B21/B27 -> 0.7654321 | C33: =C21/C27 -> 0.76639344 | D33: =D21/D27 -> 0.76518219 | E33: =E21/E27 -> 0.76612903 | F33: =F21/F27 -> 0.77075099 | G33: =G21/G27 -> 0.7734375 | H33: =H21/H27 -> 0.76862745 | I33: =I21/I27 -> 0.75581395 | ... U33: =U21/U27 -> 0.75367647
A34: =A28 -> Europe | B34: =B22/B28 -> 0.734375 | C34: =C22/C28 -> 0.74285714 | D34: =D22/D28 -> 0.73901809 | E34: =E22/E28 -> 0.73096447 | F34: =F22/F28 -> 0.72413793 | G34: =G22/G28 -> 0.74390244 | H34: =H22/H28 -> 0.73849879 | I34: =I22/I28 -> 0.73508353 | ... U34: =U22/U28 -> 0.75490196
A35: =A29 -> Asia-Pacific | B35: =B23/B29 -> 0.6116208 | C35: =C23/C29 -> 0.61316052 | D35: =D23/D29 -> 0.6189536 | E35: =E23/E29 -> 0.61753372 | F35: =F23/F29 -> 0.62031107 | G35: =G23/G29 -> 0.61208406 | H35: =H23/H29 -> 0.62349914 | I35: =I23/I29 -> 0.6205171 | ... U35: =U23/U29 -> 0.66861741
A36: =A30 -> Rest of the World | B36: =B24/B30 -> 0.63802083 | C36: =C24/C30 -> 0.63810742 | D36: =D24/D30 -> 0.64713217 | E36: =E24/E30 -> 0.65116279 | F36: =F24/F30 -> 0.653349 | G36: =G24/G30 -> 0.65358744 | H36: =H24/H30 -> 0.65452539 | I36: =I24/I30 -> 0.64929425 | ... U36: =U24/U30 -> 0.67092338
R37: =R25/R31 -> 0.6812709 | S37: =S25/S31 -> 0.68151815 | T37: =T25/T31 -> 0.68383076 | U37: =U25/U31 -> 0.68841762
A38: FOA
A39: Ad Revenue by Geography
A40: =A21 -> US & Canada | B40: 7203 | C40: 7952 | D40: 8317 | E40: 10021 | F40: 8379 | G40: 9059 | H40: 9988 | I40: 13150 | J40: 11897 | K40: 13366 | L40: 13094 | M40: 15062 | N40: 12024 | O40: 12788 | P40: 12766 | Q40: 15005 | R40: 12710 | S40: 14131 | T40: 14956 | U40: 17784 | V40: 15451 | W40: 16593 | X40: 17389 | Y40: 20982
A41: Europe | B41: 3609 | C41: 4043 | D41: 4057 | E41: 5071 | F41: 4171 | G41: 4411 | H41: 5051 | I41: 6822 | J41: 6373 | K41: 7205 | L41: 6821 | M41: 8174 | N41: 6364 | O41: 6360 | P41: 5707 | Q41: 6904 | R41: 6269 | S41: 7268 | T41: 7721 | U41: 9159 | V41: 8327 | W41: 9135 | X41: 9358 | Y41: 11154
A42: Asia Pacific | B42: 2670 | C42: 2985 | D42: 3243 | E42: 3642 | F42: 3236 | G42: 3312 | H42: 4202 | I42: 4703 | J42: 4735 | K42: 5152 | L42: 5398 | M42: 6183 | N42: 5661 | O42: 5835 | P42: 5717 | Q42: 5968 | R42: 5893 | S42: 6435 | T42: 6829 | U42: 7316 | V42: 7338 | W42: 7721 | X42: 8050 | Y42: 9012
A43: Rest of the World | B43: 1430 | C43: 1644 | D43: 1766 | E43: 2002 | F43: 1654 | G43: 1539 | H43: 1980 | I43: 2512 | J43: 2434 | K43: 2857 | L43: 2963 | M43: 3220 | N43: 2949 | O43: 3169 | P43: 3047 | Q43: 3377 | R43: 3229 | S43: 3664 | T43: 4137 | U43: 4447 | V43: 4519 | W43: 4880 | X43: 5088 | Y43: 5635
A44: Worldwide | B44: =SUM(B40:B43) -> 14912 | C44: =SUM(C40:C43) -> 16624 | D44: =SUM(D40:D43) -> 17383 | E44: =SUM(E40:E43) -> 20736 | F44: =SUM(F40:F43) -> 17440 | G44: =SUM(G40:G43) -> 18321 | H44: =SUM(H40:H43) -> 21221 | I44: =SUM(I40:I43) -> 27187 | ... Y44: =SUM(Y40:Y43) -> 46783
...
