Workbook

Sheet Cover
A1: Oracle Corporation (ORCL)
A2: DCF valuation — exit-multiple terminal · defaults anchored to consensus
A4: Last updated | B4: 2026-06-07
A5: Data pulled (FMP) | B5: Q3 2026
A6: Assumptions by | B6: Opus 4.8 — 2026-06-07
A8: VALUATION SUMMARY
A10: Fair value / share | B10: =Valuation!B36
A11: Current price | B11: =Valuation!$B$2
A12: Upside / (downside) | B12: =Valuation!B42
A13: Verdict | B13: =IF(Valuation!B36>Valuation!$B$2,"Undervalued","Overvalued")
A14: Monte Carlo P(undervalued) | B14: ='Monte Carlo'!B20
A15: KEY ASSUMPTIONS
A17: WACC (from WACC tab) | B17: =WACC!B14
A18: Terminal method | B18: =Valuation!$B$6
A19: Exit basis / multiple | B19: =Valuation!$B$7
A20: Exit multiple | B20: =Valuation!$B$8
A21: Terminal growth (g) | B21: =Valuation!$B$4
A22: Terminal weight | B22: =Valuation!B39
A23: Forecast horizon | B23: 10 years
A25: THE STORY (Opus)
A27: Oracle is a mature database/applications franchise re-accelerating on OCI and AI-training capacity, with a record RPO backlog driving the Cloud & License segment to ~20%+ near-term growth while legacy Services and Hardware stagnate or decline. We fade total growth toward a ~4% mature rate as the AI capacity buildout matures and the cloud base gets large; operating margins expand from ~31% toward ~38% on scale and software mix, but the aggressive, partly debt-funded data-center capex ramp (37% of revenue in FY25) keeps near-term FCFF compressed before capex/D&A normalizes to ~1.1x at maturity. The value rests on OCI compounding into a durable cash engine that eventually out-earns its capex.

Sheet Dashboard
A1: Oracle Corporation (ORCL) — Control Dashboard
A2: Edit the yellow cells; everything recomputes. Orange = a driver you've moved off consensus.
A4: VERDICT
A5: Fair value / share | B5: =Valuation!B36
A6: Current price | B6: =Dashboard!$B$48
A7: Upside / (downside) | B7: =Valuation!B42
A8: Verdict | B8: =IF(Valuation!B36>Dashboard!$B$48,"Undervalued","Overvalued")
A9: Monte Carlo P(undervalued) | B9: ='Monte Carlo'!B20
A11: GUARDRAIL SIGNALS (are my assumptions sane?)
A12: Signal | B12: Value | C12: Flag | D12: Healthy
A13: Terminal weight (% of EV) | B13: =Valuation!B39 | C13: =IF(Valuation!B39>0.9,"! high","ok") | D13: < 90%
A14: Implied g vs exit multiple | B14: =Valuation!B40 | C14: =IF(Valuation!B40>Dashboard!$B$46+0.02,"! rich","ok") | D14: near term g
A15: ROIC - WACC (2026) | B15: =Model!G40-WACC!B14 | C15: =IF(Model!G40-WACC!B14<0,"! destroys","creates") | D15: > 0
A16: Revenue vs consensus (2026) | B16: =Consensus!B6 | C16: =IF(ABS(Consensus!B6)>0.05,"! off-Street","on") | D16: +/- 5%
A17: MC P(undervalued) | B17: ='Monte Carlo'!B20 | C17: =IF('Monte Carlo'!B20<0.5,"! coin-flip","ok") | D17: context
A18: REVENUE DRIVERS — near-term & terminal growth per segment
A19: Segment | B19: Near-term | C19: Terminal | D19: Consensus | E19: Thesis claim
A20: Cloud And License Business | B20: 0.22 | C20: 0.04 | D20: 0.22
A21: Services Business | B21: 0.02 | C21: 0.03 | D21: 0.02
A22: Hardware Business | B22: -0.02 | C22: 0.02 | D22: -0.02
A28: PROFITABILITY & TAX
A29: Near-term operating margin | B29: 0.31 | D29: 0.31 | E29: consensus-implied; ramps to terminal
A30: Terminal operating margin | B30: 0.38 | E30: AI/ads mix + operating leverage
A31: Tax rate | B31: 0.21
A33: CAPITAL INTENSITY
A34: 2026 capex ($M) | B34: 20180.682 | D34: 20180.682 | E34: ~last-year capex +10%; set to guidance
A35: Terminal capex / D&A | B35: 1.05 | E35: converges to ~1.0x as build-out matures
A37: DISCOUNT RATE & TERMINAL
A38: Risk-free rate (10Y) | B38: 0.043
A39: Equity risk premium | B39: 0.045
A40: Beta (levered) | B40: 1.544 | E40: FMP raw beta; Damodaran bottom-up ~1.2
A41: Pre-tax cost of debt | B41: 0.045
A42: WACC (computed) | B42: =WACC!B14
A43: Terminal method | B43: Exit multiple
A44: Exit basis | B44: EV/EBITDA
A45: Exit multiple | B45: 14
A46: Terminal growth (g) | B46: 0.04
A48: Current price | B48: 181.47

Sheet Color Code
A1: Color | B1: Meaning
A2: Black | B2: Formula-driven (same-sheet)
A3: Blue | B3: Hard-coded actuals (from FMP filings)
A4: Yellow | B4: An assumption you can change — edit these to drive the model
A5: Green | B5: A formula that links to another sheet
A6: Orange | B6: (Dashboard) an assumption you've moved off consensus — your active bet
A7: How to use | B7: Edit yellow cells (Model assumptions, WACC drivers, Valuation toggles). Everything else recomputes.

Sheet WACC
A1: WACC Calculator
A2: Risk-free rate (10Y) | B2: =Dashboard!$B$38
A3: Equity risk premium | B3: =Dashboard!$B$39
A4: Beta (levered) | B4: =Dashboard!$B$40
A5: Cost of equity (CAPM) | B5: =B2+B4*B3
A6: Pre-tax cost of debt | B6: =Dashboard!$B$41
A7: Tax rate | B7: =Dashboard!$B$31
A8: After-tax cost of debt | B8: =B6*(1-B7)
A9: Market cap (E) | B9: =Dashboard!$B$48*Financials!AC17
A10: Total debt (D) | B10: =Financials!AC44
A11: Equity weight | B11: =B9/(B9+B10)
A12: Debt weight | B12: =B10/(B9+B10)
A14: WACC | B14: =B11*B5+B12*B8
A16: Yellow = edit. CAPM cost of equity; market-value weights. Feeds Valuation!WACC.

Sheet Model
A1: $M unless noted | B1: FY2021A | C1: FY2022A | D1: FY2023A | E1: FY2024A | F1: FY2025A | G1: FY2026E | H1: FY2027E | I1: FY2028E | J1: FY2029E | K1: FY2030E | L1: FY2031E | M1: FY2032E | N1: FY2033E | O1: FY2034E | P1: FY2035E
A3: REVENUE BY SEGMENT (yellow = growth assumption; actuals link to Financials)
A4: Cloud And License Business | B4: =SUM(Financials!G19:J19) | C4: =SUM(Financials!K19:N19) | D4: =SUM(Financials!O19:R19) | E4: =SUM(Financials!S19:V19) | F4: =SUM(Financials!W19:Z19) | G4: =F4*(1+G5) | H4: =G4*(1+H5) | I4: =H4*(1+I5) | J4: =I4*(1+J5) | K4: =J4*(1+K5) | L4: =K4*(1+L5) | M4: =L4*(1+M5) | N4: =M4*(1+N5) | ... P4: =O4*(1+P5)
A5: growth % (interpolated from Dashboard) | C5: =IFERROR(C4/B4-1,"") | D5: =IFERROR(D4/C4-1,"") | E5: =IFERROR(E4/D4-1,"") | F5: =IFERROR(F4/E4-1,"") | G5: =Dashboard!$B$20+(Dashboard!$C$20-Dashboard!$B$20)*MAX(0,0-2)/7 | H5: =Dashboard!$B$20+(Dashboard!$C$20-Dashboard!$B$20)*MAX(0,1-2)/7 | I5: =Dashboard!$B$20+(Dashboard!$C$20-Dashboard!$B$20)*MAX(0,2-2)/7 | J5: =Dashboard!$B$20+(Dashboard!$C$20-Dashboard!$B$20)*MAX(0,3-2)/7 | K5: =Dashboard!$B$20+(Dashboard!$C$20-Dashboard!$B$20)*MAX(0,4-2)/7 | L5: =Dashboard!$B$20+(Dashboard!$C$20-Dashboard!$B$20)*MAX(0,5-2)/7 | M5: =Dashboard!$B$20+(Dashboard!$C$20-Dashboard!$B$20)*MAX(0,6-2)/7 | N5: =Dashboard!$B$20+(Dashboard!$C$20-Dashboard!$B$20)*MAX(0,7-2)/7 | O5: =Dashboard!$B$20+(Dashboard!$C$20-Dashboard!$B$20)*MAX(0,8-2)/7 | P5: =Dashboard!$B$20+(Dashboard!$C$20-Dashboard!$B$20)*MAX(0,9-2)/7
A6: Services Business | B6: =SUM(Financials!G22:J22) | C6: =SUM(Financials!K22:N22) | D6: =SUM(Financials!O22:R22) | E6: =SUM(Financials!S22:V22) | F6: =SUM(Financials!W22:Z22) | G6: =F6*(1+G7) | H6: =G6*(1+H7) | I6: =H6*(1+I7) | J6: =I6*(1+J7) | K6: =J6*(1+K7) | L6: =K6*(1+L7) | M6: =L6*(1+M7) | N6: =M6*(1+N7) | ... P6: =O6*(1+P7)
A7: growth % (interpolated from Dashboard) | C7: =IFERROR(C6/B6-1,"") | D7: =IFERROR(D6/C6-1,"") | E7: =IFERROR(E6/D6-1,"") | F7: =IFERROR(F6/E6-1,"") | G7: =Dashboard!$B$21+(Dashboard!$C$21-Dashboard!$B$21)*MAX(0,0-2)/7 | H7: =Dashboard!$B$21+(Dashboard!$C$21-Dashboard!$B$21)*MAX(0,1-2)/7 | I7: =Dashboard!$B$21+(Dashboard!$C$21-Dashboard!$B$21)*MAX(0,2-2)/7 | J7: =Dashboard!$B$21+(Dashboard!$C$21-Dashboard!$B$21)*MAX(0,3-2)/7 | K7: =Dashboard!$B$21+(Dashboard!$C$21-Dashboard!$B$21)*MAX(0,4-2)/7 | L7: =Dashboard!$B$21+(Dashboard!$C$21-Dashboard!$B$21)*MAX(0,5-2)/7 | M7: =Dashboard!$B$21+(Dashboard!$C$21-Dashboard!$B$21)*MAX(0,6-2)/7 | N7: =Dashboard!$B$21+(Dashboard!$C$21-Dashboard!$B$21)*MAX(0,7-2)/7 | O7: =Dashboard!$B$21+(Dashboard!$C$21-Dashboard!$B$21)*MAX(0,8-2)/7 | P7: =Dashboard!$B$21+(Dashboard!$C$21-Dashboard!$B$21)*MAX(0,9-2)/7
A8: Hardware Business | B8: =SUM(Financials!G25:J25) | C8: =SUM(Financials!K25:N25) | D8: =SUM(Financials!O25:R25) | E8: =SUM(Financials!S25:V25) | F8: =SUM(Financials!W25:Z25) | G8: =F8*(1+G9) | H8: =G8*(1+H9) | I8: =H8*(1+I9) | J8: =I8*(1+J9) | K8: =J8*(1+K9) | L8: =K8*(1+L9) | M8: =L8*(1+M9) | N8: =M8*(1+N9) | ... P8: =O8*(1+P9)
A9: growth % (interpolated from Dashboard) | C9: =IFERROR(C8/B8-1,"") | D9: =IFERROR(D8/C8-1,"") | E9: =IFERROR(E8/D8-1,"") | F9: =IFERROR(F8/E8-1,"") | G9: =Dashboard!$B$22+(Dashboard!$C$22-Dashboard!$B$22)*MAX(0,0-2)/7 | H9: =Dashboard!$B$22+(Dashboard!$C$22-Dashboard!$B$22)*MAX(0,1-2)/7 | I9: =Dashboard!$B$22+(Dashboard!$C$22-Dashboard!$B$22)*MAX(0,2-2)/7 | J9: =Dashboard!$B$22+(Dashboard!$C$22-Dashboard!$B$22)*MAX(0,3-2)/7 | K9: =Dashboard!$B$22+(Dashboard!$C$22-Dashboard!$B$22)*MAX(0,4-2)/7 | L9: =Dashboard!$B$22+(Dashboard!$C$22-Dashboard!$B$22)*MAX(0,5-2)/7 | M9: =Dashboard!$B$22+(Dashboard!$C$22-Dashboard!$B$22)*MAX(0,6-2)/7 | N9: =Dashboard!$B$22+(Dashboard!$C$22-Dashboard!$B$22)*MAX(0,7-2)/7 | O9: =Dashboard!$B$22+(Dashboard!$C$22-Dashboard!$B$22)*MAX(0,8-2)/7 | P9: =Dashboard!$B$22+(Dashboard!$C$22-Dashboard!$B$22)*MAX(0,9-2)/7
A10: Total revenue | B10: =B4+B6+B8 | C10: =C4+C6+C8 | D10: =D4+D6+D8 | E10: =E4+E6+E8 | F10: =F4+F6+F8 | G10: =G4+G6+G8 | H10: =H4+H6+H8 | I10: =I4+I6+I8 | ... P10: =P4+P6+P8
A11: growth % | C11: =IFERROR(C10/B10-1,"") | D11: =IFERROR(D10/C10-1,"") | E11: =IFERROR(E10/D10-1,"") | F11: =IFERROR(F10/E10-1,"") | G11: =IFERROR(G10/F10-1,"") | H11: =IFERROR(H10/G10-1,"") | I11: =IFERROR(I10/H10-1,"") | J11: =IFERROR(J10/I10-1,"") | ... P11: =IFERROR(P10/O10-1,"")
A13: COST STRUCTURE (yellow = % of revenue)
A14: Cost of revenue | B14: =SUM(Financials!G5:J5) | C14: =SUM(Financials!K5:N5) | D14: =SUM(Financials!O5:R5) | E14: =SUM(Financials!S5:V5) | F14: =SUM(Financials!W5:Z5) | G14: =G10*G15 | H14: =H10*H15 | I14: =I10*I15 | J14: =J10*J15 | K14: =K10*K15 | L14: =L10*L15 | M14: =M10*M15 | N14: =N10*N15 | ... P14: =P10*P15
A15: % of revenue | B15: =IFERROR(B14/B10,"") | C15: =IFERROR(C14/C10,"") | D15: =IFERROR(D14/D10,"") | E15: =IFERROR(E14/E10,"") | F15: =IFERROR(F14/F10,"") | G15: 0.29488319 | H15: 0.29488319 | I15: 0.29488319 | J15: 0.29488319 | K15: 0.29488319 | L15: 0.29488319 | M15: 0.29488319 | N15: 0.29488319 | O15: 0.29488319 | P15: 0.29488319
A16: R&D / Technology | B16: =SUM(Financials!G7:J7) | C16: =SUM(Financials!K7:N7) | D16: =SUM(Financials!O7:R7) | E16: =SUM(Financials!S7:V7) | F16: =SUM(Financials!W7:Z7) | G16: =G10*G17 | H16: =H10*H17 | I16: =I10*I17 | J16: =J10*J17 | K16: =K10*K17 | L16: =L10*L17 | M16: =M10*M17 | N16: =N10*N17 | ... P16: =P10*P17
A17: % of revenue | B17: =IFERROR(B16/B10,"") | C17: =IFERROR(C16/C10,"") | D17: =IFERROR(D16/D10,"") | E17: =IFERROR(E16/E10,"") | F17: =IFERROR(F16/F10,"") | G17: 0.17178 | H17: 0.17178 | I17: 0.17178 | J17: 0.17178 | K17: 0.17178 | L17: 0.17178 | M17: 0.17178 | N17: 0.17178 | O17: 0.17178 | P17: 0.17178
A18: SG&A | B18: =SUM(Financials!G9:J9) | C18: =SUM(Financials!K9:N9) | D18: =SUM(Financials!O9:R9) | E18: =SUM(Financials!S9:V9) | F18: =SUM(Financials!W9:Z9) | G18: =G10*G19 | H18: =H10*H19 | I18: =I10*I19 | J18: =J10*J19 | K18: =K10*K19 | L18: =L10*L19 | M18: =M10*M19 | N18: =N10*N19 | ... P18: =P10*P19
A19: % of revenue | B19: =IFERROR(B18/B10,"") | C19: =IFERROR(C18/C10,"") | D19: =IFERROR(D18/D10,"") | E19: =IFERROR(E18/E10,"") | F19: =IFERROR(F18/F10,"") | G19: 0.17862681 | H19: 0.17862681 | I19: 0.17862681 | J19: 0.17862681 | K19: 0.17862681 | L19: 0.17862681 | M19: 0.17862681 | N19: 0.17862681 | O19: 0.17862681 | P19: 0.17862681
A20: Other opex (fulfilment, etc.) | B20: =B10-(B14+B16+B18)-SUM(Financials!G13:J13) | C20: =C10-(C14+C16+C18)-SUM(Financials!K13:N13) | D20: =D10-(D14+D16+D18)-SUM(Financials!O13:R13) | E20: =E10-(E14+E16+E18)-SUM(Financials!S13:V13) | F20: =F10-(F14+F16+F18)-SUM(Financials!W13:Z13) | G20: =G10*(1-(Dashboard!$B$29+(Dashboard!$B$30-Dashboard!$B$29)*MIN(1,0/4)))-(G14+G16+G18) | H20: =H10*(1-(Dashboard!$B$29+(Dashboard!$B$30-Dashboard!$B$29)*MIN(1,1/4)))-(H14+H16+H18) | I20: =I10*(1-(Dashboard!$B$29+(Dashboard!$B$30-Dashboard!$B$29)*MIN(1,2/4)))-(I14+I16+I18) | J20: =J10*(1-(Dashboard!$B$29+(Dashboard!$B$30-Dashboard!$B$29)*MIN(1,3/4)))-(J14+J16+J18) | K20: =K10*(1-(Dashboard!$B$29+(Dashboard!$B$30-Dashboard!$B$29)*MIN(1,4/4)))-(K14+K16+K18) | L20: =L10*(1-(Dashboard!$B$29+(Dashboard!$B$30-Dashboard!$B$29)*MIN(1,5/4)))-(L14+L16+L18) | M20: =M10*(1-(Dashboard!$B$29+(Dashboard!$B$30-Dashboard!$B$29)*MIN(1,6/4)))-(M14+M16+M18) | N20: =N10*(1-(Dashboard!$B$29+(Dashboard!$B$30-Dashboard!$B$29)*MIN(1,7/4)))-(N14+N16+N18) | O20: =O10*(1-(Dashboard!$B$29+(Dashboard!$B$30-Dashboard!$B$29)*MIN(1,8/4)))-(O14+O16+O18) | P20: =P10*(1-(Dashboard!$B$29+(Dashboard!$B$30-Dashboard!$B$29)*MIN(1,9/4)))-(P14+P16+P18)
A21: % of revenue | B21: =IFERROR(B20/B10,"") | C21: =IFERROR(C20/C10,"") | D21: =IFERROR(D20/D10,"") | E21: =IFERROR(E20/E10,"") | F21: =IFERROR(F20/F10,"") | G21: =IFERROR(G20/G10,"") | H21: =IFERROR(H20/H10,"") | I21: =IFERROR(I20/I10,"") | ... P21: =IFERROR(P20/P10,"")
A23: Operating income (EBIT) | B23: =B10-(B14+B16+B18)-B20 | C23: =C10-(C14+C16+C18)-C20 | D23: =D10-(D14+D16+D18)-D20 | E23: =E10-(E14+E16+E18)-E20 | F23: =F10-(F14+F16+F18)-F20 | G23: =G10-(G14+G16+G18)-G20 | H23: =H10-(H14+H16+H18)-H20 | I23: =I10-(I14+I16+I18)-I20 | ... P23: =P10-(P14+P16+P18)-P20
A24: operating margin | B24: =IFERROR(B23/B10,"") | C24: =IFERROR(C23/C10,"") | D24: =IFERROR(D23/D10,"") | E24: =IFERROR(E23/E10,"") | F24: =IFERROR(F23/F10,"") | G24: =IFERROR(G23/G10,"") | H24: =IFERROR(H23/H10,"") | I24: =IFERROR(I23/I10,"") | ... P24: =IFERROR(P23/P10,"")
A26: FCF BRIDGE (NOPAT + D&A + SBC - dNWC - Capex)
A27: NOPAT = EBIT x (1 - tax) | B27: =B23*(1-Valuation!$B$5) | C27: =C23*(1-Valuation!$B$5) | D27: =D23*(1-Valuation!$B$5) | E27: =E23*(1-Valuation!$B$5) | F27: =F23*(1-Valuation!$B$5) | G27: =G23*(1-Valuation!$B$5) | H27: =H23*(1-Valuation!$B$5) | I27: =I23*(1-Valuation!$B$5) | ... P27: =P23*(1-Valuation!$B$5)
A28: + D&A | B28: =SUM(Financials!G47:J47) | C28: =SUM(Financials!K47:N47) | D28: =SUM(Financials!O47:R47) | E28: =SUM(Financials!S47:V47) | F28: =SUM(Financials!W47:Z47) | G28: =G10*0.1076 | H28: =H10*0.1076 | I28: =I10*0.1076 | J28: =J10*0.1076 | K28: =K10*0.1076 | L28: =L10*0.1076 | M28: =M10*0.1076 | N28: =N10*0.1076 | ... P28: =P10*0.1076
A29: + SBC (non-cash) | B29: =SUM(Financials!G48:J48) | C29: =SUM(Financials!K48:N48) | D29: =SUM(Financials!O48:R48) | E29: =SUM(Financials!S48:V48) | F29: =SUM(Financials!W48:Z48) | G29: =G10*0.0814 | H29: =H10*0.0778 | I29: =I10*0.0742 | J29: =J10*0.0706 | K29: =K10*0.0670 | L29: =L10*0.0633 | M29: =M10*0.0597 | N29: =N10*0.0561 | O29: =O10*0.0525 | P29: =P10*0.0489
A30: - dNWC | G30: =(G10-F10)*0.0050 | H30: =(H10-G10)*0.0050 | I30: =(I10-H10)*0.0050 | J30: =(J10-I10)*0.0050 | K30: =(K10-J10)*0.0050 | L30: =(L10-K10)*0.0050 | M30: =(M10-L10)*0.0050 | N30: =(N10-M10)*0.0050 | ... P30: =(P10-O10)*0.0050
A31: - Capex | B31: =-SUM(Financials!G51:J51) | C31: =-SUM(Financials!K51:N51) | D31: =-SUM(Financials!O51:R51) | E31: =-SUM(Financials!S51:V51) | F31: =-SUM(Financials!W51:Z51) | G31: =G28*G32 | H31: =H28*H32 | I31: =I28*I32 | J31: =J28*J32 | K31: =K28*K32 | L31: =L28*L32 | M31: =M28*M32 | N31: =N28*N32 | ... P31: =P28*P32
A32: Capex / D&A (from Dashboard: $cap'26 -> terminal) | B32: =IFERROR(B31/B28,"") | C32: =IFERROR(C31/C28,"") | D32: =IFERROR(D31/D28,"") | E32: =IFERROR(E31/E28,"") | F32: =IFERROR(F31/F28,"") | G32: =(Dashboard!$B$34/G28)+(Dashboard!$B$35-(Dashboard!$B$34/G28))*0/9 | H32: =(Dashboard!$B$34/G28)+(Dashboard!$B$35-(Dashboard!$B$34/G28))*1/9 | I32: =(Dashboard!$B$34/G28)+(Dashboard!$B$35-(Dashboard!$B$34/G28))*2/9 | J32: =(Dashboard!$B$34/G28)+(Dashboard!$B$35-(Dashboard!$B$34/G28))*3/9 | K32: =(Dashboard!$B$34/G28)+(Dashboard!$B$35-(Dashboard!$B$34/G28))*4/9 | L32: =(Dashboard!$B$34/G28)+(Dashboard!$B$35-(Dashboard!$B$34/G28))*5/9 | M32: =(Dashboard!$B$34/G28)+(Dashboard!$B$35-(Dashboard!$B$34/G28))*6/9 | N32: =(Dashboard!$B$34/G28)+(Dashboard!$B$35-(Dashboard!$B$34/G28))*7/9 | O32: =(Dashboard!$B$34/G28)+(Dashboard!$B$35-(Dashboard!$B$34/G28))*8/9 | P32: =(Dashboard!$B$34/G28)+(Dashboard!$B$35-(Dashboard!$B$34/G28))*9/9
A34: FCFF (firm) | B34: =B27+B28+B29-B30-B31 | C34: =C27+C28+C29-C30-C31 | D34: =D27+D28+D29-D30-D31 | E34: =E27+E28+E29-E30-E31 | F34: =F27+F28+F29-F30-F31 | G34: =G27+G28+G29-G30-G31 | H34: =H27+H28+H29-H30-H31 | I34: =I27+I28+I29-I30-I31 | ... P34: =P27+P28+P29-P30-P31
A35: Valuation FCF (FCFF - SBC) | B35: =B34-B29 | C35: =C34-C29 | D35: =D34-D29 | E35: =E34-E29 | F35: =F34-F29 | G35: =G34-G29 | H35: =H34-H29 | I35: =I34-I29 | ... P35: =P34-P29
A37: RETURNS ON CAPITAL & EFFICIENCY (is new revenue/capital earning its keep?)
A38: Invested capital (debt + equity - cash) | B38: =Financials!J45+Financials!J44-Financials!J39 | C38: =Financials!N45+Financials!N44-Financials!N39 | D38: =Financials!R45+Financials!R44-Financials!R39 | E38: =Financials!V45+Financials!V44-Financials!V39 | F38: =Financials!Z45+Financials!Z44-Financials!Z39 | G38: =F38+G31-G28+G30 | H38: =G38+H31-H28+H30 | I38: =H38+I31-I28+I30 | J38: =I38+J31-J28+J30 | K38: =J38+K31-K28+K30 | L38: =K38+L31-L28+L30 | M38: =L38+M31-M28+M30 | N38: =M38+N31-N28+N30 | ... P38: =O38+P31-P28+P30
A39: Book equity (year-end) | B39: =Financials!J45 | C39: =Financials!N45 | D39: =Financials!R45 | E39: =Financials!V45 | F39: =Financials!Z45 | G39: =F39+G27 | H39: =G39+H27 | I39: =H39+I27 | J39: =I39+J27 | K39: =J39+K27 | L39: =K39+L27 | M39: =L39+M27 | N39: =M39+N27 | ... P39: =O39+P27
A40: ROIC (NOPAT / beg. invested capital) | C40: =IFERROR(C27/B38,"") | D40: =IFERROR(D27/C38,"") | E40: =IFERROR(E27/D38,"") | F40: =IFERROR(F27/E38,"") | G40: =IFERROR(G27/F38,"") | H40: =IFERROR(H27/G38,"") | I40: =IFERROR(I27/H38,"") | J40: =IFERROR(J27/I38,"") | ... P40: =IFERROR(P27/O38,"")
A41: ROE (earnings / beg. equity) | C41: =IFERROR(SUM(Financials!K15:N15)/B39,"") | D41: =IFERROR(SUM(Financials!O15:R15)/C39,"") | E41: =IFERROR(SUM(Financials!S15:V15)/D39,"") | F41: =IFERROR(SUM(Financials!W15:Z15)/E39,"") | G41: =IFERROR(G27/F39,"") | H41: =IFERROR(H27/G39,"") | I41: =IFERROR(I27/H39,"") | J41: =IFERROR(J27/I39,"") | K41: =IFERROR(K27/J39,"") | L41: =IFERROR(L27/K39,"") | M41: =IFERROR(M27/L39,"") | N41: =IFERROR(N27/M39,"") | ... P41: =IFERROR(P27/O39,"")
A42: ROIC - WACC spread (value created) | C42: =IFERROR(C40-WACC!$B$14,"") | D42: =IFERROR(D40-WACC!$B$14,"") | E42: =IFERROR(E40-WACC!$B$14,"") | F42: =IFERROR(F40-WACC!$B$14,"") | G42: =IFERROR(G40-WACC!$B$14,"") | H42: =IFERROR(H40-WACC!$B$14,"") | I42: =IFERROR(I40-WACC!$B$14,"") | J42: =IFERROR(J40-WACC!$B$14,"") | ... P42: =IFERROR(P40-WACC!$B$14,"")
A43: Incremental op margin (ΔEBIT / ΔRev) | C43: =IFERROR((C23-B23)/(C10-B10),"") | D43: =IFERROR((D23-C23)/(D10-C10),"") | E43: =IFERROR((E23-D23)/(E10-D10),"") | F43: =IFERROR((F23-E23)/(F10-E10),"") | G43: =IFERROR((G23-F23)/(G10-F10),"") | H43: =IFERROR((H23-G23)/(H10-G10),"") | I43: =IFERROR((I23-H23)/(I10-H10),"") | J43: =IFERROR((J23-I23)/(J10-I10),"") | ... P43: =IFERROR((P23-O23)/(P10-O10),"")
A44: ROIIC (ΔNOPAT / ΔInvested capital) | C44: =IFERROR((C27-B27)/(C38-B38),"") | D44: =IFERROR((D27-C27)/(D38-C38),"") | E44: =IFERROR((E27-D27)/(E38-D38),"") | F44: =IFERROR((F27-E27)/(F38-E38),"") | G44: =IFERROR((G27-F27)/(G38-F38),"") | H44: =IFERROR((H27-G27)/(H38-G38),"") | I44: =IFERROR((I27-H27)/(I38-H38),"") | J44: =IFERROR((J27-I27)/(J38-I38),"") | ... P44: =IFERROR((P27-O27)/(P38-O38),"")
A45: Sales-to-capital (ΔRev / ΔInvested capital) | C45: =IFERROR((C10-B10)/(C38-B38),"") | D45: =IFERROR((D10-C10)/(D38-C38),"") | E45: =IFERROR((E10-D10)/(E38-D38),"") | F45: =IFERROR((F10-E10)/(F38-E38),"") | G45: =IFERROR((G10-F10)/(G38-F38),"") | H45: =IFERROR((H10-G10)/(H38-G38),"") | I45: =IFERROR((I10-H10)/(I38-H38),"") | J45: =IFERROR((J10-I10)/(J38-I38),"") | ... P45: =IFERROR((P10-O10)/(P38-O38),"")
A46: Reinvestment rate (ΔInvested capital / NOPAT) | C46: =IFERROR((C38-B38)/C27,"") | D46: =IFERROR((D38-C38)/D27,"") | E46: =IFERROR((E38-D38)/E27,"") | F46: =IFERROR((F38-E38)/F27,"") | G46: =IFERROR((G38-F38)/G27,"") | H46: =IFERROR((H38-G38)/H27,"") | I46: =IFERROR((I38-H38)/I27,"") | J46: =IFERROR((J38-I38)/J27,"") | ... P46: =IFERROR((P38-O38)/P27,"")
...

Sheet Financials
A1: Line Item ($M) | B1: Q4 2019 | C1: Q1 2020 | D1: Q2 2020 | E1: Q3 2020 | F1: Q4 2020 | G1: Q1 2021 | H1: Q2 2021 | I1: Q3 2021 | J1: Q4 2021 | K1: Q1 2022 | L1: Q2 2022 | M1: Q3 2022 | N1: Q4 2022 | O1: Q1 2023 | P1: Q2 2023 | Q1: Q3 2023 | R1: Q4 2023 | S1: Q1 2024 | T1: Q2 2024 | U1: Q3 2024 | V1: Q4 2024 | W1: Q1 2025 | X1: Q2 2025 | Y1: Q3 2025 | Z1: Q4 2025 | AA1: Q1 2026 | AB1: Q2 2026 | AC1: Q3 2026
A2: INCOME STATEMENT
A3: Revenue | B3: 11136 | C3: 9218 | D3: 9614 | E3: 9796 | F3: 10439 | G3: 9367 | H3: 9800 | I3: 10085 | J3: 11227 | K3: 9728 | L3: 10360 | M3: 10513 | N3: 11840 | O3: 11445 | P3: 12275 | Q3: 12398 | R3: 13836 | S3: 12453 | T3: 12941 | U3: 13280 | V3: 14287 | W3: 13307 | X3: 14059 | Y3: 14130 | Z3: 15903 | AA3: 14926 | AB3: 16058 | AC3: 17190
A4: % YoY | F4: =IFERROR(F3/B3-1,"") | G4: =IFERROR(G3/C3-1,"") | H4: =IFERROR(H3/D3-1,"") | I4: =IFERROR(I3/E3-1,"") | J4: =IFERROR(J3/F3-1,"") | K4: =IFERROR(K3/G3-1,"") | L4: =IFERROR(L3/H3-1,"") | M4: =IFERROR(M3/I3-1,"") | ... AC4: =IFERROR(AC3/Y3-1,"")
A5: Cost of Revenue | B5: 2063 | C5: 1957 | D5: 2048 | E5: 1964 | F5: 1969 | G5: 1880 | H5: 1939 | I5: 1915 | J5: 2122 | K5: 2103 | L5: 2159 | M5: 2218 | N5: 2397 | O5: 3037 | P5: 3358 | Q5: 3439 | R5: 3730 | S5: 3610 | T5: 3740 | U5: 3869 | V5: 3924 | W5: 3906 | X5: 4085 | Y5: 4195 | Z5: 4740 | AA5: 4884 | AB5: 5374 | AC5: 6505
A6: % of revenue | B6: =IFERROR(B5/B3,"") | C6: =IFERROR(C5/C3,"") | D6: =IFERROR(D5/D3,"") | E6: =IFERROR(E5/E3,"") | F6: =IFERROR(F5/F3,"") | G6: =IFERROR(G5/G3,"") | H6: =IFERROR(H5/H3,"") | I6: =IFERROR(I5/I3,"") | ... AC6: =IFERROR(AC5/AC3,"")
A7: R&D Expense | B7: 1562 | C7: 1557 | D7: 1531 | E7: 1500 | F7: 1479 | G7: 1589 | H7: 1601 | I7: 1621 | J7: 1715 | K7: 1684 | L7: 1754 | M7: 1816 | N7: 1965 | O7: 2093 | P7: 2158 | Q7: 2146 | R7: 2226 | S7: 2216 | T7: 2226 | U7: 2248 | V7: 2226 | W7: 2306 | X7: 2471 | Y7: 2429 | Z7: 2654 | AA7: 2491 | AB7: 2561 | AC7: 2607
A8: % of revenue | B8: =IFERROR(B7/B3,"") | C8: =IFERROR(C7/C3,"") | D8: =IFERROR(D7/D3,"") | E8: =IFERROR(E7/E3,"") | F8: =IFERROR(F7/F3,"") | G8: =IFERROR(G7/G3,"") | H8: =IFERROR(H7/H3,"") | I8: =IFERROR(I7/I3,"") | ... AC8: =IFERROR(AC7/AC3,"")
A9: SG&A Expense | B9: 2648 | C9: 2310 | D9: 2391 | E9: 2337 | F9: 2237 | G9: 2149 | H9: 2160 | I9: 2245 | J9: 2382 | K9: 2152 | L9: 2273 | M9: 2339 | N9: 2602 | O9: 2588 | P9: 2582 | Q9: 2552 | R9: 2689 | S9: 2419 | T9: 2468 | U9: 2419 | V9: 2515 | W9: 2394 | X9: 2577 | Y9: 2509 | Z9: 2773 | AA9: 2439 | AB9: 2558 | AC9: 2441
A10: % of revenue | B10: =IFERROR(B9/B3,"") | C10: =IFERROR(C9/C3,"") | D10: =IFERROR(D9/D3,"") | E10: =IFERROR(E9/E3,"") | F10: =IFERROR(F9/F3,"") | G10: =IFERROR(G9/G3,"") | H10: =IFERROR(H9/H3,"") | I10: =IFERROR(I9/I3,"") | ... AC10: =IFERROR(AC9/AC3,"")
A11: Gross Profit | B11: 9073 | C11: 7261 | D11: 7566 | E11: 7832 | F11: 8470 | G11: 7487 | H11: 7861 | I11: 8170 | J11: 9105 | K11: 7625 | L11: 8201 | M11: 8295 | N11: 9444 | O11: 8408 | P11: 8917 | Q11: 8959 | R11: 10106 | S11: 8843 | T11: 9201 | U11: 9411 | V11: 10363 | W11: 9401 | X11: 9974 | Y11: 9935 | Z11: 11162 | AA11: 10042 | AB11: 10684 | AC11: 10685
A12: gross margin | B12: =IFERROR(B11/B3,"") | C12: =IFERROR(C11/C3,"") | D12: =IFERROR(D11/D3,"") | E12: =IFERROR(E11/E3,"") | F12: =IFERROR(F11/F3,"") | G12: =IFERROR(G11/G3,"") | H12: =IFERROR(H11/H3,"") | I12: =IFERROR(I11/I3,"") | ... AC12: =IFERROR(AC11/AC3,"")
A13: Operating Income | B13: 4257 | C13: 2877 | D13: 3183 | E13: 3528 | F13: 4308 | G13: 3211 | H13: 3583 | I13: 3878 | J13: 4541 | K13: 3427 | L13: -824 | M13: 3822 | N13: 4503 | O13: 2623 | P13: 3071 | Q13: 3260 | R13: 4140 | S13: 3296 | T13: 3622 | U13: 3750 | V13: 4686 | W13: 3991 | X13: 4220 | Y13: 4358 | Z13: 5109 | AA13: 4277 | AB13: 4731 | AC13: 5637
A14: operating margin | B14: =IFERROR(B13/B3,"") | C14: =IFERROR(C13/C3,"") | D14: =IFERROR(D13/D3,"") | E14: =IFERROR(E13/E3,"") | F14: =IFERROR(F13/F3,"") | G14: =IFERROR(G13/G3,"") | H14: =IFERROR(H13/H3,"") | I14: =IFERROR(I13/I3,"") | ... AC14: =IFERROR(AC13/AC3,"")
A15: Net Income | B15: 3740 | C15: 2137 | D15: 2311 | E15: 2571 | F15: 3116 | G15: 2251 | H15: 2442 | I15: 5021 | J15: 4033 | K15: 2457 | L15: -1247 | M15: 2319 | N15: 3189 | O15: 1548 | P15: 1741 | Q15: 1896 | R15: 3319 | S15: 2420 | T15: 2503 | U15: 2401 | V15: 3144 | W15: 2929 | X15: 3151 | Y15: 2936 | Z15: 3427 | AA15: 2927 | AB15: 6135 | AC15: 3721
A16: net margin | B16: =IFERROR(B15/B3,"") | C16: =IFERROR(C15/C3,"") | D16: =IFERROR(D15/D3,"") | E16: =IFERROR(E15/E3,"") | F16: =IFERROR(F15/F3,"") | G16: =IFERROR(G15/G3,"") | H16: =IFERROR(H15/H3,"") | I16: =IFERROR(I15/I3,"") | ... AC16: =IFERROR(AC15/AC3,"")
A17: Diluted Shares (M) | B17: 3505.49 | C17: 3410 | D17: 3349.275 | E17: 3271 | F17: 3162 | G17: 3126.389 | H17: 3052.5 | I17: 2994 | J17: 2949.007 | K17: 2861 | L17: 2694.003 | M17: 2754 | N17: 2742 | O17: 2747 | P17: 2746 | Q17: 2776 | R17: 2796 | S17: 2823 | T17: 2817 | U17: 2819 | V17: 2834 | W17: 2851 | X17: 2869 | Y17: 2874 | Z17: 2871 | AA17: 2909 | AB17: 2922 | AC17: 2914
A18: REVENUE BY SEGMENT — PRODUCT (% YoY, % of revenue)
A19: Cloud And License Business | B19: 9322 | C19: 7619 | D19: 7938 | E19: 8162 | F19: 8804 | G19: 7834 | H19: 8204 | I19: 8529 | J19: 9534 | K19: 8184 | L19: 8791 | M19: 8926 | N19: 10151 | O19: 9321 | P19: 10033 | Q19: 10211 | R19: 11521 | S19: 10356 | T19: 10817 | U19: 11219 | V19: 12072 | W19: 11389 | X19: 12001 | Y19: 12136 | Z19: 13704 | AA19: 12907 | AC19: 15033
A20: % YoY | F20: =IFERROR(F19/B19-1,"") | G20: =IFERROR(G19/C19-1,"") | H20: =IFERROR(H19/D19-1,"") | I20: =IFERROR(I19/E19-1,"") | J20: =IFERROR(J19/F19-1,"") | K20: =IFERROR(K19/G19-1,"") | L20: =IFERROR(L19/H19-1,"") | M20: =IFERROR(M19/I19-1,"") | ... AC20: =IFERROR(AC19/Y19-1,"")
A21: % of revenue | B21: =IFERROR(B19/B3,"") | C21: =IFERROR(C19/C3,"") | D21: =IFERROR(D19/D3,"") | E21: =IFERROR(E19/E3,"") | F21: =IFERROR(F19/F3,"") | G21: =IFERROR(G19/G3,"") | H21: =IFERROR(H19/H3,"") | I21: =IFERROR(I19/I3,"") | ... AC21: =IFERROR(AC19/AC3,"")
A22: Services Business | B22: 824 | C22: 786 | D22: 806 | E22: 778 | F22: 736 | G22: 720 | H22: 752 | I22: 737 | J22: 812 | K22: 781 | L22: 802 | M22: 789 | N22: 833 | O22: 1361 | P22: 1392 | Q22: 1376 | R22: 1465 | S22: 1383 | T22: 1368 | U22: 1307 | V22: 1373 | W22: 1263 | X22: 1330 | Y22: 1291 | Z22: 1349 | AA22: 1349 | AC22: 1443
A23: % YoY | F23: =IFERROR(F22/B22-1,"") | G23: =IFERROR(G22/C22-1,"") | H23: =IFERROR(H22/D22-1,"") | I23: =IFERROR(I22/E22-1,"") | J23: =IFERROR(J22/F22-1,"") | K23: =IFERROR(K22/G22-1,"") | L23: =IFERROR(L22/H22-1,"") | M23: =IFERROR(M22/I22-1,"") | ... AC23: =IFERROR(AC22/Y22-1,"")
A24: % of revenue | B24: =IFERROR(B22/B3,"") | C24: =IFERROR(C22/C3,"") | D24: =IFERROR(D22/D3,"") | E24: =IFERROR(E22/E3,"") | F24: =IFERROR(F22/F3,"") | G24: =IFERROR(G22/G3,"") | H24: =IFERROR(H22/H3,"") | I24: =IFERROR(I22/I3,"") | ... AC24: =IFERROR(AC22/AC3,"")
A25: Hardware Business | B25: 994 | C25: 815 | D25: 871 | E25: 857 | F25: 900 | G25: 814 | H25: 844 | I25: 820 | J25: 881 | K25: 763 | L25: 767 | M25: 798 | N25: 855 | O25: 763 | P25: 850 | Q25: 811 | R25: 850 | S25: 714 | T25: 756 | U25: 754 | V25: 842 | W25: 655 | X25: 728 | Y25: 703 | Z25: 850 | AA25: 670 | AC25: 714
A26: % YoY | F26: =IFERROR(F25/B25-1,"") | G26: =IFERROR(G25/C25-1,"") | H26: =IFERROR(H25/D25-1,"") | I26: =IFERROR(I25/E25-1,"") | J26: =IFERROR(J25/F25-1,"") | K26: =IFERROR(K25/G25-1,"") | L26: =IFERROR(L25/H25-1,"") | M26: =IFERROR(M25/I25-1,"") | ... AC26: =IFERROR(AC25/Y25-1,"")
A27: % of revenue | B27: =IFERROR(B25/B3,"") | C27: =IFERROR(C25/C3,"") | D27: =IFERROR(D25/D3,"") | E27: =IFERROR(E25/E3,"") | F27: =IFERROR(F25/F3,"") | G27: =IFERROR(G25/G3,"") | H27: =IFERROR(H25/H3,"") | I27: =IFERROR(I25/I3,"") | ... AC27: =IFERROR(AC25/AC3,"")
A28: REVENUE BY SEGMENT — GEOGRAPHY (% YoY, % of revenue)
A29: Americas | B29: 6186 | C29: 5150 | D29: 5304 | E29: 5363 | F29: 5746 | G29: 5068 | H29: 5259 | I29: 5424 | J29: 6077 | K29: 5321 | L29: 5736 | M29: 5849 | N29: 6773 | O29: 7192 | P29: 7786 | Q29: 7671 | R29: 8577 | S29: 7841 | T29: 8067 | U29: 8270 | V29: 8944 | W29: 8372 | X29: 8933 | Y29: 9000 | Z29: 10034 | AA29: 9662 | AC29: 11361
A30: % YoY | F30: =IFERROR(F29/B29-1,"") | G30: =IFERROR(G29/C29-1,"") | H30: =IFERROR(H29/D29-1,"") | I30: =IFERROR(I29/E29-1,"") | J30: =IFERROR(J29/F29-1,"") | K30: =IFERROR(K29/G29-1,"") | L30: =IFERROR(L29/H29-1,"") | M30: =IFERROR(M29/I29-1,"") | ... AC30: =IFERROR(AC29/Y29-1,"")
A31: % of revenue | B31: =IFERROR(B29/B3,"") | C31: =IFERROR(C29/C3,"") | D31: =IFERROR(D29/D3,"") | E31: =IFERROR(E29/E3,"") | F31: =IFERROR(F29/F3,"") | G31: =IFERROR(G29/G3,"") | H31: =IFERROR(H29/H3,"") | I31: =IFERROR(I29/I3,"") | ... AC31: =IFERROR(AC29/AC3,"")
A32: E M E A | B32: 3131 | C32: 2553 | D32: 2695 | E32: 2835 | F32: 2952 | G32: 2738 | H32: 2852 | I32: 2981 | J32: 3323 | K32: 2784 | L32: 2953 | M32: 3014 | N32: 3260 | O32: 2691 | P32: 2895 | Q32: 3067 | R32: 3456 | S32: 3005 | T32: 3170 | U32: 3316 | V32: 3539 | W32: 3228 | X32: 3381 | Y32: 3421 | Z32: 3995 | AA32: 3481 | AC32: 3964
A33: % YoY | F33: =IFERROR(F32/B32-1,"") | G33: =IFERROR(G32/C32-1,"") | H33: =IFERROR(H32/D32-1,"") | I33: =IFERROR(I32/E32-1,"") | J33: =IFERROR(J32/F32-1,"") | K33: =IFERROR(K32/G32-1,"") | L33: =IFERROR(L32/H32-1,"") | M33: =IFERROR(M32/I32-1,"") | ... AC33: =IFERROR(AC32/Y32-1,"")
A34: % of revenue | B34: =IFERROR(B32/B3,"") | C34: =IFERROR(C32/C3,"") | D34: =IFERROR(D32/D3,"") | E34: =IFERROR(E32/E3,"") | F34: =IFERROR(F32/F3,"") | G34: =IFERROR(G32/G3,"") | H34: =IFERROR(H32/H3,"") | I34: =IFERROR(I32/I3,"") | ... AC34: =IFERROR(AC32/AC3,"")
A35: Asia Pacific | B35: 1820 | C35: 1515 | D35: 1615 | E35: 1598 | F35: 1742 | G35: 1561 | H35: 1689 | I35: 1680 | J35: 1827 | K35: 1623 | L35: 1671 | M35: 1650 | N35: 1806 | O35: 1562 | P35: 1594 | Q35: 1660 | R35: 1803 | S35: 1607 | T35: 1704 | U35: 1694 | V35: 1804 | W35: 1707 | X35: 1745 | Y35: 1709 | Z35: 1874 | AA35: 1783 | AC35: 1865
A36: % YoY | F36: =IFERROR(F35/B35-1,"") | G36: =IFERROR(G35/C35-1,"") | H36: =IFERROR(H35/D35-1,"") | I36: =IFERROR(I35/E35-1,"") | J36: =IFERROR(J35/F35-1,"") | K36: =IFERROR(K35/G35-1,"") | L36: =IFERROR(L35/H35-1,"") | M36: =IFERROR(M35/I35-1,"") | ... AC36: =IFERROR(AC35/Y35-1,"")
A37: % of revenue | B37: =IFERROR(B35/B3,"") | C37: =IFERROR(C35/C3,"") | D37: =IFERROR(D35/D3,"") | E37: =IFERROR(E35/E3,"") | F37: =IFERROR(F35/F3,"") | G37: =IFERROR(G35/G3,"") | H37: =IFERROR(H35/H3,"") | I37: =IFERROR(I35/I3,"") | ... AC37: =IFERROR(AC35/AC3,"")
A38: BALANCE SHEET
A39: Cash & ST Investments | B39: 37827 | C39: 35704 | D39: 27444 | E39: 25858 | F39: 43057 | G39: 42279 | H39: 38593 | I39: 35864 | J39: 46554 | K39: 39310 | L39: 22838 | M39: 23389 | N39: 21902 | O39: 11220 | P39: 7350 | Q39: 8769 | R39: 10187 | S39: 12083 | T39: 8690 | U39: 9904 | V39: 10661 | W39: 10911 | X39: 11311 | Y39: 17823 | Z39: 11203 | AA39: 11005 | AB39: 19766 | AC39: 39132
A40: Total Current Assets | B40: 46386 | C40: 42384 | D40: 34540 | E40: 33442 | F40: 52140 | G40: 49939 | H40: 46251 | I40: 43744 | J40: 55567 | K40: 47117 | L40: 31078 | M40: 31675 | N40: 31633 | O40: 21004 | P40: 17561 | Q40: 18696 | R40: 21004 | S40: 22166 | T40: 19289 | U40: 21063 | V40: 22554 | W40: 23072 | X40: 23503 | Y40: 30116 | Z40: 24579 | AA40: 24634 | AB40: 34366 | AC40: 54874
...

Sheet Consensus
A1: Full consensus check — model vs Street (FMP estimates, $M)
A2: Fiscal year | B2: 2026 | C2: 2027 | D2: 2028 | E2: 2029 | F2: 2030
A3: EVERY AVAILABLE FMP CONSENSUS FIELD (consensus / model / % diff)
A4: Revenue — consensus | B4: 67268.941 | C4: 88802.066 | D4: 129909.12 | E4: 178502.99 | F4: 215587.91
A5: model | B5: =Model!G10 | C5: =Model!H10 | D5: =Model!I10 | E5: =Model!J10 | F5: =Model!K10
A6: vs consensus | B6: =IFERROR(B5/B4-1,"") | C6: =IFERROR(C5/C4-1,"") | D6: =IFERROR(D5/D4-1,"") | E6: =IFERROR(E5/E4-1,"") | F6: =IFERROR(F5/F4-1,"")
A8: EBITDA* — consensus | B8: 26493.369 | C8: 34974.029 | D8: 51163.734 | E8: 70302.065 | F8: 84907.686
A9: model | B9: =Model!G23+Model!G28 | C9: =Model!H23+Model!H28 | D9: =Model!I23+Model!I28 | E9: =Model!J23+Model!J28 | F9: =Model!K23+Model!K28
A10: vs consensus | B10: =IFERROR(B9/B8-1,"") | C10: =IFERROR(C9/C8-1,"") | D10: =IFERROR(D9/D8-1,"") | E10: =IFERROR(E9/E8-1,"") | F10: =IFERROR(F9/F8-1,"")
A12: EBIT* — consensus | B12: 19882.838 | C12: 26247.435 | D12: 38397.543 | E12: 52760.546 | F12: 63721.825
A13: model | B13: =Model!G23 | C13: =Model!H23 | D13: =Model!I23 | E13: =Model!J23 | F13: =Model!K23
A14: vs consensus | B14: =IFERROR(B13/B12-1,"") | C14: =IFERROR(C13/C12-1,"") | D14: =IFERROR(D13/D12-1,"") | E14: =IFERROR(E13/E12-1,"") | F14: =IFERROR(F13/F12-1,"")
A16: SG&A — consensus | B16: 13640.973 | C16: 18007.516 | D16: 26343.313 | E16: 36197.304 | F16: 43717.483
A17: model | B17: =Model!G18 | C17: =Model!H18 | D17: =Model!I18 | E17: =Model!J18 | F17: =Model!K18
A18: vs consensus | B18: =IFERROR(B17/B16-1,"") | C18: =IFERROR(C17/C16-1,"") | D18: =IFERROR(D17/D16-1,"") | E18: =IFERROR(E17/E16-1,"") | F18: =IFERROR(F17/F16-1,"")
A20: Net income (NOPAT) — consensus | B20: 20918.289 | C20: 22710.743 | D20: 27083.664 | E20: 43398.376 | F20: 55850.143
A21: model | B21: =Model!G27 | C21: =Model!H27 | D21: =Model!I27 | E21: =Model!J27 | F21: =Model!K27
A22: vs consensus | B22: =IFERROR(B21/B20-1,"") | C22: =IFERROR(C21/C20-1,"") | D22: =IFERROR(D21/D20-1,"") | E22: =IFERROR(E21/E20-1,"") | F22: =IFERROR(F21/F20-1,"")
A24: EPS — consensus | B24: 7.48438 | C24: 7.99423 | D24: 10.76376 | E24: 15.14249 | F24: 19.48714
A25: model | B25: =Model!G27/Financials!AC17 | C25: =Model!H27/Financials!AC17 | D25: =Model!I27/Financials!AC17 | E25: =Model!J27/Financials!AC17 | F25: =Model!K27/Financials!AC17
A26: vs consensus | B26: =IFERROR(B25/B24-1,"") | C26: =IFERROR(C25/C24-1,"") | D26: =IFERROR(D25/D24-1,"") | E26: =IFERROR(E25/E24-1,"") | F26: =IFERROR(F25/F24-1,"")
A28: Defaults anchored to consensus revenue + net income (≈0% diff). Other rows show where the model sits vs Street.
A29: *FMP's EBITDA/EBIT estimates look unreliable for AMZN (it reports NI > EBIT) — don't over-read those two.

Sheet Valuation
A1: Oracle Corporation — DCF Valuation
A2: Current price | B2: =Dashboard!$B$48
A3: WACC | B3: =WACC!B14
A4: Terminal growth (g) | B4: =Dashboard!$B$46
A5: Tax rate | B5: =Dashboard!$B$31
A6: Terminal method | B6: =Dashboard!$B$43
A7: Exit basis | B7: =Dashboard!$B$44
A8: Exit multiple | B8: =Dashboard!$B$45
A11: Forecast year | C11: 2026 | D11: 2027 | E11: 2028 | F11: 2029 | G11: 2030 | H11: 2031 | I11: 2032 | J11: 2033 | K11: 2034 | L11: 2035
A12: FCFF ($M) | C12: =Model!G35 | D12: =Model!H35 | E12: =Model!I35 | F12: =Model!J35 | G12: =Model!K35 | H12: =Model!L35 | I12: =Model!M35 | J12: =Model!N35 | ... L12: =Model!P35
A13: PV factor | C13: =1/(1+$B$3)^1 | D13: =1/(1+$B$3)^2 | E13: =1/(1+$B$3)^3 | F13: =1/(1+$B$3)^4 | G13: =1/(1+$B$3)^5 | H13: =1/(1+$B$3)^6 | I13: =1/(1+$B$3)^7 | J13: =1/(1+$B$3)^8 | K13: =1/(1+$B$3)^9 | L13: =1/(1+$B$3)^10
A14: PV of FCFF ($M) | C14: =C12*C13 | D14: =D12*D13 | E14: =E12*E13 | F14: =F12*F13 | G14: =G12*G13 | H14: =H12*H13 | I14: =I12*I13 | J14: =J12*J13 | ... L14: =L12*L13
A16: Sum PV of FCFF | B16: =SUM(C14:L14)
A18: TERMINAL VALUE (exit multiple = default; perpetuity = cross-check)
A19: Terminal-year FCFF | B19: =L12
A20: Terminal revenue | B20: =Model!P10
A21: Terminal EBIT | B21: =Model!P23
A22: Terminal EBITDA | B22: =Model!P23+Model!P28
A23: Terminal metric (per exit basis) | B23: =IF($B$7="EV/EBITDA",B22,IF($B$7="EV/Sales",B20,IF($B$7="EV/EBIT",B21,B19)))
A24: TV (exit) = metric x multiple | B24: =B23*$B$8
A25: PV of TV — exit multiple | B25: =B24/(1+$B$3)^10
A26: TV (perpetuity) = FCFF(1+g)/(WACC-g) | B26: =B19*(1+$B$4)/($B$3-$B$4)
A27: PV of TV — perpetuity | B27: =B26/(1+$B$3)^10
A28: PV of TV — SELECTED | B28: =IF($B$6="Perpetuity",B27,B25)
A30: EQUITY BRIDGE -> VALUE / SHARE
A31: Operating value (enterprise value) | B31: =B16+B28
A32: + Cash & ST investments | B32: =Financials!AC39
A33: - Long-term debt | B33: =-Financials!AC44
A34: Equity value | B34: =B31+B32+B33
A35: Diluted shares (M) | B35: =Financials!AC17
A36: VALUE / SHARE | B36: =B34/B35*1.0
A38: CROSS-CHECKS & RETURN
A39: Terminal weight (% of EV) | B39: =B28/B31
A40: Implied perpetuity g (from exit multiple) | B40: =(B24*$B$3-B19)/(B24+B19)
A41: Implied exit EV/EBITDA (from perpetuity) | B41: =B26/B22
A42: Upside / (downside) to fair value | B42: =B36/$B$2-1
A44: Owner cashflow / share | B44: =-$B$2 | C44: =C12/B35 | D44: =D12/B35 | E44: =E12/B35 | F44: =F12/B35 | G44: =G12/B35 | H44: =H12/B35 | I44: =I12/B35 | J44: =J12/B35 | K44: =K12/B35 | L44: =L12/B35+B36
A45: IRR (buy at price, hold 10y) | B45: =IRR(B44:L44)

Sheet Monte Carlo
A1: Monte Carlo simulation (live) | H1: SIMULATION ENGINE — leave as-is | K1: cagr | L1: term margin | M1: wacc | N1: exit | O1: value/share
A2: 1,000 trials, recomputed in-sheet on every edit. Edit the yellow driver distributions to re-roll. Engine grid is to the right (cols H+). | H2: R0 (base revenue) | I2: =Model!F10 | K2: =MAX(-0.05,NORMINV(RAND(),$C$6,$D$6)) | L2: =MAX(0.02,NORMINV(RAND(),$C$7,$D$7)) | M2: =MIN(0.16,MAX(0.05,NORMINV(RAND(),$C$8,$D$8))) | N2: =MIN(24,MAX(5,NORMINV(RAND(),$C$9,$D$9))) | O2: =$I$8*(SUMPRODUCT(($I$2*(1+K2)^{1;2;3;4;5;6;7;8;9;10})*(($I$3+(L2-$I$3)*{1;2;3;4;5;6;7;8;9;10}/10)*(1-$I$7)+$I$4-$I$4*($I$5+(1.05-$I$5)*{1;2;3;4;5;6;7;8;9;10}/10)-(K2/(1+K2))*$I$6)/(1+M2)^{1;2;3;4;5;6;7;8;9;10})+$I$2*(1+K2)^10*(L2+$I$4)*N2/(1+M2)^10+$I$9-$I$10)/$I$11
H3: m0 (base op margin) | I3: =Model!F24 | K3: =MAX(-0.05,NORMINV(RAND(),$C$6,$D$6)) | L3: =MAX(0.02,NORMINV(RAND(),$C$7,$D$7)) | M3: =MIN(0.16,MAX(0.05,NORMINV(RAND(),$C$8,$D$8))) | N3: =MIN(24,MAX(5,NORMINV(RAND(),$C$9,$D$9))) | O3: =$I$8*(SUMPRODUCT(($I$2*(1+K3)^{1;2;3;4;5;6;7;8;9;10})*(($I$3+(L3-$I$3)*{1;2;3;4;5;6;7;8;9;10}/10)*(1-$I$7)+$I$4-$I$4*($I$5+(1.05-$I$5)*{1;2;3;4;5;6;7;8;9;10}/10)-(K3/(1+K3))*$I$6)/(1+M3)^{1;2;3;4;5;6;7;8;9;10})+$I$2*(1+K3)^10*(L3+$I$4)*N3/(1+M3)^10+$I$9-$I$10)/$I$11
A4: DRIVER DISTRIBUTIONS (yellow = edit; Opus-set defaults) | H4: da (D&A / revenue) | I4: 0.10756285 | K4: =MAX(-0.05,NORMINV(RAND(),$C$6,$D$6)) | L4: =MAX(0.02,NORMINV(RAND(),$C$7,$D$7)) | M4: =MIN(0.16,MAX(0.05,NORMINV(RAND(),$C$8,$D$8))) | N4: =MIN(24,MAX(5,NORMINV(RAND(),$C$9,$D$9))) | O4: =$I$8*(SUMPRODUCT(($I$2*(1+K4)^{1;2;3;4;5;6;7;8;9;10})*(($I$3+(L4-$I$3)*{1;2;3;4;5;6;7;8;9;10}/10)*(1-$I$7)+$I$4-$I$4*($I$5+(1.05-$I$5)*{1;2;3;4;5;6;7;8;9;10}/10)-(K4/(1+K4))*$I$6)/(1+M4)^{1;2;3;4;5;6;7;8;9;10})+$I$2*(1+K4)^10*(L4+$I$4)*N4/(1+M4)^10+$I$9-$I$10)/$I$11
A5: Driver | B5: Dist | C5: Mean | D5: Std dev | H5: cda0 (2026 capex/D&A) | I5: 2.7890671 | K5: =MAX(-0.05,NORMINV(RAND(),$C$6,$D$6)) | L5: =MAX(0.02,NORMINV(RAND(),$C$7,$D$7)) | M5: =MIN(0.16,MAX(0.05,NORMINV(RAND(),$C$8,$D$8))) | N5: =MIN(24,MAX(5,NORMINV(RAND(),$C$9,$D$9))) | O5: =$I$8*(SUMPRODUCT(($I$2*(1+K5)^{1;2;3;4;5;6;7;8;9;10})*(($I$3+(L5-$I$3)*{1;2;3;4;5;6;7;8;9;10}/10)*(1-$I$7)+$I$4-$I$4*($I$5+(1.05-$I$5)*{1;2;3;4;5;6;7;8;9;10}/10)-(K5/(1+K5))*$I$6)/(1+M5)^{1;2;3;4;5;6;7;8;9;10})+$I$2*(1+K5)^10*(L5+$I$4)*N5/(1+M5)^10+$I$9-$I$10)/$I$11
A6: Revenue 10y CAGR | B6: Normal | C6: =(Model!P10/Model!F10)^(1/10)-1 | D6: 0.025251162 | H6: nwc (% incr revenue) | I6: 0.005 | K6: =MAX(-0.05,NORMINV(RAND(),$C$6,$D$6)) | L6: =MAX(0.02,NORMINV(RAND(),$C$7,$D$7)) | M6: =MIN(0.16,MAX(0.05,NORMINV(RAND(),$C$8,$D$8))) | N6: =MIN(24,MAX(5,NORMINV(RAND(),$C$9,$D$9))) | O6: =$I$8*(SUMPRODUCT(($I$2*(1+K6)^{1;2;3;4;5;6;7;8;9;10})*(($I$3+(L6-$I$3)*{1;2;3;4;5;6;7;8;9;10}/10)*(1-$I$7)+$I$4-$I$4*($I$5+(1.05-$I$5)*{1;2;3;4;5;6;7;8;9;10}/10)-(K6/(1+K6))*$I$6)/(1+M6)^{1;2;3;4;5;6;7;8;9;10})+$I$2*(1+K6)^10*(L6+$I$4)*N6/(1+M6)^10+$I$9-$I$10)/$I$11
A7: Terminal operating margin | B7: Normal | C7: =Dashboard!$B$30 | D7: 0.03 | H7: tax | I7: =Valuation!$B$5 | K7: =MAX(-0.05,NORMINV(RAND(),$C$6,$D$6)) | L7: =MAX(0.02,NORMINV(RAND(),$C$7,$D$7)) | M7: =MIN(0.16,MAX(0.05,NORMINV(RAND(),$C$8,$D$8))) | N7: =MIN(24,MAX(5,NORMINV(RAND(),$C$9,$D$9))) | O7: =$I$8*(SUMPRODUCT(($I$2*(1+K7)^{1;2;3;4;5;6;7;8;9;10})*(($I$3+(L7-$I$3)*{1;2;3;4;5;6;7;8;9;10}/10)*(1-$I$7)+$I$4-$I$4*($I$5+(1.05-$I$5)*{1;2;3;4;5;6;7;8;9;10}/10)-(K7/(1+K7))*$I$6)/(1+M7)^{1;2;3;4;5;6;7;8;9;10})+$I$2*(1+K7)^10*(L7+$I$4)*N7/(1+M7)^10+$I$9-$I$10)/$I$11
A8: WACC | B8: Normal | C8: =WACC!B14 | D8: 0.005 | H8: k (calibration) | I8: 1.0326525 | K8: =MAX(-0.05,NORMINV(RAND(),$C$6,$D$6)) | L8: =MAX(0.02,NORMINV(RAND(),$C$7,$D$7)) | M8: =MIN(0.16,MAX(0.05,NORMINV(RAND(),$C$8,$D$8))) | N8: =MIN(24,MAX(5,NORMINV(RAND(),$C$9,$D$9))) | O8: =$I$8*(SUMPRODUCT(($I$2*(1+K8)^{1;2;3;4;5;6;7;8;9;10})*(($I$3+(L8-$I$3)*{1;2;3;4;5;6;7;8;9;10}/10)*(1-$I$7)+$I$4-$I$4*($I$5+(1.05-$I$5)*{1;2;3;4;5;6;7;8;9;10}/10)-(K8/(1+K8))*$I$6)/(1+M8)^{1;2;3;4;5;6;7;8;9;10})+$I$2*(1+K8)^10*(L8+$I$4)*N8/(1+M8)^10+$I$9-$I$10)/$I$11
A9: Exit EV/EBITDA multiple | B9: Normal | C9: =Dashboard!$B$45 | D9: 1.5 | H9: cash | I9: =Financials!AC39 | K9: =MAX(-0.05,NORMINV(RAND(),$C$6,$D$6)) | L9: =MAX(0.02,NORMINV(RAND(),$C$7,$D$7)) | M9: =MIN(0.16,MAX(0.05,NORMINV(RAND(),$C$8,$D$8))) | N9: =MIN(24,MAX(5,NORMINV(RAND(),$C$9,$D$9))) | O9: =$I$8*(SUMPRODUCT(($I$2*(1+K9)^{1;2;3;4;5;6;7;8;9;10})*(($I$3+(L9-$I$3)*{1;2;3;4;5;6;7;8;9;10}/10)*(1-$I$7)+$I$4-$I$4*($I$5+(1.05-$I$5)*{1;2;3;4;5;6;7;8;9;10}/10)-(K9/(1+K9))*$I$6)/(1+M9)^{1;2;3;4;5;6;7;8;9;10})+$I$2*(1+K9)^10*(L9+$I$4)*N9/(1+M9)^10+$I$9-$I$10)/$I$11
H10: debt | I10: =Financials!AC44 | K10: =MAX(-0.05,NORMINV(RAND(),$C$6,$D$6)) | L10: =MAX(0.02,NORMINV(RAND(),$C$7,$D$7)) | M10: =MIN(0.16,MAX(0.05,NORMINV(RAND(),$C$8,$D$8))) | N10: =MIN(24,MAX(5,NORMINV(RAND(),$C$9,$D$9))) | O10: =$I$8*(SUMPRODUCT(($I$2*(1+K10)^{1;2;3;4;5;6;7;8;9;10})*(($I$3+(L10-$I$3)*{1;2;3;4;5;6;7;8;9;10}/10)*(1-$I$7)+$I$4-$I$4*($I$5+(1.05-$I$5)*{1;2;3;4;5;6;7;8;9;10}/10)-(K10/(1+K10))*$I$6)/(1+M10)^{1;2;3;4;5;6;7;8;9;10})+$I$2*(1+K10)^10*(L10+$I$4)*N10/(1+M10)^10+$I$9-$I$10)/$I$11
A11: SIMULATION OUTPUT — value / share (live) | H11: shares | I11: =Financials!AC17 | K11: =MAX(-0.05,NORMINV(RAND(),$C$6,$D$6)) | L11: =MAX(0.02,NORMINV(RAND(),$C$7,$D$7)) | M11: =MIN(0.16,MAX(0.05,NORMINV(RAND(),$C$8,$D$8))) | N11: =MIN(24,MAX(5,NORMINV(RAND(),$C$9,$D$9))) | O11: =$I$8*(SUMPRODUCT(($I$2*(1+K11)^{1;2;3;4;5;6;7;8;9;10})*(($I$3+(L11-$I$3)*{1;2;3;4;5;6;7;8;9;10}/10)*(1-$I$7)+$I$4-$I$4*($I$5+(1.05-$I$5)*{1;2;3;4;5;6;7;8;9;10}/10)-(K11/(1+K11))*$I$6)/(1+M11)^{1;2;3;4;5;6;7;8;9;10})+$I$2*(1+K11)^10*(L11+$I$4)*N11/(1+M11)^10+$I$9-$I$10)/$I$11
A12: Mean | B12: =AVERAGE($O$2:$O$1001) | K12: =MAX(-0.05,NORMINV(RAND(),$C$6,$D$6)) | L12: =MAX(0.02,NORMINV(RAND(),$C$7,$D$7)) | M12: =MIN(0.16,MAX(0.05,NORMINV(RAND(),$C$8,$D$8))) | N12: =MIN(24,MAX(5,NORMINV(RAND(),$C$9,$D$9))) | O12: =$I$8*(SUMPRODUCT(($I$2*(1+K12)^{1;2;3;4;5;6;7;8;9;10})*(($I$3+(L12-$I$3)*{1;2;3;4;5;6;7;8;9;10}/10)*(1-$I$7)+$I$4-$I$4*($I$5+(1.05-$I$5)*{1;2;3;4;5;6;7;8;9;10}/10)-(K12/(1+K12))*$I$6)/(1+M12)^{1;2;3;4;5;6;7;8;9;10})+$I$2*(1+K12)^10*(L12+$I$4)*N12/(1+M12)^10+$I$9-$I$10)/$I$11
A13: Median (P50) | B13: =MEDIAN($O$2:$O$1001) | K13: =MAX(-0.05,NORMINV(RAND(),$C$6,$D$6)) | L13: =MAX(0.02,NORMINV(RAND(),$C$7,$D$7)) | M13: =MIN(0.16,MAX(0.05,NORMINV(RAND(),$C$8,$D$8))) | N13: =MIN(24,MAX(5,NORMINV(RAND(),$C$9,$D$9))) | O13: =$I$8*(SUMPRODUCT(($I$2*(1+K13)^{1;2;3;4;5;6;7;8;9;10})*(($I$3+(L13-$I$3)*{1;2;3;4;5;6;7;8;9;10}/10)*(1-$I$7)+$I$4-$I$4*($I$5+(1.05-$I$5)*{1;2;3;4;5;6;7;8;9;10}/10)-(K13/(1+K13))*$I$6)/(1+M13)^{1;2;3;4;5;6;7;8;9;10})+$I$2*(1+K13)^10*(L13+$I$4)*N13/(1+M13)^10+$I$9-$I$10)/$I$11
A14: Std dev | B14: =STDEV($O$2:$O$1001) | K14: =MAX(-0.05,NORMINV(RAND(),$C$6,$D$6)) | L14: =MAX(0.02,NORMINV(RAND(),$C$7,$D$7)) | M14: =MIN(0.16,MAX(0.05,NORMINV(RAND(),$C$8,$D$8))) | N14: =MIN(24,MAX(5,NORMINV(RAND(),$C$9,$D$9))) | O14: =$I$8*(SUMPRODUCT(($I$2*(1+K14)^{1;2;3;4;5;6;7;8;9;10})*(($I$3+(L14-$I$3)*{1;2;3;4;5;6;7;8;9;10}/10)*(1-$I$7)+$I$4-$I$4*($I$5+(1.05-$I$5)*{1;2;3;4;5;6;7;8;9;10}/10)-(K14/(1+K14))*$I$6)/(1+M14)^{1;2;3;4;5;6;7;8;9;10})+$I$2*(1+K14)^10*(L14+$I$4)*N14/(1+M14)^10+$I$9-$I$10)/$I$11
A15: Min | B15: =MIN($O$2:$O$1001) | K15: =MAX(-0.05,NORMINV(RAND(),$C$6,$D$6)) | L15: =MAX(0.02,NORMINV(RAND(),$C$7,$D$7)) | M15: =MIN(0.16,MAX(0.05,NORMINV(RAND(),$C$8,$D$8))) | N15: =MIN(24,MAX(5,NORMINV(RAND(),$C$9,$D$9))) | O15: =$I$8*(SUMPRODUCT(($I$2*(1+K15)^{1;2;3;4;5;6;7;8;9;10})*(($I$3+(L15-$I$3)*{1;2;3;4;5;6;7;8;9;10}/10)*(1-$I$7)+$I$4-$I$4*($I$5+(1.05-$I$5)*{1;2;3;4;5;6;7;8;9;10}/10)-(K15/(1+K15))*$I$6)/(1+M15)^{1;2;3;4;5;6;7;8;9;10})+$I$2*(1+K15)^10*(L15+$I$4)*N15/(1+M15)^10+$I$9-$I$10)/$I$11
A16: Max | B16: =MAX($O$2:$O$1001) | K16: =MAX(-0.05,NORMINV(RAND(),$C$6,$D$6)) | L16: =MAX(0.02,NORMINV(RAND(),$C$7,$D$7)) | M16: =MIN(0.16,MAX(0.05,NORMINV(RAND(),$C$8,$D$8))) | N16: =MIN(24,MAX(5,NORMINV(RAND(),$C$9,$D$9))) | O16: =$I$8*(SUMPRODUCT(($I$2*(1+K16)^{1;2;3;4;5;6;7;8;9;10})*(($I$3+(L16-$I$3)*{1;2;3;4;5;6;7;8;9;10}/10)*(1-$I$7)+$I$4-$I$4*($I$5+(1.05-$I$5)*{1;2;3;4;5;6;7;8;9;10}/10)-(K16/(1+K16))*$I$6)/(1+M16)^{1;2;3;4;5;6;7;8;9;10})+$I$2*(1+K16)^10*(L16+$I$4)*N16/(1+M16)^10+$I$9-$I$10)/$I$11
A17: Current price | B17: =Valuation!$B$2 | K17: =MAX(-0.05,NORMINV(RAND(),$C$6,$D$6)) | L17: =MAX(0.02,NORMINV(RAND(),$C$7,$D$7)) | M17: =MIN(0.16,MAX(0.05,NORMINV(RAND(),$C$8,$D$8))) | N17: =MIN(24,MAX(5,NORMINV(RAND(),$C$9,$D$9))) | O17: =$I$8*(SUMPRODUCT(($I$2*(1+K17)^{1;2;3;4;5;6;7;8;9;10})*(($I$3+(L17-$I$3)*{1;2;3;4;5;6;7;8;9;10}/10)*(1-$I$7)+$I$4-$I$4*($I$5+(1.05-$I$5)*{1;2;3;4;5;6;7;8;9;10}/10)-(K17/(1+K17))*$I$6)/(1+M17)^{1;2;3;4;5;6;7;8;9;10})+$I$2*(1+K17)^10*(L17+$I$4)*N17/(1+M17)^10+$I$9-$I$10)/$I$11
A18: Base case (full model) | B18: =Valuation!B36 | K18: =MAX(-0.05,NORMINV(RAND(),$C$6,$D$6)) | L18: =MAX(0.02,NORMINV(RAND(),$C$7,$D$7)) | M18: =MIN(0.16,MAX(0.05,NORMINV(RAND(),$C$8,$D$8))) | N18: =MIN(24,MAX(5,NORMINV(RAND(),$C$9,$D$9))) | O18: =$I$8*(SUMPRODUCT(($I$2*(1+K18)^{1;2;3;4;5;6;7;8;9;10})*(($I$3+(L18-$I$3)*{1;2;3;4;5;6;7;8;9;10}/10)*(1-$I$7)+$I$4-$I$4*($I$5+(1.05-$I$5)*{1;2;3;4;5;6;7;8;9;10}/10)-(K18/(1+K18))*$I$6)/(1+M18)^{1;2;3;4;5;6;7;8;9;10})+$I$2*(1+K18)^10*(L18+$I$4)*N18/(1+M18)^10+$I$9-$I$10)/$I$11
K19: =MAX(-0.05,NORMINV(RAND(),$C$6,$D$6)) | L19: =MAX(0.02,NORMINV(RAND(),$C$7,$D$7)) | M19: =MIN(0.16,MAX(0.05,NORMINV(RAND(),$C$8,$D$8))) | N19: =MIN(24,MAX(5,NORMINV(RAND(),$C$9,$D$9))) | O19: =$I$8*(SUMPRODUCT(($I$2*(1+K19)^{1;2;3;4;5;6;7;8;9;10})*(($I$3+(L19-$I$3)*{1;2;3;4;5;6;7;8;9;10}/10)*(1-$I$7)+$I$4-$I$4*($I$5+(1.05-$I$5)*{1;2;3;4;5;6;7;8;9;10}/10)-(K19/(1+K19))*$I$6)/(1+M19)^{1;2;3;4;5;6;7;8;9;10})+$I$2*(1+K19)^10*(L19+$I$4)*N19/(1+M19)^10+$I$9-$I$10)/$I$11
A20: P(undervalued at current price) | B20: =COUNTIF($O$2:$O$1001,">"&Valuation!$B$2)/1000 | K20: =MAX(-0.05,NORMINV(RAND(),$C$6,$D$6)) | L20: =MAX(0.02,NORMINV(RAND(),$C$7,$D$7)) | M20: =MIN(0.16,MAX(0.05,NORMINV(RAND(),$C$8,$D$8))) | N20: =MIN(24,MAX(5,NORMINV(RAND(),$C$9,$D$9))) | O20: =$I$8*(SUMPRODUCT(($I$2*(1+K20)^{1;2;3;4;5;6;7;8;9;10})*(($I$3+(L20-$I$3)*{1;2;3;4;5;6;7;8;9;10}/10)*(1-$I$7)+$I$4-$I$4*($I$5+(1.05-$I$5)*{1;2;3;4;5;6;7;8;9;10}/10)-(K20/(1+K20))*$I$6)/(1+M20)^{1;2;3;4;5;6;7;8;9;10})+$I$2*(1+K20)^10*(L20+$I$4)*N20/(1+M20)^10+$I$9-$I$10)/$I$11
A21: P(>20% upside) | B21: =COUNTIF($O$2:$O$1001,">"&Valuation!$B$2*1.2)/1000 | K21: =MAX(-0.05,NORMINV(RAND(),$C$6,$D$6)) | L21: =MAX(0.02,NORMINV(RAND(),$C$7,$D$7)) | M21: =MIN(0.16,MAX(0.05,NORMINV(RAND(),$C$8,$D$8))) | N21: =MIN(24,MAX(5,NORMINV(RAND(),$C$9,$D$9))) | O21: =$I$8*(SUMPRODUCT(($I$2*(1+K21)^{1;2;3;4;5;6;7;8;9;10})*(($I$3+(L21-$I$3)*{1;2;3;4;5;6;7;8;9;10}/10)*(1-$I$7)+$I$4-$I$4*($I$5+(1.05-$I$5)*{1;2;3;4;5;6;7;8;9;10}/10)-(K21/(1+K21))*$I$6)/(1+M21)^{1;2;3;4;5;6;7;8;9;10})+$I$2*(1+K21)^10*(L21+$I$4)*N21/(1+M21)^10+$I$9-$I$10)/$I$11
K22: =MAX(-0.05,NORMINV(RAND(),$C$6,$D$6)) | L22: =MAX(0.02,NORMINV(RAND(),$C$7,$D$7)) | M22: =MIN(0.16,MAX(0.05,NORMINV(RAND(),$C$8,$D$8))) | N22: =MIN(24,MAX(5,NORMINV(RAND(),$C$9,$D$9))) | O22: =$I$8*(SUMPRODUCT(($I$2*(1+K22)^{1;2;3;4;5;6;7;8;9;10})*(($I$3+(L22-$I$3)*{1;2;3;4;5;6;7;8;9;10}/10)*(1-$I$7)+$I$4-$I$4*($I$5+(1.05-$I$5)*{1;2;3;4;5;6;7;8;9;10}/10)-(K22/(1+K22))*$I$6)/(1+M22)^{1;2;3;4;5;6;7;8;9;10})+$I$2*(1+K22)^10*(L22+$I$4)*N22/(1+M22)^10+$I$9-$I$10)/$I$11
A23: PERCENTILES (live) | K23: =MAX(-0.05,NORMINV(RAND(),$C$6,$D$6)) | L23: =MAX(0.02,NORMINV(RAND(),$C$7,$D$7)) | M23: =MIN(0.16,MAX(0.05,NORMINV(RAND(),$C$8,$D$8))) | N23: =MIN(24,MAX(5,NORMINV(RAND(),$C$9,$D$9))) | O23: =$I$8*(SUMPRODUCT(($I$2*(1+K23)^{1;2;3;4;5;6;7;8;9;10})*(($I$3+(L23-$I$3)*{1;2;3;4;5;6;7;8;9;10}/10)*(1-$I$7)+$I$4-$I$4*($I$5+(1.05-$I$5)*{1;2;3;4;5;6;7;8;9;10}/10)-(K23/(1+K23))*$I$6)/(1+M23)^{1;2;3;4;5;6;7;8;9;10})+$I$2*(1+K23)^10*(L23+$I$4)*N23/(1+M23)^10+$I$9-$I$10)/$I$11
A24: P5 | B24: =PERCENTILE($O$2:$O$1001,0.05) | K24: =MAX(-0.05,NORMINV(RAND(),$C$6,$D$6)) | L24: =MAX(0.02,NORMINV(RAND(),$C$7,$D$7)) | M24: =MIN(0.16,MAX(0.05,NORMINV(RAND(),$C$8,$D$8))) | N24: =MIN(24,MAX(5,NORMINV(RAND(),$C$9,$D$9))) | O24: =$I$8*(SUMPRODUCT(($I$2*(1+K24)^{1;2;3;4;5;6;7;8;9;10})*(($I$3+(L24-$I$3)*{1;2;3;4;5;6;7;8;9;10}/10)*(1-$I$7)+$I$4-$I$4*($I$5+(1.05-$I$5)*{1;2;3;4;5;6;7;8;9;10}/10)-(K24/(1+K24))*$I$6)/(1+M24)^{1;2;3;4;5;6;7;8;9;10})+$I$2*(1+K24)^10*(L24+$I$4)*N24/(1+M24)^10+$I$9-$I$10)/$I$11
A25: P10 | B25: =PERCENTILE($O$2:$O$1001,0.1) | K25: =MAX(-0.05,NORMINV(RAND(),$C$6,$D$6)) | L25: =MAX(0.02,NORMINV(RAND(),$C$7,$D$7)) | M25: =MIN(0.16,MAX(0.05,NORMINV(RAND(),$C$8,$D$8))) | N25: =MIN(24,MAX(5,NORMINV(RAND(),$C$9,$D$9))) | O25: =$I$8*(SUMPRODUCT(($I$2*(1+K25)^{1;2;3;4;5;6;7;8;9;10})*(($I$3+(L25-$I$3)*{1;2;3;4;5;6;7;8;9;10}/10)*(1-$I$7)+$I$4-$I$4*($I$5+(1.05-$I$5)*{1;2;3;4;5;6;7;8;9;10}/10)-(K25/(1+K25))*$I$6)/(1+M25)^{1;2;3;4;5;6;7;8;9;10})+$I$2*(1+K25)^10*(L25+$I$4)*N25/(1+M25)^10+$I$9-$I$10)/$I$11
A26: P25 | B26: =PERCENTILE($O$2:$O$1001,0.25) | K26: =MAX(-0.05,NORMINV(RAND(),$C$6,$D$6)) | L26: =MAX(0.02,NORMINV(RAND(),$C$7,$D$7)) | M26: =MIN(0.16,MAX(0.05,NORMINV(RAND(),$C$8,$D$8))) | N26: =MIN(24,MAX(5,NORMINV(RAND(),$C$9,$D$9))) | O26: =$I$8*(SUMPRODUCT(($I$2*(1+K26)^{1;2;3;4;5;6;7;8;9;10})*(($I$3+(L26-$I$3)*{1;2;3;4;5;6;7;8;9;10}/10)*(1-$I$7)+$I$4-$I$4*($I$5+(1.05-$I$5)*{1;2;3;4;5;6;7;8;9;10}/10)-(K26/(1+K26))*$I$6)/(1+M26)^{1;2;3;4;5;6;7;8;9;10})+$I$2*(1+K26)^10*(L26+$I$4)*N26/(1+M26)^10+$I$9-$I$10)/$I$11
A27: P50 | B27: =PERCENTILE($O$2:$O$1001,0.5) | K27: =MAX(-0.05,NORMINV(RAND(),$C$6,$D$6)) | L27: =MAX(0.02,NORMINV(RAND(),$C$7,$D$7)) | M27: =MIN(0.16,MAX(0.05,NORMINV(RAND(),$C$8,$D$8))) | N27: =MIN(24,MAX(5,NORMINV(RAND(),$C$9,$D$9))) | O27: =$I$8*(SUMPRODUCT(($I$2*(1+K27)^{1;2;3;4;5;6;7;8;9;10})*(($I$3+(L27-$I$3)*{1;2;3;4;5;6;7;8;9;10}/10)*(1-$I$7)+$I$4-$I$4*($I$5+(1.05-$I$5)*{1;2;3;4;5;6;7;8;9;10}/10)-(K27/(1+K27))*$I$6)/(1+M27)^{1;2;3;4;5;6;7;8;9;10})+$I$2*(1+K27)^10*(L27+$I$4)*N27/(1+M27)^10+$I$9-$I$10)/$I$11
A28: P75 | B28: =PERCENTILE($O$2:$O$1001,0.75) | K28: =MAX(-0.05,NORMINV(RAND(),$C$6,$D$6)) | L28: =MAX(0.02,NORMINV(RAND(),$C$7,$D$7)) | M28: =MIN(0.16,MAX(0.05,NORMINV(RAND(),$C$8,$D$8))) | N28: =MIN(24,MAX(5,NORMINV(RAND(),$C$9,$D$9))) | O28: =$I$8*(SUMPRODUCT(($I$2*(1+K28)^{1;2;3;4;5;6;7;8;9;10})*(($I$3+(L28-$I$3)*{1;2;3;4;5;6;7;8;9;10}/10)*(1-$I$7)+$I$4-$I$4*($I$5+(1.05-$I$5)*{1;2;3;4;5;6;7;8;9;10}/10)-(K28/(1+K28))*$I$6)/(1+M28)^{1;2;3;4;5;6;7;8;9;10})+$I$2*(1+K28)^10*(L28+$I$4)*N28/(1+M28)^10+$I$9-$I$10)/$I$11
A29: P90 | B29: =PERCENTILE($O$2:$O$1001,0.9) | K29: =MAX(-0.05,NORMINV(RAND(),$C$6,$D$6)) | L29: =MAX(0.02,NORMINV(RAND(),$C$7,$D$7)) | M29: =MIN(0.16,MAX(0.05,NORMINV(RAND(),$C$8,$D$8))) | N29: =MIN(24,MAX(5,NORMINV(RAND(),$C$9,$D$9))) | O29: =$I$8*(SUMPRODUCT(($I$2*(1+K29)^{1;2;3;4;5;6;7;8;9;10})*(($I$3+(L29-$I$3)*{1;2;3;4;5;6;7;8;9;10}/10)*(1-$I$7)+$I$4-$I$4*($I$5+(1.05-$I$5)*{1;2;3;4;5;6;7;8;9;10}/10)-(K29/(1+K29))*$I$6)/(1+M29)^{1;2;3;4;5;6;7;8;9;10})+$I$2*(1+K29)^10*(L29+$I$4)*N29/(1+M29)^10+$I$9-$I$10)/$I$11
A30: P95 | B30: =PERCENTILE($O$2:$O$1001,0.95) | K30: =MAX(-0.05,NORMINV(RAND(),$C$6,$D$6)) | L30: =MAX(0.02,NORMINV(RAND(),$C$7,$D$7)) | M30: =MIN(0.16,MAX(0.05,NORMINV(RAND(),$C$8,$D$8))) | N30: =MIN(24,MAX(5,NORMINV(RAND(),$C$9,$D$9))) | O30: =$I$8*(SUMPRODUCT(($I$2*(1+K30)^{1;2;3;4;5;6;7;8;9;10})*(($I$3+(L30-$I$3)*{1;2;3;4;5;6;7;8;9;10}/10)*(1-$I$7)+$I$4-$I$4*($I$5+(1.05-$I$5)*{1;2;3;4;5;6;7;8;9;10}/10)-(K30/(1+K30))*$I$6)/(1+M30)^{1;2;3;4;5;6;7;8;9;10})+$I$2*(1+K30)^10*(L30+$I$4)*N30/(1+M30)^10+$I$9-$I$10)/$I$11
K31: =MAX(-0.05,NORMINV(RAND(),$C$6,$D$6)) | L31: =MAX(0.02,NORMINV(RAND(),$C$7,$D$7)) | M31: =MIN(0.16,MAX(0.05,NORMINV(RAND(),$C$8,$D$8))) | N31: =MIN(24,MAX(5,NORMINV(RAND(),$C$9,$D$9))) | O31: =$I$8*(SUMPRODUCT(($I$2*(1+K31)^{1;2;3;4;5;6;7;8;9;10})*(($I$3+(L31-$I$3)*{1;2;3;4;5;6;7;8;9;10}/10)*(1-$I$7)+$I$4-$I$4*($I$5+(1.05-$I$5)*{1;2;3;4;5;6;7;8;9;10}/10)-(K31/(1+K31))*$I$6)/(1+M31)^{1;2;3;4;5;6;7;8;9;10})+$I$2*(1+K31)^10*(L31+$I$4)*N31/(1+M31)^10+$I$9-$I$10)/$I$11
A32: VALUE DISTRIBUTION (live histogram) | K32: =MAX(-0.05,NORMINV(RAND(),$C$6,$D$6)) | L32: =MAX(0.02,NORMINV(RAND(),$C$7,$D$7)) | M32: =MIN(0.16,MAX(0.05,NORMINV(RAND(),$C$8,$D$8))) | N32: =MIN(24,MAX(5,NORMINV(RAND(),$C$9,$D$9))) | O32: =$I$8*(SUMPRODUCT(($I$2*(1+K32)^{1;2;3;4;5;6;7;8;9;10})*(($I$3+(L32-$I$3)*{1;2;3;4;5;6;7;8;9;10}/10)*(1-$I$7)+$I$4-$I$4*($I$5+(1.05-$I$5)*{1;2;3;4;5;6;7;8;9;10}/10)-(K32/(1+K32))*$I$6)/(1+M32)^{1;2;3;4;5;6;7;8;9;10})+$I$2*(1+K32)^10*(L32+$I$4)*N32/(1+M32)^10+$I$9-$I$10)/$I$11
A33: Bin midpoint ($/sh) | B33: Count | K33: =MAX(-0.05,NORMINV(RAND(),$C$6,$D$6)) | L33: =MAX(0.02,NORMINV(RAND(),$C$7,$D$7)) | M33: =MIN(0.16,MAX(0.05,NORMINV(RAND(),$C$8,$D$8))) | N33: =MIN(24,MAX(5,NORMINV(RAND(),$C$9,$D$9))) | O33: =$I$8*(SUMPRODUCT(($I$2*(1+K33)^{1;2;3;4;5;6;7;8;9;10})*(($I$3+(L33-$I$3)*{1;2;3;4;5;6;7;8;9;10}/10)*(1-$I$7)+$I$4-$I$4*($I$5+(1.05-$I$5)*{1;2;3;4;5;6;7;8;9;10}/10)-(K33/(1+K33))*$I$6)/(1+M33)^{1;2;3;4;5;6;7;8;9;10})+$I$2*(1+K33)^10*(L33+$I$4)*N33/(1+M33)^10+$I$9-$I$10)/$I$11
A34: =$B$15+0.5*($B$16-$B$15)/15 | B34: =COUNTIFS($O$2:$O$1001,">="&($B$15+0*($B$16-$B$15)/15),$O$2:$O$1001,"<"&($B$15+1*($B$16-$B$15)/15)) | K34: =MAX(-0.05,NORMINV(RAND(),$C$6,$D$6)) | L34: =MAX(0.02,NORMINV(RAND(),$C$7,$D$7)) | M34: =MIN(0.16,MAX(0.05,NORMINV(RAND(),$C$8,$D$8))) | N34: =MIN(24,MAX(5,NORMINV(RAND(),$C$9,$D$9))) | O34: =$I$8*(SUMPRODUCT(($I$2*(1+K34)^{1;2;3;4;5;6;7;8;9;10})*(($I$3+(L34-$I$3)*{1;2;3;4;5;6;7;8;9;10}/10)*(1-$I$7)+$I$4-$I$4*($I$5+(1.05-$I$5)*{1;2;3;4;5;6;7;8;9;10}/10)-(K34/(1+K34))*$I$6)/(1+M34)^{1;2;3;4;5;6;7;8;9;10})+$I$2*(1+K34)^10*(L34+$I$4)*N34/(1+M34)^10+$I$9-$I$10)/$I$11
A35: =$B$15+1.5*($B$16-$B$15)/15 | B35: =COUNTIFS($O$2:$O$1001,">="&($B$15+1*($B$16-$B$15)/15),$O$2:$O$1001,"<"&($B$15+2*($B$16-$B$15)/15)) | K35: =MAX(-0.05,NORMINV(RAND(),$C$6,$D$6)) | L35: =MAX(0.02,NORMINV(RAND(),$C$7,$D$7)) | M35: =MIN(0.16,MAX(0.05,NORMINV(RAND(),$C$8,$D$8))) | N35: =MIN(24,MAX(5,NORMINV(RAND(),$C$9,$D$9))) | O35: =$I$8*(SUMPRODUCT(($I$2*(1+K35)^{1;2;3;4;5;6;7;8;9;10})*(($I$3+(L35-$I$3)*{1;2;3;4;5;6;7;8;9;10}/10)*(1-$I$7)+$I$4-$I$4*($I$5+(1.05-$I$5)*{1;2;3;4;5;6;7;8;9;10}/10)-(K35/(1+K35))*$I$6)/(1+M35)^{1;2;3;4;5;6;7;8;9;10})+$I$2*(1+K35)^10*(L35+$I$4)*N35/(1+M35)^10+$I$9-$I$10)/$I$11
A36: =$B$15+2.5*($B$16-$B$15)/15 | B36: =COUNTIFS($O$2:$O$1001,">="&($B$15+2*($B$16-$B$15)/15),$O$2:$O$1001,"<"&($B$15+3*($B$16-$B$15)/15)) | K36: =MAX(-0.05,NORMINV(RAND(),$C$6,$D$6)) | L36: =MAX(0.02,NORMINV(RAND(),$C$7,$D$7)) | M36: =MIN(0.16,MAX(0.05,NORMINV(RAND(),$C$8,$D$8))) | N36: =MIN(24,MAX(5,NORMINV(RAND(),$C$9,$D$9))) | O36: =$I$8*(SUMPRODUCT(($I$2*(1+K36)^{1;2;3;4;5;6;7;8;9;10})*(($I$3+(L36-$I$3)*{1;2;3;4;5;6;7;8;9;10}/10)*(1-$I$7)+$I$4-$I$4*($I$5+(1.05-$I$5)*{1;2;3;4;5;6;7;8;9;10}/10)-(K36/(1+K36))*$I$6)/(1+M36)^{1;2;3;4;5;6;7;8;9;10})+$I$2*(1+K36)^10*(L36+$I$4)*N36/(1+M36)^10+$I$9-$I$10)/$I$11
A37: =$B$15+3.5*($B$16-$B$15)/15 | B37: =COUNTIFS($O$2:$O$1001,">="&($B$15+3*($B$16-$B$15)/15),$O$2:$O$1001,"<"&($B$15+4*($B$16-$B$15)/15)) | K37: =MAX(-0.05,NORMINV(RAND(),$C$6,$D$6)) | L37: =MAX(0.02,NORMINV(RAND(),$C$7,$D$7)) | M37: =MIN(0.16,MAX(0.05,NORMINV(RAND(),$C$8,$D$8))) | N37: =MIN(24,MAX(5,NORMINV(RAND(),$C$9,$D$9))) | O37: =$I$8*(SUMPRODUCT(($I$2*(1+K37)^{1;2;3;4;5;6;7;8;9;10})*(($I$3+(L37-$I$3)*{1;2;3;4;5;6;7;8;9;10}/10)*(1-$I$7)+$I$4-$I$4*($I$5+(1.05-$I$5)*{1;2;3;4;5;6;7;8;9;10}/10)-(K37/(1+K37))*$I$6)/(1+M37)^{1;2;3;4;5;6;7;8;9;10})+$I$2*(1+K37)^10*(L37+$I$4)*N37/(1+M37)^10+$I$9-$I$10)/$I$11
A38: =$B$15+4.5*($B$16-$B$15)/15 | B38: =COUNTIFS($O$2:$O$1001,">="&($B$15+4*($B$16-$B$15)/15),$O$2:$O$1001,"<"&($B$15+5*($B$16-$B$15)/15)) | K38: =MAX(-0.05,NORMINV(RAND(),$C$6,$D$6)) | L38: =MAX(0.02,NORMINV(RAND(),$C$7,$D$7)) | M38: =MIN(0.16,MAX(0.05,NORMINV(RAND(),$C$8,$D$8))) | N38: =MIN(24,MAX(5,NORMINV(RAND(),$C$9,$D$9))) | O38: =$I$8*(SUMPRODUCT(($I$2*(1+K38)^{1;2;3;4;5;6;7;8;9;10})*(($I$3+(L38-$I$3)*{1;2;3;4;5;6;7;8;9;10}/10)*(1-$I$7)+$I$4-$I$4*($I$5+(1.05-$I$5)*{1;2;3;4;5;6;7;8;9;10}/10)-(K38/(1+K38))*$I$6)/(1+M38)^{1;2;3;4;5;6;7;8;9;10})+$I$2*(1+K38)^10*(L38+$I$4)*N38/(1+M38)^10+$I$9-$I$10)/$I$11
A39: =$B$15+5.5*($B$16-$B$15)/15 | B39: =COUNTIFS($O$2:$O$1001,">="&($B$15+5*($B$16-$B$15)/15),$O$2:$O$1001,"<"&($B$15+6*($B$16-$B$15)/15)) | K39: =MAX(-0.05,NORMINV(RAND(),$C$6,$D$6)) | L39: =MAX(0.02,NORMINV(RAND(),$C$7,$D$7)) | M39: =MIN(0.16,MAX(0.05,NORMINV(RAND(),$C$8,$D$8))) | N39: =MIN(24,MAX(5,NORMINV(RAND(),$C$9,$D$9))) | O39: =$I$8*(SUMPRODUCT(($I$2*(1+K39)^{1;2;3;4;5;6;7;8;9;10})*(($I$3+(L39-$I$3)*{1;2;3;4;5;6;7;8;9;10}/10)*(1-$I$7)+$I$4-$I$4*($I$5+(1.05-$I$5)*{1;2;3;4;5;6;7;8;9;10}/10)-(K39/(1+K39))*$I$6)/(1+M39)^{1;2;3;4;5;6;7;8;9;10})+$I$2*(1+K39)^10*(L39+$I$4)*N39/(1+M39)^10+$I$9-$I$10)/$I$11
A40: =$B$15+6.5*($B$16-$B$15)/15 | B40: =COUNTIFS($O$2:$O$1001,">="&($B$15+6*($B$16-$B$15)/15),$O$2:$O$1001,"<"&($B$15+7*($B$16-$B$15)/15)) | K40: =MAX(-0.05,NORMINV(RAND(),$C$6,$D$6)) | L40: =MAX(0.02,NORMINV(RAND(),$C$7,$D$7)) | M40: =MIN(0.16,MAX(0.05,NORMINV(RAND(),$C$8,$D$8))) | N40: =MIN(24,MAX(5,NORMINV(RAND(),$C$9,$D$9))) | O40: =$I$8*(SUMPRODUCT(($I$2*(1+K40)^{1;2;3;4;5;6;7;8;9;10})*(($I$3+(L40-$I$3)*{1;2;3;4;5;6;7;8;9;10}/10)*(1-$I$7)+$I$4-$I$4*($I$5+(1.05-$I$5)*{1;2;3;4;5;6;7;8;9;10}/10)-(K40/(1+K40))*$I$6)/(1+M40)^{1;2;3;4;5;6;7;8;9;10})+$I$2*(1+K40)^10*(L40+$I$4)*N40/(1+M40)^10+$I$9-$I$10)/$I$11
...
