Workbook

Sheet Cover
A1: Visa Inc. (V)
A2: DCF valuation — exit-multiple terminal · defaults anchored to consensus
A4: Last updated | B4: 2026-06-07
A5: Data pulled (FMP) | B5: Q2 2026
A6: Assumptions by | B6: Opus 4.8 — 2026-06-07
A8: VALUATION SUMMARY
A10: Fair value / share | B10: =Valuation!B36
A11: Current price | B11: =Valuation!$B$2
A12: Upside / (downside) | B12: =Valuation!B42
A13: Verdict | B13: =IF(Valuation!B36>Valuation!$B$2,"Undervalued","Overvalued")
A14: Monte Carlo P(undervalued) | B14: ='Monte Carlo'!B20
A15: KEY ASSUMPTIONS
A17: WACC (from WACC tab) | B17: =WACC!B14
A18: Terminal method | B18: =Valuation!$B$6
A19: Exit basis / multiple | B19: =Valuation!$B$7
A20: Exit multiple | B20: =Valuation!$B$8
A21: Terminal growth (g) | B21: =Valuation!$B$4
A22: Terminal weight | B22: =Valuation!B39
A23: Forecast horizon | B23: 10 years
A25: THE STORY (Opus)
A27: Visa is a toll-taker on global electronic payments with a structurally advantaged duopoly network, and its growth is driven by the secular shift from cash to digital plus a cross-border premium that carries the highest-margin International Transaction revenue. Net revenue compounds in the low-teens near term (in line with FMP consensus to ~$45.5B in 2026), then fades toward a mature ~4% rate as digitization penetration matures. Operating margins normalize back to the mid-to-high 60s as the FY2025 dip reverses and operating leverage on a fixed-cost network reasserts.

Sheet Dashboard
A1: Visa Inc. (V) — Control Dashboard
A2: Edit the yellow cells; everything recomputes. Orange = a driver you've moved off consensus.
A4: VERDICT
A5: Fair value / share | B5: =Valuation!B36
A6: Current price | B6: =Dashboard!$B$48
A7: Upside / (downside) | B7: =Valuation!B42
A8: Verdict | B8: =IF(Valuation!B36>Dashboard!$B$48,"Undervalued","Overvalued")
A9: Monte Carlo P(undervalued) | B9: ='Monte Carlo'!B20
A11: GUARDRAIL SIGNALS (are my assumptions sane?)
A12: Signal | B12: Value | C12: Flag | D12: Healthy
A13: Terminal weight (% of EV) | B13: =Valuation!B39 | C13: =IF(Valuation!B39>0.9,"! high","ok") | D13: < 90%
A14: Implied g vs exit multiple | B14: =Valuation!B40 | C14: =IF(Valuation!B40>Dashboard!$B$46+0.02,"! rich","ok") | D14: near term g
A15: ROIC - WACC (2026) | B15: =Model!G44-WACC!B14 | C15: =IF(Model!G44-WACC!B14<0,"! destroys","creates") | D15: > 0
A16: Revenue vs consensus (2026) | B16: =Consensus!B6 | C16: =IF(ABS(Consensus!B6)>0.05,"! off-Street","on") | D16: +/- 5%
A17: MC P(undervalued) | B17: ='Monte Carlo'!B20 | C17: =IF('Monte Carlo'!B20<0.5,"! coin-flip","ok") | D17: context
A18: REVENUE DRIVERS — near-term & terminal growth per segment
A19: Segment | B19: Near-term | C19: Terminal | D19: Consensus | E19: Thesis claim
A20: Data Processing Revenues | B20: 0.11 | C20: 0.04 | D20: 0.11
A21: Service | B21: 0.09 | C21: 0.04 | D21: 0.09
A22: International Transaction Revenues | B22: 0.11 | C22: 0.04 | D22: 0.11
A23: Service, Other | B23: 0.15 | C23: 0.04 | D23: 0.15
A24: Client Incentives | B24: 0.12 | C24: 0.04 | D24: 0.12
A28: PROFITABILITY & TAX
A29: Near-term operating margin | B29: 0.65 | D29: 0.65 | E29: consensus-implied; ramps to terminal
A30: Terminal operating margin | B30: 0.67 | E30: AI/ads mix + operating leverage
A31: Tax rate | B31: 0.19
A33: CAPITAL INTENSITY
A34: 2026 capex ($M) | B34: 1639.4732 | D34: 1639.4732 | E34: ~last-year capex +10%; set to guidance
A35: Terminal capex / D&A | B35: 1.05 | E35: converges to ~1.0x as build-out matures
A37: DISCOUNT RATE & TERMINAL
A38: Risk-free rate (10Y) | B38: 0.043
A39: Equity risk premium | B39: 0.045
A40: Beta (levered) | B40: 0.784 | E40: FMP raw beta; Damodaran bottom-up ~1.2
A41: Pre-tax cost of debt | B41: 0.045
A42: WACC (computed) | B42: =WACC!B14
A43: Terminal method | B43: Exit multiple
A44: Exit basis | B44: EV/FCF
A45: Exit multiple | B45: 24
A46: Terminal growth (g) | B46: 0.04
A48: Current price | B48: 332.64

Sheet Color Code
A1: Color | B1: Meaning
A2: Black | B2: Formula-driven (same-sheet)
A3: Blue | B3: Hard-coded actuals (from FMP filings)
A4: Yellow | B4: An assumption you can change — edit these to drive the model
A5: Green | B5: A formula that links to another sheet
A6: Orange | B6: (Dashboard) an assumption you've moved off consensus — your active bet
A7: How to use | B7: Edit yellow cells (Model assumptions, WACC drivers, Valuation toggles). Everything else recomputes.

Sheet WACC
A1: WACC Calculator
A2: Risk-free rate (10Y) | B2: =Dashboard!$B$38
A3: Equity risk premium | B3: =Dashboard!$B$39
A4: Beta (levered) | B4: =Dashboard!$B$40
A5: Cost of equity (CAPM) | B5: =B2+B4*B3
A6: Pre-tax cost of debt | B6: =Dashboard!$B$41
A7: Tax rate | B7: =Dashboard!$B$31
A8: After-tax cost of debt | B8: =B6*(1-B7)
A9: Market cap (E) | B9: =Dashboard!$B$48*Financials!AC17
A10: Total debt (D) | B10: =Financials!AC47
A11: Equity weight | B11: =B9/(B9+B10)
A12: Debt weight | B12: =B10/(B9+B10)
A14: WACC | B14: =B11*B5+B12*B8
A16: Yellow = edit. CAPM cost of equity; market-value weights. Feeds Valuation!WACC.

Sheet Model
A1: $M unless noted | B1: FY2021A | C1: FY2022A | D1: FY2023A | E1: FY2024A | F1: FY2025A | G1: FY2026E | H1: FY2027E | I1: FY2028E | J1: FY2029E | K1: FY2030E | L1: FY2031E | M1: FY2032E | N1: FY2033E | O1: FY2034E | P1: FY2035E
A3: REVENUE BY SEGMENT (yellow = growth assumption; actuals link to Financials)
A4: Data Processing Revenues | B4: =SUM(Financials!H19:K19) | C4: =SUM(Financials!L19:O19) | D4: =SUM(Financials!P19:S19) | E4: =SUM(Financials!T19:W19) | F4: =SUM(Financials!X19:AA19) | G4: =F4*(1+G5) | H4: =G4*(1+H5) | I4: =H4*(1+I5) | J4: =I4*(1+J5) | K4: =J4*(1+K5) | L4: =K4*(1+L5) | M4: =L4*(1+M5) | N4: =M4*(1+N5) | ... P4: =O4*(1+P5)
A5: growth % (interpolated from Dashboard) | C5: =IFERROR(C4/B4-1,"") | D5: =IFERROR(D4/C4-1,"") | E5: =IFERROR(E4/D4-1,"") | F5: =IFERROR(F4/E4-1,"") | G5: =Dashboard!$B$20+(Dashboard!$C$20-Dashboard!$B$20)*MAX(0,0-2)/7 | H5: =Dashboard!$B$20+(Dashboard!$C$20-Dashboard!$B$20)*MAX(0,1-2)/7 | I5: =Dashboard!$B$20+(Dashboard!$C$20-Dashboard!$B$20)*MAX(0,2-2)/7 | J5: =Dashboard!$B$20+(Dashboard!$C$20-Dashboard!$B$20)*MAX(0,3-2)/7 | K5: =Dashboard!$B$20+(Dashboard!$C$20-Dashboard!$B$20)*MAX(0,4-2)/7 | L5: =Dashboard!$B$20+(Dashboard!$C$20-Dashboard!$B$20)*MAX(0,5-2)/7 | M5: =Dashboard!$B$20+(Dashboard!$C$20-Dashboard!$B$20)*MAX(0,6-2)/7 | N5: =Dashboard!$B$20+(Dashboard!$C$20-Dashboard!$B$20)*MAX(0,7-2)/7 | O5: =Dashboard!$B$20+(Dashboard!$C$20-Dashboard!$B$20)*MAX(0,8-2)/7 | P5: =Dashboard!$B$20+(Dashboard!$C$20-Dashboard!$B$20)*MAX(0,9-2)/7
A6: Service | B6: =SUM(Financials!H22:K22) | C6: =SUM(Financials!L22:O22) | D6: =SUM(Financials!P22:S22) | E6: =SUM(Financials!T22:W22) | F6: =SUM(Financials!X22:AA22) | G6: =F6*(1+G7) | H6: =G6*(1+H7) | I6: =H6*(1+I7) | J6: =I6*(1+J7) | K6: =J6*(1+K7) | L6: =K6*(1+L7) | M6: =L6*(1+M7) | N6: =M6*(1+N7) | ... P6: =O6*(1+P7)
A7: growth % (interpolated from Dashboard) | C7: =IFERROR(C6/B6-1,"") | D7: =IFERROR(D6/C6-1,"") | E7: =IFERROR(E6/D6-1,"") | F7: =IFERROR(F6/E6-1,"") | G7: =Dashboard!$B$21+(Dashboard!$C$21-Dashboard!$B$21)*MAX(0,0-2)/7 | H7: =Dashboard!$B$21+(Dashboard!$C$21-Dashboard!$B$21)*MAX(0,1-2)/7 | I7: =Dashboard!$B$21+(Dashboard!$C$21-Dashboard!$B$21)*MAX(0,2-2)/7 | J7: =Dashboard!$B$21+(Dashboard!$C$21-Dashboard!$B$21)*MAX(0,3-2)/7 | K7: =Dashboard!$B$21+(Dashboard!$C$21-Dashboard!$B$21)*MAX(0,4-2)/7 | L7: =Dashboard!$B$21+(Dashboard!$C$21-Dashboard!$B$21)*MAX(0,5-2)/7 | M7: =Dashboard!$B$21+(Dashboard!$C$21-Dashboard!$B$21)*MAX(0,6-2)/7 | N7: =Dashboard!$B$21+(Dashboard!$C$21-Dashboard!$B$21)*MAX(0,7-2)/7 | O7: =Dashboard!$B$21+(Dashboard!$C$21-Dashboard!$B$21)*MAX(0,8-2)/7 | P7: =Dashboard!$B$21+(Dashboard!$C$21-Dashboard!$B$21)*MAX(0,9-2)/7
A8: International Transaction Revenues | B8: =SUM(Financials!H25:K25) | C8: =SUM(Financials!L25:O25) | D8: =SUM(Financials!P25:S25) | E8: =SUM(Financials!T25:W25) | F8: =SUM(Financials!X25:AA25) | G8: =F8*(1+G9) | H8: =G8*(1+H9) | I8: =H8*(1+I9) | J8: =I8*(1+J9) | K8: =J8*(1+K9) | L8: =K8*(1+L9) | M8: =L8*(1+M9) | N8: =M8*(1+N9) | ... P8: =O8*(1+P9)
A9: growth % (interpolated from Dashboard) | C9: =IFERROR(C8/B8-1,"") | D9: =IFERROR(D8/C8-1,"") | E9: =IFERROR(E8/D8-1,"") | F9: =IFERROR(F8/E8-1,"") | G9: =Dashboard!$B$22+(Dashboard!$C$22-Dashboard!$B$22)*MAX(0,0-2)/7 | H9: =Dashboard!$B$22+(Dashboard!$C$22-Dashboard!$B$22)*MAX(0,1-2)/7 | I9: =Dashboard!$B$22+(Dashboard!$C$22-Dashboard!$B$22)*MAX(0,2-2)/7 | J9: =Dashboard!$B$22+(Dashboard!$C$22-Dashboard!$B$22)*MAX(0,3-2)/7 | K9: =Dashboard!$B$22+(Dashboard!$C$22-Dashboard!$B$22)*MAX(0,4-2)/7 | L9: =Dashboard!$B$22+(Dashboard!$C$22-Dashboard!$B$22)*MAX(0,5-2)/7 | M9: =Dashboard!$B$22+(Dashboard!$C$22-Dashboard!$B$22)*MAX(0,6-2)/7 | N9: =Dashboard!$B$22+(Dashboard!$C$22-Dashboard!$B$22)*MAX(0,7-2)/7 | O9: =Dashboard!$B$22+(Dashboard!$C$22-Dashboard!$B$22)*MAX(0,8-2)/7 | P9: =Dashboard!$B$22+(Dashboard!$C$22-Dashboard!$B$22)*MAX(0,9-2)/7
A10: Service, Other | B10: =SUM(Financials!H28:K28) | C10: =SUM(Financials!L28:O28) | D10: =SUM(Financials!P28:S28) | E10: =SUM(Financials!T28:W28) | F10: =SUM(Financials!X28:AA28) | G10: =F10*(1+G11) | H10: =G10*(1+H11) | I10: =H10*(1+I11) | J10: =I10*(1+J11) | K10: =J10*(1+K11) | L10: =K10*(1+L11) | M10: =L10*(1+M11) | N10: =M10*(1+N11) | ... P10: =O10*(1+P11)
A11: growth % (interpolated from Dashboard) | C11: =IFERROR(C10/B10-1,"") | D11: =IFERROR(D10/C10-1,"") | E11: =IFERROR(E10/D10-1,"") | F11: =IFERROR(F10/E10-1,"") | G11: =Dashboard!$B$23+(Dashboard!$C$23-Dashboard!$B$23)*MAX(0,0-2)/7 | H11: =Dashboard!$B$23+(Dashboard!$C$23-Dashboard!$B$23)*MAX(0,1-2)/7 | I11: =Dashboard!$B$23+(Dashboard!$C$23-Dashboard!$B$23)*MAX(0,2-2)/7 | J11: =Dashboard!$B$23+(Dashboard!$C$23-Dashboard!$B$23)*MAX(0,3-2)/7 | K11: =Dashboard!$B$23+(Dashboard!$C$23-Dashboard!$B$23)*MAX(0,4-2)/7 | L11: =Dashboard!$B$23+(Dashboard!$C$23-Dashboard!$B$23)*MAX(0,5-2)/7 | M11: =Dashboard!$B$23+(Dashboard!$C$23-Dashboard!$B$23)*MAX(0,6-2)/7 | N11: =Dashboard!$B$23+(Dashboard!$C$23-Dashboard!$B$23)*MAX(0,7-2)/7 | O11: =Dashboard!$B$23+(Dashboard!$C$23-Dashboard!$B$23)*MAX(0,8-2)/7 | P11: =Dashboard!$B$23+(Dashboard!$C$23-Dashboard!$B$23)*MAX(0,9-2)/7
A12: Client Incentives | B12: =SUM(Financials!H31:K31) | C12: =SUM(Financials!L31:O31) | D12: =SUM(Financials!P31:S31) | E12: =SUM(Financials!T31:W31) | F12: =SUM(Financials!X31:AA31) | G12: =F12*(1+G13) | H12: =G12*(1+H13) | I12: =H12*(1+I13) | J12: =I12*(1+J13) | K12: =J12*(1+K13) | L12: =K12*(1+L13) | M12: =L12*(1+M13) | N12: =M12*(1+N13) | ... P12: =O12*(1+P13)
A13: growth % (interpolated from Dashboard) | C13: =IFERROR(C12/B12-1,"") | D13: =IFERROR(D12/C12-1,"") | E13: =IFERROR(E12/D12-1,"") | F13: =IFERROR(F12/E12-1,"") | G13: =Dashboard!$B$24+(Dashboard!$C$24-Dashboard!$B$24)*MAX(0,0-2)/7 | H13: =Dashboard!$B$24+(Dashboard!$C$24-Dashboard!$B$24)*MAX(0,1-2)/7 | I13: =Dashboard!$B$24+(Dashboard!$C$24-Dashboard!$B$24)*MAX(0,2-2)/7 | J13: =Dashboard!$B$24+(Dashboard!$C$24-Dashboard!$B$24)*MAX(0,3-2)/7 | K13: =Dashboard!$B$24+(Dashboard!$C$24-Dashboard!$B$24)*MAX(0,4-2)/7 | L13: =Dashboard!$B$24+(Dashboard!$C$24-Dashboard!$B$24)*MAX(0,5-2)/7 | M13: =Dashboard!$B$24+(Dashboard!$C$24-Dashboard!$B$24)*MAX(0,6-2)/7 | N13: =Dashboard!$B$24+(Dashboard!$C$24-Dashboard!$B$24)*MAX(0,7-2)/7 | O13: =Dashboard!$B$24+(Dashboard!$C$24-Dashboard!$B$24)*MAX(0,8-2)/7 | P13: =Dashboard!$B$24+(Dashboard!$C$24-Dashboard!$B$24)*MAX(0,9-2)/7
A14: Total revenue | B14: =B4+B6+B8+B10+B12 | C14: =C4+C6+C8+C10+C12 | D14: =D4+D6+D8+D10+D12 | E14: =E4+E6+E8+E10+E12 | F14: =F4+F6+F8+F10+F12 | G14: =G4+G6+G8+G10+G12 | H14: =H4+H6+H8+H10+H12 | I14: =I4+I6+I8+I10+I12 | ... P14: =P4+P6+P8+P10+P12
A15: growth % | C15: =IFERROR(C14/B14-1,"") | D15: =IFERROR(D14/C14-1,"") | E15: =IFERROR(E14/D14-1,"") | F15: =IFERROR(F14/E14-1,"") | G15: =IFERROR(G14/F14-1,"") | H15: =IFERROR(H14/G14-1,"") | I15: =IFERROR(I14/H14-1,"") | J15: =IFERROR(J14/I14-1,"") | ... P15: =IFERROR(P14/O14-1,"")
A17: COST STRUCTURE (yellow = % of revenue)
A18: Cost of revenue | B18: =SUM(Financials!H5:K5) | C18: =SUM(Financials!L5:O5) | D18: =SUM(Financials!P5:S5) | E18: =SUM(Financials!T5:W5) | F18: =SUM(Financials!X5:AA5) | G18: =G14*G19 | H18: =H14*H19 | I18: =I14*I19 | J18: =J14*J19 | K18: =K14*K19 | L18: =L14*L19 | M18: =M14*M19 | N18: =N14*N19 | ... P18: =P14*P19
A19: % of revenue | B19: =IFERROR(B18/B14,"") | C19: =IFERROR(C18/C14,"") | D19: =IFERROR(D18/D14,"") | E19: =IFERROR(E18/E14,"") | F19: =IFERROR(F18/F14,"") | G19: 0.196375 | H19: 0.196375 | I19: 0.196375 | J19: 0.196375 | K19: 0.196375 | L19: 0.196375 | M19: 0.196375 | N19: 0.196375 | O19: 0.196375 | P19: 0.196375
A20: R&D / Technology | B20: =SUM(Financials!H7:K7) | C20: =SUM(Financials!L7:O7) | D20: =SUM(Financials!P7:S7) | E20: =SUM(Financials!T7:W7) | F20: =SUM(Financials!X7:AA7) | G20: =G14*G21 | H20: =H14*H21 | I20: =I14*I21 | J20: =J14*J21 | K20: =K14*K21 | L20: =L14*L21 | M20: =M14*M21 | N20: =N14*N21 | ... P20: =P14*P21
A21: % of revenue | B21: =IFERROR(B20/B14,"") | C21: =IFERROR(C20/C14,"") | D21: =IFERROR(D20/D14,"") | E21: =IFERROR(E20/E14,"") | F21: =IFERROR(F20/F14,"") | G21: 0 | H21: 0 | I21: 0 | J21: 0 | K21: 0 | L21: 0 | M21: 0 | N21: 0 | O21: 0 | P21: 0
A22: SG&A | B22: =SUM(Financials!H9:K9) | C22: =SUM(Financials!L9:O9) | D22: =SUM(Financials!P9:S9) | E22: =SUM(Financials!T9:W9) | F22: =SUM(Financials!X9:AA9) | G22: =G14*G23 | H22: =H14*H23 | I22: =I14*I23 | J22: =J14*J23 | K22: =K14*K23 | L22: =L14*L23 | M22: =M14*M23 | N22: =N14*N23 | ... P22: =P14*P23
A23: % of revenue | B23: =IFERROR(B22/B14,"") | C23: =IFERROR(C22/C14,"") | D23: =IFERROR(D22/D14,"") | E23: =IFERROR(E22/E14,"") | F23: =IFERROR(F22/F14,"") | G23: 0.109225 | H23: 0.109225 | I23: 0.109225 | J23: 0.109225 | K23: 0.109225 | L23: 0.109225 | M23: 0.109225 | N23: 0.109225 | O23: 0.109225 | P23: 0.109225
A24: Other opex (fulfilment, etc.) | B24: =B14-(B18+B20+B22)-SUM(Financials!H13:K13) | C24: =C14-(C18+C20+C22)-SUM(Financials!L13:O13) | D24: =D14-(D18+D20+D22)-SUM(Financials!P13:S13) | E24: =E14-(E18+E20+E22)-SUM(Financials!T13:W13) | F24: =F14-(F18+F20+F22)-SUM(Financials!X13:AA13) | G24: =G14*(1-(Dashboard!$B$29+(Dashboard!$B$30-Dashboard!$B$29)*MIN(1,0/4)))-(G18+G20+G22) | H24: =H14*(1-(Dashboard!$B$29+(Dashboard!$B$30-Dashboard!$B$29)*MIN(1,1/4)))-(H18+H20+H22) | I24: =I14*(1-(Dashboard!$B$29+(Dashboard!$B$30-Dashboard!$B$29)*MIN(1,2/4)))-(I18+I20+I22) | J24: =J14*(1-(Dashboard!$B$29+(Dashboard!$B$30-Dashboard!$B$29)*MIN(1,3/4)))-(J18+J20+J22) | K24: =K14*(1-(Dashboard!$B$29+(Dashboard!$B$30-Dashboard!$B$29)*MIN(1,4/4)))-(K18+K20+K22) | L24: =L14*(1-(Dashboard!$B$29+(Dashboard!$B$30-Dashboard!$B$29)*MIN(1,5/4)))-(L18+L20+L22) | M24: =M14*(1-(Dashboard!$B$29+(Dashboard!$B$30-Dashboard!$B$29)*MIN(1,6/4)))-(M18+M20+M22) | N24: =N14*(1-(Dashboard!$B$29+(Dashboard!$B$30-Dashboard!$B$29)*MIN(1,7/4)))-(N18+N20+N22) | O24: =O14*(1-(Dashboard!$B$29+(Dashboard!$B$30-Dashboard!$B$29)*MIN(1,8/4)))-(O18+O20+O22) | P24: =P14*(1-(Dashboard!$B$29+(Dashboard!$B$30-Dashboard!$B$29)*MIN(1,9/4)))-(P18+P20+P22)
A25: % of revenue | B25: =IFERROR(B24/B14,"") | C25: =IFERROR(C24/C14,"") | D25: =IFERROR(D24/D14,"") | E25: =IFERROR(E24/E14,"") | F25: =IFERROR(F24/F14,"") | G25: =IFERROR(G24/G14,"") | H25: =IFERROR(H24/H14,"") | I25: =IFERROR(I24/I14,"") | ... P25: =IFERROR(P24/P14,"")
A27: Operating income (EBIT) | B27: =B14-(B18+B20+B22)-B24 | C27: =C14-(C18+C20+C22)-C24 | D27: =D14-(D18+D20+D22)-D24 | E27: =E14-(E18+E20+E22)-E24 | F27: =F14-(F18+F20+F22)-F24 | G27: =G14-(G18+G20+G22)-G24 | H27: =H14-(H18+H20+H22)-H24 | I27: =I14-(I18+I20+I22)-I24 | ... P27: =P14-(P18+P20+P22)-P24
A28: operating margin | B28: =IFERROR(B27/B14,"") | C28: =IFERROR(C27/C14,"") | D28: =IFERROR(D27/D14,"") | E28: =IFERROR(E27/E14,"") | F28: =IFERROR(F27/F14,"") | G28: =IFERROR(G27/G14,"") | H28: =IFERROR(H27/H14,"") | I28: =IFERROR(I27/I14,"") | ... P28: =IFERROR(P27/P14,"")
A30: FCF BRIDGE (NOPAT + D&A + SBC - dNWC - Capex)
A31: NOPAT = EBIT x (1 - tax) | B31: =B27*(1-Valuation!$B$5) | C31: =C27*(1-Valuation!$B$5) | D31: =D27*(1-Valuation!$B$5) | E31: =E27*(1-Valuation!$B$5) | F31: =F27*(1-Valuation!$B$5) | G31: =G27*(1-Valuation!$B$5) | H31: =H27*(1-Valuation!$B$5) | I31: =I27*(1-Valuation!$B$5) | ... P31: =P27*(1-Valuation!$B$5)
A32: + D&A | B32: =SUM(Financials!H50:K50) | C32: =SUM(Financials!L50:O50) | D32: =SUM(Financials!P50:S50) | E32: =SUM(Financials!T50:W50) | F32: =SUM(Financials!X50:AA50) | G32: =G14*0.0305 | H32: =H14*0.0305 | I32: =I14*0.0305 | J32: =J14*0.0305 | K32: =K14*0.0305 | L32: =L14*0.0305 | M32: =M14*0.0305 | N32: =N14*0.0305 | ... P32: =P14*0.0305
A33: + SBC (non-cash) | B33: =SUM(Financials!H51:K51) | C33: =SUM(Financials!L51:O51) | D33: =SUM(Financials!P51:S51) | E33: =SUM(Financials!T51:W51) | F33: =SUM(Financials!X51:AA51) | G33: =G14*0.0224 | H33: =H14*0.0214 | I33: =I14*0.0204 | J33: =J14*0.0194 | K33: =K14*0.0184 | L33: =L14*0.0174 | M33: =M14*0.0164 | N33: =N14*0.0154 | O33: =O14*0.0145 | P33: =P14*0.0135
A34: - dNWC | G34: =(G14-F14)*0.0050 | H34: =(H14-G14)*0.0050 | I34: =(I14-H14)*0.0050 | J34: =(J14-I14)*0.0050 | K34: =(K14-J14)*0.0050 | L34: =(L14-K14)*0.0050 | M34: =(M14-L14)*0.0050 | N34: =(N14-M14)*0.0050 | ... P34: =(P14-O14)*0.0050
A35: - Capex | B35: =-SUM(Financials!H54:K54) | C35: =-SUM(Financials!L54:O54) | D35: =-SUM(Financials!P54:S54) | E35: =-SUM(Financials!T54:W54) | F35: =-SUM(Financials!X54:AA54) | G35: =G32*G36 | H35: =H32*H36 | I35: =I32*I36 | J35: =J32*J36 | K35: =K32*K36 | L35: =L32*L36 | M35: =M32*M36 | N35: =N32*N36 | ... P35: =P32*P36
A36: Capex / D&A (from Dashboard: $cap'26 -> terminal) | B36: =IFERROR(B35/B32,"") | C36: =IFERROR(C35/C32,"") | D36: =IFERROR(D35/D32,"") | E36: =IFERROR(E35/E32,"") | F36: =IFERROR(F35/F32,"") | G36: =(Dashboard!$B$34/G32)+(Dashboard!$B$35-(Dashboard!$B$34/G32))*0/9 | H36: =(Dashboard!$B$34/G32)+(Dashboard!$B$35-(Dashboard!$B$34/G32))*1/9 | I36: =(Dashboard!$B$34/G32)+(Dashboard!$B$35-(Dashboard!$B$34/G32))*2/9 | J36: =(Dashboard!$B$34/G32)+(Dashboard!$B$35-(Dashboard!$B$34/G32))*3/9 | K36: =(Dashboard!$B$34/G32)+(Dashboard!$B$35-(Dashboard!$B$34/G32))*4/9 | L36: =(Dashboard!$B$34/G32)+(Dashboard!$B$35-(Dashboard!$B$34/G32))*5/9 | M36: =(Dashboard!$B$34/G32)+(Dashboard!$B$35-(Dashboard!$B$34/G32))*6/9 | N36: =(Dashboard!$B$34/G32)+(Dashboard!$B$35-(Dashboard!$B$34/G32))*7/9 | O36: =(Dashboard!$B$34/G32)+(Dashboard!$B$35-(Dashboard!$B$34/G32))*8/9 | P36: =(Dashboard!$B$34/G32)+(Dashboard!$B$35-(Dashboard!$B$34/G32))*9/9
A38: FCFF (firm) | B38: =B31+B32+B33-B34-B35 | C38: =C31+C32+C33-C34-C35 | D38: =D31+D32+D33-D34-D35 | E38: =E31+E32+E33-E34-E35 | F38: =F31+F32+F33-F34-F35 | G38: =G31+G32+G33-G34-G35 | H38: =H31+H32+H33-H34-H35 | I38: =I31+I32+I33-I34-I35 | ... P38: =P31+P32+P33-P34-P35
A39: Valuation FCF (FCFF - SBC) | B39: =B38-B33 | C39: =C38-C33 | D39: =D38-D33 | E39: =E38-E33 | F39: =F38-F33 | G39: =G38-G33 | H39: =H38-H33 | I39: =I38-I33 | ... P39: =P38-P33
A41: RETURNS ON CAPITAL & EFFICIENCY (is new revenue/capital earning its keep?)
A42: Invested capital (debt + equity - cash) | B42: =Financials!K48+Financials!K47-Financials!K42 | C42: =Financials!O48+Financials!O47-Financials!O42 | D42: =Financials!S48+Financials!S47-Financials!S42 | E42: =Financials!W48+Financials!W47-Financials!W42 | F42: =Financials!AA48+Financials!AA47-Financials!AA42 | G42: =F42+G35-G32+G34 | H42: =G42+H35-H32+H34 | I42: =H42+I35-I32+I34 | J42: =I42+J35-J32+J34 | K42: =J42+K35-K32+K34 | L42: =K42+L35-L32+L34 | M42: =L42+M35-M32+M34 | N42: =M42+N35-N32+N34 | ... P42: =O42+P35-P32+P34
A43: Book equity (year-end) | B43: =Financials!K48 | C43: =Financials!O48 | D43: =Financials!S48 | E43: =Financials!W48 | F43: =Financials!AA48 | G43: =F43+G31 | H43: =G43+H31 | I43: =H43+I31 | J43: =I43+J31 | K43: =J43+K31 | L43: =K43+L31 | M43: =L43+M31 | N43: =M43+N31 | ... P43: =O43+P31
A44: ROIC (NOPAT / beg. invested capital) | C44: =IFERROR(C31/B42,"") | D44: =IFERROR(D31/C42,"") | E44: =IFERROR(E31/D42,"") | F44: =IFERROR(F31/E42,"") | G44: =IFERROR(G31/F42,"") | H44: =IFERROR(H31/G42,"") | I44: =IFERROR(I31/H42,"") | J44: =IFERROR(J31/I42,"") | ... P44: =IFERROR(P31/O42,"")
A45: ROE (earnings / beg. equity) | C45: =IFERROR(SUM(Financials!L15:O15)/B43,"") | D45: =IFERROR(SUM(Financials!P15:S15)/C43,"") | E45: =IFERROR(SUM(Financials!T15:W15)/D43,"") | F45: =IFERROR(SUM(Financials!X15:AA15)/E43,"") | G45: =IFERROR(G31/F43,"") | H45: =IFERROR(H31/G43,"") | I45: =IFERROR(I31/H43,"") | J45: =IFERROR(J31/I43,"") | K45: =IFERROR(K31/J43,"") | L45: =IFERROR(L31/K43,"") | M45: =IFERROR(M31/L43,"") | N45: =IFERROR(N31/M43,"") | ... P45: =IFERROR(P31/O43,"")
A46: ROIC - WACC spread (value created) | C46: =IFERROR(C44-WACC!$B$14,"") | D46: =IFERROR(D44-WACC!$B$14,"") | E46: =IFERROR(E44-WACC!$B$14,"") | F46: =IFERROR(F44-WACC!$B$14,"") | G46: =IFERROR(G44-WACC!$B$14,"") | H46: =IFERROR(H44-WACC!$B$14,"") | I46: =IFERROR(I44-WACC!$B$14,"") | J46: =IFERROR(J44-WACC!$B$14,"") | ... P46: =IFERROR(P44-WACC!$B$14,"")
...

Sheet Financials
A1: Line Item ($M) | B1: Q3 2019 | C1: Q4 2019 | D1: Q1 2020 | E1: Q2 2020 | F1: Q3 2020 | G1: Q4 2020 | H1: Q1 2021 | I1: Q2 2021 | J1: Q3 2021 | K1: Q4 2021 | L1: Q1 2022 | M1: Q2 2022 | N1: Q3 2022 | O1: Q4 2022 | P1: Q1 2023 | Q1: Q2 2023 | R1: Q3 2023 | S1: Q4 2023 | T1: Q1 2024 | U1: Q2 2024 | V1: Q3 2024 | W1: Q4 2024 | X1: Q1 2025 | Y1: Q2 2025 | Z1: Q3 2025 | AA1: Q4 2025 | AB1: Q1 2026 | AC1: Q2 2026
A2: INCOME STATEMENT
A3: Revenue | B3: 5840 | C3: 6137 | D3: 6054 | E3: 5854 | F3: 4837 | G3: 5101 | H3: 5687 | I3: 5729 | J3: 6130 | K3: 6559 | L3: 7059 | M3: 7189 | N3: 7275 | O3: 7787 | P3: 7936 | Q3: 7985 | R3: 8123 | S3: 8609 | T3: 8634 | U3: 8775 | V3: 8900 | W3: 9617 | X3: 9510 | Y3: 9594 | Z3: 10172 | AA3: 10724 | AB3: 10901 | AC3: 11230
A4: % YoY | F4: =IFERROR(F3/B3-1,"") | G4: =IFERROR(G3/C3-1,"") | H4: =IFERROR(H3/D3-1,"") | I4: =IFERROR(I3/E3-1,"") | J4: =IFERROR(J3/F3-1,"") | K4: =IFERROR(K3/G3-1,"") | L4: =IFERROR(L3/H3-1,"") | M4: =IFERROR(M3/I3-1,"") | ... AC4: =IFERROR(AC3/Y3-1,"")
A5: Cost of Revenue | B5: 1056 | C5: 1064 | D5: 1163 | E5: 1123 | F5: 1113 | G5: 1113 | H5: 1154 | I5: 1293 | J5: 1284 | K5: 1239 | L5: 1315 | M5: 1416 | N5: 1461 | O5: 1541 | P5: 1515 | Q5: 1694 | R5: 1663 | S5: 1695 | T5: 1660 | U5: 1792 | V5: 1773 | W5: 1817 | X5: 2020 | Y5: 1881 | Z5: 1973 | AA5: 1981 | AB5: 1997 | AC5: 2101
A6: % of revenue | B6: =IFERROR(B5/B3,"") | C6: =IFERROR(C5/C3,"") | D6: =IFERROR(D5/D3,"") | E6: =IFERROR(E5/E3,"") | F6: =IFERROR(F5/F3,"") | G6: =IFERROR(G5/G3,"") | H6: =IFERROR(H5/H3,"") | I6: =IFERROR(I5/I3,"") | ... AC6: =IFERROR(AC5/AC3,"")
A7: R&D Expense | B7: 0 | C7: 0 | D7: 0 | E7: 0 | F7: 0 | G7: 0 | H7: 0 | I7: 0 | J7: 0 | K7: 0 | L7: 0 | M7: 0 | N7: 0 | O7: 0 | P7: 0 | Q7: 0 | R7: 0 | S7: 0 | T7: 0 | U7: 0 | V7: 0 | W7: 0 | X7: 0 | Y7: 0 | Z7: 0 | AA7: 0 | AB7: 0 | AC7: 0
A8: % of revenue | B8: =IFERROR(B7/B3,"") | C8: =IFERROR(C7/C3,"") | D8: =IFERROR(D7/D3,"") | E8: =IFERROR(E7/E3,"") | F8: =IFERROR(F7/F3,"") | G8: =IFERROR(G7/G3,"") | H8: =IFERROR(H7/H3,"") | I8: =IFERROR(I7/I3,"") | ... AC8: =IFERROR(AC7/AC3,"")
A9: SG&A Expense | B9: 710 | C9: 796 | D9: 693 | E9: 607 | F9: 527 | G9: 648 | H9: 491 | I9: 651 | J9: 580 | K9: 802 | L9: 622 | M9: 764 | N9: 719 | O9: 930 | P9: 763 | Q9: 721 | R9: 744 | S9: 988 | T9: 764 | U9: 950 | V9: 912 | W9: 1167 | X9: 930 | Y9: 973 | Z9: 1090 | AA9: 1376 | AB9: 1133 | AC9: 1233
A10: % of revenue | B10: =IFERROR(B9/B3,"") | C10: =IFERROR(C9/C3,"") | D10: =IFERROR(D9/D3,"") | E10: =IFERROR(E9/E3,"") | F10: =IFERROR(F9/F3,"") | G10: =IFERROR(G9/G3,"") | H10: =IFERROR(H9/H3,"") | I10: =IFERROR(I9/I3,"") | ... AC10: =IFERROR(AC9/AC3,"")
A11: Gross Profit | B11: 4784 | C11: 5073 | D11: 4891 | E11: 4731 | F11: 3724 | G11: 3988 | H11: 4533 | I11: 4436 | J11: 4846 | K11: 5320 | L11: 5744 | M11: 5773 | N11: 5814 | O11: 6246 | P11: 6421 | Q11: 6291 | R11: 6460 | S11: 6914 | T11: 6974 | U11: 6983 | V11: 7127 | W11: 7800 | X11: 7490 | Y11: 7713 | Z11: 8199 | AA11: 8743 | AB11: 8904 | AC11: 9129
A12: gross margin | B12: =IFERROR(B11/B3,"") | C12: =IFERROR(C11/C3,"") | D12: =IFERROR(D11/D3,"") | E12: =IFERROR(E11/E3,"") | F12: =IFERROR(F11/F3,"") | G12: =IFERROR(G11/G3,"") | H12: =IFERROR(H11/H3,"") | I12: =IFERROR(I11/I3,"") | ... AC12: =IFERROR(AC11/AC3,"")
A13: Operating Income | B13: 3908 | C13: 3735 | D13: 4016 | E13: 3924 | F13: 2999 | G13: 3142 | H13: 3844 | I13: 3581 | J13: 4064 | K13: 4315 | L13: 4776 | M13: 4802 | N13: 4148 | O13: 5087 | P13: 5090 | Q13: 5336 | R13: 5024 | S13: 5550 | T13: 5954 | U13: 5354 | V13: 5938 | W13: 6349 | X13: 6234 | Y13: 5435 | Z13: 6177 | AA13: 6148 | AB13: 6737 | AC13: 7234
A14: operating margin | B14: =IFERROR(B13/B3,"") | C14: =IFERROR(C13/C3,"") | D14: =IFERROR(D13/D3,"") | E14: =IFERROR(E13/E3,"") | F14: =IFERROR(F13/F3,"") | G14: =IFERROR(G13/G3,"") | H14: =IFERROR(H13/H3,"") | I14: =IFERROR(I13/I3,"") | ... AC14: =IFERROR(AC13/AC3,"")
A15: Net Income | B15: 3101 | C15: 3025 | D15: 3272 | E15: 3084 | F15: 2373 | G15: 2137 | H15: 3126 | I15: 3026 | J15: 2575 | K15: 3584 | L15: 3959 | M15: 3647 | N15: 3411 | O15: 3940 | P15: 4179 | Q15: 4257 | R15: 4156 | S15: 4681 | T15: 4890 | U15: 4663 | V15: 4872 | W15: 5318 | X15: 5119 | Y15: 4577 | Z15: 5272 | AA15: 5090 | AB15: 5853 | AC15: 6021
A16: net margin | B16: =IFERROR(B15/B3,"") | C16: =IFERROR(C15/C3,"") | D16: =IFERROR(D15/D3,"") | E16: =IFERROR(E15/E3,"") | F16: =IFERROR(F15/F3,"") | G16: =IFERROR(G15/G3,"") | H16: =IFERROR(H15/H3,"") | I16: =IFERROR(I15/I3,"") | ... AC16: =IFERROR(AC15/AC3,"")
A17: Diluted Shares (M) | B17: 2265 | C17: 2253 | D17: 2240 | E17: 2228 | F17: 2214 | G17: 2208 | H17: 2200 | I17: 2193 | J17: 2184 | K17: 2175 | L17: 2159 | M17: 2142 | N17: 2129 | O17: 2116 | P17: 2102 | Q17: 2093 | R17: 2080 | S17: 2065 | T17: 2045 | U17: 2039 | V17: 2029 | W17: 2003 | X17: 1985 | Y17: 1974 | Z17: 1959 | AA17: 1945 | AB17: 1933 | AC17: 1933
A18: REVENUE BY SEGMENT — PRODUCT (% YoY, % of revenue)
A19: Data Processing Revenues | B19: 2662 | C19: 2769 | D19: 2864 | E19: 2711 | F19: 2525 | G19: 2875 | H19: 3033 | I19: 2996 | J19: 3327 | K19: 3436 | L19: 3614 | M19: 3480 | N19: 3579 | O19: 3765 | P19: 3827 | Q19: 3819 | R19: 4105 | S19: 4256 | T19: 4356 | U19: 4259 | V19: 4489 | W19: 4610 | X19: 4745 | Y19: 4701 | Z19: 5153 | AA19: 5394 | AB19: 5544 | AC19: 5543
A20: % YoY | F20: =IFERROR(F19/B19-1,"") | G20: =IFERROR(G19/C19-1,"") | H20: =IFERROR(H19/D19-1,"") | I20: =IFERROR(I19/E19-1,"") | J20: =IFERROR(J19/F19-1,"") | K20: =IFERROR(K19/G19-1,"") | L20: =IFERROR(L19/H19-1,"") | M20: =IFERROR(M19/I19-1,"") | ... AC20: =IFERROR(AC19/Y19-1,"")
A21: % of revenue | B21: =IFERROR(B19/B3,"") | C21: =IFERROR(C19/C3,"") | D21: =IFERROR(D19/D3,"") | E21: =IFERROR(E19/E3,"") | F21: =IFERROR(F19/F3,"") | G21: =IFERROR(G19/G3,"") | H21: =IFERROR(H19/H3,"") | I21: =IFERROR(I19/I3,"") | ... AC21: =IFERROR(AC19/AC3,"")
A22: Service | B22: 2405 | C22: 2536 | D22: 2555 | E22: 2623 | F22: 2409 | G22: 2217 | H22: 2677 | I22: 2845 | J22: 2828 | K22: 3125 | L22: 3193 | M22: 3521 | N22: 3189 | O22: 3458 | P22: 3511 | Q22: 3771 | R22: 3668 | S22: 3876 | T22: 3915 | U22: 4033 | V22: 3967 | W22: 4199 | X22: 4208 | Y22: 4399 | Z22: 4330 | AA22: 4602 | AB22: 4760 | AC22: 4981
A23: % YoY | F23: =IFERROR(F22/B22-1,"") | G23: =IFERROR(G22/C22-1,"") | H23: =IFERROR(H22/D22-1,"") | I23: =IFERROR(I22/E22-1,"") | J23: =IFERROR(J22/F22-1,"") | K23: =IFERROR(K22/G22-1,"") | L23: =IFERROR(L22/H22-1,"") | M23: =IFERROR(M22/I22-1,"") | ... AC23: =IFERROR(AC22/Y22-1,"")
A24: % of revenue | B24: =IFERROR(B22/B3,"") | C24: =IFERROR(C22/C3,"") | D24: =IFERROR(D22/D3,"") | E24: =IFERROR(E22/E3,"") | F24: =IFERROR(F22/F3,"") | G24: =IFERROR(G22/G3,"") | H24: =IFERROR(H22/H3,"") | I24: =IFERROR(I22/I3,"") | ... AC24: =IFERROR(AC22/AC3,"")
A25: International Transaction Revenues | B25: 1977 | C25: 2180 | D25: 2018 | E25: 1833 | F25: 1102 | G25: 1346 | H25: 1451 | I25: 1488 | J25: 1696 | K25: 1895 | L25: 2174 | M25: 2208 | N25: 2560 | O25: 2873 | P25: 2797 | Q25: 2749 | R25: 2920 | S25: 3172 | T25: 3019 | U25: 2984 | V25: 3194 | W25: 3468 | X25: 3442 | Y25: 3291 | Z25: 3633 | AA25: 3800 | AB25: 3652 | AC25: 3631
A26: % YoY | F26: =IFERROR(F25/B25-1,"") | G26: =IFERROR(G25/C25-1,"") | H26: =IFERROR(H25/D25-1,"") | I26: =IFERROR(I25/E25-1,"") | J26: =IFERROR(J25/F25-1,"") | K26: =IFERROR(K25/G25-1,"") | L26: =IFERROR(L25/H25-1,"") | M26: =IFERROR(M25/I25-1,"") | ... AC26: =IFERROR(AC25/Y25-1,"")
A27: % of revenue | B27: =IFERROR(B25/B3,"") | C27: =IFERROR(C25/C3,"") | D27: =IFERROR(D25/D3,"") | E27: =IFERROR(E25/E3,"") | F27: =IFERROR(F25/F3,"") | G27: =IFERROR(G25/G3,"") | H27: =IFERROR(H25/H3,"") | I27: =IFERROR(I25/I3,"") | ... AC27: =IFERROR(AC25/AC3,"")
A28: Service, Other | B28: 342 | C28: 345 | D28: 365 | E28: 392 | F28: 314 | G28: 361 | H28: 384 | I28: 392 | J28: 409 | K28: 490 | L28: 449 | M28: 474 | N28: 517 | O28: 551 | P28: 587 | Q28: 551 | R28: 597 | S28: 744 | T28: 692 | U28: 756 | V28: 780 | W28: 969 | X28: 912 | Y28: 937 | Z28: 1028 | AA28: 1176 | AB28: 1214 | AC28: 1320
A29: % YoY | F29: =IFERROR(F28/B28-1,"") | G29: =IFERROR(G28/C28-1,"") | H29: =IFERROR(H28/D28-1,"") | I29: =IFERROR(I28/E28-1,"") | J29: =IFERROR(J28/F28-1,"") | K29: =IFERROR(K28/G28-1,"") | L29: =IFERROR(L28/H28-1,"") | M29: =IFERROR(M28/I28-1,"") | ... AC29: =IFERROR(AC28/Y28-1,"")
A30: % of revenue | B30: =IFERROR(B28/B3,"") | C30: =IFERROR(C28/C3,"") | D30: =IFERROR(D28/D3,"") | E30: =IFERROR(E28/E3,"") | F30: =IFERROR(F28/F3,"") | G30: =IFERROR(G28/G3,"") | H30: =IFERROR(H28/H3,"") | I30: =IFERROR(I28/I3,"") | ... AC30: =IFERROR(AC28/AC3,"")
A31: Client Incentives | B31: -1546 | C31: -1693 | D31: -1748 | E31: -1705 | F31: -1513 | G31: -1698 | H31: -1858 | I31: -1992 | J31: -2130 | K31: -2387 | L31: -2371 | M31: -2494 | N31: -2570 | O31: -2860 | P31: -2786 | Q31: -2905 | R31: -3167 | S31: -3439 | T31: -3348 | U31: -3257 | V31: -3530 | W31: -3629 | X31: -3797 | Y31: -3734 | Z31: -3972 | AA31: -4248 | AB31: -4269 | AC31: -4245
A32: % YoY | F32: =IFERROR(F31/B31-1,"") | G32: =IFERROR(G31/C31-1,"") | H32: =IFERROR(H31/D31-1,"") | I32: =IFERROR(I31/E31-1,"") | J32: =IFERROR(J31/F31-1,"") | K32: =IFERROR(K31/G31-1,"") | L32: =IFERROR(L31/H31-1,"") | M32: =IFERROR(M31/I31-1,"") | ... AC32: =IFERROR(AC31/Y31-1,"")
A33: % of revenue | B33: =IFERROR(B31/B3,"") | C33: =IFERROR(C31/C3,"") | D33: =IFERROR(D31/D3,"") | E33: =IFERROR(E31/E3,"") | F33: =IFERROR(F31/F3,"") | G33: =IFERROR(G31/G3,"") | H33: =IFERROR(H31/H3,"") | I33: =IFERROR(I31/I3,"") | ... AC33: =IFERROR(AC31/AC3,"")
A34: REVENUE BY SEGMENT — GEOGRAPHY (% YoY, % of revenue)
A35: Non-US | B35: 3253 | C35: 3431 | D35: 3337 | E35: 3204 | F35: 2457 | G35: 2723 | H35: 3020 | I35: 3046 | J35: 3324 | K35: 3555 | L35: 3881 | M35: 4110 | N35: 4105 | O35: 4363 | P35: 4369 | Q35: 4445 | R35: 4680 | S35: 5021 | T35: 4989 | U35: 5132 | V35: 5279 | W35: 5746 | X35: 5772 | Y35: 5783 | Z35: 6245 | AA35: 6567 | AB35: 6738 | AC35: 6911
A36: % YoY | F36: =IFERROR(F35/B35-1,"") | G36: =IFERROR(G35/C35-1,"") | H36: =IFERROR(H35/D35-1,"") | I36: =IFERROR(I35/E35-1,"") | J36: =IFERROR(J35/F35-1,"") | K36: =IFERROR(K35/G35-1,"") | L36: =IFERROR(L35/H35-1,"") | M36: =IFERROR(M35/I35-1,"") | ... AC36: =IFERROR(AC35/Y35-1,"")
A37: % of revenue | B37: =IFERROR(B35/B3,"") | C37: =IFERROR(C35/C3,"") | D37: =IFERROR(D35/D3,"") | E37: =IFERROR(E35/E3,"") | F37: =IFERROR(F35/F3,"") | G37: =IFERROR(G35/G3,"") | H37: =IFERROR(H35/H3,"") | I37: =IFERROR(I35/I3,"") | ... AC37: =IFERROR(AC35/AC3,"")
A38: UNITED STATES | B38: 2587 | C38: 2706 | D38: 2717 | E38: 2650 | F38: 2380 | G38: 2378 | H38: 2667 | I38: 2683 | J38: 2806 | K38: 3004 | L38: 3178 | M38: 3079 | N38: 3170 | O38: 3424 | P38: 3567 | Q38: 3540 | R38: 3443 | S38: 3588 | T38: 3645 | U38: 3643 | V38: 3621 | W38: 3871 | X38: 3738 | Y38: 3811 | Z38: 3927 | AA38: 4157 | AB38: 4163 | AC38: 4319
A39: % YoY | F39: =IFERROR(F38/B38-1,"") | G39: =IFERROR(G38/C38-1,"") | H39: =IFERROR(H38/D38-1,"") | I39: =IFERROR(I38/E38-1,"") | J39: =IFERROR(J38/F38-1,"") | K39: =IFERROR(K38/G38-1,"") | L39: =IFERROR(L38/H38-1,"") | M39: =IFERROR(M38/I38-1,"") | ... AC39: =IFERROR(AC38/Y38-1,"")
A40: % of revenue | B40: =IFERROR(B38/B3,"") | C40: =IFERROR(C38/C3,"") | D40: =IFERROR(D38/D3,"") | E40: =IFERROR(E38/E3,"") | F40: =IFERROR(F38/F3,"") | G40: =IFERROR(G38/G3,"") | H40: =IFERROR(H38/H3,"") | I40: =IFERROR(I38/I3,"") | ... AC40: =IFERROR(AC38/AC3,"")
...

Sheet Consensus
A1: Full consensus check — model vs Street (FMP estimates, $M)
A2: Fiscal year | B2: 2026 | C2: 2027 | D2: 2028 | E2: 2029 | F2: 2030
A3: EVERY AVAILABLE FMP CONSENSUS FIELD (consensus / model / % diff)
A4: Revenue — consensus | B4: 45540.922 | C4: 50365.218 | D4: 55528.017 | E4: 61988.196 | F4: 65566.25
A5: model | B5: =Model!G14 | C5: =Model!H14 | D5: =Model!I14 | E5: =Model!J14 | F5: =Model!K14
A6: vs consensus | B6: =IFERROR(B5/B4-1,"") | C6: =IFERROR(C5/C4-1,"") | D6: =IFERROR(D5/D4-1,"") | E6: =IFERROR(E5/E4-1,"") | F6: =IFERROR(F5/F4-1,"")
A8: EBITDA* — consensus | B8: 31357.383 | C8: 34679.172 | D8: 38234.038 | E8: 42682.22 | F8: 45145.903
A9: model | B9: =Model!G27+Model!G32 | C9: =Model!H27+Model!H32 | D9: =Model!I27+Model!I32 | E9: =Model!J27+Model!J32 | F9: =Model!K27+Model!K32
A10: vs consensus | B10: =IFERROR(B9/B8-1,"") | C10: =IFERROR(C9/C8-1,"") | D10: =IFERROR(D9/D8-1,"") | E10: =IFERROR(E9/E8-1,"") | F10: =IFERROR(F9/F8-1,"")
A12: EBIT* — consensus | B12: 29983.045 | C12: 33159.245 | D12: 36558.307 | E12: 40811.533 | F12: 43167.238
A13: model | B13: =Model!G27 | C13: =Model!H27 | D13: =Model!I27 | E13: =Model!J27 | F13: =Model!K27
A14: vs consensus | B14: =IFERROR(B13/B12-1,"") | C14: =IFERROR(C13/C12-1,"") | D14: =IFERROR(D13/D12-1,"") | E14: =IFERROR(E13/E12-1,"") | F14: =IFERROR(F13/F12-1,"")
A16: SG&A — consensus | B16: 4750.375 | C16: 5253.5975 | D16: 5792.1293 | E16: 6465.9907 | F16: 6839.2177
A17: model | B17: =Model!G22 | C17: =Model!H22 | D17: =Model!I22 | E17: =Model!J22 | F17: =Model!K22
A18: vs consensus | B18: =IFERROR(B17/B16-1,"") | C18: =IFERROR(C17/C16-1,"") | D18: =IFERROR(D17/D16-1,"") | E18: =IFERROR(E17/E16-1,"") | F18: =IFERROR(F17/F16-1,"")
A20: Net income (NOPAT) — consensus | B20: 25656.683 | C20: 29167.841 | D20: 33403.028 | E20: 38041.825 | F20: 37236.04
A21: model | B21: =Model!G31 | C21: =Model!H31 | D21: =Model!I31 | E21: =Model!J31 | F21: =Model!K31
A22: vs consensus | B22: =IFERROR(B21/B20-1,"") | C22: =IFERROR(C21/C20-1,"") | D22: =IFERROR(D21/D20-1,"") | E22: =IFERROR(E21/E20-1,"") | F22: =IFERROR(F21/F20-1,"")
A24: EPS — consensus | B24: 13.1456 | C24: 14.89144 | D24: 16.82887 | E24: 19.34986 | F24: 18.94
A25: model | B25: =Model!G31/Financials!AC17 | C25: =Model!H31/Financials!AC17 | D25: =Model!I31/Financials!AC17 | E25: =Model!J31/Financials!AC17 | F25: =Model!K31/Financials!AC17
A26: vs consensus | B26: =IFERROR(B25/B24-1,"") | C26: =IFERROR(C25/C24-1,"") | D26: =IFERROR(D25/D24-1,"") | E26: =IFERROR(E25/E24-1,"") | F26: =IFERROR(F25/F24-1,"")
A28: Defaults anchored to consensus revenue + net income (≈0% diff). Other rows show where the model sits vs Street.
A29: *FMP's EBITDA/EBIT estimates look unreliable for AMZN (it reports NI > EBIT) — don't over-read those two.

Sheet Valuation
A1: Visa Inc. — DCF Valuation
A2: Current price | B2: =Dashboard!$B$48
A3: WACC | B3: =WACC!B14
A4: Terminal growth (g) | B4: =Dashboard!$B$46
A5: Tax rate | B5: =Dashboard!$B$31
A6: Terminal method | B6: =Dashboard!$B$43
A7: Exit basis | B7: =Dashboard!$B$44
A8: Exit multiple | B8: =Dashboard!$B$45
A11: Forecast year | C11: 2026 | D11: 2027 | E11: 2028 | F11: 2029 | G11: 2030 | H11: 2031 | I11: 2032 | J11: 2033 | K11: 2034 | L11: 2035
A12: FCFF ($M) | C12: =Model!G39 | D12: =Model!H39 | E12: =Model!I39 | F12: =Model!J39 | G12: =Model!K39 | H12: =Model!L39 | I12: =Model!M39 | J12: =Model!N39 | ... L12: =Model!P39
A13: PV factor | C13: =1/(1+$B$3)^1 | D13: =1/(1+$B$3)^2 | E13: =1/(1+$B$3)^3 | F13: =1/(1+$B$3)^4 | G13: =1/(1+$B$3)^5 | H13: =1/(1+$B$3)^6 | I13: =1/(1+$B$3)^7 | J13: =1/(1+$B$3)^8 | K13: =1/(1+$B$3)^9 | L13: =1/(1+$B$3)^10
A14: PV of FCFF ($M) | C14: =C12*C13 | D14: =D12*D13 | E14: =E12*E13 | F14: =F12*F13 | G14: =G12*G13 | H14: =H12*H13 | I14: =I12*I13 | J14: =J12*J13 | ... L14: =L12*L13
A16: Sum PV of FCFF | B16: =SUM(C14:L14)
A18: TERMINAL VALUE (exit multiple = default; perpetuity = cross-check)
A19: Terminal-year FCFF | B19: =L12
A20: Terminal revenue | B20: =Model!P14
A21: Terminal EBIT | B21: =Model!P27
A22: Terminal EBITDA | B22: =Model!P27+Model!P32
A23: Terminal metric (per exit basis) | B23: =IF($B$7="EV/EBITDA",B22,IF($B$7="EV/Sales",B20,IF($B$7="EV/EBIT",B21,B19)))
A24: TV (exit) = metric x multiple | B24: =B23*$B$8
A25: PV of TV — exit multiple | B25: =B24/(1+$B$3)^10
A26: TV (perpetuity) = FCFF(1+g)/(WACC-g) | B26: =B19*(1+$B$4)/($B$3-$B$4)
A27: PV of TV — perpetuity | B27: =B26/(1+$B$3)^10
A28: PV of TV — SELECTED | B28: =IF($B$6="Perpetuity",B27,B25)
A30: EQUITY BRIDGE -> VALUE / SHARE
A31: Operating value (enterprise value) | B31: =B16+B28
A32: + Cash & ST investments | B32: =Financials!AC42
A33: - Long-term debt | B33: =-Financials!AC47
A34: Equity value | B34: =B31+B32+B33
A35: Diluted shares (M) | B35: =Financials!AC17
A36: VALUE / SHARE | B36: =B34/B35*1.0
A38: CROSS-CHECKS & RETURN
A39: Terminal weight (% of EV) | B39: =B28/B31
A40: Implied perpetuity g (from exit multiple) | B40: =(B24*$B$3-B19)/(B24+B19)
A41: Implied exit EV/EBITDA (from perpetuity) | B41: =B26/B22
A42: Upside / (downside) to fair value | B42: =B36/$B$2-1
A44: Owner cashflow / share | B44: =-$B$2 | C44: =C12/B35 | D44: =D12/B35 | E44: =E12/B35 | F44: =F12/B35 | G44: =G12/B35 | H44: =H12/B35 | I44: =I12/B35 | J44: =J12/B35 | K44: =K12/B35 | L44: =L12/B35+B36
A45: IRR (buy at price, hold 10y) | B45: =IRR(B44:L44)

Sheet Monte Carlo
A1: Monte Carlo simulation (live) | H1: SIMULATION ENGINE — leave as-is | K1: cagr | L1: term margin | M1: wacc | N1: exit | O1: value/share
A2: 1,000 trials, recomputed in-sheet on every edit. Edit the yellow driver distributions to re-roll. Engine grid is to the right (cols H+). | H2: R0 (base revenue) | I2: =Model!F14 | K2: =MAX(-0.05,NORMINV(RAND(),$C$6,$D$6)) | L2: =MAX(0.02,NORMINV(RAND(),$C$7,$D$7)) | M2: =MIN(0.16,MAX(0.05,NORMINV(RAND(),$C$8,$D$8))) | N2: =MIN(24,MAX(5,NORMINV(RAND(),$C$9,$D$9))) | O2: =$I$8*(SUMPRODUCT(($I$2*(1+K2)^{1;2;3;4;5;6;7;8;9;10})*(($I$3+(L2-$I$3)*{1;2;3;4;5;6;7;8;9;10}/10)*(1-$I$7)+$I$4-$I$4*($I$5+(1.05-$I$5)*{1;2;3;4;5;6;7;8;9;10}/10)-(K2/(1+K2))*$I$6)/(1+M2)^{1;2;3;4;5;6;7;8;9;10})+$I$2*(1+K2)^10*(L2+$I$4)*N2/(1+M2)^10+$I$9-$I$10)/$I$11
H3: m0 (base op margin) | I3: =Model!F28 | K3: =MAX(-0.05,NORMINV(RAND(),$C$6,$D$6)) | L3: =MAX(0.02,NORMINV(RAND(),$C$7,$D$7)) | M3: =MIN(0.16,MAX(0.05,NORMINV(RAND(),$C$8,$D$8))) | N3: =MIN(24,MAX(5,NORMINV(RAND(),$C$9,$D$9))) | O3: =$I$8*(SUMPRODUCT(($I$2*(1+K3)^{1;2;3;4;5;6;7;8;9;10})*(($I$3+(L3-$I$3)*{1;2;3;4;5;6;7;8;9;10}/10)*(1-$I$7)+$I$4-$I$4*($I$5+(1.05-$I$5)*{1;2;3;4;5;6;7;8;9;10}/10)-(K3/(1+K3))*$I$6)/(1+M3)^{1;2;3;4;5;6;7;8;9;10})+$I$2*(1+K3)^10*(L3+$I$4)*N3/(1+M3)^10+$I$9-$I$10)/$I$11
A4: DRIVER DISTRIBUTIONS (yellow = edit; Opus-set defaults) | H4: da (D&A / revenue) | I4: 0.0305 | K4: =MAX(-0.05,NORMINV(RAND(),$C$6,$D$6)) | L4: =MAX(0.02,NORMINV(RAND(),$C$7,$D$7)) | M4: =MIN(0.16,MAX(0.05,NORMINV(RAND(),$C$8,$D$8))) | N4: =MIN(24,MAX(5,NORMINV(RAND(),$C$9,$D$9))) | O4: =$I$8*(SUMPRODUCT(($I$2*(1+K4)^{1;2;3;4;5;6;7;8;9;10})*(($I$3+(L4-$I$3)*{1;2;3;4;5;6;7;8;9;10}/10)*(1-$I$7)+$I$4-$I$4*($I$5+(1.05-$I$5)*{1;2;3;4;5;6;7;8;9;10}/10)-(K4/(1+K4))*$I$6)/(1+M4)^{1;2;3;4;5;6;7;8;9;10})+$I$2*(1+K4)^10*(L4+$I$4)*N4/(1+M4)^10+$I$9-$I$10)/$I$11
A5: Driver | B5: Dist | C5: Mean | D5: Std dev | H5: cda0 (2026 capex/D&A) | I5: 1.1803279 | K5: =MAX(-0.05,NORMINV(RAND(),$C$6,$D$6)) | L5: =MAX(0.02,NORMINV(RAND(),$C$7,$D$7)) | M5: =MIN(0.16,MAX(0.05,NORMINV(RAND(),$C$8,$D$8))) | N5: =MIN(24,MAX(5,NORMINV(RAND(),$C$9,$D$9))) | O5: =$I$8*(SUMPRODUCT(($I$2*(1+K5)^{1;2;3;4;5;6;7;8;9;10})*(($I$3+(L5-$I$3)*{1;2;3;4;5;6;7;8;9;10}/10)*(1-$I$7)+$I$4-$I$4*($I$5+(1.05-$I$5)*{1;2;3;4;5;6;7;8;9;10}/10)-(K5/(1+K5))*$I$6)/(1+M5)^{1;2;3;4;5;6;7;8;9;10})+$I$2*(1+K5)^10*(L5+$I$4)*N5/(1+M5)^10+$I$9-$I$10)/$I$11
A6: Revenue 10y CAGR | B6: Normal | C6: =(Model!P14/Model!F14)^(1/10)-1 | D6: 0.023265018 | H6: nwc (% incr revenue) | I6: 0.005 | K6: =MAX(-0.05,NORMINV(RAND(),$C$6,$D$6)) | L6: =MAX(0.02,NORMINV(RAND(),$C$7,$D$7)) | M6: =MIN(0.16,MAX(0.05,NORMINV(RAND(),$C$8,$D$8))) | N6: =MIN(24,MAX(5,NORMINV(RAND(),$C$9,$D$9))) | O6: =$I$8*(SUMPRODUCT(($I$2*(1+K6)^{1;2;3;4;5;6;7;8;9;10})*(($I$3+(L6-$I$3)*{1;2;3;4;5;6;7;8;9;10}/10)*(1-$I$7)+$I$4-$I$4*($I$5+(1.05-$I$5)*{1;2;3;4;5;6;7;8;9;10}/10)-(K6/(1+K6))*$I$6)/(1+M6)^{1;2;3;4;5;6;7;8;9;10})+$I$2*(1+K6)^10*(L6+$I$4)*N6/(1+M6)^10+$I$9-$I$10)/$I$11
A7: Terminal operating margin | B7: Normal | C7: =Dashboard!$B$30 | D7: 0.020732624 | H7: tax | I7: =Valuation!$B$5 | K7: =MAX(-0.05,NORMINV(RAND(),$C$6,$D$6)) | L7: =MAX(0.02,NORMINV(RAND(),$C$7,$D$7)) | M7: =MIN(0.16,MAX(0.05,NORMINV(RAND(),$C$8,$D$8))) | N7: =MIN(24,MAX(5,NORMINV(RAND(),$C$9,$D$9))) | O7: =$I$8*(SUMPRODUCT(($I$2*(1+K7)^{1;2;3;4;5;6;7;8;9;10})*(($I$3+(L7-$I$3)*{1;2;3;4;5;6;7;8;9;10}/10)*(1-$I$7)+$I$4-$I$4*($I$5+(1.05-$I$5)*{1;2;3;4;5;6;7;8;9;10}/10)-(K7/(1+K7))*$I$6)/(1+M7)^{1;2;3;4;5;6;7;8;9;10})+$I$2*(1+K7)^10*(L7+$I$4)*N7/(1+M7)^10+$I$9-$I$10)/$I$11
A8: WACC | B8: Normal | C8: =WACC!B14 | D8: 0.005 | H8: k (calibration) | I8: 0.84823016 | K8: =MAX(-0.05,NORMINV(RAND(),$C$6,$D$6)) | L8: =MAX(0.02,NORMINV(RAND(),$C$7,$D$7)) | M8: =MIN(0.16,MAX(0.05,NORMINV(RAND(),$C$8,$D$8))) | N8: =MIN(24,MAX(5,NORMINV(RAND(),$C$9,$D$9))) | O8: =$I$8*(SUMPRODUCT(($I$2*(1+K8)^{1;2;3;4;5;6;7;8;9;10})*(($I$3+(L8-$I$3)*{1;2;3;4;5;6;7;8;9;10}/10)*(1-$I$7)+$I$4-$I$4*($I$5+(1.05-$I$5)*{1;2;3;4;5;6;7;8;9;10}/10)-(K8/(1+K8))*$I$6)/(1+M8)^{1;2;3;4;5;6;7;8;9;10})+$I$2*(1+K8)^10*(L8+$I$4)*N8/(1+M8)^10+$I$9-$I$10)/$I$11
A9: Exit EV/EBITDA multiple | B9: Normal | C9: =Dashboard!$B$45 | D9: 1.5 | H9: cash | I9: =Financials!AC42 | K9: =MAX(-0.05,NORMINV(RAND(),$C$6,$D$6)) | L9: =MAX(0.02,NORMINV(RAND(),$C$7,$D$7)) | M9: =MIN(0.16,MAX(0.05,NORMINV(RAND(),$C$8,$D$8))) | N9: =MIN(24,MAX(5,NORMINV(RAND(),$C$9,$D$9))) | O9: =$I$8*(SUMPRODUCT(($I$2*(1+K9)^{1;2;3;4;5;6;7;8;9;10})*(($I$3+(L9-$I$3)*{1;2;3;4;5;6;7;8;9;10}/10)*(1-$I$7)+$I$4-$I$4*($I$5+(1.05-$I$5)*{1;2;3;4;5;6;7;8;9;10}/10)-(K9/(1+K9))*$I$6)/(1+M9)^{1;2;3;4;5;6;7;8;9;10})+$I$2*(1+K9)^10*(L9+$I$4)*N9/(1+M9)^10+$I$9-$I$10)/$I$11
H10: debt | I10: =Financials!AC47 | K10: =MAX(-0.05,NORMINV(RAND(),$C$6,$D$6)) | L10: =MAX(0.02,NORMINV(RAND(),$C$7,$D$7)) | M10: =MIN(0.16,MAX(0.05,NORMINV(RAND(),$C$8,$D$8))) | N10: =MIN(24,MAX(5,NORMINV(RAND(),$C$9,$D$9))) | O10: =$I$8*(SUMPRODUCT(($I$2*(1+K10)^{1;2;3;4;5;6;7;8;9;10})*(($I$3+(L10-$I$3)*{1;2;3;4;5;6;7;8;9;10}/10)*(1-$I$7)+$I$4-$I$4*($I$5+(1.05-$I$5)*{1;2;3;4;5;6;7;8;9;10}/10)-(K10/(1+K10))*$I$6)/(1+M10)^{1;2;3;4;5;6;7;8;9;10})+$I$2*(1+K10)^10*(L10+$I$4)*N10/(1+M10)^10+$I$9-$I$10)/$I$11
A11: SIMULATION OUTPUT — value / share (live) | H11: shares | I11: =Financials!AC17 | K11: =MAX(-0.05,NORMINV(RAND(),$C$6,$D$6)) | L11: =MAX(0.02,NORMINV(RAND(),$C$7,$D$7)) | M11: =MIN(0.16,MAX(0.05,NORMINV(RAND(),$C$8,$D$8))) | N11: =MIN(24,MAX(5,NORMINV(RAND(),$C$9,$D$9))) | O11: =$I$8*(SUMPRODUCT(($I$2*(1+K11)^{1;2;3;4;5;6;7;8;9;10})*(($I$3+(L11-$I$3)*{1;2;3;4;5;6;7;8;9;10}/10)*(1-$I$7)+$I$4-$I$4*($I$5+(1.05-$I$5)*{1;2;3;4;5;6;7;8;9;10}/10)-(K11/(1+K11))*$I$6)/(1+M11)^{1;2;3;4;5;6;7;8;9;10})+$I$2*(1+K11)^10*(L11+$I$4)*N11/(1+M11)^10+$I$9-$I$10)/$I$11
A12: Mean | B12: =AVERAGE($O$2:$O$1001) | K12: =MAX(-0.05,NORMINV(RAND(),$C$6,$D$6)) | L12: =MAX(0.02,NORMINV(RAND(),$C$7,$D$7)) | M12: =MIN(0.16,MAX(0.05,NORMINV(RAND(),$C$8,$D$8))) | N12: =MIN(24,MAX(5,NORMINV(RAND(),$C$9,$D$9))) | O12: =$I$8*(SUMPRODUCT(($I$2*(1+K12)^{1;2;3;4;5;6;7;8;9;10})*(($I$3+(L12-$I$3)*{1;2;3;4;5;6;7;8;9;10}/10)*(1-$I$7)+$I$4-$I$4*($I$5+(1.05-$I$5)*{1;2;3;4;5;6;7;8;9;10}/10)-(K12/(1+K12))*$I$6)/(1+M12)^{1;2;3;4;5;6;7;8;9;10})+$I$2*(1+K12)^10*(L12+$I$4)*N12/(1+M12)^10+$I$9-$I$10)/$I$11
A13: Median (P50) | B13: =MEDIAN($O$2:$O$1001) | K13: =MAX(-0.05,NORMINV(RAND(),$C$6,$D$6)) | L13: =MAX(0.02,NORMINV(RAND(),$C$7,$D$7)) | M13: =MIN(0.16,MAX(0.05,NORMINV(RAND(),$C$8,$D$8))) | N13: =MIN(24,MAX(5,NORMINV(RAND(),$C$9,$D$9))) | O13: =$I$8*(SUMPRODUCT(($I$2*(1+K13)^{1;2;3;4;5;6;7;8;9;10})*(($I$3+(L13-$I$3)*{1;2;3;4;5;6;7;8;9;10}/10)*(1-$I$7)+$I$4-$I$4*($I$5+(1.05-$I$5)*{1;2;3;4;5;6;7;8;9;10}/10)-(K13/(1+K13))*$I$6)/(1+M13)^{1;2;3;4;5;6;7;8;9;10})+$I$2*(1+K13)^10*(L13+$I$4)*N13/(1+M13)^10+$I$9-$I$10)/$I$11
A14: Std dev | B14: =STDEV($O$2:$O$1001) | K14: =MAX(-0.05,NORMINV(RAND(),$C$6,$D$6)) | L14: =MAX(0.02,NORMINV(RAND(),$C$7,$D$7)) | M14: =MIN(0.16,MAX(0.05,NORMINV(RAND(),$C$8,$D$8))) | N14: =MIN(24,MAX(5,NORMINV(RAND(),$C$9,$D$9))) | O14: =$I$8*(SUMPRODUCT(($I$2*(1+K14)^{1;2;3;4;5;6;7;8;9;10})*(($I$3+(L14-$I$3)*{1;2;3;4;5;6;7;8;9;10}/10)*(1-$I$7)+$I$4-$I$4*($I$5+(1.05-$I$5)*{1;2;3;4;5;6;7;8;9;10}/10)-(K14/(1+K14))*$I$6)/(1+M14)^{1;2;3;4;5;6;7;8;9;10})+$I$2*(1+K14)^10*(L14+$I$4)*N14/(1+M14)^10+$I$9-$I$10)/$I$11
A15: Min | B15: =MIN($O$2:$O$1001) | K15: =MAX(-0.05,NORMINV(RAND(),$C$6,$D$6)) | L15: =MAX(0.02,NORMINV(RAND(),$C$7,$D$7)) | M15: =MIN(0.16,MAX(0.05,NORMINV(RAND(),$C$8,$D$8))) | N15: =MIN(24,MAX(5,NORMINV(RAND(),$C$9,$D$9))) | O15: =$I$8*(SUMPRODUCT(($I$2*(1+K15)^{1;2;3;4;5;6;7;8;9;10})*(($I$3+(L15-$I$3)*{1;2;3;4;5;6;7;8;9;10}/10)*(1-$I$7)+$I$4-$I$4*($I$5+(1.05-$I$5)*{1;2;3;4;5;6;7;8;9;10}/10)-(K15/(1+K15))*$I$6)/(1+M15)^{1;2;3;4;5;6;7;8;9;10})+$I$2*(1+K15)^10*(L15+$I$4)*N15/(1+M15)^10+$I$9-$I$10)/$I$11
A16: Max | B16: =MAX($O$2:$O$1001) | K16: =MAX(-0.05,NORMINV(RAND(),$C$6,$D$6)) | L16: =MAX(0.02,NORMINV(RAND(),$C$7,$D$7)) | M16: =MIN(0.16,MAX(0.05,NORMINV(RAND(),$C$8,$D$8))) | N16: =MIN(24,MAX(5,NORMINV(RAND(),$C$9,$D$9))) | O16: =$I$8*(SUMPRODUCT(($I$2*(1+K16)^{1;2;3;4;5;6;7;8;9;10})*(($I$3+(L16-$I$3)*{1;2;3;4;5;6;7;8;9;10}/10)*(1-$I$7)+$I$4-$I$4*($I$5+(1.05-$I$5)*{1;2;3;4;5;6;7;8;9;10}/10)-(K16/(1+K16))*$I$6)/(1+M16)^{1;2;3;4;5;6;7;8;9;10})+$I$2*(1+K16)^10*(L16+$I$4)*N16/(1+M16)^10+$I$9-$I$10)/$I$11
A17: Current price | B17: =Valuation!$B$2 | K17: =MAX(-0.05,NORMINV(RAND(),$C$6,$D$6)) | L17: =MAX(0.02,NORMINV(RAND(),$C$7,$D$7)) | M17: =MIN(0.16,MAX(0.05,NORMINV(RAND(),$C$8,$D$8))) | N17: =MIN(24,MAX(5,NORMINV(RAND(),$C$9,$D$9))) | O17: =$I$8*(SUMPRODUCT(($I$2*(1+K17)^{1;2;3;4;5;6;7;8;9;10})*(($I$3+(L17-$I$3)*{1;2;3;4;5;6;7;8;9;10}/10)*(1-$I$7)+$I$4-$I$4*($I$5+(1.05-$I$5)*{1;2;3;4;5;6;7;8;9;10}/10)-(K17/(1+K17))*$I$6)/(1+M17)^{1;2;3;4;5;6;7;8;9;10})+$I$2*(1+K17)^10*(L17+$I$4)*N17/(1+M17)^10+$I$9-$I$10)/$I$11
A18: Base case (full model) | B18: =Valuation!B36 | K18: =MAX(-0.05,NORMINV(RAND(),$C$6,$D$6)) | L18: =MAX(0.02,NORMINV(RAND(),$C$7,$D$7)) | M18: =MIN(0.16,MAX(0.05,NORMINV(RAND(),$C$8,$D$8))) | N18: =MIN(24,MAX(5,NORMINV(RAND(),$C$9,$D$9))) | O18: =$I$8*(SUMPRODUCT(($I$2*(1+K18)^{1;2;3;4;5;6;7;8;9;10})*(($I$3+(L18-$I$3)*{1;2;3;4;5;6;7;8;9;10}/10)*(1-$I$7)+$I$4-$I$4*($I$5+(1.05-$I$5)*{1;2;3;4;5;6;7;8;9;10}/10)-(K18/(1+K18))*$I$6)/(1+M18)^{1;2;3;4;5;6;7;8;9;10})+$I$2*(1+K18)^10*(L18+$I$4)*N18/(1+M18)^10+$I$9-$I$10)/$I$11
K19: =MAX(-0.05,NORMINV(RAND(),$C$6,$D$6)) | L19: =MAX(0.02,NORMINV(RAND(),$C$7,$D$7)) | M19: =MIN(0.16,MAX(0.05,NORMINV(RAND(),$C$8,$D$8))) | N19: =MIN(24,MAX(5,NORMINV(RAND(),$C$9,$D$9))) | O19: =$I$8*(SUMPRODUCT(($I$2*(1+K19)^{1;2;3;4;5;6;7;8;9;10})*(($I$3+(L19-$I$3)*{1;2;3;4;5;6;7;8;9;10}/10)*(1-$I$7)+$I$4-$I$4*($I$5+(1.05-$I$5)*{1;2;3;4;5;6;7;8;9;10}/10)-(K19/(1+K19))*$I$6)/(1+M19)^{1;2;3;4;5;6;7;8;9;10})+$I$2*(1+K19)^10*(L19+$I$4)*N19/(1+M19)^10+$I$9-$I$10)/$I$11
A20: P(undervalued at current price) | B20: =COUNTIF($O$2:$O$1001,">"&Valuation!$B$2)/1000 | K20: =MAX(-0.05,NORMINV(RAND(),$C$6,$D$6)) | L20: =MAX(0.02,NORMINV(RAND(),$C$7,$D$7)) | M20: =MIN(0.16,MAX(0.05,NORMINV(RAND(),$C$8,$D$8))) | N20: =MIN(24,MAX(5,NORMINV(RAND(),$C$9,$D$9))) | O20: =$I$8*(SUMPRODUCT(($I$2*(1+K20)^{1;2;3;4;5;6;7;8;9;10})*(($I$3+(L20-$I$3)*{1;2;3;4;5;6;7;8;9;10}/10)*(1-$I$7)+$I$4-$I$4*($I$5+(1.05-$I$5)*{1;2;3;4;5;6;7;8;9;10}/10)-(K20/(1+K20))*$I$6)/(1+M20)^{1;2;3;4;5;6;7;8;9;10})+$I$2*(1+K20)^10*(L20+$I$4)*N20/(1+M20)^10+$I$9-$I$10)/$I$11
A21: P(>20% upside) | B21: =COUNTIF($O$2:$O$1001,">"&Valuation!$B$2*1.2)/1000 | K21: =MAX(-0.05,NORMINV(RAND(),$C$6,$D$6)) | L21: =MAX(0.02,NORMINV(RAND(),$C$7,$D$7)) | M21: =MIN(0.16,MAX(0.05,NORMINV(RAND(),$C$8,$D$8))) | N21: =MIN(24,MAX(5,NORMINV(RAND(),$C$9,$D$9))) | O21: =$I$8*(SUMPRODUCT(($I$2*(1+K21)^{1;2;3;4;5;6;7;8;9;10})*(($I$3+(L21-$I$3)*{1;2;3;4;5;6;7;8;9;10}/10)*(1-$I$7)+$I$4-$I$4*($I$5+(1.05-$I$5)*{1;2;3;4;5;6;7;8;9;10}/10)-(K21/(1+K21))*$I$6)/(1+M21)^{1;2;3;4;5;6;7;8;9;10})+$I$2*(1+K21)^10*(L21+$I$4)*N21/(1+M21)^10+$I$9-$I$10)/$I$11
K22: =MAX(-0.05,NORMINV(RAND(),$C$6,$D$6)) | L22: =MAX(0.02,NORMINV(RAND(),$C$7,$D$7)) | M22: =MIN(0.16,MAX(0.05,NORMINV(RAND(),$C$8,$D$8))) | N22: =MIN(24,MAX(5,NORMINV(RAND(),$C$9,$D$9))) | O22: =$I$8*(SUMPRODUCT(($I$2*(1+K22)^{1;2;3;4;5;6;7;8;9;10})*(($I$3+(L22-$I$3)*{1;2;3;4;5;6;7;8;9;10}/10)*(1-$I$7)+$I$4-$I$4*($I$5+(1.05-$I$5)*{1;2;3;4;5;6;7;8;9;10}/10)-(K22/(1+K22))*$I$6)/(1+M22)^{1;2;3;4;5;6;7;8;9;10})+$I$2*(1+K22)^10*(L22+$I$4)*N22/(1+M22)^10+$I$9-$I$10)/$I$11
A23: PERCENTILES (live) | K23: =MAX(-0.05,NORMINV(RAND(),$C$6,$D$6)) | L23: =MAX(0.02,NORMINV(RAND(),$C$7,$D$7)) | M23: =MIN(0.16,MAX(0.05,NORMINV(RAND(),$C$8,$D$8))) | N23: =MIN(24,MAX(5,NORMINV(RAND(),$C$9,$D$9))) | O23: =$I$8*(SUMPRODUCT(($I$2*(1+K23)^{1;2;3;4;5;6;7;8;9;10})*(($I$3+(L23-$I$3)*{1;2;3;4;5;6;7;8;9;10}/10)*(1-$I$7)+$I$4-$I$4*($I$5+(1.05-$I$5)*{1;2;3;4;5;6;7;8;9;10}/10)-(K23/(1+K23))*$I$6)/(1+M23)^{1;2;3;4;5;6;7;8;9;10})+$I$2*(1+K23)^10*(L23+$I$4)*N23/(1+M23)^10+$I$9-$I$10)/$I$11
A24: P5 | B24: =PERCENTILE($O$2:$O$1001,0.05) | K24: =MAX(-0.05,NORMINV(RAND(),$C$6,$D$6)) | L24: =MAX(0.02,NORMINV(RAND(),$C$7,$D$7)) | M24: =MIN(0.16,MAX(0.05,NORMINV(RAND(),$C$8,$D$8))) | N24: =MIN(24,MAX(5,NORMINV(RAND(),$C$9,$D$9))) | O24: =$I$8*(SUMPRODUCT(($I$2*(1+K24)^{1;2;3;4;5;6;7;8;9;10})*(($I$3+(L24-$I$3)*{1;2;3;4;5;6;7;8;9;10}/10)*(1-$I$7)+$I$4-$I$4*($I$5+(1.05-$I$5)*{1;2;3;4;5;6;7;8;9;10}/10)-(K24/(1+K24))*$I$6)/(1+M24)^{1;2;3;4;5;6;7;8;9;10})+$I$2*(1+K24)^10*(L24+$I$4)*N24/(1+M24)^10+$I$9-$I$10)/$I$11
A25: P10 | B25: =PERCENTILE($O$2:$O$1001,0.1) | K25: =MAX(-0.05,NORMINV(RAND(),$C$6,$D$6)) | L25: =MAX(0.02,NORMINV(RAND(),$C$7,$D$7)) | M25: =MIN(0.16,MAX(0.05,NORMINV(RAND(),$C$8,$D$8))) | N25: =MIN(24,MAX(5,NORMINV(RAND(),$C$9,$D$9))) | O25: =$I$8*(SUMPRODUCT(($I$2*(1+K25)^{1;2;3;4;5;6;7;8;9;10})*(($I$3+(L25-$I$3)*{1;2;3;4;5;6;7;8;9;10}/10)*(1-$I$7)+$I$4-$I$4*($I$5+(1.05-$I$5)*{1;2;3;4;5;6;7;8;9;10}/10)-(K25/(1+K25))*$I$6)/(1+M25)^{1;2;3;4;5;6;7;8;9;10})+$I$2*(1+K25)^10*(L25+$I$4)*N25/(1+M25)^10+$I$9-$I$10)/$I$11
A26: P25 | B26: =PERCENTILE($O$2:$O$1001,0.25) | K26: =MAX(-0.05,NORMINV(RAND(),$C$6,$D$6)) | L26: =MAX(0.02,NORMINV(RAND(),$C$7,$D$7)) | M26: =MIN(0.16,MAX(0.05,NORMINV(RAND(),$C$8,$D$8))) | N26: =MIN(24,MAX(5,NORMINV(RAND(),$C$9,$D$9))) | O26: =$I$8*(SUMPRODUCT(($I$2*(1+K26)^{1;2;3;4;5;6;7;8;9;10})*(($I$3+(L26-$I$3)*{1;2;3;4;5;6;7;8;9;10}/10)*(1-$I$7)+$I$4-$I$4*($I$5+(1.05-$I$5)*{1;2;3;4;5;6;7;8;9;10}/10)-(K26/(1+K26))*$I$6)/(1+M26)^{1;2;3;4;5;6;7;8;9;10})+$I$2*(1+K26)^10*(L26+$I$4)*N26/(1+M26)^10+$I$9-$I$10)/$I$11
A27: P50 | B27: =PERCENTILE($O$2:$O$1001,0.5) | K27: =MAX(-0.05,NORMINV(RAND(),$C$6,$D$6)) | L27: =MAX(0.02,NORMINV(RAND(),$C$7,$D$7)) | M27: =MIN(0.16,MAX(0.05,NORMINV(RAND(),$C$8,$D$8))) | N27: =MIN(24,MAX(5,NORMINV(RAND(),$C$9,$D$9))) | O27: =$I$8*(SUMPRODUCT(($I$2*(1+K27)^{1;2;3;4;5;6;7;8;9;10})*(($I$3+(L27-$I$3)*{1;2;3;4;5;6;7;8;9;10}/10)*(1-$I$7)+$I$4-$I$4*($I$5+(1.05-$I$5)*{1;2;3;4;5;6;7;8;9;10}/10)-(K27/(1+K27))*$I$6)/(1+M27)^{1;2;3;4;5;6;7;8;9;10})+$I$2*(1+K27)^10*(L27+$I$4)*N27/(1+M27)^10+$I$9-$I$10)/$I$11
A28: P75 | B28: =PERCENTILE($O$2:$O$1001,0.75) | K28: =MAX(-0.05,NORMINV(RAND(),$C$6,$D$6)) | L28: =MAX(0.02,NORMINV(RAND(),$C$7,$D$7)) | M28: =MIN(0.16,MAX(0.05,NORMINV(RAND(),$C$8,$D$8))) | N28: =MIN(24,MAX(5,NORMINV(RAND(),$C$9,$D$9))) | O28: =$I$8*(SUMPRODUCT(($I$2*(1+K28)^{1;2;3;4;5;6;7;8;9;10})*(($I$3+(L28-$I$3)*{1;2;3;4;5;6;7;8;9;10}/10)*(1-$I$7)+$I$4-$I$4*($I$5+(1.05-$I$5)*{1;2;3;4;5;6;7;8;9;10}/10)-(K28/(1+K28))*$I$6)/(1+M28)^{1;2;3;4;5;6;7;8;9;10})+$I$2*(1+K28)^10*(L28+$I$4)*N28/(1+M28)^10+$I$9-$I$10)/$I$11
A29: P90 | B29: =PERCENTILE($O$2:$O$1001,0.9) | K29: =MAX(-0.05,NORMINV(RAND(),$C$6,$D$6)) | L29: =MAX(0.02,NORMINV(RAND(),$C$7,$D$7)) | M29: =MIN(0.16,MAX(0.05,NORMINV(RAND(),$C$8,$D$8))) | N29: =MIN(24,MAX(5,NORMINV(RAND(),$C$9,$D$9))) | O29: =$I$8*(SUMPRODUCT(($I$2*(1+K29)^{1;2;3;4;5;6;7;8;9;10})*(($I$3+(L29-$I$3)*{1;2;3;4;5;6;7;8;9;10}/10)*(1-$I$7)+$I$4-$I$4*($I$5+(1.05-$I$5)*{1;2;3;4;5;6;7;8;9;10}/10)-(K29/(1+K29))*$I$6)/(1+M29)^{1;2;3;4;5;6;7;8;9;10})+$I$2*(1+K29)^10*(L29+$I$4)*N29/(1+M29)^10+$I$9-$I$10)/$I$11
A30: P95 | B30: =PERCENTILE($O$2:$O$1001,0.95) | K30: =MAX(-0.05,NORMINV(RAND(),$C$6,$D$6)) | L30: =MAX(0.02,NORMINV(RAND(),$C$7,$D$7)) | M30: =MIN(0.16,MAX(0.05,NORMINV(RAND(),$C$8,$D$8))) | N30: =MIN(24,MAX(5,NORMINV(RAND(),$C$9,$D$9))) | O30: =$I$8*(SUMPRODUCT(($I$2*(1+K30)^{1;2;3;4;5;6;7;8;9;10})*(($I$3+(L30-$I$3)*{1;2;3;4;5;6;7;8;9;10}/10)*(1-$I$7)+$I$4-$I$4*($I$5+(1.05-$I$5)*{1;2;3;4;5;6;7;8;9;10}/10)-(K30/(1+K30))*$I$6)/(1+M30)^{1;2;3;4;5;6;7;8;9;10})+$I$2*(1+K30)^10*(L30+$I$4)*N30/(1+M30)^10+$I$9-$I$10)/$I$11
K31: =MAX(-0.05,NORMINV(RAND(),$C$6,$D$6)) | L31: =MAX(0.02,NORMINV(RAND(),$C$7,$D$7)) | M31: =MIN(0.16,MAX(0.05,NORMINV(RAND(),$C$8,$D$8))) | N31: =MIN(24,MAX(5,NORMINV(RAND(),$C$9,$D$9))) | O31: =$I$8*(SUMPRODUCT(($I$2*(1+K31)^{1;2;3;4;5;6;7;8;9;10})*(($I$3+(L31-$I$3)*{1;2;3;4;5;6;7;8;9;10}/10)*(1-$I$7)+$I$4-$I$4*($I$5+(1.05-$I$5)*{1;2;3;4;5;6;7;8;9;10}/10)-(K31/(1+K31))*$I$6)/(1+M31)^{1;2;3;4;5;6;7;8;9;10})+$I$2*(1+K31)^10*(L31+$I$4)*N31/(1+M31)^10+$I$9-$I$10)/$I$11
A32: VALUE DISTRIBUTION (live histogram) | K32: =MAX(-0.05,NORMINV(RAND(),$C$6,$D$6)) | L32: =MAX(0.02,NORMINV(RAND(),$C$7,$D$7)) | M32: =MIN(0.16,MAX(0.05,NORMINV(RAND(),$C$8,$D$8))) | N32: =MIN(24,MAX(5,NORMINV(RAND(),$C$9,$D$9))) | O32: =$I$8*(SUMPRODUCT(($I$2*(1+K32)^{1;2;3;4;5;6;7;8;9;10})*(($I$3+(L32-$I$3)*{1;2;3;4;5;6;7;8;9;10}/10)*(1-$I$7)+$I$4-$I$4*($I$5+(1.05-$I$5)*{1;2;3;4;5;6;7;8;9;10}/10)-(K32/(1+K32))*$I$6)/(1+M32)^{1;2;3;4;5;6;7;8;9;10})+$I$2*(1+K32)^10*(L32+$I$4)*N32/(1+M32)^10+$I$9-$I$10)/$I$11
A33: Bin midpoint ($/sh) | B33: Count | K33: =MAX(-0.05,NORMINV(RAND(),$C$6,$D$6)) | L33: =MAX(0.02,NORMINV(RAND(),$C$7,$D$7)) | M33: =MIN(0.16,MAX(0.05,NORMINV(RAND(),$C$8,$D$8))) | N33: =MIN(24,MAX(5,NORMINV(RAND(),$C$9,$D$9))) | O33: =$I$8*(SUMPRODUCT(($I$2*(1+K33)^{1;2;3;4;5;6;7;8;9;10})*(($I$3+(L33-$I$3)*{1;2;3;4;5;6;7;8;9;10}/10)*(1-$I$7)+$I$4-$I$4*($I$5+(1.05-$I$5)*{1;2;3;4;5;6;7;8;9;10}/10)-(K33/(1+K33))*$I$6)/(1+M33)^{1;2;3;4;5;6;7;8;9;10})+$I$2*(1+K33)^10*(L33+$I$4)*N33/(1+M33)^10+$I$9-$I$10)/$I$11
A34: =$B$15+0.5*($B$16-$B$15)/15 | B34: =COUNTIFS($O$2:$O$1001,">="&($B$15+0*($B$16-$B$15)/15),$O$2:$O$1001,"<"&($B$15+1*($B$16-$B$15)/15)) | K34: =MAX(-0.05,NORMINV(RAND(),$C$6,$D$6)) | L34: =MAX(0.02,NORMINV(RAND(),$C$7,$D$7)) | M34: =MIN(0.16,MAX(0.05,NORMINV(RAND(),$C$8,$D$8))) | N34: =MIN(24,MAX(5,NORMINV(RAND(),$C$9,$D$9))) | O34: =$I$8*(SUMPRODUCT(($I$2*(1+K34)^{1;2;3;4;5;6;7;8;9;10})*(($I$3+(L34-$I$3)*{1;2;3;4;5;6;7;8;9;10}/10)*(1-$I$7)+$I$4-$I$4*($I$5+(1.05-$I$5)*{1;2;3;4;5;6;7;8;9;10}/10)-(K34/(1+K34))*$I$6)/(1+M34)^{1;2;3;4;5;6;7;8;9;10})+$I$2*(1+K34)^10*(L34+$I$4)*N34/(1+M34)^10+$I$9-$I$10)/$I$11
A35: =$B$15+1.5*($B$16-$B$15)/15 | B35: =COUNTIFS($O$2:$O$1001,">="&($B$15+1*($B$16-$B$15)/15),$O$2:$O$1001,"<"&($B$15+2*($B$16-$B$15)/15)) | K35: =MAX(-0.05,NORMINV(RAND(),$C$6,$D$6)) | L35: =MAX(0.02,NORMINV(RAND(),$C$7,$D$7)) | M35: =MIN(0.16,MAX(0.05,NORMINV(RAND(),$C$8,$D$8))) | N35: =MIN(24,MAX(5,NORMINV(RAND(),$C$9,$D$9))) | O35: =$I$8*(SUMPRODUCT(($I$2*(1+K35)^{1;2;3;4;5;6;7;8;9;10})*(($I$3+(L35-$I$3)*{1;2;3;4;5;6;7;8;9;10}/10)*(1-$I$7)+$I$4-$I$4*($I$5+(1.05-$I$5)*{1;2;3;4;5;6;7;8;9;10}/10)-(K35/(1+K35))*$I$6)/(1+M35)^{1;2;3;4;5;6;7;8;9;10})+$I$2*(1+K35)^10*(L35+$I$4)*N35/(1+M35)^10+$I$9-$I$10)/$I$11
A36: =$B$15+2.5*($B$16-$B$15)/15 | B36: =COUNTIFS($O$2:$O$1001,">="&($B$15+2*($B$16-$B$15)/15),$O$2:$O$1001,"<"&($B$15+3*($B$16-$B$15)/15)) | K36: =MAX(-0.05,NORMINV(RAND(),$C$6,$D$6)) | L36: =MAX(0.02,NORMINV(RAND(),$C$7,$D$7)) | M36: =MIN(0.16,MAX(0.05,NORMINV(RAND(),$C$8,$D$8))) | N36: =MIN(24,MAX(5,NORMINV(RAND(),$C$9,$D$9))) | O36: =$I$8*(SUMPRODUCT(($I$2*(1+K36)^{1;2;3;4;5;6;7;8;9;10})*(($I$3+(L36-$I$3)*{1;2;3;4;5;6;7;8;9;10}/10)*(1-$I$7)+$I$4-$I$4*($I$5+(1.05-$I$5)*{1;2;3;4;5;6;7;8;9;10}/10)-(K36/(1+K36))*$I$6)/(1+M36)^{1;2;3;4;5;6;7;8;9;10})+$I$2*(1+K36)^10*(L36+$I$4)*N36/(1+M36)^10+$I$9-$I$10)/$I$11
A37: =$B$15+3.5*($B$16-$B$15)/15 | B37: =COUNTIFS($O$2:$O$1001,">="&($B$15+3*($B$16-$B$15)/15),$O$2:$O$1001,"<"&($B$15+4*($B$16-$B$15)/15)) | K37: =MAX(-0.05,NORMINV(RAND(),$C$6,$D$6)) | L37: =MAX(0.02,NORMINV(RAND(),$C$7,$D$7)) | M37: =MIN(0.16,MAX(0.05,NORMINV(RAND(),$C$8,$D$8))) | N37: =MIN(24,MAX(5,NORMINV(RAND(),$C$9,$D$9))) | O37: =$I$8*(SUMPRODUCT(($I$2*(1+K37)^{1;2;3;4;5;6;7;8;9;10})*(($I$3+(L37-$I$3)*{1;2;3;4;5;6;7;8;9;10}/10)*(1-$I$7)+$I$4-$I$4*($I$5+(1.05-$I$5)*{1;2;3;4;5;6;7;8;9;10}/10)-(K37/(1+K37))*$I$6)/(1+M37)^{1;2;3;4;5;6;7;8;9;10})+$I$2*(1+K37)^10*(L37+$I$4)*N37/(1+M37)^10+$I$9-$I$10)/$I$11
A38: =$B$15+4.5*($B$16-$B$15)/15 | B38: =COUNTIFS($O$2:$O$1001,">="&($B$15+4*($B$16-$B$15)/15),$O$2:$O$1001,"<"&($B$15+5*($B$16-$B$15)/15)) | K38: =MAX(-0.05,NORMINV(RAND(),$C$6,$D$6)) | L38: =MAX(0.02,NORMINV(RAND(),$C$7,$D$7)) | M38: =MIN(0.16,MAX(0.05,NORMINV(RAND(),$C$8,$D$8))) | N38: =MIN(24,MAX(5,NORMINV(RAND(),$C$9,$D$9))) | O38: =$I$8*(SUMPRODUCT(($I$2*(1+K38)^{1;2;3;4;5;6;7;8;9;10})*(($I$3+(L38-$I$3)*{1;2;3;4;5;6;7;8;9;10}/10)*(1-$I$7)+$I$4-$I$4*($I$5+(1.05-$I$5)*{1;2;3;4;5;6;7;8;9;10}/10)-(K38/(1+K38))*$I$6)/(1+M38)^{1;2;3;4;5;6;7;8;9;10})+$I$2*(1+K38)^10*(L38+$I$4)*N38/(1+M38)^10+$I$9-$I$10)/$I$11
A39: =$B$15+5.5*($B$16-$B$15)/15 | B39: =COUNTIFS($O$2:$O$1001,">="&($B$15+5*($B$16-$B$15)/15),$O$2:$O$1001,"<"&($B$15+6*($B$16-$B$15)/15)) | K39: =MAX(-0.05,NORMINV(RAND(),$C$6,$D$6)) | L39: =MAX(0.02,NORMINV(RAND(),$C$7,$D$7)) | M39: =MIN(0.16,MAX(0.05,NORMINV(RAND(),$C$8,$D$8))) | N39: =MIN(24,MAX(5,NORMINV(RAND(),$C$9,$D$9))) | O39: =$I$8*(SUMPRODUCT(($I$2*(1+K39)^{1;2;3;4;5;6;7;8;9;10})*(($I$3+(L39-$I$3)*{1;2;3;4;5;6;7;8;9;10}/10)*(1-$I$7)+$I$4-$I$4*($I$5+(1.05-$I$5)*{1;2;3;4;5;6;7;8;9;10}/10)-(K39/(1+K39))*$I$6)/(1+M39)^{1;2;3;4;5;6;7;8;9;10})+$I$2*(1+K39)^10*(L39+$I$4)*N39/(1+M39)^10+$I$9-$I$10)/$I$11
A40: =$B$15+6.5*($B$16-$B$15)/15 | B40: =COUNTIFS($O$2:$O$1001,">="&($B$15+6*($B$16-$B$15)/15),$O$2:$O$1001,"<"&($B$15+7*($B$16-$B$15)/15)) | K40: =MAX(-0.05,NORMINV(RAND(),$C$6,$D$6)) | L40: =MAX(0.02,NORMINV(RAND(),$C$7,$D$7)) | M40: =MIN(0.16,MAX(0.05,NORMINV(RAND(),$C$8,$D$8))) | N40: =MIN(24,MAX(5,NORMINV(RAND(),$C$9,$D$9))) | O40: =$I$8*(SUMPRODUCT(($I$2*(1+K40)^{1;2;3;4;5;6;7;8;9;10})*(($I$3+(L40-$I$3)*{1;2;3;4;5;6;7;8;9;10}/10)*(1-$I$7)+$I$4-$I$4*($I$5+(1.05-$I$5)*{1;2;3;4;5;6;7;8;9;10}/10)-(K40/(1+K40))*$I$6)/(1+M40)^{1;2;3;4;5;6;7;8;9;10})+$I$2*(1+K40)^10*(L40+$I$4)*N40/(1+M40)^10+$I$9-$I$10)/$I$11
...
